/cm/local/apps/slurm/var/spool/job417868/slurm_script: line 19: /common/ketrong/minconda3/etc/profile.d/conda.sh: No such file or directory
/cm/local/apps/slurm/var/spool/job417868/slurm_script: line 22: $'\nconda create --name tpot2devenv -c conda-forge python=3.10\n': command not found
/cm/local/apps/slurm/var/spool/job417868/slurm_script: line 27: $'\npip install -r requirements.txt\n': command not found
RunStart
2023-11-28 16:16:38.106662: I tensorflow/core/util/port.cc:113] oneDNN custom operations are on. You may see slightly different numerical results due to floating-point round-off errors from different computation orders. To turn them off, set the environment variable `TF_ENABLE_ONEDNN_OPTS=0`.
2023-11-28 16:16:38.140935: E external/local_xla/xla/stream_executor/cuda/cuda_dnn.cc:9261] Unable to register cuDNN factory: Attempting to register factory for plugin cuDNN when one has already been registered
2023-11-28 16:16:38.140958: E external/local_xla/xla/stream_executor/cuda/cuda_fft.cc:607] Unable to register cuFFT factory: Attempting to register factory for plugin cuFFT when one has already been registered
2023-11-28 16:16:38.141867: E external/local_xla/xla/stream_executor/cuda/cuda_blas.cc:1515] Unable to register cuBLAS factory: Attempting to register factory for plugin cuBLAS when one has already been registered
2023-11-28 16:16:38.147123: I tensorflow/core/platform/cpu_feature_guard.cc:182] This TensorFlow binary is optimized to use available CPU instructions in performance-critical operations.
To enable the following instructions: AVX2 AVX512F AVX512_VNNI FMA, in other operations, rebuild TensorFlow with the appropriate compiler flags.
2023-11-28 16:16:39.272784: W tensorflow/compiler/tf2tensorrt/utils/py_utils.cc:38] TF-TRT Warning: Could not find TensorRT
WARNING:tensorflow:From /home/ketrong/miniconda3/envs/tpot2devenv/lib/python3.10/site-packages/tensorflow/python/compat/v2_compat.py:108: disable_resource_variables (from tensorflow.python.ops.variable_scope) is deprecated and will be removed in a future version.
Instructions for updating:
non-resource variables are not supported in the long term
start
working on 
tpot2_imputetest/Impute_Experiments/logs//small_run
loading data
tpot2_imputetest/Impute_Experiments/data/26_True.pkl
starting impute modules
running experiment 1/3 - Does large hyperparameter space improve reconstruction accuracy over simple
[I 2023-11-28 16:16:54,955] A new study created in memory with name: no-name-95c2c7bb-274c-4543-b11d-8aec00ffd564
[W 2023-11-28 16:16:54,964] Trial 2 failed with parameters: {'model_name': 'GAIN', 'batch_size': 21, 'hint_rate': 0.9500000000000001, 'alpha': 48, 'iterations': 1} because of the following error: InvalidIndexError((slice(None, None, None), 0)).
Traceback (most recent call last):
  File "/home/ketrong/miniconda3/envs/tpot2devenv/lib/python3.10/site-packages/pandas/core/indexes/base.py", line 3802, in get_loc
    return self._engine.get_loc(casted_key)
  File "pandas/_libs/index.pyx", line 138, in pandas._libs.index.IndexEngine.get_loc
  File "pandas/_libs/index.pyx", line 144, in pandas._libs.index.IndexEngine.get_loc
TypeError: '(slice(None, None, None), 0)' is an invalid key

During handling of the above exception, another exception occurred:

Traceback (most recent call last):
  File "/home/ketrong/miniconda3/envs/tpot2devenv/lib/python3.10/site-packages/optuna/study/_optimize.py", line 200, in _run_trial
    value_or_values = func(trial)
  File "/common/ketrong/AutoImputeExp/tpot2_imputetest/Impute_Experiments/autoimpute.py", line 59, in obj
    return autoutils.score(trial, splitting, my_model, X, self.missing_set_train, self.masked_set_train)
  File "/common/ketrong/AutoImputeExp/tpot2_imputetest/Impute_Experiments/autoutils.py", line 62, in score
    imputed = my_model.transform(missing_set)
  File "/home/ketrong/miniconda3/envs/tpot2devenv/lib/python3.10/site-packages/sklearn/utils/_set_output.py", line 157, in wrapped
    data_to_wrap = f(self, X, *args, **kwargs)
  File "/common/ketrong/AutoImputeExp/tpot2_imputetest/Impute_Experiments/transformers.py", line 605, in transform
    return self.gain(X, self.params)
  File "/common/ketrong/AutoImputeExp/tpot2_imputetest/Impute_Experiments/transformers.py", line 636, in gain
    norm_data, norm_parameters = self.normalization(data_x)
  File "/common/ketrong/AutoImputeExp/tpot2_imputetest/Impute_Experiments/transformers.py", line 751, in normalization
    min_val[i] = np.nanmin(norm_data[:,i])
  File "/home/ketrong/miniconda3/envs/tpot2devenv/lib/python3.10/site-packages/pandas/core/frame.py", line 3807, in __getitem__
    indexer = self.columns.get_loc(key)
  File "/home/ketrong/miniconda3/envs/tpot2devenv/lib/python3.10/site-packages/pandas/core/indexes/base.py", line 3809, in get_loc
    self._check_indexing_error(key)
  File "/home/ketrong/miniconda3/envs/tpot2devenv/lib/python3.10/site-packages/pandas/core/indexes/base.py", line 5925, in _check_indexing_error
    raise InvalidIndexError(key)
pandas.errors.InvalidIndexError: (slice(None, None, None), 0)
[W 2023-11-28 16:16:54,980] Trial 2 failed with value None.
[W 2023-11-28 16:16:54,964] Trial 1 failed with parameters: {'model_name': 'GAIN', 'batch_size': 16, 'hint_rate': 0.39, 'alpha': 3, 'iterations': 1} because of the following error: InvalidIndexError((slice(None, None, None), 0)).
Traceback (most recent call last):
  File "/home/ketrong/miniconda3/envs/tpot2devenv/lib/python3.10/site-packages/pandas/core/indexes/base.py", line 3802, in get_loc
    return self._engine.get_loc(casted_key)
  File "pandas/_libs/index.pyx", line 138, in pandas._libs.index.IndexEngine.get_loc
  File "pandas/_libs/index.pyx", line 144, in pandas._libs.index.IndexEngine.get_loc
TypeError: '(slice(None, None, None), 0)' is an invalid key

During handling of the above exception, another exception occurred:

Traceback (most recent call last):
  File "/home/ketrong/miniconda3/envs/tpot2devenv/lib/python3.10/site-packages/optuna/study/_optimize.py", line 200, in _run_trial
    value_or_values = func(trial)
  File "/common/ketrong/AutoImputeExp/tpot2_imputetest/Impute_Experiments/autoimpute.py", line 59, in obj
    return autoutils.score(trial, splitting, my_model, X, self.missing_set_train, self.masked_set_train)
  File "/common/ketrong/AutoImputeExp/tpot2_imputetest/Impute_Experiments/autoutils.py", line 62, in score
    imputed = my_model.transform(missing_set)
  File "/home/ketrong/miniconda3/envs/tpot2devenv/lib/python3.10/site-packages/sklearn/utils/_set_output.py", line 157, in wrapped
    data_to_wrap = f(self, X, *args, **kwargs)
  File "/common/ketrong/AutoImputeExp/tpot2_imputetest/Impute_Experiments/transformers.py", line 605, in transform
    return self.gain(X, self.params)
  File "/common/ketrong/AutoImputeExp/tpot2_imputetest/Impute_Experiments/transformers.py", line 636, in gain
    norm_data, norm_parameters = self.normalization(data_x)
  File "/common/ketrong/AutoImputeExp/tpot2_imputetest/Impute_Experiments/transformers.py", line 751, in normalization
    min_val[i] = np.nanmin(norm_data[:,i])
  File "/home/ketrong/miniconda3/envs/tpot2devenv/lib/python3.10/site-packages/pandas/core/frame.py", line 3807, in __getitem__
    indexer = self.columns.get_loc(key)
  File "/home/ketrong/miniconda3/envs/tpot2devenv/lib/python3.10/site-packages/pandas/core/indexes/base.py", line 3809, in get_loc
    self._check_indexing_error(key)
  File "/home/ketrong/miniconda3/envs/tpot2devenv/lib/python3.10/site-packages/pandas/core/indexes/base.py", line 5925, in _check_indexing_error
    raise InvalidIndexError(key)
pandas.errors.InvalidIndexError: (slice(None, None, None), 0)
[W 2023-11-28 16:16:55,190] Trial 1 failed with value None.
[W 2023-11-28 16:16:54,969] Trial 3 failed with parameters: {'model_name': 'GAIN', 'batch_size': 2, 'hint_rate': 0.14, 'alpha': 90, 'iterations': 11} because of the following error: InvalidIndexError((slice(None, None, None), 0)).
Traceback (most recent call last):
  File "/home/ketrong/miniconda3/envs/tpot2devenv/lib/python3.10/site-packages/pandas/core/indexes/base.py", line 3802, in get_loc
    return self._engine.get_loc(casted_key)
  File "pandas/_libs/index.pyx", line 138, in pandas._libs.index.IndexEngine.get_loc
  File "pandas/_libs/index.pyx", line 144, in pandas._libs.index.IndexEngine.get_loc
TypeError: '(slice(None, None, None), 0)' is an invalid key

During handling of the above exception, another exception occurred:

Traceback (most recent call last):
  File "/home/ketrong/miniconda3/envs/tpot2devenv/lib/python3.10/site-packages/optuna/study/_optimize.py", line 200, in _run_trial
    value_or_values = func(trial)
  File "/common/ketrong/AutoImputeExp/tpot2_imputetest/Impute_Experiments/autoimpute.py", line 59, in obj
    return autoutils.score(trial, splitting, my_model, X, self.missing_set_train, self.masked_set_train)
  File "/common/ketrong/AutoImputeExp/tpot2_imputetest/Impute_Experiments/autoutils.py", line 62, in score
    imputed = my_model.transform(missing_set)
  File "/home/ketrong/miniconda3/envs/tpot2devenv/lib/python3.10/site-packages/sklearn/utils/_set_output.py", line 157, in wrapped
    data_to_wrap = f(self, X, *args, **kwargs)
  File "/common/ketrong/AutoImputeExp/tpot2_imputetest/Impute_Experiments/transformers.py", line 605, in transform
    return self.gain(X, self.params)
  File "/common/ketrong/AutoImputeExp/tpot2_imputetest/Impute_Experiments/transformers.py", line 636, in gain
    norm_data, norm_parameters = self.normalization(data_x)
  File "/common/ketrong/AutoImputeExp/tpot2_imputetest/Impute_Experiments/transformers.py", line 751, in normalization
    min_val[i] = np.nanmin(norm_data[:,i])
  File "/home/ketrong/miniconda3/envs/tpot2devenv/lib/python3.10/site-packages/pandas/core/frame.py", line 3807, in __getitem__
    indexer = self.columns.get_loc(key)
  File "/home/ketrong/miniconda3/envs/tpot2devenv/lib/python3.10/site-packages/pandas/core/indexes/base.py", line 3809, in get_loc
    self._check_indexing_error(key)
  File "/home/ketrong/miniconda3/envs/tpot2devenv/lib/python3.10/site-packages/pandas/core/indexes/base.py", line 5925, in _check_indexing_error
    raise InvalidIndexError(key)
pandas.errors.InvalidIndexError: (slice(None, None, None), 0)
[W 2023-11-28 16:16:55,335] Trial 3 failed with value None.
[W 2023-11-28 16:16:54,973] Trial 5 failed with parameters: {'model_name': 'GAIN', 'batch_size': 264, 'hint_rate': 0.89, 'alpha': 84, 'iterations': 25} because of the following error: InvalidIndexError((slice(None, None, None), 0)).
Traceback (most recent call last):
  File "/home/ketrong/miniconda3/envs/tpot2devenv/lib/python3.10/site-packages/pandas/core/indexes/base.py", line 3802, in get_loc
    return self._engine.get_loc(casted_key)
  File "pandas/_libs/index.pyx", line 138, in pandas._libs.index.IndexEngine.get_loc
  File "pandas/_libs/index.pyx", line 144, in pandas._libs.index.IndexEngine.get_loc
TypeError: '(slice(None, None, None), 0)' is an invalid key

During handling of the above exception, another exception occurred:

Traceback (most recent call last):
  File "/home/ketrong/miniconda3/envs/tpot2devenv/lib/python3.10/site-packages/optuna/study/_optimize.py", line 200, in _run_trial
    value_or_values = func(trial)
  File "/common/ketrong/AutoImputeExp/tpot2_imputetest/Impute_Experiments/autoimpute.py", line 59, in obj
    return autoutils.score(trial, splitting, my_model, X, self.missing_set_train, self.masked_set_train)
  File "/common/ketrong/AutoImputeExp/tpot2_imputetest/Impute_Experiments/autoutils.py", line 62, in score
    imputed = my_model.transform(missing_set)
  File "/home/ketrong/miniconda3/envs/tpot2devenv/lib/python3.10/site-packages/sklearn/utils/_set_output.py", line 157, in wrapped
    data_to_wrap = f(self, X, *args, **kwargs)
  File "/common/ketrong/AutoImputeExp/tpot2_imputetest/Impute_Experiments/transformers.py", line 605, in transform
    return self.gain(X, self.params)
  File "/common/ketrong/AutoImputeExp/tpot2_imputetest/Impute_Experiments/transformers.py", line 636, in gain
    norm_data, norm_parameters = self.normalization(data_x)
  File "/common/ketrong/AutoImputeExp/tpot2_imputetest/Impute_Experiments/transformers.py", line 751, in normalization
    min_val[i] = np.nanmin(norm_data[:,i])
  File "/home/ketrong/miniconda3/envs/tpot2devenv/lib/python3.10/site-packages/pandas/core/frame.py", line 3807, in __getitem__
    indexer = self.columns.get_loc(key)
  File "/home/ketrong/miniconda3/envs/tpot2devenv/lib/python3.10/site-packages/pandas/core/indexes/base.py", line 3809, in get_loc
    self._check_indexing_error(key)
  File "/home/ketrong/miniconda3/envs/tpot2devenv/lib/python3.10/site-packages/pandas/core/indexes/base.py", line 5925, in _check_indexing_error
    raise InvalidIndexError(key)
pandas.errors.InvalidIndexError: (slice(None, None, None), 0)
[W 2023-11-28 16:16:55,484] Trial 5 failed with value None.
[W 2023-11-28 16:16:54,976] Trial 7 failed with parameters: {'model_name': 'GAIN', 'batch_size': 3, 'hint_rate': 0.66, 'alpha': 83, 'iterations': 4} because of the following error: InvalidIndexError((slice(None, None, None), 0)).
Traceback (most recent call last):
  File "/home/ketrong/miniconda3/envs/tpot2devenv/lib/python3.10/site-packages/pandas/core/indexes/base.py", line 3802, in get_loc
    return self._engine.get_loc(casted_key)
  File "pandas/_libs/index.pyx", line 138, in pandas._libs.index.IndexEngine.get_loc
  File "pandas/_libs/index.pyx", line 144, in pandas._libs.index.IndexEngine.get_loc
TypeError: '(slice(None, None, None), 0)' is an invalid key

During handling of the above exception, another exception occurred:

Traceback (most recent call last):
  File "/home/ketrong/miniconda3/envs/tpot2devenv/lib/python3.10/site-packages/optuna/study/_optimize.py", line 200, in _run_trial
    value_or_values = func(trial)
  File "/common/ketrong/AutoImputeExp/tpot2_imputetest/Impute_Experiments/autoimpute.py", line 59, in obj
    return autoutils.score(trial, splitting, my_model, X, self.missing_set_train, self.masked_set_train)
  File "/common/ketrong/AutoImputeExp/tpot2_imputetest/Impute_Experiments/autoutils.py", line 62, in score
    imputed = my_model.transform(missing_set)
  File "/home/ketrong/miniconda3/envs/tpot2devenv/lib/python3.10/site-packages/sklearn/utils/_set_output.py", line 157, in wrapped
    data_to_wrap = f(self, X, *args, **kwargs)
  File "/common/ketrong/AutoImputeExp/tpot2_imputetest/Impute_Experiments/transformers.py", line 605, in transform
    return self.gain(X, self.params)
  File "/common/ketrong/AutoImputeExp/tpot2_imputetest/Impute_Experiments/transformers.py", line 636, in gain
    norm_data, norm_parameters = self.normalization(data_x)
  File "/common/ketrong/AutoImputeExp/tpot2_imputetest/Impute_Experiments/transformers.py", line 751, in normalization
    min_val[i] = np.nanmin(norm_data[:,i])
  File "/home/ketrong/miniconda3/envs/tpot2devenv/lib/python3.10/site-packages/pandas/core/frame.py", line 3807, in __getitem__
    indexer = self.columns.get_loc(key)
  File "/home/ketrong/miniconda3/envs/tpot2devenv/lib/python3.10/site-packages/pandas/core/indexes/base.py", line 3809, in get_loc
    self._check_indexing_error(key)
  File "/home/ketrong/miniconda3/envs/tpot2devenv/lib/python3.10/site-packages/pandas/core/indexes/base.py", line 5925, in _check_indexing_error
    raise InvalidIndexError(key)
pandas.errors.InvalidIndexError: (slice(None, None, None), 0)
[W 2023-11-28 16:16:54,965] Trial 0 failed with parameters: {'model_name': 'GAIN', 'batch_size': 1, 'hint_rate': 0.18000000000000002, 'alpha': 80, 'iterations': 702} because of the following error: InvalidIndexError((slice(None, None, None), 0)).
Traceback (most recent call last):
  File "/home/ketrong/miniconda3/envs/tpot2devenv/lib/python3.10/site-packages/pandas/core/indexes/base.py", line 3802, in get_loc
    return self._engine.get_loc(casted_key)
  File "pandas/_libs/index.pyx", line 138, in pandas._libs.index.IndexEngine.get_loc
  File "pandas/_libs/index.pyx", line 144, in pandas._libs.index.IndexEngine.get_loc
TypeError: '(slice(None, None, None), 0)' is an invalid key

During handling of the above exception, another exception occurred:

Traceback (most recent call last):
  File "/home/ketrong/miniconda3/envs/tpot2devenv/lib/python3.10/site-packages/optuna/study/_optimize.py", line 200, in _run_trial
    value_or_values = func(trial)
  File "/common/ketrong/AutoImputeExp/tpot2_imputetest/Impute_Experiments/autoimpute.py", line 59, in obj
    return autoutils.score(trial, splitting, my_model, X, self.missing_set_train, self.masked_set_train)
  File "/common/ketrong/AutoImputeExp/tpot2_imputetest/Impute_Experiments/autoutils.py", line 62, in score
    imputed = my_model.transform(missing_set)
  File "/home/ketrong/miniconda3/envs/tpot2devenv/lib/python3.10/site-packages/sklearn/utils/_set_output.py", line 157, in wrapped
    data_to_wrap = f(self, X, *args, **kwargs)
  File "/common/ketrong/AutoImputeExp/tpot2_imputetest/Impute_Experiments/transformers.py", line 605, in transform
    return self.gain(X, self.params)
  File "/common/ketrong/AutoImputeExp/tpot2_imputetest/Impute_Experiments/transformers.py", line 636, in gain
    norm_data, norm_parameters = self.normalization(data_x)
  File "/common/ketrong/AutoImputeExp/tpot2_imputetest/Impute_Experiments/transformers.py", line 751, in normalization
    min_val[i] = np.nanmin(norm_data[:,i])
  File "/home/ketrong/miniconda3/envs/tpot2devenv/lib/python3.10/site-packages/pandas/core/frame.py", line 3807, in __getitem__
    indexer = self.columns.get_loc(key)
  File "/home/ketrong/miniconda3/envs/tpot2devenv/lib/python3.10/site-packages/pandas/core/indexes/base.py", line 3809, in get_loc
    self._check_indexing_error(key)
  File "/home/ketrong/miniconda3/envs/tpot2devenv/lib/python3.10/site-packages/pandas/core/indexes/base.py", line 5925, in _check_indexing_error
    raise InvalidIndexError(key)
pandas.errors.InvalidIndexError: (slice(None, None, None), 0)
[W 2023-11-28 16:16:55,690] Trial 0 failed with value None.
[W 2023-11-28 16:16:54,969] Trial 4 failed with parameters: {'model_name': 'GAIN', 'batch_size': 186, 'hint_rate': 0.93, 'alpha': 50, 'iterations': 6342} because of the following error: InvalidIndexError((slice(None, None, None), 0)).
Traceback (most recent call last):
  File "/home/ketrong/miniconda3/envs/tpot2devenv/lib/python3.10/site-packages/pandas/core/indexes/base.py", line 3802, in get_loc
    return self._engine.get_loc(casted_key)
  File "pandas/_libs/index.pyx", line 138, in pandas._libs.index.IndexEngine.get_loc
  File "pandas/_libs/index.pyx", line 144, in pandas._libs.index.IndexEngine.get_loc
TypeError: '(slice(None, None, None), 0)' is an invalid key

During handling of the above exception, another exception occurred:

Traceback (most recent call last):
  File "/home/ketrong/miniconda3/envs/tpot2devenv/lib/python3.10/site-packages/optuna/study/_optimize.py", line 200, in _run_trial
    value_or_values = func(trial)
  File "/common/ketrong/AutoImputeExp/tpot2_imputetest/Impute_Experiments/autoimpute.py", line 59, in obj
    return autoutils.score(trial, splitting, my_model, X, self.missing_set_train, self.masked_set_train)
  File "/common/ketrong/AutoImputeExp/tpot2_imputetest/Impute_Experiments/autoutils.py", line 62, in score
    imputed = my_model.transform(missing_set)
  File "/home/ketrong/miniconda3/envs/tpot2devenv/lib/python3.10/site-packages/sklearn/utils/_set_output.py", line 157, in wrapped
    data_to_wrap = f(self, X, *args, **kwargs)
  File "/common/ketrong/AutoImputeExp/tpot2_imputetest/Impute_Experiments/transformers.py", line 605, in transform
    return self.gain(X, self.params)
  File "/common/ketrong/AutoImputeExp/tpot2_imputetest/Impute_Experiments/transformers.py", line 636, in gain
    norm_data, norm_parameters = self.normalization(data_x)
  File "/common/ketrong/AutoImputeExp/tpot2_imputetest/Impute_Experiments/transformers.py", line 751, in normalization
    min_val[i] = np.nanmin(norm_data[:,i])
  File "/home/ketrong/miniconda3/envs/tpot2devenv/lib/python3.10/site-packages/pandas/core/frame.py", line 3807, in __getitem__
    indexer = self.columns.get_loc(key)
  File "/home/ketrong/miniconda3/envs/tpot2devenv/lib/python3.10/site-packages/pandas/core/indexes/base.py", line 3809, in get_loc
    self._check_indexing_error(key)
  File "/home/ketrong/miniconda3/envs/tpot2devenv/lib/python3.10/site-packages/pandas/core/indexes/base.py", line 5925, in _check_indexing_error
    raise InvalidIndexError(key)
pandas.errors.InvalidIndexError: (slice(None, None, None), 0)
[W 2023-11-28 16:16:55,892] Trial 4 failed with value None.
[W 2023-11-28 16:16:54,976] Trial 6 failed with parameters: {'model_name': 'GAIN', 'batch_size': 1, 'hint_rate': 0.86, 'alpha': 61, 'iterations': 1} because of the following error: InvalidIndexError((slice(None, None, None), 0)).
Traceback (most recent call last):
  File "/home/ketrong/miniconda3/envs/tpot2devenv/lib/python3.10/site-packages/pandas/core/indexes/base.py", line 3802, in get_loc
    return self._engine.get_loc(casted_key)
  File "pandas/_libs/index.pyx", line 138, in pandas._libs.index.IndexEngine.get_loc
  File "pandas/_libs/index.pyx", line 144, in pandas._libs.index.IndexEngine.get_loc
TypeError: '(slice(None, None, None), 0)' is an invalid key

During handling of the above exception, another exception occurred:

Traceback (most recent call last):
  File "/home/ketrong/miniconda3/envs/tpot2devenv/lib/python3.10/site-packages/optuna/study/_optimize.py", line 200, in _run_trial
    value_or_values = func(trial)
  File "/common/ketrong/AutoImputeExp/tpot2_imputetest/Impute_Experiments/autoimpute.py", line 59, in obj
    return autoutils.score(trial, splitting, my_model, X, self.missing_set_train, self.masked_set_train)
  File "/common/ketrong/AutoImputeExp/tpot2_imputetest/Impute_Experiments/autoutils.py", line 62, in score
    imputed = my_model.transform(missing_set)
  File "/home/ketrong/miniconda3/envs/tpot2devenv/lib/python3.10/site-packages/sklearn/utils/_set_output.py", line 157, in wrapped
    data_to_wrap = f(self, X, *args, **kwargs)
  File "/common/ketrong/AutoImputeExp/tpot2_imputetest/Impute_Experiments/transformers.py", line 605, in transform
    return self.gain(X, self.params)
  File "/common/ketrong/AutoImputeExp/tpot2_imputetest/Impute_Experiments/transformers.py", line 636, in gain
    norm_data, norm_parameters = self.normalization(data_x)
  File "/common/ketrong/AutoImputeExp/tpot2_imputetest/Impute_Experiments/transformers.py", line 751, in normalization
    min_val[i] = np.nanmin(norm_data[:,i])
  File "/home/ketrong/miniconda3/envs/tpot2devenv/lib/python3.10/site-packages/pandas/core/frame.py", line 3807, in __getitem__
    indexer = self.columns.get_loc(key)
  File "/home/ketrong/miniconda3/envs/tpot2devenv/lib/python3.10/site-packages/pandas/core/indexes/base.py", line 3809, in get_loc
    self._check_indexing_error(key)
  File "/home/ketrong/miniconda3/envs/tpot2devenv/lib/python3.10/site-packages/pandas/core/indexes/base.py", line 5925, in _check_indexing_error
    raise InvalidIndexError(key)
pandas.errors.InvalidIndexError: (slice(None, None, None), 0)
[W 2023-11-28 16:16:56,038] Trial 6 failed with value None.
[W 2023-11-28 16:16:55,687] Trial 7 failed with value None.
[W 2023-11-28 16:16:55,689] Trial 11 failed with parameters: {'model_name': 'GAIN', 'batch_size': 343, 'hint_rate': 0.73, 'alpha': 45, 'iterations': 1} because of the following error: InvalidIndexError((slice(None, None, None), 0)).
Traceback (most recent call last):
  File "/home/ketrong/miniconda3/envs/tpot2devenv/lib/python3.10/site-packages/pandas/core/indexes/base.py", line 3802, in get_loc
    return self._engine.get_loc(casted_key)
  File "pandas/_libs/index.pyx", line 138, in pandas._libs.index.IndexEngine.get_loc
  File "pandas/_libs/index.pyx", line 144, in pandas._libs.index.IndexEngine.get_loc
TypeError: '(slice(None, None, None), 0)' is an invalid key

During handling of the above exception, another exception occurred:

Traceback (most recent call last):
  File "/home/ketrong/miniconda3/envs/tpot2devenv/lib/python3.10/site-packages/optuna/study/_optimize.py", line 200, in _run_trial
    value_or_values = func(trial)
  File "/common/ketrong/AutoImputeExp/tpot2_imputetest/Impute_Experiments/autoimpute.py", line 59, in obj
    return autoutils.score(trial, splitting, my_model, X, self.missing_set_train, self.masked_set_train)
  File "/common/ketrong/AutoImputeExp/tpot2_imputetest/Impute_Experiments/autoutils.py", line 62, in score
    imputed = my_model.transform(missing_set)
  File "/home/ketrong/miniconda3/envs/tpot2devenv/lib/python3.10/site-packages/sklearn/utils/_set_output.py", line 157, in wrapped
    data_to_wrap = f(self, X, *args, **kwargs)
  File "/common/ketrong/AutoImputeExp/tpot2_imputetest/Impute_Experiments/transformers.py", line 605, in transform
    return self.gain(X, self.params)
  File "/common/ketrong/AutoImputeExp/tpot2_imputetest/Impute_Experiments/transformers.py", line 636, in gain
    norm_data, norm_parameters = self.normalization(data_x)
  File "/common/ketrong/AutoImputeExp/tpot2_imputetest/Impute_Experiments/transformers.py", line 751, in normalization
    min_val[i] = np.nanmin(norm_data[:,i])
  File "/home/ketrong/miniconda3/envs/tpot2devenv/lib/python3.10/site-packages/pandas/core/frame.py", line 3807, in __getitem__
    indexer = self.columns.get_loc(key)
  File "/home/ketrong/miniconda3/envs/tpot2devenv/lib/python3.10/site-packages/pandas/core/indexes/base.py", line 3809, in get_loc
    self._check_indexing_error(key)
  File "/home/ketrong/miniconda3/envs/tpot2devenv/lib/python3.10/site-packages/pandas/core/indexes/base.py", line 5925, in _check_indexing_error
    raise InvalidIndexError(key)
pandas.errors.InvalidIndexError: (slice(None, None, None), 0)
[W 2023-11-28 16:16:56,331] Trial 11 failed with value None.
[W 2023-11-28 16:16:55,891] Trial 13 failed with parameters: {'model_name': 'GAIN', 'batch_size': 457, 'hint_rate': 0.86, 'alpha': 79, 'iterations': 9759} because of the following error: InvalidIndexError((slice(None, None, None), 0)).
Traceback (most recent call last):
  File "/home/ketrong/miniconda3/envs/tpot2devenv/lib/python3.10/site-packages/pandas/core/indexes/base.py", line 3802, in get_loc
    return self._engine.get_loc(casted_key)
  File "pandas/_libs/index.pyx", line 138, in pandas._libs.index.IndexEngine.get_loc
  File "pandas/_libs/index.pyx", line 144, in pandas._libs.index.IndexEngine.get_loc
TypeError: '(slice(None, None, None), 0)' is an invalid key

During handling of the above exception, another exception occurred:

Traceback (most recent call last):
  File "/home/ketrong/miniconda3/envs/tpot2devenv/lib/python3.10/site-packages/optuna/study/_optimize.py", line 200, in _run_trial
    value_or_values = func(trial)
  File "/common/ketrong/AutoImputeExp/tpot2_imputetest/Impute_Experiments/autoimpute.py", line 59, in obj
    return autoutils.score(trial, splitting, my_model, X, self.missing_set_train, self.masked_set_train)
  File "/common/ketrong/AutoImputeExp/tpot2_imputetest/Impute_Experiments/autoutils.py", line 62, in score
    imputed = my_model.transform(missing_set)
  File "/home/ketrong/miniconda3/envs/tpot2devenv/lib/python3.10/site-packages/sklearn/utils/_set_output.py", line 157, in wrapped
    data_to_wrap = f(self, X, *args, **kwargs)
  File "/common/ketrong/AutoImputeExp/tpot2_imputetest/Impute_Experiments/transformers.py", line 605, in transform
    return self.gain(X, self.params)
  File "/common/ketrong/AutoImputeExp/tpot2_imputetest/Impute_Experiments/transformers.py", line 636, in gain
    norm_data, norm_parameters = self.normalization(data_x)
  File "/common/ketrong/AutoImputeExp/tpot2_imputetest/Impute_Experiments/transformers.py", line 751, in normalization
    min_val[i] = np.nanmin(norm_data[:,i])
  File "/home/ketrong/miniconda3/envs/tpot2devenv/lib/python3.10/site-packages/pandas/core/frame.py", line 3807, in __getitem__
    indexer = self.columns.get_loc(key)
  File "/home/ketrong/miniconda3/envs/tpot2devenv/lib/python3.10/site-packages/pandas/core/indexes/base.py", line 3809, in get_loc
    self._check_indexing_error(key)
  File "/home/ketrong/miniconda3/envs/tpot2devenv/lib/python3.10/site-packages/pandas/core/indexes/base.py", line 5925, in _check_indexing_error
    raise InvalidIndexError(key)
pandas.errors.InvalidIndexError: (slice(None, None, None), 0)
[W 2023-11-28 16:16:56,485] Trial 13 failed with value None.
[W 2023-11-28 16:16:55,891] Trial 14 failed with parameters: {'model_name': 'GAIN', 'batch_size': 2, 'hint_rate': 0.02, 'alpha': 72, 'iterations': 73} because of the following error: InvalidIndexError((slice(None, None, None), 0)).
Traceback (most recent call last):
  File "/home/ketrong/miniconda3/envs/tpot2devenv/lib/python3.10/site-packages/pandas/core/indexes/base.py", line 3802, in get_loc
    return self._engine.get_loc(casted_key)
  File "pandas/_libs/index.pyx", line 138, in pandas._libs.index.IndexEngine.get_loc
  File "pandas/_libs/index.pyx", line 144, in pandas._libs.index.IndexEngine.get_loc
TypeError: '(slice(None, None, None), 0)' is an invalid key

During handling of the above exception, another exception occurred:

Traceback (most recent call last):
  File "/home/ketrong/miniconda3/envs/tpot2devenv/lib/python3.10/site-packages/optuna/study/_optimize.py", line 200, in _run_trial
    value_or_values = func(trial)
  File "/common/ketrong/AutoImputeExp/tpot2_imputetest/Impute_Experiments/autoimpute.py", line 59, in obj
    return autoutils.score(trial, splitting, my_model, X, self.missing_set_train, self.masked_set_train)
  File "/common/ketrong/AutoImputeExp/tpot2_imputetest/Impute_Experiments/autoutils.py", line 62, in score
    imputed = my_model.transform(missing_set)
  File "/home/ketrong/miniconda3/envs/tpot2devenv/lib/python3.10/site-packages/sklearn/utils/_set_output.py", line 157, in wrapped
    data_to_wrap = f(self, X, *args, **kwargs)
  File "/common/ketrong/AutoImputeExp/tpot2_imputetest/Impute_Experiments/transformers.py", line 605, in transform
    return self.gain(X, self.params)
  File "/common/ketrong/AutoImputeExp/tpot2_imputetest/Impute_Experiments/transformers.py", line 636, in gain
    norm_data, norm_parameters = self.normalization(data_x)
  File "/common/ketrong/AutoImputeExp/tpot2_imputetest/Impute_Experiments/transformers.py", line 751, in normalization
    min_val[i] = np.nanmin(norm_data[:,i])
  File "/home/ketrong/miniconda3/envs/tpot2devenv/lib/python3.10/site-packages/pandas/core/frame.py", line 3807, in __getitem__
    indexer = self.columns.get_loc(key)
  File "/home/ketrong/miniconda3/envs/tpot2devenv/lib/python3.10/site-packages/pandas/core/indexes/base.py", line 3809, in get_loc
    self._check_indexing_error(key)
  File "/home/ketrong/miniconda3/envs/tpot2devenv/lib/python3.10/site-packages/pandas/core/indexes/base.py", line 5925, in _check_indexing_error
    raise InvalidIndexError(key)
pandas.errors.InvalidIndexError: (slice(None, None, None), 0)
[W 2023-11-28 16:16:55,480] Trial 10 failed with parameters: {'model_name': 'GAIN', 'batch_size': 1, 'hint_rate': 0.02, 'alpha': 57, 'iterations': 11} because of the following error: InvalidIndexError((slice(None, None, None), 0)).
Traceback (most recent call last):
  File "/home/ketrong/miniconda3/envs/tpot2devenv/lib/python3.10/site-packages/pandas/core/indexes/base.py", line 3802, in get_loc
    return self._engine.get_loc(casted_key)
  File "pandas/_libs/index.pyx", line 138, in pandas._libs.index.IndexEngine.get_loc
  File "pandas/_libs/index.pyx", line 144, in pandas._libs.index.IndexEngine.get_loc
TypeError: '(slice(None, None, None), 0)' is an invalid key

During handling of the above exception, another exception occurred:

Traceback (most recent call last):
  File "/home/ketrong/miniconda3/envs/tpot2devenv/lib/python3.10/site-packages/optuna/study/_optimize.py", line 200, in _run_trial
    value_or_values = func(trial)
  File "/common/ketrong/AutoImputeExp/tpot2_imputetest/Impute_Experiments/autoimpute.py", line 59, in obj
    return autoutils.score(trial, splitting, my_model, X, self.missing_set_train, self.masked_set_train)
  File "/common/ketrong/AutoImputeExp/tpot2_imputetest/Impute_Experiments/autoutils.py", line 62, in score
    imputed = my_model.transform(missing_set)
  File "/home/ketrong/miniconda3/envs/tpot2devenv/lib/python3.10/site-packages/sklearn/utils/_set_output.py", line 157, in wrapped
    data_to_wrap = f(self, X, *args, **kwargs)
  File "/common/ketrong/AutoImputeExp/tpot2_imputetest/Impute_Experiments/transformers.py", line 605, in transform
    return self.gain(X, self.params)
  File "/common/ketrong/AutoImputeExp/tpot2_imputetest/Impute_Experiments/transformers.py", line 636, in gain
    norm_data, norm_parameters = self.normalization(data_x)
  File "/common/ketrong/AutoImputeExp/tpot2_imputetest/Impute_Experiments/transformers.py", line 751, in normalization
    min_val[i] = np.nanmin(norm_data[:,i])
  File "/home/ketrong/miniconda3/envs/tpot2devenv/lib/python3.10/site-packages/pandas/core/frame.py", line 3807, in __getitem__
    indexer = self.columns.get_loc(key)
  File "/home/ketrong/miniconda3/envs/tpot2devenv/lib/python3.10/site-packages/pandas/core/indexes/base.py", line 3809, in get_loc
    self._check_indexing_error(key)
  File "/home/ketrong/miniconda3/envs/tpot2devenv/lib/python3.10/site-packages/pandas/core/indexes/base.py", line 5925, in _check_indexing_error
    raise InvalidIndexError(key)
pandas.errors.InvalidIndexError: (slice(None, None, None), 0)
[W 2023-11-28 16:16:56,649] Trial 10 failed with value None.
[W 2023-11-28 16:16:54,980] Trial 9 failed with parameters: {'model_name': 'GAIN', 'batch_size': 6, 'hint_rate': 0.08, 'alpha': 15, 'iterations': 3308} because of the following error: InvalidIndexError((slice(None, None, None), 0)).
Traceback (most recent call last):
  File "/home/ketrong/miniconda3/envs/tpot2devenv/lib/python3.10/site-packages/pandas/core/indexes/base.py", line 3802, in get_loc
    return self._engine.get_loc(casted_key)
  File "pandas/_libs/index.pyx", line 138, in pandas._libs.index.IndexEngine.get_loc
  File "pandas/_libs/index.pyx", line 144, in pandas._libs.index.IndexEngine.get_loc
TypeError: '(slice(None, None, None), 0)' is an invalid key

During handling of the above exception, another exception occurred:

Traceback (most recent call last):
  File "/home/ketrong/miniconda3/envs/tpot2devenv/lib/python3.10/site-packages/optuna/study/_optimize.py", line 200, in _run_trial
    value_or_values = func(trial)
  File "/common/ketrong/AutoImputeExp/tpot2_imputetest/Impute_Experiments/autoimpute.py", line 59, in obj
    return autoutils.score(trial, splitting, my_model, X, self.missing_set_train, self.masked_set_train)
  File "/common/ketrong/AutoImputeExp/tpot2_imputetest/Impute_Experiments/autoutils.py", line 62, in score
    imputed = my_model.transform(missing_set)
  File "/home/ketrong/miniconda3/envs/tpot2devenv/lib/python3.10/site-packages/sklearn/utils/_set_output.py", line 157, in wrapped
    data_to_wrap = f(self, X, *args, **kwargs)
  File "/common/ketrong/AutoImputeExp/tpot2_imputetest/Impute_Experiments/transformers.py", line 605, in transform
    return self.gain(X, self.params)
  File "/common/ketrong/AutoImputeExp/tpot2_imputetest/Impute_Experiments/transformers.py", line 636, in gain
    norm_data, norm_parameters = self.normalization(data_x)
  File "/common/ketrong/AutoImputeExp/tpot2_imputetest/Impute_Experiments/transformers.py", line 751, in normalization
    min_val[i] = np.nanmin(norm_data[:,i])
  File "/home/ketrong/miniconda3/envs/tpot2devenv/lib/python3.10/site-packages/pandas/core/frame.py", line 3807, in __getitem__
    indexer = self.columns.get_loc(key)
  File "/home/ketrong/miniconda3/envs/tpot2devenv/lib/python3.10/site-packages/pandas/core/indexes/base.py", line 3809, in get_loc
    self._check_indexing_error(key)
  File "/home/ketrong/miniconda3/envs/tpot2devenv/lib/python3.10/site-packages/pandas/core/indexes/base.py", line 5925, in _check_indexing_error
    raise InvalidIndexError(key)
pandas.errors.InvalidIndexError: (slice(None, None, None), 0)
[W 2023-11-28 16:16:56,802] Trial 9 failed with value None.
[W 2023-11-28 16:16:56,330] Trial 16 failed with parameters: {'model_name': 'GAIN', 'batch_size': 1, 'hint_rate': 0.86, 'alpha': 87, 'iterations': 7608} because of the following error: InvalidIndexError((slice(None, None, None), 0)).
Traceback (most recent call last):
  File "/home/ketrong/miniconda3/envs/tpot2devenv/lib/python3.10/site-packages/pandas/core/indexes/base.py", line 3802, in get_loc
    return self._engine.get_loc(casted_key)
  File "pandas/_libs/index.pyx", line 138, in pandas._libs.index.IndexEngine.get_loc
  File "pandas/_libs/index.pyx", line 144, in pandas._libs.index.IndexEngine.get_loc
TypeError: '(slice(None, None, None), 0)' is an invalid key

During handling of the above exception, another exception occurred:

Traceback (most recent call last):
  File "/home/ketrong/miniconda3/envs/tpot2devenv/lib/python3.10/site-packages/optuna/study/_optimize.py", line 200, in _run_trial
    value_or_values = func(trial)
  File "/common/ketrong/AutoImputeExp/tpot2_imputetest/Impute_Experiments/autoimpute.py", line 59, in obj
    return autoutils.score(trial, splitting, my_model, X, self.missing_set_train, self.masked_set_train)
  File "/common/ketrong/AutoImputeExp/tpot2_imputetest/Impute_Experiments/autoutils.py", line 62, in score
    imputed = my_model.transform(missing_set)
  File "/home/ketrong/miniconda3/envs/tpot2devenv/lib/python3.10/site-packages/sklearn/utils/_set_output.py", line 157, in wrapped
    data_to_wrap = f(self, X, *args, **kwargs)
  File "/common/ketrong/AutoImputeExp/tpot2_imputetest/Impute_Experiments/transformers.py", line 605, in transform
    return self.gain(X, self.params)
  File "/common/ketrong/AutoImputeExp/tpot2_imputetest/Impute_Experiments/transformers.py", line 636, in gain
    norm_data, norm_parameters = self.normalization(data_x)
  File "/common/ketrong/AutoImputeExp/tpot2_imputetest/Impute_Experiments/transformers.py", line 751, in normalization
    min_val[i] = np.nanmin(norm_data[:,i])
  File "/home/ketrong/miniconda3/envs/tpot2devenv/lib/python3.10/site-packages/pandas/core/frame.py", line 3807, in __getitem__
    indexer = self.columns.get_loc(key)
  File "/home/ketrong/miniconda3/envs/tpot2devenv/lib/python3.10/site-packages/pandas/core/indexes/base.py", line 3809, in get_loc
    self._check_indexing_error(key)
  File "/home/ketrong/miniconda3/envs/tpot2devenv/lib/python3.10/site-packages/pandas/core/indexes/base.py", line 5925, in _check_indexing_error
    raise InvalidIndexError(key)
pandas.errors.InvalidIndexError: (slice(None, None, None), 0)
[W 2023-11-28 16:16:56,484] Trial 17 failed with parameters: {'model_name': 'GAIN', 'batch_size': 626, 'hint_rate': 0.85, 'alpha': 17, 'iterations': 84163} because of the following error: InvalidIndexError((slice(None, None, None), 0)).
Traceback (most recent call last):
  File "/home/ketrong/miniconda3/envs/tpot2devenv/lib/python3.10/site-packages/pandas/core/indexes/base.py", line 3802, in get_loc
    return self._engine.get_loc(casted_key)
  File "pandas/_libs/index.pyx", line 138, in pandas._libs.index.IndexEngine.get_loc
  File "pandas/_libs/index.pyx", line 144, in pandas._libs.index.IndexEngine.get_loc
TypeError: '(slice(None, None, None), 0)' is an invalid key

During handling of the above exception, another exception occurred:

Traceback (most recent call last):
  File "/home/ketrong/miniconda3/envs/tpot2devenv/lib/python3.10/site-packages/optuna/study/_optimize.py", line 200, in _run_trial
    value_or_values = func(trial)
  File "/common/ketrong/AutoImputeExp/tpot2_imputetest/Impute_Experiments/autoimpute.py", line 59, in obj
    return autoutils.score(trial, splitting, my_model, X, self.missing_set_train, self.masked_set_train)
  File "/common/ketrong/AutoImputeExp/tpot2_imputetest/Impute_Experiments/autoutils.py", line 62, in score
    imputed = my_model.transform(missing_set)
  File "/home/ketrong/miniconda3/envs/tpot2devenv/lib/python3.10/site-packages/sklearn/utils/_set_output.py", line 157, in wrapped
    data_to_wrap = f(self, X, *args, **kwargs)
  File "/common/ketrong/AutoImputeExp/tpot2_imputetest/Impute_Experiments/transformers.py", line 605, in transform
    return self.gain(X, self.params)
  File "/common/ketrong/AutoImputeExp/tpot2_imputetest/Impute_Experiments/transformers.py", line 636, in gain
    norm_data, norm_parameters = self.normalization(data_x)
  File "/common/ketrong/AutoImputeExp/tpot2_imputetest/Impute_Experiments/transformers.py", line 751, in normalization
    min_val[i] = np.nanmin(norm_data[:,i])
  File "/home/ketrong/miniconda3/envs/tpot2devenv/lib/python3.10/site-packages/pandas/core/frame.py", line 3807, in __getitem__
    indexer = self.columns.get_loc(key)
  File "/home/ketrong/miniconda3/envs/tpot2devenv/lib/python3.10/site-packages/pandas/core/indexes/base.py", line 3809, in get_loc
    self._check_indexing_error(key)
  File "/home/ketrong/miniconda3/envs/tpot2devenv/lib/python3.10/site-packages/pandas/core/indexes/base.py", line 5925, in _check_indexing_error
    raise InvalidIndexError(key)
pandas.errors.InvalidIndexError: (slice(None, None, None), 0)
[W 2023-11-28 16:16:56,950] Trial 17 failed with value None.
[W 2023-11-28 16:16:55,892] Trial 12 failed with parameters: {'model_name': 'GAIN', 'batch_size': 329, 'hint_rate': 0.21000000000000002, 'alpha': 44, 'iterations': 2} because of the following error: InvalidIndexError((slice(None, None, None), 0)).
Traceback (most recent call last):
  File "/home/ketrong/miniconda3/envs/tpot2devenv/lib/python3.10/site-packages/pandas/core/indexes/base.py", line 3802, in get_loc
    return self._engine.get_loc(casted_key)
  File "pandas/_libs/index.pyx", line 138, in pandas._libs.index.IndexEngine.get_loc
  File "pandas/_libs/index.pyx", line 144, in pandas._libs.index.IndexEngine.get_loc
TypeError: '(slice(None, None, None), 0)' is an invalid key

During handling of the above exception, another exception occurred:

Traceback (most recent call last):
  File "/home/ketrong/miniconda3/envs/tpot2devenv/lib/python3.10/site-packages/optuna/study/_optimize.py", line 200, in _run_trial
    value_or_values = func(trial)
  File "/common/ketrong/AutoImputeExp/tpot2_imputetest/Impute_Experiments/autoimpute.py", line 59, in obj
    return autoutils.score(trial, splitting, my_model, X, self.missing_set_train, self.masked_set_train)
  File "/common/ketrong/AutoImputeExp/tpot2_imputetest/Impute_Experiments/autoutils.py", line 62, in score
    imputed = my_model.transform(missing_set)
  File "/home/ketrong/miniconda3/envs/tpot2devenv/lib/python3.10/site-packages/sklearn/utils/_set_output.py", line 157, in wrapped
    data_to_wrap = f(self, X, *args, **kwargs)
  File "/common/ketrong/AutoImputeExp/tpot2_imputetest/Impute_Experiments/transformers.py", line 605, in transform
    return self.gain(X, self.params)
  File "/common/ketrong/AutoImputeExp/tpot2_imputetest/Impute_Experiments/transformers.py", line 636, in gain
    norm_data, norm_parameters = self.normalization(data_x)
  File "/common/ketrong/AutoImputeExp/tpot2_imputetest/Impute_Experiments/transformers.py", line 751, in normalization
    min_val[i] = np.nanmin(norm_data[:,i])
  File "/home/ketrong/miniconda3/envs/tpot2devenv/lib/python3.10/site-packages/pandas/core/frame.py", line 3807, in __getitem__
    indexer = self.columns.get_loc(key)
  File "/home/ketrong/miniconda3/envs/tpot2devenv/lib/python3.10/site-packages/pandas/core/indexes/base.py", line 3809, in get_loc
    self._check_indexing_error(key)
  File "/home/ketrong/miniconda3/envs/tpot2devenv/lib/python3.10/site-packages/pandas/core/indexes/base.py", line 5925, in _check_indexing_error
    raise InvalidIndexError(key)
pandas.errors.InvalidIndexError: (slice(None, None, None), 0)
[W 2023-11-28 16:16:57,098] Trial 12 failed with value None.
[W 2023-11-28 16:16:56,636] Trial 20 failed with parameters: {'model_name': 'GAIN', 'batch_size': 2, 'hint_rate': 0.33, 'alpha': 84, 'iterations': 4} because of the following error: InvalidIndexError((slice(None, None, None), 0)).
Traceback (most recent call last):
  File "/home/ketrong/miniconda3/envs/tpot2devenv/lib/python3.10/site-packages/pandas/core/indexes/base.py", line 3802, in get_loc
    return self._engine.get_loc(casted_key)
  File "pandas/_libs/index.pyx", line 138, in pandas._libs.index.IndexEngine.get_loc
  File "pandas/_libs/index.pyx", line 144, in pandas._libs.index.IndexEngine.get_loc
TypeError: '(slice(None, None, None), 0)' is an invalid key

During handling of the above exception, another exception occurred:

Traceback (most recent call last):
  File "/home/ketrong/miniconda3/envs/tpot2devenv/lib/python3.10/site-packages/optuna/study/_optimize.py", line 200, in _run_trial
    value_or_values = func(trial)
  File "/common/ketrong/AutoImputeExp/tpot2_imputetest/Impute_Experiments/autoimpute.py", line 59, in obj
    return autoutils.score(trial, splitting, my_model, X, self.missing_set_train, self.masked_set_train)
  File "/common/ketrong/AutoImputeExp/tpot2_imputetest/Impute_Experiments/autoutils.py", line 62, in score
    imputed = my_model.transform(missing_set)
  File "/home/ketrong/miniconda3/envs/tpot2devenv/lib/python3.10/site-packages/sklearn/utils/_set_output.py", line 157, in wrapped
    data_to_wrap = f(self, X, *args, **kwargs)
  File "/common/ketrong/AutoImputeExp/tpot2_imputetest/Impute_Experiments/transformers.py", line 605, in transform
    return self.gain(X, self.params)
  File "/common/ketrong/AutoImputeExp/tpot2_imputetest/Impute_Experiments/transformers.py", line 636, in gain
    norm_data, norm_parameters = self.normalization(data_x)
  File "/common/ketrong/AutoImputeExp/tpot2_imputetest/Impute_Experiments/transformers.py", line 751, in normalization
    min_val[i] = np.nanmin(norm_data[:,i])
  File "/home/ketrong/miniconda3/envs/tpot2devenv/lib/python3.10/site-packages/pandas/core/frame.py", line 3807, in __getitem__
    indexer = self.columns.get_loc(key)
  File "/home/ketrong/miniconda3/envs/tpot2devenv/lib/python3.10/site-packages/pandas/core/indexes/base.py", line 3809, in get_loc
    self._check_indexing_error(key)
  File "/home/ketrong/miniconda3/envs/tpot2devenv/lib/python3.10/site-packages/pandas/core/indexes/base.py", line 5925, in _check_indexing_error
    raise InvalidIndexError(key)
pandas.errors.InvalidIndexError: (slice(None, None, None), 0)
[W 2023-11-28 16:16:57,245] Trial 20 failed with value None.
[W 2023-11-28 16:16:56,641] Trial 22 failed with parameters: {'model_name': 'GAIN', 'batch_size': 5, 'hint_rate': 0.9600000000000001, 'alpha': 65, 'iterations': 1222} because of the following error: InvalidIndexError((slice(None, None, None), 0)).
Traceback (most recent call last):
  File "/home/ketrong/miniconda3/envs/tpot2devenv/lib/python3.10/site-packages/pandas/core/indexes/base.py", line 3802, in get_loc
    return self._engine.get_loc(casted_key)
  File "pandas/_libs/index.pyx", line 138, in pandas._libs.index.IndexEngine.get_loc
  File "pandas/_libs/index.pyx", line 144, in pandas._libs.index.IndexEngine.get_loc
TypeError: '(slice(None, None, None), 0)' is an invalid key

During handling of the above exception, another exception occurred:

Traceback (most recent call last):
  File "/home/ketrong/miniconda3/envs/tpot2devenv/lib/python3.10/site-packages/optuna/study/_optimize.py", line 200, in _run_trial
    value_or_values = func(trial)
  File "/common/ketrong/AutoImputeExp/tpot2_imputetest/Impute_Experiments/autoimpute.py", line 59, in obj
    return autoutils.score(trial, splitting, my_model, X, self.missing_set_train, self.masked_set_train)
  File "/common/ketrong/AutoImputeExp/tpot2_imputetest/Impute_Experiments/autoutils.py", line 62, in score
    imputed = my_model.transform(missing_set)
  File "/home/ketrong/miniconda3/envs/tpot2devenv/lib/python3.10/site-packages/sklearn/utils/_set_output.py", line 157, in wrapped
    data_to_wrap = f(self, X, *args, **kwargs)
  File "/common/ketrong/AutoImputeExp/tpot2_imputetest/Impute_Experiments/transformers.py", line 605, in transform
    return self.gain(X, self.params)
  File "/common/ketrong/AutoImputeExp/tpot2_imputetest/Impute_Experiments/transformers.py", line 636, in gain
    norm_data, norm_parameters = self.normalization(data_x)
  File "/common/ketrong/AutoImputeExp/tpot2_imputetest/Impute_Experiments/transformers.py", line 751, in normalization
    min_val[i] = np.nanmin(norm_data[:,i])
  File "/home/ketrong/miniconda3/envs/tpot2devenv/lib/python3.10/site-packages/pandas/core/frame.py", line 3807, in __getitem__
    indexer = self.columns.get_loc(key)
  File "/home/ketrong/miniconda3/envs/tpot2devenv/lib/python3.10/site-packages/pandas/core/indexes/base.py", line 3809, in get_loc
    self._check_indexing_error(key)
  File "/home/ketrong/miniconda3/envs/tpot2devenv/lib/python3.10/site-packages/pandas/core/indexes/base.py", line 5925, in _check_indexing_error
    raise InvalidIndexError(key)
pandas.errors.InvalidIndexError: (slice(None, None, None), 0)
[W 2023-11-28 16:16:57,400] Trial 22 failed with value None.
[W 2023-11-28 16:16:56,645] Trial 14 failed with value None.
[W 2023-11-28 16:16:56,649] Trial 28 failed with parameters: {'model_name': 'GAIN', 'batch_size': 205, 'hint_rate': 0.46, 'alpha': 78, 'iterations': 20827} because of the following error: InvalidIndexError((slice(None, None, None), 0)).
Traceback (most recent call last):
  File "/home/ketrong/miniconda3/envs/tpot2devenv/lib/python3.10/site-packages/pandas/core/indexes/base.py", line 3802, in get_loc
    return self._engine.get_loc(casted_key)
  File "pandas/_libs/index.pyx", line 138, in pandas._libs.index.IndexEngine.get_loc
  File "pandas/_libs/index.pyx", line 144, in pandas._libs.index.IndexEngine.get_loc
TypeError: '(slice(None, None, None), 0)' is an invalid key

During handling of the above exception, another exception occurred:

Traceback (most recent call last):
  File "/home/ketrong/miniconda3/envs/tpot2devenv/lib/python3.10/site-packages/optuna/study/_optimize.py", line 200, in _run_trial
    value_or_values = func(trial)
  File "/common/ketrong/AutoImputeExp/tpot2_imputetest/Impute_Experiments/autoimpute.py", line 59, in obj
    return autoutils.score(trial, splitting, my_model, X, self.missing_set_train, self.masked_set_train)
  File "/common/ketrong/AutoImputeExp/tpot2_imputetest/Impute_Experiments/autoutils.py", line 62, in score
    imputed = my_model.transform(missing_set)
  File "/home/ketrong/miniconda3/envs/tpot2devenv/lib/python3.10/site-packages/sklearn/utils/_set_output.py", line 157, in wrapped
    data_to_wrap = f(self, X, *args, **kwargs)
  File "/common/ketrong/AutoImputeExp/tpot2_imputetest/Impute_Experiments/transformers.py", line 605, in transform
    return self.gain(X, self.params)
  File "/common/ketrong/AutoImputeExp/tpot2_imputetest/Impute_Experiments/transformers.py", line 636, in gain
    norm_data, norm_parameters = self.normalization(data_x)
  File "/common/ketrong/AutoImputeExp/tpot2_imputetest/Impute_Experiments/transformers.py", line 751, in normalization
    min_val[i] = np.nanmin(norm_data[:,i])
  File "/home/ketrong/miniconda3/envs/tpot2devenv/lib/python3.10/site-packages/pandas/core/frame.py", line 3807, in __getitem__
    indexer = self.columns.get_loc(key)
  File "/home/ketrong/miniconda3/envs/tpot2devenv/lib/python3.10/site-packages/pandas/core/indexes/base.py", line 3809, in get_loc
    self._check_indexing_error(key)
  File "/home/ketrong/miniconda3/envs/tpot2devenv/lib/python3.10/site-packages/pandas/core/indexes/base.py", line 5925, in _check_indexing_error
    raise InvalidIndexError(key)
pandas.errors.InvalidIndexError: (slice(None, None, None), 0)
[W 2023-11-28 16:16:57,778] Trial 28 failed with value None.
[W 2023-11-28 16:16:56,799] Trial 24 failed with parameters: {'model_name': 'GAIN', 'batch_size': 138, 'hint_rate': 0.37, 'alpha': 81, 'iterations': 15394} because of the following error: InvalidIndexError((slice(None, None, None), 0)).
Traceback (most recent call last):
  File "/home/ketrong/miniconda3/envs/tpot2devenv/lib/python3.10/site-packages/pandas/core/indexes/base.py", line 3802, in get_loc
    return self._engine.get_loc(casted_key)
  File "pandas/_libs/index.pyx", line 138, in pandas._libs.index.IndexEngine.get_loc
  File "pandas/_libs/index.pyx", line 144, in pandas._libs.index.IndexEngine.get_loc
TypeError: '(slice(None, None, None), 0)' is an invalid key

During handling of the above exception, another exception occurred:

Traceback (most recent call last):
  File "/home/ketrong/miniconda3/envs/tpot2devenv/lib/python3.10/site-packages/optuna/study/_optimize.py", line 200, in _run_trial
    value_or_values = func(trial)
  File "/common/ketrong/AutoImputeExp/tpot2_imputetest/Impute_Experiments/autoimpute.py", line 59, in obj
    return autoutils.score(trial, splitting, my_model, X, self.missing_set_train, self.masked_set_train)
  File "/common/ketrong/AutoImputeExp/tpot2_imputetest/Impute_Experiments/autoutils.py", line 62, in score
    imputed = my_model.transform(missing_set)
  File "/home/ketrong/miniconda3/envs/tpot2devenv/lib/python3.10/site-packages/sklearn/utils/_set_output.py", line 157, in wrapped
    data_to_wrap = f(self, X, *args, **kwargs)
  File "/common/ketrong/AutoImputeExp/tpot2_imputetest/Impute_Experiments/transformers.py", line 605, in transform
    return self.gain(X, self.params)
  File "/common/ketrong/AutoImputeExp/tpot2_imputetest/Impute_Experiments/transformers.py", line 636, in gain
    norm_data, norm_parameters = self.normalization(data_x)
  File "/common/ketrong/AutoImputeExp/tpot2_imputetest/Impute_Experiments/transformers.py", line 751, in normalization
    min_val[i] = np.nanmin(norm_data[:,i])
  File "/home/ketrong/miniconda3/envs/tpot2devenv/lib/python3.10/site-packages/pandas/core/frame.py", line 3807, in __getitem__
    indexer = self.columns.get_loc(key)
  File "/home/ketrong/miniconda3/envs/tpot2devenv/lib/python3.10/site-packages/pandas/core/indexes/base.py", line 3809, in get_loc
    self._check_indexing_error(key)
  File "/home/ketrong/miniconda3/envs/tpot2devenv/lib/python3.10/site-packages/pandas/core/indexes/base.py", line 5925, in _check_indexing_error
    raise InvalidIndexError(key)
pandas.errors.InvalidIndexError: (slice(None, None, None), 0)
[W 2023-11-28 16:16:57,942] Trial 24 failed with value None.
[W 2023-11-28 16:16:56,800] Trial 25 failed with parameters: {'model_name': 'GAIN', 'batch_size': 3, 'hint_rate': 0.27, 'alpha': 70, 'iterations': 184} because of the following error: InvalidIndexError((slice(None, None, None), 0)).
Traceback (most recent call last):
  File "/home/ketrong/miniconda3/envs/tpot2devenv/lib/python3.10/site-packages/pandas/core/indexes/base.py", line 3802, in get_loc
    return self._engine.get_loc(casted_key)
  File "pandas/_libs/index.pyx", line 138, in pandas._libs.index.IndexEngine.get_loc
  File "pandas/_libs/index.pyx", line 144, in pandas._libs.index.IndexEngine.get_loc
TypeError: '(slice(None, None, None), 0)' is an invalid key

During handling of the above exception, another exception occurred:

Traceback (most recent call last):
  File "/home/ketrong/miniconda3/envs/tpot2devenv/lib/python3.10/site-packages/optuna/study/_optimize.py", line 200, in _run_trial
    value_or_values = func(trial)
  File "/common/ketrong/AutoImputeExp/tpot2_imputetest/Impute_Experiments/autoimpute.py", line 59, in obj
    return autoutils.score(trial, splitting, my_model, X, self.missing_set_train, self.masked_set_train)
  File "/common/ketrong/AutoImputeExp/tpot2_imputetest/Impute_Experiments/autoutils.py", line 62, in score
    imputed = my_model.transform(missing_set)
  File "/home/ketrong/miniconda3/envs/tpot2devenv/lib/python3.10/site-packages/sklearn/utils/_set_output.py", line 157, in wrapped
    data_to_wrap = f(self, X, *args, **kwargs)
  File "/common/ketrong/AutoImputeExp/tpot2_imputetest/Impute_Experiments/transformers.py", line 605, in transform
    return self.gain(X, self.params)
  File "/common/ketrong/AutoImputeExp/tpot2_imputetest/Impute_Experiments/transformers.py", line 636, in gain
    norm_data, norm_parameters = self.normalization(data_x)
  File "/common/ketrong/AutoImputeExp/tpot2_imputetest/Impute_Experiments/transformers.py", line 751, in normalization
    min_val[i] = np.nanmin(norm_data[:,i])
  File "/home/ketrong/miniconda3/envs/tpot2devenv/lib/python3.10/site-packages/pandas/core/frame.py", line 3807, in __getitem__
    indexer = self.columns.get_loc(key)
  File "/home/ketrong/miniconda3/envs/tpot2devenv/lib/python3.10/site-packages/pandas/core/indexes/base.py", line 3809, in get_loc
    self._check_indexing_error(key)
  File "/home/ketrong/miniconda3/envs/tpot2devenv/lib/python3.10/site-packages/pandas/core/indexes/base.py", line 5925, in _check_indexing_error
    raise InvalidIndexError(key)
pandas.errors.InvalidIndexError: (slice(None, None, None), 0)
[W 2023-11-28 16:16:58,094] Trial 25 failed with value None.
[W 2023-11-28 16:16:56,947] Trial 27 failed with parameters: {'model_name': 'GAIN', 'batch_size': 8, 'hint_rate': 0.5700000000000001, 'alpha': 82, 'iterations': 1} because of the following error: InvalidIndexError((slice(None, None, None), 0)).
Traceback (most recent call last):
  File "/home/ketrong/miniconda3/envs/tpot2devenv/lib/python3.10/site-packages/pandas/core/indexes/base.py", line 3802, in get_loc
    return self._engine.get_loc(casted_key)
  File "pandas/_libs/index.pyx", line 138, in pandas._libs.index.IndexEngine.get_loc
  File "pandas/_libs/index.pyx", line 144, in pandas._libs.index.IndexEngine.get_loc
TypeError: '(slice(None, None, None), 0)' is an invalid key

During handling of the above exception, another exception occurred:

Traceback (most recent call last):
  File "/home/ketrong/miniconda3/envs/tpot2devenv/lib/python3.10/site-packages/optuna/study/_optimize.py", line 200, in _run_trial
    value_or_values = func(trial)
  File "/common/ketrong/AutoImputeExp/tpot2_imputetest/Impute_Experiments/autoimpute.py", line 59, in obj
    return autoutils.score(trial, splitting, my_model, X, self.missing_set_train, self.masked_set_train)
  File "/common/ketrong/AutoImputeExp/tpot2_imputetest/Impute_Experiments/autoutils.py", line 62, in score
    imputed = my_model.transform(missing_set)
  File "/home/ketrong/miniconda3/envs/tpot2devenv/lib/python3.10/site-packages/sklearn/utils/_set_output.py", line 157, in wrapped
    data_to_wrap = f(self, X, *args, **kwargs)
  File "/common/ketrong/AutoImputeExp/tpot2_imputetest/Impute_Experiments/transformers.py", line 605, in transform
    return self.gain(X, self.params)
  File "/common/ketrong/AutoImputeExp/tpot2_imputetest/Impute_Experiments/transformers.py", line 636, in gain
    norm_data, norm_parameters = self.normalization(data_x)
  File "/common/ketrong/AutoImputeExp/tpot2_imputetest/Impute_Experiments/transformers.py", line 751, in normalization
    min_val[i] = np.nanmin(norm_data[:,i])
  File "/home/ketrong/miniconda3/envs/tpot2devenv/lib/python3.10/site-packages/pandas/core/frame.py", line 3807, in __getitem__
    indexer = self.columns.get_loc(key)
  File "/home/ketrong/miniconda3/envs/tpot2devenv/lib/python3.10/site-packages/pandas/core/indexes/base.py", line 3809, in get_loc
    self._check_indexing_error(key)
  File "/home/ketrong/miniconda3/envs/tpot2devenv/lib/python3.10/site-packages/pandas/core/indexes/base.py", line 5925, in _check_indexing_error
    raise InvalidIndexError(key)
pandas.errors.InvalidIndexError: (slice(None, None, None), 0)
[W 2023-11-28 16:16:58,245] Trial 27 failed with value None.
[W 2023-11-28 16:16:56,633] Trial 21 failed with parameters: {'model_name': 'GAIN', 'batch_size': 12, 'hint_rate': 0.59, 'alpha': 0, 'iterations': 427} because of the following error: InvalidIndexError((slice(None, None, None), 0)).
Traceback (most recent call last):
  File "/home/ketrong/miniconda3/envs/tpot2devenv/lib/python3.10/site-packages/pandas/core/indexes/base.py", line 3802, in get_loc
    return self._engine.get_loc(casted_key)
  File "pandas/_libs/index.pyx", line 138, in pandas._libs.index.IndexEngine.get_loc
  File "pandas/_libs/index.pyx", line 144, in pandas._libs.index.IndexEngine.get_loc
TypeError: '(slice(None, None, None), 0)' is an invalid key

During handling of the above exception, another exception occurred:

Traceback (most recent call last):
  File "/home/ketrong/miniconda3/envs/tpot2devenv/lib/python3.10/site-packages/optuna/study/_optimize.py", line 200, in _run_trial
    value_or_values = func(trial)
  File "/common/ketrong/AutoImputeExp/tpot2_imputetest/Impute_Experiments/autoimpute.py", line 59, in obj
    return autoutils.score(trial, splitting, my_model, X, self.missing_set_train, self.masked_set_train)
  File "/common/ketrong/AutoImputeExp/tpot2_imputetest/Impute_Experiments/autoutils.py", line 62, in score
    imputed = my_model.transform(missing_set)
  File "/home/ketrong/miniconda3/envs/tpot2devenv/lib/python3.10/site-packages/sklearn/utils/_set_output.py", line 157, in wrapped
    data_to_wrap = f(self, X, *args, **kwargs)
  File "/common/ketrong/AutoImputeExp/tpot2_imputetest/Impute_Experiments/transformers.py", line 605, in transform
    return self.gain(X, self.params)
  File "/common/ketrong/AutoImputeExp/tpot2_imputetest/Impute_Experiments/transformers.py", line 636, in gain
    norm_data, norm_parameters = self.normalization(data_x)
  File "/common/ketrong/AutoImputeExp/tpot2_imputetest/Impute_Experiments/transformers.py", line 751, in normalization
    min_val[i] = np.nanmin(norm_data[:,i])
  File "/home/ketrong/miniconda3/envs/tpot2devenv/lib/python3.10/site-packages/pandas/core/frame.py", line 3807, in __getitem__
    indexer = self.columns.get_loc(key)
  File "/home/ketrong/miniconda3/envs/tpot2devenv/lib/python3.10/site-packages/pandas/core/indexes/base.py", line 3809, in get_loc
    self._check_indexing_error(key)
  File "/home/ketrong/miniconda3/envs/tpot2devenv/lib/python3.10/site-packages/pandas/core/indexes/base.py", line 5925, in _check_indexing_error
    raise InvalidIndexError(key)
pandas.errors.InvalidIndexError: (slice(None, None, None), 0)
[W 2023-11-28 16:16:58,392] Trial 21 failed with value None.
[W 2023-11-28 16:16:57,098] Trial 29 failed with parameters: {'model_name': 'GAIN', 'batch_size': 17, 'hint_rate': 0.35000000000000003, 'alpha': 6, 'iterations': 183} because of the following error: InvalidIndexError((slice(None, None, None), 0)).
Traceback (most recent call last):
  File "/home/ketrong/miniconda3/envs/tpot2devenv/lib/python3.10/site-packages/pandas/core/indexes/base.py", line 3802, in get_loc
    return self._engine.get_loc(casted_key)
  File "pandas/_libs/index.pyx", line 138, in pandas._libs.index.IndexEngine.get_loc
  File "pandas/_libs/index.pyx", line 144, in pandas._libs.index.IndexEngine.get_loc
TypeError: '(slice(None, None, None), 0)' is an invalid key

During handling of the above exception, another exception occurred:

Traceback (most recent call last):
  File "/home/ketrong/miniconda3/envs/tpot2devenv/lib/python3.10/site-packages/optuna/study/_optimize.py", line 200, in _run_trial
    value_or_values = func(trial)
  File "/common/ketrong/AutoImputeExp/tpot2_imputetest/Impute_Experiments/autoimpute.py", line 59, in obj
    return autoutils.score(trial, splitting, my_model, X, self.missing_set_train, self.masked_set_train)
  File "/common/ketrong/AutoImputeExp/tpot2_imputetest/Impute_Experiments/autoutils.py", line 62, in score
    imputed = my_model.transform(missing_set)
  File "/home/ketrong/miniconda3/envs/tpot2devenv/lib/python3.10/site-packages/sklearn/utils/_set_output.py", line 157, in wrapped
    data_to_wrap = f(self, X, *args, **kwargs)
  File "/common/ketrong/AutoImputeExp/tpot2_imputetest/Impute_Experiments/transformers.py", line 605, in transform
    return self.gain(X, self.params)
  File "/common/ketrong/AutoImputeExp/tpot2_imputetest/Impute_Experiments/transformers.py", line 636, in gain
    norm_data, norm_parameters = self.normalization(data_x)
  File "/common/ketrong/AutoImputeExp/tpot2_imputetest/Impute_Experiments/transformers.py", line 751, in normalization
    min_val[i] = np.nanmin(norm_data[:,i])
  File "/home/ketrong/miniconda3/envs/tpot2devenv/lib/python3.10/site-packages/pandas/core/frame.py", line 3807, in __getitem__
    indexer = self.columns.get_loc(key)
  File "/home/ketrong/miniconda3/envs/tpot2devenv/lib/python3.10/site-packages/pandas/core/indexes/base.py", line 3809, in get_loc
    self._check_indexing_error(key)
  File "/home/ketrong/miniconda3/envs/tpot2devenv/lib/python3.10/site-packages/pandas/core/indexes/base.py", line 5925, in _check_indexing_error
    raise InvalidIndexError(key)
pandas.errors.InvalidIndexError: (slice(None, None, None), 0)
[W 2023-11-28 16:16:58,540] Trial 29 failed with value None.
[W 2023-11-28 16:16:57,393] Trial 30 failed with parameters: {'model_name': 'GAIN', 'batch_size': 1, 'hint_rate': 0.2, 'alpha': 30, 'iterations': 1} because of the following error: InvalidIndexError((slice(None, None, None), 0)).
Traceback (most recent call last):
  File "/home/ketrong/miniconda3/envs/tpot2devenv/lib/python3.10/site-packages/pandas/core/indexes/base.py", line 3802, in get_loc
    return self._engine.get_loc(casted_key)
  File "pandas/_libs/index.pyx", line 138, in pandas._libs.index.IndexEngine.get_loc
  File "pandas/_libs/index.pyx", line 144, in pandas._libs.index.IndexEngine.get_loc
TypeError: '(slice(None, None, None), 0)' is an invalid key

During handling of the above exception, another exception occurred:

Traceback (most recent call last):
  File "/home/ketrong/miniconda3/envs/tpot2devenv/lib/python3.10/site-packages/optuna/study/_optimize.py", line 200, in _run_trial
    value_or_values = func(trial)
  File "/common/ketrong/AutoImputeExp/tpot2_imputetest/Impute_Experiments/autoimpute.py", line 59, in obj
    return autoutils.score(trial, splitting, my_model, X, self.missing_set_train, self.masked_set_train)
  File "/common/ketrong/AutoImputeExp/tpot2_imputetest/Impute_Experiments/autoutils.py", line 62, in score
    imputed = my_model.transform(missing_set)
  File "/home/ketrong/miniconda3/envs/tpot2devenv/lib/python3.10/site-packages/sklearn/utils/_set_output.py", line 157, in wrapped
    data_to_wrap = f(self, X, *args, **kwargs)
  File "/common/ketrong/AutoImputeExp/tpot2_imputetest/Impute_Experiments/transformers.py", line 605, in transform
    return self.gain(X, self.params)
  File "/common/ketrong/AutoImputeExp/tpot2_imputetest/Impute_Experiments/transformers.py", line 636, in gain
    norm_data, norm_parameters = self.normalization(data_x)
  File "/common/ketrong/AutoImputeExp/tpot2_imputetest/Impute_Experiments/transformers.py", line 751, in normalization
    min_val[i] = np.nanmin(norm_data[:,i])
  File "/home/ketrong/miniconda3/envs/tpot2devenv/lib/python3.10/site-packages/pandas/core/frame.py", line 3807, in __getitem__
    indexer = self.columns.get_loc(key)
  File "/home/ketrong/miniconda3/envs/tpot2devenv/lib/python3.10/site-packages/pandas/core/indexes/base.py", line 3809, in get_loc
    self._check_indexing_error(key)
  File "/home/ketrong/miniconda3/envs/tpot2devenv/lib/python3.10/site-packages/pandas/core/indexes/base.py", line 5925, in _check_indexing_error
    raise InvalidIndexError(key)
pandas.errors.InvalidIndexError: (slice(None, None, None), 0)
[W 2023-11-28 16:16:58,691] Trial 30 failed with value None.
[W 2023-11-28 16:16:57,395] Trial 31 failed with parameters: {'model_name': 'GAIN', 'batch_size': 122, 'hint_rate': 0.48000000000000004, 'alpha': 21, 'iterations': 1} because of the following error: InvalidIndexError((slice(None, None, None), 0)).
Traceback (most recent call last):
  File "/home/ketrong/miniconda3/envs/tpot2devenv/lib/python3.10/site-packages/pandas/core/indexes/base.py", line 3802, in get_loc
    return self._engine.get_loc(casted_key)
  File "pandas/_libs/index.pyx", line 138, in pandas._libs.index.IndexEngine.get_loc
  File "pandas/_libs/index.pyx", line 144, in pandas._libs.index.IndexEngine.get_loc
TypeError: '(slice(None, None, None), 0)' is an invalid key

During handling of the above exception, another exception occurred:

Traceback (most recent call last):
  File "/home/ketrong/miniconda3/envs/tpot2devenv/lib/python3.10/site-packages/optuna/study/_optimize.py", line 200, in _run_trial
    value_or_values = func(trial)
  File "/common/ketrong/AutoImputeExp/tpot2_imputetest/Impute_Experiments/autoimpute.py", line 59, in obj
    return autoutils.score(trial, splitting, my_model, X, self.missing_set_train, self.masked_set_train)
  File "/common/ketrong/AutoImputeExp/tpot2_imputetest/Impute_Experiments/autoutils.py", line 62, in score
    imputed = my_model.transform(missing_set)
  File "/home/ketrong/miniconda3/envs/tpot2devenv/lib/python3.10/site-packages/sklearn/utils/_set_output.py", line 157, in wrapped
    data_to_wrap = f(self, X, *args, **kwargs)
  File "/common/ketrong/AutoImputeExp/tpot2_imputetest/Impute_Experiments/transformers.py", line 605, in transform
    return self.gain(X, self.params)
  File "/common/ketrong/AutoImputeExp/tpot2_imputetest/Impute_Experiments/transformers.py", line 636, in gain
    norm_data, norm_parameters = self.normalization(data_x)
  File "/common/ketrong/AutoImputeExp/tpot2_imputetest/Impute_Experiments/transformers.py", line 751, in normalization
    min_val[i] = np.nanmin(norm_data[:,i])
  File "/home/ketrong/miniconda3/envs/tpot2devenv/lib/python3.10/site-packages/pandas/core/frame.py", line 3807, in __getitem__
    indexer = self.columns.get_loc(key)
  File "/home/ketrong/miniconda3/envs/tpot2devenv/lib/python3.10/site-packages/pandas/core/indexes/base.py", line 3809, in get_loc
    self._check_indexing_error(key)
  File "/home/ketrong/miniconda3/envs/tpot2devenv/lib/python3.10/site-packages/pandas/core/indexes/base.py", line 5925, in _check_indexing_error
    raise InvalidIndexError(key)
pandas.errors.InvalidIndexError: (slice(None, None, None), 0)
[W 2023-11-28 16:16:58,841] Trial 31 failed with value None.
[W 2023-11-28 16:16:57,400] Trial 32 failed with parameters: {'model_name': 'GAIN', 'batch_size': 2, 'hint_rate': 0.59, 'alpha': 30, 'iterations': 8} because of the following error: InvalidIndexError((slice(None, None, None), 0)).
Traceback (most recent call last):
  File "/home/ketrong/miniconda3/envs/tpot2devenv/lib/python3.10/site-packages/pandas/core/indexes/base.py", line 3802, in get_loc
    return self._engine.get_loc(casted_key)
  File "pandas/_libs/index.pyx", line 138, in pandas._libs.index.IndexEngine.get_loc
  File "pandas/_libs/index.pyx", line 144, in pandas._libs.index.IndexEngine.get_loc
TypeError: '(slice(None, None, None), 0)' is an invalid key

During handling of the above exception, another exception occurred:

Traceback (most recent call last):
  File "/home/ketrong/miniconda3/envs/tpot2devenv/lib/python3.10/site-packages/optuna/study/_optimize.py", line 200, in _run_trial
    value_or_values = func(trial)
  File "/common/ketrong/AutoImputeExp/tpot2_imputetest/Impute_Experiments/autoimpute.py", line 59, in obj
    return autoutils.score(trial, splitting, my_model, X, self.missing_set_train, self.masked_set_train)
  File "/common/ketrong/AutoImputeExp/tpot2_imputetest/Impute_Experiments/autoutils.py", line 62, in score
    imputed = my_model.transform(missing_set)
  File "/home/ketrong/miniconda3/envs/tpot2devenv/lib/python3.10/site-packages/sklearn/utils/_set_output.py", line 157, in wrapped
    data_to_wrap = f(self, X, *args, **kwargs)
  File "/common/ketrong/AutoImputeExp/tpot2_imputetest/Impute_Experiments/transformers.py", line 605, in transform
    return self.gain(X, self.params)
  File "/common/ketrong/AutoImputeExp/tpot2_imputetest/Impute_Experiments/transformers.py", line 636, in gain
    norm_data, norm_parameters = self.normalization(data_x)
  File "/common/ketrong/AutoImputeExp/tpot2_imputetest/Impute_Experiments/transformers.py", line 751, in normalization
    min_val[i] = np.nanmin(norm_data[:,i])
  File "/home/ketrong/miniconda3/envs/tpot2devenv/lib/python3.10/site-packages/pandas/core/frame.py", line 3807, in __getitem__
    indexer = self.columns.get_loc(key)
  File "/home/ketrong/miniconda3/envs/tpot2devenv/lib/python3.10/site-packages/pandas/core/indexes/base.py", line 3809, in get_loc
    self._check_indexing_error(key)
  File "/home/ketrong/miniconda3/envs/tpot2devenv/lib/python3.10/site-packages/pandas/core/indexes/base.py", line 5925, in _check_indexing_error
    raise InvalidIndexError(key)
pandas.errors.InvalidIndexError: (slice(None, None, None), 0)
[W 2023-11-28 16:16:58,991] Trial 32 failed with value None.
[W 2023-11-28 16:16:56,185] Trial 15 failed with parameters: {'model_name': 'GAIN', 'batch_size': 40, 'hint_rate': 0.85, 'alpha': 91, 'iterations': 838} because of the following error: InvalidIndexError((slice(None, None, None), 0)).
Traceback (most recent call last):
  File "/home/ketrong/miniconda3/envs/tpot2devenv/lib/python3.10/site-packages/pandas/core/indexes/base.py", line 3802, in get_loc
    return self._engine.get_loc(casted_key)
  File "pandas/_libs/index.pyx", line 138, in pandas._libs.index.IndexEngine.get_loc
  File "pandas/_libs/index.pyx", line 144, in pandas._libs.index.IndexEngine.get_loc
TypeError: '(slice(None, None, None), 0)' is an invalid key

During handling of the above exception, another exception occurred:

Traceback (most recent call last):
  File "/home/ketrong/miniconda3/envs/tpot2devenv/lib/python3.10/site-packages/optuna/study/_optimize.py", line 200, in _run_trial
    value_or_values = func(trial)
  File "/common/ketrong/AutoImputeExp/tpot2_imputetest/Impute_Experiments/autoimpute.py", line 59, in obj
    return autoutils.score(trial, splitting, my_model, X, self.missing_set_train, self.masked_set_train)
  File "/common/ketrong/AutoImputeExp/tpot2_imputetest/Impute_Experiments/autoutils.py", line 62, in score
    imputed = my_model.transform(missing_set)
  File "/home/ketrong/miniconda3/envs/tpot2devenv/lib/python3.10/site-packages/sklearn/utils/_set_output.py", line 157, in wrapped
    data_to_wrap = f(self, X, *args, **kwargs)
  File "/common/ketrong/AutoImputeExp/tpot2_imputetest/Impute_Experiments/transformers.py", line 605, in transform
    return self.gain(X, self.params)
  File "/common/ketrong/AutoImputeExp/tpot2_imputetest/Impute_Experiments/transformers.py", line 636, in gain
    norm_data, norm_parameters = self.normalization(data_x)
  File "/common/ketrong/AutoImputeExp/tpot2_imputetest/Impute_Experiments/transformers.py", line 751, in normalization
    min_val[i] = np.nanmin(norm_data[:,i])
  File "/home/ketrong/miniconda3/envs/tpot2devenv/lib/python3.10/site-packages/pandas/core/frame.py", line 3807, in __getitem__
    indexer = self.columns.get_loc(key)
  File "/home/ketrong/miniconda3/envs/tpot2devenv/lib/python3.10/site-packages/pandas/core/indexes/base.py", line 3809, in get_loc
    self._check_indexing_error(key)
  File "/home/ketrong/miniconda3/envs/tpot2devenv/lib/python3.10/site-packages/pandas/core/indexes/base.py", line 5925, in _check_indexing_error
    raise InvalidIndexError(key)
pandas.errors.InvalidIndexError: (slice(None, None, None), 0)
[W 2023-11-28 16:16:59,142] Trial 15 failed with value None.
[W 2023-11-28 16:16:55,334] Trial 8 failed with parameters: {'model_name': 'GAIN', 'batch_size': 41, 'hint_rate': 0.8200000000000001, 'alpha': 31, 'iterations': 356} because of the following error: InvalidIndexError((slice(None, None, None), 0)).
Traceback (most recent call last):
  File "/home/ketrong/miniconda3/envs/tpot2devenv/lib/python3.10/site-packages/pandas/core/indexes/base.py", line 3802, in get_loc
    return self._engine.get_loc(casted_key)
  File "pandas/_libs/index.pyx", line 138, in pandas._libs.index.IndexEngine.get_loc
  File "pandas/_libs/index.pyx", line 144, in pandas._libs.index.IndexEngine.get_loc
TypeError: '(slice(None, None, None), 0)' is an invalid key

During handling of the above exception, another exception occurred:

Traceback (most recent call last):
  File "/home/ketrong/miniconda3/envs/tpot2devenv/lib/python3.10/site-packages/optuna/study/_optimize.py", line 200, in _run_trial
    value_or_values = func(trial)
  File "/common/ketrong/AutoImputeExp/tpot2_imputetest/Impute_Experiments/autoimpute.py", line 59, in obj
    return autoutils.score(trial, splitting, my_model, X, self.missing_set_train, self.masked_set_train)
  File "/common/ketrong/AutoImputeExp/tpot2_imputetest/Impute_Experiments/autoutils.py", line 62, in score
    imputed = my_model.transform(missing_set)
  File "/home/ketrong/miniconda3/envs/tpot2devenv/lib/python3.10/site-packages/sklearn/utils/_set_output.py", line 157, in wrapped
    data_to_wrap = f(self, X, *args, **kwargs)
  File "/common/ketrong/AutoImputeExp/tpot2_imputetest/Impute_Experiments/transformers.py", line 605, in transform
    return self.gain(X, self.params)
  File "/common/ketrong/AutoImputeExp/tpot2_imputetest/Impute_Experiments/transformers.py", line 636, in gain
    norm_data, norm_parameters = self.normalization(data_x)
  File "/common/ketrong/AutoImputeExp/tpot2_imputetest/Impute_Experiments/transformers.py", line 751, in normalization
    min_val[i] = np.nanmin(norm_data[:,i])
  File "/home/ketrong/miniconda3/envs/tpot2devenv/lib/python3.10/site-packages/pandas/core/frame.py", line 3807, in __getitem__
    indexer = self.columns.get_loc(key)
  File "/home/ketrong/miniconda3/envs/tpot2devenv/lib/python3.10/site-packages/pandas/core/indexes/base.py", line 3809, in get_loc
    self._check_indexing_error(key)
  File "/home/ketrong/miniconda3/envs/tpot2devenv/lib/python3.10/site-packages/pandas/core/indexes/base.py", line 5925, in _check_indexing_error
    raise InvalidIndexError(key)
pandas.errors.InvalidIndexError: (slice(None, None, None), 0)
[W 2023-11-28 16:16:59,292] Trial 8 failed with value None.
[W 2023-11-28 16:16:57,096] Trial 26 failed with parameters: {'model_name': 'GAIN', 'batch_size': 37, 'hint_rate': 0.64, 'alpha': 97, 'iterations': 72789} because of the following error: InvalidIndexError((slice(None, None, None), 0)).
Traceback (most recent call last):
  File "/home/ketrong/miniconda3/envs/tpot2devenv/lib/python3.10/site-packages/pandas/core/indexes/base.py", line 3802, in get_loc
    return self._engine.get_loc(casted_key)
  File "pandas/_libs/index.pyx", line 138, in pandas._libs.index.IndexEngine.get_loc
  File "pandas/_libs/index.pyx", line 144, in pandas._libs.index.IndexEngine.get_loc
TypeError: '(slice(None, None, None), 0)' is an invalid key

During handling of the above exception, another exception occurred:

Traceback (most recent call last):
  File "/home/ketrong/miniconda3/envs/tpot2devenv/lib/python3.10/site-packages/optuna/study/_optimize.py", line 200, in _run_trial
    value_or_values = func(trial)
  File "/common/ketrong/AutoImputeExp/tpot2_imputetest/Impute_Experiments/autoimpute.py", line 59, in obj
    return autoutils.score(trial, splitting, my_model, X, self.missing_set_train, self.masked_set_train)
  File "/common/ketrong/AutoImputeExp/tpot2_imputetest/Impute_Experiments/autoutils.py", line 62, in score
    imputed = my_model.transform(missing_set)
  File "/home/ketrong/miniconda3/envs/tpot2devenv/lib/python3.10/site-packages/sklearn/utils/_set_output.py", line 157, in wrapped
    data_to_wrap = f(self, X, *args, **kwargs)
  File "/common/ketrong/AutoImputeExp/tpot2_imputetest/Impute_Experiments/transformers.py", line 605, in transform
    return self.gain(X, self.params)
  File "/common/ketrong/AutoImputeExp/tpot2_imputetest/Impute_Experiments/transformers.py", line 636, in gain
    norm_data, norm_parameters = self.normalization(data_x)
  File "/common/ketrong/AutoImputeExp/tpot2_imputetest/Impute_Experiments/transformers.py", line 751, in normalization
    min_val[i] = np.nanmin(norm_data[:,i])
  File "/home/ketrong/miniconda3/envs/tpot2devenv/lib/python3.10/site-packages/pandas/core/frame.py", line 3807, in __getitem__
    indexer = self.columns.get_loc(key)
  File "/home/ketrong/miniconda3/envs/tpot2devenv/lib/python3.10/site-packages/pandas/core/indexes/base.py", line 3809, in get_loc
    self._check_indexing_error(key)
  File "/home/ketrong/miniconda3/envs/tpot2devenv/lib/python3.10/site-packages/pandas/core/indexes/base.py", line 5925, in _check_indexing_error
    raise InvalidIndexError(key)
pandas.errors.InvalidIndexError: (slice(None, None, None), 0)
[W 2023-11-28 16:16:59,438] Trial 26 failed with value None.
[W 2023-11-28 16:16:57,397] Trial 34 failed with parameters: {'model_name': 'GAIN', 'batch_size': 5, 'hint_rate': 0.37, 'alpha': 77, 'iterations': 143} because of the following error: InvalidIndexError((slice(None, None, None), 0)).
Traceback (most recent call last):
  File "/home/ketrong/miniconda3/envs/tpot2devenv/lib/python3.10/site-packages/pandas/core/indexes/base.py", line 3802, in get_loc
    return self._engine.get_loc(casted_key)
  File "pandas/_libs/index.pyx", line 138, in pandas._libs.index.IndexEngine.get_loc
  File "pandas/_libs/index.pyx", line 144, in pandas._libs.index.IndexEngine.get_loc
TypeError: '(slice(None, None, None), 0)' is an invalid key

During handling of the above exception, another exception occurred:

Traceback (most recent call last):
  File "/home/ketrong/miniconda3/envs/tpot2devenv/lib/python3.10/site-packages/optuna/study/_optimize.py", line 200, in _run_trial
    value_or_values = func(trial)
  File "/common/ketrong/AutoImputeExp/tpot2_imputetest/Impute_Experiments/autoimpute.py", line 59, in obj
    return autoutils.score(trial, splitting, my_model, X, self.missing_set_train, self.masked_set_train)
  File "/common/ketrong/AutoImputeExp/tpot2_imputetest/Impute_Experiments/autoutils.py", line 62, in score
    imputed = my_model.transform(missing_set)
  File "/home/ketrong/miniconda3/envs/tpot2devenv/lib/python3.10/site-packages/sklearn/utils/_set_output.py", line 157, in wrapped
    data_to_wrap = f(self, X, *args, **kwargs)
  File "/common/ketrong/AutoImputeExp/tpot2_imputetest/Impute_Experiments/transformers.py", line 605, in transform
    return self.gain(X, self.params)
  File "/common/ketrong/AutoImputeExp/tpot2_imputetest/Impute_Experiments/transformers.py", line 636, in gain
    norm_data, norm_parameters = self.normalization(data_x)
  File "/common/ketrong/AutoImputeExp/tpot2_imputetest/Impute_Experiments/transformers.py", line 751, in normalization
    min_val[i] = np.nanmin(norm_data[:,i])
  File "/home/ketrong/miniconda3/envs/tpot2devenv/lib/python3.10/site-packages/pandas/core/frame.py", line 3807, in __getitem__
    indexer = self.columns.get_loc(key)
  File "/home/ketrong/miniconda3/envs/tpot2devenv/lib/python3.10/site-packages/pandas/core/indexes/base.py", line 3809, in get_loc
    self._check_indexing_error(key)
  File "/home/ketrong/miniconda3/envs/tpot2devenv/lib/python3.10/site-packages/pandas/core/indexes/base.py", line 5925, in _check_indexing_error
    raise InvalidIndexError(key)
pandas.errors.InvalidIndexError: (slice(None, None, None), 0)
[W 2023-11-28 16:16:59,585] Trial 34 failed with value None.
[W 2023-11-28 16:16:57,398] Trial 33 failed with parameters: {'model_name': 'GAIN', 'batch_size': 993, 'hint_rate': 0.68, 'alpha': 1, 'iterations': 12942} because of the following error: InvalidIndexError((slice(None, None, None), 0)).
Traceback (most recent call last):
  File "/home/ketrong/miniconda3/envs/tpot2devenv/lib/python3.10/site-packages/pandas/core/indexes/base.py", line 3802, in get_loc
    return self._engine.get_loc(casted_key)
  File "pandas/_libs/index.pyx", line 138, in pandas._libs.index.IndexEngine.get_loc
  File "pandas/_libs/index.pyx", line 144, in pandas._libs.index.IndexEngine.get_loc
TypeError: '(slice(None, None, None), 0)' is an invalid key

During handling of the above exception, another exception occurred:

Traceback (most recent call last):
  File "/home/ketrong/miniconda3/envs/tpot2devenv/lib/python3.10/site-packages/optuna/study/_optimize.py", line 200, in _run_trial
    value_or_values = func(trial)
  File "/common/ketrong/AutoImputeExp/tpot2_imputetest/Impute_Experiments/autoimpute.py", line 59, in obj
    return autoutils.score(trial, splitting, my_model, X, self.missing_set_train, self.masked_set_train)
  File "/common/ketrong/AutoImputeExp/tpot2_imputetest/Impute_Experiments/autoutils.py", line 62, in score
    imputed = my_model.transform(missing_set)
  File "/home/ketrong/miniconda3/envs/tpot2devenv/lib/python3.10/site-packages/sklearn/utils/_set_output.py", line 157, in wrapped
    data_to_wrap = f(self, X, *args, **kwargs)
  File "/common/ketrong/AutoImputeExp/tpot2_imputetest/Impute_Experiments/transformers.py", line 605, in transform
    return self.gain(X, self.params)
  File "/common/ketrong/AutoImputeExp/tpot2_imputetest/Impute_Experiments/transformers.py", line 636, in gain
    norm_data, norm_parameters = self.normalization(data_x)
  File "/common/ketrong/AutoImputeExp/tpot2_imputetest/Impute_Experiments/transformers.py", line 751, in normalization
    min_val[i] = np.nanmin(norm_data[:,i])
  File "/home/ketrong/miniconda3/envs/tpot2devenv/lib/python3.10/site-packages/pandas/core/frame.py", line 3807, in __getitem__
    indexer = self.columns.get_loc(key)
  File "/home/ketrong/miniconda3/envs/tpot2devenv/lib/python3.10/site-packages/pandas/core/indexes/base.py", line 3809, in get_loc
    self._check_indexing_error(key)
  File "/home/ketrong/miniconda3/envs/tpot2devenv/lib/python3.10/site-packages/pandas/core/indexes/base.py", line 5925, in _check_indexing_error
    raise InvalidIndexError(key)
pandas.errors.InvalidIndexError: (slice(None, None, None), 0)
[W 2023-11-28 16:16:59,733] Trial 33 failed with value None.
[W 2023-11-28 16:16:56,948] Trial 16 failed with value None.
[W 2023-11-28 16:16:56,643] Trial 23 failed with parameters: {'model_name': 'GAIN', 'batch_size': 1, 'hint_rate': 0.81, 'alpha': 10, 'iterations': 424} because of the following error: InvalidIndexError((slice(None, None, None), 0)).
Traceback (most recent call last):
  File "/home/ketrong/miniconda3/envs/tpot2devenv/lib/python3.10/site-packages/pandas/core/indexes/base.py", line 3802, in get_loc
    return self._engine.get_loc(casted_key)
  File "pandas/_libs/index.pyx", line 138, in pandas._libs.index.IndexEngine.get_loc
  File "pandas/_libs/index.pyx", line 144, in pandas._libs.index.IndexEngine.get_loc
TypeError: '(slice(None, None, None), 0)' is an invalid key

During handling of the above exception, another exception occurred:

Traceback (most recent call last):
  File "/home/ketrong/miniconda3/envs/tpot2devenv/lib/python3.10/site-packages/optuna/study/_optimize.py", line 200, in _run_trial
    value_or_values = func(trial)
  File "/common/ketrong/AutoImputeExp/tpot2_imputetest/Impute_Experiments/autoimpute.py", line 59, in obj
    return autoutils.score(trial, splitting, my_model, X, self.missing_set_train, self.masked_set_train)
  File "/common/ketrong/AutoImputeExp/tpot2_imputetest/Impute_Experiments/autoutils.py", line 62, in score
    imputed = my_model.transform(missing_set)
  File "/home/ketrong/miniconda3/envs/tpot2devenv/lib/python3.10/site-packages/sklearn/utils/_set_output.py", line 157, in wrapped
    data_to_wrap = f(self, X, *args, **kwargs)
  File "/common/ketrong/AutoImputeExp/tpot2_imputetest/Impute_Experiments/transformers.py", line 605, in transform
    return self.gain(X, self.params)
  File "/common/ketrong/AutoImputeExp/tpot2_imputetest/Impute_Experiments/transformers.py", line 636, in gain
    norm_data, norm_parameters = self.normalization(data_x)
  File "/common/ketrong/AutoImputeExp/tpot2_imputetest/Impute_Experiments/transformers.py", line 751, in normalization
    min_val[i] = np.nanmin(norm_data[:,i])
  File "/home/ketrong/miniconda3/envs/tpot2devenv/lib/python3.10/site-packages/pandas/core/frame.py", line 3807, in __getitem__
    indexer = self.columns.get_loc(key)
  File "/home/ketrong/miniconda3/envs/tpot2devenv/lib/python3.10/site-packages/pandas/core/indexes/base.py", line 3809, in get_loc
    self._check_indexing_error(key)
  File "/home/ketrong/miniconda3/envs/tpot2devenv/lib/python3.10/site-packages/pandas/core/indexes/base.py", line 5925, in _check_indexing_error
    raise InvalidIndexError(key)
pandas.errors.InvalidIndexError: (slice(None, None, None), 0)
[W 2023-11-28 16:17:00,029] Trial 23 failed with value None.
[W 2023-11-28 16:16:56,646] Trial 18 failed with parameters: {'model_name': 'GAIN', 'batch_size': 1, 'hint_rate': 0.22, 'alpha': 71, 'iterations': 576} because of the following error: InvalidIndexError((slice(None, None, None), 0)).
Traceback (most recent call last):
  File "/home/ketrong/miniconda3/envs/tpot2devenv/lib/python3.10/site-packages/pandas/core/indexes/base.py", line 3802, in get_loc
    return self._engine.get_loc(casted_key)
  File "pandas/_libs/index.pyx", line 138, in pandas._libs.index.IndexEngine.get_loc
  File "pandas/_libs/index.pyx", line 144, in pandas._libs.index.IndexEngine.get_loc
TypeError: '(slice(None, None, None), 0)' is an invalid key

During handling of the above exception, another exception occurred:

Traceback (most recent call last):
  File "/home/ketrong/miniconda3/envs/tpot2devenv/lib/python3.10/site-packages/optuna/study/_optimize.py", line 200, in _run_trial
    value_or_values = func(trial)
  File "/common/ketrong/AutoImputeExp/tpot2_imputetest/Impute_Experiments/autoimpute.py", line 59, in obj
    return autoutils.score(trial, splitting, my_model, X, self.missing_set_train, self.masked_set_train)
  File "/common/ketrong/AutoImputeExp/tpot2_imputetest/Impute_Experiments/autoutils.py", line 62, in score
    imputed = my_model.transform(missing_set)
  File "/home/ketrong/miniconda3/envs/tpot2devenv/lib/python3.10/site-packages/sklearn/utils/_set_output.py", line 157, in wrapped
    data_to_wrap = f(self, X, *args, **kwargs)
  File "/common/ketrong/AutoImputeExp/tpot2_imputetest/Impute_Experiments/transformers.py", line 605, in transform
    return self.gain(X, self.params)
  File "/common/ketrong/AutoImputeExp/tpot2_imputetest/Impute_Experiments/transformers.py", line 636, in gain
    norm_data, norm_parameters = self.normalization(data_x)
  File "/common/ketrong/AutoImputeExp/tpot2_imputetest/Impute_Experiments/transformers.py", line 751, in normalization
    min_val[i] = np.nanmin(norm_data[:,i])
  File "/home/ketrong/miniconda3/envs/tpot2devenv/lib/python3.10/site-packages/pandas/core/frame.py", line 3807, in __getitem__
    indexer = self.columns.get_loc(key)
  File "/home/ketrong/miniconda3/envs/tpot2devenv/lib/python3.10/site-packages/pandas/core/indexes/base.py", line 3809, in get_loc
    self._check_indexing_error(key)
  File "/home/ketrong/miniconda3/envs/tpot2devenv/lib/python3.10/site-packages/pandas/core/indexes/base.py", line 5925, in _check_indexing_error
    raise InvalidIndexError(key)
pandas.errors.InvalidIndexError: (slice(None, None, None), 0)
[W 2023-11-28 16:17:00,178] Trial 18 failed with value None.
[W 2023-11-28 16:16:56,641] Trial 19 failed with parameters: {'model_name': 'GAIN', 'batch_size': 3, 'hint_rate': 0.51, 'alpha': 1, 'iterations': 5226} because of the following error: InvalidIndexError((slice(None, None, None), 0)).
Traceback (most recent call last):
  File "/home/ketrong/miniconda3/envs/tpot2devenv/lib/python3.10/site-packages/pandas/core/indexes/base.py", line 3802, in get_loc
    return self._engine.get_loc(casted_key)
  File "pandas/_libs/index.pyx", line 138, in pandas._libs.index.IndexEngine.get_loc
  File "pandas/_libs/index.pyx", line 144, in pandas._libs.index.IndexEngine.get_loc
TypeError: '(slice(None, None, None), 0)' is an invalid key

During handling of the above exception, another exception occurred:

Traceback (most recent call last):
  File "/home/ketrong/miniconda3/envs/tpot2devenv/lib/python3.10/site-packages/optuna/study/_optimize.py", line 200, in _run_trial
    value_or_values = func(trial)
  File "/common/ketrong/AutoImputeExp/tpot2_imputetest/Impute_Experiments/autoimpute.py", line 59, in obj
    return autoutils.score(trial, splitting, my_model, X, self.missing_set_train, self.masked_set_train)
  File "/common/ketrong/AutoImputeExp/tpot2_imputetest/Impute_Experiments/autoutils.py", line 62, in score
    imputed = my_model.transform(missing_set)
  File "/home/ketrong/miniconda3/envs/tpot2devenv/lib/python3.10/site-packages/sklearn/utils/_set_output.py", line 157, in wrapped
    data_to_wrap = f(self, X, *args, **kwargs)
  File "/common/ketrong/AutoImputeExp/tpot2_imputetest/Impute_Experiments/transformers.py", line 605, in transform
    return self.gain(X, self.params)
  File "/common/ketrong/AutoImputeExp/tpot2_imputetest/Impute_Experiments/transformers.py", line 636, in gain
    norm_data, norm_parameters = self.normalization(data_x)
  File "/common/ketrong/AutoImputeExp/tpot2_imputetest/Impute_Experiments/transformers.py", line 751, in normalization
    min_val[i] = np.nanmin(norm_data[:,i])
  File "/home/ketrong/miniconda3/envs/tpot2devenv/lib/python3.10/site-packages/pandas/core/frame.py", line 3807, in __getitem__
    indexer = self.columns.get_loc(key)
  File "/home/ketrong/miniconda3/envs/tpot2devenv/lib/python3.10/site-packages/pandas/core/indexes/base.py", line 3809, in get_loc
    self._check_indexing_error(key)
  File "/home/ketrong/miniconda3/envs/tpot2devenv/lib/python3.10/site-packages/pandas/core/indexes/base.py", line 5925, in _check_indexing_error
    raise InvalidIndexError(key)
pandas.errors.InvalidIndexError: (slice(None, None, None), 0)
[W 2023-11-28 16:17:00,326] Trial 19 failed with value None.
[W 2023-11-28 16:17:00,481] Trial 35 failed with parameters: {'model_name': 'GAIN', 'batch_size': 15, 'hint_rate': 0.85, 'alpha': 26, 'iterations': 1} because of the following error: InvalidIndexError((slice(None, None, None), 0)).
Traceback (most recent call last):
  File "/home/ketrong/miniconda3/envs/tpot2devenv/lib/python3.10/site-packages/pandas/core/indexes/base.py", line 3802, in get_loc
    return self._engine.get_loc(casted_key)
  File "pandas/_libs/index.pyx", line 138, in pandas._libs.index.IndexEngine.get_loc
  File "pandas/_libs/index.pyx", line 144, in pandas._libs.index.IndexEngine.get_loc
TypeError: '(slice(None, None, None), 0)' is an invalid key

During handling of the above exception, another exception occurred:

Traceback (most recent call last):
  File "/home/ketrong/miniconda3/envs/tpot2devenv/lib/python3.10/site-packages/optuna/study/_optimize.py", line 200, in _run_trial
    value_or_values = func(trial)
  File "/common/ketrong/AutoImputeExp/tpot2_imputetest/Impute_Experiments/autoimpute.py", line 59, in obj
    return autoutils.score(trial, splitting, my_model, X, self.missing_set_train, self.masked_set_train)
  File "/common/ketrong/AutoImputeExp/tpot2_imputetest/Impute_Experiments/autoutils.py", line 62, in score
    imputed = my_model.transform(missing_set)
  File "/home/ketrong/miniconda3/envs/tpot2devenv/lib/python3.10/site-packages/sklearn/utils/_set_output.py", line 157, in wrapped
    data_to_wrap = f(self, X, *args, **kwargs)
  File "/common/ketrong/AutoImputeExp/tpot2_imputetest/Impute_Experiments/transformers.py", line 605, in transform
    return self.gain(X, self.params)
  File "/common/ketrong/AutoImputeExp/tpot2_imputetest/Impute_Experiments/transformers.py", line 636, in gain
    norm_data, norm_parameters = self.normalization(data_x)
  File "/common/ketrong/AutoImputeExp/tpot2_imputetest/Impute_Experiments/transformers.py", line 751, in normalization
    min_val[i] = np.nanmin(norm_data[:,i])
  File "/home/ketrong/miniconda3/envs/tpot2devenv/lib/python3.10/site-packages/pandas/core/frame.py", line 3807, in __getitem__
    indexer = self.columns.get_loc(key)
  File "/home/ketrong/miniconda3/envs/tpot2devenv/lib/python3.10/site-packages/pandas/core/indexes/base.py", line 3809, in get_loc
    self._check_indexing_error(key)
  File "/home/ketrong/miniconda3/envs/tpot2devenv/lib/python3.10/site-packages/pandas/core/indexes/base.py", line 5925, in _check_indexing_error
    raise InvalidIndexError(key)
pandas.errors.InvalidIndexError: (slice(None, None, None), 0)
[W 2023-11-28 16:17:00,482] Trial 35 failed with value None.
[W 2023-11-28 16:17:00,631] Trial 38 failed with parameters: {'model_name': 'GAIN', 'batch_size': 1, 'hint_rate': 0.87, 'alpha': 7, 'iterations': 71537} because of the following error: InvalidIndexError((slice(None, None, None), 0)).
Traceback (most recent call last):
  File "/home/ketrong/miniconda3/envs/tpot2devenv/lib/python3.10/site-packages/pandas/core/indexes/base.py", line 3802, in get_loc
    return self._engine.get_loc(casted_key)
  File "pandas/_libs/index.pyx", line 138, in pandas._libs.index.IndexEngine.get_loc
  File "pandas/_libs/index.pyx", line 144, in pandas._libs.index.IndexEngine.get_loc
TypeError: '(slice(None, None, None), 0)' is an invalid key

During handling of the above exception, another exception occurred:

Traceback (most recent call last):
  File "/home/ketrong/miniconda3/envs/tpot2devenv/lib/python3.10/site-packages/optuna/study/_optimize.py", line 200, in _run_trial
    value_or_values = func(trial)
  File "/common/ketrong/AutoImputeExp/tpot2_imputetest/Impute_Experiments/autoimpute.py", line 59, in obj
    return autoutils.score(trial, splitting, my_model, X, self.missing_set_train, self.masked_set_train)
  File "/common/ketrong/AutoImputeExp/tpot2_imputetest/Impute_Experiments/autoutils.py", line 62, in score
    imputed = my_model.transform(missing_set)
  File "/home/ketrong/miniconda3/envs/tpot2devenv/lib/python3.10/site-packages/sklearn/utils/_set_output.py", line 157, in wrapped
    data_to_wrap = f(self, X, *args, **kwargs)
  File "/common/ketrong/AutoImputeExp/tpot2_imputetest/Impute_Experiments/transformers.py", line 605, in transform
    return self.gain(X, self.params)
  File "/common/ketrong/AutoImputeExp/tpot2_imputetest/Impute_Experiments/transformers.py", line 636, in gain
    norm_data, norm_parameters = self.normalization(data_x)
  File "/common/ketrong/AutoImputeExp/tpot2_imputetest/Impute_Experiments/transformers.py", line 751, in normalization
    min_val[i] = np.nanmin(norm_data[:,i])
  File "/home/ketrong/miniconda3/envs/tpot2devenv/lib/python3.10/site-packages/pandas/core/frame.py", line 3807, in __getitem__
    indexer = self.columns.get_loc(key)
  File "/home/ketrong/miniconda3/envs/tpot2devenv/lib/python3.10/site-packages/pandas/core/indexes/base.py", line 3809, in get_loc
    self._check_indexing_error(key)
  File "/home/ketrong/miniconda3/envs/tpot2devenv/lib/python3.10/site-packages/pandas/core/indexes/base.py", line 5925, in _check_indexing_error
    raise InvalidIndexError(key)
pandas.errors.InvalidIndexError: (slice(None, None, None), 0)
[W 2023-11-28 16:17:00,632] Trial 38 failed with value None.
[W 2023-11-28 16:17:00,781] Trial 37 failed with parameters: {'model_name': 'GAIN', 'batch_size': 1, 'hint_rate': 0.76, 'alpha': 60, 'iterations': 92737} because of the following error: InvalidIndexError((slice(None, None, None), 0)).
Traceback (most recent call last):
  File "/home/ketrong/miniconda3/envs/tpot2devenv/lib/python3.10/site-packages/pandas/core/indexes/base.py", line 3802, in get_loc
    return self._engine.get_loc(casted_key)
  File "pandas/_libs/index.pyx", line 138, in pandas._libs.index.IndexEngine.get_loc
  File "pandas/_libs/index.pyx", line 144, in pandas._libs.index.IndexEngine.get_loc
TypeError: '(slice(None, None, None), 0)' is an invalid key

During handling of the above exception, another exception occurred:

Traceback (most recent call last):
  File "/home/ketrong/miniconda3/envs/tpot2devenv/lib/python3.10/site-packages/optuna/study/_optimize.py", line 200, in _run_trial
    value_or_values = func(trial)
  File "/common/ketrong/AutoImputeExp/tpot2_imputetest/Impute_Experiments/autoimpute.py", line 59, in obj
    return autoutils.score(trial, splitting, my_model, X, self.missing_set_train, self.masked_set_train)
  File "/common/ketrong/AutoImputeExp/tpot2_imputetest/Impute_Experiments/autoutils.py", line 62, in score
    imputed = my_model.transform(missing_set)
  File "/home/ketrong/miniconda3/envs/tpot2devenv/lib/python3.10/site-packages/sklearn/utils/_set_output.py", line 157, in wrapped
    data_to_wrap = f(self, X, *args, **kwargs)
  File "/common/ketrong/AutoImputeExp/tpot2_imputetest/Impute_Experiments/transformers.py", line 605, in transform
    return self.gain(X, self.params)
  File "/common/ketrong/AutoImputeExp/tpot2_imputetest/Impute_Experiments/transformers.py", line 636, in gain
    norm_data, norm_parameters = self.normalization(data_x)
  File "/common/ketrong/AutoImputeExp/tpot2_imputetest/Impute_Experiments/transformers.py", line 751, in normalization
    min_val[i] = np.nanmin(norm_data[:,i])
  File "/home/ketrong/miniconda3/envs/tpot2devenv/lib/python3.10/site-packages/pandas/core/frame.py", line 3807, in __getitem__
    indexer = self.columns.get_loc(key)
  File "/home/ketrong/miniconda3/envs/tpot2devenv/lib/python3.10/site-packages/pandas/core/indexes/base.py", line 3809, in get_loc
    self._check_indexing_error(key)
  File "/home/ketrong/miniconda3/envs/tpot2devenv/lib/python3.10/site-packages/pandas/core/indexes/base.py", line 5925, in _check_indexing_error
    raise InvalidIndexError(key)
pandas.errors.InvalidIndexError: (slice(None, None, None), 0)
[W 2023-11-28 16:17:00,782] Trial 37 failed with value None.
[W 2023-11-28 16:17:00,930] Trial 39 failed with parameters: {'model_name': 'GAIN', 'batch_size': 7, 'hint_rate': 0.7100000000000001, 'alpha': 57, 'iterations': 9008} because of the following error: InvalidIndexError((slice(None, None, None), 0)).
Traceback (most recent call last):
  File "/home/ketrong/miniconda3/envs/tpot2devenv/lib/python3.10/site-packages/pandas/core/indexes/base.py", line 3802, in get_loc
    return self._engine.get_loc(casted_key)
  File "pandas/_libs/index.pyx", line 138, in pandas._libs.index.IndexEngine.get_loc
  File "pandas/_libs/index.pyx", line 144, in pandas._libs.index.IndexEngine.get_loc
TypeError: '(slice(None, None, None), 0)' is an invalid key

During handling of the above exception, another exception occurred:

Traceback (most recent call last):
  File "/home/ketrong/miniconda3/envs/tpot2devenv/lib/python3.10/site-packages/optuna/study/_optimize.py", line 200, in _run_trial
    value_or_values = func(trial)
  File "/common/ketrong/AutoImputeExp/tpot2_imputetest/Impute_Experiments/autoimpute.py", line 59, in obj
    return autoutils.score(trial, splitting, my_model, X, self.missing_set_train, self.masked_set_train)
  File "/common/ketrong/AutoImputeExp/tpot2_imputetest/Impute_Experiments/autoutils.py", line 62, in score
    imputed = my_model.transform(missing_set)
  File "/home/ketrong/miniconda3/envs/tpot2devenv/lib/python3.10/site-packages/sklearn/utils/_set_output.py", line 157, in wrapped
    data_to_wrap = f(self, X, *args, **kwargs)
  File "/common/ketrong/AutoImputeExp/tpot2_imputetest/Impute_Experiments/transformers.py", line 605, in transform
    return self.gain(X, self.params)
  File "/common/ketrong/AutoImputeExp/tpot2_imputetest/Impute_Experiments/transformers.py", line 636, in gain
    norm_data, norm_parameters = self.normalization(data_x)
  File "/common/ketrong/AutoImputeExp/tpot2_imputetest/Impute_Experiments/transformers.py", line 751, in normalization
    min_val[i] = np.nanmin(norm_data[:,i])
  File "/home/ketrong/miniconda3/envs/tpot2devenv/lib/python3.10/site-packages/pandas/core/frame.py", line 3807, in __getitem__
    indexer = self.columns.get_loc(key)
  File "/home/ketrong/miniconda3/envs/tpot2devenv/lib/python3.10/site-packages/pandas/core/indexes/base.py", line 3809, in get_loc
    self._check_indexing_error(key)
  File "/home/ketrong/miniconda3/envs/tpot2devenv/lib/python3.10/site-packages/pandas/core/indexes/base.py", line 5925, in _check_indexing_error
    raise InvalidIndexError(key)
pandas.errors.InvalidIndexError: (slice(None, None, None), 0)
[W 2023-11-28 16:17:00,930] Trial 39 failed with value None.
[W 2023-11-28 16:17:01,076] Trial 43 failed with parameters: {'model_name': 'GAIN', 'batch_size': 2, 'hint_rate': 0.31, 'alpha': 21, 'iterations': 26013} because of the following error: InvalidIndexError((slice(None, None, None), 0)).
Traceback (most recent call last):
  File "/home/ketrong/miniconda3/envs/tpot2devenv/lib/python3.10/site-packages/pandas/core/indexes/base.py", line 3802, in get_loc
    return self._engine.get_loc(casted_key)
  File "pandas/_libs/index.pyx", line 138, in pandas._libs.index.IndexEngine.get_loc
  File "pandas/_libs/index.pyx", line 144, in pandas._libs.index.IndexEngine.get_loc
TypeError: '(slice(None, None, None), 0)' is an invalid key

During handling of the above exception, another exception occurred:

Traceback (most recent call last):
  File "/home/ketrong/miniconda3/envs/tpot2devenv/lib/python3.10/site-packages/optuna/study/_optimize.py", line 200, in _run_trial
    value_or_values = func(trial)
  File "/common/ketrong/AutoImputeExp/tpot2_imputetest/Impute_Experiments/autoimpute.py", line 59, in obj
    return autoutils.score(trial, splitting, my_model, X, self.missing_set_train, self.masked_set_train)
  File "/common/ketrong/AutoImputeExp/tpot2_imputetest/Impute_Experiments/autoutils.py", line 62, in score
    imputed = my_model.transform(missing_set)
  File "/home/ketrong/miniconda3/envs/tpot2devenv/lib/python3.10/site-packages/sklearn/utils/_set_output.py", line 157, in wrapped
    data_to_wrap = f(self, X, *args, **kwargs)
  File "/common/ketrong/AutoImputeExp/tpot2_imputetest/Impute_Experiments/transformers.py", line 605, in transform
    return self.gain(X, self.params)
  File "/common/ketrong/AutoImputeExp/tpot2_imputetest/Impute_Experiments/transformers.py", line 636, in gain
    norm_data, norm_parameters = self.normalization(data_x)
  File "/common/ketrong/AutoImputeExp/tpot2_imputetest/Impute_Experiments/transformers.py", line 751, in normalization
    min_val[i] = np.nanmin(norm_data[:,i])
  File "/home/ketrong/miniconda3/envs/tpot2devenv/lib/python3.10/site-packages/pandas/core/frame.py", line 3807, in __getitem__
    indexer = self.columns.get_loc(key)
  File "/home/ketrong/miniconda3/envs/tpot2devenv/lib/python3.10/site-packages/pandas/core/indexes/base.py", line 3809, in get_loc
    self._check_indexing_error(key)
  File "/home/ketrong/miniconda3/envs/tpot2devenv/lib/python3.10/site-packages/pandas/core/indexes/base.py", line 5925, in _check_indexing_error
    raise InvalidIndexError(key)
pandas.errors.InvalidIndexError: (slice(None, None, None), 0)
[W 2023-11-28 16:17:01,079] Trial 43 failed with value None.
[W 2023-11-28 16:17:01,229] Trial 36 failed with parameters: {'model_name': 'GAIN', 'batch_size': 5, 'hint_rate': 0.85, 'alpha': 60, 'iterations': 53} because of the following error: InvalidIndexError((slice(None, None, None), 0)).
Traceback (most recent call last):
  File "/home/ketrong/miniconda3/envs/tpot2devenv/lib/python3.10/site-packages/pandas/core/indexes/base.py", line 3802, in get_loc
    return self._engine.get_loc(casted_key)
  File "pandas/_libs/index.pyx", line 138, in pandas._libs.index.IndexEngine.get_loc
  File "pandas/_libs/index.pyx", line 144, in pandas._libs.index.IndexEngine.get_loc
TypeError: '(slice(None, None, None), 0)' is an invalid key

During handling of the above exception, another exception occurred:

Traceback (most recent call last):
  File "/home/ketrong/miniconda3/envs/tpot2devenv/lib/python3.10/site-packages/optuna/study/_optimize.py", line 200, in _run_trial
    value_or_values = func(trial)
  File "/common/ketrong/AutoImputeExp/tpot2_imputetest/Impute_Experiments/autoimpute.py", line 59, in obj
    return autoutils.score(trial, splitting, my_model, X, self.missing_set_train, self.masked_set_train)
  File "/common/ketrong/AutoImputeExp/tpot2_imputetest/Impute_Experiments/autoutils.py", line 62, in score
    imputed = my_model.transform(missing_set)
  File "/home/ketrong/miniconda3/envs/tpot2devenv/lib/python3.10/site-packages/sklearn/utils/_set_output.py", line 157, in wrapped
    data_to_wrap = f(self, X, *args, **kwargs)
  File "/common/ketrong/AutoImputeExp/tpot2_imputetest/Impute_Experiments/transformers.py", line 605, in transform
    return self.gain(X, self.params)
  File "/common/ketrong/AutoImputeExp/tpot2_imputetest/Impute_Experiments/transformers.py", line 636, in gain
    norm_data, norm_parameters = self.normalization(data_x)
  File "/common/ketrong/AutoImputeExp/tpot2_imputetest/Impute_Experiments/transformers.py", line 751, in normalization
    min_val[i] = np.nanmin(norm_data[:,i])
  File "/home/ketrong/miniconda3/envs/tpot2devenv/lib/python3.10/site-packages/pandas/core/frame.py", line 3807, in __getitem__
    indexer = self.columns.get_loc(key)
  File "/home/ketrong/miniconda3/envs/tpot2devenv/lib/python3.10/site-packages/pandas/core/indexes/base.py", line 3809, in get_loc
    self._check_indexing_error(key)
  File "/home/ketrong/miniconda3/envs/tpot2devenv/lib/python3.10/site-packages/pandas/core/indexes/base.py", line 5925, in _check_indexing_error
    raise InvalidIndexError(key)
pandas.errors.InvalidIndexError: (slice(None, None, None), 0)
[W 2023-11-28 16:17:01,229] Trial 36 failed with value None.
[W 2023-11-28 16:17:01,381] Trial 41 failed with parameters: {'model_name': 'GAIN', 'batch_size': 93, 'hint_rate': 0.51, 'alpha': 63, 'iterations': 81509} because of the following error: InvalidIndexError((slice(None, None, None), 0)).
Traceback (most recent call last):
  File "/home/ketrong/miniconda3/envs/tpot2devenv/lib/python3.10/site-packages/pandas/core/indexes/base.py", line 3802, in get_loc
    return self._engine.get_loc(casted_key)
  File "pandas/_libs/index.pyx", line 138, in pandas._libs.index.IndexEngine.get_loc
  File "pandas/_libs/index.pyx", line 144, in pandas._libs.index.IndexEngine.get_loc
TypeError: '(slice(None, None, None), 0)' is an invalid key

During handling of the above exception, another exception occurred:

Traceback (most recent call last):
  File "/home/ketrong/miniconda3/envs/tpot2devenv/lib/python3.10/site-packages/optuna/study/_optimize.py", line 200, in _run_trial
    value_or_values = func(trial)
  File "/common/ketrong/AutoImputeExp/tpot2_imputetest/Impute_Experiments/autoimpute.py", line 59, in obj
    return autoutils.score(trial, splitting, my_model, X, self.missing_set_train, self.masked_set_train)
  File "/common/ketrong/AutoImputeExp/tpot2_imputetest/Impute_Experiments/autoutils.py", line 62, in score
    imputed = my_model.transform(missing_set)
  File "/home/ketrong/miniconda3/envs/tpot2devenv/lib/python3.10/site-packages/sklearn/utils/_set_output.py", line 157, in wrapped
    data_to_wrap = f(self, X, *args, **kwargs)
  File "/common/ketrong/AutoImputeExp/tpot2_imputetest/Impute_Experiments/transformers.py", line 605, in transform
    return self.gain(X, self.params)
  File "/common/ketrong/AutoImputeExp/tpot2_imputetest/Impute_Experiments/transformers.py", line 636, in gain
    norm_data, norm_parameters = self.normalization(data_x)
  File "/common/ketrong/AutoImputeExp/tpot2_imputetest/Impute_Experiments/transformers.py", line 751, in normalization
    min_val[i] = np.nanmin(norm_data[:,i])
  File "/home/ketrong/miniconda3/envs/tpot2devenv/lib/python3.10/site-packages/pandas/core/frame.py", line 3807, in __getitem__
    indexer = self.columns.get_loc(key)
  File "/home/ketrong/miniconda3/envs/tpot2devenv/lib/python3.10/site-packages/pandas/core/indexes/base.py", line 3809, in get_loc
    self._check_indexing_error(key)
  File "/home/ketrong/miniconda3/envs/tpot2devenv/lib/python3.10/site-packages/pandas/core/indexes/base.py", line 5925, in _check_indexing_error
    raise InvalidIndexError(key)
pandas.errors.InvalidIndexError: (slice(None, None, None), 0)
[W 2023-11-28 16:17:01,382] Trial 41 failed with value None.
[W 2023-11-28 16:17:01,527] Trial 40 failed with parameters: {'model_name': 'GAIN', 'batch_size': 2, 'hint_rate': 0.56, 'alpha': 69, 'iterations': 1} because of the following error: InvalidIndexError((slice(None, None, None), 0)).
Traceback (most recent call last):
  File "/home/ketrong/miniconda3/envs/tpot2devenv/lib/python3.10/site-packages/pandas/core/indexes/base.py", line 3802, in get_loc
    return self._engine.get_loc(casted_key)
  File "pandas/_libs/index.pyx", line 138, in pandas._libs.index.IndexEngine.get_loc
  File "pandas/_libs/index.pyx", line 144, in pandas._libs.index.IndexEngine.get_loc
TypeError: '(slice(None, None, None), 0)' is an invalid key

During handling of the above exception, another exception occurred:

Traceback (most recent call last):
  File "/home/ketrong/miniconda3/envs/tpot2devenv/lib/python3.10/site-packages/optuna/study/_optimize.py", line 200, in _run_trial
    value_or_values = func(trial)
  File "/common/ketrong/AutoImputeExp/tpot2_imputetest/Impute_Experiments/autoimpute.py", line 59, in obj
    return autoutils.score(trial, splitting, my_model, X, self.missing_set_train, self.masked_set_train)
  File "/common/ketrong/AutoImputeExp/tpot2_imputetest/Impute_Experiments/autoutils.py", line 62, in score
    imputed = my_model.transform(missing_set)
  File "/home/ketrong/miniconda3/envs/tpot2devenv/lib/python3.10/site-packages/sklearn/utils/_set_output.py", line 157, in wrapped
    data_to_wrap = f(self, X, *args, **kwargs)
  File "/common/ketrong/AutoImputeExp/tpot2_imputetest/Impute_Experiments/transformers.py", line 605, in transform
    return self.gain(X, self.params)
  File "/common/ketrong/AutoImputeExp/tpot2_imputetest/Impute_Experiments/transformers.py", line 636, in gain
    norm_data, norm_parameters = self.normalization(data_x)
  File "/common/ketrong/AutoImputeExp/tpot2_imputetest/Impute_Experiments/transformers.py", line 751, in normalization
    min_val[i] = np.nanmin(norm_data[:,i])
  File "/home/ketrong/miniconda3/envs/tpot2devenv/lib/python3.10/site-packages/pandas/core/frame.py", line 3807, in __getitem__
    indexer = self.columns.get_loc(key)
  File "/home/ketrong/miniconda3/envs/tpot2devenv/lib/python3.10/site-packages/pandas/core/indexes/base.py", line 3809, in get_loc
    self._check_indexing_error(key)
  File "/home/ketrong/miniconda3/envs/tpot2devenv/lib/python3.10/site-packages/pandas/core/indexes/base.py", line 5925, in _check_indexing_error
    raise InvalidIndexError(key)
pandas.errors.InvalidIndexError: (slice(None, None, None), 0)
[W 2023-11-28 16:17:01,529] Trial 40 failed with value None.
[W 2023-11-28 16:17:01,676] Trial 42 failed with parameters: {'model_name': 'GAIN', 'batch_size': 759, 'hint_rate': 0.06999999999999999, 'alpha': 46, 'iterations': 747} because of the following error: InvalidIndexError((slice(None, None, None), 0)).
Traceback (most recent call last):
  File "/home/ketrong/miniconda3/envs/tpot2devenv/lib/python3.10/site-packages/pandas/core/indexes/base.py", line 3802, in get_loc
    return self._engine.get_loc(casted_key)
  File "pandas/_libs/index.pyx", line 138, in pandas._libs.index.IndexEngine.get_loc
  File "pandas/_libs/index.pyx", line 144, in pandas._libs.index.IndexEngine.get_loc
TypeError: '(slice(None, None, None), 0)' is an invalid key

During handling of the above exception, another exception occurred:

Traceback (most recent call last):
  File "/home/ketrong/miniconda3/envs/tpot2devenv/lib/python3.10/site-packages/optuna/study/_optimize.py", line 200, in _run_trial
    value_or_values = func(trial)
  File "/common/ketrong/AutoImputeExp/tpot2_imputetest/Impute_Experiments/autoimpute.py", line 59, in obj
    return autoutils.score(trial, splitting, my_model, X, self.missing_set_train, self.masked_set_train)
  File "/common/ketrong/AutoImputeExp/tpot2_imputetest/Impute_Experiments/autoutils.py", line 62, in score
    imputed = my_model.transform(missing_set)
  File "/home/ketrong/miniconda3/envs/tpot2devenv/lib/python3.10/site-packages/sklearn/utils/_set_output.py", line 157, in wrapped
    data_to_wrap = f(self, X, *args, **kwargs)
  File "/common/ketrong/AutoImputeExp/tpot2_imputetest/Impute_Experiments/transformers.py", line 605, in transform
    return self.gain(X, self.params)
  File "/common/ketrong/AutoImputeExp/tpot2_imputetest/Impute_Experiments/transformers.py", line 636, in gain
    norm_data, norm_parameters = self.normalization(data_x)
  File "/common/ketrong/AutoImputeExp/tpot2_imputetest/Impute_Experiments/transformers.py", line 751, in normalization
    min_val[i] = np.nanmin(norm_data[:,i])
  File "/home/ketrong/miniconda3/envs/tpot2devenv/lib/python3.10/site-packages/pandas/core/frame.py", line 3807, in __getitem__
    indexer = self.columns.get_loc(key)
  File "/home/ketrong/miniconda3/envs/tpot2devenv/lib/python3.10/site-packages/pandas/core/indexes/base.py", line 3809, in get_loc
    self._check_indexing_error(key)
  File "/home/ketrong/miniconda3/envs/tpot2devenv/lib/python3.10/site-packages/pandas/core/indexes/base.py", line 5925, in _check_indexing_error
    raise InvalidIndexError(key)
pandas.errors.InvalidIndexError: (slice(None, None, None), 0)
[W 2023-11-28 16:17:01,677] Trial 42 failed with value None.
[W 2023-11-28 16:17:01,825] Trial 45 failed with parameters: {'model_name': 'GAIN', 'batch_size': 602, 'hint_rate': 0.7000000000000001, 'alpha': 16, 'iterations': 1124} because of the following error: InvalidIndexError((slice(None, None, None), 0)).
Traceback (most recent call last):
  File "/home/ketrong/miniconda3/envs/tpot2devenv/lib/python3.10/site-packages/pandas/core/indexes/base.py", line 3802, in get_loc
    return self._engine.get_loc(casted_key)
  File "pandas/_libs/index.pyx", line 138, in pandas._libs.index.IndexEngine.get_loc
  File "pandas/_libs/index.pyx", line 144, in pandas._libs.index.IndexEngine.get_loc
TypeError: '(slice(None, None, None), 0)' is an invalid key

During handling of the above exception, another exception occurred:

Traceback (most recent call last):
  File "/home/ketrong/miniconda3/envs/tpot2devenv/lib/python3.10/site-packages/optuna/study/_optimize.py", line 200, in _run_trial
    value_or_values = func(trial)
  File "/common/ketrong/AutoImputeExp/tpot2_imputetest/Impute_Experiments/autoimpute.py", line 59, in obj
    return autoutils.score(trial, splitting, my_model, X, self.missing_set_train, self.masked_set_train)
  File "/common/ketrong/AutoImputeExp/tpot2_imputetest/Impute_Experiments/autoutils.py", line 62, in score
    imputed = my_model.transform(missing_set)
  File "/home/ketrong/miniconda3/envs/tpot2devenv/lib/python3.10/site-packages/sklearn/utils/_set_output.py", line 157, in wrapped
    data_to_wrap = f(self, X, *args, **kwargs)
  File "/common/ketrong/AutoImputeExp/tpot2_imputetest/Impute_Experiments/transformers.py", line 605, in transform
    return self.gain(X, self.params)
  File "/common/ketrong/AutoImputeExp/tpot2_imputetest/Impute_Experiments/transformers.py", line 636, in gain
    norm_data, norm_parameters = self.normalization(data_x)
  File "/common/ketrong/AutoImputeExp/tpot2_imputetest/Impute_Experiments/transformers.py", line 751, in normalization
    min_val[i] = np.nanmin(norm_data[:,i])
  File "/home/ketrong/miniconda3/envs/tpot2devenv/lib/python3.10/site-packages/pandas/core/frame.py", line 3807, in __getitem__
    indexer = self.columns.get_loc(key)
  File "/home/ketrong/miniconda3/envs/tpot2devenv/lib/python3.10/site-packages/pandas/core/indexes/base.py", line 3809, in get_loc
    self._check_indexing_error(key)
  File "/home/ketrong/miniconda3/envs/tpot2devenv/lib/python3.10/site-packages/pandas/core/indexes/base.py", line 5925, in _check_indexing_error
    raise InvalidIndexError(key)
pandas.errors.InvalidIndexError: (slice(None, None, None), 0)
[W 2023-11-28 16:17:01,826] Trial 45 failed with value None.
[W 2023-11-28 16:17:01,977] Trial 46 failed with parameters: {'model_name': 'GAIN', 'batch_size': 1, 'hint_rate': 0.5700000000000001, 'alpha': 32, 'iterations': 1} because of the following error: InvalidIndexError((slice(None, None, None), 0)).
Traceback (most recent call last):
  File "/home/ketrong/miniconda3/envs/tpot2devenv/lib/python3.10/site-packages/pandas/core/indexes/base.py", line 3802, in get_loc
    return self._engine.get_loc(casted_key)
  File "pandas/_libs/index.pyx", line 138, in pandas._libs.index.IndexEngine.get_loc
  File "pandas/_libs/index.pyx", line 144, in pandas._libs.index.IndexEngine.get_loc
TypeError: '(slice(None, None, None), 0)' is an invalid key

During handling of the above exception, another exception occurred:

Traceback (most recent call last):
  File "/home/ketrong/miniconda3/envs/tpot2devenv/lib/python3.10/site-packages/optuna/study/_optimize.py", line 200, in _run_trial
    value_or_values = func(trial)
  File "/common/ketrong/AutoImputeExp/tpot2_imputetest/Impute_Experiments/autoimpute.py", line 59, in obj
    return autoutils.score(trial, splitting, my_model, X, self.missing_set_train, self.masked_set_train)
  File "/common/ketrong/AutoImputeExp/tpot2_imputetest/Impute_Experiments/autoutils.py", line 62, in score
    imputed = my_model.transform(missing_set)
  File "/home/ketrong/miniconda3/envs/tpot2devenv/lib/python3.10/site-packages/sklearn/utils/_set_output.py", line 157, in wrapped
    data_to_wrap = f(self, X, *args, **kwargs)
  File "/common/ketrong/AutoImputeExp/tpot2_imputetest/Impute_Experiments/transformers.py", line 605, in transform
    return self.gain(X, self.params)
  File "/common/ketrong/AutoImputeExp/tpot2_imputetest/Impute_Experiments/transformers.py", line 636, in gain
    norm_data, norm_parameters = self.normalization(data_x)
  File "/common/ketrong/AutoImputeExp/tpot2_imputetest/Impute_Experiments/transformers.py", line 751, in normalization
    min_val[i] = np.nanmin(norm_data[:,i])
  File "/home/ketrong/miniconda3/envs/tpot2devenv/lib/python3.10/site-packages/pandas/core/frame.py", line 3807, in __getitem__
    indexer = self.columns.get_loc(key)
  File "/home/ketrong/miniconda3/envs/tpot2devenv/lib/python3.10/site-packages/pandas/core/indexes/base.py", line 3809, in get_loc
    self._check_indexing_error(key)
  File "/home/ketrong/miniconda3/envs/tpot2devenv/lib/python3.10/site-packages/pandas/core/indexes/base.py", line 5925, in _check_indexing_error
    raise InvalidIndexError(key)
pandas.errors.InvalidIndexError: (slice(None, None, None), 0)
[W 2023-11-28 16:17:01,978] Trial 46 failed with value None.
[W 2023-11-28 16:17:01,978] Trial 47 failed with parameters: {'model_name': 'GAIN', 'batch_size': 638, 'hint_rate': 0.42000000000000004, 'alpha': 55, 'iterations': 2} because of the following error: InvalidIndexError((slice(None, None, None), 0)).
Traceback (most recent call last):
  File "/home/ketrong/miniconda3/envs/tpot2devenv/lib/python3.10/site-packages/pandas/core/indexes/base.py", line 3802, in get_loc
    return self._engine.get_loc(casted_key)
  File "pandas/_libs/index.pyx", line 138, in pandas._libs.index.IndexEngine.get_loc
  File "pandas/_libs/index.pyx", line 144, in pandas._libs.index.IndexEngine.get_loc
TypeError: '(slice(None, None, None), 0)' is an invalid key

During handling of the above exception, another exception occurred:

Traceback (most recent call last):
  File "/home/ketrong/miniconda3/envs/tpot2devenv/lib/python3.10/site-packages/optuna/study/_optimize.py", line 200, in _run_trial
    value_or_values = func(trial)
  File "/common/ketrong/AutoImputeExp/tpot2_imputetest/Impute_Experiments/autoimpute.py", line 59, in obj
    return autoutils.score(trial, splitting, my_model, X, self.missing_set_train, self.masked_set_train)
  File "/common/ketrong/AutoImputeExp/tpot2_imputetest/Impute_Experiments/autoutils.py", line 62, in score
    imputed = my_model.transform(missing_set)
  File "/home/ketrong/miniconda3/envs/tpot2devenv/lib/python3.10/site-packages/sklearn/utils/_set_output.py", line 157, in wrapped
    data_to_wrap = f(self, X, *args, **kwargs)
  File "/common/ketrong/AutoImputeExp/tpot2_imputetest/Impute_Experiments/transformers.py", line 605, in transform
    return self.gain(X, self.params)
  File "/common/ketrong/AutoImputeExp/tpot2_imputetest/Impute_Experiments/transformers.py", line 636, in gain
    norm_data, norm_parameters = self.normalization(data_x)
  File "/common/ketrong/AutoImputeExp/tpot2_imputetest/Impute_Experiments/transformers.py", line 751, in normalization
    min_val[i] = np.nanmin(norm_data[:,i])
  File "/home/ketrong/miniconda3/envs/tpot2devenv/lib/python3.10/site-packages/pandas/core/frame.py", line 3807, in __getitem__
    indexer = self.columns.get_loc(key)
  File "/home/ketrong/miniconda3/envs/tpot2devenv/lib/python3.10/site-packages/pandas/core/indexes/base.py", line 3809, in get_loc
    self._check_indexing_error(key)
  File "/home/ketrong/miniconda3/envs/tpot2devenv/lib/python3.10/site-packages/pandas/core/indexes/base.py", line 5925, in _check_indexing_error
    raise InvalidIndexError(key)
pandas.errors.InvalidIndexError: (slice(None, None, None), 0)
[W 2023-11-28 16:17:02,127] Trial 44 failed with parameters: {'model_name': 'GAIN', 'batch_size': 43, 'hint_rate': 0.18000000000000002, 'alpha': 50, 'iterations': 182} because of the following error: InvalidIndexError((slice(None, None, None), 0)).
Traceback (most recent call last):
  File "/home/ketrong/miniconda3/envs/tpot2devenv/lib/python3.10/site-packages/pandas/core/indexes/base.py", line 3802, in get_loc
    return self._engine.get_loc(casted_key)
  File "pandas/_libs/index.pyx", line 138, in pandas._libs.index.IndexEngine.get_loc
  File "pandas/_libs/index.pyx", line 144, in pandas._libs.index.IndexEngine.get_loc
TypeError: '(slice(None, None, None), 0)' is an invalid key

During handling of the above exception, another exception occurred:

Traceback (most recent call last):
  File "/home/ketrong/miniconda3/envs/tpot2devenv/lib/python3.10/site-packages/optuna/study/_optimize.py", line 200, in _run_trial
    value_or_values = func(trial)
  File "/common/ketrong/AutoImputeExp/tpot2_imputetest/Impute_Experiments/autoimpute.py", line 59, in obj
    return autoutils.score(trial, splitting, my_model, X, self.missing_set_train, self.masked_set_train)
  File "/common/ketrong/AutoImputeExp/tpot2_imputetest/Impute_Experiments/autoutils.py", line 62, in score
    imputed = my_model.transform(missing_set)
  File "/home/ketrong/miniconda3/envs/tpot2devenv/lib/python3.10/site-packages/sklearn/utils/_set_output.py", line 157, in wrapped
    data_to_wrap = f(self, X, *args, **kwargs)
  File "/common/ketrong/AutoImputeExp/tpot2_imputetest/Impute_Experiments/transformers.py", line 605, in transform
    return self.gain(X, self.params)
  File "/common/ketrong/AutoImputeExp/tpot2_imputetest/Impute_Experiments/transformers.py", line 636, in gain
    norm_data, norm_parameters = self.normalization(data_x)
  File "/common/ketrong/AutoImputeExp/tpot2_imputetest/Impute_Experiments/transformers.py", line 751, in normalization
    min_val[i] = np.nanmin(norm_data[:,i])
  File "/home/ketrong/miniconda3/envs/tpot2devenv/lib/python3.10/site-packages/pandas/core/frame.py", line 3807, in __getitem__
    indexer = self.columns.get_loc(key)
  File "/home/ketrong/miniconda3/envs/tpot2devenv/lib/python3.10/site-packages/pandas/core/indexes/base.py", line 3809, in get_loc
    self._check_indexing_error(key)
  File "/home/ketrong/miniconda3/envs/tpot2devenv/lib/python3.10/site-packages/pandas/core/indexes/base.py", line 5925, in _check_indexing_error
    raise InvalidIndexError(key)
pandas.errors.InvalidIndexError: (slice(None, None, None), 0)
[W 2023-11-28 16:17:02,129] Trial 44 failed with value None.
[W 2023-11-28 16:17:02,128] Trial 47 failed with value None.
Traceback (most recent call last):
  File "/home/ketrong/miniconda3/envs/tpot2devenv/lib/python3.10/site-packages/pandas/core/indexes/base.py", line 3802, in get_loc
    return self._engine.get_loc(casted_key)
  File "pandas/_libs/index.pyx", line 138, in pandas._libs.index.IndexEngine.get_loc
  File "pandas/_libs/index.pyx", line 144, in pandas._libs.index.IndexEngine.get_loc
TypeError: '(slice(None, None, None), 0)' is an invalid key

During handling of the above exception, another exception occurred:

Traceback (most recent call last):
  File "/common/ketrong/AutoImputeExp/tpot2_imputetest/Impute_Experiments/small_main.py", line 110, in <module>
    main()
  File "/common/ketrong/AutoImputeExp/tpot2_imputetest/Impute_Experiments/small_main.py", line 69, in main
    automodel.fit(X=X_train_missing)
  File "/common/ketrong/AutoImputeExp/tpot2_imputetest/Impute_Experiments/autoimpute.py", line 61, in fit
    self.study.optimize(obj, n_trials=self.n_trials, n_jobs=self.n_jobs, show_progress_bar=self.show_progress, gc_after_trial=self.garbage_collect)
  File "/home/ketrong/miniconda3/envs/tpot2devenv/lib/python3.10/site-packages/optuna/study/study.py", line 451, in optimize
    _optimize(
  File "/home/ketrong/miniconda3/envs/tpot2devenv/lib/python3.10/site-packages/optuna/study/_optimize.py", line 103, in _optimize
    f.result()
  File "/home/ketrong/miniconda3/envs/tpot2devenv/lib/python3.10/concurrent/futures/_base.py", line 451, in result
    return self.__get_result()
  File "/home/ketrong/miniconda3/envs/tpot2devenv/lib/python3.10/concurrent/futures/_base.py", line 403, in __get_result
    raise self._exception
  File "/home/ketrong/miniconda3/envs/tpot2devenv/lib/python3.10/concurrent/futures/thread.py", line 58, in run
    result = self.fn(*self.args, **self.kwargs)
  File "/home/ketrong/miniconda3/envs/tpot2devenv/lib/python3.10/site-packages/optuna/study/_optimize.py", line 163, in _optimize_sequential
    frozen_trial = _run_trial(study, func, catch)
  File "/home/ketrong/miniconda3/envs/tpot2devenv/lib/python3.10/site-packages/optuna/study/_optimize.py", line 251, in _run_trial
    raise func_err
  File "/home/ketrong/miniconda3/envs/tpot2devenv/lib/python3.10/site-packages/optuna/study/_optimize.py", line 200, in _run_trial
    value_or_values = func(trial)
  File "/common/ketrong/AutoImputeExp/tpot2_imputetest/Impute_Experiments/autoimpute.py", line 59, in obj
    return autoutils.score(trial, splitting, my_model, X, self.missing_set_train, self.masked_set_train)
  File "/common/ketrong/AutoImputeExp/tpot2_imputetest/Impute_Experiments/autoutils.py", line 62, in score
    imputed = my_model.transform(missing_set)
  File "/home/ketrong/miniconda3/envs/tpot2devenv/lib/python3.10/site-packages/sklearn/utils/_set_output.py", line 157, in wrapped
    data_to_wrap = f(self, X, *args, **kwargs)
  File "/common/ketrong/AutoImputeExp/tpot2_imputetest/Impute_Experiments/transformers.py", line 605, in transform
    return self.gain(X, self.params)
  File "/common/ketrong/AutoImputeExp/tpot2_imputetest/Impute_Experiments/transformers.py", line 636, in gain
    norm_data, norm_parameters = self.normalization(data_x)
  File "/common/ketrong/AutoImputeExp/tpot2_imputetest/Impute_Experiments/transformers.py", line 751, in normalization
    min_val[i] = np.nanmin(norm_data[:,i])
  File "/home/ketrong/miniconda3/envs/tpot2devenv/lib/python3.10/site-packages/pandas/core/frame.py", line 3807, in __getitem__
    indexer = self.columns.get_loc(key)
  File "/home/ketrong/miniconda3/envs/tpot2devenv/lib/python3.10/site-packages/pandas/core/indexes/base.py", line 3809, in get_loc
    self._check_indexing_error(key)
  File "/home/ketrong/miniconda3/envs/tpot2devenv/lib/python3.10/site-packages/pandas/core/indexes/base.py", line 5925, in _check_indexing_error
    raise InvalidIndexError(key)
pandas.errors.InvalidIndexError: (slice(None, None, None), 0)
srun: error: esplhpc-cp002: task 0: Exited with exit code 1
