/cm/local/apps/slurm/var/spool/job402249/slurm_script: line 19: /common/ketrong/minconda3/etc/profile.d/conda.sh: No such file or directory
/cm/local/apps/slurm/var/spool/job402249/slurm_script: line 22: $'\nconda create --name tpot2devenv -c conda-forge python=3.10\n': command not found
/cm/local/apps/slurm/var/spool/job402249/slurm_script: line 27: $'\npip install -r requirements.txt\n': command not found
RunStart
2023-11-21 09:49:45.021750: I tensorflow/core/util/port.cc:113] oneDNN custom operations are on. You may see slightly different numerical results due to floating-point round-off errors from different computation orders. To turn them off, set the environment variable `TF_ENABLE_ONEDNN_OPTS=0`.
2023-11-21 09:49:45.057040: E external/local_xla/xla/stream_executor/cuda/cuda_dnn.cc:9261] Unable to register cuDNN factory: Attempting to register factory for plugin cuDNN when one has already been registered
2023-11-21 09:49:45.057066: E external/local_xla/xla/stream_executor/cuda/cuda_fft.cc:607] Unable to register cuFFT factory: Attempting to register factory for plugin cuFFT when one has already been registered
2023-11-21 09:49:45.058206: E external/local_xla/xla/stream_executor/cuda/cuda_blas.cc:1515] Unable to register cuBLAS factory: Attempting to register factory for plugin cuBLAS when one has already been registered
2023-11-21 09:49:45.063715: I tensorflow/core/platform/cpu_feature_guard.cc:182] This TensorFlow binary is optimized to use available CPU instructions in performance-critical operations.
To enable the following instructions: AVX2 AVX512F AVX512_VNNI FMA, in other operations, rebuild TensorFlow with the appropriate compiler flags.
2023-11-21 09:49:47.392359: W tensorflow/compiler/tf2tensorrt/utils/py_utils.cc:38] TF-TRT Warning: Could not find TensorRT
WARNING:tensorflow:From /home/ketrong/miniconda3/envs/tpot2devenv/lib/python3.10/site-packages/tensorflow/python/compat/v2_compat.py:108: disable_resource_variables (from tensorflow.python.ops.variable_scope) is deprecated and will be removed in a future version.
Instructions for updating:
non-resource variables are not supported in the long term
working on 
tpot2_imputetest/Impute_Experiments/logs//tpot2_base_normal_6_0.5_MNAR_0
loading data
tpot2_imputetest/Impute_Experiments/data/6_True.pkl
running experiment 1/3 - Does large hyperparameter space improve reconstruction accuracy over simple
[I 2023-11-21 09:50:38,170] A new study created in memory with name: no-name-547bb11b-9214-4fcf-a2c7-23709e73b992
[W 2023-11-21 09:50:38,172] Trial 1 failed with parameters: {'model_name': 'SimpleImputer', 'strategy': 'median'} because of the following error: TypeError("SimpleImputer.__init__() got an unexpected keyword argument 'model_name'").
Traceback (most recent call last):
  File "/home/ketrong/miniconda3/envs/tpot2devenv/lib/python3.10/site-packages/optuna/study/_optimize.py", line 200, in _run_trial
    value_or_values = func(trial)
  File "/common/ketrong/AutoImputeExp/tpot2_imputetest/Impute_Experiments/autoimpute.py", line 57, in obj
    my_model = autoutils.MyModel(random_state = self.random_state, **my_params)
  File "/common/ketrong/AutoImputeExp/tpot2_imputetest/Impute_Experiments/autoutils.py", line 35, in MyModel
    my_model = SimpleImputer(
TypeError: SimpleImputer.__init__() got an unexpected keyword argument 'model_name'
[W 2023-11-21 09:50:38,173] Trial 2 failed with parameters: {'model_name': 'SimpleImputer', 'strategy': 'most_frequent'} because of the following error: TypeError("SimpleImputer.__init__() got an unexpected keyword argument 'model_name'").
Traceback (most recent call last):
  File "/home/ketrong/miniconda3/envs/tpot2devenv/lib/python3.10/site-packages/optuna/study/_optimize.py", line 200, in _run_trial
    value_or_values = func(trial)
  File "/common/ketrong/AutoImputeExp/tpot2_imputetest/Impute_Experiments/autoimpute.py", line 57, in obj
    my_model = autoutils.MyModel(random_state = self.random_state, **my_params)
  File "/common/ketrong/AutoImputeExp/tpot2_imputetest/Impute_Experiments/autoutils.py", line 35, in MyModel
    my_model = SimpleImputer(
TypeError: SimpleImputer.__init__() got an unexpected keyword argument 'model_name'
[W 2023-11-21 09:50:38,174] Trial 0 failed with parameters: {'model_name': 'SimpleImputer', 'strategy': 'median'} because of the following error: TypeError("SimpleImputer.__init__() got an unexpected keyword argument 'model_name'").
Traceback (most recent call last):
  File "/home/ketrong/miniconda3/envs/tpot2devenv/lib/python3.10/site-packages/optuna/study/_optimize.py", line 200, in _run_trial
    value_or_values = func(trial)
  File "/common/ketrong/AutoImputeExp/tpot2_imputetest/Impute_Experiments/autoimpute.py", line 57, in obj
    my_model = autoutils.MyModel(random_state = self.random_state, **my_params)
  File "/common/ketrong/AutoImputeExp/tpot2_imputetest/Impute_Experiments/autoutils.py", line 35, in MyModel
    my_model = SimpleImputer(
TypeError: SimpleImputer.__init__() got an unexpected keyword argument 'model_name'
[W 2023-11-21 09:50:38,298] Trial 0 failed with value None.
[W 2023-11-21 09:50:38,174] Trial 3 failed with parameters: {'model_name': 'SimpleImputer', 'strategy': 'constant'} because of the following error: TypeError("SimpleImputer.__init__() got an unexpected keyword argument 'model_name'").
Traceback (most recent call last):
  File "/home/ketrong/miniconda3/envs/tpot2devenv/lib/python3.10/site-packages/optuna/study/_optimize.py", line 200, in _run_trial
    value_or_values = func(trial)
  File "/common/ketrong/AutoImputeExp/tpot2_imputetest/Impute_Experiments/autoimpute.py", line 57, in obj
    my_model = autoutils.MyModel(random_state = self.random_state, **my_params)
  File "/common/ketrong/AutoImputeExp/tpot2_imputetest/Impute_Experiments/autoutils.py", line 35, in MyModel
    my_model = SimpleImputer(
TypeError: SimpleImputer.__init__() got an unexpected keyword argument 'model_name'
[W 2023-11-21 09:50:38,503] Trial 3 failed with value None.
[W 2023-11-21 09:50:38,176] Trial 5 failed with parameters: {'model_name': 'SimpleImputer', 'strategy': 'most_frequent'} because of the following error: TypeError("SimpleImputer.__init__() got an unexpected keyword argument 'model_name'").
Traceback (most recent call last):
  File "/home/ketrong/miniconda3/envs/tpot2devenv/lib/python3.10/site-packages/optuna/study/_optimize.py", line 200, in _run_trial
    value_or_values = func(trial)
  File "/common/ketrong/AutoImputeExp/tpot2_imputetest/Impute_Experiments/autoimpute.py", line 57, in obj
    my_model = autoutils.MyModel(random_state = self.random_state, **my_params)
  File "/common/ketrong/AutoImputeExp/tpot2_imputetest/Impute_Experiments/autoutils.py", line 35, in MyModel
    my_model = SimpleImputer(
TypeError: SimpleImputer.__init__() got an unexpected keyword argument 'model_name'
[W 2023-11-21 09:50:38,648] Trial 5 failed with value None.
[W 2023-11-21 09:50:38,177] Trial 7 failed with parameters: {'model_name': 'SimpleImputer', 'strategy': 'most_frequent'} because of the following error: TypeError("SimpleImputer.__init__() got an unexpected keyword argument 'model_name'").
Traceback (most recent call last):
  File "/home/ketrong/miniconda3/envs/tpot2devenv/lib/python3.10/site-packages/optuna/study/_optimize.py", line 200, in _run_trial
    value_or_values = func(trial)
  File "/common/ketrong/AutoImputeExp/tpot2_imputetest/Impute_Experiments/autoimpute.py", line 57, in obj
    my_model = autoutils.MyModel(random_state = self.random_state, **my_params)
  File "/common/ketrong/AutoImputeExp/tpot2_imputetest/Impute_Experiments/autoutils.py", line 35, in MyModel
    my_model = SimpleImputer(
TypeError: SimpleImputer.__init__() got an unexpected keyword argument 'model_name'
[W 2023-11-21 09:50:38,790] Trial 7 failed with value None.
[W 2023-11-21 09:50:38,180] Trial 10 failed with parameters: {'model_name': 'SimpleImputer', 'strategy': 'mean'} because of the following error: TypeError("SimpleImputer.__init__() got an unexpected keyword argument 'model_name'").
Traceback (most recent call last):
  File "/home/ketrong/miniconda3/envs/tpot2devenv/lib/python3.10/site-packages/optuna/study/_optimize.py", line 200, in _run_trial
    value_or_values = func(trial)
  File "/common/ketrong/AutoImputeExp/tpot2_imputetest/Impute_Experiments/autoimpute.py", line 57, in obj
    my_model = autoutils.MyModel(random_state = self.random_state, **my_params)
  File "/common/ketrong/AutoImputeExp/tpot2_imputetest/Impute_Experiments/autoutils.py", line 35, in MyModel
    my_model = SimpleImputer(
TypeError: SimpleImputer.__init__() got an unexpected keyword argument 'model_name'
[W 2023-11-21 09:50:38,181] Trial 11 failed with parameters: {'model_name': 'SimpleImputer', 'strategy': 'constant'} because of the following error: TypeError("SimpleImputer.__init__() got an unexpected keyword argument 'model_name'").
Traceback (most recent call last):
  File "/home/ketrong/miniconda3/envs/tpot2devenv/lib/python3.10/site-packages/optuna/study/_optimize.py", line 200, in _run_trial
    value_or_values = func(trial)
  File "/common/ketrong/AutoImputeExp/tpot2_imputetest/Impute_Experiments/autoimpute.py", line 57, in obj
    my_model = autoutils.MyModel(random_state = self.random_state, **my_params)
  File "/common/ketrong/AutoImputeExp/tpot2_imputetest/Impute_Experiments/autoutils.py", line 35, in MyModel
    my_model = SimpleImputer(
TypeError: SimpleImputer.__init__() got an unexpected keyword argument 'model_name'
[W 2023-11-21 09:50:38,934] Trial 11 failed with value None.
[W 2023-11-21 09:50:38,182] Trial 12 failed with parameters: {'model_name': 'SimpleImputer', 'strategy': 'median'} because of the following error: TypeError("SimpleImputer.__init__() got an unexpected keyword argument 'model_name'").
Traceback (most recent call last):
  File "/home/ketrong/miniconda3/envs/tpot2devenv/lib/python3.10/site-packages/optuna/study/_optimize.py", line 200, in _run_trial
    value_or_values = func(trial)
  File "/common/ketrong/AutoImputeExp/tpot2_imputetest/Impute_Experiments/autoimpute.py", line 57, in obj
    my_model = autoutils.MyModel(random_state = self.random_state, **my_params)
  File "/common/ketrong/AutoImputeExp/tpot2_imputetest/Impute_Experiments/autoutils.py", line 35, in MyModel
    my_model = SimpleImputer(
TypeError: SimpleImputer.__init__() got an unexpected keyword argument 'model_name'
[W 2023-11-21 09:50:39,077] Trial 12 failed with value None.
[W 2023-11-21 09:50:38,183] Trial 14 failed with parameters: {'model_name': 'SimpleImputer', 'strategy': 'constant'} because of the following error: TypeError("SimpleImputer.__init__() got an unexpected keyword argument 'model_name'").
Traceback (most recent call last):
  File "/home/ketrong/miniconda3/envs/tpot2devenv/lib/python3.10/site-packages/optuna/study/_optimize.py", line 200, in _run_trial
    value_or_values = func(trial)
  File "/common/ketrong/AutoImputeExp/tpot2_imputetest/Impute_Experiments/autoimpute.py", line 57, in obj
    my_model = autoutils.MyModel(random_state = self.random_state, **my_params)
  File "/common/ketrong/AutoImputeExp/tpot2_imputetest/Impute_Experiments/autoutils.py", line 35, in MyModel
    my_model = SimpleImputer(
TypeError: SimpleImputer.__init__() got an unexpected keyword argument 'model_name'
[W 2023-11-21 09:50:39,220] Trial 14 failed with value None.
[W 2023-11-21 09:50:38,185] Trial 16 failed with parameters: {'model_name': 'SimpleImputer', 'strategy': 'constant'} because of the following error: TypeError("SimpleImputer.__init__() got an unexpected keyword argument 'model_name'").
Traceback (most recent call last):
  File "/home/ketrong/miniconda3/envs/tpot2devenv/lib/python3.10/site-packages/optuna/study/_optimize.py", line 200, in _run_trial
    value_or_values = func(trial)
  File "/common/ketrong/AutoImputeExp/tpot2_imputetest/Impute_Experiments/autoimpute.py", line 57, in obj
    my_model = autoutils.MyModel(random_state = self.random_state, **my_params)
  File "/common/ketrong/AutoImputeExp/tpot2_imputetest/Impute_Experiments/autoutils.py", line 35, in MyModel
    my_model = SimpleImputer(
TypeError: SimpleImputer.__init__() got an unexpected keyword argument 'model_name'
[W 2023-11-21 09:50:39,360] Trial 16 failed with value None.
[W 2023-11-21 09:50:38,186] Trial 18 failed with parameters: {'model_name': 'SimpleImputer', 'strategy': 'median'} because of the following error: TypeError("SimpleImputer.__init__() got an unexpected keyword argument 'model_name'").
Traceback (most recent call last):
  File "/home/ketrong/miniconda3/envs/tpot2devenv/lib/python3.10/site-packages/optuna/study/_optimize.py", line 200, in _run_trial
    value_or_values = func(trial)
  File "/common/ketrong/AutoImputeExp/tpot2_imputetest/Impute_Experiments/autoimpute.py", line 57, in obj
    my_model = autoutils.MyModel(random_state = self.random_state, **my_params)
  File "/common/ketrong/AutoImputeExp/tpot2_imputetest/Impute_Experiments/autoutils.py", line 35, in MyModel
    my_model = SimpleImputer(
TypeError: SimpleImputer.__init__() got an unexpected keyword argument 'model_name'
[W 2023-11-21 09:50:39,500] Trial 18 failed with value None.
[W 2023-11-21 09:50:38,188] Trial 20 failed with parameters: {'model_name': 'SimpleImputer', 'strategy': 'median'} because of the following error: TypeError("SimpleImputer.__init__() got an unexpected keyword argument 'model_name'").
Traceback (most recent call last):
  File "/home/ketrong/miniconda3/envs/tpot2devenv/lib/python3.10/site-packages/optuna/study/_optimize.py", line 200, in _run_trial
    value_or_values = func(trial)
  File "/common/ketrong/AutoImputeExp/tpot2_imputetest/Impute_Experiments/autoimpute.py", line 57, in obj
    my_model = autoutils.MyModel(random_state = self.random_state, **my_params)
  File "/common/ketrong/AutoImputeExp/tpot2_imputetest/Impute_Experiments/autoutils.py", line 35, in MyModel
    my_model = SimpleImputer(
TypeError: SimpleImputer.__init__() got an unexpected keyword argument 'model_name'
[W 2023-11-21 09:50:39,643] Trial 20 failed with value None.
[W 2023-11-21 09:50:38,190] Trial 22 failed with parameters: {'model_name': 'SimpleImputer', 'strategy': 'most_frequent'} because of the following error: TypeError("SimpleImputer.__init__() got an unexpected keyword argument 'model_name'").
Traceback (most recent call last):
  File "/home/ketrong/miniconda3/envs/tpot2devenv/lib/python3.10/site-packages/optuna/study/_optimize.py", line 200, in _run_trial
    value_or_values = func(trial)
  File "/common/ketrong/AutoImputeExp/tpot2_imputetest/Impute_Experiments/autoimpute.py", line 57, in obj
    my_model = autoutils.MyModel(random_state = self.random_state, **my_params)
  File "/common/ketrong/AutoImputeExp/tpot2_imputetest/Impute_Experiments/autoutils.py", line 35, in MyModel
    my_model = SimpleImputer(
TypeError: SimpleImputer.__init__() got an unexpected keyword argument 'model_name'
[W 2023-11-21 09:50:39,785] Trial 22 failed with value None.
[W 2023-11-21 09:50:38,191] Trial 24 failed with parameters: {'model_name': 'SimpleImputer', 'strategy': 'mean'} because of the following error: TypeError("SimpleImputer.__init__() got an unexpected keyword argument 'model_name'").
Traceback (most recent call last):
  File "/home/ketrong/miniconda3/envs/tpot2devenv/lib/python3.10/site-packages/optuna/study/_optimize.py", line 200, in _run_trial
    value_or_values = func(trial)
  File "/common/ketrong/AutoImputeExp/tpot2_imputetest/Impute_Experiments/autoimpute.py", line 57, in obj
    my_model = autoutils.MyModel(random_state = self.random_state, **my_params)
  File "/common/ketrong/AutoImputeExp/tpot2_imputetest/Impute_Experiments/autoutils.py", line 35, in MyModel
    my_model = SimpleImputer(
TypeError: SimpleImputer.__init__() got an unexpected keyword argument 'model_name'
[W 2023-11-21 09:50:39,928] Trial 24 failed with value None.
[W 2023-11-21 09:50:38,193] Trial 26 failed with parameters: {'model_name': 'SimpleImputer', 'strategy': 'median'} because of the following error: TypeError("SimpleImputer.__init__() got an unexpected keyword argument 'model_name'").
Traceback (most recent call last):
  File "/home/ketrong/miniconda3/envs/tpot2devenv/lib/python3.10/site-packages/optuna/study/_optimize.py", line 200, in _run_trial
    value_or_values = func(trial)
  File "/common/ketrong/AutoImputeExp/tpot2_imputetest/Impute_Experiments/autoimpute.py", line 57, in obj
    my_model = autoutils.MyModel(random_state = self.random_state, **my_params)
  File "/common/ketrong/AutoImputeExp/tpot2_imputetest/Impute_Experiments/autoutils.py", line 35, in MyModel
    my_model = SimpleImputer(
TypeError: SimpleImputer.__init__() got an unexpected keyword argument 'model_name'
[W 2023-11-21 09:50:40,072] Trial 26 failed with value None.
[W 2023-11-21 09:50:38,195] Trial 28 failed with parameters: {'model_name': 'SimpleImputer', 'strategy': 'constant'} because of the following error: TypeError("SimpleImputer.__init__() got an unexpected keyword argument 'model_name'").
Traceback (most recent call last):
  File "/home/ketrong/miniconda3/envs/tpot2devenv/lib/python3.10/site-packages/optuna/study/_optimize.py", line 200, in _run_trial
    value_or_values = func(trial)
  File "/common/ketrong/AutoImputeExp/tpot2_imputetest/Impute_Experiments/autoimpute.py", line 57, in obj
    my_model = autoutils.MyModel(random_state = self.random_state, **my_params)
  File "/common/ketrong/AutoImputeExp/tpot2_imputetest/Impute_Experiments/autoutils.py", line 35, in MyModel
    my_model = SimpleImputer(
TypeError: SimpleImputer.__init__() got an unexpected keyword argument 'model_name'
[W 2023-11-21 09:50:40,212] Trial 28 failed with value None.
[W 2023-11-21 09:50:38,196] Trial 30 failed with parameters: {'model_name': 'SimpleImputer', 'strategy': 'mean'} because of the following error: TypeError("SimpleImputer.__init__() got an unexpected keyword argument 'model_name'").
Traceback (most recent call last):
  File "/home/ketrong/miniconda3/envs/tpot2devenv/lib/python3.10/site-packages/optuna/study/_optimize.py", line 200, in _run_trial
    value_or_values = func(trial)
  File "/common/ketrong/AutoImputeExp/tpot2_imputetest/Impute_Experiments/autoimpute.py", line 57, in obj
    my_model = autoutils.MyModel(random_state = self.random_state, **my_params)
  File "/common/ketrong/AutoImputeExp/tpot2_imputetest/Impute_Experiments/autoutils.py", line 35, in MyModel
    my_model = SimpleImputer(
TypeError: SimpleImputer.__init__() got an unexpected keyword argument 'model_name'
[W 2023-11-21 09:50:40,353] Trial 30 failed with value None.
[W 2023-11-21 09:50:38,198] Trial 32 failed with parameters: {'model_name': 'SimpleImputer', 'strategy': 'most_frequent'} because of the following error: TypeError("SimpleImputer.__init__() got an unexpected keyword argument 'model_name'").
Traceback (most recent call last):
  File "/home/ketrong/miniconda3/envs/tpot2devenv/lib/python3.10/site-packages/optuna/study/_optimize.py", line 200, in _run_trial
    value_or_values = func(trial)
  File "/common/ketrong/AutoImputeExp/tpot2_imputetest/Impute_Experiments/autoimpute.py", line 57, in obj
    my_model = autoutils.MyModel(random_state = self.random_state, **my_params)
  File "/common/ketrong/AutoImputeExp/tpot2_imputetest/Impute_Experiments/autoutils.py", line 35, in MyModel
    my_model = SimpleImputer(
TypeError: SimpleImputer.__init__() got an unexpected keyword argument 'model_name'
[W 2023-11-21 09:50:40,496] Trial 32 failed with value None.
[W 2023-11-21 09:50:38,199] Trial 34 failed with parameters: {'model_name': 'SimpleImputer', 'strategy': 'most_frequent'} because of the following error: TypeError("SimpleImputer.__init__() got an unexpected keyword argument 'model_name'").
Traceback (most recent call last):
  File "/home/ketrong/miniconda3/envs/tpot2devenv/lib/python3.10/site-packages/optuna/study/_optimize.py", line 200, in _run_trial
    value_or_values = func(trial)
  File "/common/ketrong/AutoImputeExp/tpot2_imputetest/Impute_Experiments/autoimpute.py", line 57, in obj
    my_model = autoutils.MyModel(random_state = self.random_state, **my_params)
  File "/common/ketrong/AutoImputeExp/tpot2_imputetest/Impute_Experiments/autoutils.py", line 35, in MyModel
    my_model = SimpleImputer(
TypeError: SimpleImputer.__init__() got an unexpected keyword argument 'model_name'
[W 2023-11-21 09:50:40,637] Trial 34 failed with value None.
[W 2023-11-21 09:50:38,201] Trial 36 failed with parameters: {'model_name': 'SimpleImputer', 'strategy': 'mean'} because of the following error: TypeError("SimpleImputer.__init__() got an unexpected keyword argument 'model_name'").
Traceback (most recent call last):
  File "/home/ketrong/miniconda3/envs/tpot2devenv/lib/python3.10/site-packages/optuna/study/_optimize.py", line 200, in _run_trial
    value_or_values = func(trial)
  File "/common/ketrong/AutoImputeExp/tpot2_imputetest/Impute_Experiments/autoimpute.py", line 57, in obj
    my_model = autoutils.MyModel(random_state = self.random_state, **my_params)
  File "/common/ketrong/AutoImputeExp/tpot2_imputetest/Impute_Experiments/autoutils.py", line 35, in MyModel
    my_model = SimpleImputer(
TypeError: SimpleImputer.__init__() got an unexpected keyword argument 'model_name'
[W 2023-11-21 09:50:40,780] Trial 36 failed with value None.
[W 2023-11-21 09:50:38,202] Trial 38 failed with parameters: {'model_name': 'SimpleImputer', 'strategy': 'constant'} because of the following error: TypeError("SimpleImputer.__init__() got an unexpected keyword argument 'model_name'").
Traceback (most recent call last):
  File "/home/ketrong/miniconda3/envs/tpot2devenv/lib/python3.10/site-packages/optuna/study/_optimize.py", line 200, in _run_trial
    value_or_values = func(trial)
  File "/common/ketrong/AutoImputeExp/tpot2_imputetest/Impute_Experiments/autoimpute.py", line 57, in obj
    my_model = autoutils.MyModel(random_state = self.random_state, **my_params)
  File "/common/ketrong/AutoImputeExp/tpot2_imputetest/Impute_Experiments/autoutils.py", line 35, in MyModel
    my_model = SimpleImputer(
TypeError: SimpleImputer.__init__() got an unexpected keyword argument 'model_name'
[W 2023-11-21 09:50:40,923] Trial 38 failed with value None.
[W 2023-11-21 09:50:38,204] Trial 40 failed with parameters: {'model_name': 'SimpleImputer', 'strategy': 'mean'} because of the following error: TypeError("SimpleImputer.__init__() got an unexpected keyword argument 'model_name'").
Traceback (most recent call last):
  File "/home/ketrong/miniconda3/envs/tpot2devenv/lib/python3.10/site-packages/optuna/study/_optimize.py", line 200, in _run_trial
    value_or_values = func(trial)
  File "/common/ketrong/AutoImputeExp/tpot2_imputetest/Impute_Experiments/autoimpute.py", line 57, in obj
    my_model = autoutils.MyModel(random_state = self.random_state, **my_params)
  File "/common/ketrong/AutoImputeExp/tpot2_imputetest/Impute_Experiments/autoutils.py", line 35, in MyModel
    my_model = SimpleImputer(
TypeError: SimpleImputer.__init__() got an unexpected keyword argument 'model_name'
[W 2023-11-21 09:50:41,067] Trial 40 failed with value None.
[W 2023-11-21 09:50:38,206] Trial 43 failed with parameters: {'model_name': 'SimpleImputer', 'strategy': 'most_frequent'} because of the following error: TypeError("SimpleImputer.__init__() got an unexpected keyword argument 'model_name'").
Traceback (most recent call last):
  File "/home/ketrong/miniconda3/envs/tpot2devenv/lib/python3.10/site-packages/optuna/study/_optimize.py", line 200, in _run_trial
    value_or_values = func(trial)
  File "/common/ketrong/AutoImputeExp/tpot2_imputetest/Impute_Experiments/autoimpute.py", line 57, in obj
    my_model = autoutils.MyModel(random_state = self.random_state, **my_params)
  File "/common/ketrong/AutoImputeExp/tpot2_imputetest/Impute_Experiments/autoutils.py", line 35, in MyModel
    my_model = SimpleImputer(
TypeError: SimpleImputer.__init__() got an unexpected keyword argument 'model_name'
[W 2023-11-21 09:50:41,210] Trial 43 failed with value None.
[W 2023-11-21 09:50:38,207] Trial 44 failed with parameters: {'model_name': 'SimpleImputer', 'strategy': 'constant'} because of the following error: TypeError("SimpleImputer.__init__() got an unexpected keyword argument 'model_name'").
Traceback (most recent call last):
  File "/home/ketrong/miniconda3/envs/tpot2devenv/lib/python3.10/site-packages/optuna/study/_optimize.py", line 200, in _run_trial
    value_or_values = func(trial)
  File "/common/ketrong/AutoImputeExp/tpot2_imputetest/Impute_Experiments/autoimpute.py", line 57, in obj
    my_model = autoutils.MyModel(random_state = self.random_state, **my_params)
  File "/common/ketrong/AutoImputeExp/tpot2_imputetest/Impute_Experiments/autoutils.py", line 35, in MyModel
    my_model = SimpleImputer(
TypeError: SimpleImputer.__init__() got an unexpected keyword argument 'model_name'
[W 2023-11-21 09:50:41,351] Trial 44 failed with value None.
[W 2023-11-21 09:50:38,209] Trial 46 failed with parameters: {'model_name': 'SimpleImputer', 'strategy': 'mean'} because of the following error: TypeError("SimpleImputer.__init__() got an unexpected keyword argument 'model_name'").
Traceback (most recent call last):
  File "/home/ketrong/miniconda3/envs/tpot2devenv/lib/python3.10/site-packages/optuna/study/_optimize.py", line 200, in _run_trial
    value_or_values = func(trial)
  File "/common/ketrong/AutoImputeExp/tpot2_imputetest/Impute_Experiments/autoimpute.py", line 57, in obj
    my_model = autoutils.MyModel(random_state = self.random_state, **my_params)
  File "/common/ketrong/AutoImputeExp/tpot2_imputetest/Impute_Experiments/autoutils.py", line 35, in MyModel
    my_model = SimpleImputer(
TypeError: SimpleImputer.__init__() got an unexpected keyword argument 'model_name'
[W 2023-11-21 09:50:41,495] Trial 46 failed with value None.
[W 2023-11-21 09:50:38,297] Trial 1 failed with value None.
[W 2023-11-21 09:50:38,175] Trial 4 failed with parameters: {'model_name': 'SimpleImputer', 'strategy': 'constant'} because of the following error: TypeError("SimpleImputer.__init__() got an unexpected keyword argument 'model_name'").
Traceback (most recent call last):
  File "/home/ketrong/miniconda3/envs/tpot2devenv/lib/python3.10/site-packages/optuna/study/_optimize.py", line 200, in _run_trial
    value_or_values = func(trial)
  File "/common/ketrong/AutoImputeExp/tpot2_imputetest/Impute_Experiments/autoimpute.py", line 57, in obj
    my_model = autoutils.MyModel(random_state = self.random_state, **my_params)
  File "/common/ketrong/AutoImputeExp/tpot2_imputetest/Impute_Experiments/autoutils.py", line 35, in MyModel
    my_model = SimpleImputer(
TypeError: SimpleImputer.__init__() got an unexpected keyword argument 'model_name'
[W 2023-11-21 09:50:41,778] Trial 4 failed with value None.
[W 2023-11-21 09:50:38,177] Trial 6 failed with parameters: {'model_name': 'SimpleImputer', 'strategy': 'constant'} because of the following error: TypeError("SimpleImputer.__init__() got an unexpected keyword argument 'model_name'").
Traceback (most recent call last):
  File "/home/ketrong/miniconda3/envs/tpot2devenv/lib/python3.10/site-packages/optuna/study/_optimize.py", line 200, in _run_trial
    value_or_values = func(trial)
  File "/common/ketrong/AutoImputeExp/tpot2_imputetest/Impute_Experiments/autoimpute.py", line 57, in obj
    my_model = autoutils.MyModel(random_state = self.random_state, **my_params)
  File "/common/ketrong/AutoImputeExp/tpot2_imputetest/Impute_Experiments/autoutils.py", line 35, in MyModel
    my_model = SimpleImputer(
TypeError: SimpleImputer.__init__() got an unexpected keyword argument 'model_name'
[W 2023-11-21 09:50:41,923] Trial 6 failed with value None.
[W 2023-11-21 09:50:38,179] Trial 9 failed with parameters: {'model_name': 'SimpleImputer', 'strategy': 'constant'} because of the following error: TypeError("SimpleImputer.__init__() got an unexpected keyword argument 'model_name'").
Traceback (most recent call last):
  File "/home/ketrong/miniconda3/envs/tpot2devenv/lib/python3.10/site-packages/optuna/study/_optimize.py", line 200, in _run_trial
    value_or_values = func(trial)
  File "/common/ketrong/AutoImputeExp/tpot2_imputetest/Impute_Experiments/autoimpute.py", line 57, in obj
    my_model = autoutils.MyModel(random_state = self.random_state, **my_params)
  File "/common/ketrong/AutoImputeExp/tpot2_imputetest/Impute_Experiments/autoutils.py", line 35, in MyModel
    my_model = SimpleImputer(
TypeError: SimpleImputer.__init__() got an unexpected keyword argument 'model_name'
[W 2023-11-21 09:50:42,066] Trial 9 failed with value None.
[W 2023-11-21 09:50:38,184] Trial 15 failed with parameters: {'model_name': 'SimpleImputer', 'strategy': 'median'} because of the following error: TypeError("SimpleImputer.__init__() got an unexpected keyword argument 'model_name'").
Traceback (most recent call last):
  File "/home/ketrong/miniconda3/envs/tpot2devenv/lib/python3.10/site-packages/optuna/study/_optimize.py", line 200, in _run_trial
    value_or_values = func(trial)
  File "/common/ketrong/AutoImputeExp/tpot2_imputetest/Impute_Experiments/autoimpute.py", line 57, in obj
    my_model = autoutils.MyModel(random_state = self.random_state, **my_params)
  File "/common/ketrong/AutoImputeExp/tpot2_imputetest/Impute_Experiments/autoutils.py", line 35, in MyModel
    my_model = SimpleImputer(
TypeError: SimpleImputer.__init__() got an unexpected keyword argument 'model_name'
[W 2023-11-21 09:50:42,209] Trial 15 failed with value None.
[W 2023-11-21 09:50:38,186] Trial 17 failed with parameters: {'model_name': 'SimpleImputer', 'strategy': 'most_frequent'} because of the following error: TypeError("SimpleImputer.__init__() got an unexpected keyword argument 'model_name'").
Traceback (most recent call last):
  File "/home/ketrong/miniconda3/envs/tpot2devenv/lib/python3.10/site-packages/optuna/study/_optimize.py", line 200, in _run_trial
    value_or_values = func(trial)
  File "/common/ketrong/AutoImputeExp/tpot2_imputetest/Impute_Experiments/autoimpute.py", line 57, in obj
    my_model = autoutils.MyModel(random_state = self.random_state, **my_params)
  File "/common/ketrong/AutoImputeExp/tpot2_imputetest/Impute_Experiments/autoutils.py", line 35, in MyModel
    my_model = SimpleImputer(
TypeError: SimpleImputer.__init__() got an unexpected keyword argument 'model_name'
[W 2023-11-21 09:50:42,349] Trial 17 failed with value None.
[W 2023-11-21 09:50:38,189] Trial 21 failed with parameters: {'model_name': 'SimpleImputer', 'strategy': 'constant'} because of the following error: TypeError("SimpleImputer.__init__() got an unexpected keyword argument 'model_name'").
Traceback (most recent call last):
  File "/home/ketrong/miniconda3/envs/tpot2devenv/lib/python3.10/site-packages/optuna/study/_optimize.py", line 200, in _run_trial
    value_or_values = func(trial)
  File "/common/ketrong/AutoImputeExp/tpot2_imputetest/Impute_Experiments/autoimpute.py", line 57, in obj
    my_model = autoutils.MyModel(random_state = self.random_state, **my_params)
  File "/common/ketrong/AutoImputeExp/tpot2_imputetest/Impute_Experiments/autoutils.py", line 35, in MyModel
    my_model = SimpleImputer(
TypeError: SimpleImputer.__init__() got an unexpected keyword argument 'model_name'
[W 2023-11-21 09:50:42,492] Trial 21 failed with value None.
[W 2023-11-21 09:50:38,192] Trial 25 failed with parameters: {'model_name': 'SimpleImputer', 'strategy': 'most_frequent'} because of the following error: TypeError("SimpleImputer.__init__() got an unexpected keyword argument 'model_name'").
Traceback (most recent call last):
  File "/home/ketrong/miniconda3/envs/tpot2devenv/lib/python3.10/site-packages/optuna/study/_optimize.py", line 200, in _run_trial
    value_or_values = func(trial)
  File "/common/ketrong/AutoImputeExp/tpot2_imputetest/Impute_Experiments/autoimpute.py", line 57, in obj
    my_model = autoutils.MyModel(random_state = self.random_state, **my_params)
  File "/common/ketrong/AutoImputeExp/tpot2_imputetest/Impute_Experiments/autoutils.py", line 35, in MyModel
    my_model = SimpleImputer(
TypeError: SimpleImputer.__init__() got an unexpected keyword argument 'model_name'
[W 2023-11-21 09:50:42,634] Trial 25 failed with value None.
[W 2023-11-21 09:50:38,195] Trial 29 failed with parameters: {'model_name': 'SimpleImputer', 'strategy': 'constant'} because of the following error: TypeError("SimpleImputer.__init__() got an unexpected keyword argument 'model_name'").
Traceback (most recent call last):
  File "/home/ketrong/miniconda3/envs/tpot2devenv/lib/python3.10/site-packages/optuna/study/_optimize.py", line 200, in _run_trial
    value_or_values = func(trial)
  File "/common/ketrong/AutoImputeExp/tpot2_imputetest/Impute_Experiments/autoimpute.py", line 57, in obj
    my_model = autoutils.MyModel(random_state = self.random_state, **my_params)
  File "/common/ketrong/AutoImputeExp/tpot2_imputetest/Impute_Experiments/autoutils.py", line 35, in MyModel
    my_model = SimpleImputer(
TypeError: SimpleImputer.__init__() got an unexpected keyword argument 'model_name'
[W 2023-11-21 09:50:42,775] Trial 29 failed with value None.
[W 2023-11-21 09:50:38,199] Trial 33 failed with parameters: {'model_name': 'SimpleImputer', 'strategy': 'most_frequent'} because of the following error: TypeError("SimpleImputer.__init__() got an unexpected keyword argument 'model_name'").
Traceback (most recent call last):
  File "/home/ketrong/miniconda3/envs/tpot2devenv/lib/python3.10/site-packages/optuna/study/_optimize.py", line 200, in _run_trial
    value_or_values = func(trial)
  File "/common/ketrong/AutoImputeExp/tpot2_imputetest/Impute_Experiments/autoimpute.py", line 57, in obj
    my_model = autoutils.MyModel(random_state = self.random_state, **my_params)
  File "/common/ketrong/AutoImputeExp/tpot2_imputetest/Impute_Experiments/autoutils.py", line 35, in MyModel
    my_model = SimpleImputer(
TypeError: SimpleImputer.__init__() got an unexpected keyword argument 'model_name'
[W 2023-11-21 09:50:42,918] Trial 33 failed with value None.
[W 2023-11-21 09:50:38,202] Trial 37 failed with parameters: {'model_name': 'SimpleImputer', 'strategy': 'median'} because of the following error: TypeError("SimpleImputer.__init__() got an unexpected keyword argument 'model_name'").
Traceback (most recent call last):
  File "/home/ketrong/miniconda3/envs/tpot2devenv/lib/python3.10/site-packages/optuna/study/_optimize.py", line 200, in _run_trial
    value_or_values = func(trial)
  File "/common/ketrong/AutoImputeExp/tpot2_imputetest/Impute_Experiments/autoimpute.py", line 57, in obj
    my_model = autoutils.MyModel(random_state = self.random_state, **my_params)
  File "/common/ketrong/AutoImputeExp/tpot2_imputetest/Impute_Experiments/autoutils.py", line 35, in MyModel
    my_model = SimpleImputer(
TypeError: SimpleImputer.__init__() got an unexpected keyword argument 'model_name'
[W 2023-11-21 09:50:43,058] Trial 37 failed with value None.
[W 2023-11-21 09:50:38,206] Trial 42 failed with parameters: {'model_name': 'SimpleImputer', 'strategy': 'median'} because of the following error: TypeError("SimpleImputer.__init__() got an unexpected keyword argument 'model_name'").
Traceback (most recent call last):
  File "/home/ketrong/miniconda3/envs/tpot2devenv/lib/python3.10/site-packages/optuna/study/_optimize.py", line 200, in _run_trial
    value_or_values = func(trial)
  File "/common/ketrong/AutoImputeExp/tpot2_imputetest/Impute_Experiments/autoimpute.py", line 57, in obj
    my_model = autoutils.MyModel(random_state = self.random_state, **my_params)
  File "/common/ketrong/AutoImputeExp/tpot2_imputetest/Impute_Experiments/autoutils.py", line 35, in MyModel
    my_model = SimpleImputer(
TypeError: SimpleImputer.__init__() got an unexpected keyword argument 'model_name'
[W 2023-11-21 09:50:43,201] Trial 42 failed with value None.
[W 2023-11-21 09:50:38,208] Trial 45 failed with parameters: {'model_name': 'SimpleImputer', 'strategy': 'mean'} because of the following error: TypeError("SimpleImputer.__init__() got an unexpected keyword argument 'model_name'").
Traceback (most recent call last):
  File "/home/ketrong/miniconda3/envs/tpot2devenv/lib/python3.10/site-packages/optuna/study/_optimize.py", line 200, in _run_trial
    value_or_values = func(trial)
  File "/common/ketrong/AutoImputeExp/tpot2_imputetest/Impute_Experiments/autoimpute.py", line 57, in obj
    my_model = autoutils.MyModel(random_state = self.random_state, **my_params)
  File "/common/ketrong/AutoImputeExp/tpot2_imputetest/Impute_Experiments/autoutils.py", line 35, in MyModel
    my_model = SimpleImputer(
TypeError: SimpleImputer.__init__() got an unexpected keyword argument 'model_name'
[W 2023-11-21 09:50:43,343] Trial 45 failed with value None.
[W 2023-11-21 09:50:38,297] Trial 2 failed with value None.
[W 2023-11-21 09:50:38,934] Trial 10 failed with value None.
[W 2023-11-21 09:50:38,182] Trial 13 failed with parameters: {'model_name': 'SimpleImputer', 'strategy': 'constant'} because of the following error: TypeError("SimpleImputer.__init__() got an unexpected keyword argument 'model_name'").
Traceback (most recent call last):
  File "/home/ketrong/miniconda3/envs/tpot2devenv/lib/python3.10/site-packages/optuna/study/_optimize.py", line 200, in _run_trial
    value_or_values = func(trial)
  File "/common/ketrong/AutoImputeExp/tpot2_imputetest/Impute_Experiments/autoimpute.py", line 57, in obj
    my_model = autoutils.MyModel(random_state = self.random_state, **my_params)
  File "/common/ketrong/AutoImputeExp/tpot2_imputetest/Impute_Experiments/autoutils.py", line 35, in MyModel
    my_model = SimpleImputer(
TypeError: SimpleImputer.__init__() got an unexpected keyword argument 'model_name'
[W 2023-11-21 09:50:43,767] Trial 13 failed with value None.
[W 2023-11-21 09:50:38,187] Trial 19 failed with parameters: {'model_name': 'SimpleImputer', 'strategy': 'constant'} because of the following error: TypeError("SimpleImputer.__init__() got an unexpected keyword argument 'model_name'").
Traceback (most recent call last):
  File "/home/ketrong/miniconda3/envs/tpot2devenv/lib/python3.10/site-packages/optuna/study/_optimize.py", line 200, in _run_trial
    value_or_values = func(trial)
  File "/common/ketrong/AutoImputeExp/tpot2_imputetest/Impute_Experiments/autoimpute.py", line 57, in obj
    my_model = autoutils.MyModel(random_state = self.random_state, **my_params)
  File "/common/ketrong/AutoImputeExp/tpot2_imputetest/Impute_Experiments/autoutils.py", line 35, in MyModel
    my_model = SimpleImputer(
TypeError: SimpleImputer.__init__() got an unexpected keyword argument 'model_name'
[W 2023-11-21 09:50:43,908] Trial 19 failed with value None.
[W 2023-11-21 09:50:38,197] Trial 31 failed with parameters: {'model_name': 'SimpleImputer', 'strategy': 'most_frequent'} because of the following error: TypeError("SimpleImputer.__init__() got an unexpected keyword argument 'model_name'").
Traceback (most recent call last):
  File "/home/ketrong/miniconda3/envs/tpot2devenv/lib/python3.10/site-packages/optuna/study/_optimize.py", line 200, in _run_trial
    value_or_values = func(trial)
  File "/common/ketrong/AutoImputeExp/tpot2_imputetest/Impute_Experiments/autoimpute.py", line 57, in obj
    my_model = autoutils.MyModel(random_state = self.random_state, **my_params)
  File "/common/ketrong/AutoImputeExp/tpot2_imputetest/Impute_Experiments/autoutils.py", line 35, in MyModel
    my_model = SimpleImputer(
TypeError: SimpleImputer.__init__() got an unexpected keyword argument 'model_name'
[W 2023-11-21 09:50:44,051] Trial 31 failed with value None.
[W 2023-11-21 09:50:38,200] Trial 35 failed with parameters: {'model_name': 'SimpleImputer', 'strategy': 'most_frequent'} because of the following error: TypeError("SimpleImputer.__init__() got an unexpected keyword argument 'model_name'").
Traceback (most recent call last):
  File "/home/ketrong/miniconda3/envs/tpot2devenv/lib/python3.10/site-packages/optuna/study/_optimize.py", line 200, in _run_trial
    value_or_values = func(trial)
  File "/common/ketrong/AutoImputeExp/tpot2_imputetest/Impute_Experiments/autoimpute.py", line 57, in obj
    my_model = autoutils.MyModel(random_state = self.random_state, **my_params)
  File "/common/ketrong/AutoImputeExp/tpot2_imputetest/Impute_Experiments/autoutils.py", line 35, in MyModel
    my_model = SimpleImputer(
TypeError: SimpleImputer.__init__() got an unexpected keyword argument 'model_name'
[W 2023-11-21 09:50:44,191] Trial 35 failed with value None.
[W 2023-11-21 09:50:38,205] Trial 41 failed with parameters: {'model_name': 'SimpleImputer', 'strategy': 'most_frequent'} because of the following error: TypeError("SimpleImputer.__init__() got an unexpected keyword argument 'model_name'").
Traceback (most recent call last):
  File "/home/ketrong/miniconda3/envs/tpot2devenv/lib/python3.10/site-packages/optuna/study/_optimize.py", line 200, in _run_trial
    value_or_values = func(trial)
  File "/common/ketrong/AutoImputeExp/tpot2_imputetest/Impute_Experiments/autoimpute.py", line 57, in obj
    my_model = autoutils.MyModel(random_state = self.random_state, **my_params)
  File "/common/ketrong/AutoImputeExp/tpot2_imputetest/Impute_Experiments/autoutils.py", line 35, in MyModel
    my_model = SimpleImputer(
TypeError: SimpleImputer.__init__() got an unexpected keyword argument 'model_name'
[W 2023-11-21 09:50:44,334] Trial 41 failed with value None.
[W 2023-11-21 09:50:38,178] Trial 8 failed with parameters: {'model_name': 'SimpleImputer', 'strategy': 'median'} because of the following error: TypeError("SimpleImputer.__init__() got an unexpected keyword argument 'model_name'").
Traceback (most recent call last):
  File "/home/ketrong/miniconda3/envs/tpot2devenv/lib/python3.10/site-packages/optuna/study/_optimize.py", line 200, in _run_trial
    value_or_values = func(trial)
  File "/common/ketrong/AutoImputeExp/tpot2_imputetest/Impute_Experiments/autoimpute.py", line 57, in obj
    my_model = autoutils.MyModel(random_state = self.random_state, **my_params)
  File "/common/ketrong/AutoImputeExp/tpot2_imputetest/Impute_Experiments/autoutils.py", line 35, in MyModel
    my_model = SimpleImputer(
TypeError: SimpleImputer.__init__() got an unexpected keyword argument 'model_name'
[W 2023-11-21 09:50:44,475] Trial 8 failed with value None.
[W 2023-11-21 09:50:38,194] Trial 27 failed with parameters: {'model_name': 'SimpleImputer', 'strategy': 'median'} because of the following error: TypeError("SimpleImputer.__init__() got an unexpected keyword argument 'model_name'").
Traceback (most recent call last):
  File "/home/ketrong/miniconda3/envs/tpot2devenv/lib/python3.10/site-packages/optuna/study/_optimize.py", line 200, in _run_trial
    value_or_values = func(trial)
  File "/common/ketrong/AutoImputeExp/tpot2_imputetest/Impute_Experiments/autoimpute.py", line 57, in obj
    my_model = autoutils.MyModel(random_state = self.random_state, **my_params)
  File "/common/ketrong/AutoImputeExp/tpot2_imputetest/Impute_Experiments/autoutils.py", line 35, in MyModel
    my_model = SimpleImputer(
TypeError: SimpleImputer.__init__() got an unexpected keyword argument 'model_name'
[W 2023-11-21 09:50:44,617] Trial 27 failed with value None.
[W 2023-11-21 09:50:38,210] Trial 47 failed with parameters: {'model_name': 'SimpleImputer', 'strategy': 'constant'} because of the following error: TypeError("SimpleImputer.__init__() got an unexpected keyword argument 'model_name'").
Traceback (most recent call last):
  File "/home/ketrong/miniconda3/envs/tpot2devenv/lib/python3.10/site-packages/optuna/study/_optimize.py", line 200, in _run_trial
    value_or_values = func(trial)
  File "/common/ketrong/AutoImputeExp/tpot2_imputetest/Impute_Experiments/autoimpute.py", line 57, in obj
    my_model = autoutils.MyModel(random_state = self.random_state, **my_params)
  File "/common/ketrong/AutoImputeExp/tpot2_imputetest/Impute_Experiments/autoutils.py", line 35, in MyModel
    my_model = SimpleImputer(
TypeError: SimpleImputer.__init__() got an unexpected keyword argument 'model_name'
[W 2023-11-21 09:50:44,757] Trial 47 failed with value None.
[W 2023-11-21 09:50:38,203] Trial 39 failed with parameters: {'model_name': 'SimpleImputer', 'strategy': 'median'} because of the following error: TypeError("SimpleImputer.__init__() got an unexpected keyword argument 'model_name'").
Traceback (most recent call last):
  File "/home/ketrong/miniconda3/envs/tpot2devenv/lib/python3.10/site-packages/optuna/study/_optimize.py", line 200, in _run_trial
    value_or_values = func(trial)
  File "/common/ketrong/AutoImputeExp/tpot2_imputetest/Impute_Experiments/autoimpute.py", line 57, in obj
    my_model = autoutils.MyModel(random_state = self.random_state, **my_params)
  File "/common/ketrong/AutoImputeExp/tpot2_imputetest/Impute_Experiments/autoutils.py", line 35, in MyModel
    my_model = SimpleImputer(
TypeError: SimpleImputer.__init__() got an unexpected keyword argument 'model_name'
[W 2023-11-21 09:50:44,898] Trial 39 failed with value None.
[W 2023-11-21 09:50:38,190] Trial 23 failed with parameters: {'model_name': 'SimpleImputer', 'strategy': 'most_frequent'} because of the following error: TypeError("SimpleImputer.__init__() got an unexpected keyword argument 'model_name'").
Traceback (most recent call last):
  File "/home/ketrong/miniconda3/envs/tpot2devenv/lib/python3.10/site-packages/optuna/study/_optimize.py", line 200, in _run_trial
    value_or_values = func(trial)
  File "/common/ketrong/AutoImputeExp/tpot2_imputetest/Impute_Experiments/autoimpute.py", line 57, in obj
    my_model = autoutils.MyModel(random_state = self.random_state, **my_params)
  File "/common/ketrong/AutoImputeExp/tpot2_imputetest/Impute_Experiments/autoutils.py", line 35, in MyModel
    my_model = SimpleImputer(
TypeError: SimpleImputer.__init__() got an unexpected keyword argument 'model_name'
[W 2023-11-21 09:50:45,038] Trial 23 failed with value None.
failed on 
tpot2_imputetest/Impute_Experiments/logs//tpot2_base_normal_6_0.5_MNAR_0
SimpleImputer.__init__() got an unexpected keyword argument 'model_name'
Traceback (most recent call last):
  File "/common/ketrong/AutoImputeExp/tpot2_imputetest/Impute_Experiments/utils.py", line 169, in loop_through_tasks
    SimpleImputeSpace.fit(X_train_pandas)
  File "/common/ketrong/AutoImputeExp/tpot2_imputetest/Impute_Experiments/autoimpute.py", line 60, in fit
    self.study.optimize(obj, n_trials=self.n_trials, n_jobs=self.n_jobs, show_progress_bar=self.show_progress, gc_after_trial=self.garbage_collect)
  File "/home/ketrong/miniconda3/envs/tpot2devenv/lib/python3.10/site-packages/optuna/study/study.py", line 451, in optimize
    _optimize(
  File "/home/ketrong/miniconda3/envs/tpot2devenv/lib/python3.10/site-packages/optuna/study/_optimize.py", line 103, in _optimize
    f.result()
  File "/home/ketrong/miniconda3/envs/tpot2devenv/lib/python3.10/concurrent/futures/_base.py", line 451, in result
    return self.__get_result()
  File "/home/ketrong/miniconda3/envs/tpot2devenv/lib/python3.10/concurrent/futures/_base.py", line 403, in __get_result
    raise self._exception
  File "/home/ketrong/miniconda3/envs/tpot2devenv/lib/python3.10/concurrent/futures/thread.py", line 58, in run
    result = self.fn(*self.args, **self.kwargs)
  File "/home/ketrong/miniconda3/envs/tpot2devenv/lib/python3.10/site-packages/optuna/study/_optimize.py", line 163, in _optimize_sequential
    frozen_trial = _run_trial(study, func, catch)
  File "/home/ketrong/miniconda3/envs/tpot2devenv/lib/python3.10/site-packages/optuna/study/_optimize.py", line 251, in _run_trial
    raise func_err
  File "/home/ketrong/miniconda3/envs/tpot2devenv/lib/python3.10/site-packages/optuna/study/_optimize.py", line 200, in _run_trial
    value_or_values = func(trial)
  File "/common/ketrong/AutoImputeExp/tpot2_imputetest/Impute_Experiments/autoimpute.py", line 57, in obj
    my_model = autoutils.MyModel(random_state = self.random_state, **my_params)
  File "/common/ketrong/AutoImputeExp/tpot2_imputetest/Impute_Experiments/autoutils.py", line 35, in MyModel
    my_model = SimpleImputer(
TypeError: SimpleImputer.__init__() got an unexpected keyword argument 'model_name'

DONE
