/cm/local/apps/slurm/var/spool/job423757/slurm_script: line 19: /common/ketrong/minconda3/etc/profile.d/conda.sh: No such file or directory
/cm/local/apps/slurm/var/spool/job423757/slurm_script: line 22: $'\nconda create --name tpot2devenv -c conda-forge python=3.10\n': command not found
/cm/local/apps/slurm/var/spool/job423757/slurm_script: line 27: $'\npip install -r requirements.txt\n': command not found
RunStart
2023-12-01 15:16:20.160717: I tensorflow/core/util/port.cc:113] oneDNN custom operations are on. You may see slightly different numerical results due to floating-point round-off errors from different computation orders. To turn them off, set the environment variable `TF_ENABLE_ONEDNN_OPTS=0`.
2023-12-01 15:16:20.195076: E external/local_xla/xla/stream_executor/cuda/cuda_dnn.cc:9261] Unable to register cuDNN factory: Attempting to register factory for plugin cuDNN when one has already been registered
2023-12-01 15:16:20.195100: E external/local_xla/xla/stream_executor/cuda/cuda_fft.cc:607] Unable to register cuFFT factory: Attempting to register factory for plugin cuFFT when one has already been registered
2023-12-01 15:16:20.196219: E external/local_xla/xla/stream_executor/cuda/cuda_blas.cc:1515] Unable to register cuBLAS factory: Attempting to register factory for plugin cuBLAS when one has already been registered
2023-12-01 15:16:20.201696: I tensorflow/core/platform/cpu_feature_guard.cc:182] This TensorFlow binary is optimized to use available CPU instructions in performance-critical operations.
To enable the following instructions: AVX2 AVX512F AVX512_VNNI FMA, in other operations, rebuild TensorFlow with the appropriate compiler flags.
2023-12-01 15:16:22.253207: W tensorflow/compiler/tf2tensorrt/utils/py_utils.cc:38] TF-TRT Warning: Could not find TensorRT
WARNING:tensorflow:From /home/ketrong/miniconda3/envs/tpot2devenv/lib/python3.10/site-packages/tensorflow/python/compat/v2_compat.py:108: disable_resource_variables (from tensorflow.python.ops.variable_scope) is deprecated and will be removed in a future version.
Instructions for updating:
non-resource variables are not supported in the long term
working on 
tpot2_imputetest/Impute_Experiments/logs//tpot2_base_imputation_30_0.5_MAR_0
3.324043035507202
loading data
tpot2_imputetest/Impute_Experiments/data/30_True.pkl
running experiment 1/3 - Does large hyperparameter space improve reconstruction accuracy over simple
starting impute modules
Start tpot fit
2023-12-01 15:17:44.357224: I tensorflow/core/util/port.cc:113] oneDNN custom operations are on. You may see slightly different numerical results due to floating-point round-off errors from different computation orders. To turn them off, set the environment variable `TF_ENABLE_ONEDNN_OPTS=0`.
2023-12-01 15:17:44.357363: I tensorflow/core/util/port.cc:113] oneDNN custom operations are on. You may see slightly different numerical results due to floating-point round-off errors from different computation orders. To turn them off, set the environment variable `TF_ENABLE_ONEDNN_OPTS=0`.
2023-12-01 15:17:44.357399: I tensorflow/core/util/port.cc:113] oneDNN custom operations are on. You may see slightly different numerical results due to floating-point round-off errors from different computation orders. To turn them off, set the environment variable `TF_ENABLE_ONEDNN_OPTS=0`.
2023-12-01 15:17:44.357402: I tensorflow/core/util/port.cc:113] oneDNN custom operations are on. You may see slightly different numerical results due to floating-point round-off errors from different computation orders. To turn them off, set the environment variable `TF_ENABLE_ONEDNN_OPTS=0`.
2023-12-01 15:17:44.357402: I tensorflow/core/util/port.cc:113] oneDNN custom operations are on. You may see slightly different numerical results due to floating-point round-off errors from different computation orders. To turn them off, set the environment variable `TF_ENABLE_ONEDNN_OPTS=0`.
2023-12-01 15:17:44.357398: I tensorflow/core/util/port.cc:113] oneDNN custom operations are on. You may see slightly different numerical results due to floating-point round-off errors from different computation orders. To turn them off, set the environment variable `TF_ENABLE_ONEDNN_OPTS=0`.
2023-12-01 15:17:44.357401: I tensorflow/core/util/port.cc:113] oneDNN custom operations are on. You may see slightly different numerical results due to floating-point round-off errors from different computation orders. To turn them off, set the environment variable `TF_ENABLE_ONEDNN_OPTS=0`.
2023-12-01 15:17:44.357399: I tensorflow/core/util/port.cc:113] oneDNN custom operations are on. You may see slightly different numerical results due to floating-point round-off errors from different computation orders. To turn them off, set the environment variable `TF_ENABLE_ONEDNN_OPTS=0`.
2023-12-01 15:17:44.357401: I tensorflow/core/util/port.cc:113] oneDNN custom operations are on. You may see slightly different numerical results due to floating-point round-off errors from different computation orders. To turn them off, set the environment variable `TF_ENABLE_ONEDNN_OPTS=0`.
2023-12-01 15:17:44.357412: I tensorflow/core/util/port.cc:113] oneDNN custom operations are on. You may see slightly different numerical results due to floating-point round-off errors from different computation orders. To turn them off, set the environment variable `TF_ENABLE_ONEDNN_OPTS=0`.
2023-12-01 15:17:44.357413: I tensorflow/core/util/port.cc:113] oneDNN custom operations are on. You may see slightly different numerical results due to floating-point round-off errors from different computation orders. To turn them off, set the environment variable `TF_ENABLE_ONEDNN_OPTS=0`.
2023-12-01 15:17:44.357418: I tensorflow/core/util/port.cc:113] oneDNN custom operations are on. You may see slightly different numerical results due to floating-point round-off errors from different computation orders. To turn them off, set the environment variable `TF_ENABLE_ONEDNN_OPTS=0`.
2023-12-01 15:17:44.357420: I tensorflow/core/util/port.cc:113] oneDNN custom operations are on. You may see slightly different numerical results due to floating-point round-off errors from different computation orders. To turn them off, set the environment variable `TF_ENABLE_ONEDNN_OPTS=0`.
2023-12-01 15:17:44.357416: I tensorflow/core/util/port.cc:113] oneDNN custom operations are on. You may see slightly different numerical results due to floating-point round-off errors from different computation orders. To turn them off, set the environment variable `TF_ENABLE_ONEDNN_OPTS=0`.
2023-12-01 15:17:44.357424: I tensorflow/core/util/port.cc:113] oneDNN custom operations are on. You may see slightly different numerical results due to floating-point round-off errors from different computation orders. To turn them off, set the environment variable `TF_ENABLE_ONEDNN_OPTS=0`.
2023-12-01 15:17:44.357425: I tensorflow/core/util/port.cc:113] oneDNN custom operations are on. You may see slightly different numerical results due to floating-point round-off errors from different computation orders. To turn them off, set the environment variable `TF_ENABLE_ONEDNN_OPTS=0`.
2023-12-01 15:17:44.357426: I tensorflow/core/util/port.cc:113] oneDNN custom operations are on. You may see slightly different numerical results due to floating-point round-off errors from different computation orders. To turn them off, set the environment variable `TF_ENABLE_ONEDNN_OPTS=0`.
2023-12-01 15:17:44.357425: I tensorflow/core/util/port.cc:113] oneDNN custom operations are on. You may see slightly different numerical results due to floating-point round-off errors from different computation orders. To turn them off, set the environment variable `TF_ENABLE_ONEDNN_OPTS=0`.
2023-12-01 15:17:44.357436: I tensorflow/core/util/port.cc:113] oneDNN custom operations are on. You may see slightly different numerical results due to floating-point round-off errors from different computation orders. To turn them off, set the environment variable `TF_ENABLE_ONEDNN_OPTS=0`.
2023-12-01 15:17:44.357441: I tensorflow/core/util/port.cc:113] oneDNN custom operations are on. You may see slightly different numerical results due to floating-point round-off errors from different computation orders. To turn them off, set the environment variable `TF_ENABLE_ONEDNN_OPTS=0`.
2023-12-01 15:17:44.357439: I tensorflow/core/util/port.cc:113] oneDNN custom operations are on. You may see slightly different numerical results due to floating-point round-off errors from different computation orders. To turn them off, set the environment variable `TF_ENABLE_ONEDNN_OPTS=0`.
2023-12-01 15:17:44.357444: I tensorflow/core/util/port.cc:113] oneDNN custom operations are on. You may see slightly different numerical results due to floating-point round-off errors from different computation orders. To turn them off, set the environment variable `TF_ENABLE_ONEDNN_OPTS=0`.
2023-12-01 15:17:44.357444: I tensorflow/core/util/port.cc:113] oneDNN custom operations are on. You may see slightly different numerical results due to floating-point round-off errors from different computation orders. To turn them off, set the environment variable `TF_ENABLE_ONEDNN_OPTS=0`.
2023-12-01 15:17:44.357445: I tensorflow/core/util/port.cc:113] oneDNN custom operations are on. You may see slightly different numerical results due to floating-point round-off errors from different computation orders. To turn them off, set the environment variable `TF_ENABLE_ONEDNN_OPTS=0`.
2023-12-01 15:17:44.357470: I tensorflow/core/util/port.cc:113] oneDNN custom operations are on. You may see slightly different numerical results due to floating-point round-off errors from different computation orders. To turn them off, set the environment variable `TF_ENABLE_ONEDNN_OPTS=0`.
2023-12-01 15:17:44.357469: I tensorflow/core/util/port.cc:113] oneDNN custom operations are on. You may see slightly different numerical results due to floating-point round-off errors from different computation orders. To turn them off, set the environment variable `TF_ENABLE_ONEDNN_OPTS=0`.
2023-12-01 15:17:44.357475: I tensorflow/core/util/port.cc:113] oneDNN custom operations are on. You may see slightly different numerical results due to floating-point round-off errors from different computation orders. To turn them off, set the environment variable `TF_ENABLE_ONEDNN_OPTS=0`.
2023-12-01 15:17:44.357476: I tensorflow/core/util/port.cc:113] oneDNN custom operations are on. You may see slightly different numerical results due to floating-point round-off errors from different computation orders. To turn them off, set the environment variable `TF_ENABLE_ONEDNN_OPTS=0`.
2023-12-01 15:17:44.357475: I tensorflow/core/util/port.cc:113] oneDNN custom operations are on. You may see slightly different numerical results due to floating-point round-off errors from different computation orders. To turn them off, set the environment variable `TF_ENABLE_ONEDNN_OPTS=0`.
2023-12-01 15:17:44.357478: I tensorflow/core/util/port.cc:113] oneDNN custom operations are on. You may see slightly different numerical results due to floating-point round-off errors from different computation orders. To turn them off, set the environment variable `TF_ENABLE_ONEDNN_OPTS=0`.
2023-12-01 15:17:44.357478: I tensorflow/core/util/port.cc:113] oneDNN custom operations are on. You may see slightly different numerical results due to floating-point round-off errors from different computation orders. To turn them off, set the environment variable `TF_ENABLE_ONEDNN_OPTS=0`.
2023-12-01 15:17:44.357481: I tensorflow/core/util/port.cc:113] oneDNN custom operations are on. You may see slightly different numerical results due to floating-point round-off errors from different computation orders. To turn them off, set the environment variable `TF_ENABLE_ONEDNN_OPTS=0`.
2023-12-01 15:17:44.357484: I tensorflow/core/util/port.cc:113] oneDNN custom operations are on. You may see slightly different numerical results due to floating-point round-off errors from different computation orders. To turn them off, set the environment variable `TF_ENABLE_ONEDNN_OPTS=0`.
2023-12-01 15:17:44.357486: I tensorflow/core/util/port.cc:113] oneDNN custom operations are on. You may see slightly different numerical results due to floating-point round-off errors from different computation orders. To turn them off, set the environment variable `TF_ENABLE_ONEDNN_OPTS=0`.
2023-12-01 15:17:44.357490: I tensorflow/core/util/port.cc:113] oneDNN custom operations are on. You may see slightly different numerical results due to floating-point round-off errors from different computation orders. To turn them off, set the environment variable `TF_ENABLE_ONEDNN_OPTS=0`.
2023-12-01 15:17:44.357492: I tensorflow/core/util/port.cc:113] oneDNN custom operations are on. You may see slightly different numerical results due to floating-point round-off errors from different computation orders. To turn them off, set the environment variable `TF_ENABLE_ONEDNN_OPTS=0`.
2023-12-01 15:17:44.357494: I tensorflow/core/util/port.cc:113] oneDNN custom operations are on. You may see slightly different numerical results due to floating-point round-off errors from different computation orders. To turn them off, set the environment variable `TF_ENABLE_ONEDNN_OPTS=0`.
2023-12-01 15:17:44.357494: I tensorflow/core/util/port.cc:113] oneDNN custom operations are on. You may see slightly different numerical results due to floating-point round-off errors from different computation orders. To turn them off, set the environment variable `TF_ENABLE_ONEDNN_OPTS=0`.
2023-12-01 15:17:44.357495: I tensorflow/core/util/port.cc:113] oneDNN custom operations are on. You may see slightly different numerical results due to floating-point round-off errors from different computation orders. To turn them off, set the environment variable `TF_ENABLE_ONEDNN_OPTS=0`.
2023-12-01 15:17:44.357491: I tensorflow/core/util/port.cc:113] oneDNN custom operations are on. You may see slightly different numerical results due to floating-point round-off errors from different computation orders. To turn them off, set the environment variable `TF_ENABLE_ONEDNN_OPTS=0`.
2023-12-01 15:17:44.357497: I tensorflow/core/util/port.cc:113] oneDNN custom operations are on. You may see slightly different numerical results due to floating-point round-off errors from different computation orders. To turn them off, set the environment variable `TF_ENABLE_ONEDNN_OPTS=0`.
2023-12-01 15:17:44.357495: I tensorflow/core/util/port.cc:113] oneDNN custom operations are on. You may see slightly different numerical results due to floating-point round-off errors from different computation orders. To turn them off, set the environment variable `TF_ENABLE_ONEDNN_OPTS=0`.
2023-12-01 15:17:44.357496: I tensorflow/core/util/port.cc:113] oneDNN custom operations are on. You may see slightly different numerical results due to floating-point round-off errors from different computation orders. To turn them off, set the environment variable `TF_ENABLE_ONEDNN_OPTS=0`.
2023-12-01 15:17:44.357487: I tensorflow/core/util/port.cc:113] oneDNN custom operations are on. You may see slightly different numerical results due to floating-point round-off errors from different computation orders. To turn them off, set the environment variable `TF_ENABLE_ONEDNN_OPTS=0`.
2023-12-01 15:17:44.357591: I tensorflow/core/util/port.cc:113] oneDNN custom operations are on. You may see slightly different numerical results due to floating-point round-off errors from different computation orders. To turn them off, set the environment variable `TF_ENABLE_ONEDNN_OPTS=0`.
2023-12-01 15:17:44.357599: I tensorflow/core/util/port.cc:113] oneDNN custom operations are on. You may see slightly different numerical results due to floating-point round-off errors from different computation orders. To turn them off, set the environment variable `TF_ENABLE_ONEDNN_OPTS=0`.
2023-12-01 15:17:44.358029: I tensorflow/core/util/port.cc:113] oneDNN custom operations are on. You may see slightly different numerical results due to floating-point round-off errors from different computation orders. To turn them off, set the environment variable `TF_ENABLE_ONEDNN_OPTS=0`.
2023-12-01 15:17:44.360590: I tensorflow/core/util/port.cc:113] oneDNN custom operations are on. You may see slightly different numerical results due to floating-point round-off errors from different computation orders. To turn them off, set the environment variable `TF_ENABLE_ONEDNN_OPTS=0`.
2023-12-01 15:17:44.395019: E external/local_xla/xla/stream_executor/cuda/cuda_dnn.cc:9261] Unable to register cuDNN factory: Attempting to register factory for plugin cuDNN when one has already been registered
2023-12-01 15:17:44.395017: E external/local_xla/xla/stream_executor/cuda/cuda_dnn.cc:9261] Unable to register cuDNN factory: Attempting to register factory for plugin cuDNN when one has already been registered
2023-12-01 15:17:44.395017: E external/local_xla/xla/stream_executor/cuda/cuda_dnn.cc:9261] Unable to register cuDNN factory: Attempting to register factory for plugin cuDNN when one has already been registered
2023-12-01 15:17:44.395025: E external/local_xla/xla/stream_executor/cuda/cuda_dnn.cc:9261] Unable to register cuDNN factory: Attempting to register factory for plugin cuDNN when one has already been registered
2023-12-01 15:17:44.395023: E external/local_xla/xla/stream_executor/cuda/cuda_dnn.cc:9261] Unable to register cuDNN factory: Attempting to register factory for plugin cuDNN when one has already been registered
2023-12-01 15:17:44.395024: E external/local_xla/xla/stream_executor/cuda/cuda_dnn.cc:9261] Unable to register cuDNN factory: Attempting to register factory for plugin cuDNN when one has already been registered
2023-12-01 15:17:44.395024: E external/local_xla/xla/stream_executor/cuda/cuda_dnn.cc:9261] Unable to register cuDNN factory: Attempting to register factory for plugin cuDNN when one has already been registered
2023-12-01 15:17:44.395023: E external/local_xla/xla/stream_executor/cuda/cuda_dnn.cc:9261] Unable to register cuDNN factory: Attempting to register factory for plugin cuDNN when one has already been registered
2023-12-01 15:17:44.395017: E external/local_xla/xla/stream_executor/cuda/cuda_dnn.cc:9261] Unable to register cuDNN factory: Attempting to register factory for plugin cuDNN when one has already been registered
2023-12-01 15:17:44.395028: E external/local_xla/xla/stream_executor/cuda/cuda_dnn.cc:9261] Unable to register cuDNN factory: Attempting to register factory for plugin cuDNN when one has already been registered
2023-12-01 15:17:44.395027: E external/local_xla/xla/stream_executor/cuda/cuda_dnn.cc:9261] Unable to register cuDNN factory: Attempting to register factory for plugin cuDNN when one has already been registered
2023-12-01 15:17:44.395018: E external/local_xla/xla/stream_executor/cuda/cuda_dnn.cc:9261] Unable to register cuDNN factory: Attempting to register factory for plugin cuDNN when one has already been registered
2023-12-01 15:17:44.395017: E external/local_xla/xla/stream_executor/cuda/cuda_dnn.cc:9261] Unable to register cuDNN factory: Attempting to register factory for plugin cuDNN when one has already been registered
2023-12-01 15:17:44.395029: E external/local_xla/xla/stream_executor/cuda/cuda_dnn.cc:9261] Unable to register cuDNN factory: Attempting to register factory for plugin cuDNN when one has already been registered
2023-12-01 15:17:44.395032: E external/local_xla/xla/stream_executor/cuda/cuda_dnn.cc:9261] Unable to register cuDNN factory: Attempting to register factory for plugin cuDNN when one has already been registered
2023-12-01 15:17:44.395056: E external/local_xla/xla/stream_executor/cuda/cuda_fft.cc:607] Unable to register cuFFT factory: Attempting to register factory for plugin cuFFT when one has already been registered
2023-12-01 15:17:44.395055: E external/local_xla/xla/stream_executor/cuda/cuda_fft.cc:607] Unable to register cuFFT factory: Attempting to register factory for plugin cuFFT when one has already been registered
2023-12-01 15:17:44.395055: E external/local_xla/xla/stream_executor/cuda/cuda_fft.cc:607] Unable to register cuFFT factory: Attempting to register factory for plugin cuFFT when one has already been registered
2023-12-01 15:17:44.395056: E external/local_xla/xla/stream_executor/cuda/cuda_fft.cc:607] Unable to register cuFFT factory: Attempting to register factory for plugin cuFFT when one has already been registered
2023-12-01 15:17:44.395058: E external/local_xla/xla/stream_executor/cuda/cuda_fft.cc:607] Unable to register cuFFT factory: Attempting to register factory for plugin cuFFT when one has already been registered
2023-12-01 15:17:44.395059: E external/local_xla/xla/stream_executor/cuda/cuda_fft.cc:607] Unable to register cuFFT factory: Attempting to register factory for plugin cuFFT when one has already been registered
2023-12-01 15:17:44.395055: E external/local_xla/xla/stream_executor/cuda/cuda_fft.cc:607] Unable to register cuFFT factory: Attempting to register factory for plugin cuFFT when one has already been registered
2023-12-01 15:17:44.395055: E external/local_xla/xla/stream_executor/cuda/cuda_fft.cc:607] Unable to register cuFFT factory: Attempting to register factory for plugin cuFFT when one has already been registered
2023-12-01 15:17:44.395057: E external/local_xla/xla/stream_executor/cuda/cuda_fft.cc:607] Unable to register cuFFT factory: Attempting to register factory for plugin cuFFT when one has already been registered
2023-12-01 15:17:44.395058: E external/local_xla/xla/stream_executor/cuda/cuda_fft.cc:607] Unable to register cuFFT factory: Attempting to register factory for plugin cuFFT when one has already been registered
2023-12-01 15:17:44.395059: E external/local_xla/xla/stream_executor/cuda/cuda_fft.cc:607] Unable to register cuFFT factory: Attempting to register factory for plugin cuFFT when one has already been registered
2023-12-01 15:17:44.395061: E external/local_xla/xla/stream_executor/cuda/cuda_fft.cc:607] Unable to register cuFFT factory: Attempting to register factory for plugin cuFFT when one has already been registered
2023-12-01 15:17:44.395061: E external/local_xla/xla/stream_executor/cuda/cuda_fft.cc:607] Unable to register cuFFT factory: Attempting to register factory for plugin cuFFT when one has already been registered
2023-12-01 15:17:44.395064: E external/local_xla/xla/stream_executor/cuda/cuda_fft.cc:607] Unable to register cuFFT factory: Attempting to register factory for plugin cuFFT when one has already been registered
2023-12-01 15:17:44.395060: E external/local_xla/xla/stream_executor/cuda/cuda_dnn.cc:9261] Unable to register cuDNN factory: Attempting to register factory for plugin cuDNN when one has already been registered
2023-12-01 15:17:44.395062: E external/local_xla/xla/stream_executor/cuda/cuda_dnn.cc:9261] Unable to register cuDNN factory: Attempting to register factory for plugin cuDNN when one has already been registered
2023-12-01 15:17:44.395062: E external/local_xla/xla/stream_executor/cuda/cuda_dnn.cc:9261] Unable to register cuDNN factory: Attempting to register factory for plugin cuDNN when one has already been registered
2023-12-01 15:17:44.395070: E external/local_xla/xla/stream_executor/cuda/cuda_dnn.cc:9261] Unable to register cuDNN factory: Attempting to register factory for plugin cuDNN when one has already been registered
2023-12-01 15:17:44.395088: E external/local_xla/xla/stream_executor/cuda/cuda_fft.cc:607] Unable to register cuFFT factory: Attempting to register factory for plugin cuFFT when one has already been registered
2023-12-01 15:17:44.395088: E external/local_xla/xla/stream_executor/cuda/cuda_fft.cc:607] Unable to register cuFFT factory: Attempting to register factory for plugin cuFFT when one has already been registered
2023-12-01 15:17:44.395089: E external/local_xla/xla/stream_executor/cuda/cuda_fft.cc:607] Unable to register cuFFT factory: Attempting to register factory for plugin cuFFT when one has already been registered
2023-12-01 15:17:44.395090: E external/local_xla/xla/stream_executor/cuda/cuda_fft.cc:607] Unable to register cuFFT factory: Attempting to register factory for plugin cuFFT when one has already been registered
2023-12-01 15:17:44.395082: E external/local_xla/xla/stream_executor/cuda/cuda_dnn.cc:9261] Unable to register cuDNN factory: Attempting to register factory for plugin cuDNN when one has already been registered
2023-12-01 15:17:44.395083: E external/local_xla/xla/stream_executor/cuda/cuda_dnn.cc:9261] Unable to register cuDNN factory: Attempting to register factory for plugin cuDNN when one has already been registered
2023-12-01 15:17:44.395084: E external/local_xla/xla/stream_executor/cuda/cuda_dnn.cc:9261] Unable to register cuDNN factory: Attempting to register factory for plugin cuDNN when one has already been registered
2023-12-01 15:17:44.395083: E external/local_xla/xla/stream_executor/cuda/cuda_dnn.cc:9261] Unable to register cuDNN factory: Attempting to register factory for plugin cuDNN when one has already been registered
2023-12-01 15:17:44.395085: E external/local_xla/xla/stream_executor/cuda/cuda_dnn.cc:9261] Unable to register cuDNN factory: Attempting to register factory for plugin cuDNN when one has already been registered
2023-12-01 15:17:44.395100: E external/local_xla/xla/stream_executor/cuda/cuda_fft.cc:607] Unable to register cuFFT factory: Attempting to register factory for plugin cuFFT when one has already been registered
2023-12-01 15:17:44.395101: E external/local_xla/xla/stream_executor/cuda/cuda_fft.cc:607] Unable to register cuFFT factory: Attempting to register factory for plugin cuFFT when one has already been registered
2023-12-01 15:17:44.395102: E external/local_xla/xla/stream_executor/cuda/cuda_fft.cc:607] Unable to register cuFFT factory: Attempting to register factory for plugin cuFFT when one has already been registered
2023-12-01 15:17:44.395102: E external/local_xla/xla/stream_executor/cuda/cuda_fft.cc:607] Unable to register cuFFT factory: Attempting to register factory for plugin cuFFT when one has already been registered
2023-12-01 15:17:44.395103: E external/local_xla/xla/stream_executor/cuda/cuda_fft.cc:607] Unable to register cuFFT factory: Attempting to register factory for plugin cuFFT when one has already been registered
2023-12-01 15:17:44.395099: E external/local_xla/xla/stream_executor/cuda/cuda_dnn.cc:9261] Unable to register cuDNN factory: Attempting to register factory for plugin cuDNN when one has already been registered
2023-12-01 15:17:44.395105: E external/local_xla/xla/stream_executor/cuda/cuda_dnn.cc:9261] Unable to register cuDNN factory: Attempting to register factory for plugin cuDNN when one has already been registered
2023-12-01 15:17:44.395106: E external/local_xla/xla/stream_executor/cuda/cuda_dnn.cc:9261] Unable to register cuDNN factory: Attempting to register factory for plugin cuDNN when one has already been registered
2023-12-01 15:17:44.395118: E external/local_xla/xla/stream_executor/cuda/cuda_fft.cc:607] Unable to register cuFFT factory: Attempting to register factory for plugin cuFFT when one has already been registered
2023-12-01 15:17:44.395107: E external/local_xla/xla/stream_executor/cuda/cuda_dnn.cc:9261] Unable to register cuDNN factory: Attempting to register factory for plugin cuDNN when one has already been registered
2023-12-01 15:17:44.395107: E external/local_xla/xla/stream_executor/cuda/cuda_dnn.cc:9261] Unable to register cuDNN factory: Attempting to register factory for plugin cuDNN when one has already been registered
2023-12-01 15:17:44.395110: E external/local_xla/xla/stream_executor/cuda/cuda_dnn.cc:9261] Unable to register cuDNN factory: Attempting to register factory for plugin cuDNN when one has already been registered
2023-12-01 15:17:44.395121: E external/local_xla/xla/stream_executor/cuda/cuda_fft.cc:607] Unable to register cuFFT factory: Attempting to register factory for plugin cuFFT when one has already been registered
2023-12-01 15:17:44.395125: E external/local_xla/xla/stream_executor/cuda/cuda_fft.cc:607] Unable to register cuFFT factory: Attempting to register factory for plugin cuFFT when one has already been registered
2023-12-01 15:17:44.395126: E external/local_xla/xla/stream_executor/cuda/cuda_fft.cc:607] Unable to register cuFFT factory: Attempting to register factory for plugin cuFFT when one has already been registered
2023-12-01 15:17:44.395114: E external/local_xla/xla/stream_executor/cuda/cuda_dnn.cc:9261] Unable to register cuDNN factory: Attempting to register factory for plugin cuDNN when one has already been registered
2023-12-01 15:17:44.395127: E external/local_xla/xla/stream_executor/cuda/cuda_fft.cc:607] Unable to register cuFFT factory: Attempting to register factory for plugin cuFFT when one has already been registered
2023-12-01 15:17:44.395129: E external/local_xla/xla/stream_executor/cuda/cuda_fft.cc:607] Unable to register cuFFT factory: Attempting to register factory for plugin cuFFT when one has already been registered
2023-12-01 15:17:44.395116: E external/local_xla/xla/stream_executor/cuda/cuda_dnn.cc:9261] Unable to register cuDNN factory: Attempting to register factory for plugin cuDNN when one has already been registered
2023-12-01 15:17:44.395134: E external/local_xla/xla/stream_executor/cuda/cuda_fft.cc:607] Unable to register cuFFT factory: Attempting to register factory for plugin cuFFT when one has already been registered
2023-12-01 15:17:44.395121: E external/local_xla/xla/stream_executor/cuda/cuda_dnn.cc:9261] Unable to register cuDNN factory: Attempting to register factory for plugin cuDNN when one has already been registered
2023-12-01 15:17:44.395138: E external/local_xla/xla/stream_executor/cuda/cuda_fft.cc:607] Unable to register cuFFT factory: Attempting to register factory for plugin cuFFT when one has already been registered
2023-12-01 15:17:44.395141: E external/local_xla/xla/stream_executor/cuda/cuda_fft.cc:607] Unable to register cuFFT factory: Attempting to register factory for plugin cuFFT when one has already been registered
2023-12-01 15:17:44.395130: E external/local_xla/xla/stream_executor/cuda/cuda_dnn.cc:9261] Unable to register cuDNN factory: Attempting to register factory for plugin cuDNN when one has already been registered
2023-12-01 15:17:44.395134: E external/local_xla/xla/stream_executor/cuda/cuda_dnn.cc:9261] Unable to register cuDNN factory: Attempting to register factory for plugin cuDNN when one has already been registered
2023-12-01 15:17:44.395136: E external/local_xla/xla/stream_executor/cuda/cuda_dnn.cc:9261] Unable to register cuDNN factory: Attempting to register factory for plugin cuDNN when one has already been registered
2023-12-01 15:17:44.395139: E external/local_xla/xla/stream_executor/cuda/cuda_dnn.cc:9261] Unable to register cuDNN factory: Attempting to register factory for plugin cuDNN when one has already been registered
2023-12-01 15:17:44.395141: E external/local_xla/xla/stream_executor/cuda/cuda_dnn.cc:9261] Unable to register cuDNN factory: Attempting to register factory for plugin cuDNN when one has already been registered
2023-12-01 15:17:44.395151: E external/local_xla/xla/stream_executor/cuda/cuda_fft.cc:607] Unable to register cuFFT factory: Attempting to register factory for plugin cuFFT when one has already been registered
2023-12-01 15:17:44.395140: E external/local_xla/xla/stream_executor/cuda/cuda_dnn.cc:9261] Unable to register cuDNN factory: Attempting to register factory for plugin cuDNN when one has already been registered
2023-12-01 15:17:44.395142: E external/local_xla/xla/stream_executor/cuda/cuda_dnn.cc:9261] Unable to register cuDNN factory: Attempting to register factory for plugin cuDNN when one has already been registered
2023-12-01 15:17:44.395152: E external/local_xla/xla/stream_executor/cuda/cuda_fft.cc:607] Unable to register cuFFT factory: Attempting to register factory for plugin cuFFT when one has already been registered
2023-12-01 15:17:44.395142: E external/local_xla/xla/stream_executor/cuda/cuda_dnn.cc:9261] Unable to register cuDNN factory: Attempting to register factory for plugin cuDNN when one has already been registered
2023-12-01 15:17:44.395156: E external/local_xla/xla/stream_executor/cuda/cuda_fft.cc:607] Unable to register cuFFT factory: Attempting to register factory for plugin cuFFT when one has already been registered
2023-12-01 15:17:44.395157: E external/local_xla/xla/stream_executor/cuda/cuda_fft.cc:607] Unable to register cuFFT factory: Attempting to register factory for plugin cuFFT when one has already been registered
2023-12-01 15:17:44.395158: E external/local_xla/xla/stream_executor/cuda/cuda_fft.cc:607] Unable to register cuFFT factory: Attempting to register factory for plugin cuFFT when one has already been registered
2023-12-01 15:17:44.395142: E external/local_xla/xla/stream_executor/cuda/cuda_dnn.cc:9261] Unable to register cuDNN factory: Attempting to register factory for plugin cuDNN when one has already been registered
2023-12-01 15:17:44.395161: E external/local_xla/xla/stream_executor/cuda/cuda_fft.cc:607] Unable to register cuFFT factory: Attempting to register factory for plugin cuFFT when one has already been registered
2023-12-01 15:17:44.395161: E external/local_xla/xla/stream_executor/cuda/cuda_fft.cc:607] Unable to register cuFFT factory: Attempting to register factory for plugin cuFFT when one has already been registered
2023-12-01 15:17:44.395164: E external/local_xla/xla/stream_executor/cuda/cuda_fft.cc:607] Unable to register cuFFT factory: Attempting to register factory for plugin cuFFT when one has already been registered
2023-12-01 15:17:44.395166: E external/local_xla/xla/stream_executor/cuda/cuda_fft.cc:607] Unable to register cuFFT factory: Attempting to register factory for plugin cuFFT when one has already been registered
2023-12-01 15:17:44.395240: E external/local_xla/xla/stream_executor/cuda/cuda_fft.cc:607] Unable to register cuFFT factory: Attempting to register factory for plugin cuFFT when one has already been registered
2023-12-01 15:17:44.395378: E external/local_xla/xla/stream_executor/cuda/cuda_dnn.cc:9261] Unable to register cuDNN factory: Attempting to register factory for plugin cuDNN when one has already been registered
2023-12-01 15:17:44.395443: E external/local_xla/xla/stream_executor/cuda/cuda_fft.cc:607] Unable to register cuFFT factory: Attempting to register factory for plugin cuFFT when one has already been registered
2023-12-01 15:17:44.395791: E external/local_xla/xla/stream_executor/cuda/cuda_dnn.cc:9261] Unable to register cuDNN factory: Attempting to register factory for plugin cuDNN when one has already been registered
2023-12-01 15:17:44.395883: E external/local_xla/xla/stream_executor/cuda/cuda_fft.cc:607] Unable to register cuFFT factory: Attempting to register factory for plugin cuFFT when one has already been registered
2023-12-01 15:17:44.396179: E external/local_xla/xla/stream_executor/cuda/cuda_dnn.cc:9261] Unable to register cuDNN factory: Attempting to register factory for plugin cuDNN when one has already been registered
2023-12-01 15:17:44.396253: E external/local_xla/xla/stream_executor/cuda/cuda_fft.cc:607] Unable to register cuFFT factory: Attempting to register factory for plugin cuFFT when one has already been registered
2023-12-01 15:17:44.396548: E external/local_xla/xla/stream_executor/cuda/cuda_blas.cc:1515] Unable to register cuBLAS factory: Attempting to register factory for plugin cuBLAS when one has already been registered
2023-12-01 15:17:44.396548: E external/local_xla/xla/stream_executor/cuda/cuda_blas.cc:1515] Unable to register cuBLAS factory: Attempting to register factory for plugin cuBLAS when one has already been registered
2023-12-01 15:17:44.396553: E external/local_xla/xla/stream_executor/cuda/cuda_blas.cc:1515] Unable to register cuBLAS factory: Attempting to register factory for plugin cuBLAS when one has already been registered
2023-12-01 15:17:44.396553: E external/local_xla/xla/stream_executor/cuda/cuda_blas.cc:1515] Unable to register cuBLAS factory: Attempting to register factory for plugin cuBLAS when one has already been registered
2023-12-01 15:17:44.396555: E external/local_xla/xla/stream_executor/cuda/cuda_blas.cc:1515] Unable to register cuBLAS factory: Attempting to register factory for plugin cuBLAS when one has already been registered
2023-12-01 15:17:44.396555: E external/local_xla/xla/stream_executor/cuda/cuda_blas.cc:1515] Unable to register cuBLAS factory: Attempting to register factory for plugin cuBLAS when one has already been registered
2023-12-01 15:17:44.396553: E external/local_xla/xla/stream_executor/cuda/cuda_blas.cc:1515] Unable to register cuBLAS factory: Attempting to register factory for plugin cuBLAS when one has already been registered
2023-12-01 15:17:44.396556: E external/local_xla/xla/stream_executor/cuda/cuda_blas.cc:1515] Unable to register cuBLAS factory: Attempting to register factory for plugin cuBLAS when one has already been registered
2023-12-01 15:17:44.396559: E external/local_xla/xla/stream_executor/cuda/cuda_blas.cc:1515] Unable to register cuBLAS factory: Attempting to register factory for plugin cuBLAS when one has already been registered
2023-12-01 15:17:44.396566: E external/local_xla/xla/stream_executor/cuda/cuda_blas.cc:1515] Unable to register cuBLAS factory: Attempting to register factory for plugin cuBLAS when one has already been registered
2023-12-01 15:17:44.396573: E external/local_xla/xla/stream_executor/cuda/cuda_blas.cc:1515] Unable to register cuBLAS factory: Attempting to register factory for plugin cuBLAS when one has already been registered
2023-12-01 15:17:44.396573: E external/local_xla/xla/stream_executor/cuda/cuda_blas.cc:1515] Unable to register cuBLAS factory: Attempting to register factory for plugin cuBLAS when one has already been registered
2023-12-01 15:17:44.396574: E external/local_xla/xla/stream_executor/cuda/cuda_blas.cc:1515] Unable to register cuBLAS factory: Attempting to register factory for plugin cuBLAS when one has already been registered
2023-12-01 15:17:44.396575: E external/local_xla/xla/stream_executor/cuda/cuda_blas.cc:1515] Unable to register cuBLAS factory: Attempting to register factory for plugin cuBLAS when one has already been registered
2023-12-01 15:17:44.396574: E external/local_xla/xla/stream_executor/cuda/cuda_blas.cc:1515] Unable to register cuBLAS factory: Attempting to register factory for plugin cuBLAS when one has already been registered
2023-12-01 15:17:44.396575: E external/local_xla/xla/stream_executor/cuda/cuda_blas.cc:1515] Unable to register cuBLAS factory: Attempting to register factory for plugin cuBLAS when one has already been registered
2023-12-01 15:17:44.396578: E external/local_xla/xla/stream_executor/cuda/cuda_blas.cc:1515] Unable to register cuBLAS factory: Attempting to register factory for plugin cuBLAS when one has already been registered
2023-12-01 15:17:44.396593: E external/local_xla/xla/stream_executor/cuda/cuda_blas.cc:1515] Unable to register cuBLAS factory: Attempting to register factory for plugin cuBLAS when one has already been registered
2023-12-01 15:17:44.396594: E external/local_xla/xla/stream_executor/cuda/cuda_blas.cc:1515] Unable to register cuBLAS factory: Attempting to register factory for plugin cuBLAS when one has already been registered
2023-12-01 15:17:44.396594: E external/local_xla/xla/stream_executor/cuda/cuda_blas.cc:1515] Unable to register cuBLAS factory: Attempting to register factory for plugin cuBLAS when one has already been registered
2023-12-01 15:17:44.396602: E external/local_xla/xla/stream_executor/cuda/cuda_blas.cc:1515] Unable to register cuBLAS factory: Attempting to register factory for plugin cuBLAS when one has already been registered
2023-12-01 15:17:44.396602: E external/local_xla/xla/stream_executor/cuda/cuda_blas.cc:1515] Unable to register cuBLAS factory: Attempting to register factory for plugin cuBLAS when one has already been registered
2023-12-01 15:17:44.396604: E external/local_xla/xla/stream_executor/cuda/cuda_blas.cc:1515] Unable to register cuBLAS factory: Attempting to register factory for plugin cuBLAS when one has already been registered
2023-12-01 15:17:44.396605: E external/local_xla/xla/stream_executor/cuda/cuda_blas.cc:1515] Unable to register cuBLAS factory: Attempting to register factory for plugin cuBLAS when one has already been registered
2023-12-01 15:17:44.396604: E external/local_xla/xla/stream_executor/cuda/cuda_blas.cc:1515] Unable to register cuBLAS factory: Attempting to register factory for plugin cuBLAS when one has already been registered
2023-12-01 15:17:44.396605: E external/local_xla/xla/stream_executor/cuda/cuda_blas.cc:1515] Unable to register cuBLAS factory: Attempting to register factory for plugin cuBLAS when one has already been registered
2023-12-01 15:17:44.396610: E external/local_xla/xla/stream_executor/cuda/cuda_blas.cc:1515] Unable to register cuBLAS factory: Attempting to register factory for plugin cuBLAS when one has already been registered
2023-12-01 15:17:44.396616: E external/local_xla/xla/stream_executor/cuda/cuda_blas.cc:1515] Unable to register cuBLAS factory: Attempting to register factory for plugin cuBLAS when one has already been registered
2023-12-01 15:17:44.396616: E external/local_xla/xla/stream_executor/cuda/cuda_blas.cc:1515] Unable to register cuBLAS factory: Attempting to register factory for plugin cuBLAS when one has already been registered
2023-12-01 15:17:44.396617: E external/local_xla/xla/stream_executor/cuda/cuda_blas.cc:1515] Unable to register cuBLAS factory: Attempting to register factory for plugin cuBLAS when one has already been registered
2023-12-01 15:17:44.396620: E external/local_xla/xla/stream_executor/cuda/cuda_blas.cc:1515] Unable to register cuBLAS factory: Attempting to register factory for plugin cuBLAS when one has already been registered
2023-12-01 15:17:44.396620: E external/local_xla/xla/stream_executor/cuda/cuda_blas.cc:1515] Unable to register cuBLAS factory: Attempting to register factory for plugin cuBLAS when one has already been registered
2023-12-01 15:17:44.396623: E external/local_xla/xla/stream_executor/cuda/cuda_blas.cc:1515] Unable to register cuBLAS factory: Attempting to register factory for plugin cuBLAS when one has already been registered
2023-12-01 15:17:44.396624: E external/local_xla/xla/stream_executor/cuda/cuda_blas.cc:1515] Unable to register cuBLAS factory: Attempting to register factory for plugin cuBLAS when one has already been registered
2023-12-01 15:17:44.396634: E external/local_xla/xla/stream_executor/cuda/cuda_blas.cc:1515] Unable to register cuBLAS factory: Attempting to register factory for plugin cuBLAS when one has already been registered
2023-12-01 15:17:44.396638: E external/local_xla/xla/stream_executor/cuda/cuda_blas.cc:1515] Unable to register cuBLAS factory: Attempting to register factory for plugin cuBLAS when one has already been registered
2023-12-01 15:17:44.396639: E external/local_xla/xla/stream_executor/cuda/cuda_blas.cc:1515] Unable to register cuBLAS factory: Attempting to register factory for plugin cuBLAS when one has already been registered
2023-12-01 15:17:44.396639: E external/local_xla/xla/stream_executor/cuda/cuda_blas.cc:1515] Unable to register cuBLAS factory: Attempting to register factory for plugin cuBLAS when one has already been registered
2023-12-01 15:17:44.396651: E external/local_xla/xla/stream_executor/cuda/cuda_blas.cc:1515] Unable to register cuBLAS factory: Attempting to register factory for plugin cuBLAS when one has already been registered
2023-12-01 15:17:44.396652: E external/local_xla/xla/stream_executor/cuda/cuda_blas.cc:1515] Unable to register cuBLAS factory: Attempting to register factory for plugin cuBLAS when one has already been registered
2023-12-01 15:17:44.396652: E external/local_xla/xla/stream_executor/cuda/cuda_blas.cc:1515] Unable to register cuBLAS factory: Attempting to register factory for plugin cuBLAS when one has already been registered
2023-12-01 15:17:44.396653: E external/local_xla/xla/stream_executor/cuda/cuda_blas.cc:1515] Unable to register cuBLAS factory: Attempting to register factory for plugin cuBLAS when one has already been registered
2023-12-01 15:17:44.396594: E external/local_xla/xla/stream_executor/cuda/cuda_blas.cc:1515] Unable to register cuBLAS factory: Attempting to register factory for plugin cuBLAS when one has already been registered
2023-12-01 15:17:44.396786: E external/local_xla/xla/stream_executor/cuda/cuda_dnn.cc:9261] Unable to register cuDNN factory: Attempting to register factory for plugin cuDNN when one has already been registered
2023-12-01 15:17:44.396789: E external/local_xla/xla/stream_executor/cuda/cuda_dnn.cc:9261] Unable to register cuDNN factory: Attempting to register factory for plugin cuDNN when one has already been registered
2023-12-01 15:17:44.396811: E external/local_xla/xla/stream_executor/cuda/cuda_fft.cc:607] Unable to register cuFFT factory: Attempting to register factory for plugin cuFFT when one has already been registered
2023-12-01 15:17:44.396824: E external/local_xla/xla/stream_executor/cuda/cuda_blas.cc:1515] Unable to register cuBLAS factory: Attempting to register factory for plugin cuBLAS when one has already been registered
2023-12-01 15:17:44.396861: E external/local_xla/xla/stream_executor/cuda/cuda_fft.cc:607] Unable to register cuFFT factory: Attempting to register factory for plugin cuFFT when one has already been registered
2023-12-01 15:17:44.397090: E external/local_xla/xla/stream_executor/cuda/cuda_blas.cc:1515] Unable to register cuBLAS factory: Attempting to register factory for plugin cuBLAS when one has already been registered
2023-12-01 15:17:44.397593: E external/local_xla/xla/stream_executor/cuda/cuda_blas.cc:1515] Unable to register cuBLAS factory: Attempting to register factory for plugin cuBLAS when one has already been registered
2023-12-01 15:17:44.397623: E external/local_xla/xla/stream_executor/cuda/cuda_dnn.cc:9261] Unable to register cuDNN factory: Attempting to register factory for plugin cuDNN when one has already been registered
2023-12-01 15:17:44.397639: E external/local_xla/xla/stream_executor/cuda/cuda_fft.cc:607] Unable to register cuFFT factory: Attempting to register factory for plugin cuFFT when one has already been registered
2023-12-01 15:17:44.397696: E external/local_xla/xla/stream_executor/cuda/cuda_blas.cc:1515] Unable to register cuBLAS factory: Attempting to register factory for plugin cuBLAS when one has already been registered
2023-12-01 15:17:44.398412: E external/local_xla/xla/stream_executor/cuda/cuda_blas.cc:1515] Unable to register cuBLAS factory: Attempting to register factory for plugin cuBLAS when one has already been registered
2023-12-01 15:17:44.403181: I tensorflow/core/platform/cpu_feature_guard.cc:182] This TensorFlow binary is optimized to use available CPU instructions in performance-critical operations.
To enable the following instructions: AVX2 AVX512F AVX512_VNNI FMA, in other operations, rebuild TensorFlow with the appropriate compiler flags.
2023-12-01 15:17:44.403181: I tensorflow/core/platform/cpu_feature_guard.cc:182] This TensorFlow binary is optimized to use available CPU instructions in performance-critical operations.
To enable the following instructions: AVX2 AVX512F AVX512_VNNI FMA, in other operations, rebuild TensorFlow with the appropriate compiler flags.
2023-12-01 15:17:44.403181: I tensorflow/core/platform/cpu_feature_guard.cc:182] This TensorFlow binary is optimized to use available CPU instructions in performance-critical operations.
To enable the following instructions: AVX2 AVX512F AVX512_VNNI FMA, in other operations, rebuild TensorFlow with the appropriate compiler flags.
2023-12-01 15:17:44.403182: I tensorflow/core/platform/cpu_feature_guard.cc:182] This TensorFlow binary is optimized to use available CPU instructions in performance-critical operations.
To enable the following instructions: AVX2 AVX512F AVX512_VNNI FMA, in other operations, rebuild TensorFlow with the appropriate compiler flags.
2023-12-01 15:17:44.403182: I tensorflow/core/platform/cpu_feature_guard.cc:182] This TensorFlow binary is optimized to use available CPU instructions in performance-critical operations.
To enable the following instructions: AVX2 AVX512F AVX512_VNNI FMA, in other operations, rebuild TensorFlow with the appropriate compiler flags.
2023-12-01 15:17:44.403186: I tensorflow/core/platform/cpu_feature_guard.cc:182] This TensorFlow binary is optimized to use available CPU instructions in performance-critical operations.
To enable the following instructions: AVX2 AVX512F AVX512_VNNI FMA, in other operations, rebuild TensorFlow with the appropriate compiler flags.
2023-12-01 15:17:44.403188: I tensorflow/core/platform/cpu_feature_guard.cc:182] This TensorFlow binary is optimized to use available CPU instructions in performance-critical operations.
To enable the following instructions: AVX2 AVX512F AVX512_VNNI FMA, in other operations, rebuild TensorFlow with the appropriate compiler flags.
2023-12-01 15:17:44.403188: I tensorflow/core/platform/cpu_feature_guard.cc:182] This TensorFlow binary is optimized to use available CPU instructions in performance-critical operations.
To enable the following instructions: AVX2 AVX512F AVX512_VNNI FMA, in other operations, rebuild TensorFlow with the appropriate compiler flags.
2023-12-01 15:17:44.403199: I tensorflow/core/platform/cpu_feature_guard.cc:182] This TensorFlow binary is optimized to use available CPU instructions in performance-critical operations.
To enable the following instructions: AVX2 AVX512F AVX512_VNNI FMA, in other operations, rebuild TensorFlow with the appropriate compiler flags.
2023-12-01 15:17:44.403208: I tensorflow/core/platform/cpu_feature_guard.cc:182] This TensorFlow binary is optimized to use available CPU instructions in performance-critical operations.
To enable the following instructions: AVX2 AVX512F AVX512_VNNI FMA, in other operations, rebuild TensorFlow with the appropriate compiler flags.
2023-12-01 15:17:44.403208: I tensorflow/core/platform/cpu_feature_guard.cc:182] This TensorFlow binary is optimized to use available CPU instructions in performance-critical operations.
To enable the following instructions: AVX2 AVX512F AVX512_VNNI FMA, in other operations, rebuild TensorFlow with the appropriate compiler flags.
2023-12-01 15:17:44.403215: I tensorflow/core/platform/cpu_feature_guard.cc:182] This TensorFlow binary is optimized to use available CPU instructions in performance-critical operations.
To enable the following instructions: AVX2 AVX512F AVX512_VNNI FMA, in other operations, rebuild TensorFlow with the appropriate compiler flags.
2023-12-01 15:17:44.403219: I tensorflow/core/platform/cpu_feature_guard.cc:182] This TensorFlow binary is optimized to use available CPU instructions in performance-critical operations.
To enable the following instructions: AVX2 AVX512F AVX512_VNNI FMA, in other operations, rebuild TensorFlow with the appropriate compiler flags.
2023-12-01 15:17:44.403219: I tensorflow/core/platform/cpu_feature_guard.cc:182] This TensorFlow binary is optimized to use available CPU instructions in performance-critical operations.
To enable the following instructions: AVX2 AVX512F AVX512_VNNI FMA, in other operations, rebuild TensorFlow with the appropriate compiler flags.
2023-12-01 15:17:44.403219: I tensorflow/core/platform/cpu_feature_guard.cc:182] This TensorFlow binary is optimized to use available CPU instructions in performance-critical operations.
To enable the following instructions: AVX2 AVX512F AVX512_VNNI FMA, in other operations, rebuild TensorFlow with the appropriate compiler flags.
2023-12-01 15:17:44.403220: I tensorflow/core/platform/cpu_feature_guard.cc:182] This TensorFlow binary is optimized to use available CPU instructions in performance-critical operations.
To enable the following instructions: AVX2 AVX512F AVX512_VNNI FMA, in other operations, rebuild TensorFlow with the appropriate compiler flags.
2023-12-01 15:17:44.403224: I tensorflow/core/platform/cpu_feature_guard.cc:182] This TensorFlow binary is optimized to use available CPU instructions in performance-critical operations.
To enable the following instructions: AVX2 AVX512F AVX512_VNNI FMA, in other operations, rebuild TensorFlow with the appropriate compiler flags.
2023-12-01 15:17:44.403227: I tensorflow/core/platform/cpu_feature_guard.cc:182] This TensorFlow binary is optimized to use available CPU instructions in performance-critical operations.
To enable the following instructions: AVX2 AVX512F AVX512_VNNI FMA, in other operations, rebuild TensorFlow with the appropriate compiler flags.
2023-12-01 15:17:44.403227: I tensorflow/core/platform/cpu_feature_guard.cc:182] This TensorFlow binary is optimized to use available CPU instructions in performance-critical operations.
To enable the following instructions: AVX2 AVX512F AVX512_VNNI FMA, in other operations, rebuild TensorFlow with the appropriate compiler flags.
2023-12-01 15:17:44.403228: I tensorflow/core/platform/cpu_feature_guard.cc:182] This TensorFlow binary is optimized to use available CPU instructions in performance-critical operations.
To enable the following instructions: AVX2 AVX512F AVX512_VNNI FMA, in other operations, rebuild TensorFlow with the appropriate compiler flags.
2023-12-01 15:17:44.403234: I tensorflow/core/platform/cpu_feature_guard.cc:182] This TensorFlow binary is optimized to use available CPU instructions in performance-critical operations.
To enable the following instructions: AVX2 AVX512F AVX512_VNNI FMA, in other operations, rebuild TensorFlow with the appropriate compiler flags.
2023-12-01 15:17:44.403236: I tensorflow/core/platform/cpu_feature_guard.cc:182] This TensorFlow binary is optimized to use available CPU instructions in performance-critical operations.
To enable the following instructions: AVX2 AVX512F AVX512_VNNI FMA, in other operations, rebuild TensorFlow with the appropriate compiler flags.
2023-12-01 15:17:44.403247: I tensorflow/core/platform/cpu_feature_guard.cc:182] This TensorFlow binary is optimized to use available CPU instructions in performance-critical operations.
To enable the following instructions: AVX2 AVX512F AVX512_VNNI FMA, in other operations, rebuild TensorFlow with the appropriate compiler flags.
2023-12-01 15:17:44.403253: I tensorflow/core/platform/cpu_feature_guard.cc:182] This TensorFlow binary is optimized to use available CPU instructions in performance-critical operations.
To enable the following instructions: AVX2 AVX512F AVX512_VNNI FMA, in other operations, rebuild TensorFlow with the appropriate compiler flags.
2023-12-01 15:17:44.403253: I tensorflow/core/platform/cpu_feature_guard.cc:182] This TensorFlow binary is optimized to use available CPU instructions in performance-critical operations.
To enable the following instructions: AVX2 AVX512F AVX512_VNNI FMA, in other operations, rebuild TensorFlow with the appropriate compiler flags.
2023-12-01 15:17:44.403255: I tensorflow/core/platform/cpu_feature_guard.cc:182] This TensorFlow binary is optimized to use available CPU instructions in performance-critical operations.
To enable the following instructions: AVX2 AVX512F AVX512_VNNI FMA, in other operations, rebuild TensorFlow with the appropriate compiler flags.
2023-12-01 15:17:44.403262: I tensorflow/core/platform/cpu_feature_guard.cc:182] This TensorFlow binary is optimized to use available CPU instructions in performance-critical operations.
To enable the following instructions: AVX2 AVX512F AVX512_VNNI FMA, in other operations, rebuild TensorFlow with the appropriate compiler flags.
2023-12-01 15:17:44.403263: I tensorflow/core/platform/cpu_feature_guard.cc:182] This TensorFlow binary is optimized to use available CPU instructions in performance-critical operations.
To enable the following instructions: AVX2 AVX512F AVX512_VNNI FMA, in other operations, rebuild TensorFlow with the appropriate compiler flags.
2023-12-01 15:17:44.403264: I tensorflow/core/platform/cpu_feature_guard.cc:182] This TensorFlow binary is optimized to use available CPU instructions in performance-critical operations.
To enable the following instructions: AVX2 AVX512F AVX512_VNNI FMA, in other operations, rebuild TensorFlow with the appropriate compiler flags.
2023-12-01 15:17:44.403269: I tensorflow/core/platform/cpu_feature_guard.cc:182] This TensorFlow binary is optimized to use available CPU instructions in performance-critical operations.
To enable the following instructions: AVX2 AVX512F AVX512_VNNI FMA, in other operations, rebuild TensorFlow with the appropriate compiler flags.
2023-12-01 15:17:44.403272: I tensorflow/core/platform/cpu_feature_guard.cc:182] This TensorFlow binary is optimized to use available CPU instructions in performance-critical operations.
To enable the following instructions: AVX2 AVX512F AVX512_VNNI FMA, in other operations, rebuild TensorFlow with the appropriate compiler flags.
2023-12-01 15:17:44.403274: I tensorflow/core/platform/cpu_feature_guard.cc:182] This TensorFlow binary is optimized to use available CPU instructions in performance-critical operations.
To enable the following instructions: AVX2 AVX512F AVX512_VNNI FMA, in other operations, rebuild TensorFlow with the appropriate compiler flags.
2023-12-01 15:17:44.403274: I tensorflow/core/platform/cpu_feature_guard.cc:182] This TensorFlow binary is optimized to use available CPU instructions in performance-critical operations.
To enable the following instructions: AVX2 AVX512F AVX512_VNNI FMA, in other operations, rebuild TensorFlow with the appropriate compiler flags.
2023-12-01 15:17:44.403280: I tensorflow/core/platform/cpu_feature_guard.cc:182] This TensorFlow binary is optimized to use available CPU instructions in performance-critical operations.
To enable the following instructions: AVX2 AVX512F AVX512_VNNI FMA, in other operations, rebuild TensorFlow with the appropriate compiler flags.
2023-12-01 15:17:44.403285: I tensorflow/core/platform/cpu_feature_guard.cc:182] This TensorFlow binary is optimized to use available CPU instructions in performance-critical operations.
To enable the following instructions: AVX2 AVX512F AVX512_VNNI FMA, in other operations, rebuild TensorFlow with the appropriate compiler flags.
2023-12-01 15:17:44.403390: I tensorflow/core/platform/cpu_feature_guard.cc:182] This TensorFlow binary is optimized to use available CPU instructions in performance-critical operations.
To enable the following instructions: AVX2 AVX512F AVX512_VNNI FMA, in other operations, rebuild TensorFlow with the appropriate compiler flags.
2023-12-01 15:17:44.403411: I tensorflow/core/platform/cpu_feature_guard.cc:182] This TensorFlow binary is optimized to use available CPU instructions in performance-critical operations.
To enable the following instructions: AVX2 AVX512F AVX512_VNNI FMA, in other operations, rebuild TensorFlow with the appropriate compiler flags.
2023-12-01 15:17:44.403412: I tensorflow/core/platform/cpu_feature_guard.cc:182] This TensorFlow binary is optimized to use available CPU instructions in performance-critical operations.
To enable the following instructions: AVX2 AVX512F AVX512_VNNI FMA, in other operations, rebuild TensorFlow with the appropriate compiler flags.
2023-12-01 15:17:44.403440: I tensorflow/core/platform/cpu_feature_guard.cc:182] This TensorFlow binary is optimized to use available CPU instructions in performance-critical operations.
To enable the following instructions: AVX2 AVX512F AVX512_VNNI FMA, in other operations, rebuild TensorFlow with the appropriate compiler flags.
2023-12-01 15:17:44.403442: I tensorflow/core/platform/cpu_feature_guard.cc:182] This TensorFlow binary is optimized to use available CPU instructions in performance-critical operations.
To enable the following instructions: AVX2 AVX512F AVX512_VNNI FMA, in other operations, rebuild TensorFlow with the appropriate compiler flags.
2023-12-01 15:17:44.403471: I tensorflow/core/platform/cpu_feature_guard.cc:182] This TensorFlow binary is optimized to use available CPU instructions in performance-critical operations.
To enable the following instructions: AVX2 AVX512F AVX512_VNNI FMA, in other operations, rebuild TensorFlow with the appropriate compiler flags.
2023-12-01 15:17:44.403480: I tensorflow/core/platform/cpu_feature_guard.cc:182] This TensorFlow binary is optimized to use available CPU instructions in performance-critical operations.
To enable the following instructions: AVX2 AVX512F AVX512_VNNI FMA, in other operations, rebuild TensorFlow with the appropriate compiler flags.
2023-12-01 15:17:44.403480: I tensorflow/core/platform/cpu_feature_guard.cc:182] This TensorFlow binary is optimized to use available CPU instructions in performance-critical operations.
To enable the following instructions: AVX2 AVX512F AVX512_VNNI FMA, in other operations, rebuild TensorFlow with the appropriate compiler flags.
2023-12-01 15:17:44.403491: I tensorflow/core/platform/cpu_feature_guard.cc:182] This TensorFlow binary is optimized to use available CPU instructions in performance-critical operations.
To enable the following instructions: AVX2 AVX512F AVX512_VNNI FMA, in other operations, rebuild TensorFlow with the appropriate compiler flags.
2023-12-01 15:17:44.403501: I tensorflow/core/platform/cpu_feature_guard.cc:182] This TensorFlow binary is optimized to use available CPU instructions in performance-critical operations.
To enable the following instructions: AVX2 AVX512F AVX512_VNNI FMA, in other operations, rebuild TensorFlow with the appropriate compiler flags.
2023-12-01 15:17:44.403889: I tensorflow/core/platform/cpu_feature_guard.cc:182] This TensorFlow binary is optimized to use available CPU instructions in performance-critical operations.
To enable the following instructions: AVX2 AVX512F AVX512_VNNI FMA, in other operations, rebuild TensorFlow with the appropriate compiler flags.
2023-12-01 15:17:44.405571: I tensorflow/core/platform/cpu_feature_guard.cc:182] This TensorFlow binary is optimized to use available CPU instructions in performance-critical operations.
To enable the following instructions: AVX2 AVX512F AVX512_VNNI FMA, in other operations, rebuild TensorFlow with the appropriate compiler flags.
2023-12-01 15:17:44.405597: I tensorflow/core/platform/cpu_feature_guard.cc:182] This TensorFlow binary is optimized to use available CPU instructions in performance-critical operations.
To enable the following instructions: AVX2 AVX512F AVX512_VNNI FMA, in other operations, rebuild TensorFlow with the appropriate compiler flags.
2023-12-01 15:17:47.464300: W tensorflow/compiler/tf2tensorrt/utils/py_utils.cc:38] TF-TRT Warning: Could not find TensorRT
2023-12-01 15:17:47.464303: W tensorflow/compiler/tf2tensorrt/utils/py_utils.cc:38] TF-TRT Warning: Could not find TensorRT
2023-12-01 15:17:47.464509: W tensorflow/compiler/tf2tensorrt/utils/py_utils.cc:38] TF-TRT Warning: Could not find TensorRT
2023-12-01 15:17:47.464528: W tensorflow/compiler/tf2tensorrt/utils/py_utils.cc:38] TF-TRT Warning: Could not find TensorRT
2023-12-01 15:17:47.464557: W tensorflow/compiler/tf2tensorrt/utils/py_utils.cc:38] TF-TRT Warning: Could not find TensorRT
2023-12-01 15:17:47.464579: W tensorflow/compiler/tf2tensorrt/utils/py_utils.cc:38] TF-TRT Warning: Could not find TensorRT
2023-12-01 15:17:47.464579: W tensorflow/compiler/tf2tensorrt/utils/py_utils.cc:38] TF-TRT Warning: Could not find TensorRT
2023-12-01 15:17:47.464581: W tensorflow/compiler/tf2tensorrt/utils/py_utils.cc:38] TF-TRT Warning: Could not find TensorRT
2023-12-01 15:17:47.464587: W tensorflow/compiler/tf2tensorrt/utils/py_utils.cc:38] TF-TRT Warning: Could not find TensorRT
2023-12-01 15:17:47.464592: W tensorflow/compiler/tf2tensorrt/utils/py_utils.cc:38] TF-TRT Warning: Could not find TensorRT
2023-12-01 15:17:47.464593: W tensorflow/compiler/tf2tensorrt/utils/py_utils.cc:38] TF-TRT Warning: Could not find TensorRT
2023-12-01 15:17:47.464600: W tensorflow/compiler/tf2tensorrt/utils/py_utils.cc:38] TF-TRT Warning: Could not find TensorRT
2023-12-01 15:17:47.464601: W tensorflow/compiler/tf2tensorrt/utils/py_utils.cc:38] TF-TRT Warning: Could not find TensorRT
2023-12-01 15:17:47.464609: W tensorflow/compiler/tf2tensorrt/utils/py_utils.cc:38] TF-TRT Warning: Could not find TensorRT
2023-12-01 15:17:47.464625: W tensorflow/compiler/tf2tensorrt/utils/py_utils.cc:38] TF-TRT Warning: Could not find TensorRT
2023-12-01 15:17:47.464626: W tensorflow/compiler/tf2tensorrt/utils/py_utils.cc:38] TF-TRT Warning: Could not find TensorRT
2023-12-01 15:17:47.464629: W tensorflow/compiler/tf2tensorrt/utils/py_utils.cc:38] TF-TRT Warning: Could not find TensorRT
2023-12-01 15:17:47.464630: W tensorflow/compiler/tf2tensorrt/utils/py_utils.cc:38] TF-TRT Warning: Could not find TensorRT
2023-12-01 15:17:47.464636: W tensorflow/compiler/tf2tensorrt/utils/py_utils.cc:38] TF-TRT Warning: Could not find TensorRT
2023-12-01 15:17:47.464636: W tensorflow/compiler/tf2tensorrt/utils/py_utils.cc:38] TF-TRT Warning: Could not find TensorRT
2023-12-01 15:17:47.464640: W tensorflow/compiler/tf2tensorrt/utils/py_utils.cc:38] TF-TRT Warning: Could not find TensorRT
2023-12-01 15:17:47.464640: W tensorflow/compiler/tf2tensorrt/utils/py_utils.cc:38] TF-TRT Warning: Could not find TensorRT
2023-12-01 15:17:47.464645: W tensorflow/compiler/tf2tensorrt/utils/py_utils.cc:38] TF-TRT Warning: Could not find TensorRT
2023-12-01 15:17:47.464647: W tensorflow/compiler/tf2tensorrt/utils/py_utils.cc:38] TF-TRT Warning: Could not find TensorRT
2023-12-01 15:17:47.464647: W tensorflow/compiler/tf2tensorrt/utils/py_utils.cc:38] TF-TRT Warning: Could not find TensorRT
2023-12-01 15:17:47.464648: W tensorflow/compiler/tf2tensorrt/utils/py_utils.cc:38] TF-TRT Warning: Could not find TensorRT
2023-12-01 15:17:47.464653: W tensorflow/compiler/tf2tensorrt/utils/py_utils.cc:38] TF-TRT Warning: Could not find TensorRT
2023-12-01 15:17:47.464655: W tensorflow/compiler/tf2tensorrt/utils/py_utils.cc:38] TF-TRT Warning: Could not find TensorRT
2023-12-01 15:17:47.464657: W tensorflow/compiler/tf2tensorrt/utils/py_utils.cc:38] TF-TRT Warning: Could not find TensorRT
2023-12-01 15:17:47.464661: W tensorflow/compiler/tf2tensorrt/utils/py_utils.cc:38] TF-TRT Warning: Could not find TensorRT
2023-12-01 15:17:47.464663: W tensorflow/compiler/tf2tensorrt/utils/py_utils.cc:38] TF-TRT Warning: Could not find TensorRT
2023-12-01 15:17:47.464665: W tensorflow/compiler/tf2tensorrt/utils/py_utils.cc:38] TF-TRT Warning: Could not find TensorRT
2023-12-01 15:17:47.464675: W tensorflow/compiler/tf2tensorrt/utils/py_utils.cc:38] TF-TRT Warning: Could not find TensorRT
2023-12-01 15:17:47.464676: W tensorflow/compiler/tf2tensorrt/utils/py_utils.cc:38] TF-TRT Warning: Could not find TensorRT
2023-12-01 15:17:47.464685: W tensorflow/compiler/tf2tensorrt/utils/py_utils.cc:38] TF-TRT Warning: Could not find TensorRT
2023-12-01 15:17:47.464703: W tensorflow/compiler/tf2tensorrt/utils/py_utils.cc:38] TF-TRT Warning: Could not find TensorRT
2023-12-01 15:17:47.464724: W tensorflow/compiler/tf2tensorrt/utils/py_utils.cc:38] TF-TRT Warning: Could not find TensorRT
2023-12-01 15:17:47.464736: W tensorflow/compiler/tf2tensorrt/utils/py_utils.cc:38] TF-TRT Warning: Could not find TensorRT
2023-12-01 15:17:47.464737: W tensorflow/compiler/tf2tensorrt/utils/py_utils.cc:38] TF-TRT Warning: Could not find TensorRT
2023-12-01 15:17:47.464739: W tensorflow/compiler/tf2tensorrt/utils/py_utils.cc:38] TF-TRT Warning: Could not find TensorRT
2023-12-01 15:17:47.464747: W tensorflow/compiler/tf2tensorrt/utils/py_utils.cc:38] TF-TRT Warning: Could not find TensorRT
2023-12-01 15:17:47.464750: W tensorflow/compiler/tf2tensorrt/utils/py_utils.cc:38] TF-TRT Warning: Could not find TensorRT
2023-12-01 15:17:47.464751: W tensorflow/compiler/tf2tensorrt/utils/py_utils.cc:38] TF-TRT Warning: Could not find TensorRT
2023-12-01 15:17:47.464761: W tensorflow/compiler/tf2tensorrt/utils/py_utils.cc:38] TF-TRT Warning: Could not find TensorRT
2023-12-01 15:17:47.464762: W tensorflow/compiler/tf2tensorrt/utils/py_utils.cc:38] TF-TRT Warning: Could not find TensorRT
2023-12-01 15:17:47.464761: W tensorflow/compiler/tf2tensorrt/utils/py_utils.cc:38] TF-TRT Warning: Could not find TensorRT
2023-12-01 15:17:47.465032: W tensorflow/compiler/tf2tensorrt/utils/py_utils.cc:38] TF-TRT Warning: Could not find TensorRT
2023-12-01 15:17:47.477860: W tensorflow/compiler/tf2tensorrt/utils/py_utils.cc:38] TF-TRT Warning: Could not find TensorRT
WARNING:tensorflow:From /home/ketrong/miniconda3/envs/tpot2devenv/lib/python3.10/site-packages/tensorflow/python/compat/v2_compat.py:108: disable_resource_variables (from tensorflow.python.ops.variable_scope) is deprecated and will be removed in a future version.
Instructions for updating:
non-resource variables are not supported in the long term
WARNING:tensorflow:From /home/ketrong/miniconda3/envs/tpot2devenv/lib/python3.10/site-packages/tensorflow/python/compat/v2_compat.py:108: disable_resource_variables (from tensorflow.python.ops.variable_scope) is deprecated and will be removed in a future version.
Instructions for updating:
non-resource variables are not supported in the long term
WARNING:tensorflow:From /home/ketrong/miniconda3/envs/tpot2devenv/lib/python3.10/site-packages/tensorflow/python/compat/v2_compat.py:108: disable_resource_variables (from tensorflow.python.ops.variable_scope) is deprecated and will be removed in a future version.
Instructions for updating:
non-resource variables are not supported in the long term
WARNING:tensorflow:From /home/ketrong/miniconda3/envs/tpot2devenv/lib/python3.10/site-packages/tensorflow/python/compat/v2_compat.py:108: disable_resource_variables (from tensorflow.python.ops.variable_scope) is deprecated and will be removed in a future version.
Instructions for updating:
non-resource variables are not supported in the long term
WARNING:tensorflow:From /home/ketrong/miniconda3/envs/tpot2devenv/lib/python3.10/site-packages/tensorflow/python/compat/v2_compat.py:108: disable_resource_variables (from tensorflow.python.ops.variable_scope) is deprecated and will be removed in a future version.
Instructions for updating:
non-resource variables are not supported in the long term
WARNING:tensorflow:From /home/ketrong/miniconda3/envs/tpot2devenv/lib/python3.10/site-packages/tensorflow/python/compat/v2_compat.py:108: disable_resource_variables (from tensorflow.python.ops.variable_scope) is deprecated and will be removed in a future version.
Instructions for updating:
non-resource variables are not supported in the long term
WARNING:tensorflow:From /home/ketrong/miniconda3/envs/tpot2devenv/lib/python3.10/site-packages/tensorflow/python/compat/v2_compat.py:108: disable_resource_variables (from tensorflow.python.ops.variable_scope) is deprecated and will be removed in a future version.
Instructions for updating:
non-resource variables are not supported in the long term
WARNING:tensorflow:From /home/ketrong/miniconda3/envs/tpot2devenv/lib/python3.10/site-packages/tensorflow/python/compat/v2_compat.py:108: disable_resource_variables (from tensorflow.python.ops.variable_scope) is deprecated and will be removed in a future version.
Instructions for updating:
non-resource variables are not supported in the long term
WARNING:tensorflow:From /home/ketrong/miniconda3/envs/tpot2devenv/lib/python3.10/site-packages/tensorflow/python/compat/v2_compat.py:108: disable_resource_variables (from tensorflow.python.ops.variable_scope) is deprecated and will be removed in a future version.
Instructions for updating:
non-resource variables are not supported in the long term
WARNING:tensorflow:From /home/ketrong/miniconda3/envs/tpot2devenv/lib/python3.10/site-packages/tensorflow/python/compat/v2_compat.py:108: disable_resource_variables (from tensorflow.python.ops.variable_scope) is deprecated and will be removed in a future version.
Instructions for updating:
non-resource variables are not supported in the long term
WARNING:tensorflow:From /home/ketrong/miniconda3/envs/tpot2devenv/lib/python3.10/site-packages/tensorflow/python/compat/v2_compat.py:108: disable_resource_variables (from tensorflow.python.ops.variable_scope) is deprecated and will be removed in a future version.
Instructions for updating:
non-resource variables are not supported in the long term
WARNING:tensorflow:From /home/ketrong/miniconda3/envs/tpot2devenv/lib/python3.10/site-packages/tensorflow/python/compat/v2_compat.py:108: disable_resource_variables (from tensorflow.python.ops.variable_scope) is deprecated and will be removed in a future version.
Instructions for updating:
non-resource variables are not supported in the long term
WARNING:tensorflow:From /home/ketrong/miniconda3/envs/tpot2devenv/lib/python3.10/site-packages/tensorflow/python/compat/v2_compat.py:108: disable_resource_variables (from tensorflow.python.ops.variable_scope) is deprecated and will be removed in a future version.
Instructions for updating:
non-resource variables are not supported in the long term
WARNING:tensorflow:From /home/ketrong/miniconda3/envs/tpot2devenv/lib/python3.10/site-packages/tensorflow/python/compat/v2_compat.py:108: disable_resource_variables (from tensorflow.python.ops.variable_scope) is deprecated and will be removed in a future version.
Instructions for updating:
non-resource variables are not supported in the long term
WARNING:tensorflow:From /home/ketrong/miniconda3/envs/tpot2devenv/lib/python3.10/site-packages/tensorflow/python/compat/v2_compat.py:108: disable_resource_variables (from tensorflow.python.ops.variable_scope) is deprecated and will be removed in a future version.
Instructions for updating:
non-resource variables are not supported in the long term
WARNING:tensorflow:From /home/ketrong/miniconda3/envs/tpot2devenv/lib/python3.10/site-packages/tensorflow/python/compat/v2_compat.py:108: disable_resource_variables (from tensorflow.python.ops.variable_scope) is deprecated and will be removed in a future version.
Instructions for updating:
non-resource variables are not supported in the long term
WARNING:tensorflow:From /home/ketrong/miniconda3/envs/tpot2devenv/lib/python3.10/site-packages/tensorflow/python/compat/v2_compat.py:108: disable_resource_variables (from tensorflow.python.ops.variable_scope) is deprecated and will be removed in a future version.
Instructions for updating:
non-resource variables are not supported in the long term
WARNING:tensorflow:From /home/ketrong/miniconda3/envs/tpot2devenv/lib/python3.10/site-packages/tensorflow/python/compat/v2_compat.py:108: disable_resource_variables (from tensorflow.python.ops.variable_scope) is deprecated and will be removed in a future version.
Instructions for updating:
non-resource variables are not supported in the long term
WARNING:tensorflow:From /home/ketrong/miniconda3/envs/tpot2devenv/lib/python3.10/site-packages/tensorflow/python/compat/v2_compat.py:108: disable_resource_variables (from tensorflow.python.ops.variable_scope) is deprecated and will be removed in a future version.
Instructions for updating:
non-resource variables are not supported in the long term
WARNING:tensorflow:From /home/ketrong/miniconda3/envs/tpot2devenv/lib/python3.10/site-packages/tensorflow/python/compat/v2_compat.py:108: disable_resource_variables (from tensorflow.python.ops.variable_scope) is deprecated and will be removed in a future version.
Instructions for updating:
non-resource variables are not supported in the long term
WARNING:tensorflow:From /home/ketrong/miniconda3/envs/tpot2devenv/lib/python3.10/site-packages/tensorflow/python/compat/v2_compat.py:108: disable_resource_variables (from tensorflow.python.ops.variable_scope) is deprecated and will be removed in a future version.
Instructions for updating:
non-resource variables are not supported in the long term
WARNING:tensorflow:From /home/ketrong/miniconda3/envs/tpot2devenv/lib/python3.10/site-packages/tensorflow/python/compat/v2_compat.py:108: disable_resource_variables (from tensorflow.python.ops.variable_scope) is deprecated and will be removed in a future version.
Instructions for updating:
non-resource variables are not supported in the long term
WARNING:tensorflow:From /home/ketrong/miniconda3/envs/tpot2devenv/lib/python3.10/site-packages/tensorflow/python/compat/v2_compat.py:108: disable_resource_variables (from tensorflow.python.ops.variable_scope) is deprecated and will be removed in a future version.
Instructions for updating:
non-resource variables are not supported in the long term
WARNING:tensorflow:From /home/ketrong/miniconda3/envs/tpot2devenv/lib/python3.10/site-packages/tensorflow/python/compat/v2_compat.py:108: disable_resource_variables (from tensorflow.python.ops.variable_scope) is deprecated and will be removed in a future version.
Instructions for updating:
non-resource variables are not supported in the long term
WARNING:tensorflow:From /home/ketrong/miniconda3/envs/tpot2devenv/lib/python3.10/site-packages/tensorflow/python/compat/v2_compat.py:108: disable_resource_variables (from tensorflow.python.ops.variable_scope) is deprecated and will be removed in a future version.
Instructions for updating:
non-resource variables are not supported in the long term
WARNING:tensorflow:From /home/ketrong/miniconda3/envs/tpot2devenv/lib/python3.10/site-packages/tensorflow/python/compat/v2_compat.py:108: disable_resource_variables (from tensorflow.python.ops.variable_scope) is deprecated and will be removed in a future version.
Instructions for updating:
non-resource variables are not supported in the long term
WARNING:tensorflow:From /home/ketrong/miniconda3/envs/tpot2devenv/lib/python3.10/site-packages/tensorflow/python/compat/v2_compat.py:108: disable_resource_variables (from tensorflow.python.ops.variable_scope) is deprecated and will be removed in a future version.
Instructions for updating:
non-resource variables are not supported in the long term
WARNING:tensorflow:From /home/ketrong/miniconda3/envs/tpot2devenv/lib/python3.10/site-packages/tensorflow/python/compat/v2_compat.py:108: disable_resource_variables (from tensorflow.python.ops.variable_scope) is deprecated and will be removed in a future version.
Instructions for updating:
non-resource variables are not supported in the long term
WARNING:tensorflow:From /home/ketrong/miniconda3/envs/tpot2devenv/lib/python3.10/site-packages/tensorflow/python/compat/v2_compat.py:108: disable_resource_variables (from tensorflow.python.ops.variable_scope) is deprecated and will be removed in a future version.
Instructions for updating:
non-resource variables are not supported in the long term
WARNING:tensorflow:From /home/ketrong/miniconda3/envs/tpot2devenv/lib/python3.10/site-packages/tensorflow/python/compat/v2_compat.py:108: disable_resource_variables (from tensorflow.python.ops.variable_scope) is deprecated and will be removed in a future version.
Instructions for updating:
non-resource variables are not supported in the long term
WARNING:tensorflow:From /home/ketrong/miniconda3/envs/tpot2devenv/lib/python3.10/site-packages/tensorflow/python/compat/v2_compat.py:108: disable_resource_variables (from tensorflow.python.ops.variable_scope) is deprecated and will be removed in a future version.
Instructions for updating:
non-resource variables are not supported in the long term
WARNING:tensorflow:From /home/ketrong/miniconda3/envs/tpot2devenv/lib/python3.10/site-packages/tensorflow/python/compat/v2_compat.py:108: disable_resource_variables (from tensorflow.python.ops.variable_scope) is deprecated and will be removed in a future version.
Instructions for updating:
non-resource variables are not supported in the long term
WARNING:tensorflow:From /home/ketrong/miniconda3/envs/tpot2devenv/lib/python3.10/site-packages/tensorflow/python/compat/v2_compat.py:108: disable_resource_variables (from tensorflow.python.ops.variable_scope) is deprecated and will be removed in a future version.
Instructions for updating:
non-resource variables are not supported in the long term
WARNING:tensorflow:From /home/ketrong/miniconda3/envs/tpot2devenv/lib/python3.10/site-packages/tensorflow/python/compat/v2_compat.py:108: disable_resource_variables (from tensorflow.python.ops.variable_scope) is deprecated and will be removed in a future version.
Instructions for updating:
non-resource variables are not supported in the long term
WARNING:tensorflow:From /home/ketrong/miniconda3/envs/tpot2devenv/lib/python3.10/site-packages/tensorflow/python/compat/v2_compat.py:108: disable_resource_variables (from tensorflow.python.ops.variable_scope) is deprecated and will be removed in a future version.
Instructions for updating:
non-resource variables are not supported in the long term
WARNING:tensorflow:From /home/ketrong/miniconda3/envs/tpot2devenv/lib/python3.10/site-packages/tensorflow/python/compat/v2_compat.py:108: disable_resource_variables (from tensorflow.python.ops.variable_scope) is deprecated and will be removed in a future version.
Instructions for updating:
non-resource variables are not supported in the long term
WARNING:tensorflow:From /home/ketrong/miniconda3/envs/tpot2devenv/lib/python3.10/site-packages/tensorflow/python/compat/v2_compat.py:108: disable_resource_variables (from tensorflow.python.ops.variable_scope) is deprecated and will be removed in a future version.
Instructions for updating:
non-resource variables are not supported in the long term
WARNING:tensorflow:From /home/ketrong/miniconda3/envs/tpot2devenv/lib/python3.10/site-packages/tensorflow/python/compat/v2_compat.py:108: disable_resource_variables (from tensorflow.python.ops.variable_scope) is deprecated and will be removed in a future version.
Instructions for updating:
non-resource variables are not supported in the long term
WARNING:tensorflow:From /home/ketrong/miniconda3/envs/tpot2devenv/lib/python3.10/site-packages/tensorflow/python/compat/v2_compat.py:108: disable_resource_variables (from tensorflow.python.ops.variable_scope) is deprecated and will be removed in a future version.
Instructions for updating:
non-resource variables are not supported in the long term
WARNING:tensorflow:From /home/ketrong/miniconda3/envs/tpot2devenv/lib/python3.10/site-packages/tensorflow/python/compat/v2_compat.py:108: disable_resource_variables (from tensorflow.python.ops.variable_scope) is deprecated and will be removed in a future version.
Instructions for updating:
non-resource variables are not supported in the long term
WARNING:tensorflow:From /home/ketrong/miniconda3/envs/tpot2devenv/lib/python3.10/site-packages/tensorflow/python/compat/v2_compat.py:108: disable_resource_variables (from tensorflow.python.ops.variable_scope) is deprecated and will be removed in a future version.
Instructions for updating:
non-resource variables are not supported in the long term
WARNING:tensorflow:From /home/ketrong/miniconda3/envs/tpot2devenv/lib/python3.10/site-packages/tensorflow/python/compat/v2_compat.py:108: disable_resource_variables (from tensorflow.python.ops.variable_scope) is deprecated and will be removed in a future version.
Instructions for updating:
non-resource variables are not supported in the long term
WARNING:tensorflow:From /home/ketrong/miniconda3/envs/tpot2devenv/lib/python3.10/site-packages/tensorflow/python/compat/v2_compat.py:108: disable_resource_variables (from tensorflow.python.ops.variable_scope) is deprecated and will be removed in a future version.
Instructions for updating:
non-resource variables are not supported in the long term
WARNING:tensorflow:From /home/ketrong/miniconda3/envs/tpot2devenv/lib/python3.10/site-packages/tensorflow/python/compat/v2_compat.py:108: disable_resource_variables (from tensorflow.python.ops.variable_scope) is deprecated and will be removed in a future version.
Instructions for updating:
non-resource variables are not supported in the long term
WARNING:tensorflow:From /home/ketrong/miniconda3/envs/tpot2devenv/lib/python3.10/site-packages/tensorflow/python/compat/v2_compat.py:108: disable_resource_variables (from tensorflow.python.ops.variable_scope) is deprecated and will be removed in a future version.
Instructions for updating:
non-resource variables are not supported in the long term
WARNING:tensorflow:From /home/ketrong/miniconda3/envs/tpot2devenv/lib/python3.10/site-packages/tensorflow/python/compat/v2_compat.py:108: disable_resource_variables (from tensorflow.python.ops.variable_scope) is deprecated and will be removed in a future version.
Instructions for updating:
non-resource variables are not supported in the long term
WARNING:tensorflow:From /home/ketrong/miniconda3/envs/tpot2devenv/lib/python3.10/site-packages/tensorflow/python/compat/v2_compat.py:108: disable_resource_variables (from tensorflow.python.ops.variable_scope) is deprecated and will be removed in a future version.
Instructions for updating:
non-resource variables are not supported in the long term
WARNING:tensorflow:From /home/ketrong/miniconda3/envs/tpot2devenv/lib/python3.10/site-packages/tensorflow/python/compat/v2_compat.py:108: disable_resource_variables (from tensorflow.python.ops.variable_scope) is deprecated and will be removed in a future version.
Instructions for updating:
non-resource variables are not supported in the long term
  0%|          | 0/75 [00:00<?, ?it/s]Generation:   0%|          | 0/75 [00:00<?, ?it/s]WARNING THIS INDIVIDUAL CAUSED AND EXCEPTION 
 [('SVC_1', 'GAINImputer_1'), ('SVC_1', 'GAINImputer_2'), ('SVC_1', 'GAINImputer_3')] 
 'batch_size' 
 Traceback (most recent call last):
  File "/home/ketrong/miniconda3/envs/tpot2devenv/lib/python3.10/site-packages/tpot2/utils/eval_utils.py", line 53, in objective_nan_wrapper
    value = func_timeout.func_timeout(timeout, objective_function, args=[individual], kwargs=objective_kwargs)
  File "/home/ketrong/miniconda3/envs/tpot2devenv/lib/python3.10/site-packages/func_timeout/dafunc.py", line 108, in func_timeout
    raise_exception(exception)
  File "/home/ketrong/miniconda3/envs/tpot2devenv/lib/python3.10/site-packages/func_timeout/py3_raise.py", line 7, in raise_exception
    raise exception[0] from None
  File "/home/ketrong/miniconda3/envs/tpot2devenv/lib/python3.10/site-packages/tpot2/tpot_estimator/estimator.py", line 702, in objective_function
    return objective_function_generator(
  File "/home/ketrong/miniconda3/envs/tpot2devenv/lib/python3.10/site-packages/tpot2/tpot_estimator/estimator_utils.py", line 117, in objective_function_generator
    cv_obj_scores = cross_val_score_objective(sklearn.base.clone(pipeline),x,y,scorers=scorers, cv=cv , fold=step)
  File "/home/ketrong/miniconda3/envs/tpot2devenv/lib/python3.10/site-packages/tpot2/tpot_estimator/cross_val_utils.py", line 28, in cross_val_score_objective
    this_fold_pipeline.fit(X_train,y_train)
  File "/home/ketrong/miniconda3/envs/tpot2devenv/lib/python3.10/site-packages/tpot2/graphsklearn.py", line 354, in fit
    fit_sklearn_digraph(   graph=self.graph,
  File "/home/ketrong/miniconda3/envs/tpot2devenv/lib/python3.10/site-packages/tpot2/graphsklearn.py", line 155, in fit_sklearn_digraph
    transformed, instance = fit_transform_one_cached(instance, this_X, y, subset_indexes=subset_indexes)#instance.fit_transform(this_X,y)
  File "/home/ketrong/miniconda3/envs/tpot2devenv/lib/python3.10/site-packages/joblib/memory.py", line 353, in __call__
    return self.func(*args, **kwargs)
  File "/home/ketrong/miniconda3/envs/tpot2devenv/lib/python3.10/site-packages/tpot2/graphsklearn.py", line 96, in _fit_transform_one
    res = model.fit_transform(X, y, **fit_params)
  File "/home/ketrong/miniconda3/envs/tpot2devenv/lib/python3.10/site-packages/sklearn/utils/_set_output.py", line 157, in wrapped
    data_to_wrap = f(self, X, *args, **kwargs)
  File "/common/ketrong/AutoImputeExp/tpot2_imputetest/Impute_Experiments/transformers.py", line 610, in fit_transform
    return self.fit(X, **fit_params).transform(X)
  File "/home/ketrong/miniconda3/envs/tpot2devenv/lib/python3.10/site-packages/sklearn/utils/_set_output.py", line 157, in wrapped
    data_to_wrap = f(self, X, *args, **kwargs)
  File "/common/ketrong/AutoImputeExp/tpot2_imputetest/Impute_Experiments/transformers.py", line 606, in transform
    return self.gain(X, self.params)
  File "/common/ketrong/AutoImputeExp/tpot2_imputetest/Impute_Experiments/transformers.py", line 630, in gain
    batch_size = gain_parameters['batch_size']
KeyError: 'batch_size'

WARNING THIS INDIVIDUAL CAUSED AND EXCEPTION 
 [('GaussianNB_1', 'GAINImputer_1'), ('GaussianNB_1', 'GAINImputer_2')] 
 'batch_size' 
 Traceback (most recent call last):
  File "/home/ketrong/miniconda3/envs/tpot2devenv/lib/python3.10/site-packages/tpot2/utils/eval_utils.py", line 53, in objective_nan_wrapper
    value = func_timeout.func_timeout(timeout, objective_function, args=[individual], kwargs=objective_kwargs)
  File "/home/ketrong/miniconda3/envs/tpot2devenv/lib/python3.10/site-packages/func_timeout/dafunc.py", line 108, in func_timeout
    raise_exception(exception)
  File "/home/ketrong/miniconda3/envs/tpot2devenv/lib/python3.10/site-packages/func_timeout/py3_raise.py", line 7, in raise_exception
    raise exception[0] from None
  File "/home/ketrong/miniconda3/envs/tpot2devenv/lib/python3.10/site-packages/tpot2/tpot_estimator/estimator.py", line 702, in objective_function
    return objective_function_generator(
  File "/home/ketrong/miniconda3/envs/tpot2devenv/lib/python3.10/site-packages/tpot2/tpot_estimator/estimator_utils.py", line 117, in objective_function_generator
    cv_obj_scores = cross_val_score_objective(sklearn.base.clone(pipeline),x,y,scorers=scorers, cv=cv , fold=step)
  File "/home/ketrong/miniconda3/envs/tpot2devenv/lib/python3.10/site-packages/tpot2/tpot_estimator/cross_val_utils.py", line 28, in cross_val_score_objective
    this_fold_pipeline.fit(X_train,y_train)
  File "/home/ketrong/miniconda3/envs/tpot2devenv/lib/python3.10/site-packages/tpot2/graphsklearn.py", line 354, in fit
    fit_sklearn_digraph(   graph=self.graph,
  File "/home/ketrong/miniconda3/envs/tpot2devenv/lib/python3.10/site-packages/tpot2/graphsklearn.py", line 155, in fit_sklearn_digraph
    transformed, instance = fit_transform_one_cached(instance, this_X, y, subset_indexes=subset_indexes)#instance.fit_transform(this_X,y)
  File "/home/ketrong/miniconda3/envs/tpot2devenv/lib/python3.10/site-packages/joblib/memory.py", line 353, in __call__
    return self.func(*args, **kwargs)
  File "/home/ketrong/miniconda3/envs/tpot2devenv/lib/python3.10/site-packages/tpot2/graphsklearn.py", line 96, in _fit_transform_one
    res = model.fit_transform(X, y, **fit_params)
  File "/home/ketrong/miniconda3/envs/tpot2devenv/lib/python3.10/site-packages/sklearn/utils/_set_output.py", line 157, in wrapped
    data_to_wrap = f(self, X, *args, **kwargs)
  File "/common/ketrong/AutoImputeExp/tpot2_imputetest/Impute_Experiments/transformers.py", line 610, in fit_transform
    return self.fit(X, **fit_params).transform(X)
  File "/home/ketrong/miniconda3/envs/tpot2devenv/lib/python3.10/site-packages/sklearn/utils/_set_output.py", line 157, in wrapped
    data_to_wrap = f(self, X, *args, **kwargs)
  File "/common/ketrong/AutoImputeExp/tpot2_imputetest/Impute_Experiments/transformers.py", line 606, in transform
    return self.gain(X, self.params)
  File "/common/ketrong/AutoImputeExp/tpot2_imputetest/Impute_Experiments/transformers.py", line 630, in gain
    batch_size = gain_parameters['batch_size']
KeyError: 'batch_size'

WARNING THIS INDIVIDUAL CAUSED AND EXCEPTION 
 [('GradientBoostingClassifier_1', 'RandomForestImputer_1'), ('GradientBoostingClassifier_1', 'RandomForestImputer_2'), ('GradientBoostingClassifier_1', 'RandomForestImputer_3'), ('GradientBoostingClassifier_1', 'GAINImputer_1'), ('GradientBoostingClassifier_1', 'RandomForestImputer_4'), ('GradientBoostingClassifier_1', 'IterativeImputer_1'), ('GradientBoostingClassifier_1', 'RandomForestImputer_5'), ('GradientBoostingClassifier_1', 'GAINImputer_2')] 
 'batch_size' 
 Traceback (most recent call last):
  File "/home/ketrong/miniconda3/envs/tpot2devenv/lib/python3.10/site-packages/tpot2/utils/eval_utils.py", line 53, in objective_nan_wrapper
    value = func_timeout.func_timeout(timeout, objective_function, args=[individual], kwargs=objective_kwargs)
  File "/home/ketrong/miniconda3/envs/tpot2devenv/lib/python3.10/site-packages/func_timeout/dafunc.py", line 108, in func_timeout
    raise_exception(exception)
  File "/home/ketrong/miniconda3/envs/tpot2devenv/lib/python3.10/site-packages/func_timeout/py3_raise.py", line 7, in raise_exception
    raise exception[0] from None
  File "/home/ketrong/miniconda3/envs/tpot2devenv/lib/python3.10/site-packages/tpot2/tpot_estimator/estimator.py", line 702, in objective_function
    return objective_function_generator(
  File "/home/ketrong/miniconda3/envs/tpot2devenv/lib/python3.10/site-packages/tpot2/tpot_estimator/estimator_utils.py", line 117, in objective_function_generator
    cv_obj_scores = cross_val_score_objective(sklearn.base.clone(pipeline),x,y,scorers=scorers, cv=cv , fold=step)
  File "/home/ketrong/miniconda3/envs/tpot2devenv/lib/python3.10/site-packages/tpot2/tpot_estimator/cross_val_utils.py", line 28, in cross_val_score_objective
    this_fold_pipeline.fit(X_train,y_train)
  File "/home/ketrong/miniconda3/envs/tpot2devenv/lib/python3.10/site-packages/tpot2/graphsklearn.py", line 354, in fit
    fit_sklearn_digraph(   graph=self.graph,
  File "/home/ketrong/miniconda3/envs/tpot2devenv/lib/python3.10/site-packages/tpot2/graphsklearn.py", line 155, in fit_sklearn_digraph
    transformed, instance = fit_transform_one_cached(instance, this_X, y, subset_indexes=subset_indexes)#instance.fit_transform(this_X,y)
  File "/home/ketrong/miniconda3/envs/tpot2devenv/lib/python3.10/site-packages/joblib/memory.py", line 353, in __call__
    return self.func(*args, **kwargs)
  File "/home/ketrong/miniconda3/envs/tpot2devenv/lib/python3.10/site-packages/tpot2/graphsklearn.py", line 96, in _fit_transform_one
    res = model.fit_transform(X, y, **fit_params)
  File "/home/ketrong/miniconda3/envs/tpot2devenv/lib/python3.10/site-packages/sklearn/utils/_set_output.py", line 157, in wrapped
    data_to_wrap = f(self, X, *args, **kwargs)
  File "/common/ketrong/AutoImputeExp/tpot2_imputetest/Impute_Experiments/transformers.py", line 610, in fit_transform
    return self.fit(X, **fit_params).transform(X)
  File "/home/ketrong/miniconda3/envs/tpot2devenv/lib/python3.10/site-packages/sklearn/utils/_set_output.py", line 157, in wrapped
    data_to_wrap = f(self, X, *args, **kwargs)
  File "/common/ketrong/AutoImputeExp/tpot2_imputetest/Impute_Experiments/transformers.py", line 606, in transform
    return self.gain(X, self.params)
  File "/common/ketrong/AutoImputeExp/tpot2_imputetest/Impute_Experiments/transformers.py", line 630, in gain
    batch_size = gain_parameters['batch_size']
KeyError: 'batch_size'

WARNING THIS INDIVIDUAL CAUSED AND EXCEPTION 
 [('KNeighborsClassifier_1', 'GAINImputer_1'), ('KNeighborsClassifier_1', 'SimpleImputer_1'), ('KNeighborsClassifier_1', 'IterativeImputer_1'), ('KNeighborsClassifier_1', 'GAINImputer_2'), ('KNeighborsClassifier_1', 'SimpleImputer_2'), ('KNeighborsClassifier_1', 'SimpleImputer_3')] 
 'batch_size' 
 Traceback (most recent call last):
  File "/home/ketrong/miniconda3/envs/tpot2devenv/lib/python3.10/site-packages/tpot2/utils/eval_utils.py", line 53, in objective_nan_wrapper
    value = func_timeout.func_timeout(timeout, objective_function, args=[individual], kwargs=objective_kwargs)
  File "/home/ketrong/miniconda3/envs/tpot2devenv/lib/python3.10/site-packages/func_timeout/dafunc.py", line 108, in func_timeout
    raise_exception(exception)
  File "/home/ketrong/miniconda3/envs/tpot2devenv/lib/python3.10/site-packages/func_timeout/py3_raise.py", line 7, in raise_exception
    raise exception[0] from None
  File "/home/ketrong/miniconda3/envs/tpot2devenv/lib/python3.10/site-packages/tpot2/tpot_estimator/estimator.py", line 702, in objective_function
    return objective_function_generator(
  File "/home/ketrong/miniconda3/envs/tpot2devenv/lib/python3.10/site-packages/tpot2/tpot_estimator/estimator_utils.py", line 117, in objective_function_generator
    cv_obj_scores = cross_val_score_objective(sklearn.base.clone(pipeline),x,y,scorers=scorers, cv=cv , fold=step)
  File "/home/ketrong/miniconda3/envs/tpot2devenv/lib/python3.10/site-packages/tpot2/tpot_estimator/cross_val_utils.py", line 28, in cross_val_score_objective
    this_fold_pipeline.fit(X_train,y_train)
  File "/home/ketrong/miniconda3/envs/tpot2devenv/lib/python3.10/site-packages/tpot2/graphsklearn.py", line 354, in fit
    fit_sklearn_digraph(   graph=self.graph,
  File "/home/ketrong/miniconda3/envs/tpot2devenv/lib/python3.10/site-packages/tpot2/graphsklearn.py", line 155, in fit_sklearn_digraph
    transformed, instance = fit_transform_one_cached(instance, this_X, y, subset_indexes=subset_indexes)#instance.fit_transform(this_X,y)
  File "/home/ketrong/miniconda3/envs/tpot2devenv/lib/python3.10/site-packages/joblib/memory.py", line 353, in __call__
    return self.func(*args, **kwargs)
  File "/home/ketrong/miniconda3/envs/tpot2devenv/lib/python3.10/site-packages/tpot2/graphsklearn.py", line 96, in _fit_transform_one
    res = model.fit_transform(X, y, **fit_params)
  File "/home/ketrong/miniconda3/envs/tpot2devenv/lib/python3.10/site-packages/sklearn/utils/_set_output.py", line 157, in wrapped
    data_to_wrap = f(self, X, *args, **kwargs)
  File "/common/ketrong/AutoImputeExp/tpot2_imputetest/Impute_Experiments/transformers.py", line 610, in fit_transform
    return self.fit(X, **fit_params).transform(X)
  File "/home/ketrong/miniconda3/envs/tpot2devenv/lib/python3.10/site-packages/sklearn/utils/_set_output.py", line 157, in wrapped
    data_to_wrap = f(self, X, *args, **kwargs)
  File "/common/ketrong/AutoImputeExp/tpot2_imputetest/Impute_Experiments/transformers.py", line 606, in transform
    return self.gain(X, self.params)
  File "/common/ketrong/AutoImputeExp/tpot2_imputetest/Impute_Experiments/transformers.py", line 630, in gain
    batch_size = gain_parameters['batch_size']
KeyError: 'batch_size'

WARNING THIS INDIVIDUAL CAUSED AND EXCEPTION 
 [('MultinomialNB_1', 'IterativeImputer_1')] 
 KNeighborsRegressor.predict() got an unexpected keyword argument 'return_std' 
 Traceback (most recent call last):
  File "/home/ketrong/miniconda3/envs/tpot2devenv/lib/python3.10/site-packages/tpot2/utils/eval_utils.py", line 53, in objective_nan_wrapper
    value = func_timeout.func_timeout(timeout, objective_function, args=[individual], kwargs=objective_kwargs)
  File "/home/ketrong/miniconda3/envs/tpot2devenv/lib/python3.10/site-packages/func_timeout/dafunc.py", line 108, in func_timeout
    raise_exception(exception)
  File "/home/ketrong/miniconda3/envs/tpot2devenv/lib/python3.10/site-packages/func_timeout/py3_raise.py", line 7, in raise_exception
    raise exception[0] from None
  File "/home/ketrong/miniconda3/envs/tpot2devenv/lib/python3.10/site-packages/tpot2/tpot_estimator/estimator.py", line 702, in objective_function
    return objective_function_generator(
  File "/home/ketrong/miniconda3/envs/tpot2devenv/lib/python3.10/site-packages/tpot2/tpot_estimator/estimator_utils.py", line 117, in objective_function_generator
    cv_obj_scores = cross_val_score_objective(sklearn.base.clone(pipeline),x,y,scorers=scorers, cv=cv , fold=step)
  File "/home/ketrong/miniconda3/envs/tpot2devenv/lib/python3.10/site-packages/tpot2/tpot_estimator/cross_val_utils.py", line 28, in cross_val_score_objective
    this_fold_pipeline.fit(X_train,y_train)
  File "/home/ketrong/miniconda3/envs/tpot2devenv/lib/python3.10/site-packages/tpot2/graphsklearn.py", line 354, in fit
    fit_sklearn_digraph(   graph=self.graph,
  File "/home/ketrong/miniconda3/envs/tpot2devenv/lib/python3.10/site-packages/tpot2/graphsklearn.py", line 155, in fit_sklearn_digraph
    transformed, instance = fit_transform_one_cached(instance, this_X, y, subset_indexes=subset_indexes)#instance.fit_transform(this_X,y)
  File "/home/ketrong/miniconda3/envs/tpot2devenv/lib/python3.10/site-packages/joblib/memory.py", line 353, in __call__
    return self.func(*args, **kwargs)
  File "/home/ketrong/miniconda3/envs/tpot2devenv/lib/python3.10/site-packages/tpot2/graphsklearn.py", line 96, in _fit_transform_one
    res = model.fit_transform(X, y, **fit_params)
  File "/home/ketrong/miniconda3/envs/tpot2devenv/lib/python3.10/site-packages/sklearn/utils/_set_output.py", line 157, in wrapped
    data_to_wrap = f(self, X, *args, **kwargs)
  File "/home/ketrong/miniconda3/envs/tpot2devenv/lib/python3.10/site-packages/sklearn/base.py", line 1152, in wrapper
    return fit_method(estimator, *args, **kwargs)
  File "/home/ketrong/miniconda3/envs/tpot2devenv/lib/python3.10/site-packages/sklearn/impute/_iterative.py", line 765, in fit_transform
    Xt, estimator = self._impute_one_feature(
  File "/home/ketrong/miniconda3/envs/tpot2devenv/lib/python3.10/site-packages/sklearn/impute/_iterative.py", line 425, in _impute_one_feature
    mus, sigmas = estimator.predict(X_test, return_std=True)
TypeError: KNeighborsRegressor.predict() got an unexpected keyword argument 'return_std'

WARNING THIS INDIVIDUAL CAUSED AND EXCEPTION 
 [('MLPClassifier_1', 'GAINImputer_1'), ('MLPClassifier_1', 'KNNImputer_1'), ('MLPClassifier_1', 'RandomForestImputer_1'), ('MLPClassifier_1', 'RandomForestImputer_2'), ('MLPClassifier_1', 'RandomForestImputer_3'), ('MLPClassifier_1', 'RandomForestImputer_4'), ('MLPClassifier_1', 'GAINImputer_2'), ('MLPClassifier_1', 'GAINImputer_3')] 
 'batch_size' 
 Traceback (most recent call last):
  File "/home/ketrong/miniconda3/envs/tpot2devenv/lib/python3.10/site-packages/tpot2/utils/eval_utils.py", line 53, in objective_nan_wrapper
    value = func_timeout.func_timeout(timeout, objective_function, args=[individual], kwargs=objective_kwargs)
  File "/home/ketrong/miniconda3/envs/tpot2devenv/lib/python3.10/site-packages/func_timeout/dafunc.py", line 108, in func_timeout
    raise_exception(exception)
  File "/home/ketrong/miniconda3/envs/tpot2devenv/lib/python3.10/site-packages/func_timeout/py3_raise.py", line 7, in raise_exception
    raise exception[0] from None
  File "/home/ketrong/miniconda3/envs/tpot2devenv/lib/python3.10/site-packages/tpot2/tpot_estimator/estimator.py", line 702, in objective_function
    return objective_function_generator(
  File "/home/ketrong/miniconda3/envs/tpot2devenv/lib/python3.10/site-packages/tpot2/tpot_estimator/estimator_utils.py", line 117, in objective_function_generator
    cv_obj_scores = cross_val_score_objective(sklearn.base.clone(pipeline),x,y,scorers=scorers, cv=cv , fold=step)
  File "/home/ketrong/miniconda3/envs/tpot2devenv/lib/python3.10/site-packages/tpot2/tpot_estimator/cross_val_utils.py", line 28, in cross_val_score_objective
    this_fold_pipeline.fit(X_train,y_train)
  File "/home/ketrong/miniconda3/envs/tpot2devenv/lib/python3.10/site-packages/tpot2/graphsklearn.py", line 354, in fit
    fit_sklearn_digraph(   graph=self.graph,
  File "/home/ketrong/miniconda3/envs/tpot2devenv/lib/python3.10/site-packages/tpot2/graphsklearn.py", line 155, in fit_sklearn_digraph
    transformed, instance = fit_transform_one_cached(instance, this_X, y, subset_indexes=subset_indexes)#instance.fit_transform(this_X,y)
  File "/home/ketrong/miniconda3/envs/tpot2devenv/lib/python3.10/site-packages/joblib/memory.py", line 353, in __call__
    return self.func(*args, **kwargs)
  File "/home/ketrong/miniconda3/envs/tpot2devenv/lib/python3.10/site-packages/tpot2/graphsklearn.py", line 96, in _fit_transform_one
    res = model.fit_transform(X, y, **fit_params)
  File "/home/ketrong/miniconda3/envs/tpot2devenv/lib/python3.10/site-packages/sklearn/utils/_set_output.py", line 157, in wrapped
    data_to_wrap = f(self, X, *args, **kwargs)
  File "/common/ketrong/AutoImputeExp/tpot2_imputetest/Impute_Experiments/transformers.py", line 610, in fit_transform
    return self.fit(X, **fit_params).transform(X)
  File "/home/ketrong/miniconda3/envs/tpot2devenv/lib/python3.10/site-packages/sklearn/utils/_set_output.py", line 157, in wrapped
    data_to_wrap = f(self, X, *args, **kwargs)
  File "/common/ketrong/AutoImputeExp/tpot2_imputetest/Impute_Experiments/transformers.py", line 606, in transform
    return self.gain(X, self.params)
  File "/common/ketrong/AutoImputeExp/tpot2_imputetest/Impute_Experiments/transformers.py", line 630, in gain
    batch_size = gain_parameters['batch_size']
KeyError: 'batch_size'

WARNING THIS INDIVIDUAL CAUSED AND EXCEPTION 
 [('DecisionTreeClassifier_1', 'IterativeImputer_1'), ('DecisionTreeClassifier_1', 'RandomForestImputer_1'), ('DecisionTreeClassifier_1', 'RandomForestImputer_2'), ('DecisionTreeClassifier_1', 'RandomForestImputer_3'), ('DecisionTreeClassifier_1', 'RandomForestImputer_4'), ('DecisionTreeClassifier_1', 'GAINImputer_1'), ('DecisionTreeClassifier_1', 'RandomForestImputer_5'), ('DecisionTreeClassifier_1', 'SimpleImputer_1'), ('DecisionTreeClassifier_1', 'GAINImputer_2')] 
 'batch_size' 
 Traceback (most recent call last):
  File "/home/ketrong/miniconda3/envs/tpot2devenv/lib/python3.10/site-packages/tpot2/utils/eval_utils.py", line 53, in objective_nan_wrapper
    value = func_timeout.func_timeout(timeout, objective_function, args=[individual], kwargs=objective_kwargs)
  File "/home/ketrong/miniconda3/envs/tpot2devenv/lib/python3.10/site-packages/func_timeout/dafunc.py", line 108, in func_timeout
    raise_exception(exception)
  File "/home/ketrong/miniconda3/envs/tpot2devenv/lib/python3.10/site-packages/func_timeout/py3_raise.py", line 7, in raise_exception
    raise exception[0] from None
  File "/home/ketrong/miniconda3/envs/tpot2devenv/lib/python3.10/site-packages/tpot2/tpot_estimator/estimator.py", line 702, in objective_function
    return objective_function_generator(
  File "/home/ketrong/miniconda3/envs/tpot2devenv/lib/python3.10/site-packages/tpot2/tpot_estimator/estimator_utils.py", line 117, in objective_function_generator
    cv_obj_scores = cross_val_score_objective(sklearn.base.clone(pipeline),x,y,scorers=scorers, cv=cv , fold=step)
  File "/home/ketrong/miniconda3/envs/tpot2devenv/lib/python3.10/site-packages/tpot2/tpot_estimator/cross_val_utils.py", line 28, in cross_val_score_objective
    this_fold_pipeline.fit(X_train,y_train)
  File "/home/ketrong/miniconda3/envs/tpot2devenv/lib/python3.10/site-packages/tpot2/graphsklearn.py", line 354, in fit
    fit_sklearn_digraph(   graph=self.graph,
  File "/home/ketrong/miniconda3/envs/tpot2devenv/lib/python3.10/site-packages/tpot2/graphsklearn.py", line 155, in fit_sklearn_digraph
    transformed, instance = fit_transform_one_cached(instance, this_X, y, subset_indexes=subset_indexes)#instance.fit_transform(this_X,y)
  File "/home/ketrong/miniconda3/envs/tpot2devenv/lib/python3.10/site-packages/joblib/memory.py", line 353, in __call__
    return self.func(*args, **kwargs)
  File "/home/ketrong/miniconda3/envs/tpot2devenv/lib/python3.10/site-packages/tpot2/graphsklearn.py", line 96, in _fit_transform_one
    res = model.fit_transform(X, y, **fit_params)
  File "/home/ketrong/miniconda3/envs/tpot2devenv/lib/python3.10/site-packages/sklearn/utils/_set_output.py", line 157, in wrapped
    data_to_wrap = f(self, X, *args, **kwargs)
  File "/common/ketrong/AutoImputeExp/tpot2_imputetest/Impute_Experiments/transformers.py", line 610, in fit_transform
    return self.fit(X, **fit_params).transform(X)
  File "/home/ketrong/miniconda3/envs/tpot2devenv/lib/python3.10/site-packages/sklearn/utils/_set_output.py", line 157, in wrapped
    data_to_wrap = f(self, X, *args, **kwargs)
  File "/common/ketrong/AutoImputeExp/tpot2_imputetest/Impute_Experiments/transformers.py", line 606, in transform
    return self.gain(X, self.params)
  File "/common/ketrong/AutoImputeExp/tpot2_imputetest/Impute_Experiments/transformers.py", line 630, in gain
    batch_size = gain_parameters['batch_size']
KeyError: 'batch_size'

WARNING THIS INDIVIDUAL CAUSED AND EXCEPTION 
 [('RandomForestClassifier_1', 'RandomForestImputer_1'), ('RandomForestClassifier_1', 'SimpleImputer_1'), ('RandomForestClassifier_1', 'KNNImputer_1'), ('RandomForestClassifier_1', 'GAINImputer_1'), ('RandomForestClassifier_1', 'IterativeImputer_1'), ('RandomForestClassifier_1', 'GAINImputer_2'), ('RandomForestClassifier_1', 'GAINImputer_3')] 
 'batch_size' 
 Traceback (most recent call last):
  File "/home/ketrong/miniconda3/envs/tpot2devenv/lib/python3.10/site-packages/tpot2/utils/eval_utils.py", line 53, in objective_nan_wrapper
    value = func_timeout.func_timeout(timeout, objective_function, args=[individual], kwargs=objective_kwargs)
  File "/home/ketrong/miniconda3/envs/tpot2devenv/lib/python3.10/site-packages/func_timeout/dafunc.py", line 108, in func_timeout
    raise_exception(exception)
  File "/home/ketrong/miniconda3/envs/tpot2devenv/lib/python3.10/site-packages/func_timeout/py3_raise.py", line 7, in raise_exception
    raise exception[0] from None
  File "/home/ketrong/miniconda3/envs/tpot2devenv/lib/python3.10/site-packages/tpot2/tpot_estimator/estimator.py", line 702, in objective_function
    return objective_function_generator(
  File "/home/ketrong/miniconda3/envs/tpot2devenv/lib/python3.10/site-packages/tpot2/tpot_estimator/estimator_utils.py", line 117, in objective_function_generator
    cv_obj_scores = cross_val_score_objective(sklearn.base.clone(pipeline),x,y,scorers=scorers, cv=cv , fold=step)
  File "/home/ketrong/miniconda3/envs/tpot2devenv/lib/python3.10/site-packages/tpot2/tpot_estimator/cross_val_utils.py", line 28, in cross_val_score_objective
    this_fold_pipeline.fit(X_train,y_train)
  File "/home/ketrong/miniconda3/envs/tpot2devenv/lib/python3.10/site-packages/tpot2/graphsklearn.py", line 354, in fit
    fit_sklearn_digraph(   graph=self.graph,
  File "/home/ketrong/miniconda3/envs/tpot2devenv/lib/python3.10/site-packages/tpot2/graphsklearn.py", line 155, in fit_sklearn_digraph
    transformed, instance = fit_transform_one_cached(instance, this_X, y, subset_indexes=subset_indexes)#instance.fit_transform(this_X,y)
  File "/home/ketrong/miniconda3/envs/tpot2devenv/lib/python3.10/site-packages/joblib/memory.py", line 353, in __call__
    return self.func(*args, **kwargs)
  File "/home/ketrong/miniconda3/envs/tpot2devenv/lib/python3.10/site-packages/tpot2/graphsklearn.py", line 96, in _fit_transform_one
    res = model.fit_transform(X, y, **fit_params)
  File "/home/ketrong/miniconda3/envs/tpot2devenv/lib/python3.10/site-packages/sklearn/utils/_set_output.py", line 157, in wrapped
    data_to_wrap = f(self, X, *args, **kwargs)
  File "/common/ketrong/AutoImputeExp/tpot2_imputetest/Impute_Experiments/transformers.py", line 610, in fit_transform
    return self.fit(X, **fit_params).transform(X)
  File "/home/ketrong/miniconda3/envs/tpot2devenv/lib/python3.10/site-packages/sklearn/utils/_set_output.py", line 157, in wrapped
    data_to_wrap = f(self, X, *args, **kwargs)
  File "/common/ketrong/AutoImputeExp/tpot2_imputetest/Impute_Experiments/transformers.py", line 606, in transform
    return self.gain(X, self.params)
  File "/common/ketrong/AutoImputeExp/tpot2_imputetest/Impute_Experiments/transformers.py", line 630, in gain
    batch_size = gain_parameters['batch_size']
KeyError: 'batch_size'

WARNING THIS INDIVIDUAL CAUSED AND EXCEPTION 
 [('GaussianNB_1', 'SimpleImputer_1'), ('GaussianNB_1', 'KNNImputer_1'), ('GaussianNB_1', 'GAINImputer_1'), ('GaussianNB_1', 'KNNImputer_2'), ('GaussianNB_1', 'KNNImputer_3'), ('GaussianNB_1', 'IterativeImputer_1'), ('GaussianNB_1', 'IterativeImputer_2'), ('GaussianNB_1', 'GAINImputer_2'), ('GaussianNB_1', 'RandomForestImputer_1')] 
 'batch_size' 
 Traceback (most recent call last):
  File "/home/ketrong/miniconda3/envs/tpot2devenv/lib/python3.10/site-packages/tpot2/utils/eval_utils.py", line 53, in objective_nan_wrapper
    value = func_timeout.func_timeout(timeout, objective_function, args=[individual], kwargs=objective_kwargs)
  File "/home/ketrong/miniconda3/envs/tpot2devenv/lib/python3.10/site-packages/func_timeout/dafunc.py", line 108, in func_timeout
    raise_exception(exception)
  File "/home/ketrong/miniconda3/envs/tpot2devenv/lib/python3.10/site-packages/func_timeout/py3_raise.py", line 7, in raise_exception
    raise exception[0] from None
  File "/home/ketrong/miniconda3/envs/tpot2devenv/lib/python3.10/site-packages/tpot2/tpot_estimator/estimator.py", line 702, in objective_function
    return objective_function_generator(
  File "/home/ketrong/miniconda3/envs/tpot2devenv/lib/python3.10/site-packages/tpot2/tpot_estimator/estimator_utils.py", line 117, in objective_function_generator
    cv_obj_scores = cross_val_score_objective(sklearn.base.clone(pipeline),x,y,scorers=scorers, cv=cv , fold=step)
  File "/home/ketrong/miniconda3/envs/tpot2devenv/lib/python3.10/site-packages/tpot2/tpot_estimator/cross_val_utils.py", line 28, in cross_val_score_objective
    this_fold_pipeline.fit(X_train,y_train)
  File "/home/ketrong/miniconda3/envs/tpot2devenv/lib/python3.10/site-packages/tpot2/graphsklearn.py", line 354, in fit
    fit_sklearn_digraph(   graph=self.graph,
  File "/home/ketrong/miniconda3/envs/tpot2devenv/lib/python3.10/site-packages/tpot2/graphsklearn.py", line 155, in fit_sklearn_digraph
    transformed, instance = fit_transform_one_cached(instance, this_X, y, subset_indexes=subset_indexes)#instance.fit_transform(this_X,y)
  File "/home/ketrong/miniconda3/envs/tpot2devenv/lib/python3.10/site-packages/joblib/memory.py", line 353, in __call__
    return self.func(*args, **kwargs)
  File "/home/ketrong/miniconda3/envs/tpot2devenv/lib/python3.10/site-packages/tpot2/graphsklearn.py", line 96, in _fit_transform_one
    res = model.fit_transform(X, y, **fit_params)
  File "/home/ketrong/miniconda3/envs/tpot2devenv/lib/python3.10/site-packages/sklearn/utils/_set_output.py", line 157, in wrapped
    data_to_wrap = f(self, X, *args, **kwargs)
  File "/common/ketrong/AutoImputeExp/tpot2_imputetest/Impute_Experiments/transformers.py", line 610, in fit_transform
    return self.fit(X, **fit_params).transform(X)
  File "/home/ketrong/miniconda3/envs/tpot2devenv/lib/python3.10/site-packages/sklearn/utils/_set_output.py", line 157, in wrapped
    data_to_wrap = f(self, X, *args, **kwargs)
  File "/common/ketrong/AutoImputeExp/tpot2_imputetest/Impute_Experiments/transformers.py", line 606, in transform
    return self.gain(X, self.params)
  File "/common/ketrong/AutoImputeExp/tpot2_imputetest/Impute_Experiments/transformers.py", line 630, in gain
    batch_size = gain_parameters['batch_size']
KeyError: 'batch_size'

WARNING THIS INDIVIDUAL CAUSED AND EXCEPTION 
 [('GradientBoostingClassifier_1', 'GAINImputer_1')] 
 'batch_size' 
 Traceback (most recent call last):
  File "/home/ketrong/miniconda3/envs/tpot2devenv/lib/python3.10/site-packages/tpot2/utils/eval_utils.py", line 53, in objective_nan_wrapper
    value = func_timeout.func_timeout(timeout, objective_function, args=[individual], kwargs=objective_kwargs)
  File "/home/ketrong/miniconda3/envs/tpot2devenv/lib/python3.10/site-packages/func_timeout/dafunc.py", line 108, in func_timeout
    raise_exception(exception)
  File "/home/ketrong/miniconda3/envs/tpot2devenv/lib/python3.10/site-packages/func_timeout/py3_raise.py", line 7, in raise_exception
    raise exception[0] from None
  File "/home/ketrong/miniconda3/envs/tpot2devenv/lib/python3.10/site-packages/tpot2/tpot_estimator/estimator.py", line 702, in objective_function
    return objective_function_generator(
  File "/home/ketrong/miniconda3/envs/tpot2devenv/lib/python3.10/site-packages/tpot2/tpot_estimator/estimator_utils.py", line 117, in objective_function_generator
    cv_obj_scores = cross_val_score_objective(sklearn.base.clone(pipeline),x,y,scorers=scorers, cv=cv , fold=step)
  File "/home/ketrong/miniconda3/envs/tpot2devenv/lib/python3.10/site-packages/tpot2/tpot_estimator/cross_val_utils.py", line 28, in cross_val_score_objective
    this_fold_pipeline.fit(X_train,y_train)
  File "/home/ketrong/miniconda3/envs/tpot2devenv/lib/python3.10/site-packages/tpot2/graphsklearn.py", line 354, in fit
    fit_sklearn_digraph(   graph=self.graph,
  File "/home/ketrong/miniconda3/envs/tpot2devenv/lib/python3.10/site-packages/tpot2/graphsklearn.py", line 155, in fit_sklearn_digraph
    transformed, instance = fit_transform_one_cached(instance, this_X, y, subset_indexes=subset_indexes)#instance.fit_transform(this_X,y)
  File "/home/ketrong/miniconda3/envs/tpot2devenv/lib/python3.10/site-packages/joblib/memory.py", line 353, in __call__
    return self.func(*args, **kwargs)
  File "/home/ketrong/miniconda3/envs/tpot2devenv/lib/python3.10/site-packages/tpot2/graphsklearn.py", line 96, in _fit_transform_one
    res = model.fit_transform(X, y, **fit_params)
  File "/home/ketrong/miniconda3/envs/tpot2devenv/lib/python3.10/site-packages/sklearn/utils/_set_output.py", line 157, in wrapped
    data_to_wrap = f(self, X, *args, **kwargs)
  File "/common/ketrong/AutoImputeExp/tpot2_imputetest/Impute_Experiments/transformers.py", line 610, in fit_transform
    return self.fit(X, **fit_params).transform(X)
  File "/home/ketrong/miniconda3/envs/tpot2devenv/lib/python3.10/site-packages/sklearn/utils/_set_output.py", line 157, in wrapped
    data_to_wrap = f(self, X, *args, **kwargs)
  File "/common/ketrong/AutoImputeExp/tpot2_imputetest/Impute_Experiments/transformers.py", line 606, in transform
    return self.gain(X, self.params)
  File "/common/ketrong/AutoImputeExp/tpot2_imputetest/Impute_Experiments/transformers.py", line 630, in gain
    batch_size = gain_parameters['batch_size']
KeyError: 'batch_size'

WARNING THIS INDIVIDUAL CAUSED AND EXCEPTION 
 [('RandomForestClassifier_1', 'IterativeImputer_1'), ('RandomForestClassifier_1', 'RandomForestImputer_1'), ('RandomForestClassifier_1', 'IterativeImputer_2'), ('RandomForestClassifier_1', 'RandomForestImputer_2'), ('RandomForestClassifier_1', 'GAINImputer_1'), ('RandomForestClassifier_1', 'GAINImputer_2'), ('RandomForestClassifier_1', 'GAINImputer_3'), ('RandomForestClassifier_1', 'SimpleImputer_1')] 
 'batch_size' 
 Traceback (most recent call last):
  File "/home/ketrong/miniconda3/envs/tpot2devenv/lib/python3.10/site-packages/tpot2/utils/eval_utils.py", line 53, in objective_nan_wrapper
    value = func_timeout.func_timeout(timeout, objective_function, args=[individual], kwargs=objective_kwargs)
  File "/home/ketrong/miniconda3/envs/tpot2devenv/lib/python3.10/site-packages/func_timeout/dafunc.py", line 108, in func_timeout
    raise_exception(exception)
  File "/home/ketrong/miniconda3/envs/tpot2devenv/lib/python3.10/site-packages/func_timeout/py3_raise.py", line 7, in raise_exception
    raise exception[0] from None
  File "/home/ketrong/miniconda3/envs/tpot2devenv/lib/python3.10/site-packages/tpot2/tpot_estimator/estimator.py", line 702, in objective_function
    return objective_function_generator(
  File "/home/ketrong/miniconda3/envs/tpot2devenv/lib/python3.10/site-packages/tpot2/tpot_estimator/estimator_utils.py", line 117, in objective_function_generator
    cv_obj_scores = cross_val_score_objective(sklearn.base.clone(pipeline),x,y,scorers=scorers, cv=cv , fold=step)
  File "/home/ketrong/miniconda3/envs/tpot2devenv/lib/python3.10/site-packages/tpot2/tpot_estimator/cross_val_utils.py", line 28, in cross_val_score_objective
    this_fold_pipeline.fit(X_train,y_train)
  File "/home/ketrong/miniconda3/envs/tpot2devenv/lib/python3.10/site-packages/tpot2/graphsklearn.py", line 354, in fit
    fit_sklearn_digraph(   graph=self.graph,
  File "/home/ketrong/miniconda3/envs/tpot2devenv/lib/python3.10/site-packages/tpot2/graphsklearn.py", line 155, in fit_sklearn_digraph
    transformed, instance = fit_transform_one_cached(instance, this_X, y, subset_indexes=subset_indexes)#instance.fit_transform(this_X,y)
  File "/home/ketrong/miniconda3/envs/tpot2devenv/lib/python3.10/site-packages/joblib/memory.py", line 353, in __call__
    return self.func(*args, **kwargs)
  File "/home/ketrong/miniconda3/envs/tpot2devenv/lib/python3.10/site-packages/tpot2/graphsklearn.py", line 96, in _fit_transform_one
    res = model.fit_transform(X, y, **fit_params)
  File "/home/ketrong/miniconda3/envs/tpot2devenv/lib/python3.10/site-packages/sklearn/utils/_set_output.py", line 157, in wrapped
    data_to_wrap = f(self, X, *args, **kwargs)
  File "/common/ketrong/AutoImputeExp/tpot2_imputetest/Impute_Experiments/transformers.py", line 610, in fit_transform
    return self.fit(X, **fit_params).transform(X)
  File "/home/ketrong/miniconda3/envs/tpot2devenv/lib/python3.10/site-packages/sklearn/utils/_set_output.py", line 157, in wrapped
    data_to_wrap = f(self, X, *args, **kwargs)
  File "/common/ketrong/AutoImputeExp/tpot2_imputetest/Impute_Experiments/transformers.py", line 606, in transform
    return self.gain(X, self.params)
  File "/common/ketrong/AutoImputeExp/tpot2_imputetest/Impute_Experiments/transformers.py", line 630, in gain
    batch_size = gain_parameters['batch_size']
KeyError: 'batch_size'

WARNING THIS INDIVIDUAL CAUSED AND EXCEPTION 
 [('SGDClassifier_1', 'GAINImputer_1'), ('SGDClassifier_1', 'GAINImputer_2'), ('SGDClassifier_1', 'GAINImputer_3'), ('SGDClassifier_1', 'GAINImputer_4'), ('SGDClassifier_1', 'RandomForestImputer_1')] 
 'batch_size' 
 Traceback (most recent call last):
  File "/home/ketrong/miniconda3/envs/tpot2devenv/lib/python3.10/site-packages/tpot2/utils/eval_utils.py", line 53, in objective_nan_wrapper
    value = func_timeout.func_timeout(timeout, objective_function, args=[individual], kwargs=objective_kwargs)
  File "/home/ketrong/miniconda3/envs/tpot2devenv/lib/python3.10/site-packages/func_timeout/dafunc.py", line 108, in func_timeout
    raise_exception(exception)
  File "/home/ketrong/miniconda3/envs/tpot2devenv/lib/python3.10/site-packages/func_timeout/py3_raise.py", line 7, in raise_exception
    raise exception[0] from None
  File "/home/ketrong/miniconda3/envs/tpot2devenv/lib/python3.10/site-packages/tpot2/tpot_estimator/estimator.py", line 702, in objective_function
    return objective_function_generator(
  File "/home/ketrong/miniconda3/envs/tpot2devenv/lib/python3.10/site-packages/tpot2/tpot_estimator/estimator_utils.py", line 117, in objective_function_generator
    cv_obj_scores = cross_val_score_objective(sklearn.base.clone(pipeline),x,y,scorers=scorers, cv=cv , fold=step)
  File "/home/ketrong/miniconda3/envs/tpot2devenv/lib/python3.10/site-packages/tpot2/tpot_estimator/cross_val_utils.py", line 28, in cross_val_score_objective
    this_fold_pipeline.fit(X_train,y_train)
  File "/home/ketrong/miniconda3/envs/tpot2devenv/lib/python3.10/site-packages/tpot2/graphsklearn.py", line 354, in fit
    fit_sklearn_digraph(   graph=self.graph,
  File "/home/ketrong/miniconda3/envs/tpot2devenv/lib/python3.10/site-packages/tpot2/graphsklearn.py", line 155, in fit_sklearn_digraph
    transformed, instance = fit_transform_one_cached(instance, this_X, y, subset_indexes=subset_indexes)#instance.fit_transform(this_X,y)
  File "/home/ketrong/miniconda3/envs/tpot2devenv/lib/python3.10/site-packages/joblib/memory.py", line 353, in __call__
    return self.func(*args, **kwargs)
  File "/home/ketrong/miniconda3/envs/tpot2devenv/lib/python3.10/site-packages/tpot2/graphsklearn.py", line 96, in _fit_transform_one
    res = model.fit_transform(X, y, **fit_params)
  File "/home/ketrong/miniconda3/envs/tpot2devenv/lib/python3.10/site-packages/sklearn/utils/_set_output.py", line 157, in wrapped
    data_to_wrap = f(self, X, *args, **kwargs)
  File "/common/ketrong/AutoImputeExp/tpot2_imputetest/Impute_Experiments/transformers.py", line 610, in fit_transform
    return self.fit(X, **fit_params).transform(X)
  File "/home/ketrong/miniconda3/envs/tpot2devenv/lib/python3.10/site-packages/sklearn/utils/_set_output.py", line 157, in wrapped
    data_to_wrap = f(self, X, *args, **kwargs)
  File "/common/ketrong/AutoImputeExp/tpot2_imputetest/Impute_Experiments/transformers.py", line 606, in transform
    return self.gain(X, self.params)
  File "/common/ketrong/AutoImputeExp/tpot2_imputetest/Impute_Experiments/transformers.py", line 630, in gain
    batch_size = gain_parameters['batch_size']
KeyError: 'batch_size'

WARNING THIS INDIVIDUAL CAUSED AND EXCEPTION 
 [('GradientBoostingClassifier_1', 'IterativeImputer_1'), ('GradientBoostingClassifier_1', 'IterativeImputer_2'), ('GradientBoostingClassifier_1', 'IterativeImputer_3'), ('GradientBoostingClassifier_1', 'GAINImputer_1')] 
 'batch_size' 
 Traceback (most recent call last):
  File "/home/ketrong/miniconda3/envs/tpot2devenv/lib/python3.10/site-packages/tpot2/utils/eval_utils.py", line 53, in objective_nan_wrapper
    value = func_timeout.func_timeout(timeout, objective_function, args=[individual], kwargs=objective_kwargs)
  File "/home/ketrong/miniconda3/envs/tpot2devenv/lib/python3.10/site-packages/func_timeout/dafunc.py", line 108, in func_timeout
    raise_exception(exception)
  File "/home/ketrong/miniconda3/envs/tpot2devenv/lib/python3.10/site-packages/func_timeout/py3_raise.py", line 7, in raise_exception
    raise exception[0] from None
  File "/home/ketrong/miniconda3/envs/tpot2devenv/lib/python3.10/site-packages/tpot2/tpot_estimator/estimator.py", line 702, in objective_function
    return objective_function_generator(
  File "/home/ketrong/miniconda3/envs/tpot2devenv/lib/python3.10/site-packages/tpot2/tpot_estimator/estimator_utils.py", line 117, in objective_function_generator
    cv_obj_scores = cross_val_score_objective(sklearn.base.clone(pipeline),x,y,scorers=scorers, cv=cv , fold=step)
  File "/home/ketrong/miniconda3/envs/tpot2devenv/lib/python3.10/site-packages/tpot2/tpot_estimator/cross_val_utils.py", line 28, in cross_val_score_objective
    this_fold_pipeline.fit(X_train,y_train)
  File "/home/ketrong/miniconda3/envs/tpot2devenv/lib/python3.10/site-packages/tpot2/graphsklearn.py", line 354, in fit
    fit_sklearn_digraph(   graph=self.graph,
  File "/home/ketrong/miniconda3/envs/tpot2devenv/lib/python3.10/site-packages/tpot2/graphsklearn.py", line 155, in fit_sklearn_digraph
    transformed, instance = fit_transform_one_cached(instance, this_X, y, subset_indexes=subset_indexes)#instance.fit_transform(this_X,y)
  File "/home/ketrong/miniconda3/envs/tpot2devenv/lib/python3.10/site-packages/joblib/memory.py", line 353, in __call__
    return self.func(*args, **kwargs)
  File "/home/ketrong/miniconda3/envs/tpot2devenv/lib/python3.10/site-packages/tpot2/graphsklearn.py", line 96, in _fit_transform_one
    res = model.fit_transform(X, y, **fit_params)
  File "/home/ketrong/miniconda3/envs/tpot2devenv/lib/python3.10/site-packages/sklearn/utils/_set_output.py", line 157, in wrapped
    data_to_wrap = f(self, X, *args, **kwargs)
  File "/common/ketrong/AutoImputeExp/tpot2_imputetest/Impute_Experiments/transformers.py", line 610, in fit_transform
    return self.fit(X, **fit_params).transform(X)
  File "/home/ketrong/miniconda3/envs/tpot2devenv/lib/python3.10/site-packages/sklearn/utils/_set_output.py", line 157, in wrapped
    data_to_wrap = f(self, X, *args, **kwargs)
  File "/common/ketrong/AutoImputeExp/tpot2_imputetest/Impute_Experiments/transformers.py", line 606, in transform
    return self.gain(X, self.params)
  File "/common/ketrong/AutoImputeExp/tpot2_imputetest/Impute_Experiments/transformers.py", line 630, in gain
    batch_size = gain_parameters['batch_size']
KeyError: 'batch_size'

WARNING THIS INDIVIDUAL CAUSED AND EXCEPTION 
 [('MLPClassifier_1', 'RandomForestImputer_1'), ('MLPClassifier_1', 'IterativeImputer_1'), ('MLPClassifier_1', 'RandomForestImputer_2'), ('MLPClassifier_1', 'IterativeImputer_2'), ('MLPClassifier_1', 'SimpleImputer_1'), ('MLPClassifier_1', 'KNNImputer_1'), ('MLPClassifier_1', 'IterativeImputer_3'), ('MLPClassifier_1', 'GAINImputer_1'), ('MLPClassifier_1', 'RandomForestImputer_3')] 
 'batch_size' 
 Traceback (most recent call last):
  File "/home/ketrong/miniconda3/envs/tpot2devenv/lib/python3.10/site-packages/tpot2/utils/eval_utils.py", line 53, in objective_nan_wrapper
    value = func_timeout.func_timeout(timeout, objective_function, args=[individual], kwargs=objective_kwargs)
  File "/home/ketrong/miniconda3/envs/tpot2devenv/lib/python3.10/site-packages/func_timeout/dafunc.py", line 108, in func_timeout
    raise_exception(exception)
  File "/home/ketrong/miniconda3/envs/tpot2devenv/lib/python3.10/site-packages/func_timeout/py3_raise.py", line 7, in raise_exception
    raise exception[0] from None
  File "/home/ketrong/miniconda3/envs/tpot2devenv/lib/python3.10/site-packages/tpot2/tpot_estimator/estimator.py", line 702, in objective_function
    return objective_function_generator(
  File "/home/ketrong/miniconda3/envs/tpot2devenv/lib/python3.10/site-packages/tpot2/tpot_estimator/estimator_utils.py", line 117, in objective_function_generator
    cv_obj_scores = cross_val_score_objective(sklearn.base.clone(pipeline),x,y,scorers=scorers, cv=cv , fold=step)
  File "/home/ketrong/miniconda3/envs/tpot2devenv/lib/python3.10/site-packages/tpot2/tpot_estimator/cross_val_utils.py", line 28, in cross_val_score_objective
    this_fold_pipeline.fit(X_train,y_train)
  File "/home/ketrong/miniconda3/envs/tpot2devenv/lib/python3.10/site-packages/tpot2/graphsklearn.py", line 354, in fit
    fit_sklearn_digraph(   graph=self.graph,
  File "/home/ketrong/miniconda3/envs/tpot2devenv/lib/python3.10/site-packages/tpot2/graphsklearn.py", line 155, in fit_sklearn_digraph
    transformed, instance = fit_transform_one_cached(instance, this_X, y, subset_indexes=subset_indexes)#instance.fit_transform(this_X,y)
  File "/home/ketrong/miniconda3/envs/tpot2devenv/lib/python3.10/site-packages/joblib/memory.py", line 353, in __call__
    return self.func(*args, **kwargs)
  File "/home/ketrong/miniconda3/envs/tpot2devenv/lib/python3.10/site-packages/tpot2/graphsklearn.py", line 96, in _fit_transform_one
    res = model.fit_transform(X, y, **fit_params)
  File "/home/ketrong/miniconda3/envs/tpot2devenv/lib/python3.10/site-packages/sklearn/utils/_set_output.py", line 157, in wrapped
    data_to_wrap = f(self, X, *args, **kwargs)
  File "/common/ketrong/AutoImputeExp/tpot2_imputetest/Impute_Experiments/transformers.py", line 610, in fit_transform
    return self.fit(X, **fit_params).transform(X)
  File "/home/ketrong/miniconda3/envs/tpot2devenv/lib/python3.10/site-packages/sklearn/utils/_set_output.py", line 157, in wrapped
    data_to_wrap = f(self, X, *args, **kwargs)
  File "/common/ketrong/AutoImputeExp/tpot2_imputetest/Impute_Experiments/transformers.py", line 606, in transform
    return self.gain(X, self.params)
  File "/common/ketrong/AutoImputeExp/tpot2_imputetest/Impute_Experiments/transformers.py", line 630, in gain
    batch_size = gain_parameters['batch_size']
KeyError: 'batch_size'

WARNING THIS INDIVIDUAL CAUSED AND EXCEPTION 
 [('RandomForestClassifier_1', 'SimpleImputer_1'), ('RandomForestClassifier_1', 'IterativeImputer_1'), ('RandomForestClassifier_1', 'RandomForestImputer_1'), ('RandomForestClassifier_1', 'GAINImputer_1')] 
 'batch_size' 
 Traceback (most recent call last):
  File "/home/ketrong/miniconda3/envs/tpot2devenv/lib/python3.10/site-packages/tpot2/utils/eval_utils.py", line 53, in objective_nan_wrapper
    value = func_timeout.func_timeout(timeout, objective_function, args=[individual], kwargs=objective_kwargs)
  File "/home/ketrong/miniconda3/envs/tpot2devenv/lib/python3.10/site-packages/func_timeout/dafunc.py", line 108, in func_timeout
    raise_exception(exception)
  File "/home/ketrong/miniconda3/envs/tpot2devenv/lib/python3.10/site-packages/func_timeout/py3_raise.py", line 7, in raise_exception
    raise exception[0] from None
  File "/home/ketrong/miniconda3/envs/tpot2devenv/lib/python3.10/site-packages/tpot2/tpot_estimator/estimator.py", line 702, in objective_function
    return objective_function_generator(
  File "/home/ketrong/miniconda3/envs/tpot2devenv/lib/python3.10/site-packages/tpot2/tpot_estimator/estimator_utils.py", line 117, in objective_function_generator
    cv_obj_scores = cross_val_score_objective(sklearn.base.clone(pipeline),x,y,scorers=scorers, cv=cv , fold=step)
  File "/home/ketrong/miniconda3/envs/tpot2devenv/lib/python3.10/site-packages/tpot2/tpot_estimator/cross_val_utils.py", line 28, in cross_val_score_objective
    this_fold_pipeline.fit(X_train,y_train)
  File "/home/ketrong/miniconda3/envs/tpot2devenv/lib/python3.10/site-packages/tpot2/graphsklearn.py", line 354, in fit
    fit_sklearn_digraph(   graph=self.graph,
  File "/home/ketrong/miniconda3/envs/tpot2devenv/lib/python3.10/site-packages/tpot2/graphsklearn.py", line 155, in fit_sklearn_digraph
    transformed, instance = fit_transform_one_cached(instance, this_X, y, subset_indexes=subset_indexes)#instance.fit_transform(this_X,y)
  File "/home/ketrong/miniconda3/envs/tpot2devenv/lib/python3.10/site-packages/joblib/memory.py", line 353, in __call__
    return self.func(*args, **kwargs)
  File "/home/ketrong/miniconda3/envs/tpot2devenv/lib/python3.10/site-packages/tpot2/graphsklearn.py", line 96, in _fit_transform_one
    res = model.fit_transform(X, y, **fit_params)
  File "/home/ketrong/miniconda3/envs/tpot2devenv/lib/python3.10/site-packages/sklearn/utils/_set_output.py", line 157, in wrapped
    data_to_wrap = f(self, X, *args, **kwargs)
  File "/common/ketrong/AutoImputeExp/tpot2_imputetest/Impute_Experiments/transformers.py", line 610, in fit_transform
    return self.fit(X, **fit_params).transform(X)
  File "/home/ketrong/miniconda3/envs/tpot2devenv/lib/python3.10/site-packages/sklearn/utils/_set_output.py", line 157, in wrapped
    data_to_wrap = f(self, X, *args, **kwargs)
  File "/common/ketrong/AutoImputeExp/tpot2_imputetest/Impute_Experiments/transformers.py", line 606, in transform
    return self.gain(X, self.params)
  File "/common/ketrong/AutoImputeExp/tpot2_imputetest/Impute_Experiments/transformers.py", line 630, in gain
    batch_size = gain_parameters['batch_size']
KeyError: 'batch_size'

WARNING THIS INDIVIDUAL CAUSED AND EXCEPTION 
 [('MultinomialNB_1', 'GAINImputer_1'), ('MultinomialNB_1', 'GAINImputer_2'), ('MultinomialNB_1', 'KNNImputer_1'), ('MultinomialNB_1', 'GAINImputer_3'), ('MultinomialNB_1', 'KNNImputer_2'), ('MultinomialNB_1', 'SimpleImputer_1'), ('MultinomialNB_1', 'GAINImputer_4'), ('MultinomialNB_1', 'GAINImputer_5')] 
 'batch_size' 
 Traceback (most recent call last):
  File "/home/ketrong/miniconda3/envs/tpot2devenv/lib/python3.10/site-packages/tpot2/utils/eval_utils.py", line 53, in objective_nan_wrapper
    value = func_timeout.func_timeout(timeout, objective_function, args=[individual], kwargs=objective_kwargs)
  File "/home/ketrong/miniconda3/envs/tpot2devenv/lib/python3.10/site-packages/func_timeout/dafunc.py", line 108, in func_timeout
    raise_exception(exception)
  File "/home/ketrong/miniconda3/envs/tpot2devenv/lib/python3.10/site-packages/func_timeout/py3_raise.py", line 7, in raise_exception
    raise exception[0] from None
  File "/home/ketrong/miniconda3/envs/tpot2devenv/lib/python3.10/site-packages/tpot2/tpot_estimator/estimator.py", line 702, in objective_function
    return objective_function_generator(
  File "/home/ketrong/miniconda3/envs/tpot2devenv/lib/python3.10/site-packages/tpot2/tpot_estimator/estimator_utils.py", line 117, in objective_function_generator
    cv_obj_scores = cross_val_score_objective(sklearn.base.clone(pipeline),x,y,scorers=scorers, cv=cv , fold=step)
  File "/home/ketrong/miniconda3/envs/tpot2devenv/lib/python3.10/site-packages/tpot2/tpot_estimator/cross_val_utils.py", line 28, in cross_val_score_objective
    this_fold_pipeline.fit(X_train,y_train)
  File "/home/ketrong/miniconda3/envs/tpot2devenv/lib/python3.10/site-packages/tpot2/graphsklearn.py", line 354, in fit
    fit_sklearn_digraph(   graph=self.graph,
  File "/home/ketrong/miniconda3/envs/tpot2devenv/lib/python3.10/site-packages/tpot2/graphsklearn.py", line 155, in fit_sklearn_digraph
    transformed, instance = fit_transform_one_cached(instance, this_X, y, subset_indexes=subset_indexes)#instance.fit_transform(this_X,y)
  File "/home/ketrong/miniconda3/envs/tpot2devenv/lib/python3.10/site-packages/joblib/memory.py", line 353, in __call__
    return self.func(*args, **kwargs)
  File "/home/ketrong/miniconda3/envs/tpot2devenv/lib/python3.10/site-packages/tpot2/graphsklearn.py", line 96, in _fit_transform_one
    res = model.fit_transform(X, y, **fit_params)
  File "/home/ketrong/miniconda3/envs/tpot2devenv/lib/python3.10/site-packages/sklearn/utils/_set_output.py", line 157, in wrapped
    data_to_wrap = f(self, X, *args, **kwargs)
  File "/common/ketrong/AutoImputeExp/tpot2_imputetest/Impute_Experiments/transformers.py", line 610, in fit_transform
    return self.fit(X, **fit_params).transform(X)
  File "/home/ketrong/miniconda3/envs/tpot2devenv/lib/python3.10/site-packages/sklearn/utils/_set_output.py", line 157, in wrapped
    data_to_wrap = f(self, X, *args, **kwargs)
  File "/common/ketrong/AutoImputeExp/tpot2_imputetest/Impute_Experiments/transformers.py", line 606, in transform
    return self.gain(X, self.params)
  File "/common/ketrong/AutoImputeExp/tpot2_imputetest/Impute_Experiments/transformers.py", line 630, in gain
    batch_size = gain_parameters['batch_size']
KeyError: 'batch_size'

WARNING THIS INDIVIDUAL CAUSED AND EXCEPTION 
 [('SVC_1', 'KNNImputer_1'), ('SVC_1', 'IterativeImputer_1'), ('SVC_1', 'GAINImputer_1'), ('SVC_1', 'IterativeImputer_2'), ('SVC_1', 'KNNImputer_2'), ('SVC_1', 'SimpleImputer_1'), ('SVC_1', 'GAINImputer_2'), ('SVC_1', 'SimpleImputer_2')] 
 'batch_size' 
 Traceback (most recent call last):
  File "/home/ketrong/miniconda3/envs/tpot2devenv/lib/python3.10/site-packages/tpot2/utils/eval_utils.py", line 53, in objective_nan_wrapper
    value = func_timeout.func_timeout(timeout, objective_function, args=[individual], kwargs=objective_kwargs)
  File "/home/ketrong/miniconda3/envs/tpot2devenv/lib/python3.10/site-packages/func_timeout/dafunc.py", line 108, in func_timeout
    raise_exception(exception)
  File "/home/ketrong/miniconda3/envs/tpot2devenv/lib/python3.10/site-packages/func_timeout/py3_raise.py", line 7, in raise_exception
    raise exception[0] from None
  File "/home/ketrong/miniconda3/envs/tpot2devenv/lib/python3.10/site-packages/tpot2/tpot_estimator/estimator.py", line 702, in objective_function
    return objective_function_generator(
  File "/home/ketrong/miniconda3/envs/tpot2devenv/lib/python3.10/site-packages/tpot2/tpot_estimator/estimator_utils.py", line 117, in objective_function_generator
    cv_obj_scores = cross_val_score_objective(sklearn.base.clone(pipeline),x,y,scorers=scorers, cv=cv , fold=step)
  File "/home/ketrong/miniconda3/envs/tpot2devenv/lib/python3.10/site-packages/tpot2/tpot_estimator/cross_val_utils.py", line 28, in cross_val_score_objective
    this_fold_pipeline.fit(X_train,y_train)
  File "/home/ketrong/miniconda3/envs/tpot2devenv/lib/python3.10/site-packages/tpot2/graphsklearn.py", line 354, in fit
    fit_sklearn_digraph(   graph=self.graph,
  File "/home/ketrong/miniconda3/envs/tpot2devenv/lib/python3.10/site-packages/tpot2/graphsklearn.py", line 155, in fit_sklearn_digraph
    transformed, instance = fit_transform_one_cached(instance, this_X, y, subset_indexes=subset_indexes)#instance.fit_transform(this_X,y)
  File "/home/ketrong/miniconda3/envs/tpot2devenv/lib/python3.10/site-packages/joblib/memory.py", line 353, in __call__
    return self.func(*args, **kwargs)
  File "/home/ketrong/miniconda3/envs/tpot2devenv/lib/python3.10/site-packages/tpot2/graphsklearn.py", line 96, in _fit_transform_one
    res = model.fit_transform(X, y, **fit_params)
  File "/home/ketrong/miniconda3/envs/tpot2devenv/lib/python3.10/site-packages/sklearn/utils/_set_output.py", line 157, in wrapped
    data_to_wrap = f(self, X, *args, **kwargs)
  File "/common/ketrong/AutoImputeExp/tpot2_imputetest/Impute_Experiments/transformers.py", line 610, in fit_transform
    return self.fit(X, **fit_params).transform(X)
  File "/home/ketrong/miniconda3/envs/tpot2devenv/lib/python3.10/site-packages/sklearn/utils/_set_output.py", line 157, in wrapped
    data_to_wrap = f(self, X, *args, **kwargs)
  File "/common/ketrong/AutoImputeExp/tpot2_imputetest/Impute_Experiments/transformers.py", line 606, in transform
    return self.gain(X, self.params)
  File "/common/ketrong/AutoImputeExp/tpot2_imputetest/Impute_Experiments/transformers.py", line 630, in gain
    batch_size = gain_parameters['batch_size']
KeyError: 'batch_size'

WARNING THIS INDIVIDUAL CAUSED AND EXCEPTION 
 [('BernoulliNB_1', 'SimpleImputer_1'), ('BernoulliNB_1', 'GAINImputer_1'), ('BernoulliNB_1', 'RandomForestImputer_1'), ('BernoulliNB_1', 'GAINImputer_2'), ('BernoulliNB_1', 'RandomForestImputer_2'), ('BernoulliNB_1', 'IterativeImputer_1')] 
 LinearModel.predict() got an unexpected keyword argument 'return_std' 
 Traceback (most recent call last):
  File "/home/ketrong/miniconda3/envs/tpot2devenv/lib/python3.10/site-packages/tpot2/utils/eval_utils.py", line 53, in objective_nan_wrapper
    value = func_timeout.func_timeout(timeout, objective_function, args=[individual], kwargs=objective_kwargs)
  File "/home/ketrong/miniconda3/envs/tpot2devenv/lib/python3.10/site-packages/func_timeout/dafunc.py", line 108, in func_timeout
    raise_exception(exception)
  File "/home/ketrong/miniconda3/envs/tpot2devenv/lib/python3.10/site-packages/func_timeout/py3_raise.py", line 7, in raise_exception
    raise exception[0] from None
  File "/home/ketrong/miniconda3/envs/tpot2devenv/lib/python3.10/site-packages/tpot2/tpot_estimator/estimator.py", line 702, in objective_function
    return objective_function_generator(
  File "/home/ketrong/miniconda3/envs/tpot2devenv/lib/python3.10/site-packages/tpot2/tpot_estimator/estimator_utils.py", line 117, in objective_function_generator
    cv_obj_scores = cross_val_score_objective(sklearn.base.clone(pipeline),x,y,scorers=scorers, cv=cv , fold=step)
  File "/home/ketrong/miniconda3/envs/tpot2devenv/lib/python3.10/site-packages/tpot2/tpot_estimator/cross_val_utils.py", line 28, in cross_val_score_objective
    this_fold_pipeline.fit(X_train,y_train)
  File "/home/ketrong/miniconda3/envs/tpot2devenv/lib/python3.10/site-packages/tpot2/graphsklearn.py", line 354, in fit
    fit_sklearn_digraph(   graph=self.graph,
  File "/home/ketrong/miniconda3/envs/tpot2devenv/lib/python3.10/site-packages/tpot2/graphsklearn.py", line 155, in fit_sklearn_digraph
    transformed, instance = fit_transform_one_cached(instance, this_X, y, subset_indexes=subset_indexes)#instance.fit_transform(this_X,y)
  File "/home/ketrong/miniconda3/envs/tpot2devenv/lib/python3.10/site-packages/joblib/memory.py", line 353, in __call__
    return self.func(*args, **kwargs)
  File "/home/ketrong/miniconda3/envs/tpot2devenv/lib/python3.10/site-packages/tpot2/graphsklearn.py", line 96, in _fit_transform_one
    res = model.fit_transform(X, y, **fit_params)
  File "/home/ketrong/miniconda3/envs/tpot2devenv/lib/python3.10/site-packages/sklearn/utils/_set_output.py", line 157, in wrapped
    data_to_wrap = f(self, X, *args, **kwargs)
  File "/home/ketrong/miniconda3/envs/tpot2devenv/lib/python3.10/site-packages/sklearn/base.py", line 1152, in wrapper
    return fit_method(estimator, *args, **kwargs)
  File "/home/ketrong/miniconda3/envs/tpot2devenv/lib/python3.10/site-packages/sklearn/impute/_iterative.py", line 765, in fit_transform
    Xt, estimator = self._impute_one_feature(
  File "/home/ketrong/miniconda3/envs/tpot2devenv/lib/python3.10/site-packages/sklearn/impute/_iterative.py", line 425, in _impute_one_feature
    mus, sigmas = estimator.predict(X_test, return_std=True)
TypeError: LinearModel.predict() got an unexpected keyword argument 'return_std'

WARNING THIS INDIVIDUAL CAUSED AND EXCEPTION 
 [('SVC_1', 'RandomForestImputer_1'), ('SVC_1', 'KNNImputer_1'), ('SVC_1', 'KNNImputer_2'), ('SVC_1', 'IterativeImputer_1'), ('SVC_1', 'IterativeImputer_2'), ('SVC_1', 'GAINImputer_1'), ('SVC_1', 'IterativeImputer_3'), ('SVC_1', 'IterativeImputer_4'), ('SVC_1', 'RandomForestImputer_2')] 
 'batch_size' 
 Traceback (most recent call last):
  File "/home/ketrong/miniconda3/envs/tpot2devenv/lib/python3.10/site-packages/tpot2/utils/eval_utils.py", line 53, in objective_nan_wrapper
    value = func_timeout.func_timeout(timeout, objective_function, args=[individual], kwargs=objective_kwargs)
  File "/home/ketrong/miniconda3/envs/tpot2devenv/lib/python3.10/site-packages/func_timeout/dafunc.py", line 108, in func_timeout
    raise_exception(exception)
  File "/home/ketrong/miniconda3/envs/tpot2devenv/lib/python3.10/site-packages/func_timeout/py3_raise.py", line 7, in raise_exception
    raise exception[0] from None
  File "/home/ketrong/miniconda3/envs/tpot2devenv/lib/python3.10/site-packages/tpot2/tpot_estimator/estimator.py", line 702, in objective_function
    return objective_function_generator(
  File "/home/ketrong/miniconda3/envs/tpot2devenv/lib/python3.10/site-packages/tpot2/tpot_estimator/estimator_utils.py", line 117, in objective_function_generator
    cv_obj_scores = cross_val_score_objective(sklearn.base.clone(pipeline),x,y,scorers=scorers, cv=cv , fold=step)
  File "/home/ketrong/miniconda3/envs/tpot2devenv/lib/python3.10/site-packages/tpot2/tpot_estimator/cross_val_utils.py", line 28, in cross_val_score_objective
    this_fold_pipeline.fit(X_train,y_train)
  File "/home/ketrong/miniconda3/envs/tpot2devenv/lib/python3.10/site-packages/tpot2/graphsklearn.py", line 354, in fit
    fit_sklearn_digraph(   graph=self.graph,
  File "/home/ketrong/miniconda3/envs/tpot2devenv/lib/python3.10/site-packages/tpot2/graphsklearn.py", line 155, in fit_sklearn_digraph
    transformed, instance = fit_transform_one_cached(instance, this_X, y, subset_indexes=subset_indexes)#instance.fit_transform(this_X,y)
  File "/home/ketrong/miniconda3/envs/tpot2devenv/lib/python3.10/site-packages/joblib/memory.py", line 353, in __call__
    return self.func(*args, **kwargs)
  File "/home/ketrong/miniconda3/envs/tpot2devenv/lib/python3.10/site-packages/tpot2/graphsklearn.py", line 96, in _fit_transform_one
    res = model.fit_transform(X, y, **fit_params)
  File "/home/ketrong/miniconda3/envs/tpot2devenv/lib/python3.10/site-packages/sklearn/utils/_set_output.py", line 157, in wrapped
    data_to_wrap = f(self, X, *args, **kwargs)
  File "/common/ketrong/AutoImputeExp/tpot2_imputetest/Impute_Experiments/transformers.py", line 610, in fit_transform
    return self.fit(X, **fit_params).transform(X)
  File "/home/ketrong/miniconda3/envs/tpot2devenv/lib/python3.10/site-packages/sklearn/utils/_set_output.py", line 157, in wrapped
    data_to_wrap = f(self, X, *args, **kwargs)
  File "/common/ketrong/AutoImputeExp/tpot2_imputetest/Impute_Experiments/transformers.py", line 606, in transform
    return self.gain(X, self.params)
  File "/common/ketrong/AutoImputeExp/tpot2_imputetest/Impute_Experiments/transformers.py", line 630, in gain
    batch_size = gain_parameters['batch_size']
KeyError: 'batch_size'

WARNING THIS INDIVIDUAL CAUSED AND EXCEPTION 
 [('SVC_1', 'IterativeImputer_1')] 
 ForestRegressor.predict() got an unexpected keyword argument 'return_std' 
 Traceback (most recent call last):
  File "/home/ketrong/miniconda3/envs/tpot2devenv/lib/python3.10/site-packages/tpot2/utils/eval_utils.py", line 53, in objective_nan_wrapper
    value = func_timeout.func_timeout(timeout, objective_function, args=[individual], kwargs=objective_kwargs)
  File "/home/ketrong/miniconda3/envs/tpot2devenv/lib/python3.10/site-packages/func_timeout/dafunc.py", line 108, in func_timeout
    raise_exception(exception)
  File "/home/ketrong/miniconda3/envs/tpot2devenv/lib/python3.10/site-packages/func_timeout/py3_raise.py", line 7, in raise_exception
    raise exception[0] from None
  File "/home/ketrong/miniconda3/envs/tpot2devenv/lib/python3.10/site-packages/tpot2/tpot_estimator/estimator.py", line 702, in objective_function
    return objective_function_generator(
  File "/home/ketrong/miniconda3/envs/tpot2devenv/lib/python3.10/site-packages/tpot2/tpot_estimator/estimator_utils.py", line 117, in objective_function_generator
    cv_obj_scores = cross_val_score_objective(sklearn.base.clone(pipeline),x,y,scorers=scorers, cv=cv , fold=step)
  File "/home/ketrong/miniconda3/envs/tpot2devenv/lib/python3.10/site-packages/tpot2/tpot_estimator/cross_val_utils.py", line 28, in cross_val_score_objective
    this_fold_pipeline.fit(X_train,y_train)
  File "/home/ketrong/miniconda3/envs/tpot2devenv/lib/python3.10/site-packages/tpot2/graphsklearn.py", line 354, in fit
    fit_sklearn_digraph(   graph=self.graph,
  File "/home/ketrong/miniconda3/envs/tpot2devenv/lib/python3.10/site-packages/tpot2/graphsklearn.py", line 155, in fit_sklearn_digraph
    transformed, instance = fit_transform_one_cached(instance, this_X, y, subset_indexes=subset_indexes)#instance.fit_transform(this_X,y)
  File "/home/ketrong/miniconda3/envs/tpot2devenv/lib/python3.10/site-packages/joblib/memory.py", line 353, in __call__
    return self.func(*args, **kwargs)
  File "/home/ketrong/miniconda3/envs/tpot2devenv/lib/python3.10/site-packages/tpot2/graphsklearn.py", line 96, in _fit_transform_one
    res = model.fit_transform(X, y, **fit_params)
  File "/home/ketrong/miniconda3/envs/tpot2devenv/lib/python3.10/site-packages/sklearn/utils/_set_output.py", line 157, in wrapped
    data_to_wrap = f(self, X, *args, **kwargs)
  File "/home/ketrong/miniconda3/envs/tpot2devenv/lib/python3.10/site-packages/sklearn/base.py", line 1152, in wrapper
    return fit_method(estimator, *args, **kwargs)
  File "/home/ketrong/miniconda3/envs/tpot2devenv/lib/python3.10/site-packages/sklearn/impute/_iterative.py", line 765, in fit_transform
    Xt, estimator = self._impute_one_feature(
  File "/home/ketrong/miniconda3/envs/tpot2devenv/lib/python3.10/site-packages/sklearn/impute/_iterative.py", line 425, in _impute_one_feature
    mus, sigmas = estimator.predict(X_test, return_std=True)
TypeError: ForestRegressor.predict() got an unexpected keyword argument 'return_std'

WARNING THIS INDIVIDUAL CAUSED AND EXCEPTION 
 [('MLPClassifier_1', 'RandomForestImputer_1'), ('MLPClassifier_1', 'GAINImputer_1'), ('MLPClassifier_1', 'RandomForestImputer_2'), ('MLPClassifier_1', 'GAINImputer_2'), ('MLPClassifier_1', 'SimpleImputer_1'), ('MLPClassifier_1', 'SimpleImputer_2'), ('MLPClassifier_1', 'KNNImputer_1')] 
 'batch_size' 
 Traceback (most recent call last):
  File "/home/ketrong/miniconda3/envs/tpot2devenv/lib/python3.10/site-packages/tpot2/utils/eval_utils.py", line 53, in objective_nan_wrapper
    value = func_timeout.func_timeout(timeout, objective_function, args=[individual], kwargs=objective_kwargs)
  File "/home/ketrong/miniconda3/envs/tpot2devenv/lib/python3.10/site-packages/func_timeout/dafunc.py", line 108, in func_timeout
    raise_exception(exception)
  File "/home/ketrong/miniconda3/envs/tpot2devenv/lib/python3.10/site-packages/func_timeout/py3_raise.py", line 7, in raise_exception
    raise exception[0] from None
  File "/home/ketrong/miniconda3/envs/tpot2devenv/lib/python3.10/site-packages/tpot2/tpot_estimator/estimator.py", line 702, in objective_function
    return objective_function_generator(
  File "/home/ketrong/miniconda3/envs/tpot2devenv/lib/python3.10/site-packages/tpot2/tpot_estimator/estimator_utils.py", line 117, in objective_function_generator
    cv_obj_scores = cross_val_score_objective(sklearn.base.clone(pipeline),x,y,scorers=scorers, cv=cv , fold=step)
  File "/home/ketrong/miniconda3/envs/tpot2devenv/lib/python3.10/site-packages/tpot2/tpot_estimator/cross_val_utils.py", line 28, in cross_val_score_objective
    this_fold_pipeline.fit(X_train,y_train)
  File "/home/ketrong/miniconda3/envs/tpot2devenv/lib/python3.10/site-packages/tpot2/graphsklearn.py", line 354, in fit
    fit_sklearn_digraph(   graph=self.graph,
  File "/home/ketrong/miniconda3/envs/tpot2devenv/lib/python3.10/site-packages/tpot2/graphsklearn.py", line 155, in fit_sklearn_digraph
    transformed, instance = fit_transform_one_cached(instance, this_X, y, subset_indexes=subset_indexes)#instance.fit_transform(this_X,y)
  File "/home/ketrong/miniconda3/envs/tpot2devenv/lib/python3.10/site-packages/joblib/memory.py", line 353, in __call__
    return self.func(*args, **kwargs)
  File "/home/ketrong/miniconda3/envs/tpot2devenv/lib/python3.10/site-packages/tpot2/graphsklearn.py", line 96, in _fit_transform_one
    res = model.fit_transform(X, y, **fit_params)
  File "/home/ketrong/miniconda3/envs/tpot2devenv/lib/python3.10/site-packages/sklearn/utils/_set_output.py", line 157, in wrapped
    data_to_wrap = f(self, X, *args, **kwargs)
  File "/common/ketrong/AutoImputeExp/tpot2_imputetest/Impute_Experiments/transformers.py", line 610, in fit_transform
    return self.fit(X, **fit_params).transform(X)
  File "/home/ketrong/miniconda3/envs/tpot2devenv/lib/python3.10/site-packages/sklearn/utils/_set_output.py", line 157, in wrapped
    data_to_wrap = f(self, X, *args, **kwargs)
  File "/common/ketrong/AutoImputeExp/tpot2_imputetest/Impute_Experiments/transformers.py", line 606, in transform
    return self.gain(X, self.params)
  File "/common/ketrong/AutoImputeExp/tpot2_imputetest/Impute_Experiments/transformers.py", line 630, in gain
    batch_size = gain_parameters['batch_size']
KeyError: 'batch_size'

WARNING THIS INDIVIDUAL CAUSED AND EXCEPTION 
 [('GradientBoostingClassifier_1', 'KNNImputer_1')] 
 ExponentialLoss requires 2 classes; got 5 class(es) 
 Traceback (most recent call last):
  File "/home/ketrong/miniconda3/envs/tpot2devenv/lib/python3.10/site-packages/tpot2/utils/eval_utils.py", line 53, in objective_nan_wrapper
    value = func_timeout.func_timeout(timeout, objective_function, args=[individual], kwargs=objective_kwargs)
  File "/home/ketrong/miniconda3/envs/tpot2devenv/lib/python3.10/site-packages/func_timeout/dafunc.py", line 108, in func_timeout
    raise_exception(exception)
  File "/home/ketrong/miniconda3/envs/tpot2devenv/lib/python3.10/site-packages/func_timeout/py3_raise.py", line 7, in raise_exception
    raise exception[0] from None
  File "/home/ketrong/miniconda3/envs/tpot2devenv/lib/python3.10/site-packages/tpot2/tpot_estimator/estimator.py", line 702, in objective_function
    return objective_function_generator(
  File "/home/ketrong/miniconda3/envs/tpot2devenv/lib/python3.10/site-packages/tpot2/tpot_estimator/estimator_utils.py", line 117, in objective_function_generator
    cv_obj_scores = cross_val_score_objective(sklearn.base.clone(pipeline),x,y,scorers=scorers, cv=cv , fold=step)
  File "/home/ketrong/miniconda3/envs/tpot2devenv/lib/python3.10/site-packages/tpot2/tpot_estimator/cross_val_utils.py", line 28, in cross_val_score_objective
    this_fold_pipeline.fit(X_train,y_train)
  File "/home/ketrong/miniconda3/envs/tpot2devenv/lib/python3.10/site-packages/tpot2/graphsklearn.py", line 354, in fit
    fit_sklearn_digraph(   graph=self.graph,
  File "/home/ketrong/miniconda3/envs/tpot2devenv/lib/python3.10/site-packages/tpot2/graphsklearn.py", line 153, in fit_sklearn_digraph
    transformed, instance = estimator_fit_transform_override_cross_val_predict_cached(instance, this_X, y, cv=cross_val_predict_cv, method=method,subset_indexes=subset_indexes)
  File "/home/ketrong/miniconda3/envs/tpot2devenv/lib/python3.10/site-packages/joblib/memory.py", line 353, in __call__
    return self.func(*args, **kwargs)
  File "/home/ketrong/miniconda3/envs/tpot2devenv/lib/python3.10/site-packages/tpot2/graphsklearn.py", line 77, in estimator_fit_transform_override_cross_val_predict
    estimator.fit(X,y, **fit_params)
  File "/home/ketrong/miniconda3/envs/tpot2devenv/lib/python3.10/site-packages/sklearn/base.py", line 1152, in wrapper
    return fit_method(estimator, *args, **kwargs)
  File "/home/ketrong/miniconda3/envs/tpot2devenv/lib/python3.10/site-packages/sklearn/ensemble/_gb.py", line 431, in fit
    self._check_params()
  File "/home/ketrong/miniconda3/envs/tpot2devenv/lib/python3.10/site-packages/sklearn/ensemble/_gb.py", line 276, in _check_params
    self._loss = loss_class(self.n_classes_)
  File "/home/ketrong/miniconda3/envs/tpot2devenv/lib/python3.10/site-packages/sklearn/ensemble/_gb_losses.py", line 889, in __init__
    raise ValueError(
ValueError: ExponentialLoss requires 2 classes; got 5 class(es)

WARNING THIS INDIVIDUAL CAUSED AND EXCEPTION 
 [('GradientBoostingClassifier_1', 'RandomForestImputer_1')] 
 ExponentialLoss requires 2 classes; got 5 class(es) 
 Traceback (most recent call last):
  File "/home/ketrong/miniconda3/envs/tpot2devenv/lib/python3.10/site-packages/tpot2/utils/eval_utils.py", line 53, in objective_nan_wrapper
    value = func_timeout.func_timeout(timeout, objective_function, args=[individual], kwargs=objective_kwargs)
  File "/home/ketrong/miniconda3/envs/tpot2devenv/lib/python3.10/site-packages/func_timeout/dafunc.py", line 108, in func_timeout
    raise_exception(exception)
  File "/home/ketrong/miniconda3/envs/tpot2devenv/lib/python3.10/site-packages/func_timeout/py3_raise.py", line 7, in raise_exception
    raise exception[0] from None
  File "/home/ketrong/miniconda3/envs/tpot2devenv/lib/python3.10/site-packages/tpot2/tpot_estimator/estimator.py", line 702, in objective_function
    return objective_function_generator(
  File "/home/ketrong/miniconda3/envs/tpot2devenv/lib/python3.10/site-packages/tpot2/tpot_estimator/estimator_utils.py", line 117, in objective_function_generator
    cv_obj_scores = cross_val_score_objective(sklearn.base.clone(pipeline),x,y,scorers=scorers, cv=cv , fold=step)
  File "/home/ketrong/miniconda3/envs/tpot2devenv/lib/python3.10/site-packages/tpot2/tpot_estimator/cross_val_utils.py", line 28, in cross_val_score_objective
    this_fold_pipeline.fit(X_train,y_train)
  File "/home/ketrong/miniconda3/envs/tpot2devenv/lib/python3.10/site-packages/tpot2/graphsklearn.py", line 354, in fit
    fit_sklearn_digraph(   graph=self.graph,
  File "/home/ketrong/miniconda3/envs/tpot2devenv/lib/python3.10/site-packages/tpot2/graphsklearn.py", line 153, in fit_sklearn_digraph
    transformed, instance = estimator_fit_transform_override_cross_val_predict_cached(instance, this_X, y, cv=cross_val_predict_cv, method=method,subset_indexes=subset_indexes)
  File "/home/ketrong/miniconda3/envs/tpot2devenv/lib/python3.10/site-packages/joblib/memory.py", line 353, in __call__
    return self.func(*args, **kwargs)
  File "/home/ketrong/miniconda3/envs/tpot2devenv/lib/python3.10/site-packages/tpot2/graphsklearn.py", line 77, in estimator_fit_transform_override_cross_val_predict
    estimator.fit(X,y, **fit_params)
  File "/home/ketrong/miniconda3/envs/tpot2devenv/lib/python3.10/site-packages/sklearn/base.py", line 1152, in wrapper
    return fit_method(estimator, *args, **kwargs)
  File "/home/ketrong/miniconda3/envs/tpot2devenv/lib/python3.10/site-packages/sklearn/ensemble/_gb.py", line 431, in fit
    self._check_params()
  File "/home/ketrong/miniconda3/envs/tpot2devenv/lib/python3.10/site-packages/sklearn/ensemble/_gb.py", line 276, in _check_params
    self._loss = loss_class(self.n_classes_)
  File "/home/ketrong/miniconda3/envs/tpot2devenv/lib/python3.10/site-packages/sklearn/ensemble/_gb_losses.py", line 889, in __init__
    raise ValueError(
ValueError: ExponentialLoss requires 2 classes; got 5 class(es)

WARNING THIS INDIVIDUAL CAUSED AND EXCEPTION 
 [('SGDClassifier_1', 'GAINImputer_1'), ('SGDClassifier_1', 'SimpleImputer_1'), ('SGDClassifier_1', 'RandomForestImputer_1'), ('SGDClassifier_1', 'KNNImputer_1'), ('SGDClassifier_1', 'GAINImputer_2'), ('SGDClassifier_1', 'IterativeImputer_1'), ('SGDClassifier_1', 'RandomForestImputer_2'), ('SGDClassifier_1', 'SimpleImputer_2')] 
 'batch_size' 
 Traceback (most recent call last):
  File "/home/ketrong/miniconda3/envs/tpot2devenv/lib/python3.10/site-packages/tpot2/utils/eval_utils.py", line 53, in objective_nan_wrapper
    value = func_timeout.func_timeout(timeout, objective_function, args=[individual], kwargs=objective_kwargs)
  File "/home/ketrong/miniconda3/envs/tpot2devenv/lib/python3.10/site-packages/func_timeout/dafunc.py", line 108, in func_timeout
    raise_exception(exception)
  File "/home/ketrong/miniconda3/envs/tpot2devenv/lib/python3.10/site-packages/func_timeout/py3_raise.py", line 7, in raise_exception
    raise exception[0] from None
  File "/home/ketrong/miniconda3/envs/tpot2devenv/lib/python3.10/site-packages/tpot2/tpot_estimator/estimator.py", line 702, in objective_function
    return objective_function_generator(
  File "/home/ketrong/miniconda3/envs/tpot2devenv/lib/python3.10/site-packages/tpot2/tpot_estimator/estimator_utils.py", line 117, in objective_function_generator
    cv_obj_scores = cross_val_score_objective(sklearn.base.clone(pipeline),x,y,scorers=scorers, cv=cv , fold=step)
  File "/home/ketrong/miniconda3/envs/tpot2devenv/lib/python3.10/site-packages/tpot2/tpot_estimator/cross_val_utils.py", line 28, in cross_val_score_objective
    this_fold_pipeline.fit(X_train,y_train)
  File "/home/ketrong/miniconda3/envs/tpot2devenv/lib/python3.10/site-packages/tpot2/graphsklearn.py", line 354, in fit
    fit_sklearn_digraph(   graph=self.graph,
  File "/home/ketrong/miniconda3/envs/tpot2devenv/lib/python3.10/site-packages/tpot2/graphsklearn.py", line 155, in fit_sklearn_digraph
    transformed, instance = fit_transform_one_cached(instance, this_X, y, subset_indexes=subset_indexes)#instance.fit_transform(this_X,y)
  File "/home/ketrong/miniconda3/envs/tpot2devenv/lib/python3.10/site-packages/joblib/memory.py", line 353, in __call__
    return self.func(*args, **kwargs)
  File "/home/ketrong/miniconda3/envs/tpot2devenv/lib/python3.10/site-packages/tpot2/graphsklearn.py", line 96, in _fit_transform_one
    res = model.fit_transform(X, y, **fit_params)
  File "/home/ketrong/miniconda3/envs/tpot2devenv/lib/python3.10/site-packages/sklearn/utils/_set_output.py", line 157, in wrapped
    data_to_wrap = f(self, X, *args, **kwargs)
  File "/common/ketrong/AutoImputeExp/tpot2_imputetest/Impute_Experiments/transformers.py", line 610, in fit_transform
    return self.fit(X, **fit_params).transform(X)
  File "/home/ketrong/miniconda3/envs/tpot2devenv/lib/python3.10/site-packages/sklearn/utils/_set_output.py", line 157, in wrapped
    data_to_wrap = f(self, X, *args, **kwargs)
  File "/common/ketrong/AutoImputeExp/tpot2_imputetest/Impute_Experiments/transformers.py", line 606, in transform
    return self.gain(X, self.params)
  File "/common/ketrong/AutoImputeExp/tpot2_imputetest/Impute_Experiments/transformers.py", line 630, in gain
    batch_size = gain_parameters['batch_size']
KeyError: 'batch_size'

WARNING THIS INDIVIDUAL CAUSED AND EXCEPTION 
 [('XGBClassifier_1', 'SimpleImputer_1'), ('XGBClassifier_1', 'IterativeImputer_1'), ('XGBClassifier_1', 'KNNImputer_1')] 
 LinearModel.predict() got an unexpected keyword argument 'return_std' 
 Traceback (most recent call last):
  File "/home/ketrong/miniconda3/envs/tpot2devenv/lib/python3.10/site-packages/tpot2/utils/eval_utils.py", line 53, in objective_nan_wrapper
    value = func_timeout.func_timeout(timeout, objective_function, args=[individual], kwargs=objective_kwargs)
  File "/home/ketrong/miniconda3/envs/tpot2devenv/lib/python3.10/site-packages/func_timeout/dafunc.py", line 108, in func_timeout
    raise_exception(exception)
  File "/home/ketrong/miniconda3/envs/tpot2devenv/lib/python3.10/site-packages/func_timeout/py3_raise.py", line 7, in raise_exception
    raise exception[0] from None
  File "/home/ketrong/miniconda3/envs/tpot2devenv/lib/python3.10/site-packages/tpot2/tpot_estimator/estimator.py", line 702, in objective_function
    return objective_function_generator(
  File "/home/ketrong/miniconda3/envs/tpot2devenv/lib/python3.10/site-packages/tpot2/tpot_estimator/estimator_utils.py", line 117, in objective_function_generator
    cv_obj_scores = cross_val_score_objective(sklearn.base.clone(pipeline),x,y,scorers=scorers, cv=cv , fold=step)
  File "/home/ketrong/miniconda3/envs/tpot2devenv/lib/python3.10/site-packages/tpot2/tpot_estimator/cross_val_utils.py", line 28, in cross_val_score_objective
    this_fold_pipeline.fit(X_train,y_train)
  File "/home/ketrong/miniconda3/envs/tpot2devenv/lib/python3.10/site-packages/tpot2/graphsklearn.py", line 354, in fit
    fit_sklearn_digraph(   graph=self.graph,
  File "/home/ketrong/miniconda3/envs/tpot2devenv/lib/python3.10/site-packages/tpot2/graphsklearn.py", line 155, in fit_sklearn_digraph
    transformed, instance = fit_transform_one_cached(instance, this_X, y, subset_indexes=subset_indexes)#instance.fit_transform(this_X,y)
  File "/home/ketrong/miniconda3/envs/tpot2devenv/lib/python3.10/site-packages/joblib/memory.py", line 353, in __call__
    return self.func(*args, **kwargs)
  File "/home/ketrong/miniconda3/envs/tpot2devenv/lib/python3.10/site-packages/tpot2/graphsklearn.py", line 96, in _fit_transform_one
    res = model.fit_transform(X, y, **fit_params)
  File "/home/ketrong/miniconda3/envs/tpot2devenv/lib/python3.10/site-packages/sklearn/utils/_set_output.py", line 157, in wrapped
    data_to_wrap = f(self, X, *args, **kwargs)
  File "/home/ketrong/miniconda3/envs/tpot2devenv/lib/python3.10/site-packages/sklearn/base.py", line 1152, in wrapper
    return fit_method(estimator, *args, **kwargs)
  File "/home/ketrong/miniconda3/envs/tpot2devenv/lib/python3.10/site-packages/sklearn/impute/_iterative.py", line 765, in fit_transform
    Xt, estimator = self._impute_one_feature(
  File "/home/ketrong/miniconda3/envs/tpot2devenv/lib/python3.10/site-packages/sklearn/impute/_iterative.py", line 425, in _impute_one_feature
    mus, sigmas = estimator.predict(X_test, return_std=True)
TypeError: LinearModel.predict() got an unexpected keyword argument 'return_std'

WARNING THIS INDIVIDUAL CAUSED AND EXCEPTION 
 [('SGDClassifier_1', 'KNNImputer_1')] 
 Input contains NaN. 
 Traceback (most recent call last):
  File "/home/ketrong/miniconda3/envs/tpot2devenv/lib/python3.10/site-packages/tpot2/utils/eval_utils.py", line 53, in objective_nan_wrapper
    value = func_timeout.func_timeout(timeout, objective_function, args=[individual], kwargs=objective_kwargs)
  File "/home/ketrong/miniconda3/envs/tpot2devenv/lib/python3.10/site-packages/func_timeout/dafunc.py", line 108, in func_timeout
    raise_exception(exception)
  File "/home/ketrong/miniconda3/envs/tpot2devenv/lib/python3.10/site-packages/func_timeout/py3_raise.py", line 7, in raise_exception
    raise exception[0] from None
  File "/home/ketrong/miniconda3/envs/tpot2devenv/lib/python3.10/site-packages/tpot2/tpot_estimator/estimator.py", line 702, in objective_function
    return objective_function_generator(
  File "/home/ketrong/miniconda3/envs/tpot2devenv/lib/python3.10/site-packages/tpot2/tpot_estimator/estimator_utils.py", line 117, in objective_function_generator
    cv_obj_scores = cross_val_score_objective(sklearn.base.clone(pipeline),x,y,scorers=scorers, cv=cv , fold=step)
  File "/home/ketrong/miniconda3/envs/tpot2devenv/lib/python3.10/site-packages/tpot2/tpot_estimator/cross_val_utils.py", line 31, in cross_val_score_objective
    this_fold_scores = [sklearn.metrics.get_scorer(scorer)(this_fold_pipeline, X_test, y_test) for scorer in scorers]
  File "/home/ketrong/miniconda3/envs/tpot2devenv/lib/python3.10/site-packages/tpot2/tpot_estimator/cross_val_utils.py", line 31, in <listcomp>
    this_fold_scores = [sklearn.metrics.get_scorer(scorer)(this_fold_pipeline, X_test, y_test) for scorer in scorers]
  File "/home/ketrong/miniconda3/envs/tpot2devenv/lib/python3.10/site-packages/sklearn/metrics/_scorer.py", line 266, in __call__
    return self._score(partial(_cached_call, None), estimator, X, y_true, **_kwargs)
  File "/home/ketrong/miniconda3/envs/tpot2devenv/lib/python3.10/site-packages/sklearn/metrics/_scorer.py", line 401, in _score
    return self._sign * self._score_func(y, y_pred, **scoring_kwargs)
  File "/home/ketrong/miniconda3/envs/tpot2devenv/lib/python3.10/site-packages/sklearn/utils/_param_validation.py", line 214, in wrapper
    return func(*args, **kwargs)
  File "/home/ketrong/miniconda3/envs/tpot2devenv/lib/python3.10/site-packages/sklearn/metrics/_classification.py", line 2844, in log_loss
    y_pred = check_array(
  File "/home/ketrong/miniconda3/envs/tpot2devenv/lib/python3.10/site-packages/sklearn/utils/validation.py", line 957, in check_array
    _assert_all_finite(
  File "/home/ketrong/miniconda3/envs/tpot2devenv/lib/python3.10/site-packages/sklearn/utils/validation.py", line 122, in _assert_all_finite
    _assert_all_finite_element_wise(
  File "/home/ketrong/miniconda3/envs/tpot2devenv/lib/python3.10/site-packages/sklearn/utils/validation.py", line 171, in _assert_all_finite_element_wise
    raise ValueError(msg_err)
ValueError: Input contains NaN.

WARNING THIS INDIVIDUAL CAUSED AND EXCEPTION 
 [('BernoulliNB_1', 'GAINImputer_1'), ('BernoulliNB_1', 'GAINImputer_2'), ('BernoulliNB_1', 'IterativeImputer_1'), ('BernoulliNB_1', 'IterativeImputer_2'), ('BernoulliNB_1', 'RandomForestImputer_1'), ('BernoulliNB_1', 'RandomForestImputer_2')] 
 LinearModel.predict() got an unexpected keyword argument 'return_std' 
 Traceback (most recent call last):
  File "/home/ketrong/miniconda3/envs/tpot2devenv/lib/python3.10/site-packages/tpot2/utils/eval_utils.py", line 53, in objective_nan_wrapper
    value = func_timeout.func_timeout(timeout, objective_function, args=[individual], kwargs=objective_kwargs)
  File "/home/ketrong/miniconda3/envs/tpot2devenv/lib/python3.10/site-packages/func_timeout/dafunc.py", line 108, in func_timeout
    raise_exception(exception)
  File "/home/ketrong/miniconda3/envs/tpot2devenv/lib/python3.10/site-packages/func_timeout/py3_raise.py", line 7, in raise_exception
    raise exception[0] from None
  File "/home/ketrong/miniconda3/envs/tpot2devenv/lib/python3.10/site-packages/tpot2/tpot_estimator/estimator.py", line 702, in objective_function
    return objective_function_generator(
  File "/home/ketrong/miniconda3/envs/tpot2devenv/lib/python3.10/site-packages/tpot2/tpot_estimator/estimator_utils.py", line 117, in objective_function_generator
    cv_obj_scores = cross_val_score_objective(sklearn.base.clone(pipeline),x,y,scorers=scorers, cv=cv , fold=step)
  File "/home/ketrong/miniconda3/envs/tpot2devenv/lib/python3.10/site-packages/tpot2/tpot_estimator/cross_val_utils.py", line 28, in cross_val_score_objective
    this_fold_pipeline.fit(X_train,y_train)
  File "/home/ketrong/miniconda3/envs/tpot2devenv/lib/python3.10/site-packages/tpot2/graphsklearn.py", line 354, in fit
    fit_sklearn_digraph(   graph=self.graph,
  File "/home/ketrong/miniconda3/envs/tpot2devenv/lib/python3.10/site-packages/tpot2/graphsklearn.py", line 155, in fit_sklearn_digraph
    transformed, instance = fit_transform_one_cached(instance, this_X, y, subset_indexes=subset_indexes)#instance.fit_transform(this_X,y)
  File "/home/ketrong/miniconda3/envs/tpot2devenv/lib/python3.10/site-packages/joblib/memory.py", line 353, in __call__
    return self.func(*args, **kwargs)
  File "/home/ketrong/miniconda3/envs/tpot2devenv/lib/python3.10/site-packages/tpot2/graphsklearn.py", line 96, in _fit_transform_one
    res = model.fit_transform(X, y, **fit_params)
  File "/home/ketrong/miniconda3/envs/tpot2devenv/lib/python3.10/site-packages/sklearn/utils/_set_output.py", line 157, in wrapped
    data_to_wrap = f(self, X, *args, **kwargs)
  File "/home/ketrong/miniconda3/envs/tpot2devenv/lib/python3.10/site-packages/sklearn/base.py", line 1152, in wrapper
    return fit_method(estimator, *args, **kwargs)
  File "/home/ketrong/miniconda3/envs/tpot2devenv/lib/python3.10/site-packages/sklearn/impute/_iterative.py", line 765, in fit_transform
    Xt, estimator = self._impute_one_feature(
  File "/home/ketrong/miniconda3/envs/tpot2devenv/lib/python3.10/site-packages/sklearn/impute/_iterative.py", line 425, in _impute_one_feature
    mus, sigmas = estimator.predict(X_test, return_std=True)
TypeError: LinearModel.predict() got an unexpected keyword argument 'return_std'

WARNING THIS INDIVIDUAL CAUSED AND EXCEPTION 
 [('BernoulliNB_1', 'GAINImputer_1'), ('BernoulliNB_1', 'GAINImputer_2'), ('BernoulliNB_1', 'RandomForestImputer_1'), ('BernoulliNB_1', 'KNNImputer_1')] 
 'batch_size' 
 Traceback (most recent call last):
  File "/home/ketrong/miniconda3/envs/tpot2devenv/lib/python3.10/site-packages/tpot2/utils/eval_utils.py", line 53, in objective_nan_wrapper
    value = func_timeout.func_timeout(timeout, objective_function, args=[individual], kwargs=objective_kwargs)
  File "/home/ketrong/miniconda3/envs/tpot2devenv/lib/python3.10/site-packages/func_timeout/dafunc.py", line 108, in func_timeout
    raise_exception(exception)
  File "/home/ketrong/miniconda3/envs/tpot2devenv/lib/python3.10/site-packages/func_timeout/py3_raise.py", line 7, in raise_exception
    raise exception[0] from None
  File "/home/ketrong/miniconda3/envs/tpot2devenv/lib/python3.10/site-packages/tpot2/tpot_estimator/estimator.py", line 702, in objective_function
    return objective_function_generator(
  File "/home/ketrong/miniconda3/envs/tpot2devenv/lib/python3.10/site-packages/tpot2/tpot_estimator/estimator_utils.py", line 117, in objective_function_generator
    cv_obj_scores = cross_val_score_objective(sklearn.base.clone(pipeline),x,y,scorers=scorers, cv=cv , fold=step)
  File "/home/ketrong/miniconda3/envs/tpot2devenv/lib/python3.10/site-packages/tpot2/tpot_estimator/cross_val_utils.py", line 28, in cross_val_score_objective
    this_fold_pipeline.fit(X_train,y_train)
  File "/home/ketrong/miniconda3/envs/tpot2devenv/lib/python3.10/site-packages/tpot2/graphsklearn.py", line 354, in fit
    fit_sklearn_digraph(   graph=self.graph,
  File "/home/ketrong/miniconda3/envs/tpot2devenv/lib/python3.10/site-packages/tpot2/graphsklearn.py", line 155, in fit_sklearn_digraph
    transformed, instance = fit_transform_one_cached(instance, this_X, y, subset_indexes=subset_indexes)#instance.fit_transform(this_X,y)
  File "/home/ketrong/miniconda3/envs/tpot2devenv/lib/python3.10/site-packages/joblib/memory.py", line 353, in __call__
    return self.func(*args, **kwargs)
  File "/home/ketrong/miniconda3/envs/tpot2devenv/lib/python3.10/site-packages/tpot2/graphsklearn.py", line 96, in _fit_transform_one
    res = model.fit_transform(X, y, **fit_params)
  File "/home/ketrong/miniconda3/envs/tpot2devenv/lib/python3.10/site-packages/sklearn/utils/_set_output.py", line 157, in wrapped
    data_to_wrap = f(self, X, *args, **kwargs)
  File "/common/ketrong/AutoImputeExp/tpot2_imputetest/Impute_Experiments/transformers.py", line 610, in fit_transform
    return self.fit(X, **fit_params).transform(X)
  File "/home/ketrong/miniconda3/envs/tpot2devenv/lib/python3.10/site-packages/sklearn/utils/_set_output.py", line 157, in wrapped
    data_to_wrap = f(self, X, *args, **kwargs)
  File "/common/ketrong/AutoImputeExp/tpot2_imputetest/Impute_Experiments/transformers.py", line 606, in transform
    return self.gain(X, self.params)
  File "/common/ketrong/AutoImputeExp/tpot2_imputetest/Impute_Experiments/transformers.py", line 630, in gain
    batch_size = gain_parameters['batch_size']
KeyError: 'batch_size'

WARNING THIS INDIVIDUAL CAUSED AND EXCEPTION 
 [('GaussianNB_1', 'GAINImputer_1'), ('GaussianNB_1', 'RandomForestImputer_1'), ('GaussianNB_1', 'IterativeImputer_1'), ('GaussianNB_1', 'RandomForestImputer_2'), ('GaussianNB_1', 'KNNImputer_1')] 
 'batch_size' 
 Traceback (most recent call last):
  File "/home/ketrong/miniconda3/envs/tpot2devenv/lib/python3.10/site-packages/tpot2/utils/eval_utils.py", line 53, in objective_nan_wrapper
    value = func_timeout.func_timeout(timeout, objective_function, args=[individual], kwargs=objective_kwargs)
  File "/home/ketrong/miniconda3/envs/tpot2devenv/lib/python3.10/site-packages/func_timeout/dafunc.py", line 108, in func_timeout
    raise_exception(exception)
  File "/home/ketrong/miniconda3/envs/tpot2devenv/lib/python3.10/site-packages/func_timeout/py3_raise.py", line 7, in raise_exception
    raise exception[0] from None
  File "/home/ketrong/miniconda3/envs/tpot2devenv/lib/python3.10/site-packages/tpot2/tpot_estimator/estimator.py", line 702, in objective_function
    return objective_function_generator(
  File "/home/ketrong/miniconda3/envs/tpot2devenv/lib/python3.10/site-packages/tpot2/tpot_estimator/estimator_utils.py", line 117, in objective_function_generator
    cv_obj_scores = cross_val_score_objective(sklearn.base.clone(pipeline),x,y,scorers=scorers, cv=cv , fold=step)
  File "/home/ketrong/miniconda3/envs/tpot2devenv/lib/python3.10/site-packages/tpot2/tpot_estimator/cross_val_utils.py", line 28, in cross_val_score_objective
    this_fold_pipeline.fit(X_train,y_train)
  File "/home/ketrong/miniconda3/envs/tpot2devenv/lib/python3.10/site-packages/tpot2/graphsklearn.py", line 354, in fit
    fit_sklearn_digraph(   graph=self.graph,
  File "/home/ketrong/miniconda3/envs/tpot2devenv/lib/python3.10/site-packages/tpot2/graphsklearn.py", line 155, in fit_sklearn_digraph
    transformed, instance = fit_transform_one_cached(instance, this_X, y, subset_indexes=subset_indexes)#instance.fit_transform(this_X,y)
  File "/home/ketrong/miniconda3/envs/tpot2devenv/lib/python3.10/site-packages/joblib/memory.py", line 353, in __call__
    return self.func(*args, **kwargs)
  File "/home/ketrong/miniconda3/envs/tpot2devenv/lib/python3.10/site-packages/tpot2/graphsklearn.py", line 96, in _fit_transform_one
    res = model.fit_transform(X, y, **fit_params)
  File "/home/ketrong/miniconda3/envs/tpot2devenv/lib/python3.10/site-packages/sklearn/utils/_set_output.py", line 157, in wrapped
    data_to_wrap = f(self, X, *args, **kwargs)
  File "/common/ketrong/AutoImputeExp/tpot2_imputetest/Impute_Experiments/transformers.py", line 610, in fit_transform
    return self.fit(X, **fit_params).transform(X)
  File "/home/ketrong/miniconda3/envs/tpot2devenv/lib/python3.10/site-packages/sklearn/utils/_set_output.py", line 157, in wrapped
    data_to_wrap = f(self, X, *args, **kwargs)
  File "/common/ketrong/AutoImputeExp/tpot2_imputetest/Impute_Experiments/transformers.py", line 606, in transform
    return self.gain(X, self.params)
  File "/common/ketrong/AutoImputeExp/tpot2_imputetest/Impute_Experiments/transformers.py", line 630, in gain
    batch_size = gain_parameters['batch_size']
KeyError: 'batch_size'

WARNING THIS INDIVIDUAL CAUSED AND EXCEPTION 
 [('SVC_1', 'SimpleImputer_1'), ('SVC_1', 'SimpleImputer_2'), ('SVC_1', 'GAINImputer_1'), ('SVC_1', 'KNNImputer_1'), ('SVC_1', 'KNNImputer_2'), ('SVC_1', 'SimpleImputer_3'), ('SVC_1', 'IterativeImputer_1')] 
 'batch_size' 
 Traceback (most recent call last):
  File "/home/ketrong/miniconda3/envs/tpot2devenv/lib/python3.10/site-packages/tpot2/utils/eval_utils.py", line 53, in objective_nan_wrapper
    value = func_timeout.func_timeout(timeout, objective_function, args=[individual], kwargs=objective_kwargs)
  File "/home/ketrong/miniconda3/envs/tpot2devenv/lib/python3.10/site-packages/func_timeout/dafunc.py", line 108, in func_timeout
    raise_exception(exception)
  File "/home/ketrong/miniconda3/envs/tpot2devenv/lib/python3.10/site-packages/func_timeout/py3_raise.py", line 7, in raise_exception
    raise exception[0] from None
  File "/home/ketrong/miniconda3/envs/tpot2devenv/lib/python3.10/site-packages/tpot2/tpot_estimator/estimator.py", line 702, in objective_function
    return objective_function_generator(
  File "/home/ketrong/miniconda3/envs/tpot2devenv/lib/python3.10/site-packages/tpot2/tpot_estimator/estimator_utils.py", line 117, in objective_function_generator
    cv_obj_scores = cross_val_score_objective(sklearn.base.clone(pipeline),x,y,scorers=scorers, cv=cv , fold=step)
  File "/home/ketrong/miniconda3/envs/tpot2devenv/lib/python3.10/site-packages/tpot2/tpot_estimator/cross_val_utils.py", line 28, in cross_val_score_objective
    this_fold_pipeline.fit(X_train,y_train)
  File "/home/ketrong/miniconda3/envs/tpot2devenv/lib/python3.10/site-packages/tpot2/graphsklearn.py", line 354, in fit
    fit_sklearn_digraph(   graph=self.graph,
  File "/home/ketrong/miniconda3/envs/tpot2devenv/lib/python3.10/site-packages/tpot2/graphsklearn.py", line 155, in fit_sklearn_digraph
    transformed, instance = fit_transform_one_cached(instance, this_X, y, subset_indexes=subset_indexes)#instance.fit_transform(this_X,y)
  File "/home/ketrong/miniconda3/envs/tpot2devenv/lib/python3.10/site-packages/joblib/memory.py", line 353, in __call__
    return self.func(*args, **kwargs)
  File "/home/ketrong/miniconda3/envs/tpot2devenv/lib/python3.10/site-packages/tpot2/graphsklearn.py", line 96, in _fit_transform_one
    res = model.fit_transform(X, y, **fit_params)
  File "/home/ketrong/miniconda3/envs/tpot2devenv/lib/python3.10/site-packages/sklearn/utils/_set_output.py", line 157, in wrapped
    data_to_wrap = f(self, X, *args, **kwargs)
  File "/common/ketrong/AutoImputeExp/tpot2_imputetest/Impute_Experiments/transformers.py", line 610, in fit_transform
    return self.fit(X, **fit_params).transform(X)
  File "/home/ketrong/miniconda3/envs/tpot2devenv/lib/python3.10/site-packages/sklearn/utils/_set_output.py", line 157, in wrapped
    data_to_wrap = f(self, X, *args, **kwargs)
  File "/common/ketrong/AutoImputeExp/tpot2_imputetest/Impute_Experiments/transformers.py", line 606, in transform
    return self.gain(X, self.params)
  File "/common/ketrong/AutoImputeExp/tpot2_imputetest/Impute_Experiments/transformers.py", line 630, in gain
    batch_size = gain_parameters['batch_size']
KeyError: 'batch_size'

WARNING THIS INDIVIDUAL CAUSED AND EXCEPTION 
 [('DecisionTreeClassifier_1', 'KNNImputer_1'), ('DecisionTreeClassifier_1', 'IterativeImputer_1'), ('DecisionTreeClassifier_1', 'KNNImputer_2'), ('DecisionTreeClassifier_1', 'SimpleImputer_1'), ('DecisionTreeClassifier_1', 'KNNImputer_3'), ('DecisionTreeClassifier_1', 'KNNImputer_4'), ('DecisionTreeClassifier_1', 'IterativeImputer_2'), ('DecisionTreeClassifier_1', 'IterativeImputer_3'), ('DecisionTreeClassifier_1', 'KNNImputer_5')] 
 ForestRegressor.predict() got an unexpected keyword argument 'return_std' 
 Traceback (most recent call last):
  File "/home/ketrong/miniconda3/envs/tpot2devenv/lib/python3.10/site-packages/tpot2/utils/eval_utils.py", line 53, in objective_nan_wrapper
    value = func_timeout.func_timeout(timeout, objective_function, args=[individual], kwargs=objective_kwargs)
  File "/home/ketrong/miniconda3/envs/tpot2devenv/lib/python3.10/site-packages/func_timeout/dafunc.py", line 108, in func_timeout
    raise_exception(exception)
  File "/home/ketrong/miniconda3/envs/tpot2devenv/lib/python3.10/site-packages/func_timeout/py3_raise.py", line 7, in raise_exception
    raise exception[0] from None
  File "/home/ketrong/miniconda3/envs/tpot2devenv/lib/python3.10/site-packages/tpot2/tpot_estimator/estimator.py", line 702, in objective_function
    return objective_function_generator(
  File "/home/ketrong/miniconda3/envs/tpot2devenv/lib/python3.10/site-packages/tpot2/tpot_estimator/estimator_utils.py", line 117, in objective_function_generator
    cv_obj_scores = cross_val_score_objective(sklearn.base.clone(pipeline),x,y,scorers=scorers, cv=cv , fold=step)
  File "/home/ketrong/miniconda3/envs/tpot2devenv/lib/python3.10/site-packages/tpot2/tpot_estimator/cross_val_utils.py", line 28, in cross_val_score_objective
    this_fold_pipeline.fit(X_train,y_train)
  File "/home/ketrong/miniconda3/envs/tpot2devenv/lib/python3.10/site-packages/tpot2/graphsklearn.py", line 354, in fit
    fit_sklearn_digraph(   graph=self.graph,
  File "/home/ketrong/miniconda3/envs/tpot2devenv/lib/python3.10/site-packages/tpot2/graphsklearn.py", line 155, in fit_sklearn_digraph
    transformed, instance = fit_transform_one_cached(instance, this_X, y, subset_indexes=subset_indexes)#instance.fit_transform(this_X,y)
  File "/home/ketrong/miniconda3/envs/tpot2devenv/lib/python3.10/site-packages/joblib/memory.py", line 353, in __call__
    return self.func(*args, **kwargs)
  File "/home/ketrong/miniconda3/envs/tpot2devenv/lib/python3.10/site-packages/tpot2/graphsklearn.py", line 96, in _fit_transform_one
    res = model.fit_transform(X, y, **fit_params)
  File "/home/ketrong/miniconda3/envs/tpot2devenv/lib/python3.10/site-packages/sklearn/utils/_set_output.py", line 157, in wrapped
    data_to_wrap = f(self, X, *args, **kwargs)
  File "/home/ketrong/miniconda3/envs/tpot2devenv/lib/python3.10/site-packages/sklearn/base.py", line 1152, in wrapper
    return fit_method(estimator, *args, **kwargs)
  File "/home/ketrong/miniconda3/envs/tpot2devenv/lib/python3.10/site-packages/sklearn/impute/_iterative.py", line 765, in fit_transform
    Xt, estimator = self._impute_one_feature(
  File "/home/ketrong/miniconda3/envs/tpot2devenv/lib/python3.10/site-packages/sklearn/impute/_iterative.py", line 425, in _impute_one_feature
    mus, sigmas = estimator.predict(X_test, return_std=True)
TypeError: ForestRegressor.predict() got an unexpected keyword argument 'return_std'

WARNING THIS INDIVIDUAL CAUSED AND EXCEPTION 
 [('GaussianNB_1', 'SimpleImputer_1'), ('GaussianNB_1', 'KNNImputer_1'), ('GaussianNB_1', 'GAINImputer_1'), ('GaussianNB_1', 'KNNImputer_2'), ('GaussianNB_1', 'KNNImputer_3')] 
 'batch_size' 
 Traceback (most recent call last):
  File "/home/ketrong/miniconda3/envs/tpot2devenv/lib/python3.10/site-packages/tpot2/utils/eval_utils.py", line 53, in objective_nan_wrapper
    value = func_timeout.func_timeout(timeout, objective_function, args=[individual], kwargs=objective_kwargs)
  File "/home/ketrong/miniconda3/envs/tpot2devenv/lib/python3.10/site-packages/func_timeout/dafunc.py", line 108, in func_timeout
    raise_exception(exception)
  File "/home/ketrong/miniconda3/envs/tpot2devenv/lib/python3.10/site-packages/func_timeout/py3_raise.py", line 7, in raise_exception
    raise exception[0] from None
  File "/home/ketrong/miniconda3/envs/tpot2devenv/lib/python3.10/site-packages/tpot2/tpot_estimator/estimator.py", line 702, in objective_function
    return objective_function_generator(
  File "/home/ketrong/miniconda3/envs/tpot2devenv/lib/python3.10/site-packages/tpot2/tpot_estimator/estimator_utils.py", line 117, in objective_function_generator
    cv_obj_scores = cross_val_score_objective(sklearn.base.clone(pipeline),x,y,scorers=scorers, cv=cv , fold=step)
  File "/home/ketrong/miniconda3/envs/tpot2devenv/lib/python3.10/site-packages/tpot2/tpot_estimator/cross_val_utils.py", line 28, in cross_val_score_objective
    this_fold_pipeline.fit(X_train,y_train)
  File "/home/ketrong/miniconda3/envs/tpot2devenv/lib/python3.10/site-packages/tpot2/graphsklearn.py", line 354, in fit
    fit_sklearn_digraph(   graph=self.graph,
  File "/home/ketrong/miniconda3/envs/tpot2devenv/lib/python3.10/site-packages/tpot2/graphsklearn.py", line 155, in fit_sklearn_digraph
    transformed, instance = fit_transform_one_cached(instance, this_X, y, subset_indexes=subset_indexes)#instance.fit_transform(this_X,y)
  File "/home/ketrong/miniconda3/envs/tpot2devenv/lib/python3.10/site-packages/joblib/memory.py", line 353, in __call__
    return self.func(*args, **kwargs)
  File "/home/ketrong/miniconda3/envs/tpot2devenv/lib/python3.10/site-packages/tpot2/graphsklearn.py", line 96, in _fit_transform_one
    res = model.fit_transform(X, y, **fit_params)
  File "/home/ketrong/miniconda3/envs/tpot2devenv/lib/python3.10/site-packages/sklearn/utils/_set_output.py", line 157, in wrapped
    data_to_wrap = f(self, X, *args, **kwargs)
  File "/common/ketrong/AutoImputeExp/tpot2_imputetest/Impute_Experiments/transformers.py", line 610, in fit_transform
    return self.fit(X, **fit_params).transform(X)
  File "/home/ketrong/miniconda3/envs/tpot2devenv/lib/python3.10/site-packages/sklearn/utils/_set_output.py", line 157, in wrapped
    data_to_wrap = f(self, X, *args, **kwargs)
  File "/common/ketrong/AutoImputeExp/tpot2_imputetest/Impute_Experiments/transformers.py", line 606, in transform
    return self.gain(X, self.params)
  File "/common/ketrong/AutoImputeExp/tpot2_imputetest/Impute_Experiments/transformers.py", line 630, in gain
    batch_size = gain_parameters['batch_size']
KeyError: 'batch_size'

WARNING THIS INDIVIDUAL CAUSED AND EXCEPTION 
 [('MultinomialNB_1', 'GAINImputer_1'), ('MultinomialNB_1', 'KNNImputer_1'), ('MultinomialNB_1', 'RandomForestImputer_1'), ('MultinomialNB_1', 'SimpleImputer_1'), ('MultinomialNB_1', 'KNNImputer_2'), ('MultinomialNB_1', 'RandomForestImputer_2')] 
 'batch_size' 
 Traceback (most recent call last):
  File "/home/ketrong/miniconda3/envs/tpot2devenv/lib/python3.10/site-packages/tpot2/utils/eval_utils.py", line 53, in objective_nan_wrapper
    value = func_timeout.func_timeout(timeout, objective_function, args=[individual], kwargs=objective_kwargs)
  File "/home/ketrong/miniconda3/envs/tpot2devenv/lib/python3.10/site-packages/func_timeout/dafunc.py", line 108, in func_timeout
    raise_exception(exception)
  File "/home/ketrong/miniconda3/envs/tpot2devenv/lib/python3.10/site-packages/func_timeout/py3_raise.py", line 7, in raise_exception
    raise exception[0] from None
  File "/home/ketrong/miniconda3/envs/tpot2devenv/lib/python3.10/site-packages/tpot2/tpot_estimator/estimator.py", line 702, in objective_function
    return objective_function_generator(
  File "/home/ketrong/miniconda3/envs/tpot2devenv/lib/python3.10/site-packages/tpot2/tpot_estimator/estimator_utils.py", line 117, in objective_function_generator
    cv_obj_scores = cross_val_score_objective(sklearn.base.clone(pipeline),x,y,scorers=scorers, cv=cv , fold=step)
  File "/home/ketrong/miniconda3/envs/tpot2devenv/lib/python3.10/site-packages/tpot2/tpot_estimator/cross_val_utils.py", line 28, in cross_val_score_objective
    this_fold_pipeline.fit(X_train,y_train)
  File "/home/ketrong/miniconda3/envs/tpot2devenv/lib/python3.10/site-packages/tpot2/graphsklearn.py", line 354, in fit
    fit_sklearn_digraph(   graph=self.graph,
  File "/home/ketrong/miniconda3/envs/tpot2devenv/lib/python3.10/site-packages/tpot2/graphsklearn.py", line 155, in fit_sklearn_digraph
    transformed, instance = fit_transform_one_cached(instance, this_X, y, subset_indexes=subset_indexes)#instance.fit_transform(this_X,y)
  File "/home/ketrong/miniconda3/envs/tpot2devenv/lib/python3.10/site-packages/joblib/memory.py", line 353, in __call__
    return self.func(*args, **kwargs)
  File "/home/ketrong/miniconda3/envs/tpot2devenv/lib/python3.10/site-packages/tpot2/graphsklearn.py", line 96, in _fit_transform_one
    res = model.fit_transform(X, y, **fit_params)
  File "/home/ketrong/miniconda3/envs/tpot2devenv/lib/python3.10/site-packages/sklearn/utils/_set_output.py", line 157, in wrapped
    data_to_wrap = f(self, X, *args, **kwargs)
  File "/common/ketrong/AutoImputeExp/tpot2_imputetest/Impute_Experiments/transformers.py", line 610, in fit_transform
    return self.fit(X, **fit_params).transform(X)
  File "/home/ketrong/miniconda3/envs/tpot2devenv/lib/python3.10/site-packages/sklearn/utils/_set_output.py", line 157, in wrapped
    data_to_wrap = f(self, X, *args, **kwargs)
  File "/common/ketrong/AutoImputeExp/tpot2_imputetest/Impute_Experiments/transformers.py", line 606, in transform
    return self.gain(X, self.params)
  File "/common/ketrong/AutoImputeExp/tpot2_imputetest/Impute_Experiments/transformers.py", line 630, in gain
    batch_size = gain_parameters['batch_size']
KeyError: 'batch_size'

WARNING THIS INDIVIDUAL CAUSED AND EXCEPTION 
 [('DecisionTreeClassifier_1', 'GAINImputer_1'), ('DecisionTreeClassifier_1', 'GAINImputer_2'), ('DecisionTreeClassifier_1', 'RandomForestImputer_1'), ('DecisionTreeClassifier_1', 'IterativeImputer_1'), ('DecisionTreeClassifier_1', 'SimpleImputer_1'), ('DecisionTreeClassifier_1', 'RandomForestImputer_2')] 
 ForestRegressor.predict() got an unexpected keyword argument 'return_std' 
 Traceback (most recent call last):
  File "/home/ketrong/miniconda3/envs/tpot2devenv/lib/python3.10/site-packages/tpot2/utils/eval_utils.py", line 53, in objective_nan_wrapper
    value = func_timeout.func_timeout(timeout, objective_function, args=[individual], kwargs=objective_kwargs)
  File "/home/ketrong/miniconda3/envs/tpot2devenv/lib/python3.10/site-packages/func_timeout/dafunc.py", line 108, in func_timeout
    raise_exception(exception)
  File "/home/ketrong/miniconda3/envs/tpot2devenv/lib/python3.10/site-packages/func_timeout/py3_raise.py", line 7, in raise_exception
    raise exception[0] from None
  File "/home/ketrong/miniconda3/envs/tpot2devenv/lib/python3.10/site-packages/tpot2/tpot_estimator/estimator.py", line 702, in objective_function
    return objective_function_generator(
  File "/home/ketrong/miniconda3/envs/tpot2devenv/lib/python3.10/site-packages/tpot2/tpot_estimator/estimator_utils.py", line 117, in objective_function_generator
    cv_obj_scores = cross_val_score_objective(sklearn.base.clone(pipeline),x,y,scorers=scorers, cv=cv , fold=step)
  File "/home/ketrong/miniconda3/envs/tpot2devenv/lib/python3.10/site-packages/tpot2/tpot_estimator/cross_val_utils.py", line 28, in cross_val_score_objective
    this_fold_pipeline.fit(X_train,y_train)
  File "/home/ketrong/miniconda3/envs/tpot2devenv/lib/python3.10/site-packages/tpot2/graphsklearn.py", line 354, in fit
    fit_sklearn_digraph(   graph=self.graph,
  File "/home/ketrong/miniconda3/envs/tpot2devenv/lib/python3.10/site-packages/tpot2/graphsklearn.py", line 155, in fit_sklearn_digraph
    transformed, instance = fit_transform_one_cached(instance, this_X, y, subset_indexes=subset_indexes)#instance.fit_transform(this_X,y)
  File "/home/ketrong/miniconda3/envs/tpot2devenv/lib/python3.10/site-packages/joblib/memory.py", line 353, in __call__
    return self.func(*args, **kwargs)
  File "/home/ketrong/miniconda3/envs/tpot2devenv/lib/python3.10/site-packages/tpot2/graphsklearn.py", line 96, in _fit_transform_one
    res = model.fit_transform(X, y, **fit_params)
  File "/home/ketrong/miniconda3/envs/tpot2devenv/lib/python3.10/site-packages/sklearn/utils/_set_output.py", line 157, in wrapped
    data_to_wrap = f(self, X, *args, **kwargs)
  File "/home/ketrong/miniconda3/envs/tpot2devenv/lib/python3.10/site-packages/sklearn/base.py", line 1152, in wrapper
    return fit_method(estimator, *args, **kwargs)
  File "/home/ketrong/miniconda3/envs/tpot2devenv/lib/python3.10/site-packages/sklearn/impute/_iterative.py", line 765, in fit_transform
    Xt, estimator = self._impute_one_feature(
  File "/home/ketrong/miniconda3/envs/tpot2devenv/lib/python3.10/site-packages/sklearn/impute/_iterative.py", line 425, in _impute_one_feature
    mus, sigmas = estimator.predict(X_test, return_std=True)
TypeError: ForestRegressor.predict() got an unexpected keyword argument 'return_std'

WARNING THIS INDIVIDUAL CAUSED AND EXCEPTION 
 [('MultinomialNB_1', 'KNNImputer_1'), ('MultinomialNB_1', 'RandomForestImputer_1'), ('MultinomialNB_1', 'IterativeImputer_1'), ('MultinomialNB_1', 'IterativeImputer_2'), ('MultinomialNB_1', 'RandomForestImputer_2'), ('MultinomialNB_1', 'SimpleImputer_1'), ('MultinomialNB_1', 'IterativeImputer_3'), ('MultinomialNB_1', 'KNNImputer_2')] 
 Negative values in data passed to MultinomialNB (input X) 
 Traceback (most recent call last):
  File "/home/ketrong/miniconda3/envs/tpot2devenv/lib/python3.10/site-packages/tpot2/utils/eval_utils.py", line 53, in objective_nan_wrapper
    value = func_timeout.func_timeout(timeout, objective_function, args=[individual], kwargs=objective_kwargs)
  File "/home/ketrong/miniconda3/envs/tpot2devenv/lib/python3.10/site-packages/func_timeout/dafunc.py", line 108, in func_timeout
    raise_exception(exception)
  File "/home/ketrong/miniconda3/envs/tpot2devenv/lib/python3.10/site-packages/func_timeout/py3_raise.py", line 7, in raise_exception
    raise exception[0] from None
  File "/home/ketrong/miniconda3/envs/tpot2devenv/lib/python3.10/site-packages/tpot2/tpot_estimator/estimator.py", line 702, in objective_function
    return objective_function_generator(
  File "/home/ketrong/miniconda3/envs/tpot2devenv/lib/python3.10/site-packages/tpot2/tpot_estimator/estimator_utils.py", line 117, in objective_function_generator
    cv_obj_scores = cross_val_score_objective(sklearn.base.clone(pipeline),x,y,scorers=scorers, cv=cv , fold=step)
  File "/home/ketrong/miniconda3/envs/tpot2devenv/lib/python3.10/site-packages/tpot2/tpot_estimator/cross_val_utils.py", line 28, in cross_val_score_objective
    this_fold_pipeline.fit(X_train,y_train)
  File "/home/ketrong/miniconda3/envs/tpot2devenv/lib/python3.10/site-packages/tpot2/graphsklearn.py", line 354, in fit
    fit_sklearn_digraph(   graph=self.graph,
  File "/home/ketrong/miniconda3/envs/tpot2devenv/lib/python3.10/site-packages/tpot2/graphsklearn.py", line 153, in fit_sklearn_digraph
    transformed, instance = estimator_fit_transform_override_cross_val_predict_cached(instance, this_X, y, cv=cross_val_predict_cv, method=method,subset_indexes=subset_indexes)
  File "/home/ketrong/miniconda3/envs/tpot2devenv/lib/python3.10/site-packages/joblib/memory.py", line 353, in __call__
    return self.func(*args, **kwargs)
  File "/home/ketrong/miniconda3/envs/tpot2devenv/lib/python3.10/site-packages/tpot2/graphsklearn.py", line 77, in estimator_fit_transform_override_cross_val_predict
    estimator.fit(X,y, **fit_params)
  File "/home/ketrong/miniconda3/envs/tpot2devenv/lib/python3.10/site-packages/sklearn/base.py", line 1152, in wrapper
    return fit_method(estimator, *args, **kwargs)
  File "/home/ketrong/miniconda3/envs/tpot2devenv/lib/python3.10/site-packages/sklearn/naive_bayes.py", line 772, in fit
    self._count(X, Y)
  File "/home/ketrong/miniconda3/envs/tpot2devenv/lib/python3.10/site-packages/sklearn/naive_bayes.py", line 894, in _count
    check_non_negative(X, "MultinomialNB (input X)")
  File "/home/ketrong/miniconda3/envs/tpot2devenv/lib/python3.10/site-packages/sklearn/utils/validation.py", line 1489, in check_non_negative
    raise ValueError("Negative values in data passed to %s" % whom)
ValueError: Negative values in data passed to MultinomialNB (input X)

srun: Job step aborted: Waiting up to 32 seconds for job step to finish.
slurmstepd: error: *** JOB 423757 ON esplhpc-cp001 CANCELLED AT 2023-12-01T15:20:52 ***
slurmstepd: error: *** STEP 423757.0 ON esplhpc-cp001 CANCELLED AT 2023-12-01T15:20:52 ***
