/cm/local/apps/slurm/var/spool/job403169/slurm_script: line 19: /common/ketrong/minconda3/etc/profile.d/conda.sh: No such file or directory
/cm/local/apps/slurm/var/spool/job403169/slurm_script: line 22: $'\nconda create --name tpot2devenv -c conda-forge python=3.10\n': command not found
/cm/local/apps/slurm/var/spool/job403169/slurm_script: line 27: $'\npip install -r requirements.txt\n': command not found
RunStart
2023-11-21 15:51:29.122544: I tensorflow/core/util/port.cc:113] oneDNN custom operations are on. You may see slightly different numerical results due to floating-point round-off errors from different computation orders. To turn them off, set the environment variable `TF_ENABLE_ONEDNN_OPTS=0`.
2023-11-21 15:51:29.157885: E external/local_xla/xla/stream_executor/cuda/cuda_dnn.cc:9261] Unable to register cuDNN factory: Attempting to register factory for plugin cuDNN when one has already been registered
2023-11-21 15:51:29.157910: E external/local_xla/xla/stream_executor/cuda/cuda_fft.cc:607] Unable to register cuFFT factory: Attempting to register factory for plugin cuFFT when one has already been registered
2023-11-21 15:51:29.159044: E external/local_xla/xla/stream_executor/cuda/cuda_blas.cc:1515] Unable to register cuBLAS factory: Attempting to register factory for plugin cuBLAS when one has already been registered
2023-11-21 15:51:29.164606: I tensorflow/core/platform/cpu_feature_guard.cc:182] This TensorFlow binary is optimized to use available CPU instructions in performance-critical operations.
To enable the following instructions: AVX2 AVX512F AVX512_VNNI FMA, in other operations, rebuild TensorFlow with the appropriate compiler flags.
2023-11-21 15:51:31.156198: W tensorflow/compiler/tf2tensorrt/utils/py_utils.cc:38] TF-TRT Warning: Could not find TensorRT
WARNING:tensorflow:From /home/ketrong/miniconda3/envs/tpot2devenv/lib/python3.10/site-packages/tensorflow/python/compat/v2_compat.py:108: disable_resource_variables (from tensorflow.python.ops.variable_scope) is deprecated and will be removed in a future version.
Instructions for updating:
non-resource variables are not supported in the long term
working on 
tpot2_imputetest/Impute_Experiments/logs//tpot2_base_imputation_6_0.01_MCAR_2
loading data
tpot2_imputetest/Impute_Experiments/data/6_True.pkl
running experiment 1/3 - Does large hyperparameter space improve reconstruction accuracy over simple
[I 2023-11-21 15:54:02,644] A new study created in memory with name: no-name-ecd9ffb2-c3d1-4bef-b31e-0c904eb84ce2
[W 2023-11-21 15:54:02,646] Trial 0 failed with parameters: {'model_name': 'SimpleImputer', 'strategy': 'most_frequent'} because of the following error: KeyError('model_name').
Traceback (most recent call last):
  File "/home/ketrong/miniconda3/envs/tpot2devenv/lib/python3.10/site-packages/optuna/study/_optimize.py", line 200, in _run_trial
    value_or_values = func(trial)
  File "/common/ketrong/AutoImputeExp/tpot2_imputetest/Impute_Experiments/autoimpute.py", line 57, in obj
    my_model = autoutils.MyModel(random_state = self.random_state, **my_params)
  File "/common/ketrong/AutoImputeExp/tpot2_imputetest/Impute_Experiments/autoutils.py", line 31, in MyModel
    model_name = params['model_name']
KeyError: 'model_name'
[W 2023-11-21 15:54:02,654] Trial 0 failed with value None.
[W 2023-11-21 15:54:02,647] Trial 1 failed with parameters: {'model_name': 'SimpleImputer', 'strategy': 'most_frequent'} because of the following error: KeyError('model_name').
Traceback (most recent call last):
  File "/home/ketrong/miniconda3/envs/tpot2devenv/lib/python3.10/site-packages/optuna/study/_optimize.py", line 200, in _run_trial
    value_or_values = func(trial)
  File "/common/ketrong/AutoImputeExp/tpot2_imputetest/Impute_Experiments/autoimpute.py", line 57, in obj
    my_model = autoutils.MyModel(random_state = self.random_state, **my_params)
  File "/common/ketrong/AutoImputeExp/tpot2_imputetest/Impute_Experiments/autoutils.py", line 31, in MyModel
    model_name = params['model_name']
KeyError: 'model_name'
[W 2023-11-21 15:54:02,840] Trial 1 failed with value None.
[W 2023-11-21 15:54:02,650] Trial 3 failed with parameters: {'model_name': 'SimpleImputer', 'strategy': 'most_frequent'} because of the following error: KeyError('model_name').
Traceback (most recent call last):
  File "/home/ketrong/miniconda3/envs/tpot2devenv/lib/python3.10/site-packages/optuna/study/_optimize.py", line 200, in _run_trial
    value_or_values = func(trial)
  File "/common/ketrong/AutoImputeExp/tpot2_imputetest/Impute_Experiments/autoimpute.py", line 57, in obj
    my_model = autoutils.MyModel(random_state = self.random_state, **my_params)
  File "/common/ketrong/AutoImputeExp/tpot2_imputetest/Impute_Experiments/autoutils.py", line 31, in MyModel
    model_name = params['model_name']
KeyError: 'model_name'
[W 2023-11-21 15:54:02,982] Trial 3 failed with value None.
[W 2023-11-21 15:54:02,652] Trial 6 failed with parameters: {'model_name': 'SimpleImputer', 'strategy': 'median'} because of the following error: KeyError('model_name').
Traceback (most recent call last):
  File "/home/ketrong/miniconda3/envs/tpot2devenv/lib/python3.10/site-packages/optuna/study/_optimize.py", line 200, in _run_trial
    value_or_values = func(trial)
  File "/common/ketrong/AutoImputeExp/tpot2_imputetest/Impute_Experiments/autoimpute.py", line 57, in obj
    my_model = autoutils.MyModel(random_state = self.random_state, **my_params)
  File "/common/ketrong/AutoImputeExp/tpot2_imputetest/Impute_Experiments/autoutils.py", line 31, in MyModel
    model_name = params['model_name']
KeyError: 'model_name'
[W 2023-11-21 15:54:03,123] Trial 6 failed with value None.
[W 2023-11-21 15:54:02,654] Trial 8 failed with parameters: {'model_name': 'SimpleImputer', 'strategy': 'mean'} because of the following error: KeyError('model_name').
Traceback (most recent call last):
  File "/home/ketrong/miniconda3/envs/tpot2devenv/lib/python3.10/site-packages/optuna/study/_optimize.py", line 200, in _run_trial
    value_or_values = func(trial)
  File "/common/ketrong/AutoImputeExp/tpot2_imputetest/Impute_Experiments/autoimpute.py", line 57, in obj
    my_model = autoutils.MyModel(random_state = self.random_state, **my_params)
  File "/common/ketrong/AutoImputeExp/tpot2_imputetest/Impute_Experiments/autoutils.py", line 31, in MyModel
    model_name = params['model_name']
KeyError: 'model_name'
[W 2023-11-21 15:54:03,270] Trial 8 failed with value None.
[W 2023-11-21 15:54:02,648] Trial 2 failed with parameters: {'model_name': 'SimpleImputer', 'strategy': 'median'} because of the following error: KeyError('model_name').
Traceback (most recent call last):
  File "/home/ketrong/miniconda3/envs/tpot2devenv/lib/python3.10/site-packages/optuna/study/_optimize.py", line 200, in _run_trial
    value_or_values = func(trial)
  File "/common/ketrong/AutoImputeExp/tpot2_imputetest/Impute_Experiments/autoimpute.py", line 57, in obj
    my_model = autoutils.MyModel(random_state = self.random_state, **my_params)
  File "/common/ketrong/AutoImputeExp/tpot2_imputetest/Impute_Experiments/autoutils.py", line 31, in MyModel
    model_name = params['model_name']
KeyError: 'model_name'
[W 2023-11-21 15:54:03,411] Trial 2 failed with value None.
[W 2023-11-21 15:54:02,651] Trial 4 failed with parameters: {'model_name': 'SimpleImputer', 'strategy': 'mean'} because of the following error: KeyError('model_name').
Traceback (most recent call last):
  File "/home/ketrong/miniconda3/envs/tpot2devenv/lib/python3.10/site-packages/optuna/study/_optimize.py", line 200, in _run_trial
    value_or_values = func(trial)
  File "/common/ketrong/AutoImputeExp/tpot2_imputetest/Impute_Experiments/autoimpute.py", line 57, in obj
    my_model = autoutils.MyModel(random_state = self.random_state, **my_params)
  File "/common/ketrong/AutoImputeExp/tpot2_imputetest/Impute_Experiments/autoutils.py", line 31, in MyModel
    model_name = params['model_name']
KeyError: 'model_name'
[W 2023-11-21 15:54:03,555] Trial 4 failed with value None.
[W 2023-11-21 15:54:03,269] Trial 10 failed with parameters: {'model_name': 'SimpleImputer', 'strategy': 'mean'} because of the following error: KeyError('model_name').
Traceback (most recent call last):
  File "/home/ketrong/miniconda3/envs/tpot2devenv/lib/python3.10/site-packages/optuna/study/_optimize.py", line 200, in _run_trial
    value_or_values = func(trial)
  File "/common/ketrong/AutoImputeExp/tpot2_imputetest/Impute_Experiments/autoimpute.py", line 57, in obj
    my_model = autoutils.MyModel(random_state = self.random_state, **my_params)
  File "/common/ketrong/AutoImputeExp/tpot2_imputetest/Impute_Experiments/autoutils.py", line 31, in MyModel
    model_name = params['model_name']
KeyError: 'model_name'
[W 2023-11-21 15:54:03,701] Trial 10 failed with value None.
[W 2023-11-21 15:54:02,840] Trial 9 failed with parameters: {'model_name': 'SimpleImputer', 'strategy': 'constant'} because of the following error: KeyError('model_name').
Traceback (most recent call last):
  File "/home/ketrong/miniconda3/envs/tpot2devenv/lib/python3.10/site-packages/optuna/study/_optimize.py", line 200, in _run_trial
    value_or_values = func(trial)
  File "/common/ketrong/AutoImputeExp/tpot2_imputetest/Impute_Experiments/autoimpute.py", line 57, in obj
    my_model = autoutils.MyModel(random_state = self.random_state, **my_params)
  File "/common/ketrong/AutoImputeExp/tpot2_imputetest/Impute_Experiments/autoutils.py", line 31, in MyModel
    model_name = params['model_name']
KeyError: 'model_name'
[W 2023-11-21 15:54:03,841] Trial 9 failed with value None.
[W 2023-11-21 15:54:02,652] Trial 5 failed with parameters: {'model_name': 'SimpleImputer', 'strategy': 'constant'} because of the following error: KeyError('model_name').
Traceback (most recent call last):
  File "/home/ketrong/miniconda3/envs/tpot2devenv/lib/python3.10/site-packages/optuna/study/_optimize.py", line 200, in _run_trial
    value_or_values = func(trial)
  File "/common/ketrong/AutoImputeExp/tpot2_imputetest/Impute_Experiments/autoimpute.py", line 57, in obj
    my_model = autoutils.MyModel(random_state = self.random_state, **my_params)
  File "/common/ketrong/AutoImputeExp/tpot2_imputetest/Impute_Experiments/autoutils.py", line 31, in MyModel
    model_name = params['model_name']
KeyError: 'model_name'
[W 2023-11-21 15:54:03,990] Trial 5 failed with value None.
[W 2023-11-21 15:54:03,555] Trial 14 failed with parameters: {'model_name': 'SimpleImputer', 'strategy': 'constant'} because of the following error: KeyError('model_name').
Traceback (most recent call last):
  File "/home/ketrong/miniconda3/envs/tpot2devenv/lib/python3.10/site-packages/optuna/study/_optimize.py", line 200, in _run_trial
    value_or_values = func(trial)
  File "/common/ketrong/AutoImputeExp/tpot2_imputetest/Impute_Experiments/autoimpute.py", line 57, in obj
    my_model = autoutils.MyModel(random_state = self.random_state, **my_params)
  File "/common/ketrong/AutoImputeExp/tpot2_imputetest/Impute_Experiments/autoutils.py", line 31, in MyModel
    model_name = params['model_name']
KeyError: 'model_name'
[W 2023-11-21 15:54:04,138] Trial 14 failed with value None.
[W 2023-11-21 15:54:03,556] Trial 15 failed with parameters: {'model_name': 'SimpleImputer', 'strategy': 'constant'} because of the following error: KeyError('model_name').
Traceback (most recent call last):
  File "/home/ketrong/miniconda3/envs/tpot2devenv/lib/python3.10/site-packages/optuna/study/_optimize.py", line 200, in _run_trial
    value_or_values = func(trial)
  File "/common/ketrong/AutoImputeExp/tpot2_imputetest/Impute_Experiments/autoimpute.py", line 57, in obj
    my_model = autoutils.MyModel(random_state = self.random_state, **my_params)
  File "/common/ketrong/AutoImputeExp/tpot2_imputetest/Impute_Experiments/autoutils.py", line 31, in MyModel
    model_name = params['model_name']
KeyError: 'model_name'
[W 2023-11-21 15:54:04,279] Trial 15 failed with value None.
[W 2023-11-21 15:54:03,841] Trial 13 failed with parameters: {'model_name': 'SimpleImputer', 'strategy': 'median'} because of the following error: KeyError('model_name').
Traceback (most recent call last):
  File "/home/ketrong/miniconda3/envs/tpot2devenv/lib/python3.10/site-packages/optuna/study/_optimize.py", line 200, in _run_trial
    value_or_values = func(trial)
  File "/common/ketrong/AutoImputeExp/tpot2_imputetest/Impute_Experiments/autoimpute.py", line 57, in obj
    my_model = autoutils.MyModel(random_state = self.random_state, **my_params)
  File "/common/ketrong/AutoImputeExp/tpot2_imputetest/Impute_Experiments/autoutils.py", line 31, in MyModel
    model_name = params['model_name']
KeyError: 'model_name'
[W 2023-11-21 15:54:04,422] Trial 13 failed with value None.
[W 2023-11-21 15:54:03,842] Trial 16 failed with parameters: {'model_name': 'SimpleImputer', 'strategy': 'constant'} because of the following error: KeyError('model_name').
Traceback (most recent call last):
  File "/home/ketrong/miniconda3/envs/tpot2devenv/lib/python3.10/site-packages/optuna/study/_optimize.py", line 200, in _run_trial
    value_or_values = func(trial)
  File "/common/ketrong/AutoImputeExp/tpot2_imputetest/Impute_Experiments/autoimpute.py", line 57, in obj
    my_model = autoutils.MyModel(random_state = self.random_state, **my_params)
  File "/common/ketrong/AutoImputeExp/tpot2_imputetest/Impute_Experiments/autoutils.py", line 31, in MyModel
    model_name = params['model_name']
KeyError: 'model_name'
[W 2023-11-21 15:54:04,564] Trial 16 failed with value None.
[W 2023-11-21 15:54:03,987] Trial 18 failed with parameters: {'model_name': 'SimpleImputer', 'strategy': 'median'} because of the following error: KeyError('model_name').
Traceback (most recent call last):
  File "/home/ketrong/miniconda3/envs/tpot2devenv/lib/python3.10/site-packages/optuna/study/_optimize.py", line 200, in _run_trial
    value_or_values = func(trial)
  File "/common/ketrong/AutoImputeExp/tpot2_imputetest/Impute_Experiments/autoimpute.py", line 57, in obj
    my_model = autoutils.MyModel(random_state = self.random_state, **my_params)
  File "/common/ketrong/AutoImputeExp/tpot2_imputetest/Impute_Experiments/autoutils.py", line 31, in MyModel
    model_name = params['model_name']
KeyError: 'model_name'
[W 2023-11-21 15:54:04,707] Trial 18 failed with value None.
[W 2023-11-21 15:54:03,989] Trial 20 failed with parameters: {'model_name': 'SimpleImputer', 'strategy': 'constant'} because of the following error: KeyError('model_name').
Traceback (most recent call last):
  File "/home/ketrong/miniconda3/envs/tpot2devenv/lib/python3.10/site-packages/optuna/study/_optimize.py", line 200, in _run_trial
    value_or_values = func(trial)
  File "/common/ketrong/AutoImputeExp/tpot2_imputetest/Impute_Experiments/autoimpute.py", line 57, in obj
    my_model = autoutils.MyModel(random_state = self.random_state, **my_params)
  File "/common/ketrong/AutoImputeExp/tpot2_imputetest/Impute_Experiments/autoutils.py", line 31, in MyModel
    model_name = params['model_name']
KeyError: 'model_name'
[W 2023-11-21 15:54:04,854] Trial 20 failed with value None.
[W 2023-11-21 15:54:02,653] Trial 7 failed with parameters: {'model_name': 'SimpleImputer', 'strategy': 'mean'} because of the following error: KeyError('model_name').
Traceback (most recent call last):
  File "/home/ketrong/miniconda3/envs/tpot2devenv/lib/python3.10/site-packages/optuna/study/_optimize.py", line 200, in _run_trial
    value_or_values = func(trial)
  File "/common/ketrong/AutoImputeExp/tpot2_imputetest/Impute_Experiments/autoimpute.py", line 57, in obj
    my_model = autoutils.MyModel(random_state = self.random_state, **my_params)
  File "/common/ketrong/AutoImputeExp/tpot2_imputetest/Impute_Experiments/autoutils.py", line 31, in MyModel
    model_name = params['model_name']
KeyError: 'model_name'
[W 2023-11-21 15:54:04,999] Trial 7 failed with value None.
[W 2023-11-21 15:54:04,137] Trial 23 failed with parameters: {'model_name': 'SimpleImputer', 'strategy': 'median'} because of the following error: KeyError('model_name').
Traceback (most recent call last):
  File "/home/ketrong/miniconda3/envs/tpot2devenv/lib/python3.10/site-packages/optuna/study/_optimize.py", line 200, in _run_trial
    value_or_values = func(trial)
  File "/common/ketrong/AutoImputeExp/tpot2_imputetest/Impute_Experiments/autoimpute.py", line 57, in obj
    my_model = autoutils.MyModel(random_state = self.random_state, **my_params)
  File "/common/ketrong/AutoImputeExp/tpot2_imputetest/Impute_Experiments/autoutils.py", line 31, in MyModel
    model_name = params['model_name']
KeyError: 'model_name'
[W 2023-11-21 15:54:05,141] Trial 23 failed with value None.
[W 2023-11-21 15:54:04,422] Trial 24 failed with parameters: {'model_name': 'SimpleImputer', 'strategy': 'constant'} because of the following error: KeyError('model_name').
Traceback (most recent call last):
  File "/home/ketrong/miniconda3/envs/tpot2devenv/lib/python3.10/site-packages/optuna/study/_optimize.py", line 200, in _run_trial
    value_or_values = func(trial)
  File "/common/ketrong/AutoImputeExp/tpot2_imputetest/Impute_Experiments/autoimpute.py", line 57, in obj
    my_model = autoutils.MyModel(random_state = self.random_state, **my_params)
  File "/common/ketrong/AutoImputeExp/tpot2_imputetest/Impute_Experiments/autoutils.py", line 31, in MyModel
    model_name = params['model_name']
KeyError: 'model_name'
[W 2023-11-21 15:54:05,287] Trial 24 failed with value None.
[W 2023-11-21 15:54:03,843] Trial 17 failed with parameters: {'model_name': 'SimpleImputer', 'strategy': 'mean'} because of the following error: KeyError('model_name').
Traceback (most recent call last):
  File "/home/ketrong/miniconda3/envs/tpot2devenv/lib/python3.10/site-packages/optuna/study/_optimize.py", line 200, in _run_trial
    value_or_values = func(trial)
  File "/common/ketrong/AutoImputeExp/tpot2_imputetest/Impute_Experiments/autoimpute.py", line 57, in obj
    my_model = autoutils.MyModel(random_state = self.random_state, **my_params)
  File "/common/ketrong/AutoImputeExp/tpot2_imputetest/Impute_Experiments/autoutils.py", line 31, in MyModel
    model_name = params['model_name']
KeyError: 'model_name'
[W 2023-11-21 15:54:05,430] Trial 17 failed with value None.
[W 2023-11-21 15:54:03,988] Trial 19 failed with parameters: {'model_name': 'SimpleImputer', 'strategy': 'median'} because of the following error: KeyError('model_name').
Traceback (most recent call last):
  File "/home/ketrong/miniconda3/envs/tpot2devenv/lib/python3.10/site-packages/optuna/study/_optimize.py", line 200, in _run_trial
    value_or_values = func(trial)
  File "/common/ketrong/AutoImputeExp/tpot2_imputetest/Impute_Experiments/autoimpute.py", line 57, in obj
    my_model = autoutils.MyModel(random_state = self.random_state, **my_params)
  File "/common/ketrong/AutoImputeExp/tpot2_imputetest/Impute_Experiments/autoutils.py", line 31, in MyModel
    model_name = params['model_name']
KeyError: 'model_name'
[W 2023-11-21 15:54:05,571] Trial 19 failed with value None.
[W 2023-11-21 15:54:03,990] Trial 21 failed with parameters: {'model_name': 'SimpleImputer', 'strategy': 'most_frequent'} because of the following error: KeyError('model_name').
Traceback (most recent call last):
  File "/home/ketrong/miniconda3/envs/tpot2devenv/lib/python3.10/site-packages/optuna/study/_optimize.py", line 200, in _run_trial
    value_or_values = func(trial)
  File "/common/ketrong/AutoImputeExp/tpot2_imputetest/Impute_Experiments/autoimpute.py", line 57, in obj
    my_model = autoutils.MyModel(random_state = self.random_state, **my_params)
  File "/common/ketrong/AutoImputeExp/tpot2_imputetest/Impute_Experiments/autoutils.py", line 31, in MyModel
    model_name = params['model_name']
KeyError: 'model_name'
[W 2023-11-21 15:54:05,713] Trial 21 failed with value None.
[W 2023-11-21 15:54:04,136] Trial 22 failed with parameters: {'model_name': 'SimpleImputer', 'strategy': 'mean'} because of the following error: KeyError('model_name').
Traceback (most recent call last):
  File "/home/ketrong/miniconda3/envs/tpot2devenv/lib/python3.10/site-packages/optuna/study/_optimize.py", line 200, in _run_trial
    value_or_values = func(trial)
  File "/common/ketrong/AutoImputeExp/tpot2_imputetest/Impute_Experiments/autoimpute.py", line 57, in obj
    my_model = autoutils.MyModel(random_state = self.random_state, **my_params)
  File "/common/ketrong/AutoImputeExp/tpot2_imputetest/Impute_Experiments/autoutils.py", line 31, in MyModel
    model_name = params['model_name']
KeyError: 'model_name'
[W 2023-11-21 15:54:05,859] Trial 22 failed with value None.
[W 2023-11-21 15:54:04,996] Trial 29 failed with parameters: {'model_name': 'SimpleImputer', 'strategy': 'median'} because of the following error: KeyError('model_name').
Traceback (most recent call last):
  File "/home/ketrong/miniconda3/envs/tpot2devenv/lib/python3.10/site-packages/optuna/study/_optimize.py", line 200, in _run_trial
    value_or_values = func(trial)
  File "/common/ketrong/AutoImputeExp/tpot2_imputetest/Impute_Experiments/autoimpute.py", line 57, in obj
    my_model = autoutils.MyModel(random_state = self.random_state, **my_params)
  File "/common/ketrong/AutoImputeExp/tpot2_imputetest/Impute_Experiments/autoutils.py", line 31, in MyModel
    model_name = params['model_name']
KeyError: 'model_name'
[W 2023-11-21 15:54:06,003] Trial 29 failed with value None.
[W 2023-11-21 15:54:03,269] Trial 11 failed with parameters: {'model_name': 'SimpleImputer', 'strategy': 'constant'} because of the following error: KeyError('model_name').
Traceback (most recent call last):
  File "/home/ketrong/miniconda3/envs/tpot2devenv/lib/python3.10/site-packages/optuna/study/_optimize.py", line 200, in _run_trial
    value_or_values = func(trial)
  File "/common/ketrong/AutoImputeExp/tpot2_imputetest/Impute_Experiments/autoimpute.py", line 57, in obj
    my_model = autoutils.MyModel(random_state = self.random_state, **my_params)
  File "/common/ketrong/AutoImputeExp/tpot2_imputetest/Impute_Experiments/autoutils.py", line 31, in MyModel
    model_name = params['model_name']
KeyError: 'model_name'
[W 2023-11-21 15:54:06,144] Trial 11 failed with value None.
[W 2023-11-21 15:54:03,411] Trial 12 failed with parameters: {'model_name': 'SimpleImputer', 'strategy': 'median'} because of the following error: KeyError('model_name').
Traceback (most recent call last):
  File "/home/ketrong/miniconda3/envs/tpot2devenv/lib/python3.10/site-packages/optuna/study/_optimize.py", line 200, in _run_trial
    value_or_values = func(trial)
  File "/common/ketrong/AutoImputeExp/tpot2_imputetest/Impute_Experiments/autoimpute.py", line 57, in obj
    my_model = autoutils.MyModel(random_state = self.random_state, **my_params)
  File "/common/ketrong/AutoImputeExp/tpot2_imputetest/Impute_Experiments/autoutils.py", line 31, in MyModel
    model_name = params['model_name']
KeyError: 'model_name'
[W 2023-11-21 15:54:06,290] Trial 12 failed with value None.
[W 2023-11-21 15:54:05,287] Trial 33 failed with parameters: {'model_name': 'SimpleImputer', 'strategy': 'median'} because of the following error: KeyError('model_name').
Traceback (most recent call last):
  File "/home/ketrong/miniconda3/envs/tpot2devenv/lib/python3.10/site-packages/optuna/study/_optimize.py", line 200, in _run_trial
    value_or_values = func(trial)
  File "/common/ketrong/AutoImputeExp/tpot2_imputetest/Impute_Experiments/autoimpute.py", line 57, in obj
    my_model = autoutils.MyModel(random_state = self.random_state, **my_params)
  File "/common/ketrong/AutoImputeExp/tpot2_imputetest/Impute_Experiments/autoutils.py", line 31, in MyModel
    model_name = params['model_name']
KeyError: 'model_name'
[W 2023-11-21 15:54:06,432] Trial 33 failed with value None.
[W 2023-11-21 15:54:04,706] Trial 26 failed with parameters: {'model_name': 'SimpleImputer', 'strategy': 'median'} because of the following error: KeyError('model_name').
Traceback (most recent call last):
  File "/home/ketrong/miniconda3/envs/tpot2devenv/lib/python3.10/site-packages/optuna/study/_optimize.py", line 200, in _run_trial
    value_or_values = func(trial)
  File "/common/ketrong/AutoImputeExp/tpot2_imputetest/Impute_Experiments/autoimpute.py", line 57, in obj
    my_model = autoutils.MyModel(random_state = self.random_state, **my_params)
  File "/common/ketrong/AutoImputeExp/tpot2_imputetest/Impute_Experiments/autoutils.py", line 31, in MyModel
    model_name = params['model_name']
KeyError: 'model_name'
[W 2023-11-21 15:54:06,573] Trial 26 failed with value None.
[W 2023-11-21 15:54:05,858] Trial 34 failed with parameters: {'model_name': 'SimpleImputer', 'strategy': 'median'} because of the following error: KeyError('model_name').
Traceback (most recent call last):
  File "/home/ketrong/miniconda3/envs/tpot2devenv/lib/python3.10/site-packages/optuna/study/_optimize.py", line 200, in _run_trial
    value_or_values = func(trial)
  File "/common/ketrong/AutoImputeExp/tpot2_imputetest/Impute_Experiments/autoimpute.py", line 57, in obj
    my_model = autoutils.MyModel(random_state = self.random_state, **my_params)
  File "/common/ketrong/AutoImputeExp/tpot2_imputetest/Impute_Experiments/autoutils.py", line 31, in MyModel
    model_name = params['model_name']
KeyError: 'model_name'
[W 2023-11-21 15:54:06,715] Trial 34 failed with value None.
[W 2023-11-21 15:54:04,997] Trial 30 failed with parameters: {'model_name': 'SimpleImputer', 'strategy': 'most_frequent'} because of the following error: KeyError('model_name').
Traceback (most recent call last):
  File "/home/ketrong/miniconda3/envs/tpot2devenv/lib/python3.10/site-packages/optuna/study/_optimize.py", line 200, in _run_trial
    value_or_values = func(trial)
  File "/common/ketrong/AutoImputeExp/tpot2_imputetest/Impute_Experiments/autoimpute.py", line 57, in obj
    my_model = autoutils.MyModel(random_state = self.random_state, **my_params)
  File "/common/ketrong/AutoImputeExp/tpot2_imputetest/Impute_Experiments/autoutils.py", line 31, in MyModel
    model_name = params['model_name']
KeyError: 'model_name'
[W 2023-11-21 15:54:06,863] Trial 30 failed with value None.
[W 2023-11-21 15:54:06,001] Trial 37 failed with parameters: {'model_name': 'SimpleImputer', 'strategy': 'most_frequent'} because of the following error: KeyError('model_name').
Traceback (most recent call last):
  File "/home/ketrong/miniconda3/envs/tpot2devenv/lib/python3.10/site-packages/optuna/study/_optimize.py", line 200, in _run_trial
    value_or_values = func(trial)
  File "/common/ketrong/AutoImputeExp/tpot2_imputetest/Impute_Experiments/autoimpute.py", line 57, in obj
    my_model = autoutils.MyModel(random_state = self.random_state, **my_params)
  File "/common/ketrong/AutoImputeExp/tpot2_imputetest/Impute_Experiments/autoutils.py", line 31, in MyModel
    model_name = params['model_name']
KeyError: 'model_name'
[W 2023-11-21 15:54:07,007] Trial 37 failed with value None.
[W 2023-11-21 15:54:06,003] Trial 38 failed with parameters: {'model_name': 'SimpleImputer', 'strategy': 'constant'} because of the following error: KeyError('model_name').
Traceback (most recent call last):
  File "/home/ketrong/miniconda3/envs/tpot2devenv/lib/python3.10/site-packages/optuna/study/_optimize.py", line 200, in _run_trial
    value_or_values = func(trial)
  File "/common/ketrong/AutoImputeExp/tpot2_imputetest/Impute_Experiments/autoimpute.py", line 57, in obj
    my_model = autoutils.MyModel(random_state = self.random_state, **my_params)
  File "/common/ketrong/AutoImputeExp/tpot2_imputetest/Impute_Experiments/autoutils.py", line 31, in MyModel
    model_name = params['model_name']
KeyError: 'model_name'
[W 2023-11-21 15:54:07,153] Trial 38 failed with value None.
[W 2023-11-21 15:54:05,286] Trial 32 failed with parameters: {'model_name': 'SimpleImputer', 'strategy': 'mean'} because of the following error: KeyError('model_name').
Traceback (most recent call last):
  File "/home/ketrong/miniconda3/envs/tpot2devenv/lib/python3.10/site-packages/optuna/study/_optimize.py", line 200, in _run_trial
    value_or_values = func(trial)
  File "/common/ketrong/AutoImputeExp/tpot2_imputetest/Impute_Experiments/autoimpute.py", line 57, in obj
    my_model = autoutils.MyModel(random_state = self.random_state, **my_params)
  File "/common/ketrong/AutoImputeExp/tpot2_imputetest/Impute_Experiments/autoutils.py", line 31, in MyModel
    model_name = params['model_name']
KeyError: 'model_name'
[W 2023-11-21 15:54:07,294] Trial 32 failed with value None.
[W 2023-11-21 15:54:06,290] Trial 40 failed with parameters: {'model_name': 'SimpleImputer', 'strategy': 'median'} because of the following error: KeyError('model_name').
Traceback (most recent call last):
  File "/home/ketrong/miniconda3/envs/tpot2devenv/lib/python3.10/site-packages/optuna/study/_optimize.py", line 200, in _run_trial
    value_or_values = func(trial)
  File "/common/ketrong/AutoImputeExp/tpot2_imputetest/Impute_Experiments/autoimpute.py", line 57, in obj
    my_model = autoutils.MyModel(random_state = self.random_state, **my_params)
  File "/common/ketrong/AutoImputeExp/tpot2_imputetest/Impute_Experiments/autoutils.py", line 31, in MyModel
    model_name = params['model_name']
KeyError: 'model_name'
[W 2023-11-21 15:54:07,438] Trial 40 failed with value None.
[W 2023-11-21 15:54:04,995] Trial 28 failed with parameters: {'model_name': 'SimpleImputer', 'strategy': 'constant'} because of the following error: KeyError('model_name').
Traceback (most recent call last):
  File "/home/ketrong/miniconda3/envs/tpot2devenv/lib/python3.10/site-packages/optuna/study/_optimize.py", line 200, in _run_trial
    value_or_values = func(trial)
  File "/common/ketrong/AutoImputeExp/tpot2_imputetest/Impute_Experiments/autoimpute.py", line 57, in obj
    my_model = autoutils.MyModel(random_state = self.random_state, **my_params)
  File "/common/ketrong/AutoImputeExp/tpot2_imputetest/Impute_Experiments/autoutils.py", line 31, in MyModel
    model_name = params['model_name']
KeyError: 'model_name'
[W 2023-11-21 15:54:07,579] Trial 28 failed with value None.
[W 2023-11-21 15:54:05,859] Trial 35 failed with parameters: {'model_name': 'SimpleImputer', 'strategy': 'most_frequent'} because of the following error: KeyError('model_name').
Traceback (most recent call last):
  File "/home/ketrong/miniconda3/envs/tpot2devenv/lib/python3.10/site-packages/optuna/study/_optimize.py", line 200, in _run_trial
    value_or_values = func(trial)
  File "/common/ketrong/AutoImputeExp/tpot2_imputetest/Impute_Experiments/autoimpute.py", line 57, in obj
    my_model = autoutils.MyModel(random_state = self.random_state, **my_params)
  File "/common/ketrong/AutoImputeExp/tpot2_imputetest/Impute_Experiments/autoutils.py", line 31, in MyModel
    model_name = params['model_name']
KeyError: 'model_name'
[W 2023-11-21 15:54:07,723] Trial 35 failed with value None.
[W 2023-11-21 15:54:06,001] Trial 36 failed with parameters: {'model_name': 'SimpleImputer', 'strategy': 'mean'} because of the following error: KeyError('model_name').
Traceback (most recent call last):
  File "/home/ketrong/miniconda3/envs/tpot2devenv/lib/python3.10/site-packages/optuna/study/_optimize.py", line 200, in _run_trial
    value_or_values = func(trial)
  File "/common/ketrong/AutoImputeExp/tpot2_imputetest/Impute_Experiments/autoimpute.py", line 57, in obj
    my_model = autoutils.MyModel(random_state = self.random_state, **my_params)
  File "/common/ketrong/AutoImputeExp/tpot2_imputetest/Impute_Experiments/autoutils.py", line 31, in MyModel
    model_name = params['model_name']
KeyError: 'model_name'
[W 2023-11-21 15:54:07,864] Trial 36 failed with value None.
[W 2023-11-21 15:54:04,998] Trial 31 failed with parameters: {'model_name': 'SimpleImputer', 'strategy': 'median'} because of the following error: KeyError('model_name').
Traceback (most recent call last):
  File "/home/ketrong/miniconda3/envs/tpot2devenv/lib/python3.10/site-packages/optuna/study/_optimize.py", line 200, in _run_trial
    value_or_values = func(trial)
  File "/common/ketrong/AutoImputeExp/tpot2_imputetest/Impute_Experiments/autoimpute.py", line 57, in obj
    my_model = autoutils.MyModel(random_state = self.random_state, **my_params)
  File "/common/ketrong/AutoImputeExp/tpot2_imputetest/Impute_Experiments/autoutils.py", line 31, in MyModel
    model_name = params['model_name']
KeyError: 'model_name'
[W 2023-11-21 15:54:08,006] Trial 31 failed with value None.
[W 2023-11-21 15:54:07,153] Trial 44 failed with parameters: {'model_name': 'SimpleImputer', 'strategy': 'constant'} because of the following error: KeyError('model_name').
Traceback (most recent call last):
  File "/home/ketrong/miniconda3/envs/tpot2devenv/lib/python3.10/site-packages/optuna/study/_optimize.py", line 200, in _run_trial
    value_or_values = func(trial)
  File "/common/ketrong/AutoImputeExp/tpot2_imputetest/Impute_Experiments/autoimpute.py", line 57, in obj
    my_model = autoutils.MyModel(random_state = self.random_state, **my_params)
  File "/common/ketrong/AutoImputeExp/tpot2_imputetest/Impute_Experiments/autoutils.py", line 31, in MyModel
    model_name = params['model_name']
KeyError: 'model_name'
[W 2023-11-21 15:54:08,149] Trial 44 failed with value None.
[W 2023-11-21 15:54:04,563] Trial 25 failed with parameters: {'model_name': 'SimpleImputer', 'strategy': 'most_frequent'} because of the following error: KeyError('model_name').
Traceback (most recent call last):
  File "/home/ketrong/miniconda3/envs/tpot2devenv/lib/python3.10/site-packages/optuna/study/_optimize.py", line 200, in _run_trial
    value_or_values = func(trial)
  File "/common/ketrong/AutoImputeExp/tpot2_imputetest/Impute_Experiments/autoimpute.py", line 57, in obj
    my_model = autoutils.MyModel(random_state = self.random_state, **my_params)
  File "/common/ketrong/AutoImputeExp/tpot2_imputetest/Impute_Experiments/autoutils.py", line 31, in MyModel
    model_name = params['model_name']
KeyError: 'model_name'
[W 2023-11-21 15:54:08,292] Trial 25 failed with value None.
[W 2023-11-21 15:54:07,579] Trial 45 failed with parameters: {'model_name': 'SimpleImputer', 'strategy': 'most_frequent'} because of the following error: KeyError('model_name').
Traceback (most recent call last):
  File "/home/ketrong/miniconda3/envs/tpot2devenv/lib/python3.10/site-packages/optuna/study/_optimize.py", line 200, in _run_trial
    value_or_values = func(trial)
  File "/common/ketrong/AutoImputeExp/tpot2_imputetest/Impute_Experiments/autoimpute.py", line 57, in obj
    my_model = autoutils.MyModel(random_state = self.random_state, **my_params)
  File "/common/ketrong/AutoImputeExp/tpot2_imputetest/Impute_Experiments/autoutils.py", line 31, in MyModel
    model_name = params['model_name']
KeyError: 'model_name'
[W 2023-11-21 15:54:08,435] Trial 45 failed with value None.
[W 2023-11-21 15:54:06,859] Trial 41 failed with parameters: {'model_name': 'SimpleImputer', 'strategy': 'most_frequent'} because of the following error: KeyError('model_name').
Traceback (most recent call last):
  File "/home/ketrong/miniconda3/envs/tpot2devenv/lib/python3.10/site-packages/optuna/study/_optimize.py", line 200, in _run_trial
    value_or_values = func(trial)
  File "/common/ketrong/AutoImputeExp/tpot2_imputetest/Impute_Experiments/autoimpute.py", line 57, in obj
    my_model = autoutils.MyModel(random_state = self.random_state, **my_params)
  File "/common/ketrong/AutoImputeExp/tpot2_imputetest/Impute_Experiments/autoutils.py", line 31, in MyModel
    model_name = params['model_name']
KeyError: 'model_name'
[W 2023-11-21 15:54:08,576] Trial 41 failed with value None.
[W 2023-11-21 15:54:06,863] Trial 42 failed with parameters: {'model_name': 'SimpleImputer', 'strategy': 'median'} because of the following error: KeyError('model_name').
Traceback (most recent call last):
  File "/home/ketrong/miniconda3/envs/tpot2devenv/lib/python3.10/site-packages/optuna/study/_optimize.py", line 200, in _run_trial
    value_or_values = func(trial)
  File "/common/ketrong/AutoImputeExp/tpot2_imputetest/Impute_Experiments/autoimpute.py", line 57, in obj
    my_model = autoutils.MyModel(random_state = self.random_state, **my_params)
  File "/common/ketrong/AutoImputeExp/tpot2_imputetest/Impute_Experiments/autoutils.py", line 31, in MyModel
    model_name = params['model_name']
KeyError: 'model_name'
[W 2023-11-21 15:54:08,718] Trial 42 failed with value None.
[W 2023-11-21 15:54:06,289] Trial 39 failed with parameters: {'model_name': 'SimpleImputer', 'strategy': 'median'} because of the following error: KeyError('model_name').
Traceback (most recent call last):
  File "/home/ketrong/miniconda3/envs/tpot2devenv/lib/python3.10/site-packages/optuna/study/_optimize.py", line 200, in _run_trial
    value_or_values = func(trial)
  File "/common/ketrong/AutoImputeExp/tpot2_imputetest/Impute_Experiments/autoimpute.py", line 57, in obj
    my_model = autoutils.MyModel(random_state = self.random_state, **my_params)
  File "/common/ketrong/AutoImputeExp/tpot2_imputetest/Impute_Experiments/autoutils.py", line 31, in MyModel
    model_name = params['model_name']
KeyError: 'model_name'
[W 2023-11-21 15:54:08,860] Trial 39 failed with value None.
[W 2023-11-21 15:54:07,579] Trial 46 failed with parameters: {'model_name': 'SimpleImputer', 'strategy': 'median'} because of the following error: KeyError('model_name').
Traceback (most recent call last):
  File "/home/ketrong/miniconda3/envs/tpot2devenv/lib/python3.10/site-packages/optuna/study/_optimize.py", line 200, in _run_trial
    value_or_values = func(trial)
  File "/common/ketrong/AutoImputeExp/tpot2_imputetest/Impute_Experiments/autoimpute.py", line 57, in obj
    my_model = autoutils.MyModel(random_state = self.random_state, **my_params)
  File "/common/ketrong/AutoImputeExp/tpot2_imputetest/Impute_Experiments/autoutils.py", line 31, in MyModel
    model_name = params['model_name']
KeyError: 'model_name'
[W 2023-11-21 15:54:09,003] Trial 46 failed with value None.
[W 2023-11-21 15:54:04,853] Trial 27 failed with parameters: {'model_name': 'SimpleImputer', 'strategy': 'median'} because of the following error: KeyError('model_name').
Traceback (most recent call last):
  File "/home/ketrong/miniconda3/envs/tpot2devenv/lib/python3.10/site-packages/optuna/study/_optimize.py", line 200, in _run_trial
    value_or_values = func(trial)
  File "/common/ketrong/AutoImputeExp/tpot2_imputetest/Impute_Experiments/autoimpute.py", line 57, in obj
    my_model = autoutils.MyModel(random_state = self.random_state, **my_params)
  File "/common/ketrong/AutoImputeExp/tpot2_imputetest/Impute_Experiments/autoutils.py", line 31, in MyModel
    model_name = params['model_name']
KeyError: 'model_name'
[W 2023-11-21 15:54:09,144] Trial 27 failed with value None.
[W 2023-11-21 15:54:07,153] Trial 43 failed with parameters: {'model_name': 'SimpleImputer', 'strategy': 'median'} because of the following error: KeyError('model_name').
Traceback (most recent call last):
  File "/home/ketrong/miniconda3/envs/tpot2devenv/lib/python3.10/site-packages/optuna/study/_optimize.py", line 200, in _run_trial
    value_or_values = func(trial)
  File "/common/ketrong/AutoImputeExp/tpot2_imputetest/Impute_Experiments/autoimpute.py", line 57, in obj
    my_model = autoutils.MyModel(random_state = self.random_state, **my_params)
  File "/common/ketrong/AutoImputeExp/tpot2_imputetest/Impute_Experiments/autoutils.py", line 31, in MyModel
    model_name = params['model_name']
KeyError: 'model_name'
[W 2023-11-21 15:54:09,287] Trial 43 failed with value None.
[W 2023-11-21 15:54:07,722] Trial 47 failed with parameters: {'model_name': 'SimpleImputer', 'strategy': 'median'} because of the following error: KeyError('model_name').
Traceback (most recent call last):
  File "/home/ketrong/miniconda3/envs/tpot2devenv/lib/python3.10/site-packages/optuna/study/_optimize.py", line 200, in _run_trial
    value_or_values = func(trial)
  File "/common/ketrong/AutoImputeExp/tpot2_imputetest/Impute_Experiments/autoimpute.py", line 57, in obj
    my_model = autoutils.MyModel(random_state = self.random_state, **my_params)
  File "/common/ketrong/AutoImputeExp/tpot2_imputetest/Impute_Experiments/autoutils.py", line 31, in MyModel
    model_name = params['model_name']
KeyError: 'model_name'
[W 2023-11-21 15:54:09,431] Trial 47 failed with value None.
failed on 
tpot2_imputetest/Impute_Experiments/logs//tpot2_base_imputation_6_0.01_MCAR_2
'model_name'
Traceback (most recent call last):
  File "/common/ketrong/AutoImputeExp/tpot2_imputetest/Impute_Experiments/utils.py", line 169, in loop_through_tasks
    SimpleImputeSpace.fit(X_train_pandas)
  File "/common/ketrong/AutoImputeExp/tpot2_imputetest/Impute_Experiments/autoimpute.py", line 60, in fit
    self.study.optimize(obj, n_trials=self.n_trials, n_jobs=self.n_jobs, show_progress_bar=self.show_progress, gc_after_trial=self.garbage_collect)
  File "/home/ketrong/miniconda3/envs/tpot2devenv/lib/python3.10/site-packages/optuna/study/study.py", line 451, in optimize
    _optimize(
  File "/home/ketrong/miniconda3/envs/tpot2devenv/lib/python3.10/site-packages/optuna/study/_optimize.py", line 103, in _optimize
    f.result()
  File "/home/ketrong/miniconda3/envs/tpot2devenv/lib/python3.10/concurrent/futures/_base.py", line 451, in result
    return self.__get_result()
  File "/home/ketrong/miniconda3/envs/tpot2devenv/lib/python3.10/concurrent/futures/_base.py", line 403, in __get_result
    raise self._exception
  File "/home/ketrong/miniconda3/envs/tpot2devenv/lib/python3.10/concurrent/futures/thread.py", line 58, in run
    result = self.fn(*self.args, **self.kwargs)
  File "/home/ketrong/miniconda3/envs/tpot2devenv/lib/python3.10/site-packages/optuna/study/_optimize.py", line 163, in _optimize_sequential
    frozen_trial = _run_trial(study, func, catch)
  File "/home/ketrong/miniconda3/envs/tpot2devenv/lib/python3.10/site-packages/optuna/study/_optimize.py", line 251, in _run_trial
    raise func_err
  File "/home/ketrong/miniconda3/envs/tpot2devenv/lib/python3.10/site-packages/optuna/study/_optimize.py", line 200, in _run_trial
    value_or_values = func(trial)
  File "/common/ketrong/AutoImputeExp/tpot2_imputetest/Impute_Experiments/autoimpute.py", line 57, in obj
    my_model = autoutils.MyModel(random_state = self.random_state, **my_params)
  File "/common/ketrong/AutoImputeExp/tpot2_imputetest/Impute_Experiments/autoutils.py", line 31, in MyModel
    model_name = params['model_name']
KeyError: 'model_name'

DONE
