/cm/local/apps/slurm/var/spool/job403167/slurm_script: line 19: /common/ketrong/minconda3/etc/profile.d/conda.sh: No such file or directory
/cm/local/apps/slurm/var/spool/job403167/slurm_script: line 22: $'\nconda create --name tpot2devenv -c conda-forge python=3.10\n': command not found
/cm/local/apps/slurm/var/spool/job403167/slurm_script: line 27: $'\npip install -r requirements.txt\n': command not found
RunStart
2023-11-21 15:51:30.170840: I tensorflow/core/util/port.cc:113] oneDNN custom operations are on. You may see slightly different numerical results due to floating-point round-off errors from different computation orders. To turn them off, set the environment variable `TF_ENABLE_ONEDNN_OPTS=0`.
2023-11-21 15:51:30.205466: E external/local_xla/xla/stream_executor/cuda/cuda_dnn.cc:9261] Unable to register cuDNN factory: Attempting to register factory for plugin cuDNN when one has already been registered
2023-11-21 15:51:30.205490: E external/local_xla/xla/stream_executor/cuda/cuda_fft.cc:607] Unable to register cuFFT factory: Attempting to register factory for plugin cuFFT when one has already been registered
2023-11-21 15:51:30.206608: E external/local_xla/xla/stream_executor/cuda/cuda_blas.cc:1515] Unable to register cuBLAS factory: Attempting to register factory for plugin cuBLAS when one has already been registered
2023-11-21 15:51:30.212242: I tensorflow/core/platform/cpu_feature_guard.cc:182] This TensorFlow binary is optimized to use available CPU instructions in performance-critical operations.
To enable the following instructions: AVX2 AVX512F AVX512_VNNI FMA, in other operations, rebuild TensorFlow with the appropriate compiler flags.
2023-11-21 15:51:32.355026: W tensorflow/compiler/tf2tensorrt/utils/py_utils.cc:38] TF-TRT Warning: Could not find TensorRT
WARNING:tensorflow:From /home/ketrong/miniconda3/envs/tpot2devenv/lib/python3.10/site-packages/tensorflow/python/compat/v2_compat.py:108: disable_resource_variables (from tensorflow.python.ops.variable_scope) is deprecated and will be removed in a future version.
Instructions for updating:
non-resource variables are not supported in the long term
working on 
tpot2_imputetest/Impute_Experiments/logs//tpot2_base_normal_6_0.01_MCAR_2
loading data
tpot2_imputetest/Impute_Experiments/data/6_True.pkl
running experiment 1/3 - Does large hyperparameter space improve reconstruction accuracy over simple
[I 2023-11-21 15:53:48,903] A new study created in memory with name: no-name-eb9fdfc2-136a-4599-9a7b-617e667485c5
[W 2023-11-21 15:53:48,906] Trial 0 failed with parameters: {'model_name': 'SimpleImputer', 'strategy': 'median'} because of the following error: KeyError('model_name').
Traceback (most recent call last):
  File "/home/ketrong/miniconda3/envs/tpot2devenv/lib/python3.10/site-packages/optuna/study/_optimize.py", line 200, in _run_trial
    value_or_values = func(trial)
  File "/common/ketrong/AutoImputeExp/tpot2_imputetest/Impute_Experiments/autoimpute.py", line 57, in obj
    my_model = autoutils.MyModel(random_state = self.random_state, **my_params)
  File "/common/ketrong/AutoImputeExp/tpot2_imputetest/Impute_Experiments/autoutils.py", line 31, in MyModel
    model_name = params['model_name']
KeyError: 'model_name'
[W 2023-11-21 15:53:48,919] Trial 0 failed with value None.
[W 2023-11-21 15:53:48,908] Trial 2 failed with parameters: {'model_name': 'SimpleImputer', 'strategy': 'constant'} because of the following error: KeyError('model_name').
Traceback (most recent call last):
  File "/home/ketrong/miniconda3/envs/tpot2devenv/lib/python3.10/site-packages/optuna/study/_optimize.py", line 200, in _run_trial
    value_or_values = func(trial)
  File "/common/ketrong/AutoImputeExp/tpot2_imputetest/Impute_Experiments/autoimpute.py", line 57, in obj
    my_model = autoutils.MyModel(random_state = self.random_state, **my_params)
  File "/common/ketrong/AutoImputeExp/tpot2_imputetest/Impute_Experiments/autoutils.py", line 31, in MyModel
    model_name = params['model_name']
KeyError: 'model_name'
[W 2023-11-21 15:53:49,169] Trial 2 failed with value None.
[W 2023-11-21 15:53:48,908] Trial 3 failed with parameters: {'model_name': 'SimpleImputer', 'strategy': 'constant'} because of the following error: KeyError('model_name').
Traceback (most recent call last):
  File "/home/ketrong/miniconda3/envs/tpot2devenv/lib/python3.10/site-packages/optuna/study/_optimize.py", line 200, in _run_trial
    value_or_values = func(trial)
  File "/common/ketrong/AutoImputeExp/tpot2_imputetest/Impute_Experiments/autoimpute.py", line 57, in obj
    my_model = autoutils.MyModel(random_state = self.random_state, **my_params)
  File "/common/ketrong/AutoImputeExp/tpot2_imputetest/Impute_Experiments/autoutils.py", line 31, in MyModel
    model_name = params['model_name']
KeyError: 'model_name'
[W 2023-11-21 15:53:49,385] Trial 3 failed with value None.
[W 2023-11-21 15:53:48,913] Trial 6 failed with parameters: {'model_name': 'SimpleImputer', 'strategy': 'mean'} because of the following error: KeyError('model_name').
Traceback (most recent call last):
  File "/home/ketrong/miniconda3/envs/tpot2devenv/lib/python3.10/site-packages/optuna/study/_optimize.py", line 200, in _run_trial
    value_or_values = func(trial)
  File "/common/ketrong/AutoImputeExp/tpot2_imputetest/Impute_Experiments/autoimpute.py", line 57, in obj
    my_model = autoutils.MyModel(random_state = self.random_state, **my_params)
  File "/common/ketrong/AutoImputeExp/tpot2_imputetest/Impute_Experiments/autoutils.py", line 31, in MyModel
    model_name = params['model_name']
KeyError: 'model_name'
[W 2023-11-21 15:53:49,602] Trial 6 failed with value None.
[W 2023-11-21 15:53:48,913] Trial 7 failed with parameters: {'model_name': 'SimpleImputer', 'strategy': 'mean'} because of the following error: KeyError('model_name').
Traceback (most recent call last):
  File "/home/ketrong/miniconda3/envs/tpot2devenv/lib/python3.10/site-packages/optuna/study/_optimize.py", line 200, in _run_trial
    value_or_values = func(trial)
  File "/common/ketrong/AutoImputeExp/tpot2_imputetest/Impute_Experiments/autoimpute.py", line 57, in obj
    my_model = autoutils.MyModel(random_state = self.random_state, **my_params)
  File "/common/ketrong/AutoImputeExp/tpot2_imputetest/Impute_Experiments/autoutils.py", line 31, in MyModel
    model_name = params['model_name']
KeyError: 'model_name'
[W 2023-11-21 15:53:49,813] Trial 7 failed with value None.
[W 2023-11-21 15:53:48,916] Trial 8 failed with parameters: {'model_name': 'SimpleImputer', 'strategy': 'most_frequent'} because of the following error: KeyError('model_name').
Traceback (most recent call last):
  File "/home/ketrong/miniconda3/envs/tpot2devenv/lib/python3.10/site-packages/optuna/study/_optimize.py", line 200, in _run_trial
    value_or_values = func(trial)
  File "/common/ketrong/AutoImputeExp/tpot2_imputetest/Impute_Experiments/autoimpute.py", line 57, in obj
    my_model = autoutils.MyModel(random_state = self.random_state, **my_params)
  File "/common/ketrong/AutoImputeExp/tpot2_imputetest/Impute_Experiments/autoutils.py", line 31, in MyModel
    model_name = params['model_name']
KeyError: 'model_name'
[W 2023-11-21 15:53:50,026] Trial 8 failed with value None.
[W 2023-11-21 15:53:48,918] Trial 11 failed with parameters: {'model_name': 'SimpleImputer', 'strategy': 'constant'} because of the following error: KeyError('model_name').
Traceback (most recent call last):
  File "/home/ketrong/miniconda3/envs/tpot2devenv/lib/python3.10/site-packages/optuna/study/_optimize.py", line 200, in _run_trial
    value_or_values = func(trial)
  File "/common/ketrong/AutoImputeExp/tpot2_imputetest/Impute_Experiments/autoimpute.py", line 57, in obj
    my_model = autoutils.MyModel(random_state = self.random_state, **my_params)
  File "/common/ketrong/AutoImputeExp/tpot2_imputetest/Impute_Experiments/autoutils.py", line 31, in MyModel
    model_name = params['model_name']
KeyError: 'model_name'
[W 2023-11-21 15:53:50,239] Trial 11 failed with value None.
[W 2023-11-21 15:53:49,169] Trial 13 failed with parameters: {'model_name': 'SimpleImputer', 'strategy': 'constant'} because of the following error: KeyError('model_name').
Traceback (most recent call last):
  File "/home/ketrong/miniconda3/envs/tpot2devenv/lib/python3.10/site-packages/optuna/study/_optimize.py", line 200, in _run_trial
    value_or_values = func(trial)
  File "/common/ketrong/AutoImputeExp/tpot2_imputetest/Impute_Experiments/autoimpute.py", line 57, in obj
    my_model = autoutils.MyModel(random_state = self.random_state, **my_params)
  File "/common/ketrong/AutoImputeExp/tpot2_imputetest/Impute_Experiments/autoutils.py", line 31, in MyModel
    model_name = params['model_name']
KeyError: 'model_name'
[W 2023-11-21 15:53:50,456] Trial 13 failed with value None.
[W 2023-11-21 15:53:48,910] Trial 4 failed with parameters: {'model_name': 'SimpleImputer', 'strategy': 'mean'} because of the following error: KeyError('model_name').
Traceback (most recent call last):
  File "/home/ketrong/miniconda3/envs/tpot2devenv/lib/python3.10/site-packages/optuna/study/_optimize.py", line 200, in _run_trial
    value_or_values = func(trial)
  File "/common/ketrong/AutoImputeExp/tpot2_imputetest/Impute_Experiments/autoimpute.py", line 57, in obj
    my_model = autoutils.MyModel(random_state = self.random_state, **my_params)
  File "/common/ketrong/AutoImputeExp/tpot2_imputetest/Impute_Experiments/autoutils.py", line 31, in MyModel
    model_name = params['model_name']
KeyError: 'model_name'
[W 2023-11-21 15:53:50,669] Trial 4 failed with value None.
[W 2023-11-21 15:53:49,387] Trial 14 failed with parameters: {'model_name': 'SimpleImputer', 'strategy': 'constant'} because of the following error: KeyError('model_name').
Traceback (most recent call last):
  File "/home/ketrong/miniconda3/envs/tpot2devenv/lib/python3.10/site-packages/optuna/study/_optimize.py", line 200, in _run_trial
    value_or_values = func(trial)
  File "/common/ketrong/AutoImputeExp/tpot2_imputetest/Impute_Experiments/autoimpute.py", line 57, in obj
    my_model = autoutils.MyModel(random_state = self.random_state, **my_params)
  File "/common/ketrong/AutoImputeExp/tpot2_imputetest/Impute_Experiments/autoutils.py", line 31, in MyModel
    model_name = params['model_name']
KeyError: 'model_name'
[W 2023-11-21 15:53:50,888] Trial 14 failed with value None.
[W 2023-11-21 15:53:48,917] Trial 10 failed with parameters: {'model_name': 'SimpleImputer', 'strategy': 'most_frequent'} because of the following error: KeyError('model_name').
Traceback (most recent call last):
  File "/home/ketrong/miniconda3/envs/tpot2devenv/lib/python3.10/site-packages/optuna/study/_optimize.py", line 200, in _run_trial
    value_or_values = func(trial)
  File "/common/ketrong/AutoImputeExp/tpot2_imputetest/Impute_Experiments/autoimpute.py", line 57, in obj
    my_model = autoutils.MyModel(random_state = self.random_state, **my_params)
  File "/common/ketrong/AutoImputeExp/tpot2_imputetest/Impute_Experiments/autoutils.py", line 31, in MyModel
    model_name = params['model_name']
KeyError: 'model_name'
[W 2023-11-21 15:53:51,102] Trial 10 failed with value None.
[W 2023-11-21 15:53:50,025] Trial 17 failed with parameters: {'model_name': 'SimpleImputer', 'strategy': 'median'} because of the following error: KeyError('model_name').
Traceback (most recent call last):
  File "/home/ketrong/miniconda3/envs/tpot2devenv/lib/python3.10/site-packages/optuna/study/_optimize.py", line 200, in _run_trial
    value_or_values = func(trial)
  File "/common/ketrong/AutoImputeExp/tpot2_imputetest/Impute_Experiments/autoimpute.py", line 57, in obj
    my_model = autoutils.MyModel(random_state = self.random_state, **my_params)
  File "/common/ketrong/AutoImputeExp/tpot2_imputetest/Impute_Experiments/autoutils.py", line 31, in MyModel
    model_name = params['model_name']
KeyError: 'model_name'
[W 2023-11-21 15:53:51,315] Trial 17 failed with value None.
[W 2023-11-21 15:53:48,919] Trial 12 failed with parameters: {'model_name': 'SimpleImputer', 'strategy': 'mean'} because of the following error: KeyError('model_name').
Traceback (most recent call last):
  File "/home/ketrong/miniconda3/envs/tpot2devenv/lib/python3.10/site-packages/optuna/study/_optimize.py", line 200, in _run_trial
    value_or_values = func(trial)
  File "/common/ketrong/AutoImputeExp/tpot2_imputetest/Impute_Experiments/autoimpute.py", line 57, in obj
    my_model = autoutils.MyModel(random_state = self.random_state, **my_params)
  File "/common/ketrong/AutoImputeExp/tpot2_imputetest/Impute_Experiments/autoutils.py", line 31, in MyModel
    model_name = params['model_name']
KeyError: 'model_name'
[W 2023-11-21 15:53:51,531] Trial 12 failed with value None.
[W 2023-11-21 15:53:50,238] Trial 19 failed with parameters: {'model_name': 'SimpleImputer', 'strategy': 'most_frequent'} because of the following error: KeyError('model_name').
Traceback (most recent call last):
  File "/home/ketrong/miniconda3/envs/tpot2devenv/lib/python3.10/site-packages/optuna/study/_optimize.py", line 200, in _run_trial
    value_or_values = func(trial)
  File "/common/ketrong/AutoImputeExp/tpot2_imputetest/Impute_Experiments/autoimpute.py", line 57, in obj
    my_model = autoutils.MyModel(random_state = self.random_state, **my_params)
  File "/common/ketrong/AutoImputeExp/tpot2_imputetest/Impute_Experiments/autoutils.py", line 31, in MyModel
    model_name = params['model_name']
KeyError: 'model_name'
[W 2023-11-21 15:53:51,747] Trial 19 failed with value None.
[W 2023-11-21 15:53:50,240] Trial 20 failed with parameters: {'model_name': 'SimpleImputer', 'strategy': 'median'} because of the following error: KeyError('model_name').
Traceback (most recent call last):
  File "/home/ketrong/miniconda3/envs/tpot2devenv/lib/python3.10/site-packages/optuna/study/_optimize.py", line 200, in _run_trial
    value_or_values = func(trial)
  File "/common/ketrong/AutoImputeExp/tpot2_imputetest/Impute_Experiments/autoimpute.py", line 57, in obj
    my_model = autoutils.MyModel(random_state = self.random_state, **my_params)
  File "/common/ketrong/AutoImputeExp/tpot2_imputetest/Impute_Experiments/autoutils.py", line 31, in MyModel
    model_name = params['model_name']
KeyError: 'model_name'
[W 2023-11-21 15:53:51,957] Trial 20 failed with value None.
[W 2023-11-21 15:53:48,911] Trial 5 failed with parameters: {'model_name': 'SimpleImputer', 'strategy': 'most_frequent'} because of the following error: KeyError('model_name').
Traceback (most recent call last):
  File "/home/ketrong/miniconda3/envs/tpot2devenv/lib/python3.10/site-packages/optuna/study/_optimize.py", line 200, in _run_trial
    value_or_values = func(trial)
  File "/common/ketrong/AutoImputeExp/tpot2_imputetest/Impute_Experiments/autoimpute.py", line 57, in obj
    my_model = autoutils.MyModel(random_state = self.random_state, **my_params)
  File "/common/ketrong/AutoImputeExp/tpot2_imputetest/Impute_Experiments/autoutils.py", line 31, in MyModel
    model_name = params['model_name']
KeyError: 'model_name'
[W 2023-11-21 15:53:52,172] Trial 5 failed with value None.
[W 2023-11-21 15:53:50,668] Trial 23 failed with parameters: {'model_name': 'SimpleImputer', 'strategy': 'most_frequent'} because of the following error: KeyError('model_name').
Traceback (most recent call last):
  File "/home/ketrong/miniconda3/envs/tpot2devenv/lib/python3.10/site-packages/optuna/study/_optimize.py", line 200, in _run_trial
    value_or_values = func(trial)
  File "/common/ketrong/AutoImputeExp/tpot2_imputetest/Impute_Experiments/autoimpute.py", line 57, in obj
    my_model = autoutils.MyModel(random_state = self.random_state, **my_params)
  File "/common/ketrong/AutoImputeExp/tpot2_imputetest/Impute_Experiments/autoutils.py", line 31, in MyModel
    model_name = params['model_name']
KeyError: 'model_name'
[W 2023-11-21 15:53:52,389] Trial 23 failed with value None.
[W 2023-11-21 15:53:48,915] Trial 9 failed with parameters: {'model_name': 'SimpleImputer', 'strategy': 'most_frequent'} because of the following error: KeyError('model_name').
Traceback (most recent call last):
  File "/home/ketrong/miniconda3/envs/tpot2devenv/lib/python3.10/site-packages/optuna/study/_optimize.py", line 200, in _run_trial
    value_or_values = func(trial)
  File "/common/ketrong/AutoImputeExp/tpot2_imputetest/Impute_Experiments/autoimpute.py", line 57, in obj
    my_model = autoutils.MyModel(random_state = self.random_state, **my_params)
  File "/common/ketrong/AutoImputeExp/tpot2_imputetest/Impute_Experiments/autoutils.py", line 31, in MyModel
    model_name = params['model_name']
KeyError: 'model_name'
[W 2023-11-21 15:53:52,602] Trial 9 failed with value None.
[W 2023-11-21 15:53:51,101] Trial 25 failed with parameters: {'model_name': 'SimpleImputer', 'strategy': 'median'} because of the following error: KeyError('model_name').
Traceback (most recent call last):
  File "/home/ketrong/miniconda3/envs/tpot2devenv/lib/python3.10/site-packages/optuna/study/_optimize.py", line 200, in _run_trial
    value_or_values = func(trial)
  File "/common/ketrong/AutoImputeExp/tpot2_imputetest/Impute_Experiments/autoimpute.py", line 57, in obj
    my_model = autoutils.MyModel(random_state = self.random_state, **my_params)
  File "/common/ketrong/AutoImputeExp/tpot2_imputetest/Impute_Experiments/autoutils.py", line 31, in MyModel
    model_name = params['model_name']
KeyError: 'model_name'
[W 2023-11-21 15:53:52,813] Trial 25 failed with value None.
[W 2023-11-21 15:53:50,237] Trial 18 failed with parameters: {'model_name': 'SimpleImputer', 'strategy': 'constant'} because of the following error: KeyError('model_name').
Traceback (most recent call last):
  File "/home/ketrong/miniconda3/envs/tpot2devenv/lib/python3.10/site-packages/optuna/study/_optimize.py", line 200, in _run_trial
    value_or_values = func(trial)
  File "/common/ketrong/AutoImputeExp/tpot2_imputetest/Impute_Experiments/autoimpute.py", line 57, in obj
    my_model = autoutils.MyModel(random_state = self.random_state, **my_params)
  File "/common/ketrong/AutoImputeExp/tpot2_imputetest/Impute_Experiments/autoutils.py", line 31, in MyModel
    model_name = params['model_name']
KeyError: 'model_name'
[W 2023-11-21 15:53:53,026] Trial 18 failed with value None.
[W 2023-11-21 15:53:50,456] Trial 21 failed with parameters: {'model_name': 'SimpleImputer', 'strategy': 'constant'} because of the following error: KeyError('model_name').
Traceback (most recent call last):
  File "/home/ketrong/miniconda3/envs/tpot2devenv/lib/python3.10/site-packages/optuna/study/_optimize.py", line 200, in _run_trial
    value_or_values = func(trial)
  File "/common/ketrong/AutoImputeExp/tpot2_imputetest/Impute_Experiments/autoimpute.py", line 57, in obj
    my_model = autoutils.MyModel(random_state = self.random_state, **my_params)
  File "/common/ketrong/AutoImputeExp/tpot2_imputetest/Impute_Experiments/autoutils.py", line 31, in MyModel
    model_name = params['model_name']
KeyError: 'model_name'
[W 2023-11-21 15:53:53,240] Trial 21 failed with value None.
[W 2023-11-21 15:53:50,668] Trial 24 failed with parameters: {'model_name': 'SimpleImputer', 'strategy': 'most_frequent'} because of the following error: KeyError('model_name').
Traceback (most recent call last):
  File "/home/ketrong/miniconda3/envs/tpot2devenv/lib/python3.10/site-packages/optuna/study/_optimize.py", line 200, in _run_trial
    value_or_values = func(trial)
  File "/common/ketrong/AutoImputeExp/tpot2_imputetest/Impute_Experiments/autoimpute.py", line 57, in obj
    my_model = autoutils.MyModel(random_state = self.random_state, **my_params)
  File "/common/ketrong/AutoImputeExp/tpot2_imputetest/Impute_Experiments/autoutils.py", line 31, in MyModel
    model_name = params['model_name']
KeyError: 'model_name'
[W 2023-11-21 15:53:53,450] Trial 24 failed with value None.
[W 2023-11-21 15:53:52,386] Trial 27 failed with parameters: {'model_name': 'SimpleImputer', 'strategy': 'most_frequent'} because of the following error: KeyError('model_name').
Traceback (most recent call last):
  File "/home/ketrong/miniconda3/envs/tpot2devenv/lib/python3.10/site-packages/optuna/study/_optimize.py", line 200, in _run_trial
    value_or_values = func(trial)
  File "/common/ketrong/AutoImputeExp/tpot2_imputetest/Impute_Experiments/autoimpute.py", line 57, in obj
    my_model = autoutils.MyModel(random_state = self.random_state, **my_params)
  File "/common/ketrong/AutoImputeExp/tpot2_imputetest/Impute_Experiments/autoutils.py", line 31, in MyModel
    model_name = params['model_name']
KeyError: 'model_name'
[W 2023-11-21 15:53:53,660] Trial 27 failed with value None.
[W 2023-11-21 15:53:52,601] Trial 29 failed with parameters: {'model_name': 'SimpleImputer', 'strategy': 'constant'} because of the following error: KeyError('model_name').
Traceback (most recent call last):
  File "/home/ketrong/miniconda3/envs/tpot2devenv/lib/python3.10/site-packages/optuna/study/_optimize.py", line 200, in _run_trial
    value_or_values = func(trial)
  File "/common/ketrong/AutoImputeExp/tpot2_imputetest/Impute_Experiments/autoimpute.py", line 57, in obj
    my_model = autoutils.MyModel(random_state = self.random_state, **my_params)
  File "/common/ketrong/AutoImputeExp/tpot2_imputetest/Impute_Experiments/autoutils.py", line 31, in MyModel
    model_name = params['model_name']
KeyError: 'model_name'
[W 2023-11-21 15:53:53,872] Trial 29 failed with value None.
[W 2023-11-21 15:53:50,024] Trial 16 failed with parameters: {'model_name': 'SimpleImputer', 'strategy': 'most_frequent'} because of the following error: KeyError('model_name').
Traceback (most recent call last):
  File "/home/ketrong/miniconda3/envs/tpot2devenv/lib/python3.10/site-packages/optuna/study/_optimize.py", line 200, in _run_trial
    value_or_values = func(trial)
  File "/common/ketrong/AutoImputeExp/tpot2_imputetest/Impute_Experiments/autoimpute.py", line 57, in obj
    my_model = autoutils.MyModel(random_state = self.random_state, **my_params)
  File "/common/ketrong/AutoImputeExp/tpot2_imputetest/Impute_Experiments/autoutils.py", line 31, in MyModel
    model_name = params['model_name']
KeyError: 'model_name'
[W 2023-11-21 15:53:54,085] Trial 16 failed with value None.
[W 2023-11-21 15:53:53,239] Trial 30 failed with parameters: {'model_name': 'SimpleImputer', 'strategy': 'mean'} because of the following error: KeyError('model_name').
Traceback (most recent call last):
  File "/home/ketrong/miniconda3/envs/tpot2devenv/lib/python3.10/site-packages/optuna/study/_optimize.py", line 200, in _run_trial
    value_or_values = func(trial)
  File "/common/ketrong/AutoImputeExp/tpot2_imputetest/Impute_Experiments/autoimpute.py", line 57, in obj
    my_model = autoutils.MyModel(random_state = self.random_state, **my_params)
  File "/common/ketrong/AutoImputeExp/tpot2_imputetest/Impute_Experiments/autoutils.py", line 31, in MyModel
    model_name = params['model_name']
KeyError: 'model_name'
[W 2023-11-21 15:53:54,296] Trial 30 failed with value None.
[W 2023-11-21 15:53:50,667] Trial 22 failed with parameters: {'model_name': 'SimpleImputer', 'strategy': 'median'} because of the following error: KeyError('model_name').
Traceback (most recent call last):
  File "/home/ketrong/miniconda3/envs/tpot2devenv/lib/python3.10/site-packages/optuna/study/_optimize.py", line 200, in _run_trial
    value_or_values = func(trial)
  File "/common/ketrong/AutoImputeExp/tpot2_imputetest/Impute_Experiments/autoimpute.py", line 57, in obj
    my_model = autoutils.MyModel(random_state = self.random_state, **my_params)
  File "/common/ketrong/AutoImputeExp/tpot2_imputetest/Impute_Experiments/autoutils.py", line 31, in MyModel
    model_name = params['model_name']
KeyError: 'model_name'
[W 2023-11-21 15:53:54,505] Trial 22 failed with value None.
[W 2023-11-21 15:53:49,601] Trial 15 failed with parameters: {'model_name': 'SimpleImputer', 'strategy': 'median'} because of the following error: KeyError('model_name').
Traceback (most recent call last):
  File "/home/ketrong/miniconda3/envs/tpot2devenv/lib/python3.10/site-packages/optuna/study/_optimize.py", line 200, in _run_trial
    value_or_values = func(trial)
  File "/common/ketrong/AutoImputeExp/tpot2_imputetest/Impute_Experiments/autoimpute.py", line 57, in obj
    my_model = autoutils.MyModel(random_state = self.random_state, **my_params)
  File "/common/ketrong/AutoImputeExp/tpot2_imputetest/Impute_Experiments/autoutils.py", line 31, in MyModel
    model_name = params['model_name']
KeyError: 'model_name'
[W 2023-11-21 15:53:48,907] Trial 1 failed with parameters: {'model_name': 'SimpleImputer', 'strategy': 'constant'} because of the following error: KeyError('model_name').
Traceback (most recent call last):
  File "/home/ketrong/miniconda3/envs/tpot2devenv/lib/python3.10/site-packages/optuna/study/_optimize.py", line 200, in _run_trial
    value_or_values = func(trial)
  File "/common/ketrong/AutoImputeExp/tpot2_imputetest/Impute_Experiments/autoimpute.py", line 57, in obj
    my_model = autoutils.MyModel(random_state = self.random_state, **my_params)
  File "/common/ketrong/AutoImputeExp/tpot2_imputetest/Impute_Experiments/autoutils.py", line 31, in MyModel
    model_name = params['model_name']
KeyError: 'model_name'
[W 2023-11-21 15:53:54,716] Trial 1 failed with value None.
[W 2023-11-21 15:53:51,747] Trial 26 failed with parameters: {'model_name': 'SimpleImputer', 'strategy': 'most_frequent'} because of the following error: KeyError('model_name').
Traceback (most recent call last):
  File "/home/ketrong/miniconda3/envs/tpot2devenv/lib/python3.10/site-packages/optuna/study/_optimize.py", line 200, in _run_trial
    value_or_values = func(trial)
  File "/common/ketrong/AutoImputeExp/tpot2_imputetest/Impute_Experiments/autoimpute.py", line 57, in obj
    my_model = autoutils.MyModel(random_state = self.random_state, **my_params)
  File "/common/ketrong/AutoImputeExp/tpot2_imputetest/Impute_Experiments/autoutils.py", line 31, in MyModel
    model_name = params['model_name']
KeyError: 'model_name'
[W 2023-11-21 15:53:54,925] Trial 26 failed with value None.
[W 2023-11-21 15:53:53,659] Trial 31 failed with parameters: {'model_name': 'SimpleImputer', 'strategy': 'mean'} because of the following error: KeyError('model_name').
Traceback (most recent call last):
  File "/home/ketrong/miniconda3/envs/tpot2devenv/lib/python3.10/site-packages/optuna/study/_optimize.py", line 200, in _run_trial
    value_or_values = func(trial)
  File "/common/ketrong/AutoImputeExp/tpot2_imputetest/Impute_Experiments/autoimpute.py", line 57, in obj
    my_model = autoutils.MyModel(random_state = self.random_state, **my_params)
  File "/common/ketrong/AutoImputeExp/tpot2_imputetest/Impute_Experiments/autoutils.py", line 31, in MyModel
    model_name = params['model_name']
KeyError: 'model_name'
[W 2023-11-21 15:53:55,139] Trial 31 failed with value None.
[W 2023-11-21 15:53:54,716] Trial 15 failed with value None.
[W 2023-11-21 15:53:52,388] Trial 28 failed with parameters: {'model_name': 'SimpleImputer', 'strategy': 'most_frequent'} because of the following error: KeyError('model_name').
Traceback (most recent call last):
  File "/home/ketrong/miniconda3/envs/tpot2devenv/lib/python3.10/site-packages/optuna/study/_optimize.py", line 200, in _run_trial
    value_or_values = func(trial)
  File "/common/ketrong/AutoImputeExp/tpot2_imputetest/Impute_Experiments/autoimpute.py", line 57, in obj
    my_model = autoutils.MyModel(random_state = self.random_state, **my_params)
  File "/common/ketrong/AutoImputeExp/tpot2_imputetest/Impute_Experiments/autoutils.py", line 31, in MyModel
    model_name = params['model_name']
KeyError: 'model_name'
[W 2023-11-21 15:53:55,561] Trial 28 failed with value None.
[W 2023-11-21 15:53:55,775] Trial 32 failed with parameters: {'model_name': 'SimpleImputer', 'strategy': 'mean'} because of the following error: KeyError('model_name').
Traceback (most recent call last):
  File "/home/ketrong/miniconda3/envs/tpot2devenv/lib/python3.10/site-packages/optuna/study/_optimize.py", line 200, in _run_trial
    value_or_values = func(trial)
  File "/common/ketrong/AutoImputeExp/tpot2_imputetest/Impute_Experiments/autoimpute.py", line 57, in obj
    my_model = autoutils.MyModel(random_state = self.random_state, **my_params)
  File "/common/ketrong/AutoImputeExp/tpot2_imputetest/Impute_Experiments/autoutils.py", line 31, in MyModel
    model_name = params['model_name']
KeyError: 'model_name'
[W 2023-11-21 15:53:55,775] Trial 32 failed with value None.
[W 2023-11-21 15:53:55,984] Trial 33 failed with parameters: {'model_name': 'SimpleImputer', 'strategy': 'constant'} because of the following error: KeyError('model_name').
Traceback (most recent call last):
  File "/home/ketrong/miniconda3/envs/tpot2devenv/lib/python3.10/site-packages/optuna/study/_optimize.py", line 200, in _run_trial
    value_or_values = func(trial)
  File "/common/ketrong/AutoImputeExp/tpot2_imputetest/Impute_Experiments/autoimpute.py", line 57, in obj
    my_model = autoutils.MyModel(random_state = self.random_state, **my_params)
  File "/common/ketrong/AutoImputeExp/tpot2_imputetest/Impute_Experiments/autoutils.py", line 31, in MyModel
    model_name = params['model_name']
KeyError: 'model_name'
[W 2023-11-21 15:53:55,984] Trial 33 failed with value None.
[W 2023-11-21 15:53:56,195] Trial 34 failed with parameters: {'model_name': 'SimpleImputer', 'strategy': 'median'} because of the following error: KeyError('model_name').
Traceback (most recent call last):
  File "/home/ketrong/miniconda3/envs/tpot2devenv/lib/python3.10/site-packages/optuna/study/_optimize.py", line 200, in _run_trial
    value_or_values = func(trial)
  File "/common/ketrong/AutoImputeExp/tpot2_imputetest/Impute_Experiments/autoimpute.py", line 57, in obj
    my_model = autoutils.MyModel(random_state = self.random_state, **my_params)
  File "/common/ketrong/AutoImputeExp/tpot2_imputetest/Impute_Experiments/autoutils.py", line 31, in MyModel
    model_name = params['model_name']
KeyError: 'model_name'
[W 2023-11-21 15:53:56,196] Trial 35 failed with parameters: {'model_name': 'SimpleImputer', 'strategy': 'median'} because of the following error: KeyError('model_name').
Traceback (most recent call last):
  File "/home/ketrong/miniconda3/envs/tpot2devenv/lib/python3.10/site-packages/optuna/study/_optimize.py", line 200, in _run_trial
    value_or_values = func(trial)
  File "/common/ketrong/AutoImputeExp/tpot2_imputetest/Impute_Experiments/autoimpute.py", line 57, in obj
    my_model = autoutils.MyModel(random_state = self.random_state, **my_params)
  File "/common/ketrong/AutoImputeExp/tpot2_imputetest/Impute_Experiments/autoutils.py", line 31, in MyModel
    model_name = params['model_name']
KeyError: 'model_name'
[W 2023-11-21 15:53:56,196] Trial 35 failed with value None.
[W 2023-11-21 15:53:56,196] Trial 34 failed with value None.
[W 2023-11-21 15:53:56,196] Trial 36 failed with parameters: {'model_name': 'SimpleImputer', 'strategy': 'most_frequent'} because of the following error: KeyError('model_name').
Traceback (most recent call last):
  File "/home/ketrong/miniconda3/envs/tpot2devenv/lib/python3.10/site-packages/optuna/study/_optimize.py", line 200, in _run_trial
    value_or_values = func(trial)
  File "/common/ketrong/AutoImputeExp/tpot2_imputetest/Impute_Experiments/autoimpute.py", line 57, in obj
    my_model = autoutils.MyModel(random_state = self.random_state, **my_params)
  File "/common/ketrong/AutoImputeExp/tpot2_imputetest/Impute_Experiments/autoutils.py", line 31, in MyModel
    model_name = params['model_name']
KeyError: 'model_name'
[W 2023-11-21 15:53:56,613] Trial 36 failed with value None.
[W 2023-11-21 15:53:56,613] Trial 37 failed with parameters: {'model_name': 'SimpleImputer', 'strategy': 'most_frequent'} because of the following error: KeyError('model_name').
Traceback (most recent call last):
  File "/home/ketrong/miniconda3/envs/tpot2devenv/lib/python3.10/site-packages/optuna/study/_optimize.py", line 200, in _run_trial
    value_or_values = func(trial)
  File "/common/ketrong/AutoImputeExp/tpot2_imputetest/Impute_Experiments/autoimpute.py", line 57, in obj
    my_model = autoutils.MyModel(random_state = self.random_state, **my_params)
  File "/common/ketrong/AutoImputeExp/tpot2_imputetest/Impute_Experiments/autoutils.py", line 31, in MyModel
    model_name = params['model_name']
KeyError: 'model_name'
[W 2023-11-21 15:53:56,824] Trial 37 failed with value None.
[W 2023-11-21 15:53:56,824] Trial 38 failed with parameters: {'model_name': 'SimpleImputer', 'strategy': 'constant'} because of the following error: KeyError('model_name').
Traceback (most recent call last):
  File "/home/ketrong/miniconda3/envs/tpot2devenv/lib/python3.10/site-packages/optuna/study/_optimize.py", line 200, in _run_trial
    value_or_values = func(trial)
  File "/common/ketrong/AutoImputeExp/tpot2_imputetest/Impute_Experiments/autoimpute.py", line 57, in obj
    my_model = autoutils.MyModel(random_state = self.random_state, **my_params)
  File "/common/ketrong/AutoImputeExp/tpot2_imputetest/Impute_Experiments/autoutils.py", line 31, in MyModel
    model_name = params['model_name']
KeyError: 'model_name'
[W 2023-11-21 15:53:57,034] Trial 38 failed with value None.
[W 2023-11-21 15:53:57,245] Trial 39 failed with parameters: {'model_name': 'SimpleImputer', 'strategy': 'mean'} because of the following error: KeyError('model_name').
Traceback (most recent call last):
  File "/home/ketrong/miniconda3/envs/tpot2devenv/lib/python3.10/site-packages/optuna/study/_optimize.py", line 200, in _run_trial
    value_or_values = func(trial)
  File "/common/ketrong/AutoImputeExp/tpot2_imputetest/Impute_Experiments/autoimpute.py", line 57, in obj
    my_model = autoutils.MyModel(random_state = self.random_state, **my_params)
  File "/common/ketrong/AutoImputeExp/tpot2_imputetest/Impute_Experiments/autoutils.py", line 31, in MyModel
    model_name = params['model_name']
KeyError: 'model_name'
[W 2023-11-21 15:53:57,246] Trial 39 failed with value None.
[W 2023-11-21 15:53:57,459] Trial 40 failed with parameters: {'model_name': 'SimpleImputer', 'strategy': 'constant'} because of the following error: KeyError('model_name').
Traceback (most recent call last):
  File "/home/ketrong/miniconda3/envs/tpot2devenv/lib/python3.10/site-packages/optuna/study/_optimize.py", line 200, in _run_trial
    value_or_values = func(trial)
  File "/common/ketrong/AutoImputeExp/tpot2_imputetest/Impute_Experiments/autoimpute.py", line 57, in obj
    my_model = autoutils.MyModel(random_state = self.random_state, **my_params)
  File "/common/ketrong/AutoImputeExp/tpot2_imputetest/Impute_Experiments/autoutils.py", line 31, in MyModel
    model_name = params['model_name']
KeyError: 'model_name'
[W 2023-11-21 15:53:57,461] Trial 40 failed with value None.
[W 2023-11-21 15:53:57,460] Trial 41 failed with parameters: {'model_name': 'SimpleImputer', 'strategy': 'mean'} because of the following error: KeyError('model_name').
Traceback (most recent call last):
  File "/home/ketrong/miniconda3/envs/tpot2devenv/lib/python3.10/site-packages/optuna/study/_optimize.py", line 200, in _run_trial
    value_or_values = func(trial)
  File "/common/ketrong/AutoImputeExp/tpot2_imputetest/Impute_Experiments/autoimpute.py", line 57, in obj
    my_model = autoutils.MyModel(random_state = self.random_state, **my_params)
  File "/common/ketrong/AutoImputeExp/tpot2_imputetest/Impute_Experiments/autoutils.py", line 31, in MyModel
    model_name = params['model_name']
KeyError: 'model_name'
[W 2023-11-21 15:53:57,676] Trial 41 failed with value None.
[W 2023-11-21 15:53:57,888] Trial 42 failed with parameters: {'model_name': 'SimpleImputer', 'strategy': 'median'} because of the following error: KeyError('model_name').
Traceback (most recent call last):
  File "/home/ketrong/miniconda3/envs/tpot2devenv/lib/python3.10/site-packages/optuna/study/_optimize.py", line 200, in _run_trial
    value_or_values = func(trial)
  File "/common/ketrong/AutoImputeExp/tpot2_imputetest/Impute_Experiments/autoimpute.py", line 57, in obj
    my_model = autoutils.MyModel(random_state = self.random_state, **my_params)
  File "/common/ketrong/AutoImputeExp/tpot2_imputetest/Impute_Experiments/autoutils.py", line 31, in MyModel
    model_name = params['model_name']
KeyError: 'model_name'
[W 2023-11-21 15:53:57,889] Trial 42 failed with value None.
[W 2023-11-21 15:53:58,103] Trial 43 failed with parameters: {'model_name': 'SimpleImputer', 'strategy': 'constant'} because of the following error: KeyError('model_name').
Traceback (most recent call last):
  File "/home/ketrong/miniconda3/envs/tpot2devenv/lib/python3.10/site-packages/optuna/study/_optimize.py", line 200, in _run_trial
    value_or_values = func(trial)
  File "/common/ketrong/AutoImputeExp/tpot2_imputetest/Impute_Experiments/autoimpute.py", line 57, in obj
    my_model = autoutils.MyModel(random_state = self.random_state, **my_params)
  File "/common/ketrong/AutoImputeExp/tpot2_imputetest/Impute_Experiments/autoutils.py", line 31, in MyModel
    model_name = params['model_name']
KeyError: 'model_name'
[W 2023-11-21 15:53:58,104] Trial 43 failed with value None.
[W 2023-11-21 15:53:58,313] Trial 44 failed with parameters: {'model_name': 'SimpleImputer', 'strategy': 'most_frequent'} because of the following error: KeyError('model_name').
Traceback (most recent call last):
  File "/home/ketrong/miniconda3/envs/tpot2devenv/lib/python3.10/site-packages/optuna/study/_optimize.py", line 200, in _run_trial
    value_or_values = func(trial)
  File "/common/ketrong/AutoImputeExp/tpot2_imputetest/Impute_Experiments/autoimpute.py", line 57, in obj
    my_model = autoutils.MyModel(random_state = self.random_state, **my_params)
  File "/common/ketrong/AutoImputeExp/tpot2_imputetest/Impute_Experiments/autoutils.py", line 31, in MyModel
    model_name = params['model_name']
KeyError: 'model_name'
[W 2023-11-21 15:53:58,313] Trial 44 failed with value None.
[W 2023-11-21 15:53:58,524] Trial 45 failed with parameters: {'model_name': 'SimpleImputer', 'strategy': 'median'} because of the following error: KeyError('model_name').
Traceback (most recent call last):
  File "/home/ketrong/miniconda3/envs/tpot2devenv/lib/python3.10/site-packages/optuna/study/_optimize.py", line 200, in _run_trial
    value_or_values = func(trial)
  File "/common/ketrong/AutoImputeExp/tpot2_imputetest/Impute_Experiments/autoimpute.py", line 57, in obj
    my_model = autoutils.MyModel(random_state = self.random_state, **my_params)
  File "/common/ketrong/AutoImputeExp/tpot2_imputetest/Impute_Experiments/autoutils.py", line 31, in MyModel
    model_name = params['model_name']
KeyError: 'model_name'
[W 2023-11-21 15:53:58,525] Trial 45 failed with value None.
[W 2023-11-21 15:53:58,735] Trial 46 failed with parameters: {'model_name': 'SimpleImputer', 'strategy': 'most_frequent'} because of the following error: KeyError('model_name').
Traceback (most recent call last):
  File "/home/ketrong/miniconda3/envs/tpot2devenv/lib/python3.10/site-packages/optuna/study/_optimize.py", line 200, in _run_trial
    value_or_values = func(trial)
  File "/common/ketrong/AutoImputeExp/tpot2_imputetest/Impute_Experiments/autoimpute.py", line 57, in obj
    my_model = autoutils.MyModel(random_state = self.random_state, **my_params)
  File "/common/ketrong/AutoImputeExp/tpot2_imputetest/Impute_Experiments/autoutils.py", line 31, in MyModel
    model_name = params['model_name']
KeyError: 'model_name'
[W 2023-11-21 15:53:58,735] Trial 46 failed with value None.
[W 2023-11-21 15:53:58,946] Trial 47 failed with parameters: {'model_name': 'SimpleImputer', 'strategy': 'constant'} because of the following error: KeyError('model_name').
Traceback (most recent call last):
  File "/home/ketrong/miniconda3/envs/tpot2devenv/lib/python3.10/site-packages/optuna/study/_optimize.py", line 200, in _run_trial
    value_or_values = func(trial)
  File "/common/ketrong/AutoImputeExp/tpot2_imputetest/Impute_Experiments/autoimpute.py", line 57, in obj
    my_model = autoutils.MyModel(random_state = self.random_state, **my_params)
  File "/common/ketrong/AutoImputeExp/tpot2_imputetest/Impute_Experiments/autoutils.py", line 31, in MyModel
    model_name = params['model_name']
KeyError: 'model_name'
[W 2023-11-21 15:53:58,946] Trial 47 failed with value None.
failed on 
tpot2_imputetest/Impute_Experiments/logs//tpot2_base_normal_6_0.01_MCAR_2
'model_name'
Traceback (most recent call last):
  File "/common/ketrong/AutoImputeExp/tpot2_imputetest/Impute_Experiments/utils.py", line 169, in loop_through_tasks
    SimpleImputeSpace.fit(X_train_pandas)
  File "/common/ketrong/AutoImputeExp/tpot2_imputetest/Impute_Experiments/autoimpute.py", line 60, in fit
    self.study.optimize(obj, n_trials=self.n_trials, n_jobs=self.n_jobs, show_progress_bar=self.show_progress, gc_after_trial=self.garbage_collect)
  File "/home/ketrong/miniconda3/envs/tpot2devenv/lib/python3.10/site-packages/optuna/study/study.py", line 451, in optimize
    _optimize(
  File "/home/ketrong/miniconda3/envs/tpot2devenv/lib/python3.10/site-packages/optuna/study/_optimize.py", line 103, in _optimize
    f.result()
  File "/home/ketrong/miniconda3/envs/tpot2devenv/lib/python3.10/concurrent/futures/_base.py", line 451, in result
    return self.__get_result()
  File "/home/ketrong/miniconda3/envs/tpot2devenv/lib/python3.10/concurrent/futures/_base.py", line 403, in __get_result
    raise self._exception
  File "/home/ketrong/miniconda3/envs/tpot2devenv/lib/python3.10/concurrent/futures/thread.py", line 58, in run
    result = self.fn(*self.args, **self.kwargs)
  File "/home/ketrong/miniconda3/envs/tpot2devenv/lib/python3.10/site-packages/optuna/study/_optimize.py", line 163, in _optimize_sequential
    frozen_trial = _run_trial(study, func, catch)
  File "/home/ketrong/miniconda3/envs/tpot2devenv/lib/python3.10/site-packages/optuna/study/_optimize.py", line 251, in _run_trial
    raise func_err
  File "/home/ketrong/miniconda3/envs/tpot2devenv/lib/python3.10/site-packages/optuna/study/_optimize.py", line 200, in _run_trial
    value_or_values = func(trial)
  File "/common/ketrong/AutoImputeExp/tpot2_imputetest/Impute_Experiments/autoimpute.py", line 57, in obj
    my_model = autoutils.MyModel(random_state = self.random_state, **my_params)
  File "/common/ketrong/AutoImputeExp/tpot2_imputetest/Impute_Experiments/autoutils.py", line 31, in MyModel
    model_name = params['model_name']
KeyError: 'model_name'

DONE
