Run: 8
/cm/local/apps/slurm/var/spool/job565598/slurm_script: line 23: /common/ketrong/minconda3/etc/profile.d/conda.sh: No such file or directory
/cm/local/apps/slurm/var/spool/job565598/slurm_script: line 26: $'\nconda create --name tpot2devenv -c conda-forge python=3.10\n': command not found
/cm/local/apps/slurm/var/spool/job565598/slurm_script: line 31: $'\npip install -r requirements.txt\n': command not found
RunStart
2023-12-19 13:26:12.296701: I tensorflow/core/util/port.cc:113] oneDNN custom operations are on. You may see slightly different numerical results due to floating-point round-off errors from different computation orders. To turn them off, set the environment variable `TF_ENABLE_ONEDNN_OPTS=0`.
2023-12-19 13:26:12.329097: E external/local_xla/xla/stream_executor/cuda/cuda_dnn.cc:9261] Unable to register cuDNN factory: Attempting to register factory for plugin cuDNN when one has already been registered
2023-12-19 13:26:12.329118: E external/local_xla/xla/stream_executor/cuda/cuda_fft.cc:607] Unable to register cuFFT factory: Attempting to register factory for plugin cuFFT when one has already been registered
2023-12-19 13:26:12.329913: E external/local_xla/xla/stream_executor/cuda/cuda_blas.cc:1515] Unable to register cuBLAS factory: Attempting to register factory for plugin cuBLAS when one has already been registered
2023-12-19 13:26:12.334702: I tensorflow/core/platform/cpu_feature_guard.cc:182] This TensorFlow binary is optimized to use available CPU instructions in performance-critical operations.
To enable the following instructions: AVX2 AVX512F AVX512_VNNI FMA, in other operations, rebuild TensorFlow with the appropriate compiler flags.
2023-12-19 13:26:13.725788: W tensorflow/compiler/tf2tensorrt/utils/py_utils.cc:38] TF-TRT Warning: Could not find TensorRT
WARNING:tensorflow:From /home/ketrong/miniconda3/envs/tpot2devenv/lib/python3.10/site-packages/tensorflow/python/compat/v2_compat.py:108: disable_resource_variables (from tensorflow.python.ops.variable_scope) is deprecated and will be removed in a future version.
Instructions for updating:
non-resource variables are not supported in the long term
starting loops
working on 
logs/6/tpot2_base_normal_MAR_0.3
2.743337392807007
loading data
logs/6/tpot2_base_normal_MAR_0.3/data/6_True.pkl
working on 
logs/6/tpot2_base_imputation_MAR_0.3
4.110466003417969
loading data
logs/6/tpot2_base_imputation_MAR_0.3/data/6_True.pkl
6
finished
working on 
logs/26/tpot2_base_normal_MAR_0.3
0.8066186904907227
loading data
logs/26/tpot2_base_normal_MAR_0.3/data/26_True.pkl
working on 
logs/26/tpot2_base_imputation_MAR_0.3
1.9135277271270752
loading data
logs/26/tpot2_base_imputation_MAR_0.3/data/26_True.pkl
26
finished
working on 
logs/30/tpot2_base_normal_MAR_0.3
4.69236946105957
loading data
logs/30/tpot2_base_normal_MAR_0.3/data/30_True.pkl
working on 
logs/30/tpot2_base_imputation_MAR_0.3
1.205096960067749
loading data
logs/30/tpot2_base_imputation_MAR_0.3/data/30_True.pkl
30
finished
working on 
logs/32/tpot2_base_normal_MAR_0.3
4.387010812759399
loading data
logs/32/tpot2_base_normal_MAR_0.3/data/32_True.pkl
working on 
logs/32/tpot2_base_imputation_MAR_0.3
4.406152009963989
loading data
logs/32/tpot2_base_imputation_MAR_0.3/data/32_True.pkl
32
finished
working on 
logs/151/tpot2_base_normal_MAR_0.3
2.741478681564331
loading data
logs/151/tpot2_base_normal_MAR_0.3/data/151_True.pkl
failed on 
logs/151/tpot2_base_normal_MAR_0.3
Cannot remove faulty tasks cache directory /home/ketrong/.cache/openml/org/openml/www/tasks/151.Please do this manually!
Traceback (most recent call last):
  File "/home/ketrong/miniconda3/envs/tpot2devenv/lib/python3.10/site-packages/openml/datasets/functions.py", line 1021, in _get_dataset_description
    with io.open(description_file, encoding="utf8") as fh:
FileNotFoundError: [Errno 2] No such file or directory: '/home/ketrong/.cache/openml/org/openml/www/datasets/125/description.xml'

During handling of the above exception, another exception occurred:

Traceback (most recent call last):
  File "/home/ketrong/miniconda3/envs/tpot2devenv/lib/python3.10/site-packages/openml/datasets/functions.py", line 486, in get_dataset
    description = _get_dataset_description(did_cache_dir, dataset_id)
  File "/home/ketrong/miniconda3/envs/tpot2devenv/lib/python3.10/site-packages/openml/datasets/functions.py", line 1032, in _get_dataset_description
    with io.open(description_file, "w", encoding="utf8") as fh:
FileNotFoundError: [Errno 2] No such file or directory: '/home/ketrong/.cache/openml/org/openml/www/datasets/125/description.xml'

During handling of the above exception, another exception occurred:

Traceback (most recent call last):
  File "/home/ketrong/miniconda3/envs/tpot2devenv/lib/python3.10/site-packages/openml/utils.py", line 375, in _remove_cache_dir_for_id
    shutil.rmtree(cache_dir)
  File "/home/ketrong/miniconda3/envs/tpot2devenv/lib/python3.10/shutil.py", line 715, in rmtree
    onerror(os.lstat, path, sys.exc_info())
  File "/home/ketrong/miniconda3/envs/tpot2devenv/lib/python3.10/shutil.py", line 713, in rmtree
    orig_st = os.lstat(path)
FileNotFoundError: [Errno 2] No such file or directory: '/home/ketrong/.cache/openml/org/openml/www/datasets/125'

During handling of the above exception, another exception occurred:

Traceback (most recent call last):
  File "/home/ketrong/miniconda3/envs/tpot2devenv/lib/python3.10/site-packages/openml/tasks/functions.py", line 399, in get_task
    dataset = get_dataset(task.dataset_id, *dataset_args, **get_dataset_kwargs)
  File "/home/ketrong/miniconda3/envs/tpot2devenv/lib/python3.10/site-packages/openml/datasets/functions.py", line 517, in get_dataset
    _remove_cache_dir_for_id(DATASETS_CACHE_DIR_NAME, did_cache_dir)
  File "/home/ketrong/miniconda3/envs/tpot2devenv/lib/python3.10/site-packages/openml/utils.py", line 377, in _remove_cache_dir_for_id
    raise ValueError(
ValueError: Cannot remove faulty datasets cache directory /home/ketrong/.cache/openml/org/openml/www/datasets/125.Please do this manually!

During handling of the above exception, another exception occurred:

Traceback (most recent call last):
  File "/home/ketrong/miniconda3/envs/tpot2devenv/lib/python3.10/site-packages/openml/utils.py", line 375, in _remove_cache_dir_for_id
    shutil.rmtree(cache_dir)
  File "/home/ketrong/miniconda3/envs/tpot2devenv/lib/python3.10/shutil.py", line 721, in rmtree
    onerror(os.open, path, sys.exc_info())
  File "/home/ketrong/miniconda3/envs/tpot2devenv/lib/python3.10/shutil.py", line 718, in rmtree
    fd = os.open(path, os.O_RDONLY)
FileNotFoundError: [Errno 2] No such file or directory: '/home/ketrong/.cache/openml/org/openml/www/tasks/151'

During handling of the above exception, another exception occurred:

Traceback (most recent call last):
  File "/common/ketrong/AutoImputeExp/tpot2_imputetest/Impute_Experiments/utils.py", line 310, in loop_through_tasks
    X_train, y_train, X_test, y_test = load_task(base_save_folder=base_save_folder, exp=exp, type=type, levelstr=levelstr, task_id=taskid, preprocess=True)
  File "/common/ketrong/AutoImputeExp/tpot2_imputetest/Impute_Experiments/utils.py", line 200, in load_task
    task = openml.tasks.get_task(task_id, **kwargs)
  File "/home/ketrong/miniconda3/envs/tpot2devenv/lib/python3.10/site-packages/openml/tasks/functions.py", line 411, in get_task
    openml.utils._remove_cache_dir_for_id(
  File "/home/ketrong/miniconda3/envs/tpot2devenv/lib/python3.10/site-packages/openml/utils.py", line 377, in _remove_cache_dir_for_id
    raise ValueError(
ValueError: Cannot remove faulty tasks cache directory /home/ketrong/.cache/openml/org/openml/www/tasks/151.Please do this manually!

full run takes
0.018918498555819195
hours
DONE
