Run: 10
/cm/local/apps/slurm/var/spool/job576854/slurm_script: line 23: /common/ketrong/minconda3/etc/profile.d/conda.sh: No such file or directory
/cm/local/apps/slurm/var/spool/job576854/slurm_script: line 26: $'\nconda create --name tpot2devenv -c conda-forge python=3.10\n': command not found
/cm/local/apps/slurm/var/spool/job576854/slurm_script: line 31: $'\npip install -r requirements.txt\n': command not found
RunStart
2024-01-03 13:17:15.529679: I tensorflow/core/util/port.cc:113] oneDNN custom operations are on. You may see slightly different numerical results due to floating-point round-off errors from different computation orders. To turn them off, set the environment variable `TF_ENABLE_ONEDNN_OPTS=0`.
2024-01-03 13:17:15.566013: E external/local_xla/xla/stream_executor/cuda/cuda_dnn.cc:9261] Unable to register cuDNN factory: Attempting to register factory for plugin cuDNN when one has already been registered
2024-01-03 13:17:15.566038: E external/local_xla/xla/stream_executor/cuda/cuda_fft.cc:607] Unable to register cuFFT factory: Attempting to register factory for plugin cuFFT when one has already been registered
2024-01-03 13:17:15.567418: E external/local_xla/xla/stream_executor/cuda/cuda_blas.cc:1515] Unable to register cuBLAS factory: Attempting to register factory for plugin cuBLAS when one has already been registered
2024-01-03 13:17:15.573699: I tensorflow/core/platform/cpu_feature_guard.cc:182] This TensorFlow binary is optimized to use available CPU instructions in performance-critical operations.
To enable the following instructions: AVX2 AVX512F AVX512_VNNI FMA, in other operations, rebuild TensorFlow with the appropriate compiler flags.
2024-01-03 13:17:17.590846: W tensorflow/compiler/tf2tensorrt/utils/py_utils.cc:38] TF-TRT Warning: Could not find TensorRT
WARNING:tensorflow:From /home/ketrong/miniconda3/envs/tpot2devenv/lib/python3.10/site-packages/tensorflow/python/compat/v2_compat.py:108: disable_resource_variables (from tensorflow.python.ops.variable_scope) is deprecated and will be removed in a future version.
Instructions for updating:
non-resource variables are not supported in the long term
starting loops
working on 
logs/3764/tpot2_base_normal_MAR_0.9
4.62365198135376
loading data
logs/3764/tpot2_base_normal_MAR_0.9/data/3764_True.pkl
failed on 
logs/3764/tpot2_base_normal_MAR_0.9
Cannot remove faulty tasks cache directory /home/ketrong/.cache/openml/org/openml/www/tasks/3764.Please do this manually!
Traceback (most recent call last):
  File "/home/ketrong/miniconda3/envs/tpot2devenv/lib/python3.10/site-packages/openml/tasks/functions.py", line 70, in _get_cached_task
    with io.open(os.path.join(tid_cache_dir, "task.xml"), encoding="utf8") as fh:
FileNotFoundError: [Errno 2] No such file or directory: '/home/ketrong/.cache/openml/org/openml/www/tasks/3764/task.xml'

During handling of the above exception, another exception occurred:

Traceback (most recent call last):
  File "/home/ketrong/miniconda3/envs/tpot2devenv/lib/python3.10/site-packages/openml/tasks/functions.py", line 422, in _get_task_description
    return _get_cached_task(task_id)
  File "/home/ketrong/miniconda3/envs/tpot2devenv/lib/python3.10/site-packages/openml/tasks/functions.py", line 74, in _get_cached_task
    raise OpenMLCacheException("Task file for tid %d not " "cached" % tid)
openml.exceptions.OpenMLCacheException: Task file for tid 3764 not cached

During handling of the above exception, another exception occurred:

Traceback (most recent call last):
  File "/home/ketrong/miniconda3/envs/tpot2devenv/lib/python3.10/site-packages/openml/tasks/functions.py", line 398, in get_task
    task = _get_task_description(task_id)
  File "/home/ketrong/miniconda3/envs/tpot2devenv/lib/python3.10/site-packages/openml/tasks/functions.py", line 433, in _get_task_description
    with io.open(xml_file, "w", encoding="utf8") as fh:
FileNotFoundError: [Errno 2] No such file or directory: '/home/ketrong/.cache/openml/org/openml/www/tasks/3764/task.xml'

During handling of the above exception, another exception occurred:

Traceback (most recent call last):
  File "/home/ketrong/miniconda3/envs/tpot2devenv/lib/python3.10/site-packages/openml/utils.py", line 375, in _remove_cache_dir_for_id
    shutil.rmtree(cache_dir)
  File "/home/ketrong/miniconda3/envs/tpot2devenv/lib/python3.10/shutil.py", line 715, in rmtree
    onerror(os.lstat, path, sys.exc_info())
  File "/home/ketrong/miniconda3/envs/tpot2devenv/lib/python3.10/shutil.py", line 713, in rmtree
    orig_st = os.lstat(path)
FileNotFoundError: [Errno 2] No such file or directory: '/home/ketrong/.cache/openml/org/openml/www/tasks/3764'

During handling of the above exception, another exception occurred:

Traceback (most recent call last):
  File "/common/ketrong/AutoImputeExp/tpot2_imputetest/Impute_Experiments/utils.py", line 310, in loop_through_tasks
    X_train, y_train, X_test, y_test = load_task(base_save_folder=base_save_folder, exp=exp, type=type, levelstr=levelstr, task_id=taskid, preprocess=True)
  File "/common/ketrong/AutoImputeExp/tpot2_imputetest/Impute_Experiments/utils.py", line 200, in load_task
    task = openml.tasks.get_task(task_id)
  File "/home/ketrong/miniconda3/envs/tpot2devenv/lib/python3.10/site-packages/openml/tasks/functions.py", line 411, in get_task
    openml.utils._remove_cache_dir_for_id(
  File "/home/ketrong/miniconda3/envs/tpot2devenv/lib/python3.10/site-packages/openml/utils.py", line 377, in _remove_cache_dir_for_id
    raise ValueError(
ValueError: Cannot remove faulty tasks cache directory /home/ketrong/.cache/openml/org/openml/www/tasks/3764.Please do this manually!

full run takes
0.0031331790155834623
hours
DONE
