Run: 15
/cm/local/apps/slurm/var/spool/job565635/slurm_script: line 23: /common/ketrong/minconda3/etc/profile.d/conda.sh: No such file or directory
/cm/local/apps/slurm/var/spool/job565635/slurm_script: line 26: $'\nconda create --name tpot2devenv -c conda-forge python=3.10\n': command not found
/cm/local/apps/slurm/var/spool/job565635/slurm_script: line 31: $'\npip install -r requirements.txt\n': command not found
RunStart
2023-12-19 14:02:50.394181: I tensorflow/core/util/port.cc:113] oneDNN custom operations are on. You may see slightly different numerical results due to floating-point round-off errors from different computation orders. To turn them off, set the environment variable `TF_ENABLE_ONEDNN_OPTS=0`.
2023-12-19 14:02:50.429753: E external/local_xla/xla/stream_executor/cuda/cuda_dnn.cc:9261] Unable to register cuDNN factory: Attempting to register factory for plugin cuDNN when one has already been registered
2023-12-19 14:02:50.429776: E external/local_xla/xla/stream_executor/cuda/cuda_fft.cc:607] Unable to register cuFFT factory: Attempting to register factory for plugin cuFFT when one has already been registered
2023-12-19 14:02:50.430906: E external/local_xla/xla/stream_executor/cuda/cuda_blas.cc:1515] Unable to register cuBLAS factory: Attempting to register factory for plugin cuBLAS when one has already been registered
2023-12-19 14:02:50.436592: I tensorflow/core/platform/cpu_feature_guard.cc:182] This TensorFlow binary is optimized to use available CPU instructions in performance-critical operations.
To enable the following instructions: AVX2 AVX512F AVX512_VNNI FMA, in other operations, rebuild TensorFlow with the appropriate compiler flags.
2023-12-19 14:02:52.505731: W tensorflow/compiler/tf2tensorrt/utils/py_utils.cc:38] TF-TRT Warning: Could not find TensorRT
WARNING:tensorflow:From /home/ketrong/miniconda3/envs/tpot2devenv/lib/python3.10/site-packages/tensorflow/python/compat/v2_compat.py:108: disable_resource_variables (from tensorflow.python.ops.variable_scope) is deprecated and will be removed in a future version.
Instructions for updating:
non-resource variables are not supported in the long term
starting loops
working on 
logs/6/tpot2_base_normal_MNAR_0.9
1.8868205547332764
loading data
logs/6/tpot2_base_normal_MNAR_0.9/data/6_True.pkl
working on 
logs/6/tpot2_base_imputation_MNAR_0.9
0.4230051040649414
loading data
logs/6/tpot2_base_imputation_MNAR_0.9/data/6_True.pkl
6
finished
working on 
logs/26/tpot2_base_normal_MNAR_0.9
2.2389166355133057
loading data
logs/26/tpot2_base_normal_MNAR_0.9/data/26_True.pkl
working on 
logs/26/tpot2_base_imputation_MNAR_0.9
1.6780571937561035
loading data
logs/26/tpot2_base_imputation_MNAR_0.9/data/26_True.pkl
26
finished
working on 
logs/30/tpot2_base_normal_MNAR_0.9
0.0545198917388916
loading data
logs/30/tpot2_base_normal_MNAR_0.9/data/30_True.pkl
working on 
logs/30/tpot2_base_imputation_MNAR_0.9
0.10098624229431152
loading data
logs/30/tpot2_base_imputation_MNAR_0.9/data/30_True.pkl
30
finished
working on 
logs/32/tpot2_base_normal_MNAR_0.9
3.7177958488464355
loading data
logs/32/tpot2_base_normal_MNAR_0.9/data/32_True.pkl
working on 
logs/32/tpot2_base_imputation_MNAR_0.9
1.7474784851074219
loading data
logs/32/tpot2_base_imputation_MNAR_0.9/data/32_True.pkl
32
finished
working on 
logs/137/tpot2_base_normal_MNAR_0.9
4.973770380020142
loading data
logs/137/tpot2_base_normal_MNAR_0.9/data/137_True.pkl
Cannot remove faulty tasks cache directory /home/ketrong/.cache/openml/org/openml/www/tasks/137.Please do this manually!
Traceback (most recent call last):
  File "/home/ketrong/miniconda3/envs/tpot2devenv/lib/python3.10/site-packages/openml/tasks/task.py", line 157, in download_split
    split = OpenMLSplit._from_arff_file(cached_split_file)
  File "/home/ketrong/miniconda3/envs/tpot2devenv/lib/python3.10/site-packages/openml/tasks/split.py", line 87, in _from_arff_file
    raise FileNotFoundError("Split arff %s does not exist!" % filename)
FileNotFoundError: Split arff /home/ketrong/.cache/openml/org/openml/www/tasks/137/datasplits.arff does not exist!

During handling of the above exception, another exception occurred:

Traceback (most recent call last):
  File "/home/ketrong/miniconda3/envs/tpot2devenv/lib/python3.10/site-packages/openml/tasks/functions.py", line 409, in get_task
    task.download_split()
  File "/home/ketrong/miniconda3/envs/tpot2devenv/lib/python3.10/site-packages/openml/tasks/task.py", line 161, in download_split
    split = OpenMLSplit._from_arff_file(cached_split_file)
  File "/home/ketrong/miniconda3/envs/tpot2devenv/lib/python3.10/site-packages/openml/tasks/split.py", line 87, in _from_arff_file
    raise FileNotFoundError("Split arff %s does not exist!" % filename)
FileNotFoundError: Split arff /home/ketrong/.cache/openml/org/openml/www/tasks/137/datasplits.arff does not exist!

During handling of the above exception, another exception occurred:

Traceback (most recent call last):
  File "/home/ketrong/miniconda3/envs/tpot2devenv/lib/python3.10/site-packages/openml/utils.py", line 375, in _remove_cache_dir_for_id
    shutil.rmtree(cache_dir)
  File "/home/ketrong/miniconda3/envs/tpot2devenv/lib/python3.10/shutil.py", line 715, in rmtree
    onerror(os.lstat, path, sys.exc_info())
  File "/home/ketrong/miniconda3/envs/tpot2devenv/lib/python3.10/shutil.py", line 713, in rmtree
    orig_st = os.lstat(path)
FileNotFoundError: [Errno 2] No such file or directory: '/home/ketrong/.cache/openml/org/openml/www/tasks/137'

During handling of the above exception, another exception occurred:

Traceback (most recent call last):
  File "/common/ketrong/AutoImputeExp/tpot2_imputetest/Impute_Experiments/utils.py", line 310, in loop_through_tasks
    X_train, y_train, X_test, y_test = load_task(base_save_folder=base_save_folder, exp=exp, type=type, levelstr=levelstr, task_id=taskid, preprocess=True)
  File "/common/ketrong/AutoImputeExp/tpot2_imputetest/Impute_Experiments/utils.py", line 200, in load_task
    task = openml.tasks.get_task(task_id)
  File "/home/ketrong/miniconda3/envs/tpot2devenv/lib/python3.10/site-packages/openml/tasks/functions.py", line 411, in get_task
    openml.utils._remove_cache_dir_for_id(
  File "/home/ketrong/miniconda3/envs/tpot2devenv/lib/python3.10/site-packages/openml/utils.py", line 377, in _remove_cache_dir_for_id
    raise ValueError(
ValueError: Cannot remove faulty tasks cache directory /home/ketrong/.cache/openml/org/openml/www/tasks/137.Please do this manually!

137
remove from investigation?
working on 
logs/137/tpot2_base_imputation_MNAR_0.9
4.284991025924683
loading data
logs/137/tpot2_base_imputation_MNAR_0.9/data/137_True.pkl
Cannot remove faulty tasks cache directory /home/ketrong/.cache/openml/org/openml/www/tasks/137.Please do this manually!
Traceback (most recent call last):
  File "/home/ketrong/miniconda3/envs/tpot2devenv/lib/python3.10/site-packages/openml/tasks/task.py", line 157, in download_split
    split = OpenMLSplit._from_arff_file(cached_split_file)
  File "/home/ketrong/miniconda3/envs/tpot2devenv/lib/python3.10/site-packages/openml/tasks/split.py", line 87, in _from_arff_file
    raise FileNotFoundError("Split arff %s does not exist!" % filename)
FileNotFoundError: Split arff /home/ketrong/.cache/openml/org/openml/www/tasks/137/datasplits.arff does not exist!

During handling of the above exception, another exception occurred:

Traceback (most recent call last):
  File "/home/ketrong/miniconda3/envs/tpot2devenv/lib/python3.10/site-packages/openml/tasks/functions.py", line 409, in get_task
    task.download_split()
  File "/home/ketrong/miniconda3/envs/tpot2devenv/lib/python3.10/site-packages/openml/tasks/task.py", line 161, in download_split
    split = OpenMLSplit._from_arff_file(cached_split_file)
  File "/home/ketrong/miniconda3/envs/tpot2devenv/lib/python3.10/site-packages/openml/tasks/split.py", line 88, in _from_arff_file
    file_data = arff.load(open(filename), return_type=arff.DENSE_GEN)
  File "/home/ketrong/miniconda3/envs/tpot2devenv/lib/python3.10/site-packages/arff.py", line 1059, in load
    return decoder.decode(fp, encode_nominal=encode_nominal,
  File "/home/ketrong/miniconda3/envs/tpot2devenv/lib/python3.10/site-packages/arff.py", line 896, in decode
    raise e
  File "/home/ketrong/miniconda3/envs/tpot2devenv/lib/python3.10/site-packages/arff.py", line 892, in decode
    return self._decode(s, encode_nominal=encode_nominal,
  File "/home/ketrong/miniconda3/envs/tpot2devenv/lib/python3.10/site-packages/arff.py", line 813, in _decode
    obj['relation'] = self._decode_relation(row)
  File "/home/ketrong/miniconda3/envs/tpot2devenv/lib/python3.10/site-packages/arff.py", line 706, in _decode_relation
    raise BadRelationFormat()
arff.BadRelationFormat: Bad @RELATION format, at line 1.

During handling of the above exception, another exception occurred:

Traceback (most recent call last):
  File "/home/ketrong/miniconda3/envs/tpot2devenv/lib/python3.10/site-packages/openml/utils.py", line 375, in _remove_cache_dir_for_id
    shutil.rmtree(cache_dir)
  File "/home/ketrong/miniconda3/envs/tpot2devenv/lib/python3.10/shutil.py", line 731, in rmtree
    onerror(os.rmdir, path, sys.exc_info())
  File "/home/ketrong/miniconda3/envs/tpot2devenv/lib/python3.10/shutil.py", line 729, in rmtree
    os.rmdir(path)
OSError: [Errno 39] Directory not empty: '/home/ketrong/.cache/openml/org/openml/www/tasks/137'

During handling of the above exception, another exception occurred:

Traceback (most recent call last):
  File "/common/ketrong/AutoImputeExp/tpot2_imputetest/Impute_Experiments/utils.py", line 310, in loop_through_tasks
    X_train, y_train, X_test, y_test = load_task(base_save_folder=base_save_folder, exp=exp, type=type, levelstr=levelstr, task_id=taskid, preprocess=True)
  File "/common/ketrong/AutoImputeExp/tpot2_imputetest/Impute_Experiments/utils.py", line 200, in load_task
    task = openml.tasks.get_task(task_id)
  File "/home/ketrong/miniconda3/envs/tpot2devenv/lib/python3.10/site-packages/openml/tasks/functions.py", line 411, in get_task
    openml.utils._remove_cache_dir_for_id(
  File "/home/ketrong/miniconda3/envs/tpot2devenv/lib/python3.10/site-packages/openml/utils.py", line 377, in _remove_cache_dir_for_id
    raise ValueError(
ValueError: Cannot remove faulty tasks cache directory /home/ketrong/.cache/openml/org/openml/www/tasks/137.Please do this manually!

137
remove from investigation?
137
finished
working on 
logs/151/tpot2_base_normal_MNAR_0.9
2.1327266693115234
loading data
logs/151/tpot2_base_normal_MNAR_0.9/data/151_True.pkl
Cannot remove faulty tasks cache directory /home/ketrong/.cache/openml/org/openml/www/tasks/151.Please do this manually!
Traceback (most recent call last):
  File "/home/ketrong/miniconda3/envs/tpot2devenv/lib/python3.10/site-packages/openml/tasks/task.py", line 157, in download_split
    split = OpenMLSplit._from_arff_file(cached_split_file)
  File "/home/ketrong/miniconda3/envs/tpot2devenv/lib/python3.10/site-packages/openml/tasks/split.py", line 87, in _from_arff_file
    raise FileNotFoundError("Split arff %s does not exist!" % filename)
FileNotFoundError: Split arff /home/ketrong/.cache/openml/org/openml/www/tasks/151/datasplits.arff does not exist!

During handling of the above exception, another exception occurred:

Traceback (most recent call last):
  File "/home/ketrong/miniconda3/envs/tpot2devenv/lib/python3.10/site-packages/openml/tasks/functions.py", line 409, in get_task
    task.download_split()
  File "/home/ketrong/miniconda3/envs/tpot2devenv/lib/python3.10/site-packages/openml/tasks/task.py", line 161, in download_split
    split = OpenMLSplit._from_arff_file(cached_split_file)
  File "/home/ketrong/miniconda3/envs/tpot2devenv/lib/python3.10/site-packages/openml/tasks/split.py", line 88, in _from_arff_file
    file_data = arff.load(open(filename), return_type=arff.DENSE_GEN)
  File "/home/ketrong/miniconda3/envs/tpot2devenv/lib/python3.10/site-packages/arff.py", line 1059, in load
    return decoder.decode(fp, encode_nominal=encode_nominal,
  File "/home/ketrong/miniconda3/envs/tpot2devenv/lib/python3.10/site-packages/arff.py", line 896, in decode
    raise e
  File "/home/ketrong/miniconda3/envs/tpot2devenv/lib/python3.10/site-packages/arff.py", line 892, in decode
    return self._decode(s, encode_nominal=encode_nominal,
  File "/home/ketrong/miniconda3/envs/tpot2devenv/lib/python3.10/site-packages/arff.py", line 813, in _decode
    obj['relation'] = self._decode_relation(row)
  File "/home/ketrong/miniconda3/envs/tpot2devenv/lib/python3.10/site-packages/arff.py", line 706, in _decode_relation
    raise BadRelationFormat()
arff.BadRelationFormat: Bad @RELATION format, at line 1.

During handling of the above exception, another exception occurred:

Traceback (most recent call last):
  File "/home/ketrong/miniconda3/envs/tpot2devenv/lib/python3.10/site-packages/openml/utils.py", line 375, in _remove_cache_dir_for_id
    shutil.rmtree(cache_dir)
  File "/home/ketrong/miniconda3/envs/tpot2devenv/lib/python3.10/shutil.py", line 731, in rmtree
    onerror(os.rmdir, path, sys.exc_info())
  File "/home/ketrong/miniconda3/envs/tpot2devenv/lib/python3.10/shutil.py", line 729, in rmtree
    os.rmdir(path)
OSError: [Errno 39] Directory not empty: '/home/ketrong/.cache/openml/org/openml/www/tasks/151'

During handling of the above exception, another exception occurred:

Traceback (most recent call last):
  File "/common/ketrong/AutoImputeExp/tpot2_imputetest/Impute_Experiments/utils.py", line 310, in loop_through_tasks
    X_train, y_train, X_test, y_test = load_task(base_save_folder=base_save_folder, exp=exp, type=type, levelstr=levelstr, task_id=taskid, preprocess=True)
  File "/common/ketrong/AutoImputeExp/tpot2_imputetest/Impute_Experiments/utils.py", line 200, in load_task
    task = openml.tasks.get_task(task_id)
  File "/home/ketrong/miniconda3/envs/tpot2devenv/lib/python3.10/site-packages/openml/tasks/functions.py", line 411, in get_task
    openml.utils._remove_cache_dir_for_id(
  File "/home/ketrong/miniconda3/envs/tpot2devenv/lib/python3.10/site-packages/openml/utils.py", line 377, in _remove_cache_dir_for_id
    raise ValueError(
ValueError: Cannot remove faulty tasks cache directory /home/ketrong/.cache/openml/org/openml/www/tasks/151.Please do this manually!

151
remove from investigation?
working on 
logs/151/tpot2_base_imputation_MNAR_0.9
1.6096577644348145
loading data
logs/151/tpot2_base_imputation_MNAR_0.9/data/151_True.pkl
Cannot remove faulty tasks cache directory /home/ketrong/.cache/openml/org/openml/www/tasks/151.Please do this manually!
Traceback (most recent call last):
  File "/home/ketrong/miniconda3/envs/tpot2devenv/lib/python3.10/site-packages/openml/tasks/task.py", line 157, in download_split
    split = OpenMLSplit._from_arff_file(cached_split_file)
  File "/home/ketrong/miniconda3/envs/tpot2devenv/lib/python3.10/site-packages/openml/tasks/split.py", line 87, in _from_arff_file
    raise FileNotFoundError("Split arff %s does not exist!" % filename)
FileNotFoundError: Split arff /home/ketrong/.cache/openml/org/openml/www/tasks/151/datasplits.arff does not exist!

During handling of the above exception, another exception occurred:

Traceback (most recent call last):
  File "/home/ketrong/miniconda3/envs/tpot2devenv/lib/python3.10/site-packages/openml/tasks/functions.py", line 409, in get_task
    task.download_split()
  File "/home/ketrong/miniconda3/envs/tpot2devenv/lib/python3.10/site-packages/openml/tasks/task.py", line 161, in download_split
    split = OpenMLSplit._from_arff_file(cached_split_file)
  File "/home/ketrong/miniconda3/envs/tpot2devenv/lib/python3.10/site-packages/openml/tasks/split.py", line 88, in _from_arff_file
    file_data = arff.load(open(filename), return_type=arff.DENSE_GEN)
  File "/home/ketrong/miniconda3/envs/tpot2devenv/lib/python3.10/site-packages/arff.py", line 1059, in load
    return decoder.decode(fp, encode_nominal=encode_nominal,
  File "/home/ketrong/miniconda3/envs/tpot2devenv/lib/python3.10/site-packages/arff.py", line 896, in decode
    raise e
  File "/home/ketrong/miniconda3/envs/tpot2devenv/lib/python3.10/site-packages/arff.py", line 892, in decode
    return self._decode(s, encode_nominal=encode_nominal,
  File "/home/ketrong/miniconda3/envs/tpot2devenv/lib/python3.10/site-packages/arff.py", line 813, in _decode
    obj['relation'] = self._decode_relation(row)
  File "/home/ketrong/miniconda3/envs/tpot2devenv/lib/python3.10/site-packages/arff.py", line 706, in _decode_relation
    raise BadRelationFormat()
arff.BadRelationFormat: Bad @RELATION format, at line 1.

During handling of the above exception, another exception occurred:

Traceback (most recent call last):
  File "/home/ketrong/miniconda3/envs/tpot2devenv/lib/python3.10/site-packages/openml/utils.py", line 375, in _remove_cache_dir_for_id
    shutil.rmtree(cache_dir)
  File "/home/ketrong/miniconda3/envs/tpot2devenv/lib/python3.10/shutil.py", line 731, in rmtree
    onerror(os.rmdir, path, sys.exc_info())
  File "/home/ketrong/miniconda3/envs/tpot2devenv/lib/python3.10/shutil.py", line 729, in rmtree
    os.rmdir(path)
OSError: [Errno 39] Directory not empty: '/home/ketrong/.cache/openml/org/openml/www/tasks/151'

During handling of the above exception, another exception occurred:

Traceback (most recent call last):
  File "/common/ketrong/AutoImputeExp/tpot2_imputetest/Impute_Experiments/utils.py", line 310, in loop_through_tasks
    X_train, y_train, X_test, y_test = load_task(base_save_folder=base_save_folder, exp=exp, type=type, levelstr=levelstr, task_id=taskid, preprocess=True)
  File "/common/ketrong/AutoImputeExp/tpot2_imputetest/Impute_Experiments/utils.py", line 200, in load_task
    task = openml.tasks.get_task(task_id)
  File "/home/ketrong/miniconda3/envs/tpot2devenv/lib/python3.10/site-packages/openml/tasks/functions.py", line 411, in get_task
    openml.utils._remove_cache_dir_for_id(
  File "/home/ketrong/miniconda3/envs/tpot2devenv/lib/python3.10/site-packages/openml/utils.py", line 377, in _remove_cache_dir_for_id
    raise ValueError(
ValueError: Cannot remove faulty tasks cache directory /home/ketrong/.cache/openml/org/openml/www/tasks/151.Please do this manually!

151
remove from investigation?
151
finished
working on 
logs/183/tpot2_base_normal_MNAR_0.9
4.458223819732666
loading data
logs/183/tpot2_base_normal_MNAR_0.9/data/183_True.pkl
Task type Supervised Data Stream Classification not supported.
Traceback (most recent call last):
  File "/home/ketrong/miniconda3/envs/tpot2devenv/lib/python3.10/site-packages/openml/tasks/functions.py", line 70, in _get_cached_task
    with io.open(os.path.join(tid_cache_dir, "task.xml"), encoding="utf8") as fh:
FileNotFoundError: [Errno 2] No such file or directory: '/home/ketrong/.cache/openml/org/openml/www/tasks/183/task.xml'

During handling of the above exception, another exception occurred:

Traceback (most recent call last):
  File "/home/ketrong/miniconda3/envs/tpot2devenv/lib/python3.10/site-packages/openml/tasks/functions.py", line 422, in _get_task_description
    return _get_cached_task(task_id)
  File "/home/ketrong/miniconda3/envs/tpot2devenv/lib/python3.10/site-packages/openml/tasks/functions.py", line 74, in _get_cached_task
    raise OpenMLCacheException("Task file for tid %d not " "cached" % tid)
openml.exceptions.OpenMLCacheException: Task file for tid 183 not cached

During handling of the above exception, another exception occurred:

Traceback (most recent call last):
  File "/common/ketrong/AutoImputeExp/tpot2_imputetest/Impute_Experiments/utils.py", line 310, in loop_through_tasks
    X_train, y_train, X_test, y_test = load_task(base_save_folder=base_save_folder, exp=exp, type=type, levelstr=levelstr, task_id=taskid, preprocess=True)
  File "/common/ketrong/AutoImputeExp/tpot2_imputetest/Impute_Experiments/utils.py", line 200, in load_task
    task = openml.tasks.get_task(task_id)
  File "/home/ketrong/miniconda3/envs/tpot2devenv/lib/python3.10/site-packages/openml/tasks/functions.py", line 415, in get_task
    raise e
  File "/home/ketrong/miniconda3/envs/tpot2devenv/lib/python3.10/site-packages/openml/tasks/functions.py", line 398, in get_task
    task = _get_task_description(task_id)
  File "/home/ketrong/miniconda3/envs/tpot2devenv/lib/python3.10/site-packages/openml/tasks/functions.py", line 435, in _get_task_description
    return _create_task_from_xml(task_xml)
  File "/home/ketrong/miniconda3/envs/tpot2devenv/lib/python3.10/site-packages/openml/tasks/functions.py", line 510, in _create_task_from_xml
    raise NotImplementedError("Task type %s not supported." % common_kwargs["task_type"])
NotImplementedError: Task type Supervised Data Stream Classification not supported.

183
remove from investigation?
working on 
logs/183/tpot2_base_imputation_MNAR_0.9
0.4328484535217285
loading data
logs/183/tpot2_base_imputation_MNAR_0.9/data/183_True.pkl
Task type Supervised Data Stream Classification not supported.
Traceback (most recent call last):
  File "/home/ketrong/miniconda3/envs/tpot2devenv/lib/python3.10/site-packages/openml/tasks/functions.py", line 70, in _get_cached_task
    with io.open(os.path.join(tid_cache_dir, "task.xml"), encoding="utf8") as fh:
FileNotFoundError: [Errno 2] No such file or directory: '/home/ketrong/.cache/openml/org/openml/www/tasks/183/task.xml'

During handling of the above exception, another exception occurred:

Traceback (most recent call last):
  File "/home/ketrong/miniconda3/envs/tpot2devenv/lib/python3.10/site-packages/openml/tasks/functions.py", line 422, in _get_task_description
    return _get_cached_task(task_id)
  File "/home/ketrong/miniconda3/envs/tpot2devenv/lib/python3.10/site-packages/openml/tasks/functions.py", line 74, in _get_cached_task
    raise OpenMLCacheException("Task file for tid %d not " "cached" % tid)
openml.exceptions.OpenMLCacheException: Task file for tid 183 not cached

During handling of the above exception, another exception occurred:

Traceback (most recent call last):
  File "/common/ketrong/AutoImputeExp/tpot2_imputetest/Impute_Experiments/utils.py", line 310, in loop_through_tasks
    X_train, y_train, X_test, y_test = load_task(base_save_folder=base_save_folder, exp=exp, type=type, levelstr=levelstr, task_id=taskid, preprocess=True)
  File "/common/ketrong/AutoImputeExp/tpot2_imputetest/Impute_Experiments/utils.py", line 200, in load_task
    task = openml.tasks.get_task(task_id)
  File "/home/ketrong/miniconda3/envs/tpot2devenv/lib/python3.10/site-packages/openml/tasks/functions.py", line 415, in get_task
    raise e
  File "/home/ketrong/miniconda3/envs/tpot2devenv/lib/python3.10/site-packages/openml/tasks/functions.py", line 398, in get_task
    task = _get_task_description(task_id)
  File "/home/ketrong/miniconda3/envs/tpot2devenv/lib/python3.10/site-packages/openml/tasks/functions.py", line 435, in _get_task_description
    return _create_task_from_xml(task_xml)
  File "/home/ketrong/miniconda3/envs/tpot2devenv/lib/python3.10/site-packages/openml/tasks/functions.py", line 510, in _create_task_from_xml
    raise NotImplementedError("Task type %s not supported." % common_kwargs["task_type"])
NotImplementedError: Task type Supervised Data Stream Classification not supported.

183
remove from investigation?
183
finished
working on 
logs/184/tpot2_base_normal_MNAR_0.9
0.017996788024902344
loading data
logs/184/tpot2_base_normal_MNAR_0.9/data/184_True.pkl
Task type Supervised Data Stream Classification not supported.
Traceback (most recent call last):
  File "/home/ketrong/miniconda3/envs/tpot2devenv/lib/python3.10/site-packages/openml/tasks/functions.py", line 70, in _get_cached_task
    with io.open(os.path.join(tid_cache_dir, "task.xml"), encoding="utf8") as fh:
FileNotFoundError: [Errno 2] No such file or directory: '/home/ketrong/.cache/openml/org/openml/www/tasks/184/task.xml'

During handling of the above exception, another exception occurred:

Traceback (most recent call last):
  File "/home/ketrong/miniconda3/envs/tpot2devenv/lib/python3.10/site-packages/openml/tasks/functions.py", line 422, in _get_task_description
    return _get_cached_task(task_id)
  File "/home/ketrong/miniconda3/envs/tpot2devenv/lib/python3.10/site-packages/openml/tasks/functions.py", line 74, in _get_cached_task
    raise OpenMLCacheException("Task file for tid %d not " "cached" % tid)
openml.exceptions.OpenMLCacheException: Task file for tid 184 not cached

During handling of the above exception, another exception occurred:

Traceback (most recent call last):
  File "/common/ketrong/AutoImputeExp/tpot2_imputetest/Impute_Experiments/utils.py", line 310, in loop_through_tasks
    X_train, y_train, X_test, y_test = load_task(base_save_folder=base_save_folder, exp=exp, type=type, levelstr=levelstr, task_id=taskid, preprocess=True)
  File "/common/ketrong/AutoImputeExp/tpot2_imputetest/Impute_Experiments/utils.py", line 200, in load_task
    task = openml.tasks.get_task(task_id)
  File "/home/ketrong/miniconda3/envs/tpot2devenv/lib/python3.10/site-packages/openml/tasks/functions.py", line 415, in get_task
    raise e
  File "/home/ketrong/miniconda3/envs/tpot2devenv/lib/python3.10/site-packages/openml/tasks/functions.py", line 398, in get_task
    task = _get_task_description(task_id)
  File "/home/ketrong/miniconda3/envs/tpot2devenv/lib/python3.10/site-packages/openml/tasks/functions.py", line 435, in _get_task_description
    return _create_task_from_xml(task_xml)
  File "/home/ketrong/miniconda3/envs/tpot2devenv/lib/python3.10/site-packages/openml/tasks/functions.py", line 510, in _create_task_from_xml
    raise NotImplementedError("Task type %s not supported." % common_kwargs["task_type"])
NotImplementedError: Task type Supervised Data Stream Classification not supported.

184
remove from investigation?
working on 
logs/184/tpot2_base_imputation_MNAR_0.9
0.01800084114074707
loading data
logs/184/tpot2_base_imputation_MNAR_0.9/data/184_True.pkl
Task type Supervised Data Stream Classification not supported.
Traceback (most recent call last):
  File "/home/ketrong/miniconda3/envs/tpot2devenv/lib/python3.10/site-packages/openml/tasks/functions.py", line 70, in _get_cached_task
    with io.open(os.path.join(tid_cache_dir, "task.xml"), encoding="utf8") as fh:
FileNotFoundError: [Errno 2] No such file or directory: '/home/ketrong/.cache/openml/org/openml/www/tasks/184/task.xml'

During handling of the above exception, another exception occurred:

Traceback (most recent call last):
  File "/home/ketrong/miniconda3/envs/tpot2devenv/lib/python3.10/site-packages/openml/tasks/functions.py", line 422, in _get_task_description
    return _get_cached_task(task_id)
  File "/home/ketrong/miniconda3/envs/tpot2devenv/lib/python3.10/site-packages/openml/tasks/functions.py", line 74, in _get_cached_task
    raise OpenMLCacheException("Task file for tid %d not " "cached" % tid)
openml.exceptions.OpenMLCacheException: Task file for tid 184 not cached

During handling of the above exception, another exception occurred:

Traceback (most recent call last):
  File "/common/ketrong/AutoImputeExp/tpot2_imputetest/Impute_Experiments/utils.py", line 310, in loop_through_tasks
    X_train, y_train, X_test, y_test = load_task(base_save_folder=base_save_folder, exp=exp, type=type, levelstr=levelstr, task_id=taskid, preprocess=True)
  File "/common/ketrong/AutoImputeExp/tpot2_imputetest/Impute_Experiments/utils.py", line 200, in load_task
    task = openml.tasks.get_task(task_id)
  File "/home/ketrong/miniconda3/envs/tpot2devenv/lib/python3.10/site-packages/openml/tasks/functions.py", line 415, in get_task
    raise e
  File "/home/ketrong/miniconda3/envs/tpot2devenv/lib/python3.10/site-packages/openml/tasks/functions.py", line 398, in get_task
    task = _get_task_description(task_id)
  File "/home/ketrong/miniconda3/envs/tpot2devenv/lib/python3.10/site-packages/openml/tasks/functions.py", line 435, in _get_task_description
    return _create_task_from_xml(task_xml)
  File "/home/ketrong/miniconda3/envs/tpot2devenv/lib/python3.10/site-packages/openml/tasks/functions.py", line 510, in _create_task_from_xml
    raise NotImplementedError("Task type %s not supported." % common_kwargs["task_type"])
NotImplementedError: Task type Supervised Data Stream Classification not supported.

184
remove from investigation?
184
finished
working on 
logs/189/tpot2_base_normal_MNAR_0.9
2.3665273189544678
loading data
logs/189/tpot2_base_normal_MNAR_0.9/data/189_True.pkl
Task type Supervised Data Stream Classification not supported.
Traceback (most recent call last):
  File "/home/ketrong/miniconda3/envs/tpot2devenv/lib/python3.10/site-packages/openml/tasks/functions.py", line 70, in _get_cached_task
    with io.open(os.path.join(tid_cache_dir, "task.xml"), encoding="utf8") as fh:
FileNotFoundError: [Errno 2] No such file or directory: '/home/ketrong/.cache/openml/org/openml/www/tasks/189/task.xml'

During handling of the above exception, another exception occurred:

Traceback (most recent call last):
  File "/home/ketrong/miniconda3/envs/tpot2devenv/lib/python3.10/site-packages/openml/tasks/functions.py", line 422, in _get_task_description
    return _get_cached_task(task_id)
  File "/home/ketrong/miniconda3/envs/tpot2devenv/lib/python3.10/site-packages/openml/tasks/functions.py", line 74, in _get_cached_task
    raise OpenMLCacheException("Task file for tid %d not " "cached" % tid)
openml.exceptions.OpenMLCacheException: Task file for tid 189 not cached

During handling of the above exception, another exception occurred:

Traceback (most recent call last):
  File "/common/ketrong/AutoImputeExp/tpot2_imputetest/Impute_Experiments/utils.py", line 310, in loop_through_tasks
    X_train, y_train, X_test, y_test = load_task(base_save_folder=base_save_folder, exp=exp, type=type, levelstr=levelstr, task_id=taskid, preprocess=True)
  File "/common/ketrong/AutoImputeExp/tpot2_imputetest/Impute_Experiments/utils.py", line 200, in load_task
    task = openml.tasks.get_task(task_id)
  File "/home/ketrong/miniconda3/envs/tpot2devenv/lib/python3.10/site-packages/openml/tasks/functions.py", line 415, in get_task
    raise e
  File "/home/ketrong/miniconda3/envs/tpot2devenv/lib/python3.10/site-packages/openml/tasks/functions.py", line 398, in get_task
    task = _get_task_description(task_id)
  File "/home/ketrong/miniconda3/envs/tpot2devenv/lib/python3.10/site-packages/openml/tasks/functions.py", line 435, in _get_task_description
    return _create_task_from_xml(task_xml)
  File "/home/ketrong/miniconda3/envs/tpot2devenv/lib/python3.10/site-packages/openml/tasks/functions.py", line 510, in _create_task_from_xml
    raise NotImplementedError("Task type %s not supported." % common_kwargs["task_type"])
NotImplementedError: Task type Supervised Data Stream Classification not supported.

189
remove from investigation?
working on 
logs/189/tpot2_base_imputation_MNAR_0.9
1.0367436408996582
loading data
logs/189/tpot2_base_imputation_MNAR_0.9/data/189_True.pkl
Task type Supervised Data Stream Classification not supported.
Traceback (most recent call last):
  File "/home/ketrong/miniconda3/envs/tpot2devenv/lib/python3.10/site-packages/openml/tasks/functions.py", line 70, in _get_cached_task
    with io.open(os.path.join(tid_cache_dir, "task.xml"), encoding="utf8") as fh:
FileNotFoundError: [Errno 2] No such file or directory: '/home/ketrong/.cache/openml/org/openml/www/tasks/189/task.xml'

During handling of the above exception, another exception occurred:

Traceback (most recent call last):
  File "/home/ketrong/miniconda3/envs/tpot2devenv/lib/python3.10/site-packages/openml/tasks/functions.py", line 422, in _get_task_description
    return _get_cached_task(task_id)
  File "/home/ketrong/miniconda3/envs/tpot2devenv/lib/python3.10/site-packages/openml/tasks/functions.py", line 74, in _get_cached_task
    raise OpenMLCacheException("Task file for tid %d not " "cached" % tid)
openml.exceptions.OpenMLCacheException: Task file for tid 189 not cached

During handling of the above exception, another exception occurred:

Traceback (most recent call last):
  File "/common/ketrong/AutoImputeExp/tpot2_imputetest/Impute_Experiments/utils.py", line 310, in loop_through_tasks
    X_train, y_train, X_test, y_test = load_task(base_save_folder=base_save_folder, exp=exp, type=type, levelstr=levelstr, task_id=taskid, preprocess=True)
  File "/common/ketrong/AutoImputeExp/tpot2_imputetest/Impute_Experiments/utils.py", line 200, in load_task
    task = openml.tasks.get_task(task_id)
  File "/home/ketrong/miniconda3/envs/tpot2devenv/lib/python3.10/site-packages/openml/tasks/functions.py", line 415, in get_task
    raise e
  File "/home/ketrong/miniconda3/envs/tpot2devenv/lib/python3.10/site-packages/openml/tasks/functions.py", line 398, in get_task
    task = _get_task_description(task_id)
  File "/home/ketrong/miniconda3/envs/tpot2devenv/lib/python3.10/site-packages/openml/tasks/functions.py", line 435, in _get_task_description
    return _create_task_from_xml(task_xml)
  File "/home/ketrong/miniconda3/envs/tpot2devenv/lib/python3.10/site-packages/openml/tasks/functions.py", line 510, in _create_task_from_xml
    raise NotImplementedError("Task type %s not supported." % common_kwargs["task_type"])
NotImplementedError: Task type Supervised Data Stream Classification not supported.

189
remove from investigation?
189
finished
working on 
logs/197/tpot2_base_normal_MNAR_0.9
0.07079529762268066
loading data
logs/197/tpot2_base_normal_MNAR_0.9/data/197_True.pkl
Task type Supervised Data Stream Classification not supported.
Traceback (most recent call last):
  File "/home/ketrong/miniconda3/envs/tpot2devenv/lib/python3.10/site-packages/openml/tasks/functions.py", line 70, in _get_cached_task
    with io.open(os.path.join(tid_cache_dir, "task.xml"), encoding="utf8") as fh:
FileNotFoundError: [Errno 2] No such file or directory: '/home/ketrong/.cache/openml/org/openml/www/tasks/197/task.xml'

During handling of the above exception, another exception occurred:

Traceback (most recent call last):
  File "/home/ketrong/miniconda3/envs/tpot2devenv/lib/python3.10/site-packages/openml/tasks/functions.py", line 422, in _get_task_description
    return _get_cached_task(task_id)
  File "/home/ketrong/miniconda3/envs/tpot2devenv/lib/python3.10/site-packages/openml/tasks/functions.py", line 74, in _get_cached_task
    raise OpenMLCacheException("Task file for tid %d not " "cached" % tid)
openml.exceptions.OpenMLCacheException: Task file for tid 197 not cached

During handling of the above exception, another exception occurred:

Traceback (most recent call last):
  File "/common/ketrong/AutoImputeExp/tpot2_imputetest/Impute_Experiments/utils.py", line 310, in loop_through_tasks
    X_train, y_train, X_test, y_test = load_task(base_save_folder=base_save_folder, exp=exp, type=type, levelstr=levelstr, task_id=taskid, preprocess=True)
  File "/common/ketrong/AutoImputeExp/tpot2_imputetest/Impute_Experiments/utils.py", line 200, in load_task
    task = openml.tasks.get_task(task_id)
  File "/home/ketrong/miniconda3/envs/tpot2devenv/lib/python3.10/site-packages/openml/tasks/functions.py", line 415, in get_task
    raise e
  File "/home/ketrong/miniconda3/envs/tpot2devenv/lib/python3.10/site-packages/openml/tasks/functions.py", line 398, in get_task
    task = _get_task_description(task_id)
  File "/home/ketrong/miniconda3/envs/tpot2devenv/lib/python3.10/site-packages/openml/tasks/functions.py", line 435, in _get_task_description
    return _create_task_from_xml(task_xml)
  File "/home/ketrong/miniconda3/envs/tpot2devenv/lib/python3.10/site-packages/openml/tasks/functions.py", line 510, in _create_task_from_xml
    raise NotImplementedError("Task type %s not supported." % common_kwargs["task_type"])
NotImplementedError: Task type Supervised Data Stream Classification not supported.

197
remove from investigation?
working on 
logs/197/tpot2_base_imputation_MNAR_0.9
4.854938268661499
loading data
logs/197/tpot2_base_imputation_MNAR_0.9/data/197_True.pkl
Task type Supervised Data Stream Classification not supported.
Traceback (most recent call last):
  File "/home/ketrong/miniconda3/envs/tpot2devenv/lib/python3.10/site-packages/openml/tasks/functions.py", line 70, in _get_cached_task
    with io.open(os.path.join(tid_cache_dir, "task.xml"), encoding="utf8") as fh:
FileNotFoundError: [Errno 2] No such file or directory: '/home/ketrong/.cache/openml/org/openml/www/tasks/197/task.xml'

During handling of the above exception, another exception occurred:

Traceback (most recent call last):
  File "/home/ketrong/miniconda3/envs/tpot2devenv/lib/python3.10/site-packages/openml/tasks/functions.py", line 422, in _get_task_description
    return _get_cached_task(task_id)
  File "/home/ketrong/miniconda3/envs/tpot2devenv/lib/python3.10/site-packages/openml/tasks/functions.py", line 74, in _get_cached_task
    raise OpenMLCacheException("Task file for tid %d not " "cached" % tid)
openml.exceptions.OpenMLCacheException: Task file for tid 197 not cached

During handling of the above exception, another exception occurred:

Traceback (most recent call last):
  File "/common/ketrong/AutoImputeExp/tpot2_imputetest/Impute_Experiments/utils.py", line 310, in loop_through_tasks
    X_train, y_train, X_test, y_test = load_task(base_save_folder=base_save_folder, exp=exp, type=type, levelstr=levelstr, task_id=taskid, preprocess=True)
  File "/common/ketrong/AutoImputeExp/tpot2_imputetest/Impute_Experiments/utils.py", line 200, in load_task
    task = openml.tasks.get_task(task_id)
  File "/home/ketrong/miniconda3/envs/tpot2devenv/lib/python3.10/site-packages/openml/tasks/functions.py", line 415, in get_task
    raise e
  File "/home/ketrong/miniconda3/envs/tpot2devenv/lib/python3.10/site-packages/openml/tasks/functions.py", line 398, in get_task
    task = _get_task_description(task_id)
  File "/home/ketrong/miniconda3/envs/tpot2devenv/lib/python3.10/site-packages/openml/tasks/functions.py", line 435, in _get_task_description
    return _create_task_from_xml(task_xml)
  File "/home/ketrong/miniconda3/envs/tpot2devenv/lib/python3.10/site-packages/openml/tasks/functions.py", line 510, in _create_task_from_xml
    raise NotImplementedError("Task type %s not supported." % common_kwargs["task_type"])
NotImplementedError: Task type Supervised Data Stream Classification not supported.

197
remove from investigation?
197
finished
working on 
logs/198/tpot2_base_normal_MNAR_0.9
3.7558438777923584
loading data
logs/198/tpot2_base_normal_MNAR_0.9/data/198_True.pkl
Task type Supervised Data Stream Classification not supported.
Traceback (most recent call last):
  File "/home/ketrong/miniconda3/envs/tpot2devenv/lib/python3.10/site-packages/openml/tasks/functions.py", line 70, in _get_cached_task
    with io.open(os.path.join(tid_cache_dir, "task.xml"), encoding="utf8") as fh:
FileNotFoundError: [Errno 2] No such file or directory: '/home/ketrong/.cache/openml/org/openml/www/tasks/198/task.xml'

During handling of the above exception, another exception occurred:

Traceback (most recent call last):
  File "/home/ketrong/miniconda3/envs/tpot2devenv/lib/python3.10/site-packages/openml/tasks/functions.py", line 422, in _get_task_description
    return _get_cached_task(task_id)
  File "/home/ketrong/miniconda3/envs/tpot2devenv/lib/python3.10/site-packages/openml/tasks/functions.py", line 74, in _get_cached_task
    raise OpenMLCacheException("Task file for tid %d not " "cached" % tid)
openml.exceptions.OpenMLCacheException: Task file for tid 198 not cached

During handling of the above exception, another exception occurred:

Traceback (most recent call last):
  File "/common/ketrong/AutoImputeExp/tpot2_imputetest/Impute_Experiments/utils.py", line 310, in loop_through_tasks
    X_train, y_train, X_test, y_test = load_task(base_save_folder=base_save_folder, exp=exp, type=type, levelstr=levelstr, task_id=taskid, preprocess=True)
  File "/common/ketrong/AutoImputeExp/tpot2_imputetest/Impute_Experiments/utils.py", line 200, in load_task
    task = openml.tasks.get_task(task_id)
  File "/home/ketrong/miniconda3/envs/tpot2devenv/lib/python3.10/site-packages/openml/tasks/functions.py", line 415, in get_task
    raise e
  File "/home/ketrong/miniconda3/envs/tpot2devenv/lib/python3.10/site-packages/openml/tasks/functions.py", line 398, in get_task
    task = _get_task_description(task_id)
  File "/home/ketrong/miniconda3/envs/tpot2devenv/lib/python3.10/site-packages/openml/tasks/functions.py", line 435, in _get_task_description
    return _create_task_from_xml(task_xml)
  File "/home/ketrong/miniconda3/envs/tpot2devenv/lib/python3.10/site-packages/openml/tasks/functions.py", line 510, in _create_task_from_xml
    raise NotImplementedError("Task type %s not supported." % common_kwargs["task_type"])
NotImplementedError: Task type Supervised Data Stream Classification not supported.

198
remove from investigation?
working on 
logs/198/tpot2_base_imputation_MNAR_0.9
4.628477573394775
loading data
logs/198/tpot2_base_imputation_MNAR_0.9/data/198_True.pkl
Task type Supervised Data Stream Classification not supported.
Traceback (most recent call last):
  File "/home/ketrong/miniconda3/envs/tpot2devenv/lib/python3.10/site-packages/openml/tasks/functions.py", line 70, in _get_cached_task
    with io.open(os.path.join(tid_cache_dir, "task.xml"), encoding="utf8") as fh:
FileNotFoundError: [Errno 2] No such file or directory: '/home/ketrong/.cache/openml/org/openml/www/tasks/198/task.xml'

During handling of the above exception, another exception occurred:

Traceback (most recent call last):
  File "/home/ketrong/miniconda3/envs/tpot2devenv/lib/python3.10/site-packages/openml/tasks/functions.py", line 422, in _get_task_description
    return _get_cached_task(task_id)
  File "/home/ketrong/miniconda3/envs/tpot2devenv/lib/python3.10/site-packages/openml/tasks/functions.py", line 74, in _get_cached_task
    raise OpenMLCacheException("Task file for tid %d not " "cached" % tid)
openml.exceptions.OpenMLCacheException: Task file for tid 198 not cached

During handling of the above exception, another exception occurred:

Traceback (most recent call last):
  File "/common/ketrong/AutoImputeExp/tpot2_imputetest/Impute_Experiments/utils.py", line 310, in loop_through_tasks
    X_train, y_train, X_test, y_test = load_task(base_save_folder=base_save_folder, exp=exp, type=type, levelstr=levelstr, task_id=taskid, preprocess=True)
  File "/common/ketrong/AutoImputeExp/tpot2_imputetest/Impute_Experiments/utils.py", line 200, in load_task
    task = openml.tasks.get_task(task_id)
  File "/home/ketrong/miniconda3/envs/tpot2devenv/lib/python3.10/site-packages/openml/tasks/functions.py", line 415, in get_task
    raise e
  File "/home/ketrong/miniconda3/envs/tpot2devenv/lib/python3.10/site-packages/openml/tasks/functions.py", line 398, in get_task
    task = _get_task_description(task_id)
  File "/home/ketrong/miniconda3/envs/tpot2devenv/lib/python3.10/site-packages/openml/tasks/functions.py", line 435, in _get_task_description
    return _create_task_from_xml(task_xml)
  File "/home/ketrong/miniconda3/envs/tpot2devenv/lib/python3.10/site-packages/openml/tasks/functions.py", line 510, in _create_task_from_xml
    raise NotImplementedError("Task type %s not supported." % common_kwargs["task_type"])
NotImplementedError: Task type Supervised Data Stream Classification not supported.

198
remove from investigation?
198
finished
working on 
logs/215/tpot2_base_normal_MNAR_0.9
2.2003912925720215
loading data
logs/215/tpot2_base_normal_MNAR_0.9/data/215_True.pkl
working on 
logs/215/tpot2_base_imputation_MNAR_0.9
3.997188091278076
loading data
logs/215/tpot2_base_imputation_MNAR_0.9/data/215_True.pkl
215
finished
working on 
logs/216/tpot2_base_normal_MNAR_0.9
2.011307716369629
loading data
logs/216/tpot2_base_normal_MNAR_0.9/data/216_True.pkl
Split arff /home/ketrong/.cache/openml/org/openml/www/tasks/216/datasplits.arff does not exist!
Traceback (most recent call last):
  File "/home/ketrong/miniconda3/envs/tpot2devenv/lib/python3.10/site-packages/openml/tasks/task.py", line 157, in download_split
    split = OpenMLSplit._from_arff_file(cached_split_file)
  File "/home/ketrong/miniconda3/envs/tpot2devenv/lib/python3.10/site-packages/openml/tasks/split.py", line 87, in _from_arff_file
    raise FileNotFoundError("Split arff %s does not exist!" % filename)
FileNotFoundError: Split arff /home/ketrong/.cache/openml/org/openml/www/tasks/216/datasplits.arff does not exist!

During handling of the above exception, another exception occurred:

Traceback (most recent call last):
  File "/common/ketrong/AutoImputeExp/tpot2_imputetest/Impute_Experiments/utils.py", line 310, in loop_through_tasks
    X_train, y_train, X_test, y_test = load_task(base_save_folder=base_save_folder, exp=exp, type=type, levelstr=levelstr, task_id=taskid, preprocess=True)
  File "/common/ketrong/AutoImputeExp/tpot2_imputetest/Impute_Experiments/utils.py", line 200, in load_task
    task = openml.tasks.get_task(task_id)
  File "/home/ketrong/miniconda3/envs/tpot2devenv/lib/python3.10/site-packages/openml/tasks/functions.py", line 415, in get_task
    raise e
  File "/home/ketrong/miniconda3/envs/tpot2devenv/lib/python3.10/site-packages/openml/tasks/functions.py", line 409, in get_task
    task.download_split()
  File "/home/ketrong/miniconda3/envs/tpot2devenv/lib/python3.10/site-packages/openml/tasks/task.py", line 161, in download_split
    split = OpenMLSplit._from_arff_file(cached_split_file)
  File "/home/ketrong/miniconda3/envs/tpot2devenv/lib/python3.10/site-packages/openml/tasks/split.py", line 87, in _from_arff_file
    raise FileNotFoundError("Split arff %s does not exist!" % filename)
FileNotFoundError: Split arff /home/ketrong/.cache/openml/org/openml/www/tasks/216/datasplits.arff does not exist!

216
remove from investigation?
working on 
logs/216/tpot2_base_imputation_MNAR_0.9
4.962107181549072
loading data
logs/216/tpot2_base_imputation_MNAR_0.9/data/216_True.pkl
Cannot remove faulty tasks cache directory /home/ketrong/.cache/openml/org/openml/www/tasks/216.Please do this manually!
Traceback (most recent call last):
  File "/home/ketrong/miniconda3/envs/tpot2devenv/lib/python3.10/site-packages/openml/tasks/task.py", line 157, in download_split
    split = OpenMLSplit._from_arff_file(cached_split_file)
  File "/home/ketrong/miniconda3/envs/tpot2devenv/lib/python3.10/site-packages/openml/tasks/split.py", line 87, in _from_arff_file
    raise FileNotFoundError("Split arff %s does not exist!" % filename)
FileNotFoundError: Split arff /home/ketrong/.cache/openml/org/openml/www/tasks/216/datasplits.arff does not exist!

During handling of the above exception, another exception occurred:

Traceback (most recent call last):
  File "/home/ketrong/miniconda3/envs/tpot2devenv/lib/python3.10/site-packages/openml/tasks/functions.py", line 409, in get_task
    task.download_split()
  File "/home/ketrong/miniconda3/envs/tpot2devenv/lib/python3.10/site-packages/openml/tasks/task.py", line 161, in download_split
    split = OpenMLSplit._from_arff_file(cached_split_file)
  File "/home/ketrong/miniconda3/envs/tpot2devenv/lib/python3.10/site-packages/openml/tasks/split.py", line 88, in _from_arff_file
    file_data = arff.load(open(filename), return_type=arff.DENSE_GEN)
  File "/home/ketrong/miniconda3/envs/tpot2devenv/lib/python3.10/site-packages/arff.py", line 1059, in load
    return decoder.decode(fp, encode_nominal=encode_nominal,
  File "/home/ketrong/miniconda3/envs/tpot2devenv/lib/python3.10/site-packages/arff.py", line 896, in decode
    raise e
  File "/home/ketrong/miniconda3/envs/tpot2devenv/lib/python3.10/site-packages/arff.py", line 892, in decode
    return self._decode(s, encode_nominal=encode_nominal,
  File "/home/ketrong/miniconda3/envs/tpot2devenv/lib/python3.10/site-packages/arff.py", line 813, in _decode
    obj['relation'] = self._decode_relation(row)
  File "/home/ketrong/miniconda3/envs/tpot2devenv/lib/python3.10/site-packages/arff.py", line 706, in _decode_relation
    raise BadRelationFormat()
arff.BadRelationFormat: Bad @RELATION format, at line 1.

During handling of the above exception, another exception occurred:

Traceback (most recent call last):
  File "/home/ketrong/miniconda3/envs/tpot2devenv/lib/python3.10/site-packages/openml/utils.py", line 375, in _remove_cache_dir_for_id
    shutil.rmtree(cache_dir)
  File "/home/ketrong/miniconda3/envs/tpot2devenv/lib/python3.10/shutil.py", line 731, in rmtree
    onerror(os.rmdir, path, sys.exc_info())
  File "/home/ketrong/miniconda3/envs/tpot2devenv/lib/python3.10/shutil.py", line 729, in rmtree
    os.rmdir(path)
OSError: [Errno 39] Directory not empty: '/home/ketrong/.cache/openml/org/openml/www/tasks/216'

During handling of the above exception, another exception occurred:

Traceback (most recent call last):
  File "/common/ketrong/AutoImputeExp/tpot2_imputetest/Impute_Experiments/utils.py", line 310, in loop_through_tasks
    X_train, y_train, X_test, y_test = load_task(base_save_folder=base_save_folder, exp=exp, type=type, levelstr=levelstr, task_id=taskid, preprocess=True)
  File "/common/ketrong/AutoImputeExp/tpot2_imputetest/Impute_Experiments/utils.py", line 200, in load_task
    task = openml.tasks.get_task(task_id)
  File "/home/ketrong/miniconda3/envs/tpot2devenv/lib/python3.10/site-packages/openml/tasks/functions.py", line 411, in get_task
    openml.utils._remove_cache_dir_for_id(
  File "/home/ketrong/miniconda3/envs/tpot2devenv/lib/python3.10/site-packages/openml/utils.py", line 377, in _remove_cache_dir_for_id
    raise ValueError(
ValueError: Cannot remove faulty tasks cache directory /home/ketrong/.cache/openml/org/openml/www/tasks/216.Please do this manually!

216
remove from investigation?
216
finished
working on 
logs/218/tpot2_base_normal_MNAR_0.9
1.837374210357666
loading data
logs/218/tpot2_base_normal_MNAR_0.9/data/218_True.pkl
working on 
logs/218/tpot2_base_imputation_MNAR_0.9
2.5697925090789795
loading data
logs/218/tpot2_base_imputation_MNAR_0.9/data/218_True.pkl
218
finished
working on 
logs/251/tpot2_base_normal_MNAR_0.9
2.2763967514038086
loading data
logs/251/tpot2_base_normal_MNAR_0.9/data/251_True.pkl
WARNING:openml.datasets.functions:Could not download file from http://openml1.win.tue.nl/dataset21/dataset_21.pq: Bucket does not exist or is private.
WARNING:openml.datasets.functions:Failed to download parquet, fallback on ARFF.
WARNING:openml.datasets.functions:Could not download file from http://openml1.win.tue.nl/dataset21/dataset_21.pq: Bucket does not exist or is private.
WARNING:openml.datasets.functions:Failed to download parquet, fallback on ARFF.
working on 
logs/251/tpot2_base_imputation_MNAR_0.9
0.9545555114746094
loading data
logs/251/tpot2_base_imputation_MNAR_0.9/data/251_True.pkl
WARNING:openml.datasets.functions:Could not download file from http://openml1.win.tue.nl/dataset21/dataset_21.pq: Bucket does not exist or is private.
WARNING:openml.datasets.functions:Failed to download parquet, fallback on ARFF.
WARNING:openml.datasets.functions:Could not download file from http://openml1.win.tue.nl/dataset21/dataset_21.pq: Bucket does not exist or is private.
WARNING:openml.datasets.functions:Failed to download parquet, fallback on ARFF.
251
finished
working on 
logs/287/tpot2_base_normal_MNAR_0.9
4.43200159072876
loading data
logs/287/tpot2_base_normal_MNAR_0.9/data/287_True.pkl
working on 
logs/287/tpot2_base_imputation_MNAR_0.9
1.3065555095672607
loading data
logs/287/tpot2_base_imputation_MNAR_0.9/data/287_True.pkl
287
finished
working on 
logs/310/tpot2_base_normal_MNAR_0.9
0.11561155319213867
loading data
logs/310/tpot2_base_normal_MNAR_0.9/data/310_True.pkl
Cannot remove faulty tasks cache directory /home/ketrong/.cache/openml/org/openml/www/tasks/310.Please do this manually!
Traceback (most recent call last):
  File "/home/ketrong/miniconda3/envs/tpot2devenv/lib/python3.10/site-packages/openml/tasks/task.py", line 157, in download_split
    split = OpenMLSplit._from_arff_file(cached_split_file)
  File "/home/ketrong/miniconda3/envs/tpot2devenv/lib/python3.10/site-packages/openml/tasks/split.py", line 87, in _from_arff_file
    raise FileNotFoundError("Split arff %s does not exist!" % filename)
FileNotFoundError: Split arff /home/ketrong/.cache/openml/org/openml/www/tasks/310/datasplits.arff does not exist!

During handling of the above exception, another exception occurred:

Traceback (most recent call last):
  File "/home/ketrong/miniconda3/envs/tpot2devenv/lib/python3.10/site-packages/openml/tasks/functions.py", line 409, in get_task
    task.download_split()
  File "/home/ketrong/miniconda3/envs/tpot2devenv/lib/python3.10/site-packages/openml/tasks/task.py", line 161, in download_split
    split = OpenMLSplit._from_arff_file(cached_split_file)
  File "/home/ketrong/miniconda3/envs/tpot2devenv/lib/python3.10/site-packages/openml/tasks/split.py", line 88, in _from_arff_file
    file_data = arff.load(open(filename), return_type=arff.DENSE_GEN)
  File "/home/ketrong/miniconda3/envs/tpot2devenv/lib/python3.10/site-packages/arff.py", line 1059, in load
    return decoder.decode(fp, encode_nominal=encode_nominal,
  File "/home/ketrong/miniconda3/envs/tpot2devenv/lib/python3.10/site-packages/arff.py", line 896, in decode
    raise e
  File "/home/ketrong/miniconda3/envs/tpot2devenv/lib/python3.10/site-packages/arff.py", line 892, in decode
    return self._decode(s, encode_nominal=encode_nominal,
  File "/home/ketrong/miniconda3/envs/tpot2devenv/lib/python3.10/site-packages/arff.py", line 813, in _decode
    obj['relation'] = self._decode_relation(row)
  File "/home/ketrong/miniconda3/envs/tpot2devenv/lib/python3.10/site-packages/arff.py", line 706, in _decode_relation
    raise BadRelationFormat()
arff.BadRelationFormat: Bad @RELATION format, at line 1.

During handling of the above exception, another exception occurred:

Traceback (most recent call last):
  File "/home/ketrong/miniconda3/envs/tpot2devenv/lib/python3.10/site-packages/openml/utils.py", line 375, in _remove_cache_dir_for_id
    shutil.rmtree(cache_dir)
  File "/home/ketrong/miniconda3/envs/tpot2devenv/lib/python3.10/shutil.py", line 731, in rmtree
    onerror(os.rmdir, path, sys.exc_info())
  File "/home/ketrong/miniconda3/envs/tpot2devenv/lib/python3.10/shutil.py", line 729, in rmtree
    os.rmdir(path)
OSError: [Errno 39] Directory not empty: '/home/ketrong/.cache/openml/org/openml/www/tasks/310'

During handling of the above exception, another exception occurred:

Traceback (most recent call last):
  File "/common/ketrong/AutoImputeExp/tpot2_imputetest/Impute_Experiments/utils.py", line 310, in loop_through_tasks
    X_train, y_train, X_test, y_test = load_task(base_save_folder=base_save_folder, exp=exp, type=type, levelstr=levelstr, task_id=taskid, preprocess=True)
  File "/common/ketrong/AutoImputeExp/tpot2_imputetest/Impute_Experiments/utils.py", line 200, in load_task
    task = openml.tasks.get_task(task_id)
  File "/home/ketrong/miniconda3/envs/tpot2devenv/lib/python3.10/site-packages/openml/tasks/functions.py", line 411, in get_task
    openml.utils._remove_cache_dir_for_id(
  File "/home/ketrong/miniconda3/envs/tpot2devenv/lib/python3.10/site-packages/openml/utils.py", line 377, in _remove_cache_dir_for_id
    raise ValueError(
ValueError: Cannot remove faulty tasks cache directory /home/ketrong/.cache/openml/org/openml/www/tasks/310.Please do this manually!

310
remove from investigation?
working on 
logs/310/tpot2_base_imputation_MNAR_0.9
4.936991453170776
loading data
logs/310/tpot2_base_imputation_MNAR_0.9/data/310_True.pkl
Cannot remove faulty tasks cache directory /home/ketrong/.cache/openml/org/openml/www/tasks/310.Please do this manually!
Traceback (most recent call last):
  File "/home/ketrong/miniconda3/envs/tpot2devenv/lib/python3.10/site-packages/openml/tasks/task.py", line 157, in download_split
    split = OpenMLSplit._from_arff_file(cached_split_file)
  File "/home/ketrong/miniconda3/envs/tpot2devenv/lib/python3.10/site-packages/openml/tasks/split.py", line 87, in _from_arff_file
    raise FileNotFoundError("Split arff %s does not exist!" % filename)
FileNotFoundError: Split arff /home/ketrong/.cache/openml/org/openml/www/tasks/310/datasplits.arff does not exist!

During handling of the above exception, another exception occurred:

Traceback (most recent call last):
  File "/home/ketrong/miniconda3/envs/tpot2devenv/lib/python3.10/site-packages/openml/tasks/functions.py", line 409, in get_task
    task.download_split()
  File "/home/ketrong/miniconda3/envs/tpot2devenv/lib/python3.10/site-packages/openml/tasks/task.py", line 161, in download_split
    split = OpenMLSplit._from_arff_file(cached_split_file)
  File "/home/ketrong/miniconda3/envs/tpot2devenv/lib/python3.10/site-packages/openml/tasks/split.py", line 88, in _from_arff_file
    file_data = arff.load(open(filename), return_type=arff.DENSE_GEN)
  File "/home/ketrong/miniconda3/envs/tpot2devenv/lib/python3.10/site-packages/arff.py", line 1059, in load
    return decoder.decode(fp, encode_nominal=encode_nominal,
  File "/home/ketrong/miniconda3/envs/tpot2devenv/lib/python3.10/site-packages/arff.py", line 896, in decode
    raise e
  File "/home/ketrong/miniconda3/envs/tpot2devenv/lib/python3.10/site-packages/arff.py", line 892, in decode
    return self._decode(s, encode_nominal=encode_nominal,
  File "/home/ketrong/miniconda3/envs/tpot2devenv/lib/python3.10/site-packages/arff.py", line 813, in _decode
    obj['relation'] = self._decode_relation(row)
  File "/home/ketrong/miniconda3/envs/tpot2devenv/lib/python3.10/site-packages/arff.py", line 706, in _decode_relation
    raise BadRelationFormat()
arff.BadRelationFormat: Bad @RELATION format, at line 1.

During handling of the above exception, another exception occurred:

Traceback (most recent call last):
  File "/home/ketrong/miniconda3/envs/tpot2devenv/lib/python3.10/site-packages/openml/utils.py", line 375, in _remove_cache_dir_for_id
    shutil.rmtree(cache_dir)
  File "/home/ketrong/miniconda3/envs/tpot2devenv/lib/python3.10/shutil.py", line 731, in rmtree
    onerror(os.rmdir, path, sys.exc_info())
  File "/home/ketrong/miniconda3/envs/tpot2devenv/lib/python3.10/shutil.py", line 729, in rmtree
    os.rmdir(path)
OSError: [Errno 39] Directory not empty: '/home/ketrong/.cache/openml/org/openml/www/tasks/310'

During handling of the above exception, another exception occurred:

Traceback (most recent call last):
  File "/common/ketrong/AutoImputeExp/tpot2_imputetest/Impute_Experiments/utils.py", line 310, in loop_through_tasks
    X_train, y_train, X_test, y_test = load_task(base_save_folder=base_save_folder, exp=exp, type=type, levelstr=levelstr, task_id=taskid, preprocess=True)
  File "/common/ketrong/AutoImputeExp/tpot2_imputetest/Impute_Experiments/utils.py", line 200, in load_task
    task = openml.tasks.get_task(task_id)
  File "/home/ketrong/miniconda3/envs/tpot2devenv/lib/python3.10/site-packages/openml/tasks/functions.py", line 411, in get_task
    openml.utils._remove_cache_dir_for_id(
  File "/home/ketrong/miniconda3/envs/tpot2devenv/lib/python3.10/site-packages/openml/utils.py", line 377, in _remove_cache_dir_for_id
    raise ValueError(
ValueError: Cannot remove faulty tasks cache directory /home/ketrong/.cache/openml/org/openml/www/tasks/310.Please do this manually!

310
remove from investigation?
310
finished
working on 
logs/375/tpot2_base_normal_MNAR_0.9
2.4364962577819824
loading data
logs/375/tpot2_base_normal_MNAR_0.9/data/375_True.pkl
https://www.openml.org/api/v1/xml/task/375 returned code 151: Unknown task - None
Traceback (most recent call last):
  File "/home/ketrong/miniconda3/envs/tpot2devenv/lib/python3.10/site-packages/openml/tasks/functions.py", line 70, in _get_cached_task
    with io.open(os.path.join(tid_cache_dir, "task.xml"), encoding="utf8") as fh:
FileNotFoundError: [Errno 2] No such file or directory: '/home/ketrong/.cache/openml/org/openml/www/tasks/375/task.xml'

During handling of the above exception, another exception occurred:

Traceback (most recent call last):
  File "/home/ketrong/miniconda3/envs/tpot2devenv/lib/python3.10/site-packages/openml/tasks/functions.py", line 422, in _get_task_description
    return _get_cached_task(task_id)
  File "/home/ketrong/miniconda3/envs/tpot2devenv/lib/python3.10/site-packages/openml/tasks/functions.py", line 74, in _get_cached_task
    raise OpenMLCacheException("Task file for tid %d not " "cached" % tid)
openml.exceptions.OpenMLCacheException: Task file for tid 375 not cached

During handling of the above exception, another exception occurred:

Traceback (most recent call last):
  File "/common/ketrong/AutoImputeExp/tpot2_imputetest/Impute_Experiments/utils.py", line 310, in loop_through_tasks
    X_train, y_train, X_test, y_test = load_task(base_save_folder=base_save_folder, exp=exp, type=type, levelstr=levelstr, task_id=taskid, preprocess=True)
  File "/common/ketrong/AutoImputeExp/tpot2_imputetest/Impute_Experiments/utils.py", line 200, in load_task
    task = openml.tasks.get_task(task_id)
  File "/home/ketrong/miniconda3/envs/tpot2devenv/lib/python3.10/site-packages/openml/tasks/functions.py", line 415, in get_task
    raise e
  File "/home/ketrong/miniconda3/envs/tpot2devenv/lib/python3.10/site-packages/openml/tasks/functions.py", line 398, in get_task
    task = _get_task_description(task_id)
  File "/home/ketrong/miniconda3/envs/tpot2devenv/lib/python3.10/site-packages/openml/tasks/functions.py", line 431, in _get_task_description
    task_xml = openml._api_calls._perform_api_call("task/%d" % task_id, "get")
  File "/home/ketrong/miniconda3/envs/tpot2devenv/lib/python3.10/site-packages/openml/_api_calls.py", line 99, in _perform_api_call
    response = __read_url(url, request_method, data)
  File "/home/ketrong/miniconda3/envs/tpot2devenv/lib/python3.10/site-packages/openml/_api_calls.py", line 308, in __read_url
    return _send_request(
  File "/home/ketrong/miniconda3/envs/tpot2devenv/lib/python3.10/site-packages/openml/_api_calls.py", line 344, in _send_request
    __check_response(response=response, url=url, file_elements=files)
  File "/home/ketrong/miniconda3/envs/tpot2devenv/lib/python3.10/site-packages/openml/_api_calls.py", line 409, in __check_response
    raise __parse_server_exception(response, url, file_elements=file_elements)
openml.exceptions.OpenMLServerException: https://www.openml.org/api/v1/xml/task/375 returned code 151: Unknown task - None

375
remove from investigation?
working on 
logs/375/tpot2_base_imputation_MNAR_0.9
4.18690824508667
loading data
logs/375/tpot2_base_imputation_MNAR_0.9/data/375_True.pkl
https://www.openml.org/api/v1/xml/task/375 returned code 151: Unknown task - None
Traceback (most recent call last):
  File "/home/ketrong/miniconda3/envs/tpot2devenv/lib/python3.10/site-packages/openml/tasks/functions.py", line 70, in _get_cached_task
    with io.open(os.path.join(tid_cache_dir, "task.xml"), encoding="utf8") as fh:
FileNotFoundError: [Errno 2] No such file or directory: '/home/ketrong/.cache/openml/org/openml/www/tasks/375/task.xml'

During handling of the above exception, another exception occurred:

Traceback (most recent call last):
  File "/home/ketrong/miniconda3/envs/tpot2devenv/lib/python3.10/site-packages/openml/tasks/functions.py", line 422, in _get_task_description
    return _get_cached_task(task_id)
  File "/home/ketrong/miniconda3/envs/tpot2devenv/lib/python3.10/site-packages/openml/tasks/functions.py", line 74, in _get_cached_task
    raise OpenMLCacheException("Task file for tid %d not " "cached" % tid)
openml.exceptions.OpenMLCacheException: Task file for tid 375 not cached

During handling of the above exception, another exception occurred:

Traceback (most recent call last):
  File "/common/ketrong/AutoImputeExp/tpot2_imputetest/Impute_Experiments/utils.py", line 310, in loop_through_tasks
    X_train, y_train, X_test, y_test = load_task(base_save_folder=base_save_folder, exp=exp, type=type, levelstr=levelstr, task_id=taskid, preprocess=True)
  File "/common/ketrong/AutoImputeExp/tpot2_imputetest/Impute_Experiments/utils.py", line 200, in load_task
    task = openml.tasks.get_task(task_id)
  File "/home/ketrong/miniconda3/envs/tpot2devenv/lib/python3.10/site-packages/openml/tasks/functions.py", line 415, in get_task
    raise e
  File "/home/ketrong/miniconda3/envs/tpot2devenv/lib/python3.10/site-packages/openml/tasks/functions.py", line 398, in get_task
    task = _get_task_description(task_id)
  File "/home/ketrong/miniconda3/envs/tpot2devenv/lib/python3.10/site-packages/openml/tasks/functions.py", line 431, in _get_task_description
    task_xml = openml._api_calls._perform_api_call("task/%d" % task_id, "get")
  File "/home/ketrong/miniconda3/envs/tpot2devenv/lib/python3.10/site-packages/openml/_api_calls.py", line 99, in _perform_api_call
    response = __read_url(url, request_method, data)
  File "/home/ketrong/miniconda3/envs/tpot2devenv/lib/python3.10/site-packages/openml/_api_calls.py", line 308, in __read_url
    return _send_request(
  File "/home/ketrong/miniconda3/envs/tpot2devenv/lib/python3.10/site-packages/openml/_api_calls.py", line 344, in _send_request
    __check_response(response=response, url=url, file_elements=files)
  File "/home/ketrong/miniconda3/envs/tpot2devenv/lib/python3.10/site-packages/openml/_api_calls.py", line 409, in __check_response
    raise __parse_server_exception(response, url, file_elements=file_elements)
openml.exceptions.OpenMLServerException: https://www.openml.org/api/v1/xml/task/375 returned code 151: Unknown task - None

375
remove from investigation?
375
finished
working on 
logs/725/tpot2_base_normal_MNAR_0.9
0.49443817138671875
loading data
logs/725/tpot2_base_normal_MNAR_0.9/data/725_True.pkl
https://www.openml.org/api/v1/xml/task/725 returned code 151: Unknown task - None
Traceback (most recent call last):
  File "/home/ketrong/miniconda3/envs/tpot2devenv/lib/python3.10/site-packages/openml/tasks/functions.py", line 70, in _get_cached_task
    with io.open(os.path.join(tid_cache_dir, "task.xml"), encoding="utf8") as fh:
FileNotFoundError: [Errno 2] No such file or directory: '/home/ketrong/.cache/openml/org/openml/www/tasks/725/task.xml'

During handling of the above exception, another exception occurred:

Traceback (most recent call last):
  File "/home/ketrong/miniconda3/envs/tpot2devenv/lib/python3.10/site-packages/openml/tasks/functions.py", line 422, in _get_task_description
    return _get_cached_task(task_id)
  File "/home/ketrong/miniconda3/envs/tpot2devenv/lib/python3.10/site-packages/openml/tasks/functions.py", line 74, in _get_cached_task
    raise OpenMLCacheException("Task file for tid %d not " "cached" % tid)
openml.exceptions.OpenMLCacheException: Task file for tid 725 not cached

During handling of the above exception, another exception occurred:

Traceback (most recent call last):
  File "/common/ketrong/AutoImputeExp/tpot2_imputetest/Impute_Experiments/utils.py", line 310, in loop_through_tasks
    X_train, y_train, X_test, y_test = load_task(base_save_folder=base_save_folder, exp=exp, type=type, levelstr=levelstr, task_id=taskid, preprocess=True)
  File "/common/ketrong/AutoImputeExp/tpot2_imputetest/Impute_Experiments/utils.py", line 200, in load_task
    task = openml.tasks.get_task(task_id)
  File "/home/ketrong/miniconda3/envs/tpot2devenv/lib/python3.10/site-packages/openml/tasks/functions.py", line 415, in get_task
    raise e
  File "/home/ketrong/miniconda3/envs/tpot2devenv/lib/python3.10/site-packages/openml/tasks/functions.py", line 398, in get_task
    task = _get_task_description(task_id)
  File "/home/ketrong/miniconda3/envs/tpot2devenv/lib/python3.10/site-packages/openml/tasks/functions.py", line 431, in _get_task_description
    task_xml = openml._api_calls._perform_api_call("task/%d" % task_id, "get")
  File "/home/ketrong/miniconda3/envs/tpot2devenv/lib/python3.10/site-packages/openml/_api_calls.py", line 99, in _perform_api_call
    response = __read_url(url, request_method, data)
  File "/home/ketrong/miniconda3/envs/tpot2devenv/lib/python3.10/site-packages/openml/_api_calls.py", line 308, in __read_url
    return _send_request(
  File "/home/ketrong/miniconda3/envs/tpot2devenv/lib/python3.10/site-packages/openml/_api_calls.py", line 344, in _send_request
    __check_response(response=response, url=url, file_elements=files)
  File "/home/ketrong/miniconda3/envs/tpot2devenv/lib/python3.10/site-packages/openml/_api_calls.py", line 409, in __check_response
    raise __parse_server_exception(response, url, file_elements=file_elements)
openml.exceptions.OpenMLServerException: https://www.openml.org/api/v1/xml/task/725 returned code 151: Unknown task - None

725
remove from investigation?
working on 
logs/725/tpot2_base_imputation_MNAR_0.9
2.4048497676849365
loading data
logs/725/tpot2_base_imputation_MNAR_0.9/data/725_True.pkl
https://www.openml.org/api/v1/xml/task/725 returned code 151: Unknown task - None
Traceback (most recent call last):
  File "/home/ketrong/miniconda3/envs/tpot2devenv/lib/python3.10/site-packages/openml/tasks/functions.py", line 70, in _get_cached_task
    with io.open(os.path.join(tid_cache_dir, "task.xml"), encoding="utf8") as fh:
FileNotFoundError: [Errno 2] No such file or directory: '/home/ketrong/.cache/openml/org/openml/www/tasks/725/task.xml'

During handling of the above exception, another exception occurred:

Traceback (most recent call last):
  File "/home/ketrong/miniconda3/envs/tpot2devenv/lib/python3.10/site-packages/openml/tasks/functions.py", line 422, in _get_task_description
    return _get_cached_task(task_id)
  File "/home/ketrong/miniconda3/envs/tpot2devenv/lib/python3.10/site-packages/openml/tasks/functions.py", line 74, in _get_cached_task
    raise OpenMLCacheException("Task file for tid %d not " "cached" % tid)
openml.exceptions.OpenMLCacheException: Task file for tid 725 not cached

During handling of the above exception, another exception occurred:

Traceback (most recent call last):
  File "/common/ketrong/AutoImputeExp/tpot2_imputetest/Impute_Experiments/utils.py", line 310, in loop_through_tasks
    X_train, y_train, X_test, y_test = load_task(base_save_folder=base_save_folder, exp=exp, type=type, levelstr=levelstr, task_id=taskid, preprocess=True)
  File "/common/ketrong/AutoImputeExp/tpot2_imputetest/Impute_Experiments/utils.py", line 200, in load_task
    task = openml.tasks.get_task(task_id)
  File "/home/ketrong/miniconda3/envs/tpot2devenv/lib/python3.10/site-packages/openml/tasks/functions.py", line 415, in get_task
    raise e
  File "/home/ketrong/miniconda3/envs/tpot2devenv/lib/python3.10/site-packages/openml/tasks/functions.py", line 398, in get_task
    task = _get_task_description(task_id)
  File "/home/ketrong/miniconda3/envs/tpot2devenv/lib/python3.10/site-packages/openml/tasks/functions.py", line 431, in _get_task_description
    task_xml = openml._api_calls._perform_api_call("task/%d" % task_id, "get")
  File "/home/ketrong/miniconda3/envs/tpot2devenv/lib/python3.10/site-packages/openml/_api_calls.py", line 99, in _perform_api_call
    response = __read_url(url, request_method, data)
  File "/home/ketrong/miniconda3/envs/tpot2devenv/lib/python3.10/site-packages/openml/_api_calls.py", line 308, in __read_url
    return _send_request(
  File "/home/ketrong/miniconda3/envs/tpot2devenv/lib/python3.10/site-packages/openml/_api_calls.py", line 344, in _send_request
    __check_response(response=response, url=url, file_elements=files)
  File "/home/ketrong/miniconda3/envs/tpot2devenv/lib/python3.10/site-packages/openml/_api_calls.py", line 409, in __check_response
    raise __parse_server_exception(response, url, file_elements=file_elements)
openml.exceptions.OpenMLServerException: https://www.openml.org/api/v1/xml/task/725 returned code 151: Unknown task - None

725
remove from investigation?
725
finished
working on 
logs/728/tpot2_base_normal_MNAR_0.9
1.935788631439209
loading data
logs/728/tpot2_base_normal_MNAR_0.9/data/728_True.pkl
https://www.openml.org/api/v1/xml/task/728 returned code 151: Unknown task - None
Traceback (most recent call last):
  File "/home/ketrong/miniconda3/envs/tpot2devenv/lib/python3.10/site-packages/openml/tasks/functions.py", line 70, in _get_cached_task
    with io.open(os.path.join(tid_cache_dir, "task.xml"), encoding="utf8") as fh:
FileNotFoundError: [Errno 2] No such file or directory: '/home/ketrong/.cache/openml/org/openml/www/tasks/728/task.xml'

During handling of the above exception, another exception occurred:

Traceback (most recent call last):
  File "/home/ketrong/miniconda3/envs/tpot2devenv/lib/python3.10/site-packages/openml/tasks/functions.py", line 422, in _get_task_description
    return _get_cached_task(task_id)
  File "/home/ketrong/miniconda3/envs/tpot2devenv/lib/python3.10/site-packages/openml/tasks/functions.py", line 74, in _get_cached_task
    raise OpenMLCacheException("Task file for tid %d not " "cached" % tid)
openml.exceptions.OpenMLCacheException: Task file for tid 728 not cached

During handling of the above exception, another exception occurred:

Traceback (most recent call last):
  File "/common/ketrong/AutoImputeExp/tpot2_imputetest/Impute_Experiments/utils.py", line 310, in loop_through_tasks
    X_train, y_train, X_test, y_test = load_task(base_save_folder=base_save_folder, exp=exp, type=type, levelstr=levelstr, task_id=taskid, preprocess=True)
  File "/common/ketrong/AutoImputeExp/tpot2_imputetest/Impute_Experiments/utils.py", line 200, in load_task
    task = openml.tasks.get_task(task_id)
  File "/home/ketrong/miniconda3/envs/tpot2devenv/lib/python3.10/site-packages/openml/tasks/functions.py", line 415, in get_task
    raise e
  File "/home/ketrong/miniconda3/envs/tpot2devenv/lib/python3.10/site-packages/openml/tasks/functions.py", line 398, in get_task
    task = _get_task_description(task_id)
  File "/home/ketrong/miniconda3/envs/tpot2devenv/lib/python3.10/site-packages/openml/tasks/functions.py", line 431, in _get_task_description
    task_xml = openml._api_calls._perform_api_call("task/%d" % task_id, "get")
  File "/home/ketrong/miniconda3/envs/tpot2devenv/lib/python3.10/site-packages/openml/_api_calls.py", line 99, in _perform_api_call
    response = __read_url(url, request_method, data)
  File "/home/ketrong/miniconda3/envs/tpot2devenv/lib/python3.10/site-packages/openml/_api_calls.py", line 308, in __read_url
    return _send_request(
  File "/home/ketrong/miniconda3/envs/tpot2devenv/lib/python3.10/site-packages/openml/_api_calls.py", line 344, in _send_request
    __check_response(response=response, url=url, file_elements=files)
  File "/home/ketrong/miniconda3/envs/tpot2devenv/lib/python3.10/site-packages/openml/_api_calls.py", line 409, in __check_response
    raise __parse_server_exception(response, url, file_elements=file_elements)
openml.exceptions.OpenMLServerException: https://www.openml.org/api/v1/xml/task/728 returned code 151: Unknown task - None

728
remove from investigation?
working on 
logs/728/tpot2_base_imputation_MNAR_0.9
4.322331428527832
loading data
logs/728/tpot2_base_imputation_MNAR_0.9/data/728_True.pkl
https://www.openml.org/api/v1/xml/task/728 returned code 151: Unknown task - None
Traceback (most recent call last):
  File "/home/ketrong/miniconda3/envs/tpot2devenv/lib/python3.10/site-packages/openml/tasks/functions.py", line 70, in _get_cached_task
    with io.open(os.path.join(tid_cache_dir, "task.xml"), encoding="utf8") as fh:
FileNotFoundError: [Errno 2] No such file or directory: '/home/ketrong/.cache/openml/org/openml/www/tasks/728/task.xml'

During handling of the above exception, another exception occurred:

Traceback (most recent call last):
  File "/home/ketrong/miniconda3/envs/tpot2devenv/lib/python3.10/site-packages/openml/tasks/functions.py", line 422, in _get_task_description
    return _get_cached_task(task_id)
  File "/home/ketrong/miniconda3/envs/tpot2devenv/lib/python3.10/site-packages/openml/tasks/functions.py", line 74, in _get_cached_task
    raise OpenMLCacheException("Task file for tid %d not " "cached" % tid)
openml.exceptions.OpenMLCacheException: Task file for tid 728 not cached

During handling of the above exception, another exception occurred:

Traceback (most recent call last):
  File "/common/ketrong/AutoImputeExp/tpot2_imputetest/Impute_Experiments/utils.py", line 310, in loop_through_tasks
    X_train, y_train, X_test, y_test = load_task(base_save_folder=base_save_folder, exp=exp, type=type, levelstr=levelstr, task_id=taskid, preprocess=True)
  File "/common/ketrong/AutoImputeExp/tpot2_imputetest/Impute_Experiments/utils.py", line 200, in load_task
    task = openml.tasks.get_task(task_id)
  File "/home/ketrong/miniconda3/envs/tpot2devenv/lib/python3.10/site-packages/openml/tasks/functions.py", line 415, in get_task
    raise e
  File "/home/ketrong/miniconda3/envs/tpot2devenv/lib/python3.10/site-packages/openml/tasks/functions.py", line 398, in get_task
    task = _get_task_description(task_id)
  File "/home/ketrong/miniconda3/envs/tpot2devenv/lib/python3.10/site-packages/openml/tasks/functions.py", line 431, in _get_task_description
    task_xml = openml._api_calls._perform_api_call("task/%d" % task_id, "get")
  File "/home/ketrong/miniconda3/envs/tpot2devenv/lib/python3.10/site-packages/openml/_api_calls.py", line 99, in _perform_api_call
    response = __read_url(url, request_method, data)
  File "/home/ketrong/miniconda3/envs/tpot2devenv/lib/python3.10/site-packages/openml/_api_calls.py", line 308, in __read_url
    return _send_request(
  File "/home/ketrong/miniconda3/envs/tpot2devenv/lib/python3.10/site-packages/openml/_api_calls.py", line 344, in _send_request
    __check_response(response=response, url=url, file_elements=files)
  File "/home/ketrong/miniconda3/envs/tpot2devenv/lib/python3.10/site-packages/openml/_api_calls.py", line 409, in __check_response
    raise __parse_server_exception(response, url, file_elements=file_elements)
openml.exceptions.OpenMLServerException: https://www.openml.org/api/v1/xml/task/728 returned code 151: Unknown task - None

728
remove from investigation?
728
finished
working on 
logs/737/tpot2_base_normal_MNAR_0.9
3.897059440612793
loading data
logs/737/tpot2_base_normal_MNAR_0.9/data/737_True.pkl
https://www.openml.org/api/v1/xml/task/737 returned code 151: Unknown task - None
Traceback (most recent call last):
  File "/home/ketrong/miniconda3/envs/tpot2devenv/lib/python3.10/site-packages/openml/tasks/functions.py", line 70, in _get_cached_task
    with io.open(os.path.join(tid_cache_dir, "task.xml"), encoding="utf8") as fh:
FileNotFoundError: [Errno 2] No such file or directory: '/home/ketrong/.cache/openml/org/openml/www/tasks/737/task.xml'

During handling of the above exception, another exception occurred:

Traceback (most recent call last):
  File "/home/ketrong/miniconda3/envs/tpot2devenv/lib/python3.10/site-packages/openml/tasks/functions.py", line 422, in _get_task_description
    return _get_cached_task(task_id)
  File "/home/ketrong/miniconda3/envs/tpot2devenv/lib/python3.10/site-packages/openml/tasks/functions.py", line 74, in _get_cached_task
    raise OpenMLCacheException("Task file for tid %d not " "cached" % tid)
openml.exceptions.OpenMLCacheException: Task file for tid 737 not cached

During handling of the above exception, another exception occurred:

Traceback (most recent call last):
  File "/common/ketrong/AutoImputeExp/tpot2_imputetest/Impute_Experiments/utils.py", line 310, in loop_through_tasks
    X_train, y_train, X_test, y_test = load_task(base_save_folder=base_save_folder, exp=exp, type=type, levelstr=levelstr, task_id=taskid, preprocess=True)
  File "/common/ketrong/AutoImputeExp/tpot2_imputetest/Impute_Experiments/utils.py", line 200, in load_task
    task = openml.tasks.get_task(task_id)
  File "/home/ketrong/miniconda3/envs/tpot2devenv/lib/python3.10/site-packages/openml/tasks/functions.py", line 415, in get_task
    raise e
  File "/home/ketrong/miniconda3/envs/tpot2devenv/lib/python3.10/site-packages/openml/tasks/functions.py", line 398, in get_task
    task = _get_task_description(task_id)
  File "/home/ketrong/miniconda3/envs/tpot2devenv/lib/python3.10/site-packages/openml/tasks/functions.py", line 431, in _get_task_description
    task_xml = openml._api_calls._perform_api_call("task/%d" % task_id, "get")
  File "/home/ketrong/miniconda3/envs/tpot2devenv/lib/python3.10/site-packages/openml/_api_calls.py", line 99, in _perform_api_call
    response = __read_url(url, request_method, data)
  File "/home/ketrong/miniconda3/envs/tpot2devenv/lib/python3.10/site-packages/openml/_api_calls.py", line 308, in __read_url
    return _send_request(
  File "/home/ketrong/miniconda3/envs/tpot2devenv/lib/python3.10/site-packages/openml/_api_calls.py", line 344, in _send_request
    __check_response(response=response, url=url, file_elements=files)
  File "/home/ketrong/miniconda3/envs/tpot2devenv/lib/python3.10/site-packages/openml/_api_calls.py", line 409, in __check_response
    raise __parse_server_exception(response, url, file_elements=file_elements)
openml.exceptions.OpenMLServerException: https://www.openml.org/api/v1/xml/task/737 returned code 151: Unknown task - None

737
remove from investigation?
working on 
logs/737/tpot2_base_imputation_MNAR_0.9
3.664076805114746
loading data
logs/737/tpot2_base_imputation_MNAR_0.9/data/737_True.pkl
https://www.openml.org/api/v1/xml/task/737 returned code 151: Unknown task - None
Traceback (most recent call last):
  File "/home/ketrong/miniconda3/envs/tpot2devenv/lib/python3.10/site-packages/openml/tasks/functions.py", line 70, in _get_cached_task
    with io.open(os.path.join(tid_cache_dir, "task.xml"), encoding="utf8") as fh:
FileNotFoundError: [Errno 2] No such file or directory: '/home/ketrong/.cache/openml/org/openml/www/tasks/737/task.xml'

During handling of the above exception, another exception occurred:

Traceback (most recent call last):
  File "/home/ketrong/miniconda3/envs/tpot2devenv/lib/python3.10/site-packages/openml/tasks/functions.py", line 422, in _get_task_description
    return _get_cached_task(task_id)
  File "/home/ketrong/miniconda3/envs/tpot2devenv/lib/python3.10/site-packages/openml/tasks/functions.py", line 74, in _get_cached_task
    raise OpenMLCacheException("Task file for tid %d not " "cached" % tid)
openml.exceptions.OpenMLCacheException: Task file for tid 737 not cached

During handling of the above exception, another exception occurred:

Traceback (most recent call last):
  File "/common/ketrong/AutoImputeExp/tpot2_imputetest/Impute_Experiments/utils.py", line 310, in loop_through_tasks
    X_train, y_train, X_test, y_test = load_task(base_save_folder=base_save_folder, exp=exp, type=type, levelstr=levelstr, task_id=taskid, preprocess=True)
  File "/common/ketrong/AutoImputeExp/tpot2_imputetest/Impute_Experiments/utils.py", line 200, in load_task
    task = openml.tasks.get_task(task_id)
  File "/home/ketrong/miniconda3/envs/tpot2devenv/lib/python3.10/site-packages/openml/tasks/functions.py", line 415, in get_task
    raise e
  File "/home/ketrong/miniconda3/envs/tpot2devenv/lib/python3.10/site-packages/openml/tasks/functions.py", line 398, in get_task
    task = _get_task_description(task_id)
  File "/home/ketrong/miniconda3/envs/tpot2devenv/lib/python3.10/site-packages/openml/tasks/functions.py", line 431, in _get_task_description
    task_xml = openml._api_calls._perform_api_call("task/%d" % task_id, "get")
  File "/home/ketrong/miniconda3/envs/tpot2devenv/lib/python3.10/site-packages/openml/_api_calls.py", line 99, in _perform_api_call
    response = __read_url(url, request_method, data)
  File "/home/ketrong/miniconda3/envs/tpot2devenv/lib/python3.10/site-packages/openml/_api_calls.py", line 308, in __read_url
    return _send_request(
  File "/home/ketrong/miniconda3/envs/tpot2devenv/lib/python3.10/site-packages/openml/_api_calls.py", line 344, in _send_request
    __check_response(response=response, url=url, file_elements=files)
  File "/home/ketrong/miniconda3/envs/tpot2devenv/lib/python3.10/site-packages/openml/_api_calls.py", line 409, in __check_response
    raise __parse_server_exception(response, url, file_elements=file_elements)
openml.exceptions.OpenMLServerException: https://www.openml.org/api/v1/xml/task/737 returned code 151: Unknown task - None

737
remove from investigation?
737
finished
working on 
logs/803/tpot2_base_normal_MNAR_0.9
2.5642664432525635
loading data
logs/803/tpot2_base_normal_MNAR_0.9/data/803_True.pkl
https://www.openml.org/api/v1/xml/task/803 returned code 151: Unknown task - None
Traceback (most recent call last):
  File "/home/ketrong/miniconda3/envs/tpot2devenv/lib/python3.10/site-packages/openml/tasks/functions.py", line 70, in _get_cached_task
    with io.open(os.path.join(tid_cache_dir, "task.xml"), encoding="utf8") as fh:
FileNotFoundError: [Errno 2] No such file or directory: '/home/ketrong/.cache/openml/org/openml/www/tasks/803/task.xml'

During handling of the above exception, another exception occurred:

Traceback (most recent call last):
  File "/home/ketrong/miniconda3/envs/tpot2devenv/lib/python3.10/site-packages/openml/tasks/functions.py", line 422, in _get_task_description
    return _get_cached_task(task_id)
  File "/home/ketrong/miniconda3/envs/tpot2devenv/lib/python3.10/site-packages/openml/tasks/functions.py", line 74, in _get_cached_task
    raise OpenMLCacheException("Task file for tid %d not " "cached" % tid)
openml.exceptions.OpenMLCacheException: Task file for tid 803 not cached

During handling of the above exception, another exception occurred:

Traceback (most recent call last):
  File "/common/ketrong/AutoImputeExp/tpot2_imputetest/Impute_Experiments/utils.py", line 310, in loop_through_tasks
    X_train, y_train, X_test, y_test = load_task(base_save_folder=base_save_folder, exp=exp, type=type, levelstr=levelstr, task_id=taskid, preprocess=True)
  File "/common/ketrong/AutoImputeExp/tpot2_imputetest/Impute_Experiments/utils.py", line 200, in load_task
    task = openml.tasks.get_task(task_id)
  File "/home/ketrong/miniconda3/envs/tpot2devenv/lib/python3.10/site-packages/openml/tasks/functions.py", line 415, in get_task
    raise e
  File "/home/ketrong/miniconda3/envs/tpot2devenv/lib/python3.10/site-packages/openml/tasks/functions.py", line 398, in get_task
    task = _get_task_description(task_id)
  File "/home/ketrong/miniconda3/envs/tpot2devenv/lib/python3.10/site-packages/openml/tasks/functions.py", line 431, in _get_task_description
    task_xml = openml._api_calls._perform_api_call("task/%d" % task_id, "get")
  File "/home/ketrong/miniconda3/envs/tpot2devenv/lib/python3.10/site-packages/openml/_api_calls.py", line 99, in _perform_api_call
    response = __read_url(url, request_method, data)
  File "/home/ketrong/miniconda3/envs/tpot2devenv/lib/python3.10/site-packages/openml/_api_calls.py", line 308, in __read_url
    return _send_request(
  File "/home/ketrong/miniconda3/envs/tpot2devenv/lib/python3.10/site-packages/openml/_api_calls.py", line 344, in _send_request
    __check_response(response=response, url=url, file_elements=files)
  File "/home/ketrong/miniconda3/envs/tpot2devenv/lib/python3.10/site-packages/openml/_api_calls.py", line 409, in __check_response
    raise __parse_server_exception(response, url, file_elements=file_elements)
openml.exceptions.OpenMLServerException: https://www.openml.org/api/v1/xml/task/803 returned code 151: Unknown task - None

803
remove from investigation?
working on 
logs/803/tpot2_base_imputation_MNAR_0.9
0.020463228225708008
loading data
logs/803/tpot2_base_imputation_MNAR_0.9/data/803_True.pkl
https://www.openml.org/api/v1/xml/task/803 returned code 151: Unknown task - None
Traceback (most recent call last):
  File "/home/ketrong/miniconda3/envs/tpot2devenv/lib/python3.10/site-packages/openml/tasks/functions.py", line 70, in _get_cached_task
    with io.open(os.path.join(tid_cache_dir, "task.xml"), encoding="utf8") as fh:
FileNotFoundError: [Errno 2] No such file or directory: '/home/ketrong/.cache/openml/org/openml/www/tasks/803/task.xml'

During handling of the above exception, another exception occurred:

Traceback (most recent call last):
  File "/home/ketrong/miniconda3/envs/tpot2devenv/lib/python3.10/site-packages/openml/tasks/functions.py", line 422, in _get_task_description
    return _get_cached_task(task_id)
  File "/home/ketrong/miniconda3/envs/tpot2devenv/lib/python3.10/site-packages/openml/tasks/functions.py", line 74, in _get_cached_task
    raise OpenMLCacheException("Task file for tid %d not " "cached" % tid)
openml.exceptions.OpenMLCacheException: Task file for tid 803 not cached

During handling of the above exception, another exception occurred:

Traceback (most recent call last):
  File "/common/ketrong/AutoImputeExp/tpot2_imputetest/Impute_Experiments/utils.py", line 310, in loop_through_tasks
    X_train, y_train, X_test, y_test = load_task(base_save_folder=base_save_folder, exp=exp, type=type, levelstr=levelstr, task_id=taskid, preprocess=True)
  File "/common/ketrong/AutoImputeExp/tpot2_imputetest/Impute_Experiments/utils.py", line 200, in load_task
    task = openml.tasks.get_task(task_id)
  File "/home/ketrong/miniconda3/envs/tpot2devenv/lib/python3.10/site-packages/openml/tasks/functions.py", line 415, in get_task
    raise e
  File "/home/ketrong/miniconda3/envs/tpot2devenv/lib/python3.10/site-packages/openml/tasks/functions.py", line 398, in get_task
    task = _get_task_description(task_id)
  File "/home/ketrong/miniconda3/envs/tpot2devenv/lib/python3.10/site-packages/openml/tasks/functions.py", line 431, in _get_task_description
    task_xml = openml._api_calls._perform_api_call("task/%d" % task_id, "get")
  File "/home/ketrong/miniconda3/envs/tpot2devenv/lib/python3.10/site-packages/openml/_api_calls.py", line 99, in _perform_api_call
    response = __read_url(url, request_method, data)
  File "/home/ketrong/miniconda3/envs/tpot2devenv/lib/python3.10/site-packages/openml/_api_calls.py", line 308, in __read_url
    return _send_request(
  File "/home/ketrong/miniconda3/envs/tpot2devenv/lib/python3.10/site-packages/openml/_api_calls.py", line 344, in _send_request
    __check_response(response=response, url=url, file_elements=files)
  File "/home/ketrong/miniconda3/envs/tpot2devenv/lib/python3.10/site-packages/openml/_api_calls.py", line 409, in __check_response
    raise __parse_server_exception(response, url, file_elements=file_elements)
openml.exceptions.OpenMLServerException: https://www.openml.org/api/v1/xml/task/803 returned code 151: Unknown task - None

803
remove from investigation?
803
finished
working on 
logs/823/tpot2_base_normal_MNAR_0.9
4.127559661865234
loading data
logs/823/tpot2_base_normal_MNAR_0.9/data/823_True.pkl
https://www.openml.org/api/v1/xml/task/823 returned code 151: Unknown task - None
Traceback (most recent call last):
  File "/home/ketrong/miniconda3/envs/tpot2devenv/lib/python3.10/site-packages/openml/tasks/functions.py", line 70, in _get_cached_task
    with io.open(os.path.join(tid_cache_dir, "task.xml"), encoding="utf8") as fh:
FileNotFoundError: [Errno 2] No such file or directory: '/home/ketrong/.cache/openml/org/openml/www/tasks/823/task.xml'

During handling of the above exception, another exception occurred:

Traceback (most recent call last):
  File "/home/ketrong/miniconda3/envs/tpot2devenv/lib/python3.10/site-packages/openml/tasks/functions.py", line 422, in _get_task_description
    return _get_cached_task(task_id)
  File "/home/ketrong/miniconda3/envs/tpot2devenv/lib/python3.10/site-packages/openml/tasks/functions.py", line 74, in _get_cached_task
    raise OpenMLCacheException("Task file for tid %d not " "cached" % tid)
openml.exceptions.OpenMLCacheException: Task file for tid 823 not cached

During handling of the above exception, another exception occurred:

Traceback (most recent call last):
  File "/common/ketrong/AutoImputeExp/tpot2_imputetest/Impute_Experiments/utils.py", line 310, in loop_through_tasks
    X_train, y_train, X_test, y_test = load_task(base_save_folder=base_save_folder, exp=exp, type=type, levelstr=levelstr, task_id=taskid, preprocess=True)
  File "/common/ketrong/AutoImputeExp/tpot2_imputetest/Impute_Experiments/utils.py", line 200, in load_task
    task = openml.tasks.get_task(task_id)
  File "/home/ketrong/miniconda3/envs/tpot2devenv/lib/python3.10/site-packages/openml/tasks/functions.py", line 415, in get_task
    raise e
  File "/home/ketrong/miniconda3/envs/tpot2devenv/lib/python3.10/site-packages/openml/tasks/functions.py", line 398, in get_task
    task = _get_task_description(task_id)
  File "/home/ketrong/miniconda3/envs/tpot2devenv/lib/python3.10/site-packages/openml/tasks/functions.py", line 431, in _get_task_description
    task_xml = openml._api_calls._perform_api_call("task/%d" % task_id, "get")
  File "/home/ketrong/miniconda3/envs/tpot2devenv/lib/python3.10/site-packages/openml/_api_calls.py", line 99, in _perform_api_call
    response = __read_url(url, request_method, data)
  File "/home/ketrong/miniconda3/envs/tpot2devenv/lib/python3.10/site-packages/openml/_api_calls.py", line 308, in __read_url
    return _send_request(
  File "/home/ketrong/miniconda3/envs/tpot2devenv/lib/python3.10/site-packages/openml/_api_calls.py", line 344, in _send_request
    __check_response(response=response, url=url, file_elements=files)
  File "/home/ketrong/miniconda3/envs/tpot2devenv/lib/python3.10/site-packages/openml/_api_calls.py", line 409, in __check_response
    raise __parse_server_exception(response, url, file_elements=file_elements)
openml.exceptions.OpenMLServerException: https://www.openml.org/api/v1/xml/task/823 returned code 151: Unknown task - None

823
remove from investigation?
working on 
logs/823/tpot2_base_imputation_MNAR_0.9
3.063523054122925
loading data
logs/823/tpot2_base_imputation_MNAR_0.9/data/823_True.pkl
https://www.openml.org/api/v1/xml/task/823 returned code 151: Unknown task - None
Traceback (most recent call last):
  File "/home/ketrong/miniconda3/envs/tpot2devenv/lib/python3.10/site-packages/openml/tasks/functions.py", line 70, in _get_cached_task
    with io.open(os.path.join(tid_cache_dir, "task.xml"), encoding="utf8") as fh:
FileNotFoundError: [Errno 2] No such file or directory: '/home/ketrong/.cache/openml/org/openml/www/tasks/823/task.xml'

During handling of the above exception, another exception occurred:

Traceback (most recent call last):
  File "/home/ketrong/miniconda3/envs/tpot2devenv/lib/python3.10/site-packages/openml/tasks/functions.py", line 422, in _get_task_description
    return _get_cached_task(task_id)
  File "/home/ketrong/miniconda3/envs/tpot2devenv/lib/python3.10/site-packages/openml/tasks/functions.py", line 74, in _get_cached_task
    raise OpenMLCacheException("Task file for tid %d not " "cached" % tid)
openml.exceptions.OpenMLCacheException: Task file for tid 823 not cached

During handling of the above exception, another exception occurred:

Traceback (most recent call last):
  File "/common/ketrong/AutoImputeExp/tpot2_imputetest/Impute_Experiments/utils.py", line 310, in loop_through_tasks
    X_train, y_train, X_test, y_test = load_task(base_save_folder=base_save_folder, exp=exp, type=type, levelstr=levelstr, task_id=taskid, preprocess=True)
  File "/common/ketrong/AutoImputeExp/tpot2_imputetest/Impute_Experiments/utils.py", line 200, in load_task
    task = openml.tasks.get_task(task_id)
  File "/home/ketrong/miniconda3/envs/tpot2devenv/lib/python3.10/site-packages/openml/tasks/functions.py", line 415, in get_task
    raise e
  File "/home/ketrong/miniconda3/envs/tpot2devenv/lib/python3.10/site-packages/openml/tasks/functions.py", line 398, in get_task
    task = _get_task_description(task_id)
  File "/home/ketrong/miniconda3/envs/tpot2devenv/lib/python3.10/site-packages/openml/tasks/functions.py", line 431, in _get_task_description
    task_xml = openml._api_calls._perform_api_call("task/%d" % task_id, "get")
  File "/home/ketrong/miniconda3/envs/tpot2devenv/lib/python3.10/site-packages/openml/_api_calls.py", line 99, in _perform_api_call
    response = __read_url(url, request_method, data)
  File "/home/ketrong/miniconda3/envs/tpot2devenv/lib/python3.10/site-packages/openml/_api_calls.py", line 308, in __read_url
    return _send_request(
  File "/home/ketrong/miniconda3/envs/tpot2devenv/lib/python3.10/site-packages/openml/_api_calls.py", line 344, in _send_request
    __check_response(response=response, url=url, file_elements=files)
  File "/home/ketrong/miniconda3/envs/tpot2devenv/lib/python3.10/site-packages/openml/_api_calls.py", line 409, in __check_response
    raise __parse_server_exception(response, url, file_elements=file_elements)
openml.exceptions.OpenMLServerException: https://www.openml.org/api/v1/xml/task/823 returned code 151: Unknown task - None

823
remove from investigation?
823
finished
working on 
logs/847/tpot2_base_normal_MNAR_0.9
3.935242176055908
loading data
logs/847/tpot2_base_normal_MNAR_0.9/data/847_True.pkl
https://www.openml.org/api/v1/xml/task/847 returned code 151: Unknown task - None
Traceback (most recent call last):
  File "/home/ketrong/miniconda3/envs/tpot2devenv/lib/python3.10/site-packages/openml/tasks/functions.py", line 70, in _get_cached_task
    with io.open(os.path.join(tid_cache_dir, "task.xml"), encoding="utf8") as fh:
FileNotFoundError: [Errno 2] No such file or directory: '/home/ketrong/.cache/openml/org/openml/www/tasks/847/task.xml'

During handling of the above exception, another exception occurred:

Traceback (most recent call last):
  File "/home/ketrong/miniconda3/envs/tpot2devenv/lib/python3.10/site-packages/openml/tasks/functions.py", line 422, in _get_task_description
    return _get_cached_task(task_id)
  File "/home/ketrong/miniconda3/envs/tpot2devenv/lib/python3.10/site-packages/openml/tasks/functions.py", line 74, in _get_cached_task
    raise OpenMLCacheException("Task file for tid %d not " "cached" % tid)
openml.exceptions.OpenMLCacheException: Task file for tid 847 not cached

During handling of the above exception, another exception occurred:

Traceback (most recent call last):
  File "/common/ketrong/AutoImputeExp/tpot2_imputetest/Impute_Experiments/utils.py", line 310, in loop_through_tasks
    X_train, y_train, X_test, y_test = load_task(base_save_folder=base_save_folder, exp=exp, type=type, levelstr=levelstr, task_id=taskid, preprocess=True)
  File "/common/ketrong/AutoImputeExp/tpot2_imputetest/Impute_Experiments/utils.py", line 200, in load_task
    task = openml.tasks.get_task(task_id)
  File "/home/ketrong/miniconda3/envs/tpot2devenv/lib/python3.10/site-packages/openml/tasks/functions.py", line 415, in get_task
    raise e
  File "/home/ketrong/miniconda3/envs/tpot2devenv/lib/python3.10/site-packages/openml/tasks/functions.py", line 398, in get_task
    task = _get_task_description(task_id)
  File "/home/ketrong/miniconda3/envs/tpot2devenv/lib/python3.10/site-packages/openml/tasks/functions.py", line 431, in _get_task_description
    task_xml = openml._api_calls._perform_api_call("task/%d" % task_id, "get")
  File "/home/ketrong/miniconda3/envs/tpot2devenv/lib/python3.10/site-packages/openml/_api_calls.py", line 99, in _perform_api_call
    response = __read_url(url, request_method, data)
  File "/home/ketrong/miniconda3/envs/tpot2devenv/lib/python3.10/site-packages/openml/_api_calls.py", line 308, in __read_url
    return _send_request(
  File "/home/ketrong/miniconda3/envs/tpot2devenv/lib/python3.10/site-packages/openml/_api_calls.py", line 344, in _send_request
    __check_response(response=response, url=url, file_elements=files)
  File "/home/ketrong/miniconda3/envs/tpot2devenv/lib/python3.10/site-packages/openml/_api_calls.py", line 409, in __check_response
    raise __parse_server_exception(response, url, file_elements=file_elements)
openml.exceptions.OpenMLServerException: https://www.openml.org/api/v1/xml/task/847 returned code 151: Unknown task - None

847
remove from investigation?
working on 
logs/847/tpot2_base_imputation_MNAR_0.9
4.161066055297852
loading data
logs/847/tpot2_base_imputation_MNAR_0.9/data/847_True.pkl
https://www.openml.org/api/v1/xml/task/847 returned code 151: Unknown task - None
Traceback (most recent call last):
  File "/home/ketrong/miniconda3/envs/tpot2devenv/lib/python3.10/site-packages/openml/tasks/functions.py", line 70, in _get_cached_task
    with io.open(os.path.join(tid_cache_dir, "task.xml"), encoding="utf8") as fh:
FileNotFoundError: [Errno 2] No such file or directory: '/home/ketrong/.cache/openml/org/openml/www/tasks/847/task.xml'

During handling of the above exception, another exception occurred:

Traceback (most recent call last):
  File "/home/ketrong/miniconda3/envs/tpot2devenv/lib/python3.10/site-packages/openml/tasks/functions.py", line 422, in _get_task_description
    return _get_cached_task(task_id)
  File "/home/ketrong/miniconda3/envs/tpot2devenv/lib/python3.10/site-packages/openml/tasks/functions.py", line 74, in _get_cached_task
    raise OpenMLCacheException("Task file for tid %d not " "cached" % tid)
openml.exceptions.OpenMLCacheException: Task file for tid 847 not cached

During handling of the above exception, another exception occurred:

Traceback (most recent call last):
  File "/common/ketrong/AutoImputeExp/tpot2_imputetest/Impute_Experiments/utils.py", line 310, in loop_through_tasks
    X_train, y_train, X_test, y_test = load_task(base_save_folder=base_save_folder, exp=exp, type=type, levelstr=levelstr, task_id=taskid, preprocess=True)
  File "/common/ketrong/AutoImputeExp/tpot2_imputetest/Impute_Experiments/utils.py", line 200, in load_task
    task = openml.tasks.get_task(task_id)
  File "/home/ketrong/miniconda3/envs/tpot2devenv/lib/python3.10/site-packages/openml/tasks/functions.py", line 415, in get_task
    raise e
  File "/home/ketrong/miniconda3/envs/tpot2devenv/lib/python3.10/site-packages/openml/tasks/functions.py", line 398, in get_task
    task = _get_task_description(task_id)
  File "/home/ketrong/miniconda3/envs/tpot2devenv/lib/python3.10/site-packages/openml/tasks/functions.py", line 431, in _get_task_description
    task_xml = openml._api_calls._perform_api_call("task/%d" % task_id, "get")
  File "/home/ketrong/miniconda3/envs/tpot2devenv/lib/python3.10/site-packages/openml/_api_calls.py", line 99, in _perform_api_call
    response = __read_url(url, request_method, data)
  File "/home/ketrong/miniconda3/envs/tpot2devenv/lib/python3.10/site-packages/openml/_api_calls.py", line 308, in __read_url
    return _send_request(
  File "/home/ketrong/miniconda3/envs/tpot2devenv/lib/python3.10/site-packages/openml/_api_calls.py", line 344, in _send_request
    __check_response(response=response, url=url, file_elements=files)
  File "/home/ketrong/miniconda3/envs/tpot2devenv/lib/python3.10/site-packages/openml/_api_calls.py", line 409, in __check_response
    raise __parse_server_exception(response, url, file_elements=file_elements)
openml.exceptions.OpenMLServerException: https://www.openml.org/api/v1/xml/task/847 returned code 151: Unknown task - None

847
remove from investigation?
847
finished
working on 
logs/871/tpot2_base_normal_MNAR_0.9
2.821138858795166
loading data
logs/871/tpot2_base_normal_MNAR_0.9/data/871_True.pkl
https://www.openml.org/api/v1/xml/task/871 returned code 151: Unknown task - None
Traceback (most recent call last):
  File "/home/ketrong/miniconda3/envs/tpot2devenv/lib/python3.10/site-packages/openml/tasks/functions.py", line 70, in _get_cached_task
    with io.open(os.path.join(tid_cache_dir, "task.xml"), encoding="utf8") as fh:
FileNotFoundError: [Errno 2] No such file or directory: '/home/ketrong/.cache/openml/org/openml/www/tasks/871/task.xml'

During handling of the above exception, another exception occurred:

Traceback (most recent call last):
  File "/home/ketrong/miniconda3/envs/tpot2devenv/lib/python3.10/site-packages/openml/tasks/functions.py", line 422, in _get_task_description
    return _get_cached_task(task_id)
  File "/home/ketrong/miniconda3/envs/tpot2devenv/lib/python3.10/site-packages/openml/tasks/functions.py", line 74, in _get_cached_task
    raise OpenMLCacheException("Task file for tid %d not " "cached" % tid)
openml.exceptions.OpenMLCacheException: Task file for tid 871 not cached

During handling of the above exception, another exception occurred:

Traceback (most recent call last):
  File "/common/ketrong/AutoImputeExp/tpot2_imputetest/Impute_Experiments/utils.py", line 310, in loop_through_tasks
    X_train, y_train, X_test, y_test = load_task(base_save_folder=base_save_folder, exp=exp, type=type, levelstr=levelstr, task_id=taskid, preprocess=True)
  File "/common/ketrong/AutoImputeExp/tpot2_imputetest/Impute_Experiments/utils.py", line 200, in load_task
    task = openml.tasks.get_task(task_id)
  File "/home/ketrong/miniconda3/envs/tpot2devenv/lib/python3.10/site-packages/openml/tasks/functions.py", line 415, in get_task
    raise e
  File "/home/ketrong/miniconda3/envs/tpot2devenv/lib/python3.10/site-packages/openml/tasks/functions.py", line 398, in get_task
    task = _get_task_description(task_id)
  File "/home/ketrong/miniconda3/envs/tpot2devenv/lib/python3.10/site-packages/openml/tasks/functions.py", line 431, in _get_task_description
    task_xml = openml._api_calls._perform_api_call("task/%d" % task_id, "get")
  File "/home/ketrong/miniconda3/envs/tpot2devenv/lib/python3.10/site-packages/openml/_api_calls.py", line 99, in _perform_api_call
    response = __read_url(url, request_method, data)
  File "/home/ketrong/miniconda3/envs/tpot2devenv/lib/python3.10/site-packages/openml/_api_calls.py", line 308, in __read_url
    return _send_request(
  File "/home/ketrong/miniconda3/envs/tpot2devenv/lib/python3.10/site-packages/openml/_api_calls.py", line 344, in _send_request
    __check_response(response=response, url=url, file_elements=files)
  File "/home/ketrong/miniconda3/envs/tpot2devenv/lib/python3.10/site-packages/openml/_api_calls.py", line 409, in __check_response
    raise __parse_server_exception(response, url, file_elements=file_elements)
openml.exceptions.OpenMLServerException: https://www.openml.org/api/v1/xml/task/871 returned code 151: Unknown task - None

871
remove from investigation?
working on 
logs/871/tpot2_base_imputation_MNAR_0.9
3.7077436447143555
loading data
logs/871/tpot2_base_imputation_MNAR_0.9/data/871_True.pkl
https://www.openml.org/api/v1/xml/task/871 returned code 151: Unknown task - None
Traceback (most recent call last):
  File "/home/ketrong/miniconda3/envs/tpot2devenv/lib/python3.10/site-packages/openml/tasks/functions.py", line 70, in _get_cached_task
    with io.open(os.path.join(tid_cache_dir, "task.xml"), encoding="utf8") as fh:
FileNotFoundError: [Errno 2] No such file or directory: '/home/ketrong/.cache/openml/org/openml/www/tasks/871/task.xml'

During handling of the above exception, another exception occurred:

Traceback (most recent call last):
  File "/home/ketrong/miniconda3/envs/tpot2devenv/lib/python3.10/site-packages/openml/tasks/functions.py", line 422, in _get_task_description
    return _get_cached_task(task_id)
  File "/home/ketrong/miniconda3/envs/tpot2devenv/lib/python3.10/site-packages/openml/tasks/functions.py", line 74, in _get_cached_task
    raise OpenMLCacheException("Task file for tid %d not " "cached" % tid)
openml.exceptions.OpenMLCacheException: Task file for tid 871 not cached

During handling of the above exception, another exception occurred:

Traceback (most recent call last):
  File "/common/ketrong/AutoImputeExp/tpot2_imputetest/Impute_Experiments/utils.py", line 310, in loop_through_tasks
    X_train, y_train, X_test, y_test = load_task(base_save_folder=base_save_folder, exp=exp, type=type, levelstr=levelstr, task_id=taskid, preprocess=True)
  File "/common/ketrong/AutoImputeExp/tpot2_imputetest/Impute_Experiments/utils.py", line 200, in load_task
    task = openml.tasks.get_task(task_id)
  File "/home/ketrong/miniconda3/envs/tpot2devenv/lib/python3.10/site-packages/openml/tasks/functions.py", line 415, in get_task
    raise e
  File "/home/ketrong/miniconda3/envs/tpot2devenv/lib/python3.10/site-packages/openml/tasks/functions.py", line 398, in get_task
    task = _get_task_description(task_id)
  File "/home/ketrong/miniconda3/envs/tpot2devenv/lib/python3.10/site-packages/openml/tasks/functions.py", line 431, in _get_task_description
    task_xml = openml._api_calls._perform_api_call("task/%d" % task_id, "get")
  File "/home/ketrong/miniconda3/envs/tpot2devenv/lib/python3.10/site-packages/openml/_api_calls.py", line 99, in _perform_api_call
    response = __read_url(url, request_method, data)
  File "/home/ketrong/miniconda3/envs/tpot2devenv/lib/python3.10/site-packages/openml/_api_calls.py", line 308, in __read_url
    return _send_request(
  File "/home/ketrong/miniconda3/envs/tpot2devenv/lib/python3.10/site-packages/openml/_api_calls.py", line 344, in _send_request
    __check_response(response=response, url=url, file_elements=files)
  File "/home/ketrong/miniconda3/envs/tpot2devenv/lib/python3.10/site-packages/openml/_api_calls.py", line 409, in __check_response
    raise __parse_server_exception(response, url, file_elements=file_elements)
openml.exceptions.OpenMLServerException: https://www.openml.org/api/v1/xml/task/871 returned code 151: Unknown task - None

871
remove from investigation?
871
finished
working on 
logs/881/tpot2_base_normal_MNAR_0.9
2.7445015907287598
loading data
logs/881/tpot2_base_normal_MNAR_0.9/data/881_True.pkl
https://www.openml.org/api/v1/xml/task/881 returned code 151: Unknown task - None
Traceback (most recent call last):
  File "/home/ketrong/miniconda3/envs/tpot2devenv/lib/python3.10/site-packages/openml/tasks/functions.py", line 70, in _get_cached_task
    with io.open(os.path.join(tid_cache_dir, "task.xml"), encoding="utf8") as fh:
FileNotFoundError: [Errno 2] No such file or directory: '/home/ketrong/.cache/openml/org/openml/www/tasks/881/task.xml'

During handling of the above exception, another exception occurred:

Traceback (most recent call last):
  File "/home/ketrong/miniconda3/envs/tpot2devenv/lib/python3.10/site-packages/openml/tasks/functions.py", line 422, in _get_task_description
    return _get_cached_task(task_id)
  File "/home/ketrong/miniconda3/envs/tpot2devenv/lib/python3.10/site-packages/openml/tasks/functions.py", line 74, in _get_cached_task
    raise OpenMLCacheException("Task file for tid %d not " "cached" % tid)
openml.exceptions.OpenMLCacheException: Task file for tid 881 not cached

During handling of the above exception, another exception occurred:

Traceback (most recent call last):
  File "/common/ketrong/AutoImputeExp/tpot2_imputetest/Impute_Experiments/utils.py", line 310, in loop_through_tasks
    X_train, y_train, X_test, y_test = load_task(base_save_folder=base_save_folder, exp=exp, type=type, levelstr=levelstr, task_id=taskid, preprocess=True)
  File "/common/ketrong/AutoImputeExp/tpot2_imputetest/Impute_Experiments/utils.py", line 200, in load_task
    task = openml.tasks.get_task(task_id)
  File "/home/ketrong/miniconda3/envs/tpot2devenv/lib/python3.10/site-packages/openml/tasks/functions.py", line 415, in get_task
    raise e
  File "/home/ketrong/miniconda3/envs/tpot2devenv/lib/python3.10/site-packages/openml/tasks/functions.py", line 398, in get_task
    task = _get_task_description(task_id)
  File "/home/ketrong/miniconda3/envs/tpot2devenv/lib/python3.10/site-packages/openml/tasks/functions.py", line 431, in _get_task_description
    task_xml = openml._api_calls._perform_api_call("task/%d" % task_id, "get")
  File "/home/ketrong/miniconda3/envs/tpot2devenv/lib/python3.10/site-packages/openml/_api_calls.py", line 99, in _perform_api_call
    response = __read_url(url, request_method, data)
  File "/home/ketrong/miniconda3/envs/tpot2devenv/lib/python3.10/site-packages/openml/_api_calls.py", line 308, in __read_url
    return _send_request(
  File "/home/ketrong/miniconda3/envs/tpot2devenv/lib/python3.10/site-packages/openml/_api_calls.py", line 344, in _send_request
    __check_response(response=response, url=url, file_elements=files)
  File "/home/ketrong/miniconda3/envs/tpot2devenv/lib/python3.10/site-packages/openml/_api_calls.py", line 409, in __check_response
    raise __parse_server_exception(response, url, file_elements=file_elements)
openml.exceptions.OpenMLServerException: https://www.openml.org/api/v1/xml/task/881 returned code 151: Unknown task - None

881
remove from investigation?
working on 
logs/881/tpot2_base_imputation_MNAR_0.9
4.0488128662109375
loading data
logs/881/tpot2_base_imputation_MNAR_0.9/data/881_True.pkl
https://www.openml.org/api/v1/xml/task/881 returned code 151: Unknown task - None
Traceback (most recent call last):
  File "/home/ketrong/miniconda3/envs/tpot2devenv/lib/python3.10/site-packages/openml/tasks/functions.py", line 70, in _get_cached_task
    with io.open(os.path.join(tid_cache_dir, "task.xml"), encoding="utf8") as fh:
FileNotFoundError: [Errno 2] No such file or directory: '/home/ketrong/.cache/openml/org/openml/www/tasks/881/task.xml'

During handling of the above exception, another exception occurred:

Traceback (most recent call last):
  File "/home/ketrong/miniconda3/envs/tpot2devenv/lib/python3.10/site-packages/openml/tasks/functions.py", line 422, in _get_task_description
    return _get_cached_task(task_id)
  File "/home/ketrong/miniconda3/envs/tpot2devenv/lib/python3.10/site-packages/openml/tasks/functions.py", line 74, in _get_cached_task
    raise OpenMLCacheException("Task file for tid %d not " "cached" % tid)
openml.exceptions.OpenMLCacheException: Task file for tid 881 not cached

During handling of the above exception, another exception occurred:

Traceback (most recent call last):
  File "/common/ketrong/AutoImputeExp/tpot2_imputetest/Impute_Experiments/utils.py", line 310, in loop_through_tasks
    X_train, y_train, X_test, y_test = load_task(base_save_folder=base_save_folder, exp=exp, type=type, levelstr=levelstr, task_id=taskid, preprocess=True)
  File "/common/ketrong/AutoImputeExp/tpot2_imputetest/Impute_Experiments/utils.py", line 200, in load_task
    task = openml.tasks.get_task(task_id)
  File "/home/ketrong/miniconda3/envs/tpot2devenv/lib/python3.10/site-packages/openml/tasks/functions.py", line 415, in get_task
    raise e
  File "/home/ketrong/miniconda3/envs/tpot2devenv/lib/python3.10/site-packages/openml/tasks/functions.py", line 398, in get_task
    task = _get_task_description(task_id)
  File "/home/ketrong/miniconda3/envs/tpot2devenv/lib/python3.10/site-packages/openml/tasks/functions.py", line 431, in _get_task_description
    task_xml = openml._api_calls._perform_api_call("task/%d" % task_id, "get")
  File "/home/ketrong/miniconda3/envs/tpot2devenv/lib/python3.10/site-packages/openml/_api_calls.py", line 99, in _perform_api_call
    response = __read_url(url, request_method, data)
  File "/home/ketrong/miniconda3/envs/tpot2devenv/lib/python3.10/site-packages/openml/_api_calls.py", line 308, in __read_url
    return _send_request(
  File "/home/ketrong/miniconda3/envs/tpot2devenv/lib/python3.10/site-packages/openml/_api_calls.py", line 344, in _send_request
    __check_response(response=response, url=url, file_elements=files)
  File "/home/ketrong/miniconda3/envs/tpot2devenv/lib/python3.10/site-packages/openml/_api_calls.py", line 409, in __check_response
    raise __parse_server_exception(response, url, file_elements=file_elements)
openml.exceptions.OpenMLServerException: https://www.openml.org/api/v1/xml/task/881 returned code 151: Unknown task - None

881
remove from investigation?
881
finished
working on 
logs/901/tpot2_base_normal_MNAR_0.9
1.3277788162231445
loading data
logs/901/tpot2_base_normal_MNAR_0.9/data/901_True.pkl
https://www.openml.org/api/v1/xml/task/901 returned code 151: Unknown task - None
Traceback (most recent call last):
  File "/home/ketrong/miniconda3/envs/tpot2devenv/lib/python3.10/site-packages/openml/tasks/functions.py", line 70, in _get_cached_task
    with io.open(os.path.join(tid_cache_dir, "task.xml"), encoding="utf8") as fh:
FileNotFoundError: [Errno 2] No such file or directory: '/home/ketrong/.cache/openml/org/openml/www/tasks/901/task.xml'

During handling of the above exception, another exception occurred:

Traceback (most recent call last):
  File "/home/ketrong/miniconda3/envs/tpot2devenv/lib/python3.10/site-packages/openml/tasks/functions.py", line 422, in _get_task_description
    return _get_cached_task(task_id)
  File "/home/ketrong/miniconda3/envs/tpot2devenv/lib/python3.10/site-packages/openml/tasks/functions.py", line 74, in _get_cached_task
    raise OpenMLCacheException("Task file for tid %d not " "cached" % tid)
openml.exceptions.OpenMLCacheException: Task file for tid 901 not cached

During handling of the above exception, another exception occurred:

Traceback (most recent call last):
  File "/common/ketrong/AutoImputeExp/tpot2_imputetest/Impute_Experiments/utils.py", line 310, in loop_through_tasks
    X_train, y_train, X_test, y_test = load_task(base_save_folder=base_save_folder, exp=exp, type=type, levelstr=levelstr, task_id=taskid, preprocess=True)
  File "/common/ketrong/AutoImputeExp/tpot2_imputetest/Impute_Experiments/utils.py", line 200, in load_task
    task = openml.tasks.get_task(task_id)
  File "/home/ketrong/miniconda3/envs/tpot2devenv/lib/python3.10/site-packages/openml/tasks/functions.py", line 415, in get_task
    raise e
  File "/home/ketrong/miniconda3/envs/tpot2devenv/lib/python3.10/site-packages/openml/tasks/functions.py", line 398, in get_task
    task = _get_task_description(task_id)
  File "/home/ketrong/miniconda3/envs/tpot2devenv/lib/python3.10/site-packages/openml/tasks/functions.py", line 431, in _get_task_description
    task_xml = openml._api_calls._perform_api_call("task/%d" % task_id, "get")
  File "/home/ketrong/miniconda3/envs/tpot2devenv/lib/python3.10/site-packages/openml/_api_calls.py", line 99, in _perform_api_call
    response = __read_url(url, request_method, data)
  File "/home/ketrong/miniconda3/envs/tpot2devenv/lib/python3.10/site-packages/openml/_api_calls.py", line 308, in __read_url
    return _send_request(
  File "/home/ketrong/miniconda3/envs/tpot2devenv/lib/python3.10/site-packages/openml/_api_calls.py", line 344, in _send_request
    __check_response(response=response, url=url, file_elements=files)
  File "/home/ketrong/miniconda3/envs/tpot2devenv/lib/python3.10/site-packages/openml/_api_calls.py", line 409, in __check_response
    raise __parse_server_exception(response, url, file_elements=file_elements)
openml.exceptions.OpenMLServerException: https://www.openml.org/api/v1/xml/task/901 returned code 151: Unknown task - None

901
remove from investigation?
working on 
logs/901/tpot2_base_imputation_MNAR_0.9
3.9406356811523438
loading data
logs/901/tpot2_base_imputation_MNAR_0.9/data/901_True.pkl
https://www.openml.org/api/v1/xml/task/901 returned code 151: Unknown task - None
Traceback (most recent call last):
  File "/home/ketrong/miniconda3/envs/tpot2devenv/lib/python3.10/site-packages/openml/tasks/functions.py", line 70, in _get_cached_task
    with io.open(os.path.join(tid_cache_dir, "task.xml"), encoding="utf8") as fh:
FileNotFoundError: [Errno 2] No such file or directory: '/home/ketrong/.cache/openml/org/openml/www/tasks/901/task.xml'

During handling of the above exception, another exception occurred:

Traceback (most recent call last):
  File "/home/ketrong/miniconda3/envs/tpot2devenv/lib/python3.10/site-packages/openml/tasks/functions.py", line 422, in _get_task_description
    return _get_cached_task(task_id)
  File "/home/ketrong/miniconda3/envs/tpot2devenv/lib/python3.10/site-packages/openml/tasks/functions.py", line 74, in _get_cached_task
    raise OpenMLCacheException("Task file for tid %d not " "cached" % tid)
openml.exceptions.OpenMLCacheException: Task file for tid 901 not cached

During handling of the above exception, another exception occurred:

Traceback (most recent call last):
  File "/common/ketrong/AutoImputeExp/tpot2_imputetest/Impute_Experiments/utils.py", line 310, in loop_through_tasks
    X_train, y_train, X_test, y_test = load_task(base_save_folder=base_save_folder, exp=exp, type=type, levelstr=levelstr, task_id=taskid, preprocess=True)
  File "/common/ketrong/AutoImputeExp/tpot2_imputetest/Impute_Experiments/utils.py", line 200, in load_task
    task = openml.tasks.get_task(task_id)
  File "/home/ketrong/miniconda3/envs/tpot2devenv/lib/python3.10/site-packages/openml/tasks/functions.py", line 415, in get_task
    raise e
  File "/home/ketrong/miniconda3/envs/tpot2devenv/lib/python3.10/site-packages/openml/tasks/functions.py", line 398, in get_task
    task = _get_task_description(task_id)
  File "/home/ketrong/miniconda3/envs/tpot2devenv/lib/python3.10/site-packages/openml/tasks/functions.py", line 431, in _get_task_description
    task_xml = openml._api_calls._perform_api_call("task/%d" % task_id, "get")
  File "/home/ketrong/miniconda3/envs/tpot2devenv/lib/python3.10/site-packages/openml/_api_calls.py", line 99, in _perform_api_call
    response = __read_url(url, request_method, data)
  File "/home/ketrong/miniconda3/envs/tpot2devenv/lib/python3.10/site-packages/openml/_api_calls.py", line 308, in __read_url
    return _send_request(
  File "/home/ketrong/miniconda3/envs/tpot2devenv/lib/python3.10/site-packages/openml/_api_calls.py", line 344, in _send_request
    __check_response(response=response, url=url, file_elements=files)
  File "/home/ketrong/miniconda3/envs/tpot2devenv/lib/python3.10/site-packages/openml/_api_calls.py", line 409, in __check_response
    raise __parse_server_exception(response, url, file_elements=file_elements)
openml.exceptions.OpenMLServerException: https://www.openml.org/api/v1/xml/task/901 returned code 151: Unknown task - None

901
remove from investigation?
901
finished
working on 
logs/923/tpot2_base_normal_MNAR_0.9
4.014791011810303
loading data
logs/923/tpot2_base_normal_MNAR_0.9/data/923_True.pkl
https://www.openml.org/api/v1/xml/task/923 returned code 151: Unknown task - None
Traceback (most recent call last):
  File "/home/ketrong/miniconda3/envs/tpot2devenv/lib/python3.10/site-packages/openml/tasks/functions.py", line 70, in _get_cached_task
    with io.open(os.path.join(tid_cache_dir, "task.xml"), encoding="utf8") as fh:
FileNotFoundError: [Errno 2] No such file or directory: '/home/ketrong/.cache/openml/org/openml/www/tasks/923/task.xml'

During handling of the above exception, another exception occurred:

Traceback (most recent call last):
  File "/home/ketrong/miniconda3/envs/tpot2devenv/lib/python3.10/site-packages/openml/tasks/functions.py", line 422, in _get_task_description
    return _get_cached_task(task_id)
  File "/home/ketrong/miniconda3/envs/tpot2devenv/lib/python3.10/site-packages/openml/tasks/functions.py", line 74, in _get_cached_task
    raise OpenMLCacheException("Task file for tid %d not " "cached" % tid)
openml.exceptions.OpenMLCacheException: Task file for tid 923 not cached

During handling of the above exception, another exception occurred:

Traceback (most recent call last):
  File "/common/ketrong/AutoImputeExp/tpot2_imputetest/Impute_Experiments/utils.py", line 310, in loop_through_tasks
    X_train, y_train, X_test, y_test = load_task(base_save_folder=base_save_folder, exp=exp, type=type, levelstr=levelstr, task_id=taskid, preprocess=True)
  File "/common/ketrong/AutoImputeExp/tpot2_imputetest/Impute_Experiments/utils.py", line 200, in load_task
    task = openml.tasks.get_task(task_id)
  File "/home/ketrong/miniconda3/envs/tpot2devenv/lib/python3.10/site-packages/openml/tasks/functions.py", line 415, in get_task
    raise e
  File "/home/ketrong/miniconda3/envs/tpot2devenv/lib/python3.10/site-packages/openml/tasks/functions.py", line 398, in get_task
    task = _get_task_description(task_id)
  File "/home/ketrong/miniconda3/envs/tpot2devenv/lib/python3.10/site-packages/openml/tasks/functions.py", line 431, in _get_task_description
    task_xml = openml._api_calls._perform_api_call("task/%d" % task_id, "get")
  File "/home/ketrong/miniconda3/envs/tpot2devenv/lib/python3.10/site-packages/openml/_api_calls.py", line 99, in _perform_api_call
    response = __read_url(url, request_method, data)
  File "/home/ketrong/miniconda3/envs/tpot2devenv/lib/python3.10/site-packages/openml/_api_calls.py", line 308, in __read_url
    return _send_request(
  File "/home/ketrong/miniconda3/envs/tpot2devenv/lib/python3.10/site-packages/openml/_api_calls.py", line 344, in _send_request
    __check_response(response=response, url=url, file_elements=files)
  File "/home/ketrong/miniconda3/envs/tpot2devenv/lib/python3.10/site-packages/openml/_api_calls.py", line 409, in __check_response
    raise __parse_server_exception(response, url, file_elements=file_elements)
openml.exceptions.OpenMLServerException: https://www.openml.org/api/v1/xml/task/923 returned code 151: Unknown task - None

923
remove from investigation?
working on 
logs/923/tpot2_base_imputation_MNAR_0.9
2.976898431777954
loading data
logs/923/tpot2_base_imputation_MNAR_0.9/data/923_True.pkl
https://www.openml.org/api/v1/xml/task/923 returned code 151: Unknown task - None
Traceback (most recent call last):
  File "/home/ketrong/miniconda3/envs/tpot2devenv/lib/python3.10/site-packages/openml/tasks/functions.py", line 70, in _get_cached_task
    with io.open(os.path.join(tid_cache_dir, "task.xml"), encoding="utf8") as fh:
FileNotFoundError: [Errno 2] No such file or directory: '/home/ketrong/.cache/openml/org/openml/www/tasks/923/task.xml'

During handling of the above exception, another exception occurred:

Traceback (most recent call last):
  File "/home/ketrong/miniconda3/envs/tpot2devenv/lib/python3.10/site-packages/openml/tasks/functions.py", line 422, in _get_task_description
    return _get_cached_task(task_id)
  File "/home/ketrong/miniconda3/envs/tpot2devenv/lib/python3.10/site-packages/openml/tasks/functions.py", line 74, in _get_cached_task
    raise OpenMLCacheException("Task file for tid %d not " "cached" % tid)
openml.exceptions.OpenMLCacheException: Task file for tid 923 not cached

During handling of the above exception, another exception occurred:

Traceback (most recent call last):
  File "/common/ketrong/AutoImputeExp/tpot2_imputetest/Impute_Experiments/utils.py", line 310, in loop_through_tasks
    X_train, y_train, X_test, y_test = load_task(base_save_folder=base_save_folder, exp=exp, type=type, levelstr=levelstr, task_id=taskid, preprocess=True)
  File "/common/ketrong/AutoImputeExp/tpot2_imputetest/Impute_Experiments/utils.py", line 200, in load_task
    task = openml.tasks.get_task(task_id)
  File "/home/ketrong/miniconda3/envs/tpot2devenv/lib/python3.10/site-packages/openml/tasks/functions.py", line 415, in get_task
    raise e
  File "/home/ketrong/miniconda3/envs/tpot2devenv/lib/python3.10/site-packages/openml/tasks/functions.py", line 398, in get_task
    task = _get_task_description(task_id)
  File "/home/ketrong/miniconda3/envs/tpot2devenv/lib/python3.10/site-packages/openml/tasks/functions.py", line 431, in _get_task_description
    task_xml = openml._api_calls._perform_api_call("task/%d" % task_id, "get")
  File "/home/ketrong/miniconda3/envs/tpot2devenv/lib/python3.10/site-packages/openml/_api_calls.py", line 99, in _perform_api_call
    response = __read_url(url, request_method, data)
  File "/home/ketrong/miniconda3/envs/tpot2devenv/lib/python3.10/site-packages/openml/_api_calls.py", line 308, in __read_url
    return _send_request(
  File "/home/ketrong/miniconda3/envs/tpot2devenv/lib/python3.10/site-packages/openml/_api_calls.py", line 344, in _send_request
    __check_response(response=response, url=url, file_elements=files)
  File "/home/ketrong/miniconda3/envs/tpot2devenv/lib/python3.10/site-packages/openml/_api_calls.py", line 409, in __check_response
    raise __parse_server_exception(response, url, file_elements=file_elements)
openml.exceptions.OpenMLServerException: https://www.openml.org/api/v1/xml/task/923 returned code 151: Unknown task - None

923
remove from investigation?
923
finished
working on 
logs/1046/tpot2_base_normal_MNAR_0.9
0.4537813663482666
loading data
logs/1046/tpot2_base_normal_MNAR_0.9/data/1046_True.pkl
https://www.openml.org/api/v1/xml/task/1046 returned code 151: Unknown task - None
Traceback (most recent call last):
  File "/home/ketrong/miniconda3/envs/tpot2devenv/lib/python3.10/site-packages/openml/tasks/functions.py", line 70, in _get_cached_task
    with io.open(os.path.join(tid_cache_dir, "task.xml"), encoding="utf8") as fh:
FileNotFoundError: [Errno 2] No such file or directory: '/home/ketrong/.cache/openml/org/openml/www/tasks/1046/task.xml'

During handling of the above exception, another exception occurred:

Traceback (most recent call last):
  File "/home/ketrong/miniconda3/envs/tpot2devenv/lib/python3.10/site-packages/openml/tasks/functions.py", line 422, in _get_task_description
    return _get_cached_task(task_id)
  File "/home/ketrong/miniconda3/envs/tpot2devenv/lib/python3.10/site-packages/openml/tasks/functions.py", line 74, in _get_cached_task
    raise OpenMLCacheException("Task file for tid %d not " "cached" % tid)
openml.exceptions.OpenMLCacheException: Task file for tid 1046 not cached

During handling of the above exception, another exception occurred:

Traceback (most recent call last):
  File "/common/ketrong/AutoImputeExp/tpot2_imputetest/Impute_Experiments/utils.py", line 310, in loop_through_tasks
    X_train, y_train, X_test, y_test = load_task(base_save_folder=base_save_folder, exp=exp, type=type, levelstr=levelstr, task_id=taskid, preprocess=True)
  File "/common/ketrong/AutoImputeExp/tpot2_imputetest/Impute_Experiments/utils.py", line 200, in load_task
    task = openml.tasks.get_task(task_id)
  File "/home/ketrong/miniconda3/envs/tpot2devenv/lib/python3.10/site-packages/openml/tasks/functions.py", line 415, in get_task
    raise e
  File "/home/ketrong/miniconda3/envs/tpot2devenv/lib/python3.10/site-packages/openml/tasks/functions.py", line 398, in get_task
    task = _get_task_description(task_id)
  File "/home/ketrong/miniconda3/envs/tpot2devenv/lib/python3.10/site-packages/openml/tasks/functions.py", line 431, in _get_task_description
    task_xml = openml._api_calls._perform_api_call("task/%d" % task_id, "get")
  File "/home/ketrong/miniconda3/envs/tpot2devenv/lib/python3.10/site-packages/openml/_api_calls.py", line 99, in _perform_api_call
    response = __read_url(url, request_method, data)
  File "/home/ketrong/miniconda3/envs/tpot2devenv/lib/python3.10/site-packages/openml/_api_calls.py", line 308, in __read_url
    return _send_request(
  File "/home/ketrong/miniconda3/envs/tpot2devenv/lib/python3.10/site-packages/openml/_api_calls.py", line 344, in _send_request
    __check_response(response=response, url=url, file_elements=files)
  File "/home/ketrong/miniconda3/envs/tpot2devenv/lib/python3.10/site-packages/openml/_api_calls.py", line 409, in __check_response
    raise __parse_server_exception(response, url, file_elements=file_elements)
openml.exceptions.OpenMLServerException: https://www.openml.org/api/v1/xml/task/1046 returned code 151: Unknown task - None

1046
remove from investigation?
working on 
logs/1046/tpot2_base_imputation_MNAR_0.9
2.410893201828003
loading data
logs/1046/tpot2_base_imputation_MNAR_0.9/data/1046_True.pkl
https://www.openml.org/api/v1/xml/task/1046 returned code 151: Unknown task - None
Traceback (most recent call last):
  File "/home/ketrong/miniconda3/envs/tpot2devenv/lib/python3.10/site-packages/openml/tasks/functions.py", line 70, in _get_cached_task
    with io.open(os.path.join(tid_cache_dir, "task.xml"), encoding="utf8") as fh:
FileNotFoundError: [Errno 2] No such file or directory: '/home/ketrong/.cache/openml/org/openml/www/tasks/1046/task.xml'

During handling of the above exception, another exception occurred:

Traceback (most recent call last):
  File "/home/ketrong/miniconda3/envs/tpot2devenv/lib/python3.10/site-packages/openml/tasks/functions.py", line 422, in _get_task_description
    return _get_cached_task(task_id)
  File "/home/ketrong/miniconda3/envs/tpot2devenv/lib/python3.10/site-packages/openml/tasks/functions.py", line 74, in _get_cached_task
    raise OpenMLCacheException("Task file for tid %d not " "cached" % tid)
openml.exceptions.OpenMLCacheException: Task file for tid 1046 not cached

During handling of the above exception, another exception occurred:

Traceback (most recent call last):
  File "/common/ketrong/AutoImputeExp/tpot2_imputetest/Impute_Experiments/utils.py", line 310, in loop_through_tasks
    X_train, y_train, X_test, y_test = load_task(base_save_folder=base_save_folder, exp=exp, type=type, levelstr=levelstr, task_id=taskid, preprocess=True)
  File "/common/ketrong/AutoImputeExp/tpot2_imputetest/Impute_Experiments/utils.py", line 200, in load_task
    task = openml.tasks.get_task(task_id)
  File "/home/ketrong/miniconda3/envs/tpot2devenv/lib/python3.10/site-packages/openml/tasks/functions.py", line 415, in get_task
    raise e
  File "/home/ketrong/miniconda3/envs/tpot2devenv/lib/python3.10/site-packages/openml/tasks/functions.py", line 398, in get_task
    task = _get_task_description(task_id)
  File "/home/ketrong/miniconda3/envs/tpot2devenv/lib/python3.10/site-packages/openml/tasks/functions.py", line 431, in _get_task_description
    task_xml = openml._api_calls._perform_api_call("task/%d" % task_id, "get")
  File "/home/ketrong/miniconda3/envs/tpot2devenv/lib/python3.10/site-packages/openml/_api_calls.py", line 99, in _perform_api_call
    response = __read_url(url, request_method, data)
  File "/home/ketrong/miniconda3/envs/tpot2devenv/lib/python3.10/site-packages/openml/_api_calls.py", line 308, in __read_url
    return _send_request(
  File "/home/ketrong/miniconda3/envs/tpot2devenv/lib/python3.10/site-packages/openml/_api_calls.py", line 344, in _send_request
    __check_response(response=response, url=url, file_elements=files)
  File "/home/ketrong/miniconda3/envs/tpot2devenv/lib/python3.10/site-packages/openml/_api_calls.py", line 409, in __check_response
    raise __parse_server_exception(response, url, file_elements=file_elements)
openml.exceptions.OpenMLServerException: https://www.openml.org/api/v1/xml/task/1046 returned code 151: Unknown task - None

1046
remove from investigation?
1046
finished
working on 
logs/1120/tpot2_base_normal_MNAR_0.9
4.816693544387817
loading data
logs/1120/tpot2_base_normal_MNAR_0.9/data/1120_True.pkl
https://www.openml.org/api/v1/xml/task/1120 returned code 151: Unknown task - None
Traceback (most recent call last):
  File "/home/ketrong/miniconda3/envs/tpot2devenv/lib/python3.10/site-packages/openml/tasks/functions.py", line 70, in _get_cached_task
    with io.open(os.path.join(tid_cache_dir, "task.xml"), encoding="utf8") as fh:
FileNotFoundError: [Errno 2] No such file or directory: '/home/ketrong/.cache/openml/org/openml/www/tasks/1120/task.xml'

During handling of the above exception, another exception occurred:

Traceback (most recent call last):
  File "/home/ketrong/miniconda3/envs/tpot2devenv/lib/python3.10/site-packages/openml/tasks/functions.py", line 422, in _get_task_description
    return _get_cached_task(task_id)
  File "/home/ketrong/miniconda3/envs/tpot2devenv/lib/python3.10/site-packages/openml/tasks/functions.py", line 74, in _get_cached_task
    raise OpenMLCacheException("Task file for tid %d not " "cached" % tid)
openml.exceptions.OpenMLCacheException: Task file for tid 1120 not cached

During handling of the above exception, another exception occurred:

Traceback (most recent call last):
  File "/common/ketrong/AutoImputeExp/tpot2_imputetest/Impute_Experiments/utils.py", line 310, in loop_through_tasks
    X_train, y_train, X_test, y_test = load_task(base_save_folder=base_save_folder, exp=exp, type=type, levelstr=levelstr, task_id=taskid, preprocess=True)
  File "/common/ketrong/AutoImputeExp/tpot2_imputetest/Impute_Experiments/utils.py", line 200, in load_task
    task = openml.tasks.get_task(task_id)
  File "/home/ketrong/miniconda3/envs/tpot2devenv/lib/python3.10/site-packages/openml/tasks/functions.py", line 415, in get_task
    raise e
  File "/home/ketrong/miniconda3/envs/tpot2devenv/lib/python3.10/site-packages/openml/tasks/functions.py", line 398, in get_task
    task = _get_task_description(task_id)
  File "/home/ketrong/miniconda3/envs/tpot2devenv/lib/python3.10/site-packages/openml/tasks/functions.py", line 431, in _get_task_description
    task_xml = openml._api_calls._perform_api_call("task/%d" % task_id, "get")
  File "/home/ketrong/miniconda3/envs/tpot2devenv/lib/python3.10/site-packages/openml/_api_calls.py", line 99, in _perform_api_call
    response = __read_url(url, request_method, data)
  File "/home/ketrong/miniconda3/envs/tpot2devenv/lib/python3.10/site-packages/openml/_api_calls.py", line 308, in __read_url
    return _send_request(
  File "/home/ketrong/miniconda3/envs/tpot2devenv/lib/python3.10/site-packages/openml/_api_calls.py", line 344, in _send_request
    __check_response(response=response, url=url, file_elements=files)
  File "/home/ketrong/miniconda3/envs/tpot2devenv/lib/python3.10/site-packages/openml/_api_calls.py", line 409, in __check_response
    raise __parse_server_exception(response, url, file_elements=file_elements)
openml.exceptions.OpenMLServerException: https://www.openml.org/api/v1/xml/task/1120 returned code 151: Unknown task - None

1120
remove from investigation?
working on 
logs/1120/tpot2_base_imputation_MNAR_0.9
3.996121406555176
loading data
logs/1120/tpot2_base_imputation_MNAR_0.9/data/1120_True.pkl
https://www.openml.org/api/v1/xml/task/1120 returned code 151: Unknown task - None
Traceback (most recent call last):
  File "/home/ketrong/miniconda3/envs/tpot2devenv/lib/python3.10/site-packages/openml/tasks/functions.py", line 70, in _get_cached_task
    with io.open(os.path.join(tid_cache_dir, "task.xml"), encoding="utf8") as fh:
FileNotFoundError: [Errno 2] No such file or directory: '/home/ketrong/.cache/openml/org/openml/www/tasks/1120/task.xml'

During handling of the above exception, another exception occurred:

Traceback (most recent call last):
  File "/home/ketrong/miniconda3/envs/tpot2devenv/lib/python3.10/site-packages/openml/tasks/functions.py", line 422, in _get_task_description
    return _get_cached_task(task_id)
  File "/home/ketrong/miniconda3/envs/tpot2devenv/lib/python3.10/site-packages/openml/tasks/functions.py", line 74, in _get_cached_task
    raise OpenMLCacheException("Task file for tid %d not " "cached" % tid)
openml.exceptions.OpenMLCacheException: Task file for tid 1120 not cached

During handling of the above exception, another exception occurred:

Traceback (most recent call last):
  File "/common/ketrong/AutoImputeExp/tpot2_imputetest/Impute_Experiments/utils.py", line 310, in loop_through_tasks
    X_train, y_train, X_test, y_test = load_task(base_save_folder=base_save_folder, exp=exp, type=type, levelstr=levelstr, task_id=taskid, preprocess=True)
  File "/common/ketrong/AutoImputeExp/tpot2_imputetest/Impute_Experiments/utils.py", line 200, in load_task
    task = openml.tasks.get_task(task_id)
  File "/home/ketrong/miniconda3/envs/tpot2devenv/lib/python3.10/site-packages/openml/tasks/functions.py", line 415, in get_task
    raise e
  File "/home/ketrong/miniconda3/envs/tpot2devenv/lib/python3.10/site-packages/openml/tasks/functions.py", line 398, in get_task
    task = _get_task_description(task_id)
  File "/home/ketrong/miniconda3/envs/tpot2devenv/lib/python3.10/site-packages/openml/tasks/functions.py", line 431, in _get_task_description
    task_xml = openml._api_calls._perform_api_call("task/%d" % task_id, "get")
  File "/home/ketrong/miniconda3/envs/tpot2devenv/lib/python3.10/site-packages/openml/_api_calls.py", line 99, in _perform_api_call
    response = __read_url(url, request_method, data)
  File "/home/ketrong/miniconda3/envs/tpot2devenv/lib/python3.10/site-packages/openml/_api_calls.py", line 308, in __read_url
    return _send_request(
  File "/home/ketrong/miniconda3/envs/tpot2devenv/lib/python3.10/site-packages/openml/_api_calls.py", line 344, in _send_request
    __check_response(response=response, url=url, file_elements=files)
  File "/home/ketrong/miniconda3/envs/tpot2devenv/lib/python3.10/site-packages/openml/_api_calls.py", line 409, in __check_response
    raise __parse_server_exception(response, url, file_elements=file_elements)
openml.exceptions.OpenMLServerException: https://www.openml.org/api/v1/xml/task/1120 returned code 151: Unknown task - None

1120
remove from investigation?
1120
finished
working on 
logs/1193/tpot2_base_normal_MNAR_0.9
0.9763336181640625
loading data
logs/1193/tpot2_base_normal_MNAR_0.9/data/1193_True.pkl
https://www.openml.org/api/v1/xml/task/1193 returned code 151: Unknown task - None
Traceback (most recent call last):
  File "/home/ketrong/miniconda3/envs/tpot2devenv/lib/python3.10/site-packages/openml/tasks/functions.py", line 70, in _get_cached_task
    with io.open(os.path.join(tid_cache_dir, "task.xml"), encoding="utf8") as fh:
FileNotFoundError: [Errno 2] No such file or directory: '/home/ketrong/.cache/openml/org/openml/www/tasks/1193/task.xml'

During handling of the above exception, another exception occurred:

Traceback (most recent call last):
  File "/home/ketrong/miniconda3/envs/tpot2devenv/lib/python3.10/site-packages/openml/tasks/functions.py", line 422, in _get_task_description
    return _get_cached_task(task_id)
  File "/home/ketrong/miniconda3/envs/tpot2devenv/lib/python3.10/site-packages/openml/tasks/functions.py", line 74, in _get_cached_task
    raise OpenMLCacheException("Task file for tid %d not " "cached" % tid)
openml.exceptions.OpenMLCacheException: Task file for tid 1193 not cached

During handling of the above exception, another exception occurred:

Traceback (most recent call last):
  File "/common/ketrong/AutoImputeExp/tpot2_imputetest/Impute_Experiments/utils.py", line 310, in loop_through_tasks
    X_train, y_train, X_test, y_test = load_task(base_save_folder=base_save_folder, exp=exp, type=type, levelstr=levelstr, task_id=taskid, preprocess=True)
  File "/common/ketrong/AutoImputeExp/tpot2_imputetest/Impute_Experiments/utils.py", line 200, in load_task
    task = openml.tasks.get_task(task_id)
  File "/home/ketrong/miniconda3/envs/tpot2devenv/lib/python3.10/site-packages/openml/tasks/functions.py", line 415, in get_task
    raise e
  File "/home/ketrong/miniconda3/envs/tpot2devenv/lib/python3.10/site-packages/openml/tasks/functions.py", line 398, in get_task
    task = _get_task_description(task_id)
  File "/home/ketrong/miniconda3/envs/tpot2devenv/lib/python3.10/site-packages/openml/tasks/functions.py", line 431, in _get_task_description
    task_xml = openml._api_calls._perform_api_call("task/%d" % task_id, "get")
  File "/home/ketrong/miniconda3/envs/tpot2devenv/lib/python3.10/site-packages/openml/_api_calls.py", line 99, in _perform_api_call
    response = __read_url(url, request_method, data)
  File "/home/ketrong/miniconda3/envs/tpot2devenv/lib/python3.10/site-packages/openml/_api_calls.py", line 308, in __read_url
    return _send_request(
  File "/home/ketrong/miniconda3/envs/tpot2devenv/lib/python3.10/site-packages/openml/_api_calls.py", line 344, in _send_request
    __check_response(response=response, url=url, file_elements=files)
  File "/home/ketrong/miniconda3/envs/tpot2devenv/lib/python3.10/site-packages/openml/_api_calls.py", line 409, in __check_response
    raise __parse_server_exception(response, url, file_elements=file_elements)
openml.exceptions.OpenMLServerException: https://www.openml.org/api/v1/xml/task/1193 returned code 151: Unknown task - None

1193
remove from investigation?
working on 
logs/1193/tpot2_base_imputation_MNAR_0.9
3.8828084468841553
loading data
logs/1193/tpot2_base_imputation_MNAR_0.9/data/1193_True.pkl
https://www.openml.org/api/v1/xml/task/1193 returned code 151: Unknown task - None
Traceback (most recent call last):
  File "/home/ketrong/miniconda3/envs/tpot2devenv/lib/python3.10/site-packages/openml/tasks/functions.py", line 70, in _get_cached_task
    with io.open(os.path.join(tid_cache_dir, "task.xml"), encoding="utf8") as fh:
FileNotFoundError: [Errno 2] No such file or directory: '/home/ketrong/.cache/openml/org/openml/www/tasks/1193/task.xml'

During handling of the above exception, another exception occurred:

Traceback (most recent call last):
  File "/home/ketrong/miniconda3/envs/tpot2devenv/lib/python3.10/site-packages/openml/tasks/functions.py", line 422, in _get_task_description
    return _get_cached_task(task_id)
  File "/home/ketrong/miniconda3/envs/tpot2devenv/lib/python3.10/site-packages/openml/tasks/functions.py", line 74, in _get_cached_task
    raise OpenMLCacheException("Task file for tid %d not " "cached" % tid)
openml.exceptions.OpenMLCacheException: Task file for tid 1193 not cached

During handling of the above exception, another exception occurred:

Traceback (most recent call last):
  File "/common/ketrong/AutoImputeExp/tpot2_imputetest/Impute_Experiments/utils.py", line 310, in loop_through_tasks
    X_train, y_train, X_test, y_test = load_task(base_save_folder=base_save_folder, exp=exp, type=type, levelstr=levelstr, task_id=taskid, preprocess=True)
  File "/common/ketrong/AutoImputeExp/tpot2_imputetest/Impute_Experiments/utils.py", line 200, in load_task
    task = openml.tasks.get_task(task_id)
  File "/home/ketrong/miniconda3/envs/tpot2devenv/lib/python3.10/site-packages/openml/tasks/functions.py", line 415, in get_task
    raise e
  File "/home/ketrong/miniconda3/envs/tpot2devenv/lib/python3.10/site-packages/openml/tasks/functions.py", line 398, in get_task
    task = _get_task_description(task_id)
  File "/home/ketrong/miniconda3/envs/tpot2devenv/lib/python3.10/site-packages/openml/tasks/functions.py", line 431, in _get_task_description
    task_xml = openml._api_calls._perform_api_call("task/%d" % task_id, "get")
  File "/home/ketrong/miniconda3/envs/tpot2devenv/lib/python3.10/site-packages/openml/_api_calls.py", line 99, in _perform_api_call
    response = __read_url(url, request_method, data)
  File "/home/ketrong/miniconda3/envs/tpot2devenv/lib/python3.10/site-packages/openml/_api_calls.py", line 308, in __read_url
    return _send_request(
  File "/home/ketrong/miniconda3/envs/tpot2devenv/lib/python3.10/site-packages/openml/_api_calls.py", line 344, in _send_request
    __check_response(response=response, url=url, file_elements=files)
  File "/home/ketrong/miniconda3/envs/tpot2devenv/lib/python3.10/site-packages/openml/_api_calls.py", line 409, in __check_response
    raise __parse_server_exception(response, url, file_elements=file_elements)
openml.exceptions.OpenMLServerException: https://www.openml.org/api/v1/xml/task/1193 returned code 151: Unknown task - None

1193
remove from investigation?
1193
finished
working on 
logs/1199/tpot2_base_normal_MNAR_0.9
1.1616284847259521
loading data
logs/1199/tpot2_base_normal_MNAR_0.9/data/1199_True.pkl
https://www.openml.org/api/v1/xml/task/1199 returned code 151: Unknown task - None
Traceback (most recent call last):
  File "/home/ketrong/miniconda3/envs/tpot2devenv/lib/python3.10/site-packages/openml/tasks/functions.py", line 70, in _get_cached_task
    with io.open(os.path.join(tid_cache_dir, "task.xml"), encoding="utf8") as fh:
FileNotFoundError: [Errno 2] No such file or directory: '/home/ketrong/.cache/openml/org/openml/www/tasks/1199/task.xml'

During handling of the above exception, another exception occurred:

Traceback (most recent call last):
  File "/home/ketrong/miniconda3/envs/tpot2devenv/lib/python3.10/site-packages/openml/tasks/functions.py", line 422, in _get_task_description
    return _get_cached_task(task_id)
  File "/home/ketrong/miniconda3/envs/tpot2devenv/lib/python3.10/site-packages/openml/tasks/functions.py", line 74, in _get_cached_task
    raise OpenMLCacheException("Task file for tid %d not " "cached" % tid)
openml.exceptions.OpenMLCacheException: Task file for tid 1199 not cached

During handling of the above exception, another exception occurred:

Traceback (most recent call last):
  File "/common/ketrong/AutoImputeExp/tpot2_imputetest/Impute_Experiments/utils.py", line 310, in loop_through_tasks
    X_train, y_train, X_test, y_test = load_task(base_save_folder=base_save_folder, exp=exp, type=type, levelstr=levelstr, task_id=taskid, preprocess=True)
  File "/common/ketrong/AutoImputeExp/tpot2_imputetest/Impute_Experiments/utils.py", line 200, in load_task
    task = openml.tasks.get_task(task_id)
  File "/home/ketrong/miniconda3/envs/tpot2devenv/lib/python3.10/site-packages/openml/tasks/functions.py", line 415, in get_task
    raise e
  File "/home/ketrong/miniconda3/envs/tpot2devenv/lib/python3.10/site-packages/openml/tasks/functions.py", line 398, in get_task
    task = _get_task_description(task_id)
  File "/home/ketrong/miniconda3/envs/tpot2devenv/lib/python3.10/site-packages/openml/tasks/functions.py", line 431, in _get_task_description
    task_xml = openml._api_calls._perform_api_call("task/%d" % task_id, "get")
  File "/home/ketrong/miniconda3/envs/tpot2devenv/lib/python3.10/site-packages/openml/_api_calls.py", line 99, in _perform_api_call
    response = __read_url(url, request_method, data)
  File "/home/ketrong/miniconda3/envs/tpot2devenv/lib/python3.10/site-packages/openml/_api_calls.py", line 308, in __read_url
    return _send_request(
  File "/home/ketrong/miniconda3/envs/tpot2devenv/lib/python3.10/site-packages/openml/_api_calls.py", line 344, in _send_request
    __check_response(response=response, url=url, file_elements=files)
  File "/home/ketrong/miniconda3/envs/tpot2devenv/lib/python3.10/site-packages/openml/_api_calls.py", line 409, in __check_response
    raise __parse_server_exception(response, url, file_elements=file_elements)
openml.exceptions.OpenMLServerException: https://www.openml.org/api/v1/xml/task/1199 returned code 151: Unknown task - None

1199
remove from investigation?
working on 
logs/1199/tpot2_base_imputation_MNAR_0.9
3.034181594848633
loading data
logs/1199/tpot2_base_imputation_MNAR_0.9/data/1199_True.pkl
https://www.openml.org/api/v1/xml/task/1199 returned code 151: Unknown task - None
Traceback (most recent call last):
  File "/home/ketrong/miniconda3/envs/tpot2devenv/lib/python3.10/site-packages/openml/tasks/functions.py", line 70, in _get_cached_task
    with io.open(os.path.join(tid_cache_dir, "task.xml"), encoding="utf8") as fh:
FileNotFoundError: [Errno 2] No such file or directory: '/home/ketrong/.cache/openml/org/openml/www/tasks/1199/task.xml'

During handling of the above exception, another exception occurred:

Traceback (most recent call last):
  File "/home/ketrong/miniconda3/envs/tpot2devenv/lib/python3.10/site-packages/openml/tasks/functions.py", line 422, in _get_task_description
    return _get_cached_task(task_id)
  File "/home/ketrong/miniconda3/envs/tpot2devenv/lib/python3.10/site-packages/openml/tasks/functions.py", line 74, in _get_cached_task
    raise OpenMLCacheException("Task file for tid %d not " "cached" % tid)
openml.exceptions.OpenMLCacheException: Task file for tid 1199 not cached

During handling of the above exception, another exception occurred:

Traceback (most recent call last):
  File "/common/ketrong/AutoImputeExp/tpot2_imputetest/Impute_Experiments/utils.py", line 310, in loop_through_tasks
    X_train, y_train, X_test, y_test = load_task(base_save_folder=base_save_folder, exp=exp, type=type, levelstr=levelstr, task_id=taskid, preprocess=True)
  File "/common/ketrong/AutoImputeExp/tpot2_imputetest/Impute_Experiments/utils.py", line 200, in load_task
    task = openml.tasks.get_task(task_id)
  File "/home/ketrong/miniconda3/envs/tpot2devenv/lib/python3.10/site-packages/openml/tasks/functions.py", line 415, in get_task
    raise e
  File "/home/ketrong/miniconda3/envs/tpot2devenv/lib/python3.10/site-packages/openml/tasks/functions.py", line 398, in get_task
    task = _get_task_description(task_id)
  File "/home/ketrong/miniconda3/envs/tpot2devenv/lib/python3.10/site-packages/openml/tasks/functions.py", line 431, in _get_task_description
    task_xml = openml._api_calls._perform_api_call("task/%d" % task_id, "get")
  File "/home/ketrong/miniconda3/envs/tpot2devenv/lib/python3.10/site-packages/openml/_api_calls.py", line 99, in _perform_api_call
    response = __read_url(url, request_method, data)
  File "/home/ketrong/miniconda3/envs/tpot2devenv/lib/python3.10/site-packages/openml/_api_calls.py", line 308, in __read_url
    return _send_request(
  File "/home/ketrong/miniconda3/envs/tpot2devenv/lib/python3.10/site-packages/openml/_api_calls.py", line 344, in _send_request
    __check_response(response=response, url=url, file_elements=files)
  File "/home/ketrong/miniconda3/envs/tpot2devenv/lib/python3.10/site-packages/openml/_api_calls.py", line 409, in __check_response
    raise __parse_server_exception(response, url, file_elements=file_elements)
openml.exceptions.OpenMLServerException: https://www.openml.org/api/v1/xml/task/1199 returned code 151: Unknown task - None

1199
remove from investigation?
1199
finished
working on 
logs/1200/tpot2_base_normal_MNAR_0.9
1.5561413764953613
loading data
logs/1200/tpot2_base_normal_MNAR_0.9/data/1200_True.pkl
https://www.openml.org/api/v1/xml/task/1200 returned code 151: Unknown task - None
Traceback (most recent call last):
  File "/home/ketrong/miniconda3/envs/tpot2devenv/lib/python3.10/site-packages/openml/tasks/functions.py", line 70, in _get_cached_task
    with io.open(os.path.join(tid_cache_dir, "task.xml"), encoding="utf8") as fh:
FileNotFoundError: [Errno 2] No such file or directory: '/home/ketrong/.cache/openml/org/openml/www/tasks/1200/task.xml'

During handling of the above exception, another exception occurred:

Traceback (most recent call last):
  File "/home/ketrong/miniconda3/envs/tpot2devenv/lib/python3.10/site-packages/openml/tasks/functions.py", line 422, in _get_task_description
    return _get_cached_task(task_id)
  File "/home/ketrong/miniconda3/envs/tpot2devenv/lib/python3.10/site-packages/openml/tasks/functions.py", line 74, in _get_cached_task
    raise OpenMLCacheException("Task file for tid %d not " "cached" % tid)
openml.exceptions.OpenMLCacheException: Task file for tid 1200 not cached

During handling of the above exception, another exception occurred:

Traceback (most recent call last):
  File "/common/ketrong/AutoImputeExp/tpot2_imputetest/Impute_Experiments/utils.py", line 310, in loop_through_tasks
    X_train, y_train, X_test, y_test = load_task(base_save_folder=base_save_folder, exp=exp, type=type, levelstr=levelstr, task_id=taskid, preprocess=True)
  File "/common/ketrong/AutoImputeExp/tpot2_imputetest/Impute_Experiments/utils.py", line 200, in load_task
    task = openml.tasks.get_task(task_id)
  File "/home/ketrong/miniconda3/envs/tpot2devenv/lib/python3.10/site-packages/openml/tasks/functions.py", line 415, in get_task
    raise e
  File "/home/ketrong/miniconda3/envs/tpot2devenv/lib/python3.10/site-packages/openml/tasks/functions.py", line 398, in get_task
    task = _get_task_description(task_id)
  File "/home/ketrong/miniconda3/envs/tpot2devenv/lib/python3.10/site-packages/openml/tasks/functions.py", line 431, in _get_task_description
    task_xml = openml._api_calls._perform_api_call("task/%d" % task_id, "get")
  File "/home/ketrong/miniconda3/envs/tpot2devenv/lib/python3.10/site-packages/openml/_api_calls.py", line 99, in _perform_api_call
    response = __read_url(url, request_method, data)
  File "/home/ketrong/miniconda3/envs/tpot2devenv/lib/python3.10/site-packages/openml/_api_calls.py", line 308, in __read_url
    return _send_request(
  File "/home/ketrong/miniconda3/envs/tpot2devenv/lib/python3.10/site-packages/openml/_api_calls.py", line 344, in _send_request
    __check_response(response=response, url=url, file_elements=files)
  File "/home/ketrong/miniconda3/envs/tpot2devenv/lib/python3.10/site-packages/openml/_api_calls.py", line 409, in __check_response
    raise __parse_server_exception(response, url, file_elements=file_elements)
openml.exceptions.OpenMLServerException: https://www.openml.org/api/v1/xml/task/1200 returned code 151: Unknown task - None

1200
remove from investigation?
working on 
logs/1200/tpot2_base_imputation_MNAR_0.9
2.027975559234619
loading data
logs/1200/tpot2_base_imputation_MNAR_0.9/data/1200_True.pkl
https://www.openml.org/api/v1/xml/task/1200 returned code 151: Unknown task - None
Traceback (most recent call last):
  File "/home/ketrong/miniconda3/envs/tpot2devenv/lib/python3.10/site-packages/openml/tasks/functions.py", line 70, in _get_cached_task
    with io.open(os.path.join(tid_cache_dir, "task.xml"), encoding="utf8") as fh:
FileNotFoundError: [Errno 2] No such file or directory: '/home/ketrong/.cache/openml/org/openml/www/tasks/1200/task.xml'

During handling of the above exception, another exception occurred:

Traceback (most recent call last):
  File "/home/ketrong/miniconda3/envs/tpot2devenv/lib/python3.10/site-packages/openml/tasks/functions.py", line 422, in _get_task_description
    return _get_cached_task(task_id)
  File "/home/ketrong/miniconda3/envs/tpot2devenv/lib/python3.10/site-packages/openml/tasks/functions.py", line 74, in _get_cached_task
    raise OpenMLCacheException("Task file for tid %d not " "cached" % tid)
openml.exceptions.OpenMLCacheException: Task file for tid 1200 not cached

During handling of the above exception, another exception occurred:

Traceback (most recent call last):
  File "/common/ketrong/AutoImputeExp/tpot2_imputetest/Impute_Experiments/utils.py", line 310, in loop_through_tasks
    X_train, y_train, X_test, y_test = load_task(base_save_folder=base_save_folder, exp=exp, type=type, levelstr=levelstr, task_id=taskid, preprocess=True)
  File "/common/ketrong/AutoImputeExp/tpot2_imputetest/Impute_Experiments/utils.py", line 200, in load_task
    task = openml.tasks.get_task(task_id)
  File "/home/ketrong/miniconda3/envs/tpot2devenv/lib/python3.10/site-packages/openml/tasks/functions.py", line 415, in get_task
    raise e
  File "/home/ketrong/miniconda3/envs/tpot2devenv/lib/python3.10/site-packages/openml/tasks/functions.py", line 398, in get_task
    task = _get_task_description(task_id)
  File "/home/ketrong/miniconda3/envs/tpot2devenv/lib/python3.10/site-packages/openml/tasks/functions.py", line 431, in _get_task_description
    task_xml = openml._api_calls._perform_api_call("task/%d" % task_id, "get")
  File "/home/ketrong/miniconda3/envs/tpot2devenv/lib/python3.10/site-packages/openml/_api_calls.py", line 99, in _perform_api_call
    response = __read_url(url, request_method, data)
  File "/home/ketrong/miniconda3/envs/tpot2devenv/lib/python3.10/site-packages/openml/_api_calls.py", line 308, in __read_url
    return _send_request(
  File "/home/ketrong/miniconda3/envs/tpot2devenv/lib/python3.10/site-packages/openml/_api_calls.py", line 344, in _send_request
    __check_response(response=response, url=url, file_elements=files)
  File "/home/ketrong/miniconda3/envs/tpot2devenv/lib/python3.10/site-packages/openml/_api_calls.py", line 409, in __check_response
    raise __parse_server_exception(response, url, file_elements=file_elements)
openml.exceptions.OpenMLServerException: https://www.openml.org/api/v1/xml/task/1200 returned code 151: Unknown task - None

1200
remove from investigation?
1200
finished
working on 
logs/1213/tpot2_base_normal_MNAR_0.9
2.5810654163360596
loading data
logs/1213/tpot2_base_normal_MNAR_0.9/data/1213_True.pkl
https://www.openml.org/api/v1/xml/task/1213 returned code 151: Unknown task - None
Traceback (most recent call last):
  File "/home/ketrong/miniconda3/envs/tpot2devenv/lib/python3.10/site-packages/openml/tasks/functions.py", line 70, in _get_cached_task
    with io.open(os.path.join(tid_cache_dir, "task.xml"), encoding="utf8") as fh:
FileNotFoundError: [Errno 2] No such file or directory: '/home/ketrong/.cache/openml/org/openml/www/tasks/1213/task.xml'

During handling of the above exception, another exception occurred:

Traceback (most recent call last):
  File "/home/ketrong/miniconda3/envs/tpot2devenv/lib/python3.10/site-packages/openml/tasks/functions.py", line 422, in _get_task_description
    return _get_cached_task(task_id)
  File "/home/ketrong/miniconda3/envs/tpot2devenv/lib/python3.10/site-packages/openml/tasks/functions.py", line 74, in _get_cached_task
    raise OpenMLCacheException("Task file for tid %d not " "cached" % tid)
openml.exceptions.OpenMLCacheException: Task file for tid 1213 not cached

During handling of the above exception, another exception occurred:

Traceback (most recent call last):
  File "/common/ketrong/AutoImputeExp/tpot2_imputetest/Impute_Experiments/utils.py", line 310, in loop_through_tasks
    X_train, y_train, X_test, y_test = load_task(base_save_folder=base_save_folder, exp=exp, type=type, levelstr=levelstr, task_id=taskid, preprocess=True)
  File "/common/ketrong/AutoImputeExp/tpot2_imputetest/Impute_Experiments/utils.py", line 200, in load_task
    task = openml.tasks.get_task(task_id)
  File "/home/ketrong/miniconda3/envs/tpot2devenv/lib/python3.10/site-packages/openml/tasks/functions.py", line 415, in get_task
    raise e
  File "/home/ketrong/miniconda3/envs/tpot2devenv/lib/python3.10/site-packages/openml/tasks/functions.py", line 398, in get_task
    task = _get_task_description(task_id)
  File "/home/ketrong/miniconda3/envs/tpot2devenv/lib/python3.10/site-packages/openml/tasks/functions.py", line 431, in _get_task_description
    task_xml = openml._api_calls._perform_api_call("task/%d" % task_id, "get")
  File "/home/ketrong/miniconda3/envs/tpot2devenv/lib/python3.10/site-packages/openml/_api_calls.py", line 99, in _perform_api_call
    response = __read_url(url, request_method, data)
  File "/home/ketrong/miniconda3/envs/tpot2devenv/lib/python3.10/site-packages/openml/_api_calls.py", line 308, in __read_url
    return _send_request(
  File "/home/ketrong/miniconda3/envs/tpot2devenv/lib/python3.10/site-packages/openml/_api_calls.py", line 344, in _send_request
    __check_response(response=response, url=url, file_elements=files)
  File "/home/ketrong/miniconda3/envs/tpot2devenv/lib/python3.10/site-packages/openml/_api_calls.py", line 409, in __check_response
    raise __parse_server_exception(response, url, file_elements=file_elements)
openml.exceptions.OpenMLServerException: https://www.openml.org/api/v1/xml/task/1213 returned code 151: Unknown task - None

1213
remove from investigation?
working on 
logs/1213/tpot2_base_imputation_MNAR_0.9
1.4717106819152832
loading data
logs/1213/tpot2_base_imputation_MNAR_0.9/data/1213_True.pkl
https://www.openml.org/api/v1/xml/task/1213 returned code 151: Unknown task - None
Traceback (most recent call last):
  File "/home/ketrong/miniconda3/envs/tpot2devenv/lib/python3.10/site-packages/openml/tasks/functions.py", line 70, in _get_cached_task
    with io.open(os.path.join(tid_cache_dir, "task.xml"), encoding="utf8") as fh:
FileNotFoundError: [Errno 2] No such file or directory: '/home/ketrong/.cache/openml/org/openml/www/tasks/1213/task.xml'

During handling of the above exception, another exception occurred:

Traceback (most recent call last):
  File "/home/ketrong/miniconda3/envs/tpot2devenv/lib/python3.10/site-packages/openml/tasks/functions.py", line 422, in _get_task_description
    return _get_cached_task(task_id)
  File "/home/ketrong/miniconda3/envs/tpot2devenv/lib/python3.10/site-packages/openml/tasks/functions.py", line 74, in _get_cached_task
    raise OpenMLCacheException("Task file for tid %d not " "cached" % tid)
openml.exceptions.OpenMLCacheException: Task file for tid 1213 not cached

During handling of the above exception, another exception occurred:

Traceback (most recent call last):
  File "/common/ketrong/AutoImputeExp/tpot2_imputetest/Impute_Experiments/utils.py", line 310, in loop_through_tasks
    X_train, y_train, X_test, y_test = load_task(base_save_folder=base_save_folder, exp=exp, type=type, levelstr=levelstr, task_id=taskid, preprocess=True)
  File "/common/ketrong/AutoImputeExp/tpot2_imputetest/Impute_Experiments/utils.py", line 200, in load_task
    task = openml.tasks.get_task(task_id)
  File "/home/ketrong/miniconda3/envs/tpot2devenv/lib/python3.10/site-packages/openml/tasks/functions.py", line 415, in get_task
    raise e
  File "/home/ketrong/miniconda3/envs/tpot2devenv/lib/python3.10/site-packages/openml/tasks/functions.py", line 398, in get_task
    task = _get_task_description(task_id)
  File "/home/ketrong/miniconda3/envs/tpot2devenv/lib/python3.10/site-packages/openml/tasks/functions.py", line 431, in _get_task_description
    task_xml = openml._api_calls._perform_api_call("task/%d" % task_id, "get")
  File "/home/ketrong/miniconda3/envs/tpot2devenv/lib/python3.10/site-packages/openml/_api_calls.py", line 99, in _perform_api_call
    response = __read_url(url, request_method, data)
  File "/home/ketrong/miniconda3/envs/tpot2devenv/lib/python3.10/site-packages/openml/_api_calls.py", line 308, in __read_url
    return _send_request(
  File "/home/ketrong/miniconda3/envs/tpot2devenv/lib/python3.10/site-packages/openml/_api_calls.py", line 344, in _send_request
    __check_response(response=response, url=url, file_elements=files)
  File "/home/ketrong/miniconda3/envs/tpot2devenv/lib/python3.10/site-packages/openml/_api_calls.py", line 409, in __check_response
    raise __parse_server_exception(response, url, file_elements=file_elements)
openml.exceptions.OpenMLServerException: https://www.openml.org/api/v1/xml/task/1213 returned code 151: Unknown task - None

1213
remove from investigation?
1213
finished
working on 
logs/1220/tpot2_base_normal_MNAR_0.9
3.135277271270752
loading data
logs/1220/tpot2_base_normal_MNAR_0.9/data/1220_True.pkl
https://www.openml.org/api/v1/xml/task/1220 returned code 151: Unknown task - None
Traceback (most recent call last):
  File "/home/ketrong/miniconda3/envs/tpot2devenv/lib/python3.10/site-packages/openml/tasks/functions.py", line 70, in _get_cached_task
    with io.open(os.path.join(tid_cache_dir, "task.xml"), encoding="utf8") as fh:
FileNotFoundError: [Errno 2] No such file or directory: '/home/ketrong/.cache/openml/org/openml/www/tasks/1220/task.xml'

During handling of the above exception, another exception occurred:

Traceback (most recent call last):
  File "/home/ketrong/miniconda3/envs/tpot2devenv/lib/python3.10/site-packages/openml/tasks/functions.py", line 422, in _get_task_description
    return _get_cached_task(task_id)
  File "/home/ketrong/miniconda3/envs/tpot2devenv/lib/python3.10/site-packages/openml/tasks/functions.py", line 74, in _get_cached_task
    raise OpenMLCacheException("Task file for tid %d not " "cached" % tid)
openml.exceptions.OpenMLCacheException: Task file for tid 1220 not cached

During handling of the above exception, another exception occurred:

Traceback (most recent call last):
  File "/common/ketrong/AutoImputeExp/tpot2_imputetest/Impute_Experiments/utils.py", line 310, in loop_through_tasks
    X_train, y_train, X_test, y_test = load_task(base_save_folder=base_save_folder, exp=exp, type=type, levelstr=levelstr, task_id=taskid, preprocess=True)
  File "/common/ketrong/AutoImputeExp/tpot2_imputetest/Impute_Experiments/utils.py", line 200, in load_task
    task = openml.tasks.get_task(task_id)
  File "/home/ketrong/miniconda3/envs/tpot2devenv/lib/python3.10/site-packages/openml/tasks/functions.py", line 415, in get_task
    raise e
  File "/home/ketrong/miniconda3/envs/tpot2devenv/lib/python3.10/site-packages/openml/tasks/functions.py", line 398, in get_task
    task = _get_task_description(task_id)
  File "/home/ketrong/miniconda3/envs/tpot2devenv/lib/python3.10/site-packages/openml/tasks/functions.py", line 431, in _get_task_description
    task_xml = openml._api_calls._perform_api_call("task/%d" % task_id, "get")
  File "/home/ketrong/miniconda3/envs/tpot2devenv/lib/python3.10/site-packages/openml/_api_calls.py", line 99, in _perform_api_call
    response = __read_url(url, request_method, data)
  File "/home/ketrong/miniconda3/envs/tpot2devenv/lib/python3.10/site-packages/openml/_api_calls.py", line 308, in __read_url
    return _send_request(
  File "/home/ketrong/miniconda3/envs/tpot2devenv/lib/python3.10/site-packages/openml/_api_calls.py", line 344, in _send_request
    __check_response(response=response, url=url, file_elements=files)
  File "/home/ketrong/miniconda3/envs/tpot2devenv/lib/python3.10/site-packages/openml/_api_calls.py", line 409, in __check_response
    raise __parse_server_exception(response, url, file_elements=file_elements)
openml.exceptions.OpenMLServerException: https://www.openml.org/api/v1/xml/task/1220 returned code 151: Unknown task - None

1220
remove from investigation?
working on 
logs/1220/tpot2_base_imputation_MNAR_0.9
0.4971940517425537
loading data
logs/1220/tpot2_base_imputation_MNAR_0.9/data/1220_True.pkl
https://www.openml.org/api/v1/xml/task/1220 returned code 151: Unknown task - None
Traceback (most recent call last):
  File "/home/ketrong/miniconda3/envs/tpot2devenv/lib/python3.10/site-packages/openml/tasks/functions.py", line 70, in _get_cached_task
    with io.open(os.path.join(tid_cache_dir, "task.xml"), encoding="utf8") as fh:
FileNotFoundError: [Errno 2] No such file or directory: '/home/ketrong/.cache/openml/org/openml/www/tasks/1220/task.xml'

During handling of the above exception, another exception occurred:

Traceback (most recent call last):
  File "/home/ketrong/miniconda3/envs/tpot2devenv/lib/python3.10/site-packages/openml/tasks/functions.py", line 422, in _get_task_description
    return _get_cached_task(task_id)
  File "/home/ketrong/miniconda3/envs/tpot2devenv/lib/python3.10/site-packages/openml/tasks/functions.py", line 74, in _get_cached_task
    raise OpenMLCacheException("Task file for tid %d not " "cached" % tid)
openml.exceptions.OpenMLCacheException: Task file for tid 1220 not cached

During handling of the above exception, another exception occurred:

Traceback (most recent call last):
  File "/common/ketrong/AutoImputeExp/tpot2_imputetest/Impute_Experiments/utils.py", line 310, in loop_through_tasks
    X_train, y_train, X_test, y_test = load_task(base_save_folder=base_save_folder, exp=exp, type=type, levelstr=levelstr, task_id=taskid, preprocess=True)
  File "/common/ketrong/AutoImputeExp/tpot2_imputetest/Impute_Experiments/utils.py", line 200, in load_task
    task = openml.tasks.get_task(task_id)
  File "/home/ketrong/miniconda3/envs/tpot2devenv/lib/python3.10/site-packages/openml/tasks/functions.py", line 415, in get_task
    raise e
  File "/home/ketrong/miniconda3/envs/tpot2devenv/lib/python3.10/site-packages/openml/tasks/functions.py", line 398, in get_task
    task = _get_task_description(task_id)
  File "/home/ketrong/miniconda3/envs/tpot2devenv/lib/python3.10/site-packages/openml/tasks/functions.py", line 431, in _get_task_description
    task_xml = openml._api_calls._perform_api_call("task/%d" % task_id, "get")
  File "/home/ketrong/miniconda3/envs/tpot2devenv/lib/python3.10/site-packages/openml/_api_calls.py", line 99, in _perform_api_call
    response = __read_url(url, request_method, data)
  File "/home/ketrong/miniconda3/envs/tpot2devenv/lib/python3.10/site-packages/openml/_api_calls.py", line 308, in __read_url
    return _send_request(
  File "/home/ketrong/miniconda3/envs/tpot2devenv/lib/python3.10/site-packages/openml/_api_calls.py", line 344, in _send_request
    __check_response(response=response, url=url, file_elements=files)
  File "/home/ketrong/miniconda3/envs/tpot2devenv/lib/python3.10/site-packages/openml/_api_calls.py", line 409, in __check_response
    raise __parse_server_exception(response, url, file_elements=file_elements)
openml.exceptions.OpenMLServerException: https://www.openml.org/api/v1/xml/task/1220 returned code 151: Unknown task - None

1220
remove from investigation?
1220
finished
working on 
logs/1459/tpot2_base_normal_MNAR_0.9
1.2447597980499268
loading data
logs/1459/tpot2_base_normal_MNAR_0.9/data/1459_True.pkl
https://www.openml.org/api/v1/xml/task/1459 returned code 151: Unknown task - None
Traceback (most recent call last):
  File "/home/ketrong/miniconda3/envs/tpot2devenv/lib/python3.10/site-packages/openml/tasks/functions.py", line 70, in _get_cached_task
    with io.open(os.path.join(tid_cache_dir, "task.xml"), encoding="utf8") as fh:
FileNotFoundError: [Errno 2] No such file or directory: '/home/ketrong/.cache/openml/org/openml/www/tasks/1459/task.xml'

During handling of the above exception, another exception occurred:

Traceback (most recent call last):
  File "/home/ketrong/miniconda3/envs/tpot2devenv/lib/python3.10/site-packages/openml/tasks/functions.py", line 422, in _get_task_description
    return _get_cached_task(task_id)
  File "/home/ketrong/miniconda3/envs/tpot2devenv/lib/python3.10/site-packages/openml/tasks/functions.py", line 74, in _get_cached_task
    raise OpenMLCacheException("Task file for tid %d not " "cached" % tid)
openml.exceptions.OpenMLCacheException: Task file for tid 1459 not cached

During handling of the above exception, another exception occurred:

Traceback (most recent call last):
  File "/common/ketrong/AutoImputeExp/tpot2_imputetest/Impute_Experiments/utils.py", line 310, in loop_through_tasks
    X_train, y_train, X_test, y_test = load_task(base_save_folder=base_save_folder, exp=exp, type=type, levelstr=levelstr, task_id=taskid, preprocess=True)
  File "/common/ketrong/AutoImputeExp/tpot2_imputetest/Impute_Experiments/utils.py", line 200, in load_task
    task = openml.tasks.get_task(task_id)
  File "/home/ketrong/miniconda3/envs/tpot2devenv/lib/python3.10/site-packages/openml/tasks/functions.py", line 415, in get_task
    raise e
  File "/home/ketrong/miniconda3/envs/tpot2devenv/lib/python3.10/site-packages/openml/tasks/functions.py", line 398, in get_task
    task = _get_task_description(task_id)
  File "/home/ketrong/miniconda3/envs/tpot2devenv/lib/python3.10/site-packages/openml/tasks/functions.py", line 431, in _get_task_description
    task_xml = openml._api_calls._perform_api_call("task/%d" % task_id, "get")
  File "/home/ketrong/miniconda3/envs/tpot2devenv/lib/python3.10/site-packages/openml/_api_calls.py", line 99, in _perform_api_call
    response = __read_url(url, request_method, data)
  File "/home/ketrong/miniconda3/envs/tpot2devenv/lib/python3.10/site-packages/openml/_api_calls.py", line 308, in __read_url
    return _send_request(
  File "/home/ketrong/miniconda3/envs/tpot2devenv/lib/python3.10/site-packages/openml/_api_calls.py", line 344, in _send_request
    __check_response(response=response, url=url, file_elements=files)
  File "/home/ketrong/miniconda3/envs/tpot2devenv/lib/python3.10/site-packages/openml/_api_calls.py", line 409, in __check_response
    raise __parse_server_exception(response, url, file_elements=file_elements)
openml.exceptions.OpenMLServerException: https://www.openml.org/api/v1/xml/task/1459 returned code 151: Unknown task - None

1459
remove from investigation?
working on 
logs/1459/tpot2_base_imputation_MNAR_0.9
4.463356018066406
loading data
logs/1459/tpot2_base_imputation_MNAR_0.9/data/1459_True.pkl
https://www.openml.org/api/v1/xml/task/1459 returned code 151: Unknown task - None
Traceback (most recent call last):
  File "/home/ketrong/miniconda3/envs/tpot2devenv/lib/python3.10/site-packages/openml/tasks/functions.py", line 70, in _get_cached_task
    with io.open(os.path.join(tid_cache_dir, "task.xml"), encoding="utf8") as fh:
FileNotFoundError: [Errno 2] No such file or directory: '/home/ketrong/.cache/openml/org/openml/www/tasks/1459/task.xml'

During handling of the above exception, another exception occurred:

Traceback (most recent call last):
  File "/home/ketrong/miniconda3/envs/tpot2devenv/lib/python3.10/site-packages/openml/tasks/functions.py", line 422, in _get_task_description
    return _get_cached_task(task_id)
  File "/home/ketrong/miniconda3/envs/tpot2devenv/lib/python3.10/site-packages/openml/tasks/functions.py", line 74, in _get_cached_task
    raise OpenMLCacheException("Task file for tid %d not " "cached" % tid)
openml.exceptions.OpenMLCacheException: Task file for tid 1459 not cached

During handling of the above exception, another exception occurred:

Traceback (most recent call last):
  File "/common/ketrong/AutoImputeExp/tpot2_imputetest/Impute_Experiments/utils.py", line 310, in loop_through_tasks
    X_train, y_train, X_test, y_test = load_task(base_save_folder=base_save_folder, exp=exp, type=type, levelstr=levelstr, task_id=taskid, preprocess=True)
  File "/common/ketrong/AutoImputeExp/tpot2_imputetest/Impute_Experiments/utils.py", line 200, in load_task
    task = openml.tasks.get_task(task_id)
  File "/home/ketrong/miniconda3/envs/tpot2devenv/lib/python3.10/site-packages/openml/tasks/functions.py", line 415, in get_task
    raise e
  File "/home/ketrong/miniconda3/envs/tpot2devenv/lib/python3.10/site-packages/openml/tasks/functions.py", line 398, in get_task
    task = _get_task_description(task_id)
  File "/home/ketrong/miniconda3/envs/tpot2devenv/lib/python3.10/site-packages/openml/tasks/functions.py", line 431, in _get_task_description
    task_xml = openml._api_calls._perform_api_call("task/%d" % task_id, "get")
  File "/home/ketrong/miniconda3/envs/tpot2devenv/lib/python3.10/site-packages/openml/_api_calls.py", line 99, in _perform_api_call
    response = __read_url(url, request_method, data)
  File "/home/ketrong/miniconda3/envs/tpot2devenv/lib/python3.10/site-packages/openml/_api_calls.py", line 308, in __read_url
    return _send_request(
  File "/home/ketrong/miniconda3/envs/tpot2devenv/lib/python3.10/site-packages/openml/_api_calls.py", line 344, in _send_request
    __check_response(response=response, url=url, file_elements=files)
  File "/home/ketrong/miniconda3/envs/tpot2devenv/lib/python3.10/site-packages/openml/_api_calls.py", line 409, in __check_response
    raise __parse_server_exception(response, url, file_elements=file_elements)
openml.exceptions.OpenMLServerException: https://www.openml.org/api/v1/xml/task/1459 returned code 151: Unknown task - None

1459
remove from investigation?
1459
finished
working on 
logs/1471/tpot2_base_normal_MNAR_0.9
1.1960992813110352
loading data
logs/1471/tpot2_base_normal_MNAR_0.9/data/1471_True.pkl
https://www.openml.org/api/v1/xml/task/1471 returned code 151: Unknown task - None
Traceback (most recent call last):
  File "/home/ketrong/miniconda3/envs/tpot2devenv/lib/python3.10/site-packages/openml/tasks/functions.py", line 70, in _get_cached_task
    with io.open(os.path.join(tid_cache_dir, "task.xml"), encoding="utf8") as fh:
FileNotFoundError: [Errno 2] No such file or directory: '/home/ketrong/.cache/openml/org/openml/www/tasks/1471/task.xml'

During handling of the above exception, another exception occurred:

Traceback (most recent call last):
  File "/home/ketrong/miniconda3/envs/tpot2devenv/lib/python3.10/site-packages/openml/tasks/functions.py", line 422, in _get_task_description
    return _get_cached_task(task_id)
  File "/home/ketrong/miniconda3/envs/tpot2devenv/lib/python3.10/site-packages/openml/tasks/functions.py", line 74, in _get_cached_task
    raise OpenMLCacheException("Task file for tid %d not " "cached" % tid)
openml.exceptions.OpenMLCacheException: Task file for tid 1471 not cached

During handling of the above exception, another exception occurred:

Traceback (most recent call last):
  File "/common/ketrong/AutoImputeExp/tpot2_imputetest/Impute_Experiments/utils.py", line 310, in loop_through_tasks
    X_train, y_train, X_test, y_test = load_task(base_save_folder=base_save_folder, exp=exp, type=type, levelstr=levelstr, task_id=taskid, preprocess=True)
  File "/common/ketrong/AutoImputeExp/tpot2_imputetest/Impute_Experiments/utils.py", line 200, in load_task
    task = openml.tasks.get_task(task_id)
  File "/home/ketrong/miniconda3/envs/tpot2devenv/lib/python3.10/site-packages/openml/tasks/functions.py", line 415, in get_task
    raise e
  File "/home/ketrong/miniconda3/envs/tpot2devenv/lib/python3.10/site-packages/openml/tasks/functions.py", line 398, in get_task
    task = _get_task_description(task_id)
  File "/home/ketrong/miniconda3/envs/tpot2devenv/lib/python3.10/site-packages/openml/tasks/functions.py", line 431, in _get_task_description
    task_xml = openml._api_calls._perform_api_call("task/%d" % task_id, "get")
  File "/home/ketrong/miniconda3/envs/tpot2devenv/lib/python3.10/site-packages/openml/_api_calls.py", line 99, in _perform_api_call
    response = __read_url(url, request_method, data)
  File "/home/ketrong/miniconda3/envs/tpot2devenv/lib/python3.10/site-packages/openml/_api_calls.py", line 308, in __read_url
    return _send_request(
  File "/home/ketrong/miniconda3/envs/tpot2devenv/lib/python3.10/site-packages/openml/_api_calls.py", line 344, in _send_request
    __check_response(response=response, url=url, file_elements=files)
  File "/home/ketrong/miniconda3/envs/tpot2devenv/lib/python3.10/site-packages/openml/_api_calls.py", line 409, in __check_response
    raise __parse_server_exception(response, url, file_elements=file_elements)
openml.exceptions.OpenMLServerException: https://www.openml.org/api/v1/xml/task/1471 returned code 151: Unknown task - None

1471
remove from investigation?
working on 
logs/1471/tpot2_base_imputation_MNAR_0.9
0.8438925743103027
loading data
logs/1471/tpot2_base_imputation_MNAR_0.9/data/1471_True.pkl
https://www.openml.org/api/v1/xml/task/1471 returned code 151: Unknown task - None
Traceback (most recent call last):
  File "/home/ketrong/miniconda3/envs/tpot2devenv/lib/python3.10/site-packages/openml/tasks/functions.py", line 70, in _get_cached_task
    with io.open(os.path.join(tid_cache_dir, "task.xml"), encoding="utf8") as fh:
FileNotFoundError: [Errno 2] No such file or directory: '/home/ketrong/.cache/openml/org/openml/www/tasks/1471/task.xml'

During handling of the above exception, another exception occurred:

Traceback (most recent call last):
  File "/home/ketrong/miniconda3/envs/tpot2devenv/lib/python3.10/site-packages/openml/tasks/functions.py", line 422, in _get_task_description
    return _get_cached_task(task_id)
  File "/home/ketrong/miniconda3/envs/tpot2devenv/lib/python3.10/site-packages/openml/tasks/functions.py", line 74, in _get_cached_task
    raise OpenMLCacheException("Task file for tid %d not " "cached" % tid)
openml.exceptions.OpenMLCacheException: Task file for tid 1471 not cached

During handling of the above exception, another exception occurred:

Traceback (most recent call last):
  File "/common/ketrong/AutoImputeExp/tpot2_imputetest/Impute_Experiments/utils.py", line 310, in loop_through_tasks
    X_train, y_train, X_test, y_test = load_task(base_save_folder=base_save_folder, exp=exp, type=type, levelstr=levelstr, task_id=taskid, preprocess=True)
  File "/common/ketrong/AutoImputeExp/tpot2_imputetest/Impute_Experiments/utils.py", line 200, in load_task
    task = openml.tasks.get_task(task_id)
  File "/home/ketrong/miniconda3/envs/tpot2devenv/lib/python3.10/site-packages/openml/tasks/functions.py", line 415, in get_task
    raise e
  File "/home/ketrong/miniconda3/envs/tpot2devenv/lib/python3.10/site-packages/openml/tasks/functions.py", line 398, in get_task
    task = _get_task_description(task_id)
  File "/home/ketrong/miniconda3/envs/tpot2devenv/lib/python3.10/site-packages/openml/tasks/functions.py", line 431, in _get_task_description
    task_xml = openml._api_calls._perform_api_call("task/%d" % task_id, "get")
  File "/home/ketrong/miniconda3/envs/tpot2devenv/lib/python3.10/site-packages/openml/_api_calls.py", line 99, in _perform_api_call
    response = __read_url(url, request_method, data)
  File "/home/ketrong/miniconda3/envs/tpot2devenv/lib/python3.10/site-packages/openml/_api_calls.py", line 308, in __read_url
    return _send_request(
  File "/home/ketrong/miniconda3/envs/tpot2devenv/lib/python3.10/site-packages/openml/_api_calls.py", line 344, in _send_request
    __check_response(response=response, url=url, file_elements=files)
  File "/home/ketrong/miniconda3/envs/tpot2devenv/lib/python3.10/site-packages/openml/_api_calls.py", line 409, in __check_response
    raise __parse_server_exception(response, url, file_elements=file_elements)
openml.exceptions.OpenMLServerException: https://www.openml.org/api/v1/xml/task/1471 returned code 151: Unknown task - None

1471
remove from investigation?
1471
finished
working on 
logs/1481/tpot2_base_normal_MNAR_0.9
4.847986459732056
loading data
logs/1481/tpot2_base_normal_MNAR_0.9/data/1481_True.pkl
https://www.openml.org/api/v1/xml/task/1481 returned code 151: Unknown task - None
Traceback (most recent call last):
  File "/home/ketrong/miniconda3/envs/tpot2devenv/lib/python3.10/site-packages/openml/tasks/functions.py", line 70, in _get_cached_task
    with io.open(os.path.join(tid_cache_dir, "task.xml"), encoding="utf8") as fh:
FileNotFoundError: [Errno 2] No such file or directory: '/home/ketrong/.cache/openml/org/openml/www/tasks/1481/task.xml'

During handling of the above exception, another exception occurred:

Traceback (most recent call last):
  File "/home/ketrong/miniconda3/envs/tpot2devenv/lib/python3.10/site-packages/openml/tasks/functions.py", line 422, in _get_task_description
    return _get_cached_task(task_id)
  File "/home/ketrong/miniconda3/envs/tpot2devenv/lib/python3.10/site-packages/openml/tasks/functions.py", line 74, in _get_cached_task
    raise OpenMLCacheException("Task file for tid %d not " "cached" % tid)
openml.exceptions.OpenMLCacheException: Task file for tid 1481 not cached

During handling of the above exception, another exception occurred:

Traceback (most recent call last):
  File "/common/ketrong/AutoImputeExp/tpot2_imputetest/Impute_Experiments/utils.py", line 310, in loop_through_tasks
    X_train, y_train, X_test, y_test = load_task(base_save_folder=base_save_folder, exp=exp, type=type, levelstr=levelstr, task_id=taskid, preprocess=True)
  File "/common/ketrong/AutoImputeExp/tpot2_imputetest/Impute_Experiments/utils.py", line 200, in load_task
    task = openml.tasks.get_task(task_id)
  File "/home/ketrong/miniconda3/envs/tpot2devenv/lib/python3.10/site-packages/openml/tasks/functions.py", line 415, in get_task
    raise e
  File "/home/ketrong/miniconda3/envs/tpot2devenv/lib/python3.10/site-packages/openml/tasks/functions.py", line 398, in get_task
    task = _get_task_description(task_id)
  File "/home/ketrong/miniconda3/envs/tpot2devenv/lib/python3.10/site-packages/openml/tasks/functions.py", line 431, in _get_task_description
    task_xml = openml._api_calls._perform_api_call("task/%d" % task_id, "get")
  File "/home/ketrong/miniconda3/envs/tpot2devenv/lib/python3.10/site-packages/openml/_api_calls.py", line 99, in _perform_api_call
    response = __read_url(url, request_method, data)
  File "/home/ketrong/miniconda3/envs/tpot2devenv/lib/python3.10/site-packages/openml/_api_calls.py", line 308, in __read_url
    return _send_request(
  File "/home/ketrong/miniconda3/envs/tpot2devenv/lib/python3.10/site-packages/openml/_api_calls.py", line 344, in _send_request
    __check_response(response=response, url=url, file_elements=files)
  File "/home/ketrong/miniconda3/envs/tpot2devenv/lib/python3.10/site-packages/openml/_api_calls.py", line 409, in __check_response
    raise __parse_server_exception(response, url, file_elements=file_elements)
openml.exceptions.OpenMLServerException: https://www.openml.org/api/v1/xml/task/1481 returned code 151: Unknown task - None

1481
remove from investigation?
working on 
logs/1481/tpot2_base_imputation_MNAR_0.9
1.3768959045410156
loading data
logs/1481/tpot2_base_imputation_MNAR_0.9/data/1481_True.pkl
https://www.openml.org/api/v1/xml/task/1481 returned code 151: Unknown task - None
Traceback (most recent call last):
  File "/home/ketrong/miniconda3/envs/tpot2devenv/lib/python3.10/site-packages/openml/tasks/functions.py", line 70, in _get_cached_task
    with io.open(os.path.join(tid_cache_dir, "task.xml"), encoding="utf8") as fh:
FileNotFoundError: [Errno 2] No such file or directory: '/home/ketrong/.cache/openml/org/openml/www/tasks/1481/task.xml'

During handling of the above exception, another exception occurred:

Traceback (most recent call last):
  File "/home/ketrong/miniconda3/envs/tpot2devenv/lib/python3.10/site-packages/openml/tasks/functions.py", line 422, in _get_task_description
    return _get_cached_task(task_id)
  File "/home/ketrong/miniconda3/envs/tpot2devenv/lib/python3.10/site-packages/openml/tasks/functions.py", line 74, in _get_cached_task
    raise OpenMLCacheException("Task file for tid %d not " "cached" % tid)
openml.exceptions.OpenMLCacheException: Task file for tid 1481 not cached

During handling of the above exception, another exception occurred:

Traceback (most recent call last):
  File "/common/ketrong/AutoImputeExp/tpot2_imputetest/Impute_Experiments/utils.py", line 310, in loop_through_tasks
    X_train, y_train, X_test, y_test = load_task(base_save_folder=base_save_folder, exp=exp, type=type, levelstr=levelstr, task_id=taskid, preprocess=True)
  File "/common/ketrong/AutoImputeExp/tpot2_imputetest/Impute_Experiments/utils.py", line 200, in load_task
    task = openml.tasks.get_task(task_id)
  File "/home/ketrong/miniconda3/envs/tpot2devenv/lib/python3.10/site-packages/openml/tasks/functions.py", line 415, in get_task
    raise e
  File "/home/ketrong/miniconda3/envs/tpot2devenv/lib/python3.10/site-packages/openml/tasks/functions.py", line 398, in get_task
    task = _get_task_description(task_id)
  File "/home/ketrong/miniconda3/envs/tpot2devenv/lib/python3.10/site-packages/openml/tasks/functions.py", line 431, in _get_task_description
    task_xml = openml._api_calls._perform_api_call("task/%d" % task_id, "get")
  File "/home/ketrong/miniconda3/envs/tpot2devenv/lib/python3.10/site-packages/openml/_api_calls.py", line 99, in _perform_api_call
    response = __read_url(url, request_method, data)
  File "/home/ketrong/miniconda3/envs/tpot2devenv/lib/python3.10/site-packages/openml/_api_calls.py", line 308, in __read_url
    return _send_request(
  File "/home/ketrong/miniconda3/envs/tpot2devenv/lib/python3.10/site-packages/openml/_api_calls.py", line 344, in _send_request
    __check_response(response=response, url=url, file_elements=files)
  File "/home/ketrong/miniconda3/envs/tpot2devenv/lib/python3.10/site-packages/openml/_api_calls.py", line 409, in __check_response
    raise __parse_server_exception(response, url, file_elements=file_elements)
openml.exceptions.OpenMLServerException: https://www.openml.org/api/v1/xml/task/1481 returned code 151: Unknown task - None

1481
remove from investigation?
1481
finished
working on 
logs/1489/tpot2_base_normal_MNAR_0.9
3.6896729469299316
loading data
logs/1489/tpot2_base_normal_MNAR_0.9/data/1489_True.pkl
https://www.openml.org/api/v1/xml/task/1489 returned code 151: Unknown task - None
Traceback (most recent call last):
  File "/home/ketrong/miniconda3/envs/tpot2devenv/lib/python3.10/site-packages/openml/tasks/functions.py", line 70, in _get_cached_task
    with io.open(os.path.join(tid_cache_dir, "task.xml"), encoding="utf8") as fh:
FileNotFoundError: [Errno 2] No such file or directory: '/home/ketrong/.cache/openml/org/openml/www/tasks/1489/task.xml'

During handling of the above exception, another exception occurred:

Traceback (most recent call last):
  File "/home/ketrong/miniconda3/envs/tpot2devenv/lib/python3.10/site-packages/openml/tasks/functions.py", line 422, in _get_task_description
    return _get_cached_task(task_id)
  File "/home/ketrong/miniconda3/envs/tpot2devenv/lib/python3.10/site-packages/openml/tasks/functions.py", line 74, in _get_cached_task
    raise OpenMLCacheException("Task file for tid %d not " "cached" % tid)
openml.exceptions.OpenMLCacheException: Task file for tid 1489 not cached

During handling of the above exception, another exception occurred:

Traceback (most recent call last):
  File "/common/ketrong/AutoImputeExp/tpot2_imputetest/Impute_Experiments/utils.py", line 310, in loop_through_tasks
    X_train, y_train, X_test, y_test = load_task(base_save_folder=base_save_folder, exp=exp, type=type, levelstr=levelstr, task_id=taskid, preprocess=True)
  File "/common/ketrong/AutoImputeExp/tpot2_imputetest/Impute_Experiments/utils.py", line 200, in load_task
    task = openml.tasks.get_task(task_id)
  File "/home/ketrong/miniconda3/envs/tpot2devenv/lib/python3.10/site-packages/openml/tasks/functions.py", line 415, in get_task
    raise e
  File "/home/ketrong/miniconda3/envs/tpot2devenv/lib/python3.10/site-packages/openml/tasks/functions.py", line 398, in get_task
    task = _get_task_description(task_id)
  File "/home/ketrong/miniconda3/envs/tpot2devenv/lib/python3.10/site-packages/openml/tasks/functions.py", line 431, in _get_task_description
    task_xml = openml._api_calls._perform_api_call("task/%d" % task_id, "get")
  File "/home/ketrong/miniconda3/envs/tpot2devenv/lib/python3.10/site-packages/openml/_api_calls.py", line 99, in _perform_api_call
    response = __read_url(url, request_method, data)
  File "/home/ketrong/miniconda3/envs/tpot2devenv/lib/python3.10/site-packages/openml/_api_calls.py", line 308, in __read_url
    return _send_request(
  File "/home/ketrong/miniconda3/envs/tpot2devenv/lib/python3.10/site-packages/openml/_api_calls.py", line 344, in _send_request
    __check_response(response=response, url=url, file_elements=files)
  File "/home/ketrong/miniconda3/envs/tpot2devenv/lib/python3.10/site-packages/openml/_api_calls.py", line 409, in __check_response
    raise __parse_server_exception(response, url, file_elements=file_elements)
openml.exceptions.OpenMLServerException: https://www.openml.org/api/v1/xml/task/1489 returned code 151: Unknown task - None

1489
remove from investigation?
slurmstepd: error: *** STEP 565635.0 ON esplhpc-cp003 CANCELLED AT 2023-12-19T14:15:11 ***
slurmstepd: error: *** JOB 565635 ON esplhpc-cp003 CANCELLED AT 2023-12-19T14:15:11 ***
