Run: 13
/cm/local/apps/slurm/var/spool/job565650/slurm_script: line 23: /common/ketrong/minconda3/etc/profile.d/conda.sh: No such file or directory
/cm/local/apps/slurm/var/spool/job565650/slurm_script: line 26: $'\nconda create --name tpot2devenv -c conda-forge python=3.10\n': command not found
/cm/local/apps/slurm/var/spool/job565650/slurm_script: line 31: $'\npip install -r requirements.txt\n': command not found
RunStart
2023-12-19 14:02:47.076845: I tensorflow/core/util/port.cc:113] oneDNN custom operations are on. You may see slightly different numerical results due to floating-point round-off errors from different computation orders. To turn them off, set the environment variable `TF_ENABLE_ONEDNN_OPTS=0`.
2023-12-19 14:02:47.110274: E external/local_xla/xla/stream_executor/cuda/cuda_dnn.cc:9261] Unable to register cuDNN factory: Attempting to register factory for plugin cuDNN when one has already been registered
2023-12-19 14:02:47.110296: E external/local_xla/xla/stream_executor/cuda/cuda_fft.cc:607] Unable to register cuFFT factory: Attempting to register factory for plugin cuFFT when one has already been registered
2023-12-19 14:02:47.111119: E external/local_xla/xla/stream_executor/cuda/cuda_blas.cc:1515] Unable to register cuBLAS factory: Attempting to register factory for plugin cuBLAS when one has already been registered
2023-12-19 14:02:47.116048: I tensorflow/core/platform/cpu_feature_guard.cc:182] This TensorFlow binary is optimized to use available CPU instructions in performance-critical operations.
To enable the following instructions: AVX2 AVX512F AVX512_VNNI FMA, in other operations, rebuild TensorFlow with the appropriate compiler flags.
2023-12-19 14:02:50.289380: W tensorflow/compiler/tf2tensorrt/utils/py_utils.cc:38] TF-TRT Warning: Could not find TensorRT
WARNING:tensorflow:From /home/ketrong/miniconda3/envs/tpot2devenv/lib/python3.10/site-packages/tensorflow/python/compat/v2_compat.py:108: disable_resource_variables (from tensorflow.python.ops.variable_scope) is deprecated and will be removed in a future version.
Instructions for updating:
non-resource variables are not supported in the long term
starting loops
working on 
logs/6/tpot2_base_normal_MNAR_0.3
2.5677170753479004
loading data
logs/6/tpot2_base_normal_MNAR_0.3/data/6_True.pkl
working on 
logs/6/tpot2_base_imputation_MNAR_0.3
2.0209646224975586
loading data
logs/6/tpot2_base_imputation_MNAR_0.3/data/6_True.pkl
6
finished
working on 
logs/26/tpot2_base_normal_MNAR_0.3
0.1871647834777832
loading data
logs/26/tpot2_base_normal_MNAR_0.3/data/26_True.pkl
working on 
logs/26/tpot2_base_imputation_MNAR_0.3
3.8620290756225586
loading data
logs/26/tpot2_base_imputation_MNAR_0.3/data/26_True.pkl
26
finished
working on 
logs/30/tpot2_base_normal_MNAR_0.3
2.52138090133667
loading data
logs/30/tpot2_base_normal_MNAR_0.3/data/30_True.pkl
working on 
logs/30/tpot2_base_imputation_MNAR_0.3
4.958636045455933
loading data
logs/30/tpot2_base_imputation_MNAR_0.3/data/30_True.pkl
30
finished
working on 
logs/32/tpot2_base_normal_MNAR_0.3
1.4961967468261719
loading data
logs/32/tpot2_base_normal_MNAR_0.3/data/32_True.pkl
working on 
logs/32/tpot2_base_imputation_MNAR_0.3
2.6527678966522217
loading data
logs/32/tpot2_base_imputation_MNAR_0.3/data/32_True.pkl
32
finished
working on 
logs/137/tpot2_base_normal_MNAR_0.3
1.2986881732940674
loading data
logs/137/tpot2_base_normal_MNAR_0.3/data/137_True.pkl
Cannot remove faulty tasks cache directory /home/ketrong/.cache/openml/org/openml/www/tasks/137.Please do this manually!
Traceback (most recent call last):
  File "/home/ketrong/miniconda3/envs/tpot2devenv/lib/python3.10/site-packages/openml/tasks/task.py", line 157, in download_split
    split = OpenMLSplit._from_arff_file(cached_split_file)
  File "/home/ketrong/miniconda3/envs/tpot2devenv/lib/python3.10/site-packages/openml/tasks/split.py", line 87, in _from_arff_file
    raise FileNotFoundError("Split arff %s does not exist!" % filename)
FileNotFoundError: Split arff /home/ketrong/.cache/openml/org/openml/www/tasks/137/datasplits.arff does not exist!

During handling of the above exception, another exception occurred:

Traceback (most recent call last):
  File "/home/ketrong/miniconda3/envs/tpot2devenv/lib/python3.10/site-packages/openml/tasks/functions.py", line 409, in get_task
    task.download_split()
  File "/home/ketrong/miniconda3/envs/tpot2devenv/lib/python3.10/site-packages/openml/tasks/task.py", line 161, in download_split
    split = OpenMLSplit._from_arff_file(cached_split_file)
  File "/home/ketrong/miniconda3/envs/tpot2devenv/lib/python3.10/site-packages/openml/tasks/split.py", line 87, in _from_arff_file
    raise FileNotFoundError("Split arff %s does not exist!" % filename)
FileNotFoundError: Split arff /home/ketrong/.cache/openml/org/openml/www/tasks/137/datasplits.arff does not exist!

During handling of the above exception, another exception occurred:

Traceback (most recent call last):
  File "/home/ketrong/miniconda3/envs/tpot2devenv/lib/python3.10/site-packages/openml/utils.py", line 375, in _remove_cache_dir_for_id
    shutil.rmtree(cache_dir)
  File "/home/ketrong/miniconda3/envs/tpot2devenv/lib/python3.10/shutil.py", line 715, in rmtree
    onerror(os.lstat, path, sys.exc_info())
  File "/home/ketrong/miniconda3/envs/tpot2devenv/lib/python3.10/shutil.py", line 713, in rmtree
    orig_st = os.lstat(path)
FileNotFoundError: [Errno 2] No such file or directory: '/home/ketrong/.cache/openml/org/openml/www/tasks/137'

During handling of the above exception, another exception occurred:

Traceback (most recent call last):
  File "/common/ketrong/AutoImputeExp/tpot2_imputetest/Impute_Experiments/utils.py", line 310, in loop_through_tasks
    X_train, y_train, X_test, y_test = load_task(base_save_folder=base_save_folder, exp=exp, type=type, levelstr=levelstr, task_id=taskid, preprocess=True)
  File "/common/ketrong/AutoImputeExp/tpot2_imputetest/Impute_Experiments/utils.py", line 200, in load_task
    task = openml.tasks.get_task(task_id)
  File "/home/ketrong/miniconda3/envs/tpot2devenv/lib/python3.10/site-packages/openml/tasks/functions.py", line 411, in get_task
    openml.utils._remove_cache_dir_for_id(
  File "/home/ketrong/miniconda3/envs/tpot2devenv/lib/python3.10/site-packages/openml/utils.py", line 377, in _remove_cache_dir_for_id
    raise ValueError(
ValueError: Cannot remove faulty tasks cache directory /home/ketrong/.cache/openml/org/openml/www/tasks/137.Please do this manually!

137
remove from investigation?
working on 
logs/137/tpot2_base_imputation_MNAR_0.3
0.5808219909667969
loading data
logs/137/tpot2_base_imputation_MNAR_0.3/data/137_True.pkl
Cannot remove faulty tasks cache directory /home/ketrong/.cache/openml/org/openml/www/tasks/137.Please do this manually!
Traceback (most recent call last):
  File "/home/ketrong/miniconda3/envs/tpot2devenv/lib/python3.10/site-packages/openml/tasks/task.py", line 157, in download_split
    split = OpenMLSplit._from_arff_file(cached_split_file)
  File "/home/ketrong/miniconda3/envs/tpot2devenv/lib/python3.10/site-packages/openml/tasks/split.py", line 87, in _from_arff_file
    raise FileNotFoundError("Split arff %s does not exist!" % filename)
FileNotFoundError: Split arff /home/ketrong/.cache/openml/org/openml/www/tasks/137/datasplits.arff does not exist!

During handling of the above exception, another exception occurred:

Traceback (most recent call last):
  File "/home/ketrong/miniconda3/envs/tpot2devenv/lib/python3.10/site-packages/openml/tasks/functions.py", line 409, in get_task
    task.download_split()
  File "/home/ketrong/miniconda3/envs/tpot2devenv/lib/python3.10/site-packages/openml/tasks/task.py", line 161, in download_split
    split = OpenMLSplit._from_arff_file(cached_split_file)
  File "/home/ketrong/miniconda3/envs/tpot2devenv/lib/python3.10/site-packages/openml/tasks/split.py", line 88, in _from_arff_file
    file_data = arff.load(open(filename), return_type=arff.DENSE_GEN)
  File "/home/ketrong/miniconda3/envs/tpot2devenv/lib/python3.10/site-packages/arff.py", line 1059, in load
    return decoder.decode(fp, encode_nominal=encode_nominal,
  File "/home/ketrong/miniconda3/envs/tpot2devenv/lib/python3.10/site-packages/arff.py", line 896, in decode
    raise e
  File "/home/ketrong/miniconda3/envs/tpot2devenv/lib/python3.10/site-packages/arff.py", line 892, in decode
    return self._decode(s, encode_nominal=encode_nominal,
  File "/home/ketrong/miniconda3/envs/tpot2devenv/lib/python3.10/site-packages/arff.py", line 813, in _decode
    obj['relation'] = self._decode_relation(row)
  File "/home/ketrong/miniconda3/envs/tpot2devenv/lib/python3.10/site-packages/arff.py", line 706, in _decode_relation
    raise BadRelationFormat()
arff.BadRelationFormat: Bad @RELATION format, at line 1.

During handling of the above exception, another exception occurred:

Traceback (most recent call last):
  File "/home/ketrong/miniconda3/envs/tpot2devenv/lib/python3.10/site-packages/openml/utils.py", line 375, in _remove_cache_dir_for_id
    shutil.rmtree(cache_dir)
  File "/home/ketrong/miniconda3/envs/tpot2devenv/lib/python3.10/shutil.py", line 731, in rmtree
    onerror(os.rmdir, path, sys.exc_info())
  File "/home/ketrong/miniconda3/envs/tpot2devenv/lib/python3.10/shutil.py", line 729, in rmtree
    os.rmdir(path)
OSError: [Errno 39] Directory not empty: '/home/ketrong/.cache/openml/org/openml/www/tasks/137'

During handling of the above exception, another exception occurred:

Traceback (most recent call last):
  File "/common/ketrong/AutoImputeExp/tpot2_imputetest/Impute_Experiments/utils.py", line 310, in loop_through_tasks
    X_train, y_train, X_test, y_test = load_task(base_save_folder=base_save_folder, exp=exp, type=type, levelstr=levelstr, task_id=taskid, preprocess=True)
  File "/common/ketrong/AutoImputeExp/tpot2_imputetest/Impute_Experiments/utils.py", line 200, in load_task
    task = openml.tasks.get_task(task_id)
  File "/home/ketrong/miniconda3/envs/tpot2devenv/lib/python3.10/site-packages/openml/tasks/functions.py", line 411, in get_task
    openml.utils._remove_cache_dir_for_id(
  File "/home/ketrong/miniconda3/envs/tpot2devenv/lib/python3.10/site-packages/openml/utils.py", line 377, in _remove_cache_dir_for_id
    raise ValueError(
ValueError: Cannot remove faulty tasks cache directory /home/ketrong/.cache/openml/org/openml/www/tasks/137.Please do this manually!

137
remove from investigation?
137
finished
working on 
logs/151/tpot2_base_normal_MNAR_0.3
3.479581356048584
loading data
logs/151/tpot2_base_normal_MNAR_0.3/data/151_True.pkl
Cannot remove faulty tasks cache directory /home/ketrong/.cache/openml/org/openml/www/tasks/151.Please do this manually!
Traceback (most recent call last):
  File "/home/ketrong/miniconda3/envs/tpot2devenv/lib/python3.10/site-packages/openml/tasks/task.py", line 157, in download_split
    split = OpenMLSplit._from_arff_file(cached_split_file)
  File "/home/ketrong/miniconda3/envs/tpot2devenv/lib/python3.10/site-packages/openml/tasks/split.py", line 87, in _from_arff_file
    raise FileNotFoundError("Split arff %s does not exist!" % filename)
FileNotFoundError: Split arff /home/ketrong/.cache/openml/org/openml/www/tasks/151/datasplits.arff does not exist!

During handling of the above exception, another exception occurred:

Traceback (most recent call last):
  File "/home/ketrong/miniconda3/envs/tpot2devenv/lib/python3.10/site-packages/openml/tasks/functions.py", line 409, in get_task
    task.download_split()
  File "/home/ketrong/miniconda3/envs/tpot2devenv/lib/python3.10/site-packages/openml/tasks/task.py", line 161, in download_split
    split = OpenMLSplit._from_arff_file(cached_split_file)
  File "/home/ketrong/miniconda3/envs/tpot2devenv/lib/python3.10/site-packages/openml/tasks/split.py", line 88, in _from_arff_file
    file_data = arff.load(open(filename), return_type=arff.DENSE_GEN)
  File "/home/ketrong/miniconda3/envs/tpot2devenv/lib/python3.10/site-packages/arff.py", line 1059, in load
    return decoder.decode(fp, encode_nominal=encode_nominal,
  File "/home/ketrong/miniconda3/envs/tpot2devenv/lib/python3.10/site-packages/arff.py", line 896, in decode
    raise e
  File "/home/ketrong/miniconda3/envs/tpot2devenv/lib/python3.10/site-packages/arff.py", line 892, in decode
    return self._decode(s, encode_nominal=encode_nominal,
  File "/home/ketrong/miniconda3/envs/tpot2devenv/lib/python3.10/site-packages/arff.py", line 813, in _decode
    obj['relation'] = self._decode_relation(row)
  File "/home/ketrong/miniconda3/envs/tpot2devenv/lib/python3.10/site-packages/arff.py", line 706, in _decode_relation
    raise BadRelationFormat()
arff.BadRelationFormat: Bad @RELATION format, at line 1.

During handling of the above exception, another exception occurred:

Traceback (most recent call last):
  File "/home/ketrong/miniconda3/envs/tpot2devenv/lib/python3.10/site-packages/openml/utils.py", line 375, in _remove_cache_dir_for_id
    shutil.rmtree(cache_dir)
  File "/home/ketrong/miniconda3/envs/tpot2devenv/lib/python3.10/shutil.py", line 731, in rmtree
    onerror(os.rmdir, path, sys.exc_info())
  File "/home/ketrong/miniconda3/envs/tpot2devenv/lib/python3.10/shutil.py", line 729, in rmtree
    os.rmdir(path)
OSError: [Errno 39] Directory not empty: '/home/ketrong/.cache/openml/org/openml/www/tasks/151'

During handling of the above exception, another exception occurred:

Traceback (most recent call last):
  File "/common/ketrong/AutoImputeExp/tpot2_imputetest/Impute_Experiments/utils.py", line 310, in loop_through_tasks
    X_train, y_train, X_test, y_test = load_task(base_save_folder=base_save_folder, exp=exp, type=type, levelstr=levelstr, task_id=taskid, preprocess=True)
  File "/common/ketrong/AutoImputeExp/tpot2_imputetest/Impute_Experiments/utils.py", line 200, in load_task
    task = openml.tasks.get_task(task_id)
  File "/home/ketrong/miniconda3/envs/tpot2devenv/lib/python3.10/site-packages/openml/tasks/functions.py", line 411, in get_task
    openml.utils._remove_cache_dir_for_id(
  File "/home/ketrong/miniconda3/envs/tpot2devenv/lib/python3.10/site-packages/openml/utils.py", line 377, in _remove_cache_dir_for_id
    raise ValueError(
ValueError: Cannot remove faulty tasks cache directory /home/ketrong/.cache/openml/org/openml/www/tasks/151.Please do this manually!

151
remove from investigation?
working on 
logs/151/tpot2_base_imputation_MNAR_0.3
4.279354810714722
loading data
logs/151/tpot2_base_imputation_MNAR_0.3/data/151_True.pkl
Cannot remove faulty tasks cache directory /home/ketrong/.cache/openml/org/openml/www/tasks/151.Please do this manually!
Traceback (most recent call last):
  File "/home/ketrong/miniconda3/envs/tpot2devenv/lib/python3.10/site-packages/openml/tasks/task.py", line 157, in download_split
    split = OpenMLSplit._from_arff_file(cached_split_file)
  File "/home/ketrong/miniconda3/envs/tpot2devenv/lib/python3.10/site-packages/openml/tasks/split.py", line 87, in _from_arff_file
    raise FileNotFoundError("Split arff %s does not exist!" % filename)
FileNotFoundError: Split arff /home/ketrong/.cache/openml/org/openml/www/tasks/151/datasplits.arff does not exist!

During handling of the above exception, another exception occurred:

Traceback (most recent call last):
  File "/home/ketrong/miniconda3/envs/tpot2devenv/lib/python3.10/site-packages/openml/tasks/functions.py", line 409, in get_task
    task.download_split()
  File "/home/ketrong/miniconda3/envs/tpot2devenv/lib/python3.10/site-packages/openml/tasks/task.py", line 161, in download_split
    split = OpenMLSplit._from_arff_file(cached_split_file)
  File "/home/ketrong/miniconda3/envs/tpot2devenv/lib/python3.10/site-packages/openml/tasks/split.py", line 88, in _from_arff_file
    file_data = arff.load(open(filename), return_type=arff.DENSE_GEN)
  File "/home/ketrong/miniconda3/envs/tpot2devenv/lib/python3.10/site-packages/arff.py", line 1059, in load
    return decoder.decode(fp, encode_nominal=encode_nominal,
  File "/home/ketrong/miniconda3/envs/tpot2devenv/lib/python3.10/site-packages/arff.py", line 896, in decode
    raise e
  File "/home/ketrong/miniconda3/envs/tpot2devenv/lib/python3.10/site-packages/arff.py", line 892, in decode
    return self._decode(s, encode_nominal=encode_nominal,
  File "/home/ketrong/miniconda3/envs/tpot2devenv/lib/python3.10/site-packages/arff.py", line 813, in _decode
    obj['relation'] = self._decode_relation(row)
  File "/home/ketrong/miniconda3/envs/tpot2devenv/lib/python3.10/site-packages/arff.py", line 706, in _decode_relation
    raise BadRelationFormat()
arff.BadRelationFormat: Bad @RELATION format, at line 1.

During handling of the above exception, another exception occurred:

Traceback (most recent call last):
  File "/home/ketrong/miniconda3/envs/tpot2devenv/lib/python3.10/site-packages/openml/utils.py", line 375, in _remove_cache_dir_for_id
    shutil.rmtree(cache_dir)
  File "/home/ketrong/miniconda3/envs/tpot2devenv/lib/python3.10/shutil.py", line 731, in rmtree
    onerror(os.rmdir, path, sys.exc_info())
  File "/home/ketrong/miniconda3/envs/tpot2devenv/lib/python3.10/shutil.py", line 729, in rmtree
    os.rmdir(path)
OSError: [Errno 39] Directory not empty: '/home/ketrong/.cache/openml/org/openml/www/tasks/151'

During handling of the above exception, another exception occurred:

Traceback (most recent call last):
  File "/common/ketrong/AutoImputeExp/tpot2_imputetest/Impute_Experiments/utils.py", line 310, in loop_through_tasks
    X_train, y_train, X_test, y_test = load_task(base_save_folder=base_save_folder, exp=exp, type=type, levelstr=levelstr, task_id=taskid, preprocess=True)
  File "/common/ketrong/AutoImputeExp/tpot2_imputetest/Impute_Experiments/utils.py", line 200, in load_task
    task = openml.tasks.get_task(task_id)
  File "/home/ketrong/miniconda3/envs/tpot2devenv/lib/python3.10/site-packages/openml/tasks/functions.py", line 411, in get_task
    openml.utils._remove_cache_dir_for_id(
  File "/home/ketrong/miniconda3/envs/tpot2devenv/lib/python3.10/site-packages/openml/utils.py", line 377, in _remove_cache_dir_for_id
    raise ValueError(
ValueError: Cannot remove faulty tasks cache directory /home/ketrong/.cache/openml/org/openml/www/tasks/151.Please do this manually!

151
remove from investigation?
151
finished
working on 
logs/183/tpot2_base_normal_MNAR_0.3
4.858495473861694
loading data
logs/183/tpot2_base_normal_MNAR_0.3/data/183_True.pkl
Task type Supervised Data Stream Classification not supported.
Traceback (most recent call last):
  File "/home/ketrong/miniconda3/envs/tpot2devenv/lib/python3.10/site-packages/openml/tasks/functions.py", line 70, in _get_cached_task
    with io.open(os.path.join(tid_cache_dir, "task.xml"), encoding="utf8") as fh:
FileNotFoundError: [Errno 2] No such file or directory: '/home/ketrong/.cache/openml/org/openml/www/tasks/183/task.xml'

During handling of the above exception, another exception occurred:

Traceback (most recent call last):
  File "/home/ketrong/miniconda3/envs/tpot2devenv/lib/python3.10/site-packages/openml/tasks/functions.py", line 422, in _get_task_description
    return _get_cached_task(task_id)
  File "/home/ketrong/miniconda3/envs/tpot2devenv/lib/python3.10/site-packages/openml/tasks/functions.py", line 74, in _get_cached_task
    raise OpenMLCacheException("Task file for tid %d not " "cached" % tid)
openml.exceptions.OpenMLCacheException: Task file for tid 183 not cached

During handling of the above exception, another exception occurred:

Traceback (most recent call last):
  File "/common/ketrong/AutoImputeExp/tpot2_imputetest/Impute_Experiments/utils.py", line 310, in loop_through_tasks
    X_train, y_train, X_test, y_test = load_task(base_save_folder=base_save_folder, exp=exp, type=type, levelstr=levelstr, task_id=taskid, preprocess=True)
  File "/common/ketrong/AutoImputeExp/tpot2_imputetest/Impute_Experiments/utils.py", line 200, in load_task
    task = openml.tasks.get_task(task_id)
  File "/home/ketrong/miniconda3/envs/tpot2devenv/lib/python3.10/site-packages/openml/tasks/functions.py", line 415, in get_task
    raise e
  File "/home/ketrong/miniconda3/envs/tpot2devenv/lib/python3.10/site-packages/openml/tasks/functions.py", line 398, in get_task
    task = _get_task_description(task_id)
  File "/home/ketrong/miniconda3/envs/tpot2devenv/lib/python3.10/site-packages/openml/tasks/functions.py", line 435, in _get_task_description
    return _create_task_from_xml(task_xml)
  File "/home/ketrong/miniconda3/envs/tpot2devenv/lib/python3.10/site-packages/openml/tasks/functions.py", line 510, in _create_task_from_xml
    raise NotImplementedError("Task type %s not supported." % common_kwargs["task_type"])
NotImplementedError: Task type Supervised Data Stream Classification not supported.

183
remove from investigation?
working on 
logs/183/tpot2_base_imputation_MNAR_0.3
0.24360275268554688
loading data
logs/183/tpot2_base_imputation_MNAR_0.3/data/183_True.pkl
Cannot remove faulty tasks cache directory /home/ketrong/.cache/openml/org/openml/www/tasks/183.Please do this manually!
Traceback (most recent call last):
  File "/home/ketrong/miniconda3/envs/tpot2devenv/lib/python3.10/site-packages/openml/tasks/functions.py", line 70, in _get_cached_task
    with io.open(os.path.join(tid_cache_dir, "task.xml"), encoding="utf8") as fh:
FileNotFoundError: [Errno 2] No such file or directory: '/home/ketrong/.cache/openml/org/openml/www/tasks/183/task.xml'

During handling of the above exception, another exception occurred:

Traceback (most recent call last):
  File "/home/ketrong/miniconda3/envs/tpot2devenv/lib/python3.10/site-packages/openml/tasks/functions.py", line 422, in _get_task_description
    return _get_cached_task(task_id)
  File "/home/ketrong/miniconda3/envs/tpot2devenv/lib/python3.10/site-packages/openml/tasks/functions.py", line 74, in _get_cached_task
    raise OpenMLCacheException("Task file for tid %d not " "cached" % tid)
openml.exceptions.OpenMLCacheException: Task file for tid 183 not cached

During handling of the above exception, another exception occurred:

Traceback (most recent call last):
  File "/home/ketrong/miniconda3/envs/tpot2devenv/lib/python3.10/site-packages/openml/tasks/functions.py", line 398, in get_task
    task = _get_task_description(task_id)
  File "/home/ketrong/miniconda3/envs/tpot2devenv/lib/python3.10/site-packages/openml/tasks/functions.py", line 433, in _get_task_description
    with io.open(xml_file, "w", encoding="utf8") as fh:
FileNotFoundError: [Errno 2] No such file or directory: '/home/ketrong/.cache/openml/org/openml/www/tasks/183/task.xml'

During handling of the above exception, another exception occurred:

Traceback (most recent call last):
  File "/home/ketrong/miniconda3/envs/tpot2devenv/lib/python3.10/site-packages/openml/utils.py", line 375, in _remove_cache_dir_for_id
    shutil.rmtree(cache_dir)
  File "/home/ketrong/miniconda3/envs/tpot2devenv/lib/python3.10/shutil.py", line 715, in rmtree
    onerror(os.lstat, path, sys.exc_info())
  File "/home/ketrong/miniconda3/envs/tpot2devenv/lib/python3.10/shutil.py", line 713, in rmtree
    orig_st = os.lstat(path)
FileNotFoundError: [Errno 2] No such file or directory: '/home/ketrong/.cache/openml/org/openml/www/tasks/183'

During handling of the above exception, another exception occurred:

Traceback (most recent call last):
  File "/common/ketrong/AutoImputeExp/tpot2_imputetest/Impute_Experiments/utils.py", line 310, in loop_through_tasks
    X_train, y_train, X_test, y_test = load_task(base_save_folder=base_save_folder, exp=exp, type=type, levelstr=levelstr, task_id=taskid, preprocess=True)
  File "/common/ketrong/AutoImputeExp/tpot2_imputetest/Impute_Experiments/utils.py", line 200, in load_task
    task = openml.tasks.get_task(task_id)
  File "/home/ketrong/miniconda3/envs/tpot2devenv/lib/python3.10/site-packages/openml/tasks/functions.py", line 411, in get_task
    openml.utils._remove_cache_dir_for_id(
  File "/home/ketrong/miniconda3/envs/tpot2devenv/lib/python3.10/site-packages/openml/utils.py", line 377, in _remove_cache_dir_for_id
    raise ValueError(
ValueError: Cannot remove faulty tasks cache directory /home/ketrong/.cache/openml/org/openml/www/tasks/183.Please do this manually!

183
remove from investigation?
183
finished
working on 
logs/184/tpot2_base_normal_MNAR_0.3
4.20637845993042
loading data
logs/184/tpot2_base_normal_MNAR_0.3/data/184_True.pkl
Task type Supervised Data Stream Classification not supported.
Traceback (most recent call last):
  File "/home/ketrong/miniconda3/envs/tpot2devenv/lib/python3.10/site-packages/openml/tasks/functions.py", line 70, in _get_cached_task
    with io.open(os.path.join(tid_cache_dir, "task.xml"), encoding="utf8") as fh:
FileNotFoundError: [Errno 2] No such file or directory: '/home/ketrong/.cache/openml/org/openml/www/tasks/184/task.xml'

During handling of the above exception, another exception occurred:

Traceback (most recent call last):
  File "/home/ketrong/miniconda3/envs/tpot2devenv/lib/python3.10/site-packages/openml/tasks/functions.py", line 422, in _get_task_description
    return _get_cached_task(task_id)
  File "/home/ketrong/miniconda3/envs/tpot2devenv/lib/python3.10/site-packages/openml/tasks/functions.py", line 74, in _get_cached_task
    raise OpenMLCacheException("Task file for tid %d not " "cached" % tid)
openml.exceptions.OpenMLCacheException: Task file for tid 184 not cached

During handling of the above exception, another exception occurred:

Traceback (most recent call last):
  File "/common/ketrong/AutoImputeExp/tpot2_imputetest/Impute_Experiments/utils.py", line 310, in loop_through_tasks
    X_train, y_train, X_test, y_test = load_task(base_save_folder=base_save_folder, exp=exp, type=type, levelstr=levelstr, task_id=taskid, preprocess=True)
  File "/common/ketrong/AutoImputeExp/tpot2_imputetest/Impute_Experiments/utils.py", line 200, in load_task
    task = openml.tasks.get_task(task_id)
  File "/home/ketrong/miniconda3/envs/tpot2devenv/lib/python3.10/site-packages/openml/tasks/functions.py", line 415, in get_task
    raise e
  File "/home/ketrong/miniconda3/envs/tpot2devenv/lib/python3.10/site-packages/openml/tasks/functions.py", line 398, in get_task
    task = _get_task_description(task_id)
  File "/home/ketrong/miniconda3/envs/tpot2devenv/lib/python3.10/site-packages/openml/tasks/functions.py", line 435, in _get_task_description
    return _create_task_from_xml(task_xml)
  File "/home/ketrong/miniconda3/envs/tpot2devenv/lib/python3.10/site-packages/openml/tasks/functions.py", line 510, in _create_task_from_xml
    raise NotImplementedError("Task type %s not supported." % common_kwargs["task_type"])
NotImplementedError: Task type Supervised Data Stream Classification not supported.

184
remove from investigation?
working on 
logs/184/tpot2_base_imputation_MNAR_0.3
1.947070598602295
loading data
logs/184/tpot2_base_imputation_MNAR_0.3/data/184_True.pkl
Cannot remove faulty tasks cache directory /home/ketrong/.cache/openml/org/openml/www/tasks/184.Please do this manually!
Traceback (most recent call last):
  File "/home/ketrong/miniconda3/envs/tpot2devenv/lib/python3.10/site-packages/openml/tasks/functions.py", line 70, in _get_cached_task
    with io.open(os.path.join(tid_cache_dir, "task.xml"), encoding="utf8") as fh:
FileNotFoundError: [Errno 2] No such file or directory: '/home/ketrong/.cache/openml/org/openml/www/tasks/184/task.xml'

During handling of the above exception, another exception occurred:

Traceback (most recent call last):
  File "/home/ketrong/miniconda3/envs/tpot2devenv/lib/python3.10/site-packages/openml/tasks/functions.py", line 422, in _get_task_description
    return _get_cached_task(task_id)
  File "/home/ketrong/miniconda3/envs/tpot2devenv/lib/python3.10/site-packages/openml/tasks/functions.py", line 74, in _get_cached_task
    raise OpenMLCacheException("Task file for tid %d not " "cached" % tid)
openml.exceptions.OpenMLCacheException: Task file for tid 184 not cached

During handling of the above exception, another exception occurred:

Traceback (most recent call last):
  File "/home/ketrong/miniconda3/envs/tpot2devenv/lib/python3.10/site-packages/openml/tasks/functions.py", line 398, in get_task
    task = _get_task_description(task_id)
  File "/home/ketrong/miniconda3/envs/tpot2devenv/lib/python3.10/site-packages/openml/tasks/functions.py", line 433, in _get_task_description
    with io.open(xml_file, "w", encoding="utf8") as fh:
FileNotFoundError: [Errno 2] No such file or directory: '/home/ketrong/.cache/openml/org/openml/www/tasks/184/task.xml'

During handling of the above exception, another exception occurred:

Traceback (most recent call last):
  File "/home/ketrong/miniconda3/envs/tpot2devenv/lib/python3.10/site-packages/openml/utils.py", line 375, in _remove_cache_dir_for_id
    shutil.rmtree(cache_dir)
  File "/home/ketrong/miniconda3/envs/tpot2devenv/lib/python3.10/shutil.py", line 715, in rmtree
    onerror(os.lstat, path, sys.exc_info())
  File "/home/ketrong/miniconda3/envs/tpot2devenv/lib/python3.10/shutil.py", line 713, in rmtree
    orig_st = os.lstat(path)
FileNotFoundError: [Errno 2] No such file or directory: '/home/ketrong/.cache/openml/org/openml/www/tasks/184'

During handling of the above exception, another exception occurred:

Traceback (most recent call last):
  File "/common/ketrong/AutoImputeExp/tpot2_imputetest/Impute_Experiments/utils.py", line 310, in loop_through_tasks
    X_train, y_train, X_test, y_test = load_task(base_save_folder=base_save_folder, exp=exp, type=type, levelstr=levelstr, task_id=taskid, preprocess=True)
  File "/common/ketrong/AutoImputeExp/tpot2_imputetest/Impute_Experiments/utils.py", line 200, in load_task
    task = openml.tasks.get_task(task_id)
  File "/home/ketrong/miniconda3/envs/tpot2devenv/lib/python3.10/site-packages/openml/tasks/functions.py", line 411, in get_task
    openml.utils._remove_cache_dir_for_id(
  File "/home/ketrong/miniconda3/envs/tpot2devenv/lib/python3.10/site-packages/openml/utils.py", line 377, in _remove_cache_dir_for_id
    raise ValueError(
ValueError: Cannot remove faulty tasks cache directory /home/ketrong/.cache/openml/org/openml/www/tasks/184.Please do this manually!

184
remove from investigation?
184
finished
working on 
logs/189/tpot2_base_normal_MNAR_0.3
2.2754480838775635
loading data
logs/189/tpot2_base_normal_MNAR_0.3/data/189_True.pkl
Task type Supervised Data Stream Classification not supported.
Traceback (most recent call last):
  File "/home/ketrong/miniconda3/envs/tpot2devenv/lib/python3.10/site-packages/openml/tasks/functions.py", line 70, in _get_cached_task
    with io.open(os.path.join(tid_cache_dir, "task.xml"), encoding="utf8") as fh:
FileNotFoundError: [Errno 2] No such file or directory: '/home/ketrong/.cache/openml/org/openml/www/tasks/189/task.xml'

During handling of the above exception, another exception occurred:

Traceback (most recent call last):
  File "/home/ketrong/miniconda3/envs/tpot2devenv/lib/python3.10/site-packages/openml/tasks/functions.py", line 422, in _get_task_description
    return _get_cached_task(task_id)
  File "/home/ketrong/miniconda3/envs/tpot2devenv/lib/python3.10/site-packages/openml/tasks/functions.py", line 74, in _get_cached_task
    raise OpenMLCacheException("Task file for tid %d not " "cached" % tid)
openml.exceptions.OpenMLCacheException: Task file for tid 189 not cached

During handling of the above exception, another exception occurred:

Traceback (most recent call last):
  File "/common/ketrong/AutoImputeExp/tpot2_imputetest/Impute_Experiments/utils.py", line 310, in loop_through_tasks
    X_train, y_train, X_test, y_test = load_task(base_save_folder=base_save_folder, exp=exp, type=type, levelstr=levelstr, task_id=taskid, preprocess=True)
  File "/common/ketrong/AutoImputeExp/tpot2_imputetest/Impute_Experiments/utils.py", line 200, in load_task
    task = openml.tasks.get_task(task_id)
  File "/home/ketrong/miniconda3/envs/tpot2devenv/lib/python3.10/site-packages/openml/tasks/functions.py", line 415, in get_task
    raise e
  File "/home/ketrong/miniconda3/envs/tpot2devenv/lib/python3.10/site-packages/openml/tasks/functions.py", line 398, in get_task
    task = _get_task_description(task_id)
  File "/home/ketrong/miniconda3/envs/tpot2devenv/lib/python3.10/site-packages/openml/tasks/functions.py", line 435, in _get_task_description
    return _create_task_from_xml(task_xml)
  File "/home/ketrong/miniconda3/envs/tpot2devenv/lib/python3.10/site-packages/openml/tasks/functions.py", line 510, in _create_task_from_xml
    raise NotImplementedError("Task type %s not supported." % common_kwargs["task_type"])
NotImplementedError: Task type Supervised Data Stream Classification not supported.

189
remove from investigation?
working on 
logs/189/tpot2_base_imputation_MNAR_0.3
3.9507558345794678
loading data
logs/189/tpot2_base_imputation_MNAR_0.3/data/189_True.pkl
Task type Supervised Data Stream Classification not supported.
Traceback (most recent call last):
  File "/home/ketrong/miniconda3/envs/tpot2devenv/lib/python3.10/site-packages/openml/tasks/functions.py", line 70, in _get_cached_task
    with io.open(os.path.join(tid_cache_dir, "task.xml"), encoding="utf8") as fh:
FileNotFoundError: [Errno 2] No such file or directory: '/home/ketrong/.cache/openml/org/openml/www/tasks/189/task.xml'

During handling of the above exception, another exception occurred:

Traceback (most recent call last):
  File "/home/ketrong/miniconda3/envs/tpot2devenv/lib/python3.10/site-packages/openml/tasks/functions.py", line 422, in _get_task_description
    return _get_cached_task(task_id)
  File "/home/ketrong/miniconda3/envs/tpot2devenv/lib/python3.10/site-packages/openml/tasks/functions.py", line 74, in _get_cached_task
    raise OpenMLCacheException("Task file for tid %d not " "cached" % tid)
openml.exceptions.OpenMLCacheException: Task file for tid 189 not cached

During handling of the above exception, another exception occurred:

Traceback (most recent call last):
  File "/common/ketrong/AutoImputeExp/tpot2_imputetest/Impute_Experiments/utils.py", line 310, in loop_through_tasks
    X_train, y_train, X_test, y_test = load_task(base_save_folder=base_save_folder, exp=exp, type=type, levelstr=levelstr, task_id=taskid, preprocess=True)
  File "/common/ketrong/AutoImputeExp/tpot2_imputetest/Impute_Experiments/utils.py", line 200, in load_task
    task = openml.tasks.get_task(task_id)
  File "/home/ketrong/miniconda3/envs/tpot2devenv/lib/python3.10/site-packages/openml/tasks/functions.py", line 415, in get_task
    raise e
  File "/home/ketrong/miniconda3/envs/tpot2devenv/lib/python3.10/site-packages/openml/tasks/functions.py", line 398, in get_task
    task = _get_task_description(task_id)
  File "/home/ketrong/miniconda3/envs/tpot2devenv/lib/python3.10/site-packages/openml/tasks/functions.py", line 435, in _get_task_description
    return _create_task_from_xml(task_xml)
  File "/home/ketrong/miniconda3/envs/tpot2devenv/lib/python3.10/site-packages/openml/tasks/functions.py", line 510, in _create_task_from_xml
    raise NotImplementedError("Task type %s not supported." % common_kwargs["task_type"])
NotImplementedError: Task type Supervised Data Stream Classification not supported.

189
remove from investigation?
189
finished
working on 
logs/197/tpot2_base_normal_MNAR_0.3
0.5573115348815918
loading data
logs/197/tpot2_base_normal_MNAR_0.3/data/197_True.pkl
Cannot remove faulty tasks cache directory /home/ketrong/.cache/openml/org/openml/www/tasks/197.Please do this manually!
Traceback (most recent call last):
  File "/home/ketrong/miniconda3/envs/tpot2devenv/lib/python3.10/site-packages/openml/tasks/functions.py", line 70, in _get_cached_task
    with io.open(os.path.join(tid_cache_dir, "task.xml"), encoding="utf8") as fh:
FileNotFoundError: [Errno 2] No such file or directory: '/home/ketrong/.cache/openml/org/openml/www/tasks/197/task.xml'

During handling of the above exception, another exception occurred:

Traceback (most recent call last):
  File "/home/ketrong/miniconda3/envs/tpot2devenv/lib/python3.10/site-packages/openml/tasks/functions.py", line 422, in _get_task_description
    return _get_cached_task(task_id)
  File "/home/ketrong/miniconda3/envs/tpot2devenv/lib/python3.10/site-packages/openml/tasks/functions.py", line 74, in _get_cached_task
    raise OpenMLCacheException("Task file for tid %d not " "cached" % tid)
openml.exceptions.OpenMLCacheException: Task file for tid 197 not cached

During handling of the above exception, another exception occurred:

Traceback (most recent call last):
  File "/home/ketrong/miniconda3/envs/tpot2devenv/lib/python3.10/site-packages/openml/tasks/functions.py", line 398, in get_task
    task = _get_task_description(task_id)
  File "/home/ketrong/miniconda3/envs/tpot2devenv/lib/python3.10/site-packages/openml/tasks/functions.py", line 433, in _get_task_description
    with io.open(xml_file, "w", encoding="utf8") as fh:
FileNotFoundError: [Errno 2] No such file or directory: '/home/ketrong/.cache/openml/org/openml/www/tasks/197/task.xml'

During handling of the above exception, another exception occurred:

Traceback (most recent call last):
  File "/home/ketrong/miniconda3/envs/tpot2devenv/lib/python3.10/site-packages/openml/utils.py", line 375, in _remove_cache_dir_for_id
    shutil.rmtree(cache_dir)
  File "/home/ketrong/miniconda3/envs/tpot2devenv/lib/python3.10/shutil.py", line 715, in rmtree
    onerror(os.lstat, path, sys.exc_info())
  File "/home/ketrong/miniconda3/envs/tpot2devenv/lib/python3.10/shutil.py", line 713, in rmtree
    orig_st = os.lstat(path)
FileNotFoundError: [Errno 2] No such file or directory: '/home/ketrong/.cache/openml/org/openml/www/tasks/197'

During handling of the above exception, another exception occurred:

Traceback (most recent call last):
  File "/common/ketrong/AutoImputeExp/tpot2_imputetest/Impute_Experiments/utils.py", line 310, in loop_through_tasks
    X_train, y_train, X_test, y_test = load_task(base_save_folder=base_save_folder, exp=exp, type=type, levelstr=levelstr, task_id=taskid, preprocess=True)
  File "/common/ketrong/AutoImputeExp/tpot2_imputetest/Impute_Experiments/utils.py", line 200, in load_task
    task = openml.tasks.get_task(task_id)
  File "/home/ketrong/miniconda3/envs/tpot2devenv/lib/python3.10/site-packages/openml/tasks/functions.py", line 411, in get_task
    openml.utils._remove_cache_dir_for_id(
  File "/home/ketrong/miniconda3/envs/tpot2devenv/lib/python3.10/site-packages/openml/utils.py", line 377, in _remove_cache_dir_for_id
    raise ValueError(
ValueError: Cannot remove faulty tasks cache directory /home/ketrong/.cache/openml/org/openml/www/tasks/197.Please do this manually!

197
remove from investigation?
working on 
logs/197/tpot2_base_imputation_MNAR_0.3
1.470367193222046
loading data
logs/197/tpot2_base_imputation_MNAR_0.3/data/197_True.pkl
Task type Supervised Data Stream Classification not supported.
Traceback (most recent call last):
  File "/home/ketrong/miniconda3/envs/tpot2devenv/lib/python3.10/site-packages/openml/tasks/functions.py", line 70, in _get_cached_task
    with io.open(os.path.join(tid_cache_dir, "task.xml"), encoding="utf8") as fh:
FileNotFoundError: [Errno 2] No such file or directory: '/home/ketrong/.cache/openml/org/openml/www/tasks/197/task.xml'

During handling of the above exception, another exception occurred:

Traceback (most recent call last):
  File "/home/ketrong/miniconda3/envs/tpot2devenv/lib/python3.10/site-packages/openml/tasks/functions.py", line 422, in _get_task_description
    return _get_cached_task(task_id)
  File "/home/ketrong/miniconda3/envs/tpot2devenv/lib/python3.10/site-packages/openml/tasks/functions.py", line 74, in _get_cached_task
    raise OpenMLCacheException("Task file for tid %d not " "cached" % tid)
openml.exceptions.OpenMLCacheException: Task file for tid 197 not cached

During handling of the above exception, another exception occurred:

Traceback (most recent call last):
  File "/common/ketrong/AutoImputeExp/tpot2_imputetest/Impute_Experiments/utils.py", line 310, in loop_through_tasks
    X_train, y_train, X_test, y_test = load_task(base_save_folder=base_save_folder, exp=exp, type=type, levelstr=levelstr, task_id=taskid, preprocess=True)
  File "/common/ketrong/AutoImputeExp/tpot2_imputetest/Impute_Experiments/utils.py", line 200, in load_task
    task = openml.tasks.get_task(task_id)
  File "/home/ketrong/miniconda3/envs/tpot2devenv/lib/python3.10/site-packages/openml/tasks/functions.py", line 415, in get_task
    raise e
  File "/home/ketrong/miniconda3/envs/tpot2devenv/lib/python3.10/site-packages/openml/tasks/functions.py", line 398, in get_task
    task = _get_task_description(task_id)
  File "/home/ketrong/miniconda3/envs/tpot2devenv/lib/python3.10/site-packages/openml/tasks/functions.py", line 435, in _get_task_description
    return _create_task_from_xml(task_xml)
  File "/home/ketrong/miniconda3/envs/tpot2devenv/lib/python3.10/site-packages/openml/tasks/functions.py", line 510, in _create_task_from_xml
    raise NotImplementedError("Task type %s not supported." % common_kwargs["task_type"])
NotImplementedError: Task type Supervised Data Stream Classification not supported.

197
remove from investigation?
197
finished
working on 
logs/198/tpot2_base_normal_MNAR_0.3
1.0407626628875732
loading data
logs/198/tpot2_base_normal_MNAR_0.3/data/198_True.pkl
Task type Supervised Data Stream Classification not supported.
Traceback (most recent call last):
  File "/home/ketrong/miniconda3/envs/tpot2devenv/lib/python3.10/site-packages/openml/tasks/functions.py", line 70, in _get_cached_task
    with io.open(os.path.join(tid_cache_dir, "task.xml"), encoding="utf8") as fh:
FileNotFoundError: [Errno 2] No such file or directory: '/home/ketrong/.cache/openml/org/openml/www/tasks/198/task.xml'

During handling of the above exception, another exception occurred:

Traceback (most recent call last):
  File "/home/ketrong/miniconda3/envs/tpot2devenv/lib/python3.10/site-packages/openml/tasks/functions.py", line 422, in _get_task_description
    return _get_cached_task(task_id)
  File "/home/ketrong/miniconda3/envs/tpot2devenv/lib/python3.10/site-packages/openml/tasks/functions.py", line 74, in _get_cached_task
    raise OpenMLCacheException("Task file for tid %d not " "cached" % tid)
openml.exceptions.OpenMLCacheException: Task file for tid 198 not cached

During handling of the above exception, another exception occurred:

Traceback (most recent call last):
  File "/common/ketrong/AutoImputeExp/tpot2_imputetest/Impute_Experiments/utils.py", line 310, in loop_through_tasks
    X_train, y_train, X_test, y_test = load_task(base_save_folder=base_save_folder, exp=exp, type=type, levelstr=levelstr, task_id=taskid, preprocess=True)
  File "/common/ketrong/AutoImputeExp/tpot2_imputetest/Impute_Experiments/utils.py", line 200, in load_task
    task = openml.tasks.get_task(task_id)
  File "/home/ketrong/miniconda3/envs/tpot2devenv/lib/python3.10/site-packages/openml/tasks/functions.py", line 415, in get_task
    raise e
  File "/home/ketrong/miniconda3/envs/tpot2devenv/lib/python3.10/site-packages/openml/tasks/functions.py", line 398, in get_task
    task = _get_task_description(task_id)
  File "/home/ketrong/miniconda3/envs/tpot2devenv/lib/python3.10/site-packages/openml/tasks/functions.py", line 435, in _get_task_description
    return _create_task_from_xml(task_xml)
  File "/home/ketrong/miniconda3/envs/tpot2devenv/lib/python3.10/site-packages/openml/tasks/functions.py", line 510, in _create_task_from_xml
    raise NotImplementedError("Task type %s not supported." % common_kwargs["task_type"])
NotImplementedError: Task type Supervised Data Stream Classification not supported.

198
remove from investigation?
working on 
logs/198/tpot2_base_imputation_MNAR_0.3
1.9920103549957275
loading data
logs/198/tpot2_base_imputation_MNAR_0.3/data/198_True.pkl
Task type Supervised Data Stream Classification not supported.
Traceback (most recent call last):
  File "/home/ketrong/miniconda3/envs/tpot2devenv/lib/python3.10/site-packages/openml/tasks/functions.py", line 70, in _get_cached_task
    with io.open(os.path.join(tid_cache_dir, "task.xml"), encoding="utf8") as fh:
FileNotFoundError: [Errno 2] No such file or directory: '/home/ketrong/.cache/openml/org/openml/www/tasks/198/task.xml'

During handling of the above exception, another exception occurred:

Traceback (most recent call last):
  File "/home/ketrong/miniconda3/envs/tpot2devenv/lib/python3.10/site-packages/openml/tasks/functions.py", line 422, in _get_task_description
    return _get_cached_task(task_id)
  File "/home/ketrong/miniconda3/envs/tpot2devenv/lib/python3.10/site-packages/openml/tasks/functions.py", line 74, in _get_cached_task
    raise OpenMLCacheException("Task file for tid %d not " "cached" % tid)
openml.exceptions.OpenMLCacheException: Task file for tid 198 not cached

During handling of the above exception, another exception occurred:

Traceback (most recent call last):
  File "/common/ketrong/AutoImputeExp/tpot2_imputetest/Impute_Experiments/utils.py", line 310, in loop_through_tasks
    X_train, y_train, X_test, y_test = load_task(base_save_folder=base_save_folder, exp=exp, type=type, levelstr=levelstr, task_id=taskid, preprocess=True)
  File "/common/ketrong/AutoImputeExp/tpot2_imputetest/Impute_Experiments/utils.py", line 200, in load_task
    task = openml.tasks.get_task(task_id)
  File "/home/ketrong/miniconda3/envs/tpot2devenv/lib/python3.10/site-packages/openml/tasks/functions.py", line 415, in get_task
    raise e
  File "/home/ketrong/miniconda3/envs/tpot2devenv/lib/python3.10/site-packages/openml/tasks/functions.py", line 398, in get_task
    task = _get_task_description(task_id)
  File "/home/ketrong/miniconda3/envs/tpot2devenv/lib/python3.10/site-packages/openml/tasks/functions.py", line 435, in _get_task_description
    return _create_task_from_xml(task_xml)
  File "/home/ketrong/miniconda3/envs/tpot2devenv/lib/python3.10/site-packages/openml/tasks/functions.py", line 510, in _create_task_from_xml
    raise NotImplementedError("Task type %s not supported." % common_kwargs["task_type"])
NotImplementedError: Task type Supervised Data Stream Classification not supported.

198
remove from investigation?
198
finished
working on 
logs/215/tpot2_base_normal_MNAR_0.3
4.476210594177246
loading data
logs/215/tpot2_base_normal_MNAR_0.3/data/215_True.pkl
working on 
logs/215/tpot2_base_imputation_MNAR_0.3
2.6608550548553467
loading data
logs/215/tpot2_base_imputation_MNAR_0.3/data/215_True.pkl
215
finished
working on 
logs/216/tpot2_base_normal_MNAR_0.3
1.8961541652679443
loading data
logs/216/tpot2_base_normal_MNAR_0.3/data/216_True.pkl
Split arff /home/ketrong/.cache/openml/org/openml/www/tasks/216/datasplits.arff does not exist!
Traceback (most recent call last):
  File "/home/ketrong/miniconda3/envs/tpot2devenv/lib/python3.10/site-packages/openml/tasks/task.py", line 157, in download_split
    split = OpenMLSplit._from_arff_file(cached_split_file)
  File "/home/ketrong/miniconda3/envs/tpot2devenv/lib/python3.10/site-packages/openml/tasks/split.py", line 87, in _from_arff_file
    raise FileNotFoundError("Split arff %s does not exist!" % filename)
FileNotFoundError: Split arff /home/ketrong/.cache/openml/org/openml/www/tasks/216/datasplits.arff does not exist!

During handling of the above exception, another exception occurred:

Traceback (most recent call last):
  File "/common/ketrong/AutoImputeExp/tpot2_imputetest/Impute_Experiments/utils.py", line 310, in loop_through_tasks
    X_train, y_train, X_test, y_test = load_task(base_save_folder=base_save_folder, exp=exp, type=type, levelstr=levelstr, task_id=taskid, preprocess=True)
  File "/common/ketrong/AutoImputeExp/tpot2_imputetest/Impute_Experiments/utils.py", line 200, in load_task
    task = openml.tasks.get_task(task_id)
  File "/home/ketrong/miniconda3/envs/tpot2devenv/lib/python3.10/site-packages/openml/tasks/functions.py", line 415, in get_task
    raise e
  File "/home/ketrong/miniconda3/envs/tpot2devenv/lib/python3.10/site-packages/openml/tasks/functions.py", line 409, in get_task
    task.download_split()
  File "/home/ketrong/miniconda3/envs/tpot2devenv/lib/python3.10/site-packages/openml/tasks/task.py", line 161, in download_split
    split = OpenMLSplit._from_arff_file(cached_split_file)
  File "/home/ketrong/miniconda3/envs/tpot2devenv/lib/python3.10/site-packages/openml/tasks/split.py", line 87, in _from_arff_file
    raise FileNotFoundError("Split arff %s does not exist!" % filename)
FileNotFoundError: Split arff /home/ketrong/.cache/openml/org/openml/www/tasks/216/datasplits.arff does not exist!

216
remove from investigation?
working on 
logs/216/tpot2_base_imputation_MNAR_0.3
2.2504959106445312
loading data
logs/216/tpot2_base_imputation_MNAR_0.3/data/216_True.pkl
Cannot remove faulty tasks cache directory /home/ketrong/.cache/openml/org/openml/www/tasks/216.Please do this manually!
Traceback (most recent call last):
  File "/home/ketrong/miniconda3/envs/tpot2devenv/lib/python3.10/site-packages/openml/tasks/task.py", line 157, in download_split
    split = OpenMLSplit._from_arff_file(cached_split_file)
  File "/home/ketrong/miniconda3/envs/tpot2devenv/lib/python3.10/site-packages/openml/tasks/split.py", line 87, in _from_arff_file
    raise FileNotFoundError("Split arff %s does not exist!" % filename)
FileNotFoundError: Split arff /home/ketrong/.cache/openml/org/openml/www/tasks/216/datasplits.arff does not exist!

During handling of the above exception, another exception occurred:

Traceback (most recent call last):
  File "/home/ketrong/miniconda3/envs/tpot2devenv/lib/python3.10/site-packages/openml/tasks/task.py", line 140, in _download_split
    with io.open(cache_file, encoding="utf8"):
FileNotFoundError: [Errno 2] No such file or directory: '/home/ketrong/.cache/openml/org/openml/www/tasks/216/datasplits.arff'

During handling of the above exception, another exception occurred:

Traceback (most recent call last):
  File "/home/ketrong/miniconda3/envs/tpot2devenv/lib/python3.10/site-packages/openml/tasks/functions.py", line 409, in get_task
    task.download_split()
  File "/home/ketrong/miniconda3/envs/tpot2devenv/lib/python3.10/site-packages/openml/tasks/task.py", line 160, in download_split
    self._download_split(cached_split_file)
  File "/home/ketrong/miniconda3/envs/tpot2devenv/lib/python3.10/site-packages/openml/tasks/task.py", line 144, in _download_split
    openml._api_calls._download_text_file(
  File "/home/ketrong/miniconda3/envs/tpot2devenv/lib/python3.10/site-packages/openml/_api_calls.py", line 252, in _download_text_file
    with open(output_path, "w", encoding=encoding) as fh:
FileNotFoundError: [Errno 2] No such file or directory: '/home/ketrong/.cache/openml/org/openml/www/tasks/216/datasplits.arff'

During handling of the above exception, another exception occurred:

Traceback (most recent call last):
  File "/home/ketrong/miniconda3/envs/tpot2devenv/lib/python3.10/site-packages/openml/utils.py", line 375, in _remove_cache_dir_for_id
    shutil.rmtree(cache_dir)
  File "/home/ketrong/miniconda3/envs/tpot2devenv/lib/python3.10/shutil.py", line 715, in rmtree
    onerror(os.lstat, path, sys.exc_info())
  File "/home/ketrong/miniconda3/envs/tpot2devenv/lib/python3.10/shutil.py", line 713, in rmtree
    orig_st = os.lstat(path)
FileNotFoundError: [Errno 2] No such file or directory: '/home/ketrong/.cache/openml/org/openml/www/tasks/216'

During handling of the above exception, another exception occurred:

Traceback (most recent call last):
  File "/common/ketrong/AutoImputeExp/tpot2_imputetest/Impute_Experiments/utils.py", line 310, in loop_through_tasks
    X_train, y_train, X_test, y_test = load_task(base_save_folder=base_save_folder, exp=exp, type=type, levelstr=levelstr, task_id=taskid, preprocess=True)
  File "/common/ketrong/AutoImputeExp/tpot2_imputetest/Impute_Experiments/utils.py", line 200, in load_task
    task = openml.tasks.get_task(task_id)
  File "/home/ketrong/miniconda3/envs/tpot2devenv/lib/python3.10/site-packages/openml/tasks/functions.py", line 411, in get_task
    openml.utils._remove_cache_dir_for_id(
  File "/home/ketrong/miniconda3/envs/tpot2devenv/lib/python3.10/site-packages/openml/utils.py", line 377, in _remove_cache_dir_for_id
    raise ValueError(
ValueError: Cannot remove faulty tasks cache directory /home/ketrong/.cache/openml/org/openml/www/tasks/216.Please do this manually!

216
remove from investigation?
216
finished
working on 
logs/218/tpot2_base_normal_MNAR_0.3
3.567870616912842
loading data
logs/218/tpot2_base_normal_MNAR_0.3/data/218_True.pkl
working on 
logs/218/tpot2_base_imputation_MNAR_0.3
0.3288261890411377
loading data
logs/218/tpot2_base_imputation_MNAR_0.3/data/218_True.pkl
218
finished
working on 
logs/251/tpot2_base_normal_MNAR_0.3
1.852386713027954
loading data
logs/251/tpot2_base_normal_MNAR_0.3/data/251_True.pkl
WARNING:openml.datasets.functions:Could not download file from http://openml1.win.tue.nl/dataset21/dataset_21.pq: Bucket does not exist or is private.
WARNING:openml.datasets.functions:Failed to download parquet, fallback on ARFF.
WARNING:openml.datasets.functions:Could not download file from http://openml1.win.tue.nl/dataset21/dataset_21.pq: Bucket does not exist or is private.
WARNING:openml.datasets.functions:Failed to download parquet, fallback on ARFF.
working on 
logs/251/tpot2_base_imputation_MNAR_0.3
1.5946636199951172
loading data
logs/251/tpot2_base_imputation_MNAR_0.3/data/251_True.pkl
WARNING:openml.datasets.functions:Could not download file from http://openml1.win.tue.nl/dataset21/dataset_21.pq: Bucket does not exist or is private.
WARNING:openml.datasets.functions:Failed to download parquet, fallback on ARFF.
WARNING:openml.datasets.functions:Could not download file from http://openml1.win.tue.nl/dataset21/dataset_21.pq: Bucket does not exist or is private.
WARNING:openml.datasets.functions:Failed to download parquet, fallback on ARFF.
251
finished
working on 
logs/287/tpot2_base_normal_MNAR_0.3
4.470420598983765
loading data
logs/287/tpot2_base_normal_MNAR_0.3/data/287_True.pkl
working on 
logs/287/tpot2_base_imputation_MNAR_0.3
3.9906928539276123
loading data
logs/287/tpot2_base_imputation_MNAR_0.3/data/287_True.pkl
287
finished
working on 
logs/310/tpot2_base_normal_MNAR_0.3
4.251983880996704
loading data
logs/310/tpot2_base_normal_MNAR_0.3/data/310_True.pkl
Cannot remove faulty tasks cache directory /home/ketrong/.cache/openml/org/openml/www/tasks/310.Please do this manually!
Traceback (most recent call last):
  File "/home/ketrong/miniconda3/envs/tpot2devenv/lib/python3.10/site-packages/openml/tasks/task.py", line 157, in download_split
    split = OpenMLSplit._from_arff_file(cached_split_file)
  File "/home/ketrong/miniconda3/envs/tpot2devenv/lib/python3.10/site-packages/openml/tasks/split.py", line 87, in _from_arff_file
    raise FileNotFoundError("Split arff %s does not exist!" % filename)
FileNotFoundError: Split arff /home/ketrong/.cache/openml/org/openml/www/tasks/310/datasplits.arff does not exist!

During handling of the above exception, another exception occurred:

Traceback (most recent call last):
  File "/home/ketrong/miniconda3/envs/tpot2devenv/lib/python3.10/site-packages/openml/tasks/functions.py", line 409, in get_task
    task.download_split()
  File "/home/ketrong/miniconda3/envs/tpot2devenv/lib/python3.10/site-packages/openml/tasks/task.py", line 161, in download_split
    split = OpenMLSplit._from_arff_file(cached_split_file)
  File "/home/ketrong/miniconda3/envs/tpot2devenv/lib/python3.10/site-packages/openml/tasks/split.py", line 88, in _from_arff_file
    file_data = arff.load(open(filename), return_type=arff.DENSE_GEN)
  File "/home/ketrong/miniconda3/envs/tpot2devenv/lib/python3.10/site-packages/arff.py", line 1059, in load
    return decoder.decode(fp, encode_nominal=encode_nominal,
  File "/home/ketrong/miniconda3/envs/tpot2devenv/lib/python3.10/site-packages/arff.py", line 896, in decode
    raise e
  File "/home/ketrong/miniconda3/envs/tpot2devenv/lib/python3.10/site-packages/arff.py", line 892, in decode
    return self._decode(s, encode_nominal=encode_nominal,
  File "/home/ketrong/miniconda3/envs/tpot2devenv/lib/python3.10/site-packages/arff.py", line 813, in _decode
    obj['relation'] = self._decode_relation(row)
  File "/home/ketrong/miniconda3/envs/tpot2devenv/lib/python3.10/site-packages/arff.py", line 706, in _decode_relation
    raise BadRelationFormat()
arff.BadRelationFormat: Bad @RELATION format, at line 1.

During handling of the above exception, another exception occurred:

Traceback (most recent call last):
  File "/home/ketrong/miniconda3/envs/tpot2devenv/lib/python3.10/site-packages/openml/utils.py", line 375, in _remove_cache_dir_for_id
    shutil.rmtree(cache_dir)
  File "/home/ketrong/miniconda3/envs/tpot2devenv/lib/python3.10/shutil.py", line 731, in rmtree
    onerror(os.rmdir, path, sys.exc_info())
  File "/home/ketrong/miniconda3/envs/tpot2devenv/lib/python3.10/shutil.py", line 729, in rmtree
    os.rmdir(path)
OSError: [Errno 39] Directory not empty: '/home/ketrong/.cache/openml/org/openml/www/tasks/310'

During handling of the above exception, another exception occurred:

Traceback (most recent call last):
  File "/common/ketrong/AutoImputeExp/tpot2_imputetest/Impute_Experiments/utils.py", line 310, in loop_through_tasks
    X_train, y_train, X_test, y_test = load_task(base_save_folder=base_save_folder, exp=exp, type=type, levelstr=levelstr, task_id=taskid, preprocess=True)
  File "/common/ketrong/AutoImputeExp/tpot2_imputetest/Impute_Experiments/utils.py", line 200, in load_task
    task = openml.tasks.get_task(task_id)
  File "/home/ketrong/miniconda3/envs/tpot2devenv/lib/python3.10/site-packages/openml/tasks/functions.py", line 411, in get_task
    openml.utils._remove_cache_dir_for_id(
  File "/home/ketrong/miniconda3/envs/tpot2devenv/lib/python3.10/site-packages/openml/utils.py", line 377, in _remove_cache_dir_for_id
    raise ValueError(
ValueError: Cannot remove faulty tasks cache directory /home/ketrong/.cache/openml/org/openml/www/tasks/310.Please do this manually!

310
remove from investigation?
working on 
logs/310/tpot2_base_imputation_MNAR_0.3
4.96315598487854
loading data
logs/310/tpot2_base_imputation_MNAR_0.3/data/310_True.pkl
Cannot remove faulty tasks cache directory /home/ketrong/.cache/openml/org/openml/www/tasks/310.Please do this manually!
Traceback (most recent call last):
  File "/home/ketrong/miniconda3/envs/tpot2devenv/lib/python3.10/site-packages/openml/tasks/task.py", line 157, in download_split
    split = OpenMLSplit._from_arff_file(cached_split_file)
  File "/home/ketrong/miniconda3/envs/tpot2devenv/lib/python3.10/site-packages/openml/tasks/split.py", line 87, in _from_arff_file
    raise FileNotFoundError("Split arff %s does not exist!" % filename)
FileNotFoundError: Split arff /home/ketrong/.cache/openml/org/openml/www/tasks/310/datasplits.arff does not exist!

During handling of the above exception, another exception occurred:

Traceback (most recent call last):
  File "/home/ketrong/miniconda3/envs/tpot2devenv/lib/python3.10/site-packages/openml/tasks/functions.py", line 409, in get_task
    task.download_split()
  File "/home/ketrong/miniconda3/envs/tpot2devenv/lib/python3.10/site-packages/openml/tasks/task.py", line 161, in download_split
    split = OpenMLSplit._from_arff_file(cached_split_file)
  File "/home/ketrong/miniconda3/envs/tpot2devenv/lib/python3.10/site-packages/openml/tasks/split.py", line 88, in _from_arff_file
    file_data = arff.load(open(filename), return_type=arff.DENSE_GEN)
  File "/home/ketrong/miniconda3/envs/tpot2devenv/lib/python3.10/site-packages/arff.py", line 1059, in load
    return decoder.decode(fp, encode_nominal=encode_nominal,
  File "/home/ketrong/miniconda3/envs/tpot2devenv/lib/python3.10/site-packages/arff.py", line 896, in decode
    raise e
  File "/home/ketrong/miniconda3/envs/tpot2devenv/lib/python3.10/site-packages/arff.py", line 892, in decode
    return self._decode(s, encode_nominal=encode_nominal,
  File "/home/ketrong/miniconda3/envs/tpot2devenv/lib/python3.10/site-packages/arff.py", line 813, in _decode
    obj['relation'] = self._decode_relation(row)
  File "/home/ketrong/miniconda3/envs/tpot2devenv/lib/python3.10/site-packages/arff.py", line 706, in _decode_relation
    raise BadRelationFormat()
arff.BadRelationFormat: Bad @RELATION format, at line 1.

During handling of the above exception, another exception occurred:

Traceback (most recent call last):
  File "/home/ketrong/miniconda3/envs/tpot2devenv/lib/python3.10/site-packages/openml/utils.py", line 375, in _remove_cache_dir_for_id
    shutil.rmtree(cache_dir)
  File "/home/ketrong/miniconda3/envs/tpot2devenv/lib/python3.10/shutil.py", line 731, in rmtree
    onerror(os.rmdir, path, sys.exc_info())
  File "/home/ketrong/miniconda3/envs/tpot2devenv/lib/python3.10/shutil.py", line 729, in rmtree
    os.rmdir(path)
OSError: [Errno 39] Directory not empty: '/home/ketrong/.cache/openml/org/openml/www/tasks/310'

During handling of the above exception, another exception occurred:

Traceback (most recent call last):
  File "/common/ketrong/AutoImputeExp/tpot2_imputetest/Impute_Experiments/utils.py", line 310, in loop_through_tasks
    X_train, y_train, X_test, y_test = load_task(base_save_folder=base_save_folder, exp=exp, type=type, levelstr=levelstr, task_id=taskid, preprocess=True)
  File "/common/ketrong/AutoImputeExp/tpot2_imputetest/Impute_Experiments/utils.py", line 200, in load_task
    task = openml.tasks.get_task(task_id)
  File "/home/ketrong/miniconda3/envs/tpot2devenv/lib/python3.10/site-packages/openml/tasks/functions.py", line 411, in get_task
    openml.utils._remove_cache_dir_for_id(
  File "/home/ketrong/miniconda3/envs/tpot2devenv/lib/python3.10/site-packages/openml/utils.py", line 377, in _remove_cache_dir_for_id
    raise ValueError(
ValueError: Cannot remove faulty tasks cache directory /home/ketrong/.cache/openml/org/openml/www/tasks/310.Please do this manually!

310
remove from investigation?
310
finished
working on 
logs/375/tpot2_base_normal_MNAR_0.3
2.497948408126831
loading data
logs/375/tpot2_base_normal_MNAR_0.3/data/375_True.pkl
https://www.openml.org/api/v1/xml/task/375 returned code 151: Unknown task - None
Traceback (most recent call last):
  File "/home/ketrong/miniconda3/envs/tpot2devenv/lib/python3.10/site-packages/openml/tasks/functions.py", line 70, in _get_cached_task
    with io.open(os.path.join(tid_cache_dir, "task.xml"), encoding="utf8") as fh:
FileNotFoundError: [Errno 2] No such file or directory: '/home/ketrong/.cache/openml/org/openml/www/tasks/375/task.xml'

During handling of the above exception, another exception occurred:

Traceback (most recent call last):
  File "/home/ketrong/miniconda3/envs/tpot2devenv/lib/python3.10/site-packages/openml/tasks/functions.py", line 422, in _get_task_description
    return _get_cached_task(task_id)
  File "/home/ketrong/miniconda3/envs/tpot2devenv/lib/python3.10/site-packages/openml/tasks/functions.py", line 74, in _get_cached_task
    raise OpenMLCacheException("Task file for tid %d not " "cached" % tid)
openml.exceptions.OpenMLCacheException: Task file for tid 375 not cached

During handling of the above exception, another exception occurred:

Traceback (most recent call last):
  File "/common/ketrong/AutoImputeExp/tpot2_imputetest/Impute_Experiments/utils.py", line 310, in loop_through_tasks
    X_train, y_train, X_test, y_test = load_task(base_save_folder=base_save_folder, exp=exp, type=type, levelstr=levelstr, task_id=taskid, preprocess=True)
  File "/common/ketrong/AutoImputeExp/tpot2_imputetest/Impute_Experiments/utils.py", line 200, in load_task
    task = openml.tasks.get_task(task_id)
  File "/home/ketrong/miniconda3/envs/tpot2devenv/lib/python3.10/site-packages/openml/tasks/functions.py", line 415, in get_task
    raise e
  File "/home/ketrong/miniconda3/envs/tpot2devenv/lib/python3.10/site-packages/openml/tasks/functions.py", line 398, in get_task
    task = _get_task_description(task_id)
  File "/home/ketrong/miniconda3/envs/tpot2devenv/lib/python3.10/site-packages/openml/tasks/functions.py", line 431, in _get_task_description
    task_xml = openml._api_calls._perform_api_call("task/%d" % task_id, "get")
  File "/home/ketrong/miniconda3/envs/tpot2devenv/lib/python3.10/site-packages/openml/_api_calls.py", line 99, in _perform_api_call
    response = __read_url(url, request_method, data)
  File "/home/ketrong/miniconda3/envs/tpot2devenv/lib/python3.10/site-packages/openml/_api_calls.py", line 308, in __read_url
    return _send_request(
  File "/home/ketrong/miniconda3/envs/tpot2devenv/lib/python3.10/site-packages/openml/_api_calls.py", line 344, in _send_request
    __check_response(response=response, url=url, file_elements=files)
  File "/home/ketrong/miniconda3/envs/tpot2devenv/lib/python3.10/site-packages/openml/_api_calls.py", line 409, in __check_response
    raise __parse_server_exception(response, url, file_elements=file_elements)
openml.exceptions.OpenMLServerException: https://www.openml.org/api/v1/xml/task/375 returned code 151: Unknown task - None

375
remove from investigation?
working on 
logs/375/tpot2_base_imputation_MNAR_0.3
1.865727424621582
loading data
logs/375/tpot2_base_imputation_MNAR_0.3/data/375_True.pkl
https://www.openml.org/api/v1/xml/task/375 returned code 151: Unknown task - None
Traceback (most recent call last):
  File "/home/ketrong/miniconda3/envs/tpot2devenv/lib/python3.10/site-packages/openml/tasks/functions.py", line 70, in _get_cached_task
    with io.open(os.path.join(tid_cache_dir, "task.xml"), encoding="utf8") as fh:
FileNotFoundError: [Errno 2] No such file or directory: '/home/ketrong/.cache/openml/org/openml/www/tasks/375/task.xml'

During handling of the above exception, another exception occurred:

Traceback (most recent call last):
  File "/home/ketrong/miniconda3/envs/tpot2devenv/lib/python3.10/site-packages/openml/tasks/functions.py", line 422, in _get_task_description
    return _get_cached_task(task_id)
  File "/home/ketrong/miniconda3/envs/tpot2devenv/lib/python3.10/site-packages/openml/tasks/functions.py", line 74, in _get_cached_task
    raise OpenMLCacheException("Task file for tid %d not " "cached" % tid)
openml.exceptions.OpenMLCacheException: Task file for tid 375 not cached

During handling of the above exception, another exception occurred:

Traceback (most recent call last):
  File "/common/ketrong/AutoImputeExp/tpot2_imputetest/Impute_Experiments/utils.py", line 310, in loop_through_tasks
    X_train, y_train, X_test, y_test = load_task(base_save_folder=base_save_folder, exp=exp, type=type, levelstr=levelstr, task_id=taskid, preprocess=True)
  File "/common/ketrong/AutoImputeExp/tpot2_imputetest/Impute_Experiments/utils.py", line 200, in load_task
    task = openml.tasks.get_task(task_id)
  File "/home/ketrong/miniconda3/envs/tpot2devenv/lib/python3.10/site-packages/openml/tasks/functions.py", line 415, in get_task
    raise e
  File "/home/ketrong/miniconda3/envs/tpot2devenv/lib/python3.10/site-packages/openml/tasks/functions.py", line 398, in get_task
    task = _get_task_description(task_id)
  File "/home/ketrong/miniconda3/envs/tpot2devenv/lib/python3.10/site-packages/openml/tasks/functions.py", line 431, in _get_task_description
    task_xml = openml._api_calls._perform_api_call("task/%d" % task_id, "get")
  File "/home/ketrong/miniconda3/envs/tpot2devenv/lib/python3.10/site-packages/openml/_api_calls.py", line 99, in _perform_api_call
    response = __read_url(url, request_method, data)
  File "/home/ketrong/miniconda3/envs/tpot2devenv/lib/python3.10/site-packages/openml/_api_calls.py", line 308, in __read_url
    return _send_request(
  File "/home/ketrong/miniconda3/envs/tpot2devenv/lib/python3.10/site-packages/openml/_api_calls.py", line 344, in _send_request
    __check_response(response=response, url=url, file_elements=files)
  File "/home/ketrong/miniconda3/envs/tpot2devenv/lib/python3.10/site-packages/openml/_api_calls.py", line 409, in __check_response
    raise __parse_server_exception(response, url, file_elements=file_elements)
openml.exceptions.OpenMLServerException: https://www.openml.org/api/v1/xml/task/375 returned code 151: Unknown task - None

375
remove from investigation?
375
finished
working on 
logs/725/tpot2_base_normal_MNAR_0.3
3.3414804935455322
loading data
logs/725/tpot2_base_normal_MNAR_0.3/data/725_True.pkl
https://www.openml.org/api/v1/xml/task/725 returned code 151: Unknown task - None
Traceback (most recent call last):
  File "/home/ketrong/miniconda3/envs/tpot2devenv/lib/python3.10/site-packages/openml/tasks/functions.py", line 70, in _get_cached_task
    with io.open(os.path.join(tid_cache_dir, "task.xml"), encoding="utf8") as fh:
FileNotFoundError: [Errno 2] No such file or directory: '/home/ketrong/.cache/openml/org/openml/www/tasks/725/task.xml'

During handling of the above exception, another exception occurred:

Traceback (most recent call last):
  File "/home/ketrong/miniconda3/envs/tpot2devenv/lib/python3.10/site-packages/openml/tasks/functions.py", line 422, in _get_task_description
    return _get_cached_task(task_id)
  File "/home/ketrong/miniconda3/envs/tpot2devenv/lib/python3.10/site-packages/openml/tasks/functions.py", line 74, in _get_cached_task
    raise OpenMLCacheException("Task file for tid %d not " "cached" % tid)
openml.exceptions.OpenMLCacheException: Task file for tid 725 not cached

During handling of the above exception, another exception occurred:

Traceback (most recent call last):
  File "/common/ketrong/AutoImputeExp/tpot2_imputetest/Impute_Experiments/utils.py", line 310, in loop_through_tasks
    X_train, y_train, X_test, y_test = load_task(base_save_folder=base_save_folder, exp=exp, type=type, levelstr=levelstr, task_id=taskid, preprocess=True)
  File "/common/ketrong/AutoImputeExp/tpot2_imputetest/Impute_Experiments/utils.py", line 200, in load_task
    task = openml.tasks.get_task(task_id)
  File "/home/ketrong/miniconda3/envs/tpot2devenv/lib/python3.10/site-packages/openml/tasks/functions.py", line 415, in get_task
    raise e
  File "/home/ketrong/miniconda3/envs/tpot2devenv/lib/python3.10/site-packages/openml/tasks/functions.py", line 398, in get_task
    task = _get_task_description(task_id)
  File "/home/ketrong/miniconda3/envs/tpot2devenv/lib/python3.10/site-packages/openml/tasks/functions.py", line 431, in _get_task_description
    task_xml = openml._api_calls._perform_api_call("task/%d" % task_id, "get")
  File "/home/ketrong/miniconda3/envs/tpot2devenv/lib/python3.10/site-packages/openml/_api_calls.py", line 99, in _perform_api_call
    response = __read_url(url, request_method, data)
  File "/home/ketrong/miniconda3/envs/tpot2devenv/lib/python3.10/site-packages/openml/_api_calls.py", line 308, in __read_url
    return _send_request(
  File "/home/ketrong/miniconda3/envs/tpot2devenv/lib/python3.10/site-packages/openml/_api_calls.py", line 344, in _send_request
    __check_response(response=response, url=url, file_elements=files)
  File "/home/ketrong/miniconda3/envs/tpot2devenv/lib/python3.10/site-packages/openml/_api_calls.py", line 409, in __check_response
    raise __parse_server_exception(response, url, file_elements=file_elements)
openml.exceptions.OpenMLServerException: https://www.openml.org/api/v1/xml/task/725 returned code 151: Unknown task - None

725
remove from investigation?
working on 
logs/725/tpot2_base_imputation_MNAR_0.3
4.427704095840454
loading data
logs/725/tpot2_base_imputation_MNAR_0.3/data/725_True.pkl
https://www.openml.org/api/v1/xml/task/725 returned code 151: Unknown task - None
Traceback (most recent call last):
  File "/home/ketrong/miniconda3/envs/tpot2devenv/lib/python3.10/site-packages/openml/tasks/functions.py", line 70, in _get_cached_task
    with io.open(os.path.join(tid_cache_dir, "task.xml"), encoding="utf8") as fh:
FileNotFoundError: [Errno 2] No such file or directory: '/home/ketrong/.cache/openml/org/openml/www/tasks/725/task.xml'

During handling of the above exception, another exception occurred:

Traceback (most recent call last):
  File "/home/ketrong/miniconda3/envs/tpot2devenv/lib/python3.10/site-packages/openml/tasks/functions.py", line 422, in _get_task_description
    return _get_cached_task(task_id)
  File "/home/ketrong/miniconda3/envs/tpot2devenv/lib/python3.10/site-packages/openml/tasks/functions.py", line 74, in _get_cached_task
    raise OpenMLCacheException("Task file for tid %d not " "cached" % tid)
openml.exceptions.OpenMLCacheException: Task file for tid 725 not cached

During handling of the above exception, another exception occurred:

Traceback (most recent call last):
  File "/common/ketrong/AutoImputeExp/tpot2_imputetest/Impute_Experiments/utils.py", line 310, in loop_through_tasks
    X_train, y_train, X_test, y_test = load_task(base_save_folder=base_save_folder, exp=exp, type=type, levelstr=levelstr, task_id=taskid, preprocess=True)
  File "/common/ketrong/AutoImputeExp/tpot2_imputetest/Impute_Experiments/utils.py", line 200, in load_task
    task = openml.tasks.get_task(task_id)
  File "/home/ketrong/miniconda3/envs/tpot2devenv/lib/python3.10/site-packages/openml/tasks/functions.py", line 415, in get_task
    raise e
  File "/home/ketrong/miniconda3/envs/tpot2devenv/lib/python3.10/site-packages/openml/tasks/functions.py", line 398, in get_task
    task = _get_task_description(task_id)
  File "/home/ketrong/miniconda3/envs/tpot2devenv/lib/python3.10/site-packages/openml/tasks/functions.py", line 431, in _get_task_description
    task_xml = openml._api_calls._perform_api_call("task/%d" % task_id, "get")
  File "/home/ketrong/miniconda3/envs/tpot2devenv/lib/python3.10/site-packages/openml/_api_calls.py", line 99, in _perform_api_call
    response = __read_url(url, request_method, data)
  File "/home/ketrong/miniconda3/envs/tpot2devenv/lib/python3.10/site-packages/openml/_api_calls.py", line 308, in __read_url
    return _send_request(
  File "/home/ketrong/miniconda3/envs/tpot2devenv/lib/python3.10/site-packages/openml/_api_calls.py", line 344, in _send_request
    __check_response(response=response, url=url, file_elements=files)
  File "/home/ketrong/miniconda3/envs/tpot2devenv/lib/python3.10/site-packages/openml/_api_calls.py", line 409, in __check_response
    raise __parse_server_exception(response, url, file_elements=file_elements)
openml.exceptions.OpenMLServerException: https://www.openml.org/api/v1/xml/task/725 returned code 151: Unknown task - None

725
remove from investigation?
725
finished
working on 
logs/728/tpot2_base_normal_MNAR_0.3
1.4755163192749023
loading data
logs/728/tpot2_base_normal_MNAR_0.3/data/728_True.pkl
https://www.openml.org/api/v1/xml/task/728 returned code 151: Unknown task - None
Traceback (most recent call last):
  File "/home/ketrong/miniconda3/envs/tpot2devenv/lib/python3.10/site-packages/openml/tasks/functions.py", line 70, in _get_cached_task
    with io.open(os.path.join(tid_cache_dir, "task.xml"), encoding="utf8") as fh:
FileNotFoundError: [Errno 2] No such file or directory: '/home/ketrong/.cache/openml/org/openml/www/tasks/728/task.xml'

During handling of the above exception, another exception occurred:

Traceback (most recent call last):
  File "/home/ketrong/miniconda3/envs/tpot2devenv/lib/python3.10/site-packages/openml/tasks/functions.py", line 422, in _get_task_description
    return _get_cached_task(task_id)
  File "/home/ketrong/miniconda3/envs/tpot2devenv/lib/python3.10/site-packages/openml/tasks/functions.py", line 74, in _get_cached_task
    raise OpenMLCacheException("Task file for tid %d not " "cached" % tid)
openml.exceptions.OpenMLCacheException: Task file for tid 728 not cached

During handling of the above exception, another exception occurred:

Traceback (most recent call last):
  File "/common/ketrong/AutoImputeExp/tpot2_imputetest/Impute_Experiments/utils.py", line 310, in loop_through_tasks
    X_train, y_train, X_test, y_test = load_task(base_save_folder=base_save_folder, exp=exp, type=type, levelstr=levelstr, task_id=taskid, preprocess=True)
  File "/common/ketrong/AutoImputeExp/tpot2_imputetest/Impute_Experiments/utils.py", line 200, in load_task
    task = openml.tasks.get_task(task_id)
  File "/home/ketrong/miniconda3/envs/tpot2devenv/lib/python3.10/site-packages/openml/tasks/functions.py", line 415, in get_task
    raise e
  File "/home/ketrong/miniconda3/envs/tpot2devenv/lib/python3.10/site-packages/openml/tasks/functions.py", line 398, in get_task
    task = _get_task_description(task_id)
  File "/home/ketrong/miniconda3/envs/tpot2devenv/lib/python3.10/site-packages/openml/tasks/functions.py", line 431, in _get_task_description
    task_xml = openml._api_calls._perform_api_call("task/%d" % task_id, "get")
  File "/home/ketrong/miniconda3/envs/tpot2devenv/lib/python3.10/site-packages/openml/_api_calls.py", line 99, in _perform_api_call
    response = __read_url(url, request_method, data)
  File "/home/ketrong/miniconda3/envs/tpot2devenv/lib/python3.10/site-packages/openml/_api_calls.py", line 308, in __read_url
    return _send_request(
  File "/home/ketrong/miniconda3/envs/tpot2devenv/lib/python3.10/site-packages/openml/_api_calls.py", line 344, in _send_request
    __check_response(response=response, url=url, file_elements=files)
  File "/home/ketrong/miniconda3/envs/tpot2devenv/lib/python3.10/site-packages/openml/_api_calls.py", line 409, in __check_response
    raise __parse_server_exception(response, url, file_elements=file_elements)
openml.exceptions.OpenMLServerException: https://www.openml.org/api/v1/xml/task/728 returned code 151: Unknown task - None

728
remove from investigation?
working on 
logs/728/tpot2_base_imputation_MNAR_0.3
2.0543947219848633
loading data
logs/728/tpot2_base_imputation_MNAR_0.3/data/728_True.pkl
https://www.openml.org/api/v1/xml/task/728 returned code 151: Unknown task - None
Traceback (most recent call last):
  File "/home/ketrong/miniconda3/envs/tpot2devenv/lib/python3.10/site-packages/openml/tasks/functions.py", line 70, in _get_cached_task
    with io.open(os.path.join(tid_cache_dir, "task.xml"), encoding="utf8") as fh:
FileNotFoundError: [Errno 2] No such file or directory: '/home/ketrong/.cache/openml/org/openml/www/tasks/728/task.xml'

During handling of the above exception, another exception occurred:

Traceback (most recent call last):
  File "/home/ketrong/miniconda3/envs/tpot2devenv/lib/python3.10/site-packages/openml/tasks/functions.py", line 422, in _get_task_description
    return _get_cached_task(task_id)
  File "/home/ketrong/miniconda3/envs/tpot2devenv/lib/python3.10/site-packages/openml/tasks/functions.py", line 74, in _get_cached_task
    raise OpenMLCacheException("Task file for tid %d not " "cached" % tid)
openml.exceptions.OpenMLCacheException: Task file for tid 728 not cached

During handling of the above exception, another exception occurred:

Traceback (most recent call last):
  File "/common/ketrong/AutoImputeExp/tpot2_imputetest/Impute_Experiments/utils.py", line 310, in loop_through_tasks
    X_train, y_train, X_test, y_test = load_task(base_save_folder=base_save_folder, exp=exp, type=type, levelstr=levelstr, task_id=taskid, preprocess=True)
  File "/common/ketrong/AutoImputeExp/tpot2_imputetest/Impute_Experiments/utils.py", line 200, in load_task
    task = openml.tasks.get_task(task_id)
  File "/home/ketrong/miniconda3/envs/tpot2devenv/lib/python3.10/site-packages/openml/tasks/functions.py", line 415, in get_task
    raise e
  File "/home/ketrong/miniconda3/envs/tpot2devenv/lib/python3.10/site-packages/openml/tasks/functions.py", line 398, in get_task
    task = _get_task_description(task_id)
  File "/home/ketrong/miniconda3/envs/tpot2devenv/lib/python3.10/site-packages/openml/tasks/functions.py", line 431, in _get_task_description
    task_xml = openml._api_calls._perform_api_call("task/%d" % task_id, "get")
  File "/home/ketrong/miniconda3/envs/tpot2devenv/lib/python3.10/site-packages/openml/_api_calls.py", line 99, in _perform_api_call
    response = __read_url(url, request_method, data)
  File "/home/ketrong/miniconda3/envs/tpot2devenv/lib/python3.10/site-packages/openml/_api_calls.py", line 308, in __read_url
    return _send_request(
  File "/home/ketrong/miniconda3/envs/tpot2devenv/lib/python3.10/site-packages/openml/_api_calls.py", line 344, in _send_request
    __check_response(response=response, url=url, file_elements=files)
  File "/home/ketrong/miniconda3/envs/tpot2devenv/lib/python3.10/site-packages/openml/_api_calls.py", line 409, in __check_response
    raise __parse_server_exception(response, url, file_elements=file_elements)
openml.exceptions.OpenMLServerException: https://www.openml.org/api/v1/xml/task/728 returned code 151: Unknown task - None

728
remove from investigation?
728
finished
working on 
logs/737/tpot2_base_normal_MNAR_0.3
1.0464863777160645
loading data
logs/737/tpot2_base_normal_MNAR_0.3/data/737_True.pkl
https://www.openml.org/api/v1/xml/task/737 returned code 151: Unknown task - None
Traceback (most recent call last):
  File "/home/ketrong/miniconda3/envs/tpot2devenv/lib/python3.10/site-packages/openml/tasks/functions.py", line 70, in _get_cached_task
    with io.open(os.path.join(tid_cache_dir, "task.xml"), encoding="utf8") as fh:
FileNotFoundError: [Errno 2] No such file or directory: '/home/ketrong/.cache/openml/org/openml/www/tasks/737/task.xml'

During handling of the above exception, another exception occurred:

Traceback (most recent call last):
  File "/home/ketrong/miniconda3/envs/tpot2devenv/lib/python3.10/site-packages/openml/tasks/functions.py", line 422, in _get_task_description
    return _get_cached_task(task_id)
  File "/home/ketrong/miniconda3/envs/tpot2devenv/lib/python3.10/site-packages/openml/tasks/functions.py", line 74, in _get_cached_task
    raise OpenMLCacheException("Task file for tid %d not " "cached" % tid)
openml.exceptions.OpenMLCacheException: Task file for tid 737 not cached

During handling of the above exception, another exception occurred:

Traceback (most recent call last):
  File "/common/ketrong/AutoImputeExp/tpot2_imputetest/Impute_Experiments/utils.py", line 310, in loop_through_tasks
    X_train, y_train, X_test, y_test = load_task(base_save_folder=base_save_folder, exp=exp, type=type, levelstr=levelstr, task_id=taskid, preprocess=True)
  File "/common/ketrong/AutoImputeExp/tpot2_imputetest/Impute_Experiments/utils.py", line 200, in load_task
    task = openml.tasks.get_task(task_id)
  File "/home/ketrong/miniconda3/envs/tpot2devenv/lib/python3.10/site-packages/openml/tasks/functions.py", line 415, in get_task
    raise e
  File "/home/ketrong/miniconda3/envs/tpot2devenv/lib/python3.10/site-packages/openml/tasks/functions.py", line 398, in get_task
    task = _get_task_description(task_id)
  File "/home/ketrong/miniconda3/envs/tpot2devenv/lib/python3.10/site-packages/openml/tasks/functions.py", line 431, in _get_task_description
    task_xml = openml._api_calls._perform_api_call("task/%d" % task_id, "get")
  File "/home/ketrong/miniconda3/envs/tpot2devenv/lib/python3.10/site-packages/openml/_api_calls.py", line 99, in _perform_api_call
    response = __read_url(url, request_method, data)
  File "/home/ketrong/miniconda3/envs/tpot2devenv/lib/python3.10/site-packages/openml/_api_calls.py", line 308, in __read_url
    return _send_request(
  File "/home/ketrong/miniconda3/envs/tpot2devenv/lib/python3.10/site-packages/openml/_api_calls.py", line 344, in _send_request
    __check_response(response=response, url=url, file_elements=files)
  File "/home/ketrong/miniconda3/envs/tpot2devenv/lib/python3.10/site-packages/openml/_api_calls.py", line 409, in __check_response
    raise __parse_server_exception(response, url, file_elements=file_elements)
openml.exceptions.OpenMLServerException: https://www.openml.org/api/v1/xml/task/737 returned code 151: Unknown task - None

737
remove from investigation?
working on 
logs/737/tpot2_base_imputation_MNAR_0.3
0.5694973468780518
loading data
logs/737/tpot2_base_imputation_MNAR_0.3/data/737_True.pkl
https://www.openml.org/api/v1/xml/task/737 returned code 151: Unknown task - None
Traceback (most recent call last):
  File "/home/ketrong/miniconda3/envs/tpot2devenv/lib/python3.10/site-packages/openml/tasks/functions.py", line 70, in _get_cached_task
    with io.open(os.path.join(tid_cache_dir, "task.xml"), encoding="utf8") as fh:
FileNotFoundError: [Errno 2] No such file or directory: '/home/ketrong/.cache/openml/org/openml/www/tasks/737/task.xml'

During handling of the above exception, another exception occurred:

Traceback (most recent call last):
  File "/home/ketrong/miniconda3/envs/tpot2devenv/lib/python3.10/site-packages/openml/tasks/functions.py", line 422, in _get_task_description
    return _get_cached_task(task_id)
  File "/home/ketrong/miniconda3/envs/tpot2devenv/lib/python3.10/site-packages/openml/tasks/functions.py", line 74, in _get_cached_task
    raise OpenMLCacheException("Task file for tid %d not " "cached" % tid)
openml.exceptions.OpenMLCacheException: Task file for tid 737 not cached

During handling of the above exception, another exception occurred:

Traceback (most recent call last):
  File "/common/ketrong/AutoImputeExp/tpot2_imputetest/Impute_Experiments/utils.py", line 310, in loop_through_tasks
    X_train, y_train, X_test, y_test = load_task(base_save_folder=base_save_folder, exp=exp, type=type, levelstr=levelstr, task_id=taskid, preprocess=True)
  File "/common/ketrong/AutoImputeExp/tpot2_imputetest/Impute_Experiments/utils.py", line 200, in load_task
    task = openml.tasks.get_task(task_id)
  File "/home/ketrong/miniconda3/envs/tpot2devenv/lib/python3.10/site-packages/openml/tasks/functions.py", line 415, in get_task
    raise e
  File "/home/ketrong/miniconda3/envs/tpot2devenv/lib/python3.10/site-packages/openml/tasks/functions.py", line 398, in get_task
    task = _get_task_description(task_id)
  File "/home/ketrong/miniconda3/envs/tpot2devenv/lib/python3.10/site-packages/openml/tasks/functions.py", line 431, in _get_task_description
    task_xml = openml._api_calls._perform_api_call("task/%d" % task_id, "get")
  File "/home/ketrong/miniconda3/envs/tpot2devenv/lib/python3.10/site-packages/openml/_api_calls.py", line 99, in _perform_api_call
    response = __read_url(url, request_method, data)
  File "/home/ketrong/miniconda3/envs/tpot2devenv/lib/python3.10/site-packages/openml/_api_calls.py", line 308, in __read_url
    return _send_request(
  File "/home/ketrong/miniconda3/envs/tpot2devenv/lib/python3.10/site-packages/openml/_api_calls.py", line 344, in _send_request
    __check_response(response=response, url=url, file_elements=files)
  File "/home/ketrong/miniconda3/envs/tpot2devenv/lib/python3.10/site-packages/openml/_api_calls.py", line 409, in __check_response
    raise __parse_server_exception(response, url, file_elements=file_elements)
openml.exceptions.OpenMLServerException: https://www.openml.org/api/v1/xml/task/737 returned code 151: Unknown task - None

737
remove from investigation?
737
finished
working on 
logs/803/tpot2_base_normal_MNAR_0.3
2.4766287803649902
loading data
logs/803/tpot2_base_normal_MNAR_0.3/data/803_True.pkl
https://www.openml.org/api/v1/xml/task/803 returned code 151: Unknown task - None
Traceback (most recent call last):
  File "/home/ketrong/miniconda3/envs/tpot2devenv/lib/python3.10/site-packages/openml/tasks/functions.py", line 70, in _get_cached_task
    with io.open(os.path.join(tid_cache_dir, "task.xml"), encoding="utf8") as fh:
FileNotFoundError: [Errno 2] No such file or directory: '/home/ketrong/.cache/openml/org/openml/www/tasks/803/task.xml'

During handling of the above exception, another exception occurred:

Traceback (most recent call last):
  File "/home/ketrong/miniconda3/envs/tpot2devenv/lib/python3.10/site-packages/openml/tasks/functions.py", line 422, in _get_task_description
    return _get_cached_task(task_id)
  File "/home/ketrong/miniconda3/envs/tpot2devenv/lib/python3.10/site-packages/openml/tasks/functions.py", line 74, in _get_cached_task
    raise OpenMLCacheException("Task file for tid %d not " "cached" % tid)
openml.exceptions.OpenMLCacheException: Task file for tid 803 not cached

During handling of the above exception, another exception occurred:

Traceback (most recent call last):
  File "/common/ketrong/AutoImputeExp/tpot2_imputetest/Impute_Experiments/utils.py", line 310, in loop_through_tasks
    X_train, y_train, X_test, y_test = load_task(base_save_folder=base_save_folder, exp=exp, type=type, levelstr=levelstr, task_id=taskid, preprocess=True)
  File "/common/ketrong/AutoImputeExp/tpot2_imputetest/Impute_Experiments/utils.py", line 200, in load_task
    task = openml.tasks.get_task(task_id)
  File "/home/ketrong/miniconda3/envs/tpot2devenv/lib/python3.10/site-packages/openml/tasks/functions.py", line 415, in get_task
    raise e
  File "/home/ketrong/miniconda3/envs/tpot2devenv/lib/python3.10/site-packages/openml/tasks/functions.py", line 398, in get_task
    task = _get_task_description(task_id)
  File "/home/ketrong/miniconda3/envs/tpot2devenv/lib/python3.10/site-packages/openml/tasks/functions.py", line 431, in _get_task_description
    task_xml = openml._api_calls._perform_api_call("task/%d" % task_id, "get")
  File "/home/ketrong/miniconda3/envs/tpot2devenv/lib/python3.10/site-packages/openml/_api_calls.py", line 99, in _perform_api_call
    response = __read_url(url, request_method, data)
  File "/home/ketrong/miniconda3/envs/tpot2devenv/lib/python3.10/site-packages/openml/_api_calls.py", line 308, in __read_url
    return _send_request(
  File "/home/ketrong/miniconda3/envs/tpot2devenv/lib/python3.10/site-packages/openml/_api_calls.py", line 344, in _send_request
    __check_response(response=response, url=url, file_elements=files)
  File "/home/ketrong/miniconda3/envs/tpot2devenv/lib/python3.10/site-packages/openml/_api_calls.py", line 409, in __check_response
    raise __parse_server_exception(response, url, file_elements=file_elements)
openml.exceptions.OpenMLServerException: https://www.openml.org/api/v1/xml/task/803 returned code 151: Unknown task - None

803
remove from investigation?
working on 
logs/803/tpot2_base_imputation_MNAR_0.3
3.7319626808166504
loading data
logs/803/tpot2_base_imputation_MNAR_0.3/data/803_True.pkl
https://www.openml.org/api/v1/xml/task/803 returned code 151: Unknown task - None
Traceback (most recent call last):
  File "/home/ketrong/miniconda3/envs/tpot2devenv/lib/python3.10/site-packages/openml/tasks/functions.py", line 70, in _get_cached_task
    with io.open(os.path.join(tid_cache_dir, "task.xml"), encoding="utf8") as fh:
FileNotFoundError: [Errno 2] No such file or directory: '/home/ketrong/.cache/openml/org/openml/www/tasks/803/task.xml'

During handling of the above exception, another exception occurred:

Traceback (most recent call last):
  File "/home/ketrong/miniconda3/envs/tpot2devenv/lib/python3.10/site-packages/openml/tasks/functions.py", line 422, in _get_task_description
    return _get_cached_task(task_id)
  File "/home/ketrong/miniconda3/envs/tpot2devenv/lib/python3.10/site-packages/openml/tasks/functions.py", line 74, in _get_cached_task
    raise OpenMLCacheException("Task file for tid %d not " "cached" % tid)
openml.exceptions.OpenMLCacheException: Task file for tid 803 not cached

During handling of the above exception, another exception occurred:

Traceback (most recent call last):
  File "/common/ketrong/AutoImputeExp/tpot2_imputetest/Impute_Experiments/utils.py", line 310, in loop_through_tasks
    X_train, y_train, X_test, y_test = load_task(base_save_folder=base_save_folder, exp=exp, type=type, levelstr=levelstr, task_id=taskid, preprocess=True)
  File "/common/ketrong/AutoImputeExp/tpot2_imputetest/Impute_Experiments/utils.py", line 200, in load_task
    task = openml.tasks.get_task(task_id)
  File "/home/ketrong/miniconda3/envs/tpot2devenv/lib/python3.10/site-packages/openml/tasks/functions.py", line 415, in get_task
    raise e
  File "/home/ketrong/miniconda3/envs/tpot2devenv/lib/python3.10/site-packages/openml/tasks/functions.py", line 398, in get_task
    task = _get_task_description(task_id)
  File "/home/ketrong/miniconda3/envs/tpot2devenv/lib/python3.10/site-packages/openml/tasks/functions.py", line 431, in _get_task_description
    task_xml = openml._api_calls._perform_api_call("task/%d" % task_id, "get")
  File "/home/ketrong/miniconda3/envs/tpot2devenv/lib/python3.10/site-packages/openml/_api_calls.py", line 99, in _perform_api_call
    response = __read_url(url, request_method, data)
  File "/home/ketrong/miniconda3/envs/tpot2devenv/lib/python3.10/site-packages/openml/_api_calls.py", line 308, in __read_url
    return _send_request(
  File "/home/ketrong/miniconda3/envs/tpot2devenv/lib/python3.10/site-packages/openml/_api_calls.py", line 344, in _send_request
    __check_response(response=response, url=url, file_elements=files)
  File "/home/ketrong/miniconda3/envs/tpot2devenv/lib/python3.10/site-packages/openml/_api_calls.py", line 409, in __check_response
    raise __parse_server_exception(response, url, file_elements=file_elements)
openml.exceptions.OpenMLServerException: https://www.openml.org/api/v1/xml/task/803 returned code 151: Unknown task - None

803
remove from investigation?
803
finished
working on 
logs/823/tpot2_base_normal_MNAR_0.3
3.840791702270508
loading data
logs/823/tpot2_base_normal_MNAR_0.3/data/823_True.pkl
https://www.openml.org/api/v1/xml/task/823 returned code 151: Unknown task - None
Traceback (most recent call last):
  File "/home/ketrong/miniconda3/envs/tpot2devenv/lib/python3.10/site-packages/openml/tasks/functions.py", line 70, in _get_cached_task
    with io.open(os.path.join(tid_cache_dir, "task.xml"), encoding="utf8") as fh:
FileNotFoundError: [Errno 2] No such file or directory: '/home/ketrong/.cache/openml/org/openml/www/tasks/823/task.xml'

During handling of the above exception, another exception occurred:

Traceback (most recent call last):
  File "/home/ketrong/miniconda3/envs/tpot2devenv/lib/python3.10/site-packages/openml/tasks/functions.py", line 422, in _get_task_description
    return _get_cached_task(task_id)
  File "/home/ketrong/miniconda3/envs/tpot2devenv/lib/python3.10/site-packages/openml/tasks/functions.py", line 74, in _get_cached_task
    raise OpenMLCacheException("Task file for tid %d not " "cached" % tid)
openml.exceptions.OpenMLCacheException: Task file for tid 823 not cached

During handling of the above exception, another exception occurred:

Traceback (most recent call last):
  File "/common/ketrong/AutoImputeExp/tpot2_imputetest/Impute_Experiments/utils.py", line 310, in loop_through_tasks
    X_train, y_train, X_test, y_test = load_task(base_save_folder=base_save_folder, exp=exp, type=type, levelstr=levelstr, task_id=taskid, preprocess=True)
  File "/common/ketrong/AutoImputeExp/tpot2_imputetest/Impute_Experiments/utils.py", line 200, in load_task
    task = openml.tasks.get_task(task_id)
  File "/home/ketrong/miniconda3/envs/tpot2devenv/lib/python3.10/site-packages/openml/tasks/functions.py", line 415, in get_task
    raise e
  File "/home/ketrong/miniconda3/envs/tpot2devenv/lib/python3.10/site-packages/openml/tasks/functions.py", line 398, in get_task
    task = _get_task_description(task_id)
  File "/home/ketrong/miniconda3/envs/tpot2devenv/lib/python3.10/site-packages/openml/tasks/functions.py", line 431, in _get_task_description
    task_xml = openml._api_calls._perform_api_call("task/%d" % task_id, "get")
  File "/home/ketrong/miniconda3/envs/tpot2devenv/lib/python3.10/site-packages/openml/_api_calls.py", line 99, in _perform_api_call
    response = __read_url(url, request_method, data)
  File "/home/ketrong/miniconda3/envs/tpot2devenv/lib/python3.10/site-packages/openml/_api_calls.py", line 308, in __read_url
    return _send_request(
  File "/home/ketrong/miniconda3/envs/tpot2devenv/lib/python3.10/site-packages/openml/_api_calls.py", line 344, in _send_request
    __check_response(response=response, url=url, file_elements=files)
  File "/home/ketrong/miniconda3/envs/tpot2devenv/lib/python3.10/site-packages/openml/_api_calls.py", line 409, in __check_response
    raise __parse_server_exception(response, url, file_elements=file_elements)
openml.exceptions.OpenMLServerException: https://www.openml.org/api/v1/xml/task/823 returned code 151: Unknown task - None

823
remove from investigation?
working on 
logs/823/tpot2_base_imputation_MNAR_0.3
0.8456864356994629
loading data
logs/823/tpot2_base_imputation_MNAR_0.3/data/823_True.pkl
https://www.openml.org/api/v1/xml/task/823 returned code 151: Unknown task - None
Traceback (most recent call last):
  File "/home/ketrong/miniconda3/envs/tpot2devenv/lib/python3.10/site-packages/openml/tasks/functions.py", line 70, in _get_cached_task
    with io.open(os.path.join(tid_cache_dir, "task.xml"), encoding="utf8") as fh:
FileNotFoundError: [Errno 2] No such file or directory: '/home/ketrong/.cache/openml/org/openml/www/tasks/823/task.xml'

During handling of the above exception, another exception occurred:

Traceback (most recent call last):
  File "/home/ketrong/miniconda3/envs/tpot2devenv/lib/python3.10/site-packages/openml/tasks/functions.py", line 422, in _get_task_description
    return _get_cached_task(task_id)
  File "/home/ketrong/miniconda3/envs/tpot2devenv/lib/python3.10/site-packages/openml/tasks/functions.py", line 74, in _get_cached_task
    raise OpenMLCacheException("Task file for tid %d not " "cached" % tid)
openml.exceptions.OpenMLCacheException: Task file for tid 823 not cached

During handling of the above exception, another exception occurred:

Traceback (most recent call last):
  File "/common/ketrong/AutoImputeExp/tpot2_imputetest/Impute_Experiments/utils.py", line 310, in loop_through_tasks
    X_train, y_train, X_test, y_test = load_task(base_save_folder=base_save_folder, exp=exp, type=type, levelstr=levelstr, task_id=taskid, preprocess=True)
  File "/common/ketrong/AutoImputeExp/tpot2_imputetest/Impute_Experiments/utils.py", line 200, in load_task
    task = openml.tasks.get_task(task_id)
  File "/home/ketrong/miniconda3/envs/tpot2devenv/lib/python3.10/site-packages/openml/tasks/functions.py", line 415, in get_task
    raise e
  File "/home/ketrong/miniconda3/envs/tpot2devenv/lib/python3.10/site-packages/openml/tasks/functions.py", line 398, in get_task
    task = _get_task_description(task_id)
  File "/home/ketrong/miniconda3/envs/tpot2devenv/lib/python3.10/site-packages/openml/tasks/functions.py", line 431, in _get_task_description
    task_xml = openml._api_calls._perform_api_call("task/%d" % task_id, "get")
  File "/home/ketrong/miniconda3/envs/tpot2devenv/lib/python3.10/site-packages/openml/_api_calls.py", line 99, in _perform_api_call
    response = __read_url(url, request_method, data)
  File "/home/ketrong/miniconda3/envs/tpot2devenv/lib/python3.10/site-packages/openml/_api_calls.py", line 308, in __read_url
    return _send_request(
  File "/home/ketrong/miniconda3/envs/tpot2devenv/lib/python3.10/site-packages/openml/_api_calls.py", line 344, in _send_request
    __check_response(response=response, url=url, file_elements=files)
  File "/home/ketrong/miniconda3/envs/tpot2devenv/lib/python3.10/site-packages/openml/_api_calls.py", line 409, in __check_response
    raise __parse_server_exception(response, url, file_elements=file_elements)
openml.exceptions.OpenMLServerException: https://www.openml.org/api/v1/xml/task/823 returned code 151: Unknown task - None

823
remove from investigation?
823
finished
working on 
logs/847/tpot2_base_normal_MNAR_0.3
4.815667390823364
loading data
logs/847/tpot2_base_normal_MNAR_0.3/data/847_True.pkl
https://www.openml.org/api/v1/xml/task/847 returned code 151: Unknown task - None
Traceback (most recent call last):
  File "/home/ketrong/miniconda3/envs/tpot2devenv/lib/python3.10/site-packages/openml/tasks/functions.py", line 70, in _get_cached_task
    with io.open(os.path.join(tid_cache_dir, "task.xml"), encoding="utf8") as fh:
FileNotFoundError: [Errno 2] No such file or directory: '/home/ketrong/.cache/openml/org/openml/www/tasks/847/task.xml'

During handling of the above exception, another exception occurred:

Traceback (most recent call last):
  File "/home/ketrong/miniconda3/envs/tpot2devenv/lib/python3.10/site-packages/openml/tasks/functions.py", line 422, in _get_task_description
    return _get_cached_task(task_id)
  File "/home/ketrong/miniconda3/envs/tpot2devenv/lib/python3.10/site-packages/openml/tasks/functions.py", line 74, in _get_cached_task
    raise OpenMLCacheException("Task file for tid %d not " "cached" % tid)
openml.exceptions.OpenMLCacheException: Task file for tid 847 not cached

During handling of the above exception, another exception occurred:

Traceback (most recent call last):
  File "/common/ketrong/AutoImputeExp/tpot2_imputetest/Impute_Experiments/utils.py", line 310, in loop_through_tasks
    X_train, y_train, X_test, y_test = load_task(base_save_folder=base_save_folder, exp=exp, type=type, levelstr=levelstr, task_id=taskid, preprocess=True)
  File "/common/ketrong/AutoImputeExp/tpot2_imputetest/Impute_Experiments/utils.py", line 200, in load_task
    task = openml.tasks.get_task(task_id)
  File "/home/ketrong/miniconda3/envs/tpot2devenv/lib/python3.10/site-packages/openml/tasks/functions.py", line 415, in get_task
    raise e
  File "/home/ketrong/miniconda3/envs/tpot2devenv/lib/python3.10/site-packages/openml/tasks/functions.py", line 398, in get_task
    task = _get_task_description(task_id)
  File "/home/ketrong/miniconda3/envs/tpot2devenv/lib/python3.10/site-packages/openml/tasks/functions.py", line 431, in _get_task_description
    task_xml = openml._api_calls._perform_api_call("task/%d" % task_id, "get")
  File "/home/ketrong/miniconda3/envs/tpot2devenv/lib/python3.10/site-packages/openml/_api_calls.py", line 99, in _perform_api_call
    response = __read_url(url, request_method, data)
  File "/home/ketrong/miniconda3/envs/tpot2devenv/lib/python3.10/site-packages/openml/_api_calls.py", line 308, in __read_url
    return _send_request(
  File "/home/ketrong/miniconda3/envs/tpot2devenv/lib/python3.10/site-packages/openml/_api_calls.py", line 344, in _send_request
    __check_response(response=response, url=url, file_elements=files)
  File "/home/ketrong/miniconda3/envs/tpot2devenv/lib/python3.10/site-packages/openml/_api_calls.py", line 409, in __check_response
    raise __parse_server_exception(response, url, file_elements=file_elements)
openml.exceptions.OpenMLServerException: https://www.openml.org/api/v1/xml/task/847 returned code 151: Unknown task - None

847
remove from investigation?
working on 
logs/847/tpot2_base_imputation_MNAR_0.3
3.726822853088379
loading data
logs/847/tpot2_base_imputation_MNAR_0.3/data/847_True.pkl
https://www.openml.org/api/v1/xml/task/847 returned code 151: Unknown task - None
Traceback (most recent call last):
  File "/home/ketrong/miniconda3/envs/tpot2devenv/lib/python3.10/site-packages/openml/tasks/functions.py", line 70, in _get_cached_task
    with io.open(os.path.join(tid_cache_dir, "task.xml"), encoding="utf8") as fh:
FileNotFoundError: [Errno 2] No such file or directory: '/home/ketrong/.cache/openml/org/openml/www/tasks/847/task.xml'

During handling of the above exception, another exception occurred:

Traceback (most recent call last):
  File "/home/ketrong/miniconda3/envs/tpot2devenv/lib/python3.10/site-packages/openml/tasks/functions.py", line 422, in _get_task_description
    return _get_cached_task(task_id)
  File "/home/ketrong/miniconda3/envs/tpot2devenv/lib/python3.10/site-packages/openml/tasks/functions.py", line 74, in _get_cached_task
    raise OpenMLCacheException("Task file for tid %d not " "cached" % tid)
openml.exceptions.OpenMLCacheException: Task file for tid 847 not cached

During handling of the above exception, another exception occurred:

Traceback (most recent call last):
  File "/common/ketrong/AutoImputeExp/tpot2_imputetest/Impute_Experiments/utils.py", line 310, in loop_through_tasks
    X_train, y_train, X_test, y_test = load_task(base_save_folder=base_save_folder, exp=exp, type=type, levelstr=levelstr, task_id=taskid, preprocess=True)
  File "/common/ketrong/AutoImputeExp/tpot2_imputetest/Impute_Experiments/utils.py", line 200, in load_task
    task = openml.tasks.get_task(task_id)
  File "/home/ketrong/miniconda3/envs/tpot2devenv/lib/python3.10/site-packages/openml/tasks/functions.py", line 415, in get_task
    raise e
  File "/home/ketrong/miniconda3/envs/tpot2devenv/lib/python3.10/site-packages/openml/tasks/functions.py", line 398, in get_task
    task = _get_task_description(task_id)
  File "/home/ketrong/miniconda3/envs/tpot2devenv/lib/python3.10/site-packages/openml/tasks/functions.py", line 431, in _get_task_description
    task_xml = openml._api_calls._perform_api_call("task/%d" % task_id, "get")
  File "/home/ketrong/miniconda3/envs/tpot2devenv/lib/python3.10/site-packages/openml/_api_calls.py", line 99, in _perform_api_call
    response = __read_url(url, request_method, data)
  File "/home/ketrong/miniconda3/envs/tpot2devenv/lib/python3.10/site-packages/openml/_api_calls.py", line 308, in __read_url
    return _send_request(
  File "/home/ketrong/miniconda3/envs/tpot2devenv/lib/python3.10/site-packages/openml/_api_calls.py", line 344, in _send_request
    __check_response(response=response, url=url, file_elements=files)
  File "/home/ketrong/miniconda3/envs/tpot2devenv/lib/python3.10/site-packages/openml/_api_calls.py", line 409, in __check_response
    raise __parse_server_exception(response, url, file_elements=file_elements)
openml.exceptions.OpenMLServerException: https://www.openml.org/api/v1/xml/task/847 returned code 151: Unknown task - None

847
remove from investigation?
847
finished
working on 
logs/871/tpot2_base_normal_MNAR_0.3
4.7959065437316895
loading data
logs/871/tpot2_base_normal_MNAR_0.3/data/871_True.pkl
https://www.openml.org/api/v1/xml/task/871 returned code 151: Unknown task - None
Traceback (most recent call last):
  File "/home/ketrong/miniconda3/envs/tpot2devenv/lib/python3.10/site-packages/openml/tasks/functions.py", line 70, in _get_cached_task
    with io.open(os.path.join(tid_cache_dir, "task.xml"), encoding="utf8") as fh:
FileNotFoundError: [Errno 2] No such file or directory: '/home/ketrong/.cache/openml/org/openml/www/tasks/871/task.xml'

During handling of the above exception, another exception occurred:

Traceback (most recent call last):
  File "/home/ketrong/miniconda3/envs/tpot2devenv/lib/python3.10/site-packages/openml/tasks/functions.py", line 422, in _get_task_description
    return _get_cached_task(task_id)
  File "/home/ketrong/miniconda3/envs/tpot2devenv/lib/python3.10/site-packages/openml/tasks/functions.py", line 74, in _get_cached_task
    raise OpenMLCacheException("Task file for tid %d not " "cached" % tid)
openml.exceptions.OpenMLCacheException: Task file for tid 871 not cached

During handling of the above exception, another exception occurred:

Traceback (most recent call last):
  File "/common/ketrong/AutoImputeExp/tpot2_imputetest/Impute_Experiments/utils.py", line 310, in loop_through_tasks
    X_train, y_train, X_test, y_test = load_task(base_save_folder=base_save_folder, exp=exp, type=type, levelstr=levelstr, task_id=taskid, preprocess=True)
  File "/common/ketrong/AutoImputeExp/tpot2_imputetest/Impute_Experiments/utils.py", line 200, in load_task
    task = openml.tasks.get_task(task_id)
  File "/home/ketrong/miniconda3/envs/tpot2devenv/lib/python3.10/site-packages/openml/tasks/functions.py", line 415, in get_task
    raise e
  File "/home/ketrong/miniconda3/envs/tpot2devenv/lib/python3.10/site-packages/openml/tasks/functions.py", line 398, in get_task
    task = _get_task_description(task_id)
  File "/home/ketrong/miniconda3/envs/tpot2devenv/lib/python3.10/site-packages/openml/tasks/functions.py", line 431, in _get_task_description
    task_xml = openml._api_calls._perform_api_call("task/%d" % task_id, "get")
  File "/home/ketrong/miniconda3/envs/tpot2devenv/lib/python3.10/site-packages/openml/_api_calls.py", line 99, in _perform_api_call
    response = __read_url(url, request_method, data)
  File "/home/ketrong/miniconda3/envs/tpot2devenv/lib/python3.10/site-packages/openml/_api_calls.py", line 308, in __read_url
    return _send_request(
  File "/home/ketrong/miniconda3/envs/tpot2devenv/lib/python3.10/site-packages/openml/_api_calls.py", line 344, in _send_request
    __check_response(response=response, url=url, file_elements=files)
  File "/home/ketrong/miniconda3/envs/tpot2devenv/lib/python3.10/site-packages/openml/_api_calls.py", line 409, in __check_response
    raise __parse_server_exception(response, url, file_elements=file_elements)
openml.exceptions.OpenMLServerException: https://www.openml.org/api/v1/xml/task/871 returned code 151: Unknown task - None

871
remove from investigation?
working on 
logs/871/tpot2_base_imputation_MNAR_0.3
1.3113205432891846
loading data
logs/871/tpot2_base_imputation_MNAR_0.3/data/871_True.pkl
https://www.openml.org/api/v1/xml/task/871 returned code 151: Unknown task - None
Traceback (most recent call last):
  File "/home/ketrong/miniconda3/envs/tpot2devenv/lib/python3.10/site-packages/openml/tasks/functions.py", line 70, in _get_cached_task
    with io.open(os.path.join(tid_cache_dir, "task.xml"), encoding="utf8") as fh:
FileNotFoundError: [Errno 2] No such file or directory: '/home/ketrong/.cache/openml/org/openml/www/tasks/871/task.xml'

During handling of the above exception, another exception occurred:

Traceback (most recent call last):
  File "/home/ketrong/miniconda3/envs/tpot2devenv/lib/python3.10/site-packages/openml/tasks/functions.py", line 422, in _get_task_description
    return _get_cached_task(task_id)
  File "/home/ketrong/miniconda3/envs/tpot2devenv/lib/python3.10/site-packages/openml/tasks/functions.py", line 74, in _get_cached_task
    raise OpenMLCacheException("Task file for tid %d not " "cached" % tid)
openml.exceptions.OpenMLCacheException: Task file for tid 871 not cached

During handling of the above exception, another exception occurred:

Traceback (most recent call last):
  File "/common/ketrong/AutoImputeExp/tpot2_imputetest/Impute_Experiments/utils.py", line 310, in loop_through_tasks
    X_train, y_train, X_test, y_test = load_task(base_save_folder=base_save_folder, exp=exp, type=type, levelstr=levelstr, task_id=taskid, preprocess=True)
  File "/common/ketrong/AutoImputeExp/tpot2_imputetest/Impute_Experiments/utils.py", line 200, in load_task
    task = openml.tasks.get_task(task_id)
  File "/home/ketrong/miniconda3/envs/tpot2devenv/lib/python3.10/site-packages/openml/tasks/functions.py", line 415, in get_task
    raise e
  File "/home/ketrong/miniconda3/envs/tpot2devenv/lib/python3.10/site-packages/openml/tasks/functions.py", line 398, in get_task
    task = _get_task_description(task_id)
  File "/home/ketrong/miniconda3/envs/tpot2devenv/lib/python3.10/site-packages/openml/tasks/functions.py", line 431, in _get_task_description
    task_xml = openml._api_calls._perform_api_call("task/%d" % task_id, "get")
  File "/home/ketrong/miniconda3/envs/tpot2devenv/lib/python3.10/site-packages/openml/_api_calls.py", line 99, in _perform_api_call
    response = __read_url(url, request_method, data)
  File "/home/ketrong/miniconda3/envs/tpot2devenv/lib/python3.10/site-packages/openml/_api_calls.py", line 308, in __read_url
    return _send_request(
  File "/home/ketrong/miniconda3/envs/tpot2devenv/lib/python3.10/site-packages/openml/_api_calls.py", line 344, in _send_request
    __check_response(response=response, url=url, file_elements=files)
  File "/home/ketrong/miniconda3/envs/tpot2devenv/lib/python3.10/site-packages/openml/_api_calls.py", line 409, in __check_response
    raise __parse_server_exception(response, url, file_elements=file_elements)
openml.exceptions.OpenMLServerException: https://www.openml.org/api/v1/xml/task/871 returned code 151: Unknown task - None

871
remove from investigation?
871
finished
working on 
logs/881/tpot2_base_normal_MNAR_0.3
1.4660580158233643
loading data
logs/881/tpot2_base_normal_MNAR_0.3/data/881_True.pkl
https://www.openml.org/api/v1/xml/task/881 returned code 151: Unknown task - None
Traceback (most recent call last):
  File "/home/ketrong/miniconda3/envs/tpot2devenv/lib/python3.10/site-packages/openml/tasks/functions.py", line 70, in _get_cached_task
    with io.open(os.path.join(tid_cache_dir, "task.xml"), encoding="utf8") as fh:
FileNotFoundError: [Errno 2] No such file or directory: '/home/ketrong/.cache/openml/org/openml/www/tasks/881/task.xml'

During handling of the above exception, another exception occurred:

Traceback (most recent call last):
  File "/home/ketrong/miniconda3/envs/tpot2devenv/lib/python3.10/site-packages/openml/tasks/functions.py", line 422, in _get_task_description
    return _get_cached_task(task_id)
  File "/home/ketrong/miniconda3/envs/tpot2devenv/lib/python3.10/site-packages/openml/tasks/functions.py", line 74, in _get_cached_task
    raise OpenMLCacheException("Task file for tid %d not " "cached" % tid)
openml.exceptions.OpenMLCacheException: Task file for tid 881 not cached

During handling of the above exception, another exception occurred:

Traceback (most recent call last):
  File "/common/ketrong/AutoImputeExp/tpot2_imputetest/Impute_Experiments/utils.py", line 310, in loop_through_tasks
    X_train, y_train, X_test, y_test = load_task(base_save_folder=base_save_folder, exp=exp, type=type, levelstr=levelstr, task_id=taskid, preprocess=True)
  File "/common/ketrong/AutoImputeExp/tpot2_imputetest/Impute_Experiments/utils.py", line 200, in load_task
    task = openml.tasks.get_task(task_id)
  File "/home/ketrong/miniconda3/envs/tpot2devenv/lib/python3.10/site-packages/openml/tasks/functions.py", line 415, in get_task
    raise e
  File "/home/ketrong/miniconda3/envs/tpot2devenv/lib/python3.10/site-packages/openml/tasks/functions.py", line 398, in get_task
    task = _get_task_description(task_id)
  File "/home/ketrong/miniconda3/envs/tpot2devenv/lib/python3.10/site-packages/openml/tasks/functions.py", line 431, in _get_task_description
    task_xml = openml._api_calls._perform_api_call("task/%d" % task_id, "get")
  File "/home/ketrong/miniconda3/envs/tpot2devenv/lib/python3.10/site-packages/openml/_api_calls.py", line 99, in _perform_api_call
    response = __read_url(url, request_method, data)
  File "/home/ketrong/miniconda3/envs/tpot2devenv/lib/python3.10/site-packages/openml/_api_calls.py", line 308, in __read_url
    return _send_request(
  File "/home/ketrong/miniconda3/envs/tpot2devenv/lib/python3.10/site-packages/openml/_api_calls.py", line 344, in _send_request
    __check_response(response=response, url=url, file_elements=files)
  File "/home/ketrong/miniconda3/envs/tpot2devenv/lib/python3.10/site-packages/openml/_api_calls.py", line 409, in __check_response
    raise __parse_server_exception(response, url, file_elements=file_elements)
openml.exceptions.OpenMLServerException: https://www.openml.org/api/v1/xml/task/881 returned code 151: Unknown task - None

881
remove from investigation?
working on 
logs/881/tpot2_base_imputation_MNAR_0.3
1.1577987670898438
loading data
logs/881/tpot2_base_imputation_MNAR_0.3/data/881_True.pkl
https://www.openml.org/api/v1/xml/task/881 returned code 151: Unknown task - None
Traceback (most recent call last):
  File "/home/ketrong/miniconda3/envs/tpot2devenv/lib/python3.10/site-packages/openml/tasks/functions.py", line 70, in _get_cached_task
    with io.open(os.path.join(tid_cache_dir, "task.xml"), encoding="utf8") as fh:
FileNotFoundError: [Errno 2] No such file or directory: '/home/ketrong/.cache/openml/org/openml/www/tasks/881/task.xml'

During handling of the above exception, another exception occurred:

Traceback (most recent call last):
  File "/home/ketrong/miniconda3/envs/tpot2devenv/lib/python3.10/site-packages/openml/tasks/functions.py", line 422, in _get_task_description
    return _get_cached_task(task_id)
  File "/home/ketrong/miniconda3/envs/tpot2devenv/lib/python3.10/site-packages/openml/tasks/functions.py", line 74, in _get_cached_task
    raise OpenMLCacheException("Task file for tid %d not " "cached" % tid)
openml.exceptions.OpenMLCacheException: Task file for tid 881 not cached

During handling of the above exception, another exception occurred:

Traceback (most recent call last):
  File "/common/ketrong/AutoImputeExp/tpot2_imputetest/Impute_Experiments/utils.py", line 310, in loop_through_tasks
    X_train, y_train, X_test, y_test = load_task(base_save_folder=base_save_folder, exp=exp, type=type, levelstr=levelstr, task_id=taskid, preprocess=True)
  File "/common/ketrong/AutoImputeExp/tpot2_imputetest/Impute_Experiments/utils.py", line 200, in load_task
    task = openml.tasks.get_task(task_id)
  File "/home/ketrong/miniconda3/envs/tpot2devenv/lib/python3.10/site-packages/openml/tasks/functions.py", line 415, in get_task
    raise e
  File "/home/ketrong/miniconda3/envs/tpot2devenv/lib/python3.10/site-packages/openml/tasks/functions.py", line 398, in get_task
    task = _get_task_description(task_id)
  File "/home/ketrong/miniconda3/envs/tpot2devenv/lib/python3.10/site-packages/openml/tasks/functions.py", line 431, in _get_task_description
    task_xml = openml._api_calls._perform_api_call("task/%d" % task_id, "get")
  File "/home/ketrong/miniconda3/envs/tpot2devenv/lib/python3.10/site-packages/openml/_api_calls.py", line 99, in _perform_api_call
    response = __read_url(url, request_method, data)
  File "/home/ketrong/miniconda3/envs/tpot2devenv/lib/python3.10/site-packages/openml/_api_calls.py", line 308, in __read_url
    return _send_request(
  File "/home/ketrong/miniconda3/envs/tpot2devenv/lib/python3.10/site-packages/openml/_api_calls.py", line 344, in _send_request
    __check_response(response=response, url=url, file_elements=files)
  File "/home/ketrong/miniconda3/envs/tpot2devenv/lib/python3.10/site-packages/openml/_api_calls.py", line 409, in __check_response
    raise __parse_server_exception(response, url, file_elements=file_elements)
openml.exceptions.OpenMLServerException: https://www.openml.org/api/v1/xml/task/881 returned code 151: Unknown task - None

881
remove from investigation?
881
finished
working on 
logs/901/tpot2_base_normal_MNAR_0.3
2.0064611434936523
loading data
logs/901/tpot2_base_normal_MNAR_0.3/data/901_True.pkl
https://www.openml.org/api/v1/xml/task/901 returned code 151: Unknown task - None
Traceback (most recent call last):
  File "/home/ketrong/miniconda3/envs/tpot2devenv/lib/python3.10/site-packages/openml/tasks/functions.py", line 70, in _get_cached_task
    with io.open(os.path.join(tid_cache_dir, "task.xml"), encoding="utf8") as fh:
FileNotFoundError: [Errno 2] No such file or directory: '/home/ketrong/.cache/openml/org/openml/www/tasks/901/task.xml'

During handling of the above exception, another exception occurred:

Traceback (most recent call last):
  File "/home/ketrong/miniconda3/envs/tpot2devenv/lib/python3.10/site-packages/openml/tasks/functions.py", line 422, in _get_task_description
    return _get_cached_task(task_id)
  File "/home/ketrong/miniconda3/envs/tpot2devenv/lib/python3.10/site-packages/openml/tasks/functions.py", line 74, in _get_cached_task
    raise OpenMLCacheException("Task file for tid %d not " "cached" % tid)
openml.exceptions.OpenMLCacheException: Task file for tid 901 not cached

During handling of the above exception, another exception occurred:

Traceback (most recent call last):
  File "/common/ketrong/AutoImputeExp/tpot2_imputetest/Impute_Experiments/utils.py", line 310, in loop_through_tasks
    X_train, y_train, X_test, y_test = load_task(base_save_folder=base_save_folder, exp=exp, type=type, levelstr=levelstr, task_id=taskid, preprocess=True)
  File "/common/ketrong/AutoImputeExp/tpot2_imputetest/Impute_Experiments/utils.py", line 200, in load_task
    task = openml.tasks.get_task(task_id)
  File "/home/ketrong/miniconda3/envs/tpot2devenv/lib/python3.10/site-packages/openml/tasks/functions.py", line 415, in get_task
    raise e
  File "/home/ketrong/miniconda3/envs/tpot2devenv/lib/python3.10/site-packages/openml/tasks/functions.py", line 398, in get_task
    task = _get_task_description(task_id)
  File "/home/ketrong/miniconda3/envs/tpot2devenv/lib/python3.10/site-packages/openml/tasks/functions.py", line 431, in _get_task_description
    task_xml = openml._api_calls._perform_api_call("task/%d" % task_id, "get")
  File "/home/ketrong/miniconda3/envs/tpot2devenv/lib/python3.10/site-packages/openml/_api_calls.py", line 99, in _perform_api_call
    response = __read_url(url, request_method, data)
  File "/home/ketrong/miniconda3/envs/tpot2devenv/lib/python3.10/site-packages/openml/_api_calls.py", line 308, in __read_url
    return _send_request(
  File "/home/ketrong/miniconda3/envs/tpot2devenv/lib/python3.10/site-packages/openml/_api_calls.py", line 344, in _send_request
    __check_response(response=response, url=url, file_elements=files)
  File "/home/ketrong/miniconda3/envs/tpot2devenv/lib/python3.10/site-packages/openml/_api_calls.py", line 409, in __check_response
    raise __parse_server_exception(response, url, file_elements=file_elements)
openml.exceptions.OpenMLServerException: https://www.openml.org/api/v1/xml/task/901 returned code 151: Unknown task - None

901
remove from investigation?
working on 
logs/901/tpot2_base_imputation_MNAR_0.3
0.7673556804656982
loading data
logs/901/tpot2_base_imputation_MNAR_0.3/data/901_True.pkl
https://www.openml.org/api/v1/xml/task/901 returned code 151: Unknown task - None
Traceback (most recent call last):
  File "/home/ketrong/miniconda3/envs/tpot2devenv/lib/python3.10/site-packages/openml/tasks/functions.py", line 70, in _get_cached_task
    with io.open(os.path.join(tid_cache_dir, "task.xml"), encoding="utf8") as fh:
FileNotFoundError: [Errno 2] No such file or directory: '/home/ketrong/.cache/openml/org/openml/www/tasks/901/task.xml'

During handling of the above exception, another exception occurred:

Traceback (most recent call last):
  File "/home/ketrong/miniconda3/envs/tpot2devenv/lib/python3.10/site-packages/openml/tasks/functions.py", line 422, in _get_task_description
    return _get_cached_task(task_id)
  File "/home/ketrong/miniconda3/envs/tpot2devenv/lib/python3.10/site-packages/openml/tasks/functions.py", line 74, in _get_cached_task
    raise OpenMLCacheException("Task file for tid %d not " "cached" % tid)
openml.exceptions.OpenMLCacheException: Task file for tid 901 not cached

During handling of the above exception, another exception occurred:

Traceback (most recent call last):
  File "/common/ketrong/AutoImputeExp/tpot2_imputetest/Impute_Experiments/utils.py", line 310, in loop_through_tasks
    X_train, y_train, X_test, y_test = load_task(base_save_folder=base_save_folder, exp=exp, type=type, levelstr=levelstr, task_id=taskid, preprocess=True)
  File "/common/ketrong/AutoImputeExp/tpot2_imputetest/Impute_Experiments/utils.py", line 200, in load_task
    task = openml.tasks.get_task(task_id)
  File "/home/ketrong/miniconda3/envs/tpot2devenv/lib/python3.10/site-packages/openml/tasks/functions.py", line 415, in get_task
    raise e
  File "/home/ketrong/miniconda3/envs/tpot2devenv/lib/python3.10/site-packages/openml/tasks/functions.py", line 398, in get_task
    task = _get_task_description(task_id)
  File "/home/ketrong/miniconda3/envs/tpot2devenv/lib/python3.10/site-packages/openml/tasks/functions.py", line 431, in _get_task_description
    task_xml = openml._api_calls._perform_api_call("task/%d" % task_id, "get")
  File "/home/ketrong/miniconda3/envs/tpot2devenv/lib/python3.10/site-packages/openml/_api_calls.py", line 99, in _perform_api_call
    response = __read_url(url, request_method, data)
  File "/home/ketrong/miniconda3/envs/tpot2devenv/lib/python3.10/site-packages/openml/_api_calls.py", line 308, in __read_url
    return _send_request(
  File "/home/ketrong/miniconda3/envs/tpot2devenv/lib/python3.10/site-packages/openml/_api_calls.py", line 344, in _send_request
    __check_response(response=response, url=url, file_elements=files)
  File "/home/ketrong/miniconda3/envs/tpot2devenv/lib/python3.10/site-packages/openml/_api_calls.py", line 409, in __check_response
    raise __parse_server_exception(response, url, file_elements=file_elements)
openml.exceptions.OpenMLServerException: https://www.openml.org/api/v1/xml/task/901 returned code 151: Unknown task - None

901
remove from investigation?
901
finished
working on 
logs/923/tpot2_base_normal_MNAR_0.3
0.34522128105163574
loading data
logs/923/tpot2_base_normal_MNAR_0.3/data/923_True.pkl
https://www.openml.org/api/v1/xml/task/923 returned code 151: Unknown task - None
Traceback (most recent call last):
  File "/home/ketrong/miniconda3/envs/tpot2devenv/lib/python3.10/site-packages/openml/tasks/functions.py", line 70, in _get_cached_task
    with io.open(os.path.join(tid_cache_dir, "task.xml"), encoding="utf8") as fh:
FileNotFoundError: [Errno 2] No such file or directory: '/home/ketrong/.cache/openml/org/openml/www/tasks/923/task.xml'

During handling of the above exception, another exception occurred:

Traceback (most recent call last):
  File "/home/ketrong/miniconda3/envs/tpot2devenv/lib/python3.10/site-packages/openml/tasks/functions.py", line 422, in _get_task_description
    return _get_cached_task(task_id)
  File "/home/ketrong/miniconda3/envs/tpot2devenv/lib/python3.10/site-packages/openml/tasks/functions.py", line 74, in _get_cached_task
    raise OpenMLCacheException("Task file for tid %d not " "cached" % tid)
openml.exceptions.OpenMLCacheException: Task file for tid 923 not cached

During handling of the above exception, another exception occurred:

Traceback (most recent call last):
  File "/common/ketrong/AutoImputeExp/tpot2_imputetest/Impute_Experiments/utils.py", line 310, in loop_through_tasks
    X_train, y_train, X_test, y_test = load_task(base_save_folder=base_save_folder, exp=exp, type=type, levelstr=levelstr, task_id=taskid, preprocess=True)
  File "/common/ketrong/AutoImputeExp/tpot2_imputetest/Impute_Experiments/utils.py", line 200, in load_task
    task = openml.tasks.get_task(task_id)
  File "/home/ketrong/miniconda3/envs/tpot2devenv/lib/python3.10/site-packages/openml/tasks/functions.py", line 415, in get_task
    raise e
  File "/home/ketrong/miniconda3/envs/tpot2devenv/lib/python3.10/site-packages/openml/tasks/functions.py", line 398, in get_task
    task = _get_task_description(task_id)
  File "/home/ketrong/miniconda3/envs/tpot2devenv/lib/python3.10/site-packages/openml/tasks/functions.py", line 431, in _get_task_description
    task_xml = openml._api_calls._perform_api_call("task/%d" % task_id, "get")
  File "/home/ketrong/miniconda3/envs/tpot2devenv/lib/python3.10/site-packages/openml/_api_calls.py", line 99, in _perform_api_call
    response = __read_url(url, request_method, data)
  File "/home/ketrong/miniconda3/envs/tpot2devenv/lib/python3.10/site-packages/openml/_api_calls.py", line 308, in __read_url
    return _send_request(
  File "/home/ketrong/miniconda3/envs/tpot2devenv/lib/python3.10/site-packages/openml/_api_calls.py", line 344, in _send_request
    __check_response(response=response, url=url, file_elements=files)
  File "/home/ketrong/miniconda3/envs/tpot2devenv/lib/python3.10/site-packages/openml/_api_calls.py", line 409, in __check_response
    raise __parse_server_exception(response, url, file_elements=file_elements)
openml.exceptions.OpenMLServerException: https://www.openml.org/api/v1/xml/task/923 returned code 151: Unknown task - None

923
remove from investigation?
working on 
logs/923/tpot2_base_imputation_MNAR_0.3
3.0235581398010254
loading data
logs/923/tpot2_base_imputation_MNAR_0.3/data/923_True.pkl
https://www.openml.org/api/v1/xml/task/923 returned code 151: Unknown task - None
Traceback (most recent call last):
  File "/home/ketrong/miniconda3/envs/tpot2devenv/lib/python3.10/site-packages/openml/tasks/functions.py", line 70, in _get_cached_task
    with io.open(os.path.join(tid_cache_dir, "task.xml"), encoding="utf8") as fh:
FileNotFoundError: [Errno 2] No such file or directory: '/home/ketrong/.cache/openml/org/openml/www/tasks/923/task.xml'

During handling of the above exception, another exception occurred:

Traceback (most recent call last):
  File "/home/ketrong/miniconda3/envs/tpot2devenv/lib/python3.10/site-packages/openml/tasks/functions.py", line 422, in _get_task_description
    return _get_cached_task(task_id)
  File "/home/ketrong/miniconda3/envs/tpot2devenv/lib/python3.10/site-packages/openml/tasks/functions.py", line 74, in _get_cached_task
    raise OpenMLCacheException("Task file for tid %d not " "cached" % tid)
openml.exceptions.OpenMLCacheException: Task file for tid 923 not cached

During handling of the above exception, another exception occurred:

Traceback (most recent call last):
  File "/common/ketrong/AutoImputeExp/tpot2_imputetest/Impute_Experiments/utils.py", line 310, in loop_through_tasks
    X_train, y_train, X_test, y_test = load_task(base_save_folder=base_save_folder, exp=exp, type=type, levelstr=levelstr, task_id=taskid, preprocess=True)
  File "/common/ketrong/AutoImputeExp/tpot2_imputetest/Impute_Experiments/utils.py", line 200, in load_task
    task = openml.tasks.get_task(task_id)
  File "/home/ketrong/miniconda3/envs/tpot2devenv/lib/python3.10/site-packages/openml/tasks/functions.py", line 415, in get_task
    raise e
  File "/home/ketrong/miniconda3/envs/tpot2devenv/lib/python3.10/site-packages/openml/tasks/functions.py", line 398, in get_task
    task = _get_task_description(task_id)
  File "/home/ketrong/miniconda3/envs/tpot2devenv/lib/python3.10/site-packages/openml/tasks/functions.py", line 431, in _get_task_description
    task_xml = openml._api_calls._perform_api_call("task/%d" % task_id, "get")
  File "/home/ketrong/miniconda3/envs/tpot2devenv/lib/python3.10/site-packages/openml/_api_calls.py", line 99, in _perform_api_call
    response = __read_url(url, request_method, data)
  File "/home/ketrong/miniconda3/envs/tpot2devenv/lib/python3.10/site-packages/openml/_api_calls.py", line 308, in __read_url
    return _send_request(
  File "/home/ketrong/miniconda3/envs/tpot2devenv/lib/python3.10/site-packages/openml/_api_calls.py", line 344, in _send_request
    __check_response(response=response, url=url, file_elements=files)
  File "/home/ketrong/miniconda3/envs/tpot2devenv/lib/python3.10/site-packages/openml/_api_calls.py", line 409, in __check_response
    raise __parse_server_exception(response, url, file_elements=file_elements)
openml.exceptions.OpenMLServerException: https://www.openml.org/api/v1/xml/task/923 returned code 151: Unknown task - None

923
remove from investigation?
923
finished
working on 
logs/1046/tpot2_base_normal_MNAR_0.3
3.4788849353790283
loading data
logs/1046/tpot2_base_normal_MNAR_0.3/data/1046_True.pkl
https://www.openml.org/api/v1/xml/task/1046 returned code 151: Unknown task - None
Traceback (most recent call last):
  File "/home/ketrong/miniconda3/envs/tpot2devenv/lib/python3.10/site-packages/openml/tasks/functions.py", line 70, in _get_cached_task
    with io.open(os.path.join(tid_cache_dir, "task.xml"), encoding="utf8") as fh:
FileNotFoundError: [Errno 2] No such file or directory: '/home/ketrong/.cache/openml/org/openml/www/tasks/1046/task.xml'

During handling of the above exception, another exception occurred:

Traceback (most recent call last):
  File "/home/ketrong/miniconda3/envs/tpot2devenv/lib/python3.10/site-packages/openml/tasks/functions.py", line 422, in _get_task_description
    return _get_cached_task(task_id)
  File "/home/ketrong/miniconda3/envs/tpot2devenv/lib/python3.10/site-packages/openml/tasks/functions.py", line 74, in _get_cached_task
    raise OpenMLCacheException("Task file for tid %d not " "cached" % tid)
openml.exceptions.OpenMLCacheException: Task file for tid 1046 not cached

During handling of the above exception, another exception occurred:

Traceback (most recent call last):
  File "/common/ketrong/AutoImputeExp/tpot2_imputetest/Impute_Experiments/utils.py", line 310, in loop_through_tasks
    X_train, y_train, X_test, y_test = load_task(base_save_folder=base_save_folder, exp=exp, type=type, levelstr=levelstr, task_id=taskid, preprocess=True)
  File "/common/ketrong/AutoImputeExp/tpot2_imputetest/Impute_Experiments/utils.py", line 200, in load_task
    task = openml.tasks.get_task(task_id)
  File "/home/ketrong/miniconda3/envs/tpot2devenv/lib/python3.10/site-packages/openml/tasks/functions.py", line 415, in get_task
    raise e
  File "/home/ketrong/miniconda3/envs/tpot2devenv/lib/python3.10/site-packages/openml/tasks/functions.py", line 398, in get_task
    task = _get_task_description(task_id)
  File "/home/ketrong/miniconda3/envs/tpot2devenv/lib/python3.10/site-packages/openml/tasks/functions.py", line 431, in _get_task_description
    task_xml = openml._api_calls._perform_api_call("task/%d" % task_id, "get")
  File "/home/ketrong/miniconda3/envs/tpot2devenv/lib/python3.10/site-packages/openml/_api_calls.py", line 99, in _perform_api_call
    response = __read_url(url, request_method, data)
  File "/home/ketrong/miniconda3/envs/tpot2devenv/lib/python3.10/site-packages/openml/_api_calls.py", line 308, in __read_url
    return _send_request(
  File "/home/ketrong/miniconda3/envs/tpot2devenv/lib/python3.10/site-packages/openml/_api_calls.py", line 344, in _send_request
    __check_response(response=response, url=url, file_elements=files)
  File "/home/ketrong/miniconda3/envs/tpot2devenv/lib/python3.10/site-packages/openml/_api_calls.py", line 409, in __check_response
    raise __parse_server_exception(response, url, file_elements=file_elements)
openml.exceptions.OpenMLServerException: https://www.openml.org/api/v1/xml/task/1046 returned code 151: Unknown task - None

1046
remove from investigation?
working on 
logs/1046/tpot2_base_imputation_MNAR_0.3
2.0560247898101807
loading data
logs/1046/tpot2_base_imputation_MNAR_0.3/data/1046_True.pkl
https://www.openml.org/api/v1/xml/task/1046 returned code 151: Unknown task - None
Traceback (most recent call last):
  File "/home/ketrong/miniconda3/envs/tpot2devenv/lib/python3.10/site-packages/openml/tasks/functions.py", line 70, in _get_cached_task
    with io.open(os.path.join(tid_cache_dir, "task.xml"), encoding="utf8") as fh:
FileNotFoundError: [Errno 2] No such file or directory: '/home/ketrong/.cache/openml/org/openml/www/tasks/1046/task.xml'

During handling of the above exception, another exception occurred:

Traceback (most recent call last):
  File "/home/ketrong/miniconda3/envs/tpot2devenv/lib/python3.10/site-packages/openml/tasks/functions.py", line 422, in _get_task_description
    return _get_cached_task(task_id)
  File "/home/ketrong/miniconda3/envs/tpot2devenv/lib/python3.10/site-packages/openml/tasks/functions.py", line 74, in _get_cached_task
    raise OpenMLCacheException("Task file for tid %d not " "cached" % tid)
openml.exceptions.OpenMLCacheException: Task file for tid 1046 not cached

During handling of the above exception, another exception occurred:

Traceback (most recent call last):
  File "/common/ketrong/AutoImputeExp/tpot2_imputetest/Impute_Experiments/utils.py", line 310, in loop_through_tasks
    X_train, y_train, X_test, y_test = load_task(base_save_folder=base_save_folder, exp=exp, type=type, levelstr=levelstr, task_id=taskid, preprocess=True)
  File "/common/ketrong/AutoImputeExp/tpot2_imputetest/Impute_Experiments/utils.py", line 200, in load_task
    task = openml.tasks.get_task(task_id)
  File "/home/ketrong/miniconda3/envs/tpot2devenv/lib/python3.10/site-packages/openml/tasks/functions.py", line 415, in get_task
    raise e
  File "/home/ketrong/miniconda3/envs/tpot2devenv/lib/python3.10/site-packages/openml/tasks/functions.py", line 398, in get_task
    task = _get_task_description(task_id)
  File "/home/ketrong/miniconda3/envs/tpot2devenv/lib/python3.10/site-packages/openml/tasks/functions.py", line 431, in _get_task_description
    task_xml = openml._api_calls._perform_api_call("task/%d" % task_id, "get")
  File "/home/ketrong/miniconda3/envs/tpot2devenv/lib/python3.10/site-packages/openml/_api_calls.py", line 99, in _perform_api_call
    response = __read_url(url, request_method, data)
  File "/home/ketrong/miniconda3/envs/tpot2devenv/lib/python3.10/site-packages/openml/_api_calls.py", line 308, in __read_url
    return _send_request(
  File "/home/ketrong/miniconda3/envs/tpot2devenv/lib/python3.10/site-packages/openml/_api_calls.py", line 344, in _send_request
    __check_response(response=response, url=url, file_elements=files)
  File "/home/ketrong/miniconda3/envs/tpot2devenv/lib/python3.10/site-packages/openml/_api_calls.py", line 409, in __check_response
    raise __parse_server_exception(response, url, file_elements=file_elements)
openml.exceptions.OpenMLServerException: https://www.openml.org/api/v1/xml/task/1046 returned code 151: Unknown task - None

1046
remove from investigation?
1046
finished
working on 
logs/1120/tpot2_base_normal_MNAR_0.3
3.295045852661133
loading data
logs/1120/tpot2_base_normal_MNAR_0.3/data/1120_True.pkl
https://www.openml.org/api/v1/xml/task/1120 returned code 151: Unknown task - None
Traceback (most recent call last):
  File "/home/ketrong/miniconda3/envs/tpot2devenv/lib/python3.10/site-packages/openml/tasks/functions.py", line 70, in _get_cached_task
    with io.open(os.path.join(tid_cache_dir, "task.xml"), encoding="utf8") as fh:
FileNotFoundError: [Errno 2] No such file or directory: '/home/ketrong/.cache/openml/org/openml/www/tasks/1120/task.xml'

During handling of the above exception, another exception occurred:

Traceback (most recent call last):
  File "/home/ketrong/miniconda3/envs/tpot2devenv/lib/python3.10/site-packages/openml/tasks/functions.py", line 422, in _get_task_description
    return _get_cached_task(task_id)
  File "/home/ketrong/miniconda3/envs/tpot2devenv/lib/python3.10/site-packages/openml/tasks/functions.py", line 74, in _get_cached_task
    raise OpenMLCacheException("Task file for tid %d not " "cached" % tid)
openml.exceptions.OpenMLCacheException: Task file for tid 1120 not cached

During handling of the above exception, another exception occurred:

Traceback (most recent call last):
  File "/common/ketrong/AutoImputeExp/tpot2_imputetest/Impute_Experiments/utils.py", line 310, in loop_through_tasks
    X_train, y_train, X_test, y_test = load_task(base_save_folder=base_save_folder, exp=exp, type=type, levelstr=levelstr, task_id=taskid, preprocess=True)
  File "/common/ketrong/AutoImputeExp/tpot2_imputetest/Impute_Experiments/utils.py", line 200, in load_task
    task = openml.tasks.get_task(task_id)
  File "/home/ketrong/miniconda3/envs/tpot2devenv/lib/python3.10/site-packages/openml/tasks/functions.py", line 415, in get_task
    raise e
  File "/home/ketrong/miniconda3/envs/tpot2devenv/lib/python3.10/site-packages/openml/tasks/functions.py", line 398, in get_task
    task = _get_task_description(task_id)
  File "/home/ketrong/miniconda3/envs/tpot2devenv/lib/python3.10/site-packages/openml/tasks/functions.py", line 431, in _get_task_description
    task_xml = openml._api_calls._perform_api_call("task/%d" % task_id, "get")
  File "/home/ketrong/miniconda3/envs/tpot2devenv/lib/python3.10/site-packages/openml/_api_calls.py", line 99, in _perform_api_call
    response = __read_url(url, request_method, data)
  File "/home/ketrong/miniconda3/envs/tpot2devenv/lib/python3.10/site-packages/openml/_api_calls.py", line 308, in __read_url
    return _send_request(
  File "/home/ketrong/miniconda3/envs/tpot2devenv/lib/python3.10/site-packages/openml/_api_calls.py", line 344, in _send_request
    __check_response(response=response, url=url, file_elements=files)
  File "/home/ketrong/miniconda3/envs/tpot2devenv/lib/python3.10/site-packages/openml/_api_calls.py", line 409, in __check_response
    raise __parse_server_exception(response, url, file_elements=file_elements)
openml.exceptions.OpenMLServerException: https://www.openml.org/api/v1/xml/task/1120 returned code 151: Unknown task - None

1120
remove from investigation?
working on 
logs/1120/tpot2_base_imputation_MNAR_0.3
1.7466795444488525
loading data
logs/1120/tpot2_base_imputation_MNAR_0.3/data/1120_True.pkl
https://www.openml.org/api/v1/xml/task/1120 returned code 151: Unknown task - None
Traceback (most recent call last):
  File "/home/ketrong/miniconda3/envs/tpot2devenv/lib/python3.10/site-packages/openml/tasks/functions.py", line 70, in _get_cached_task
    with io.open(os.path.join(tid_cache_dir, "task.xml"), encoding="utf8") as fh:
FileNotFoundError: [Errno 2] No such file or directory: '/home/ketrong/.cache/openml/org/openml/www/tasks/1120/task.xml'

During handling of the above exception, another exception occurred:

Traceback (most recent call last):
  File "/home/ketrong/miniconda3/envs/tpot2devenv/lib/python3.10/site-packages/openml/tasks/functions.py", line 422, in _get_task_description
    return _get_cached_task(task_id)
  File "/home/ketrong/miniconda3/envs/tpot2devenv/lib/python3.10/site-packages/openml/tasks/functions.py", line 74, in _get_cached_task
    raise OpenMLCacheException("Task file for tid %d not " "cached" % tid)
openml.exceptions.OpenMLCacheException: Task file for tid 1120 not cached

During handling of the above exception, another exception occurred:

Traceback (most recent call last):
  File "/common/ketrong/AutoImputeExp/tpot2_imputetest/Impute_Experiments/utils.py", line 310, in loop_through_tasks
    X_train, y_train, X_test, y_test = load_task(base_save_folder=base_save_folder, exp=exp, type=type, levelstr=levelstr, task_id=taskid, preprocess=True)
  File "/common/ketrong/AutoImputeExp/tpot2_imputetest/Impute_Experiments/utils.py", line 200, in load_task
    task = openml.tasks.get_task(task_id)
  File "/home/ketrong/miniconda3/envs/tpot2devenv/lib/python3.10/site-packages/openml/tasks/functions.py", line 415, in get_task
    raise e
  File "/home/ketrong/miniconda3/envs/tpot2devenv/lib/python3.10/site-packages/openml/tasks/functions.py", line 398, in get_task
    task = _get_task_description(task_id)
  File "/home/ketrong/miniconda3/envs/tpot2devenv/lib/python3.10/site-packages/openml/tasks/functions.py", line 431, in _get_task_description
    task_xml = openml._api_calls._perform_api_call("task/%d" % task_id, "get")
  File "/home/ketrong/miniconda3/envs/tpot2devenv/lib/python3.10/site-packages/openml/_api_calls.py", line 99, in _perform_api_call
    response = __read_url(url, request_method, data)
  File "/home/ketrong/miniconda3/envs/tpot2devenv/lib/python3.10/site-packages/openml/_api_calls.py", line 308, in __read_url
    return _send_request(
  File "/home/ketrong/miniconda3/envs/tpot2devenv/lib/python3.10/site-packages/openml/_api_calls.py", line 344, in _send_request
    __check_response(response=response, url=url, file_elements=files)
  File "/home/ketrong/miniconda3/envs/tpot2devenv/lib/python3.10/site-packages/openml/_api_calls.py", line 409, in __check_response
    raise __parse_server_exception(response, url, file_elements=file_elements)
openml.exceptions.OpenMLServerException: https://www.openml.org/api/v1/xml/task/1120 returned code 151: Unknown task - None

1120
remove from investigation?
1120
finished
working on 
logs/1193/tpot2_base_normal_MNAR_0.3
0.08342957496643066
loading data
logs/1193/tpot2_base_normal_MNAR_0.3/data/1193_True.pkl
https://www.openml.org/api/v1/xml/task/1193 returned code 151: Unknown task - None
Traceback (most recent call last):
  File "/home/ketrong/miniconda3/envs/tpot2devenv/lib/python3.10/site-packages/openml/tasks/functions.py", line 70, in _get_cached_task
    with io.open(os.path.join(tid_cache_dir, "task.xml"), encoding="utf8") as fh:
FileNotFoundError: [Errno 2] No such file or directory: '/home/ketrong/.cache/openml/org/openml/www/tasks/1193/task.xml'

During handling of the above exception, another exception occurred:

Traceback (most recent call last):
  File "/home/ketrong/miniconda3/envs/tpot2devenv/lib/python3.10/site-packages/openml/tasks/functions.py", line 422, in _get_task_description
    return _get_cached_task(task_id)
  File "/home/ketrong/miniconda3/envs/tpot2devenv/lib/python3.10/site-packages/openml/tasks/functions.py", line 74, in _get_cached_task
    raise OpenMLCacheException("Task file for tid %d not " "cached" % tid)
openml.exceptions.OpenMLCacheException: Task file for tid 1193 not cached

During handling of the above exception, another exception occurred:

Traceback (most recent call last):
  File "/common/ketrong/AutoImputeExp/tpot2_imputetest/Impute_Experiments/utils.py", line 310, in loop_through_tasks
    X_train, y_train, X_test, y_test = load_task(base_save_folder=base_save_folder, exp=exp, type=type, levelstr=levelstr, task_id=taskid, preprocess=True)
  File "/common/ketrong/AutoImputeExp/tpot2_imputetest/Impute_Experiments/utils.py", line 200, in load_task
    task = openml.tasks.get_task(task_id)
  File "/home/ketrong/miniconda3/envs/tpot2devenv/lib/python3.10/site-packages/openml/tasks/functions.py", line 415, in get_task
    raise e
  File "/home/ketrong/miniconda3/envs/tpot2devenv/lib/python3.10/site-packages/openml/tasks/functions.py", line 398, in get_task
    task = _get_task_description(task_id)
  File "/home/ketrong/miniconda3/envs/tpot2devenv/lib/python3.10/site-packages/openml/tasks/functions.py", line 431, in _get_task_description
    task_xml = openml._api_calls._perform_api_call("task/%d" % task_id, "get")
  File "/home/ketrong/miniconda3/envs/tpot2devenv/lib/python3.10/site-packages/openml/_api_calls.py", line 99, in _perform_api_call
    response = __read_url(url, request_method, data)
  File "/home/ketrong/miniconda3/envs/tpot2devenv/lib/python3.10/site-packages/openml/_api_calls.py", line 308, in __read_url
    return _send_request(
  File "/home/ketrong/miniconda3/envs/tpot2devenv/lib/python3.10/site-packages/openml/_api_calls.py", line 344, in _send_request
    __check_response(response=response, url=url, file_elements=files)
  File "/home/ketrong/miniconda3/envs/tpot2devenv/lib/python3.10/site-packages/openml/_api_calls.py", line 409, in __check_response
    raise __parse_server_exception(response, url, file_elements=file_elements)
openml.exceptions.OpenMLServerException: https://www.openml.org/api/v1/xml/task/1193 returned code 151: Unknown task - None

1193
remove from investigation?
working on 
logs/1193/tpot2_base_imputation_MNAR_0.3
4.911139726638794
loading data
logs/1193/tpot2_base_imputation_MNAR_0.3/data/1193_True.pkl
https://www.openml.org/api/v1/xml/task/1193 returned code 151: Unknown task - None
Traceback (most recent call last):
  File "/home/ketrong/miniconda3/envs/tpot2devenv/lib/python3.10/site-packages/openml/tasks/functions.py", line 70, in _get_cached_task
    with io.open(os.path.join(tid_cache_dir, "task.xml"), encoding="utf8") as fh:
FileNotFoundError: [Errno 2] No such file or directory: '/home/ketrong/.cache/openml/org/openml/www/tasks/1193/task.xml'

During handling of the above exception, another exception occurred:

Traceback (most recent call last):
  File "/home/ketrong/miniconda3/envs/tpot2devenv/lib/python3.10/site-packages/openml/tasks/functions.py", line 422, in _get_task_description
    return _get_cached_task(task_id)
  File "/home/ketrong/miniconda3/envs/tpot2devenv/lib/python3.10/site-packages/openml/tasks/functions.py", line 74, in _get_cached_task
    raise OpenMLCacheException("Task file for tid %d not " "cached" % tid)
openml.exceptions.OpenMLCacheException: Task file for tid 1193 not cached

During handling of the above exception, another exception occurred:

Traceback (most recent call last):
  File "/common/ketrong/AutoImputeExp/tpot2_imputetest/Impute_Experiments/utils.py", line 310, in loop_through_tasks
    X_train, y_train, X_test, y_test = load_task(base_save_folder=base_save_folder, exp=exp, type=type, levelstr=levelstr, task_id=taskid, preprocess=True)
  File "/common/ketrong/AutoImputeExp/tpot2_imputetest/Impute_Experiments/utils.py", line 200, in load_task
    task = openml.tasks.get_task(task_id)
  File "/home/ketrong/miniconda3/envs/tpot2devenv/lib/python3.10/site-packages/openml/tasks/functions.py", line 415, in get_task
    raise e
  File "/home/ketrong/miniconda3/envs/tpot2devenv/lib/python3.10/site-packages/openml/tasks/functions.py", line 398, in get_task
    task = _get_task_description(task_id)
  File "/home/ketrong/miniconda3/envs/tpot2devenv/lib/python3.10/site-packages/openml/tasks/functions.py", line 431, in _get_task_description
    task_xml = openml._api_calls._perform_api_call("task/%d" % task_id, "get")
  File "/home/ketrong/miniconda3/envs/tpot2devenv/lib/python3.10/site-packages/openml/_api_calls.py", line 99, in _perform_api_call
    response = __read_url(url, request_method, data)
  File "/home/ketrong/miniconda3/envs/tpot2devenv/lib/python3.10/site-packages/openml/_api_calls.py", line 308, in __read_url
    return _send_request(
  File "/home/ketrong/miniconda3/envs/tpot2devenv/lib/python3.10/site-packages/openml/_api_calls.py", line 344, in _send_request
    __check_response(response=response, url=url, file_elements=files)
  File "/home/ketrong/miniconda3/envs/tpot2devenv/lib/python3.10/site-packages/openml/_api_calls.py", line 409, in __check_response
    raise __parse_server_exception(response, url, file_elements=file_elements)
openml.exceptions.OpenMLServerException: https://www.openml.org/api/v1/xml/task/1193 returned code 151: Unknown task - None

1193
remove from investigation?
1193
finished
working on 
logs/1199/tpot2_base_normal_MNAR_0.3
3.07926869392395
loading data
logs/1199/tpot2_base_normal_MNAR_0.3/data/1199_True.pkl
https://www.openml.org/api/v1/xml/task/1199 returned code 151: Unknown task - None
Traceback (most recent call last):
  File "/home/ketrong/miniconda3/envs/tpot2devenv/lib/python3.10/site-packages/openml/tasks/functions.py", line 70, in _get_cached_task
    with io.open(os.path.join(tid_cache_dir, "task.xml"), encoding="utf8") as fh:
FileNotFoundError: [Errno 2] No such file or directory: '/home/ketrong/.cache/openml/org/openml/www/tasks/1199/task.xml'

During handling of the above exception, another exception occurred:

Traceback (most recent call last):
  File "/home/ketrong/miniconda3/envs/tpot2devenv/lib/python3.10/site-packages/openml/tasks/functions.py", line 422, in _get_task_description
    return _get_cached_task(task_id)
  File "/home/ketrong/miniconda3/envs/tpot2devenv/lib/python3.10/site-packages/openml/tasks/functions.py", line 74, in _get_cached_task
    raise OpenMLCacheException("Task file for tid %d not " "cached" % tid)
openml.exceptions.OpenMLCacheException: Task file for tid 1199 not cached

During handling of the above exception, another exception occurred:

Traceback (most recent call last):
  File "/common/ketrong/AutoImputeExp/tpot2_imputetest/Impute_Experiments/utils.py", line 310, in loop_through_tasks
    X_train, y_train, X_test, y_test = load_task(base_save_folder=base_save_folder, exp=exp, type=type, levelstr=levelstr, task_id=taskid, preprocess=True)
  File "/common/ketrong/AutoImputeExp/tpot2_imputetest/Impute_Experiments/utils.py", line 200, in load_task
    task = openml.tasks.get_task(task_id)
  File "/home/ketrong/miniconda3/envs/tpot2devenv/lib/python3.10/site-packages/openml/tasks/functions.py", line 415, in get_task
    raise e
  File "/home/ketrong/miniconda3/envs/tpot2devenv/lib/python3.10/site-packages/openml/tasks/functions.py", line 398, in get_task
    task = _get_task_description(task_id)
  File "/home/ketrong/miniconda3/envs/tpot2devenv/lib/python3.10/site-packages/openml/tasks/functions.py", line 431, in _get_task_description
    task_xml = openml._api_calls._perform_api_call("task/%d" % task_id, "get")
  File "/home/ketrong/miniconda3/envs/tpot2devenv/lib/python3.10/site-packages/openml/_api_calls.py", line 99, in _perform_api_call
    response = __read_url(url, request_method, data)
  File "/home/ketrong/miniconda3/envs/tpot2devenv/lib/python3.10/site-packages/openml/_api_calls.py", line 308, in __read_url
    return _send_request(
  File "/home/ketrong/miniconda3/envs/tpot2devenv/lib/python3.10/site-packages/openml/_api_calls.py", line 344, in _send_request
    __check_response(response=response, url=url, file_elements=files)
  File "/home/ketrong/miniconda3/envs/tpot2devenv/lib/python3.10/site-packages/openml/_api_calls.py", line 409, in __check_response
    raise __parse_server_exception(response, url, file_elements=file_elements)
openml.exceptions.OpenMLServerException: https://www.openml.org/api/v1/xml/task/1199 returned code 151: Unknown task - None

1199
remove from investigation?
working on 
logs/1199/tpot2_base_imputation_MNAR_0.3
2.4380593299865723
loading data
logs/1199/tpot2_base_imputation_MNAR_0.3/data/1199_True.pkl
https://www.openml.org/api/v1/xml/task/1199 returned code 151: Unknown task - None
Traceback (most recent call last):
  File "/home/ketrong/miniconda3/envs/tpot2devenv/lib/python3.10/site-packages/openml/tasks/functions.py", line 70, in _get_cached_task
    with io.open(os.path.join(tid_cache_dir, "task.xml"), encoding="utf8") as fh:
FileNotFoundError: [Errno 2] No such file or directory: '/home/ketrong/.cache/openml/org/openml/www/tasks/1199/task.xml'

During handling of the above exception, another exception occurred:

Traceback (most recent call last):
  File "/home/ketrong/miniconda3/envs/tpot2devenv/lib/python3.10/site-packages/openml/tasks/functions.py", line 422, in _get_task_description
    return _get_cached_task(task_id)
  File "/home/ketrong/miniconda3/envs/tpot2devenv/lib/python3.10/site-packages/openml/tasks/functions.py", line 74, in _get_cached_task
    raise OpenMLCacheException("Task file for tid %d not " "cached" % tid)
openml.exceptions.OpenMLCacheException: Task file for tid 1199 not cached

During handling of the above exception, another exception occurred:

Traceback (most recent call last):
  File "/common/ketrong/AutoImputeExp/tpot2_imputetest/Impute_Experiments/utils.py", line 310, in loop_through_tasks
    X_train, y_train, X_test, y_test = load_task(base_save_folder=base_save_folder, exp=exp, type=type, levelstr=levelstr, task_id=taskid, preprocess=True)
  File "/common/ketrong/AutoImputeExp/tpot2_imputetest/Impute_Experiments/utils.py", line 200, in load_task
    task = openml.tasks.get_task(task_id)
  File "/home/ketrong/miniconda3/envs/tpot2devenv/lib/python3.10/site-packages/openml/tasks/functions.py", line 415, in get_task
    raise e
  File "/home/ketrong/miniconda3/envs/tpot2devenv/lib/python3.10/site-packages/openml/tasks/functions.py", line 398, in get_task
    task = _get_task_description(task_id)
  File "/home/ketrong/miniconda3/envs/tpot2devenv/lib/python3.10/site-packages/openml/tasks/functions.py", line 431, in _get_task_description
    task_xml = openml._api_calls._perform_api_call("task/%d" % task_id, "get")
  File "/home/ketrong/miniconda3/envs/tpot2devenv/lib/python3.10/site-packages/openml/_api_calls.py", line 99, in _perform_api_call
    response = __read_url(url, request_method, data)
  File "/home/ketrong/miniconda3/envs/tpot2devenv/lib/python3.10/site-packages/openml/_api_calls.py", line 308, in __read_url
    return _send_request(
  File "/home/ketrong/miniconda3/envs/tpot2devenv/lib/python3.10/site-packages/openml/_api_calls.py", line 344, in _send_request
    __check_response(response=response, url=url, file_elements=files)
  File "/home/ketrong/miniconda3/envs/tpot2devenv/lib/python3.10/site-packages/openml/_api_calls.py", line 409, in __check_response
    raise __parse_server_exception(response, url, file_elements=file_elements)
openml.exceptions.OpenMLServerException: https://www.openml.org/api/v1/xml/task/1199 returned code 151: Unknown task - None

1199
remove from investigation?
1199
finished
working on 
logs/1200/tpot2_base_normal_MNAR_0.3
0.39607954025268555
loading data
logs/1200/tpot2_base_normal_MNAR_0.3/data/1200_True.pkl
https://www.openml.org/api/v1/xml/task/1200 returned code 151: Unknown task - None
Traceback (most recent call last):
  File "/home/ketrong/miniconda3/envs/tpot2devenv/lib/python3.10/site-packages/openml/tasks/functions.py", line 70, in _get_cached_task
    with io.open(os.path.join(tid_cache_dir, "task.xml"), encoding="utf8") as fh:
FileNotFoundError: [Errno 2] No such file or directory: '/home/ketrong/.cache/openml/org/openml/www/tasks/1200/task.xml'

During handling of the above exception, another exception occurred:

Traceback (most recent call last):
  File "/home/ketrong/miniconda3/envs/tpot2devenv/lib/python3.10/site-packages/openml/tasks/functions.py", line 422, in _get_task_description
    return _get_cached_task(task_id)
  File "/home/ketrong/miniconda3/envs/tpot2devenv/lib/python3.10/site-packages/openml/tasks/functions.py", line 74, in _get_cached_task
    raise OpenMLCacheException("Task file for tid %d not " "cached" % tid)
openml.exceptions.OpenMLCacheException: Task file for tid 1200 not cached

During handling of the above exception, another exception occurred:

Traceback (most recent call last):
  File "/common/ketrong/AutoImputeExp/tpot2_imputetest/Impute_Experiments/utils.py", line 310, in loop_through_tasks
    X_train, y_train, X_test, y_test = load_task(base_save_folder=base_save_folder, exp=exp, type=type, levelstr=levelstr, task_id=taskid, preprocess=True)
  File "/common/ketrong/AutoImputeExp/tpot2_imputetest/Impute_Experiments/utils.py", line 200, in load_task
    task = openml.tasks.get_task(task_id)
  File "/home/ketrong/miniconda3/envs/tpot2devenv/lib/python3.10/site-packages/openml/tasks/functions.py", line 415, in get_task
    raise e
  File "/home/ketrong/miniconda3/envs/tpot2devenv/lib/python3.10/site-packages/openml/tasks/functions.py", line 398, in get_task
    task = _get_task_description(task_id)
  File "/home/ketrong/miniconda3/envs/tpot2devenv/lib/python3.10/site-packages/openml/tasks/functions.py", line 431, in _get_task_description
    task_xml = openml._api_calls._perform_api_call("task/%d" % task_id, "get")
  File "/home/ketrong/miniconda3/envs/tpot2devenv/lib/python3.10/site-packages/openml/_api_calls.py", line 99, in _perform_api_call
    response = __read_url(url, request_method, data)
  File "/home/ketrong/miniconda3/envs/tpot2devenv/lib/python3.10/site-packages/openml/_api_calls.py", line 308, in __read_url
    return _send_request(
  File "/home/ketrong/miniconda3/envs/tpot2devenv/lib/python3.10/site-packages/openml/_api_calls.py", line 344, in _send_request
    __check_response(response=response, url=url, file_elements=files)
  File "/home/ketrong/miniconda3/envs/tpot2devenv/lib/python3.10/site-packages/openml/_api_calls.py", line 409, in __check_response
    raise __parse_server_exception(response, url, file_elements=file_elements)
openml.exceptions.OpenMLServerException: https://www.openml.org/api/v1/xml/task/1200 returned code 151: Unknown task - None

1200
remove from investigation?
working on 
logs/1200/tpot2_base_imputation_MNAR_0.3
4.046759366989136
loading data
logs/1200/tpot2_base_imputation_MNAR_0.3/data/1200_True.pkl
https://www.openml.org/api/v1/xml/task/1200 returned code 151: Unknown task - None
Traceback (most recent call last):
  File "/home/ketrong/miniconda3/envs/tpot2devenv/lib/python3.10/site-packages/openml/tasks/functions.py", line 70, in _get_cached_task
    with io.open(os.path.join(tid_cache_dir, "task.xml"), encoding="utf8") as fh:
FileNotFoundError: [Errno 2] No such file or directory: '/home/ketrong/.cache/openml/org/openml/www/tasks/1200/task.xml'

During handling of the above exception, another exception occurred:

Traceback (most recent call last):
  File "/home/ketrong/miniconda3/envs/tpot2devenv/lib/python3.10/site-packages/openml/tasks/functions.py", line 422, in _get_task_description
    return _get_cached_task(task_id)
  File "/home/ketrong/miniconda3/envs/tpot2devenv/lib/python3.10/site-packages/openml/tasks/functions.py", line 74, in _get_cached_task
    raise OpenMLCacheException("Task file for tid %d not " "cached" % tid)
openml.exceptions.OpenMLCacheException: Task file for tid 1200 not cached

During handling of the above exception, another exception occurred:

Traceback (most recent call last):
  File "/common/ketrong/AutoImputeExp/tpot2_imputetest/Impute_Experiments/utils.py", line 310, in loop_through_tasks
    X_train, y_train, X_test, y_test = load_task(base_save_folder=base_save_folder, exp=exp, type=type, levelstr=levelstr, task_id=taskid, preprocess=True)
  File "/common/ketrong/AutoImputeExp/tpot2_imputetest/Impute_Experiments/utils.py", line 200, in load_task
    task = openml.tasks.get_task(task_id)
  File "/home/ketrong/miniconda3/envs/tpot2devenv/lib/python3.10/site-packages/openml/tasks/functions.py", line 415, in get_task
    raise e
  File "/home/ketrong/miniconda3/envs/tpot2devenv/lib/python3.10/site-packages/openml/tasks/functions.py", line 398, in get_task
    task = _get_task_description(task_id)
  File "/home/ketrong/miniconda3/envs/tpot2devenv/lib/python3.10/site-packages/openml/tasks/functions.py", line 431, in _get_task_description
    task_xml = openml._api_calls._perform_api_call("task/%d" % task_id, "get")
  File "/home/ketrong/miniconda3/envs/tpot2devenv/lib/python3.10/site-packages/openml/_api_calls.py", line 99, in _perform_api_call
    response = __read_url(url, request_method, data)
  File "/home/ketrong/miniconda3/envs/tpot2devenv/lib/python3.10/site-packages/openml/_api_calls.py", line 308, in __read_url
    return _send_request(
  File "/home/ketrong/miniconda3/envs/tpot2devenv/lib/python3.10/site-packages/openml/_api_calls.py", line 344, in _send_request
    __check_response(response=response, url=url, file_elements=files)
  File "/home/ketrong/miniconda3/envs/tpot2devenv/lib/python3.10/site-packages/openml/_api_calls.py", line 409, in __check_response
    raise __parse_server_exception(response, url, file_elements=file_elements)
openml.exceptions.OpenMLServerException: https://www.openml.org/api/v1/xml/task/1200 returned code 151: Unknown task - None

1200
remove from investigation?
1200
finished
working on 
logs/1213/tpot2_base_normal_MNAR_0.3
2.167609214782715
loading data
logs/1213/tpot2_base_normal_MNAR_0.3/data/1213_True.pkl
https://www.openml.org/api/v1/xml/task/1213 returned code 151: Unknown task - None
Traceback (most recent call last):
  File "/home/ketrong/miniconda3/envs/tpot2devenv/lib/python3.10/site-packages/openml/tasks/functions.py", line 70, in _get_cached_task
    with io.open(os.path.join(tid_cache_dir, "task.xml"), encoding="utf8") as fh:
FileNotFoundError: [Errno 2] No such file or directory: '/home/ketrong/.cache/openml/org/openml/www/tasks/1213/task.xml'

During handling of the above exception, another exception occurred:

Traceback (most recent call last):
  File "/home/ketrong/miniconda3/envs/tpot2devenv/lib/python3.10/site-packages/openml/tasks/functions.py", line 422, in _get_task_description
    return _get_cached_task(task_id)
  File "/home/ketrong/miniconda3/envs/tpot2devenv/lib/python3.10/site-packages/openml/tasks/functions.py", line 74, in _get_cached_task
    raise OpenMLCacheException("Task file for tid %d not " "cached" % tid)
openml.exceptions.OpenMLCacheException: Task file for tid 1213 not cached

During handling of the above exception, another exception occurred:

Traceback (most recent call last):
  File "/common/ketrong/AutoImputeExp/tpot2_imputetest/Impute_Experiments/utils.py", line 310, in loop_through_tasks
    X_train, y_train, X_test, y_test = load_task(base_save_folder=base_save_folder, exp=exp, type=type, levelstr=levelstr, task_id=taskid, preprocess=True)
  File "/common/ketrong/AutoImputeExp/tpot2_imputetest/Impute_Experiments/utils.py", line 200, in load_task
    task = openml.tasks.get_task(task_id)
  File "/home/ketrong/miniconda3/envs/tpot2devenv/lib/python3.10/site-packages/openml/tasks/functions.py", line 415, in get_task
    raise e
  File "/home/ketrong/miniconda3/envs/tpot2devenv/lib/python3.10/site-packages/openml/tasks/functions.py", line 398, in get_task
    task = _get_task_description(task_id)
  File "/home/ketrong/miniconda3/envs/tpot2devenv/lib/python3.10/site-packages/openml/tasks/functions.py", line 431, in _get_task_description
    task_xml = openml._api_calls._perform_api_call("task/%d" % task_id, "get")
  File "/home/ketrong/miniconda3/envs/tpot2devenv/lib/python3.10/site-packages/openml/_api_calls.py", line 99, in _perform_api_call
    response = __read_url(url, request_method, data)
  File "/home/ketrong/miniconda3/envs/tpot2devenv/lib/python3.10/site-packages/openml/_api_calls.py", line 308, in __read_url
    return _send_request(
  File "/home/ketrong/miniconda3/envs/tpot2devenv/lib/python3.10/site-packages/openml/_api_calls.py", line 344, in _send_request
    __check_response(response=response, url=url, file_elements=files)
  File "/home/ketrong/miniconda3/envs/tpot2devenv/lib/python3.10/site-packages/openml/_api_calls.py", line 409, in __check_response
    raise __parse_server_exception(response, url, file_elements=file_elements)
openml.exceptions.OpenMLServerException: https://www.openml.org/api/v1/xml/task/1213 returned code 151: Unknown task - None

1213
remove from investigation?
working on 
logs/1213/tpot2_base_imputation_MNAR_0.3
0.4456799030303955
loading data
logs/1213/tpot2_base_imputation_MNAR_0.3/data/1213_True.pkl
https://www.openml.org/api/v1/xml/task/1213 returned code 151: Unknown task - None
Traceback (most recent call last):
  File "/home/ketrong/miniconda3/envs/tpot2devenv/lib/python3.10/site-packages/openml/tasks/functions.py", line 70, in _get_cached_task
    with io.open(os.path.join(tid_cache_dir, "task.xml"), encoding="utf8") as fh:
FileNotFoundError: [Errno 2] No such file or directory: '/home/ketrong/.cache/openml/org/openml/www/tasks/1213/task.xml'

During handling of the above exception, another exception occurred:

Traceback (most recent call last):
  File "/home/ketrong/miniconda3/envs/tpot2devenv/lib/python3.10/site-packages/openml/tasks/functions.py", line 422, in _get_task_description
    return _get_cached_task(task_id)
  File "/home/ketrong/miniconda3/envs/tpot2devenv/lib/python3.10/site-packages/openml/tasks/functions.py", line 74, in _get_cached_task
    raise OpenMLCacheException("Task file for tid %d not " "cached" % tid)
openml.exceptions.OpenMLCacheException: Task file for tid 1213 not cached

During handling of the above exception, another exception occurred:

Traceback (most recent call last):
  File "/common/ketrong/AutoImputeExp/tpot2_imputetest/Impute_Experiments/utils.py", line 310, in loop_through_tasks
    X_train, y_train, X_test, y_test = load_task(base_save_folder=base_save_folder, exp=exp, type=type, levelstr=levelstr, task_id=taskid, preprocess=True)
  File "/common/ketrong/AutoImputeExp/tpot2_imputetest/Impute_Experiments/utils.py", line 200, in load_task
    task = openml.tasks.get_task(task_id)
  File "/home/ketrong/miniconda3/envs/tpot2devenv/lib/python3.10/site-packages/openml/tasks/functions.py", line 415, in get_task
    raise e
  File "/home/ketrong/miniconda3/envs/tpot2devenv/lib/python3.10/site-packages/openml/tasks/functions.py", line 398, in get_task
    task = _get_task_description(task_id)
  File "/home/ketrong/miniconda3/envs/tpot2devenv/lib/python3.10/site-packages/openml/tasks/functions.py", line 431, in _get_task_description
    task_xml = openml._api_calls._perform_api_call("task/%d" % task_id, "get")
  File "/home/ketrong/miniconda3/envs/tpot2devenv/lib/python3.10/site-packages/openml/_api_calls.py", line 99, in _perform_api_call
    response = __read_url(url, request_method, data)
  File "/home/ketrong/miniconda3/envs/tpot2devenv/lib/python3.10/site-packages/openml/_api_calls.py", line 308, in __read_url
    return _send_request(
  File "/home/ketrong/miniconda3/envs/tpot2devenv/lib/python3.10/site-packages/openml/_api_calls.py", line 344, in _send_request
    __check_response(response=response, url=url, file_elements=files)
  File "/home/ketrong/miniconda3/envs/tpot2devenv/lib/python3.10/site-packages/openml/_api_calls.py", line 409, in __check_response
    raise __parse_server_exception(response, url, file_elements=file_elements)
openml.exceptions.OpenMLServerException: https://www.openml.org/api/v1/xml/task/1213 returned code 151: Unknown task - None

1213
remove from investigation?
1213
finished
working on 
logs/1220/tpot2_base_normal_MNAR_0.3
2.5161495208740234
loading data
logs/1220/tpot2_base_normal_MNAR_0.3/data/1220_True.pkl
https://www.openml.org/api/v1/xml/task/1220 returned code 151: Unknown task - None
Traceback (most recent call last):
  File "/home/ketrong/miniconda3/envs/tpot2devenv/lib/python3.10/site-packages/openml/tasks/functions.py", line 70, in _get_cached_task
    with io.open(os.path.join(tid_cache_dir, "task.xml"), encoding="utf8") as fh:
FileNotFoundError: [Errno 2] No such file or directory: '/home/ketrong/.cache/openml/org/openml/www/tasks/1220/task.xml'

During handling of the above exception, another exception occurred:

Traceback (most recent call last):
  File "/home/ketrong/miniconda3/envs/tpot2devenv/lib/python3.10/site-packages/openml/tasks/functions.py", line 422, in _get_task_description
    return _get_cached_task(task_id)
  File "/home/ketrong/miniconda3/envs/tpot2devenv/lib/python3.10/site-packages/openml/tasks/functions.py", line 74, in _get_cached_task
    raise OpenMLCacheException("Task file for tid %d not " "cached" % tid)
openml.exceptions.OpenMLCacheException: Task file for tid 1220 not cached

During handling of the above exception, another exception occurred:

Traceback (most recent call last):
  File "/common/ketrong/AutoImputeExp/tpot2_imputetest/Impute_Experiments/utils.py", line 310, in loop_through_tasks
    X_train, y_train, X_test, y_test = load_task(base_save_folder=base_save_folder, exp=exp, type=type, levelstr=levelstr, task_id=taskid, preprocess=True)
  File "/common/ketrong/AutoImputeExp/tpot2_imputetest/Impute_Experiments/utils.py", line 200, in load_task
    task = openml.tasks.get_task(task_id)
  File "/home/ketrong/miniconda3/envs/tpot2devenv/lib/python3.10/site-packages/openml/tasks/functions.py", line 415, in get_task
    raise e
  File "/home/ketrong/miniconda3/envs/tpot2devenv/lib/python3.10/site-packages/openml/tasks/functions.py", line 398, in get_task
    task = _get_task_description(task_id)
  File "/home/ketrong/miniconda3/envs/tpot2devenv/lib/python3.10/site-packages/openml/tasks/functions.py", line 431, in _get_task_description
    task_xml = openml._api_calls._perform_api_call("task/%d" % task_id, "get")
  File "/home/ketrong/miniconda3/envs/tpot2devenv/lib/python3.10/site-packages/openml/_api_calls.py", line 99, in _perform_api_call
    response = __read_url(url, request_method, data)
  File "/home/ketrong/miniconda3/envs/tpot2devenv/lib/python3.10/site-packages/openml/_api_calls.py", line 308, in __read_url
    return _send_request(
  File "/home/ketrong/miniconda3/envs/tpot2devenv/lib/python3.10/site-packages/openml/_api_calls.py", line 344, in _send_request
    __check_response(response=response, url=url, file_elements=files)
  File "/home/ketrong/miniconda3/envs/tpot2devenv/lib/python3.10/site-packages/openml/_api_calls.py", line 409, in __check_response
    raise __parse_server_exception(response, url, file_elements=file_elements)
openml.exceptions.OpenMLServerException: https://www.openml.org/api/v1/xml/task/1220 returned code 151: Unknown task - None

1220
remove from investigation?
working on 
logs/1220/tpot2_base_imputation_MNAR_0.3
0.18128728866577148
loading data
logs/1220/tpot2_base_imputation_MNAR_0.3/data/1220_True.pkl
https://www.openml.org/api/v1/xml/task/1220 returned code 151: Unknown task - None
Traceback (most recent call last):
  File "/home/ketrong/miniconda3/envs/tpot2devenv/lib/python3.10/site-packages/openml/tasks/functions.py", line 70, in _get_cached_task
    with io.open(os.path.join(tid_cache_dir, "task.xml"), encoding="utf8") as fh:
FileNotFoundError: [Errno 2] No such file or directory: '/home/ketrong/.cache/openml/org/openml/www/tasks/1220/task.xml'

During handling of the above exception, another exception occurred:

Traceback (most recent call last):
  File "/home/ketrong/miniconda3/envs/tpot2devenv/lib/python3.10/site-packages/openml/tasks/functions.py", line 422, in _get_task_description
    return _get_cached_task(task_id)
  File "/home/ketrong/miniconda3/envs/tpot2devenv/lib/python3.10/site-packages/openml/tasks/functions.py", line 74, in _get_cached_task
    raise OpenMLCacheException("Task file for tid %d not " "cached" % tid)
openml.exceptions.OpenMLCacheException: Task file for tid 1220 not cached

During handling of the above exception, another exception occurred:

Traceback (most recent call last):
  File "/common/ketrong/AutoImputeExp/tpot2_imputetest/Impute_Experiments/utils.py", line 310, in loop_through_tasks
    X_train, y_train, X_test, y_test = load_task(base_save_folder=base_save_folder, exp=exp, type=type, levelstr=levelstr, task_id=taskid, preprocess=True)
  File "/common/ketrong/AutoImputeExp/tpot2_imputetest/Impute_Experiments/utils.py", line 200, in load_task
    task = openml.tasks.get_task(task_id)
  File "/home/ketrong/miniconda3/envs/tpot2devenv/lib/python3.10/site-packages/openml/tasks/functions.py", line 415, in get_task
    raise e
  File "/home/ketrong/miniconda3/envs/tpot2devenv/lib/python3.10/site-packages/openml/tasks/functions.py", line 398, in get_task
    task = _get_task_description(task_id)
  File "/home/ketrong/miniconda3/envs/tpot2devenv/lib/python3.10/site-packages/openml/tasks/functions.py", line 431, in _get_task_description
    task_xml = openml._api_calls._perform_api_call("task/%d" % task_id, "get")
  File "/home/ketrong/miniconda3/envs/tpot2devenv/lib/python3.10/site-packages/openml/_api_calls.py", line 99, in _perform_api_call
    response = __read_url(url, request_method, data)
  File "/home/ketrong/miniconda3/envs/tpot2devenv/lib/python3.10/site-packages/openml/_api_calls.py", line 308, in __read_url
    return _send_request(
  File "/home/ketrong/miniconda3/envs/tpot2devenv/lib/python3.10/site-packages/openml/_api_calls.py", line 344, in _send_request
    __check_response(response=response, url=url, file_elements=files)
  File "/home/ketrong/miniconda3/envs/tpot2devenv/lib/python3.10/site-packages/openml/_api_calls.py", line 409, in __check_response
    raise __parse_server_exception(response, url, file_elements=file_elements)
openml.exceptions.OpenMLServerException: https://www.openml.org/api/v1/xml/task/1220 returned code 151: Unknown task - None

1220
remove from investigation?
1220
finished
working on 
logs/1459/tpot2_base_normal_MNAR_0.3
slurmstepd: error: *** JOB 565650 ON esplhpc-cp002 CANCELLED AT 2023-12-19T14:15:11 ***
slurmstepd: error: *** STEP 565650.0 ON esplhpc-cp002 CANCELLED AT 2023-12-19T14:15:11 ***
