Run: 6
/cm/local/apps/slurm/var/spool/job844212/slurm_script: line 23: /common/ketrong/minconda3/etc/profile.d/conda.sh: No such file or directory
/cm/local/apps/slurm/var/spool/job844212/slurm_script: line 26: $'\nconda create --name tpot2devenv -c conda-forge python=3.10\n': command not found
/cm/local/apps/slurm/var/spool/job844212/slurm_script: line 31: $'\npip install -r requirements.txt\n': command not found
RunStart
2024-04-28 00:21:02.783755: I tensorflow/core/util/port.cc:113] oneDNN custom operations are on. You may see slightly different numerical results due to floating-point round-off errors from different computation orders. To turn them off, set the environment variable `TF_ENABLE_ONEDNN_OPTS=0`.
2024-04-28 00:21:02.818464: E external/local_xla/xla/stream_executor/cuda/cuda_dnn.cc:9261] Unable to register cuDNN factory: Attempting to register factory for plugin cuDNN when one has already been registered
2024-04-28 00:21:02.818486: E external/local_xla/xla/stream_executor/cuda/cuda_fft.cc:607] Unable to register cuFFT factory: Attempting to register factory for plugin cuFFT when one has already been registered
2024-04-28 00:21:02.819646: E external/local_xla/xla/stream_executor/cuda/cuda_blas.cc:1515] Unable to register cuBLAS factory: Attempting to register factory for plugin cuBLAS when one has already been registered
2024-04-28 00:21:02.825223: I tensorflow/core/platform/cpu_feature_guard.cc:182] This TensorFlow binary is optimized to use available CPU instructions in performance-critical operations.
To enable the following instructions: AVX2 AVX512F AVX512_VNNI FMA, in other operations, rebuild TensorFlow with the appropriate compiler flags.
2024-04-28 00:21:04.400468: W tensorflow/compiler/tf2tensorrt/utils/py_utils.cc:38] TF-TRT Warning: Could not find TensorRT
WARNING:tensorflow:From /home/ketrong/miniconda3/envs/tpot2devenv/lib/python3.10/site-packages/tensorflow/python/compat/v2_compat.py:108: disable_resource_variables (from tensorflow.python.ops.variable_scope) is deprecated and will be removed in a future version.
Instructions for updating:
non-resource variables are not supported in the long term
starting loops
working on 
logs/3764/tpot2_base_normal_MAR_0.01
0.30426764488220215
loading data
logs/3764/tpot2_base_normal_MAR_0.01/data/3764_True.pkl
Could not download file from https://openml1.win.tue.nl/datasets/0000/0901/dataset_901.pq: [Errno 2] No such file or directory: '/home/ketrong/.cache/openml/org/openml/www/datasets/901/dataset_901.pq.ea79047bc946f709596901e738b3bb63.part.minio' -> '/home/ketrong/.cache/openml/org/openml/www/datasets/901/dataset_901.pq'
Failed to download parquet, fallback on ARFF.
failed on 
logs/3764/tpot2_base_normal_MAR_0.01
Cannot remove faulty datasets cache directory /home/ketrong/.cache/openml/org/openml/www/datasets/901.Please do this manually!
Traceback (most recent call last):
  File "/home/ketrong/miniconda3/envs/tpot2devenv/lib/python3.10/site-packages/openml/datasets/functions.py", line 498, in get_dataset
    parquet_file = _get_dataset_parquet(
  File "/home/ketrong/miniconda3/envs/tpot2devenv/lib/python3.10/site-packages/openml/datasets/functions.py", line 1098, in _get_dataset_parquet
    openml._api_calls._download_minio_file(
  File "/home/ketrong/miniconda3/envs/tpot2devenv/lib/python3.10/site-packages/openml/_api_calls.py", line 151, in _download_minio_file
    client.fget_object(
  File "/home/ketrong/miniconda3/envs/tpot2devenv/lib/python3.10/site-packages/minio/api.py", line 1074, in fget_object
    with open(tmp_file_path, "wb") as tmp_file:
OSError: [Errno 5] Input/output error: '/home/ketrong/.cache/openml/org/openml/www/datasets/901/dataset_901.pq.ea79047bc946f709596901e738b3bb63.part.minio'

During handling of the above exception, another exception occurred:

Traceback (most recent call last):
  File "/home/ketrong/miniconda3/envs/tpot2devenv/lib/python3.10/site-packages/openml/utils.py", line 375, in _remove_cache_dir_for_id
    shutil.rmtree(cache_dir)
  File "/home/ketrong/miniconda3/envs/tpot2devenv/lib/python3.10/shutil.py", line 715, in rmtree
    onerror(os.lstat, path, sys.exc_info())
  File "/home/ketrong/miniconda3/envs/tpot2devenv/lib/python3.10/shutil.py", line 713, in rmtree
    orig_st = os.lstat(path)
FileNotFoundError: [Errno 2] No such file or directory: '/home/ketrong/.cache/openml/org/openml/www/datasets/901'

During handling of the above exception, another exception occurred:

Traceback (most recent call last):
  File "/common/ketrong/AutoImputeExp/tpot2_imputetest/Impute_Experiments/utils.py", line 316, in loop_through_tasks
    X_train, y_train, X_test, y_test = load_task(base_save_folder=base_save_folder, exp=exp, type=type, levelstr=levelstr, task_id=taskid, preprocess=True)
  File "/common/ketrong/AutoImputeExp/tpot2_imputetest/Impute_Experiments/utils.py", line 208, in load_task
    X, y = task.get_X_and_y(dataset_format="dataframe")
  File "/home/ketrong/miniconda3/envs/tpot2devenv/lib/python3.10/site-packages/openml/tasks/task.py", line 269, in get_X_and_y
    dataset = self.get_dataset()
  File "/home/ketrong/miniconda3/envs/tpot2devenv/lib/python3.10/site-packages/openml/tasks/task.py", line 119, in get_dataset
    return datasets.get_dataset(self.dataset_id)
  File "/home/ketrong/miniconda3/envs/tpot2devenv/lib/python3.10/site-packages/openml/datasets/functions.py", line 517, in get_dataset
    _remove_cache_dir_for_id(DATASETS_CACHE_DIR_NAME, did_cache_dir)
  File "/home/ketrong/miniconda3/envs/tpot2devenv/lib/python3.10/site-packages/openml/utils.py", line 377, in _remove_cache_dir_for_id
    raise ValueError(
ValueError: Cannot remove faulty datasets cache directory /home/ketrong/.cache/openml/org/openml/www/datasets/901.Please do this manually!

full run takes
0.0025380298164155747
hours
DONE
